{"type":"orderbook_delta","sid":1,"seq":1521,"msg":{"market_ticker":"KXNEXTTEAMNBA-26LJAM-GSW","market_id":"abbbad28-f309-4dd5-af38-2ad7ebf2acc3","price_dollars":"0.0100","delta_fp":"1.00","side":"yes","ts":"2026-07-01T02:34:10.876742Z","ts_ms":1782873250876}}

{"type":"orderbook_delta","sid":1,"seq":1522,"msg":{"market_ticker":"KXNEXTTEAMNBA-26LJAM-GSW","market_id":"abbbad28-f309-4dd5-af38-2ad7ebf2acc3","price_dollars":"0.0100","delta_fp":"1.00","side":"yes","ts":"2026-07-01T02:34:10.877226Z","ts_ms":1782873250877}}

{"type":"orderbook_delta","sid":1,"seq":1523,"msg":{"market_ticker":"KXNEXTTEAMNBA-26LJAM-GSW","market_id":"abbbad28-f309-4dd5-af38-2ad7ebf2acc3","price_dollars":"0.0100","delta_fp":"1.00","side":"yes","ts":"2026-07-01T02:34:10.877488Z","ts_ms":1782873250877}}

{"type":"orderbook_delta","sid":1,"seq":1524,"msg":{"market_ticker":"KXNEXTTEAMNBA-26LJAM-GSW","market_id":"abbbad28-f309-4dd5-af38-2ad7ebf2acc3","price_dollars":"0.0100","delta_fp":"1.00","side":"yes","ts":"2026-07-01T02:34:10.877962Z","ts_ms":1782873250877}}

{"type":"orderbook_delta","sid":1,"seq":1525,"msg":{"market_ticker":"KXNEXTTEAMNBA-26LJAM-GSW","market_id":"abbbad28-f309-4dd5-af38-2ad7ebf2acc3","price_dollars":"0.0100","delta_fp":"1.00","side":"yes","ts":"2026-07-01T02:34:10.878481Z","ts_ms":1782873250878}}

{"type":"orderbook_delta","sid":1,"seq":1526,"msg":{"market_ticker":"KXNEXTTEAMNBA-26LJAM-GSW","market_id":"abbbad28-f309-4dd5-af38-2ad7ebf2acc3","price_dollars":"0.0100","delta_fp":"1.00","side":"yes","ts":"2026-07-01T02:34:10.878917Z","ts_ms":1782873250878}}

{"type":"orderbook_delta","sid":1,"seq":1527,"msg":{"market_ticker":"KXNEXTTEAMNBA-26LJAM-GSW","market_id":"abbbad28-f309-4dd5-af38-2ad7ebf2acc3","price_dollars":"0.0100","delta_fp":"1.00","side":"yes","ts":"2026-07-01T02:34:10.879321Z","ts_ms":1782873250879}}

{"type":"orderbook_delta","sid":1,"seq":1528,"msg":{"market_ticker":"KXNEXTTEAMNBA-26LJAM-GSW","market_id":"abbbad28-f309-4dd5-af38-2ad7ebf2acc3","price_dollars":"0.0100","delta_fp":"1.00","side":"yes","ts":"2026-07-01T02:34:10.879658Z","ts_ms":1782873250879}}

{"type":"orderbook_delta","sid":1,"seq":1529,"msg":{"market_ticker":"KXNEXTTEAMNBA-26LJAM-GSW","market_id":"abbbad28-f309-4dd5-af38-2ad7ebf2acc3","price_dollars":"0.0100","delta_fp":"1.00","side":"yes","ts":"2026-07-01T02:34:10.880091Z","ts_ms":1782873250880}}

{"type":"orderbook_delta","sid":1,"seq":1530,"msg":{"market_ticker":"KXNEXTTEAMNBA-26LJAM-GSW","market_id":"abbbad28-f309-4dd5-af38-2ad7ebf2acc3","price_dollars":"0.0100","delta_fp":"1.00","side":"yes","ts":"2026-07-01T02:34:10.880536Z","ts_ms":1782873250880}}

{"type":"orderbook_delta","sid":1,"seq":1531,"msg":{"market_ticker":"KXNEXTTEAMNBA-26LJAM-MIA","market_id":"492cb255-91da-4c91-bc9e-f83d090cc6dd","price_dollars":"0.0100","delta_fp":"1.00","side":"yes","ts":"2026-07-01T02:34:12.057066Z","ts_ms":1782873252057}}

{"type":"orderbook_delta","sid":1,"seq":1532,"msg":{"market_ticker":"KXNEXTTEAMNBA-26LJAM-MIA","market_id":"492cb255-91da-4c91-bc9e-f83d090cc6dd","price_dollars":"0.0100","delta_fp":"1.00","side":"yes","ts":"2026-07-01T02:34:12.057862Z","ts_ms":1782873252057}}

{"type":"orderbook_delta","sid":1,"seq":1533,"msg":{"market_ticker":"KXNEXTTEAMNBA-26LJAM-MIA","market_id":"492cb255-91da-4c91-bc9e-f83d090cc6dd","price_dollars":"0.0100","delta_fp":"1.00","side":"yes","ts":"2026-07-01T02:34:12.058525Z","ts_ms":1782873252058}}

{"type":"orderbook_delta","sid":1,"seq":1534,"msg":{"market_ticker":"KXNEXTTEAMNBA-26LJAM-MIA","market_id":"492cb255-91da-4c91-bc9e-f83d090cc6dd","price_dollars":"0.0100","delta_fp":"1.00","side":"yes","ts":"2026-07-01T02:34:12.059011Z","ts_ms":1782873252059}}

{"type":"orderbook_delta","sid":1,"seq":1535,"msg":{"market_ticker":"KXNEXTTEAMNBA-26LJAM-MIA","market_id":"492cb255-91da-4c91-bc9e-f83d090cc6dd","price_dollars":"0.0100","delta_fp":"1.00","side":"yes","ts":"2026-07-01T02:34:12.059421Z","ts_ms":1782873252059}}

{"type":"orderbook_delta","sid":1,"seq":1536,"msg":{"market_ticker":"KXNEXTTEAMNBA-26LJAM-MIA","market_id":"492cb255-91da-4c91-bc9e-f83d090cc6dd","price_dollars":"0.0100","delta_fp":"1.00","side":"yes","ts":"2026-07-01T02:34:12.059984Z","ts_ms":1782873252059}}

{"type":"orderbook_delta","sid":1,"seq":1537,"msg":{"market_ticker":"KXNEXTTEAMNBA-26LJAM-MIA","market_id":"492cb255-91da-4c91-bc9e-f83d090cc6dd","price_dollars":"0.0100","delta_fp":"1.00","side":"yes","ts":"2026-07-01T02:34:12.060609Z","ts_ms":1782873252060}}

{"type":"orderbook_delta","sid":1,"seq":1538,"msg":{"market_ticker":"KXNEXTTEAMNBA-26LJAM-MIA","market_id":"492cb255-91da-4c91-bc9e-f83d090cc6dd","price_dollars":"0.0100","delta_fp":"1.00","side":"yes","ts":"2026-07-01T02:34:12.061131Z","ts_ms":1782873252061}}

{"type":"orderbook_delta","sid":1,"seq":1539,"msg":{"market_ticker":"KXNEXTTEAMNBA-26LJAM-MIA","market_id":"492cb255-91da-4c91-bc9e-f83d090cc6dd","price_dollars":"0.0100","delta_fp":"1.00","side":"yes","ts":"2026-07-01T02:34:12.061665Z","ts_ms":1782873252061}}

{"type":"orderbook_delta","sid":1,"seq":1540,"msg":{"market_ticker":"KXNEXTTEAMNBA-26LJAM-MIA","market_id":"492cb255-91da-4c91-bc9e-f83d090cc6dd","price_dollars":"0.0100","delta_fp":"1.00","side":"yes","ts":"2026-07-01T02:34:12.062121Z","ts_ms":1782873252062}}

{"type":"orderbook_delta","sid":1,"seq":1541,"msg":{"market_ticker":"KXNEXTTEAMNBA-26LJAM-MIA","market_id":"492cb255-91da-4c91-bc9e-f83d090cc6dd","price_dollars":"0.0100","delta_fp":"1.00","side":"yes","ts":"2026-07-01T02:34:12.062532Z","ts_ms":1782873252062}}

{"type":"orderbook_delta","sid":1,"seq":1542,"msg":{"market_ticker":"KXNEXTTEAMNBA-26LJAM-MIA","market_id":"492cb255-91da-4c91-bc9e-f83d090cc6dd","price_dollars":"0.0100","delta_fp":"1.00","side":"yes","ts":"2026-07-01T02:34:12.062793Z","ts_ms":1782873252062}}

{"type":"orderbook_delta","sid":1,"seq":1543,"msg":{"market_ticker":"KXNEXTTEAMNBA-26LJAM-MIA","market_id":"492cb255-91da-4c91-bc9e-f83d090cc6dd","price_dollars":"0.0100","delta_fp":"1.00","side":"yes","ts":"2026-07-01T02:34:12.063097Z","ts_ms":1782873252063}}

{"type":"orderbook_delta","sid":1,"seq":1544,"msg":{"market_ticker":"KXNEXTTEAMNBA-26LJAM-MIA","market_id":"492cb255-91da-4c91-bc9e-f83d090cc6dd","price_dollars":"0.0100","delta_fp":"1.00","side":"yes","ts":"2026-07-01T02:34:12.063405Z","ts_ms":1782873252063}}

{"type":"orderbook_delta","sid":1,"seq":1545,"msg":{"market_ticker":"KXNEXTTEAMNBA-26LJAM-MIA","market_id":"492cb255-91da-4c91-bc9e-f83d090cc6dd","price_dollars":"0.0100","delta_fp":"1.00","side":"yes","ts":"2026-07-01T02:34:12.063796Z","ts_ms":1782873252063}}

{"type":"orderbook_delta","sid":1,"seq":1546,"msg":{"market_ticker":"KXNEXTTEAMNBA-26LJAM-MIA","market_id":"492cb255-91da-4c91-bc9e-f83d090cc6dd","price_dollars":"0.0100","delta_fp":"1.00","side":"yes","ts":"2026-07-01T02:34:12.064161Z","ts_ms":1782873252064}}

{"type":"orderbook_delta","sid":1,"seq":1547,"msg":{"market_ticker":"KXNEXTTEAMNBA-26LJAM-MIA","market_id":"492cb255-91da-4c91-bc9e-f83d090cc6dd","price_dollars":"0.0100","delta_fp":"1.00","side":"yes","ts":"2026-07-01T02:34:12.064509Z","ts_ms":1782873252064}}

{"type":"orderbook_delta","sid":1,"seq":1548,"msg":{"market_ticker":"KXNEXTTEAMNBA-26LJAM-MIA","market_id":"492cb255-91da-4c91-bc9e-f83d090cc6dd","price_dollars":"0.0100","delta_fp":"1.00","side":"yes","ts":"2026-07-01T02:34:12.064872Z","ts_ms":1782873252064}}

{"type":"orderbook_delta","sid":1,"seq":1549,"msg":{"market_ticker":"KXNEXTTEAMNBA-26LJAM-MIA","market_id":"492cb255-91da-4c91-bc9e-f83d090cc6dd","price_dollars":"0.0100","delta_fp":"1.00","side":"yes","ts":"2026-07-01T02:34:12.065343Z","ts_ms":1782873252065}}

{"type":"orderbook_delta","sid":1,"seq":1550,"msg":{"market_ticker":"KXNEXTTEAMNBA-26LJAM-MIA","market_id":"492cb255-91da-4c91-bc9e-f83d090cc6dd","price_dollars":"0.0100","delta_fp":"1.00","side":"yes","ts":"2026-07-01T02:34:12.065776Z","ts_ms":1782873252065}}

{"type":"orderbook_delta","sid":1,"seq":1551,"msg":{"market_ticker":"KXNEXTTEAMNBA-26LJAM-GSW","market_id":"abbbad28-f309-4dd5-af38-2ad7ebf2acc3","price_dollars":"0.5200","delta_fp":"-0.72","side":"no","ts":"2026-07-01T02:34:12.168149Z","ts_ms":1782873252168}}

{"type":"orderbook_delta","sid":1,"seq":1552,"msg":{"market_ticker":"KXNEXTTEAMNBA-26LJAM-MIA","market_id":"492cb255-91da-4c91-bc9e-f83d090cc6dd","price_dollars":"0.8300","delta_fp":"-0.51","side":"no","ts":"2026-07-01T02:34:12.273006Z","ts_ms":1782873252273}}

{"type":"orderbook_delta","sid":1,"seq":1553,"msg":{"market_ticker":"KXNEXTTEAMNBA-26LJAM-MIA","market_id":"492cb255-91da-4c91-bc9e-f83d090cc6dd","price_dollars":"0.8300","delta_fp":"-1.08","side":"no","ts":"2026-07-01T02:34:13.865245Z","ts_ms":1782873253865}}

{"type":"orderbook_delta","sid":1,"seq":1554,"msg":{"market_ticker":"KXNEXTTEAMNBA-26LJAM-CLE","market_id":"7552b8d4-05de-4e41-84a8-97b0684da4a9","price_dollars":"0.7400","delta_fp":"-1.12","side":"no","ts":"2026-07-01T02:34:13.890909Z","ts_ms":1782873253890}}

{"type":"orderbook_delta","sid":1,"seq":1555,"msg":{"market_ticker":"KXNEXTTEAMNBA-26LJAM-MIA","market_id":"492cb255-91da-4c91-bc9e-f83d090cc6dd","price_dollars":"0.0100","delta_fp":"-1.00","side":"yes","ts":"2026-07-01T02:34:14.021483Z","ts_ms":1782873254021}}

{"type":"orderbook_delta","sid":1,"seq":1556,"msg":{"market_ticker":"KXNEXTTEAMNBA-26LJAM-MIA","market_id":"492cb255-91da-4c91-bc9e-f83d090cc6dd","price_dollars":"0.0100","delta_fp":"-1.00","side":"yes","ts":"2026-07-01T02:34:14.02184Z","ts_ms":1782873254021}}

{"type":"orderbook_delta","sid":1,"seq":1557,"msg":{"market_ticker":"KXNEXTTEAMNBA-26LJAM-MIA","market_id":"492cb255-91da-4c91-bc9e-f83d090cc6dd","price_dollars":"0.0100","delta_fp":"-1.00","side":"yes","ts":"2026-07-01T02:34:14.022094Z","ts_ms":1782873254022}}

{"type":"orderbook_delta","sid":1,"seq":1558,"msg":{"market_ticker":"KXNEXTTEAMNBA-26LJAM-MIA","market_id":"492cb255-91da-4c91-bc9e-f83d090cc6dd","price_dollars":"0.0100","delta_fp":"-1.00","side":"yes","ts":"2026-07-01T02:34:14.022493Z","ts_ms":1782873254022}}

{"type":"orderbook_delta","sid":1,"seq":1559,"msg":{"market_ticker":"KXNEXTTEAMNBA-26LJAM-MIA","market_id":"492cb255-91da-4c91-bc9e-f83d090cc6dd","price_dollars":"0.0100","delta_fp":"-1.00","side":"yes","ts":"2026-07-01T02:34:14.02284Z","ts_ms":1782873254022}}

{"type":"orderbook_delta","sid":1,"seq":1560,"msg":{"market_ticker":"KXNEXTTEAMNBA-26LJAM-MIA","market_id":"492cb255-91da-4c91-bc9e-f83d090cc6dd","price_dollars":"0.0100","delta_fp":"-1.00","side":"yes","ts":"2026-07-01T02:34:14.023259Z","ts_ms":1782873254023}}

{"type":"orderbook_delta","sid":1,"seq":1561,"msg":{"market_ticker":"KXNEXTTEAMNBA-26LJAM-MIA","market_id":"492cb255-91da-4c91-bc9e-f83d090cc6dd","price_dollars":"0.0100","delta_fp":"-1.00","side":"yes","ts":"2026-07-01T02:34:14.023586Z","ts_ms":1782873254023}}

{"type":"orderbook_delta","sid":1,"seq":1562,"msg":{"market_ticker":"KXNEXTTEAMNBA-26LJAM-MIA","market_id":"492cb255-91da-4c91-bc9e-f83d090cc6dd","price_dollars":"0.0100","delta_fp":"-1.00","side":"yes","ts":"2026-07-01T02:34:14.023946Z","ts_ms":1782873254023}}

{"type":"orderbook_delta","sid":1,"seq":1563,"msg":{"market_ticker":"KXNEXTTEAMNBA-26LJAM-MIA","market_id":"492cb255-91da-4c91-bc9e-f83d090cc6dd","price_dollars":"0.0100","delta_fp":"-1.00","side":"yes","ts":"2026-07-01T02:34:14.024277Z","ts_ms":1782873254024}}

{"type":"orderbook_delta","sid":1,"seq":1564,"msg":{"market_ticker":"KXNEXTTEAMNBA-26LJAM-MIA","market_id":"492cb255-91da-4c91-bc9e-f83d090cc6dd","price_dollars":"0.0100","delta_fp":"-1.00","side":"yes","ts":"2026-07-01T02:34:14.024872Z","ts_ms":1782873254024}}

{"type":"orderbook_delta","sid":1,"seq":1565,"msg":{"market_ticker":"KXNEXTTEAMNBA-26LJAM-MIA","market_id":"492cb255-91da-4c91-bc9e-f83d090cc6dd","price_dollars":"0.0100","delta_fp":"-1.00","side":"yes","ts":"2026-07-01T02:34:14.025235Z","ts_ms":1782873254025}}

{"type":"orderbook_delta","sid":1,"seq":1566,"msg":{"market_ticker":"KXNEXTTEAMNBA-26LJAM-MIA","market_id":"492cb255-91da-4c91-bc9e-f83d090cc6dd","price_dollars":"0.0100","delta_fp":"-1.00","side":"yes","ts":"2026-07-01T02:34:14.025558Z","ts_ms":1782873254025}}

{"type":"orderbook_delta","sid":1,"seq":1567,"msg":{"market_ticker":"KXNEXTTEAMNBA-26LJAM-MIA","market_id":"492cb255-91da-4c91-bc9e-f83d090cc6dd","price_dollars":"0.0100","delta_fp":"-1.00","side":"yes","ts":"2026-07-01T02:34:14.025914Z","ts_ms":1782873254025}}

{"type":"orderbook_delta","sid":1,"seq":1568,"msg":{"market_ticker":"KXNEXTTEAMNBA-26LJAM-MIA","market_id":"492cb255-91da-4c91-bc9e-f83d090cc6dd","price_dollars":"0.0100","delta_fp":"-1.00","side":"yes","ts":"2026-07-01T02:34:14.026284Z","ts_ms":1782873254026}}

{"type":"orderbook_delta","sid":1,"seq":1569,"msg":{"market_ticker":"KXNEXTTEAMNBA-26LJAM-MIA","market_id":"492cb255-91da-4c91-bc9e-f83d090cc6dd","price_dollars":"0.0100","delta_fp":"-1.00","side":"yes","ts":"2026-07-01T02:34:14.02666Z","ts_ms":1782873254026}}

{"type":"orderbook_delta","sid":1,"seq":1570,"msg":{"market_ticker":"KXNEXTTEAMNBA-26LJAM-MIA","market_id":"492cb255-91da-4c91-bc9e-f83d090cc6dd","price_dollars":"0.0100","delta_fp":"-1.00","side":"yes","ts":"2026-07-01T02:34:14.027028Z","ts_ms":1782873254027}}

{"type":"orderbook_delta","sid":1,"seq":1571,"msg":{"market_ticker":"KXNEXTTEAMNBA-26LJAM-MIA","market_id":"492cb255-91da-4c91-bc9e-f83d090cc6dd","price_dollars":"0.0100","delta_fp":"-1.00","side":"yes","ts":"2026-07-01T02:34:14.027307Z","ts_ms":1782873254027}}

{"type":"orderbook_delta","sid":1,"seq":1572,"msg":{"market_ticker":"KXNEXTTEAMNBA-26LJAM-MIA","market_id":"492cb255-91da-4c91-bc9e-f83d090cc6dd","price_dollars":"0.0100","delta_fp":"-1.00","side":"yes","ts":"2026-07-01T02:34:14.027603Z","ts_ms":1782873254027}}

{"type":"orderbook_delta","sid":1,"seq":1573,"msg":{"market_ticker":"KXNEXTTEAMNBA-26LJAM-MIA","market_id":"492cb255-91da-4c91-bc9e-f83d090cc6dd","price_dollars":"0.0100","delta_fp":"-1.00","side":"yes","ts":"2026-07-01T02:34:14.02817Z","ts_ms":1782873254028}}

{"type":"orderbook_delta","sid":1,"seq":1574,"msg":{"market_ticker":"KXNEXTTEAMNBA-26LJAM-MIA","market_id":"492cb255-91da-4c91-bc9e-f83d090cc6dd","price_dollars":"0.0100","delta_fp":"-1.00","side":"yes","ts":"2026-07-01T02:34:14.028473Z","ts_ms":1782873254028}}

{"type":"orderbook_delta","sid":1,"seq":1575,"msg":{"market_ticker":"KXNEXTTEAMNBA-26LJAM-MIA","market_id":"492cb255-91da-4c91-bc9e-f83d090cc6dd","price_dollars":"0.8300","delta_fp":"-0.90","side":"no","ts":"2026-07-01T02:34:15.465046Z","ts_ms":1782873255465}}

{"type":"orderbook_delta","sid":1,"seq":1576,"msg":{"market_ticker":"KXNEXTTEAMNBA-26LJAM-GSW","market_id":"abbbad28-f309-4dd5-af38-2ad7ebf2acc3","price_dollars":"0.5200","delta_fp":"-1.42","side":"no","ts":"2026-07-01T02:34:16.926358Z","ts_ms":1782873256926}}

{"type":"orderbook_delta","sid":1,"seq":1577,"msg":{"market_ticker":"KXNEXTTEAMNBA-26LJAM-GSW","market_id":"abbbad28-f309-4dd5-af38-2ad7ebf2acc3","price_dollars":"0.0100","delta_fp":"1.00","side":"yes","ts":"2026-07-01T02:34:17.167302Z","ts_ms":1782873257167}}

{"type":"orderbook_delta","sid":1,"seq":1578,"msg":{"market_ticker":"KXNEXTTEAMNBA-26LJAM-GSW","market_id":"abbbad28-f309-4dd5-af38-2ad7ebf2acc3","price_dollars":"0.0100","delta_fp":"1.00","side":"yes","ts":"2026-07-01T02:34:17.167947Z","ts_ms":1782873257167}}

{"type":"orderbook_delta","sid":1,"seq":1579,"msg":{"market_ticker":"KXNEXTTEAMNBA-26LJAM-GSW","market_id":"abbbad28-f309-4dd5-af38-2ad7ebf2acc3","price_dollars":"0.0100","delta_fp":"1.00","side":"yes","ts":"2026-07-01T02:34:17.16881Z","ts_ms":1782873257168}}

{"type":"orderbook_delta","sid":1,"seq":1580,"msg":{"market_ticker":"KXNEXTTEAMNBA-26LJAM-GSW","market_id":"abbbad28-f309-4dd5-af38-2ad7ebf2acc3","price_dollars":"0.0100","delta_fp":"1.00","side":"yes","ts":"2026-07-01T02:34:17.169737Z","ts_ms":1782873257169}}

{"type":"orderbook_delta","sid":1,"seq":1581,"msg":{"market_ticker":"KXNEXTTEAMNBA-26LJAM-GSW","market_id":"abbbad28-f309-4dd5-af38-2ad7ebf2acc3","price_dollars":"0.0100","delta_fp":"1.00","side":"yes","ts":"2026-07-01T02:34:17.170649Z","ts_ms":1782873257170}}

{"type":"orderbook_delta","sid":1,"seq":1582,"msg":{"market_ticker":"KXNEXTTEAMNBA-26LJAM-GSW","market_id":"abbbad28-f309-4dd5-af38-2ad7ebf2acc3","price_dollars":"0.0100","delta_fp":"1.00","side":"yes","ts":"2026-07-01T02:34:17.171541Z","ts_ms":1782873257171}}

{"type":"orderbook_delta","sid":1,"seq":1583,"msg":{"market_ticker":"KXNEXTTEAMNBA-26LJAM-GSW","market_id":"abbbad28-f309-4dd5-af38-2ad7ebf2acc3","price_dollars":"0.0100","delta_fp":"1.00","side":"yes","ts":"2026-07-01T02:34:17.172373Z","ts_ms":1782873257172}}

{"type":"orderbook_delta","sid":1,"seq":1584,"msg":{"market_ticker":"KXNEXTTEAMNBA-26LJAM-GSW","market_id":"abbbad28-f309-4dd5-af38-2ad7ebf2acc3","price_dollars":"0.0100","delta_fp":"1.00","side":"yes","ts":"2026-07-01T02:34:17.173167Z","ts_ms":1782873257173}}

{"type":"orderbook_delta","sid":1,"seq":1585,"msg":{"market_ticker":"KXNEXTTEAMNBA-26LJAM-GSW","market_id":"abbbad28-f309-4dd5-af38-2ad7ebf2acc3","price_dollars":"0.0100","delta_fp":"1.00","side":"yes","ts":"2026-07-01T02:34:17.173863Z","ts_ms":1782873257173}}

{"type":"orderbook_delta","sid":1,"seq":1586,"msg":{"market_ticker":"KXNEXTTEAMNBA-26LJAM-GSW","market_id":"abbbad28-f309-4dd5-af38-2ad7ebf2acc3","price_dollars":"0.0100","delta_fp":"1.00","side":"yes","ts":"2026-07-01T02:34:17.174441Z","ts_ms":1782873257174}}

{"type":"orderbook_delta","sid":1,"seq":1587,"msg":{"market_ticker":"KXNEXTTEAMNBA-26LJAM-GSW","market_id":"abbbad28-f309-4dd5-af38-2ad7ebf2acc3","price_dollars":"0.0100","delta_fp":"1.00","side":"yes","ts":"2026-07-01T02:34:17.175094Z","ts_ms":1782873257175}}

{"type":"orderbook_delta","sid":1,"seq":1588,"msg":{"market_ticker":"KXNEXTTEAMNBA-26LJAM-GSW","market_id":"abbbad28-f309-4dd5-af38-2ad7ebf2acc3","price_dollars":"0.0100","delta_fp":"1.00","side":"yes","ts":"2026-07-01T02:34:17.175941Z","ts_ms":1782873257175}}

{"type":"orderbook_delta","sid":1,"seq":1589,"msg":{"market_ticker":"KXNEXTTEAMNBA-26LJAM-GSW","market_id":"abbbad28-f309-4dd5-af38-2ad7ebf2acc3","price_dollars":"0.0100","delta_fp":"1.00","side":"yes","ts":"2026-07-01T02:34:17.17662Z","ts_ms":1782873257176}}

{"type":"orderbook_delta","sid":1,"seq":1590,"msg":{"market_ticker":"KXNEXTTEAMNBA-26LJAM-GSW","market_id":"abbbad28-f309-4dd5-af38-2ad7ebf2acc3","price_dollars":"0.0100","delta_fp":"1.00","side":"yes","ts":"2026-07-01T02:34:17.177474Z","ts_ms":1782873257177}}

{"type":"orderbook_delta","sid":1,"seq":1591,"msg":{"market_ticker":"KXNEXTTEAMNBA-26LJAM-GSW","market_id":"abbbad28-f309-4dd5-af38-2ad7ebf2acc3","price_dollars":"0.0100","delta_fp":"1.00","side":"yes","ts":"2026-07-01T02:34:17.178097Z","ts_ms":1782873257178}}

{"type":"orderbook_delta","sid":1,"seq":1592,"msg":{"market_ticker":"KXNEXTTEAMNBA-26LJAM-GSW","market_id":"abbbad28-f309-4dd5-af38-2ad7ebf2acc3","price_dollars":"0.0100","delta_fp":"1.00","side":"yes","ts":"2026-07-01T02:34:17.178511Z","ts_ms":1782873257178}}

{"type":"orderbook_delta","sid":1,"seq":1593,"msg":{"market_ticker":"KXNEXTTEAMNBA-26LJAM-GSW","market_id":"abbbad28-f309-4dd5-af38-2ad7ebf2acc3","price_dollars":"0.0100","delta_fp":"1.00","side":"yes","ts":"2026-07-01T02:34:17.179012Z","ts_ms":1782873257179}}

{"type":"orderbook_delta","sid":1,"seq":1594,"msg":{"market_ticker":"KXNEXTTEAMNBA-26LJAM-GSW","market_id":"abbbad28-f309-4dd5-af38-2ad7ebf2acc3","price_dollars":"0.0100","delta_fp":"1.00","side":"yes","ts":"2026-07-01T02:34:17.179466Z","ts_ms":1782873257179}}

{"type":"orderbook_delta","sid":1,"seq":1595,"msg":{"market_ticker":"KXNEXTTEAMNBA-26LJAM-GSW","market_id":"abbbad28-f309-4dd5-af38-2ad7ebf2acc3","price_dollars":"0.0100","delta_fp":"1.00","side":"yes","ts":"2026-07-01T02:34:17.179949Z","ts_ms":1782873257179}}

{"type":"orderbook_delta","sid":1,"seq":1596,"msg":{"market_ticker":"KXNEXTTEAMNBA-26LJAM-GSW","market_id":"abbbad28-f309-4dd5-af38-2ad7ebf2acc3","price_dollars":"0.0100","delta_fp":"1.00","side":"yes","ts":"2026-07-01T02:34:17.180431Z","ts_ms":1782873257180}}

{"type":"orderbook_delta","sid":1,"seq":1597,"msg":{"market_ticker":"KXNEXTTEAMNBA-26LJAM-MIA","market_id":"492cb255-91da-4c91-bc9e-f83d090cc6dd","price_dollars":"0.0100","delta_fp":"1.00","side":"yes","ts":"2026-07-01T02:34:18.259844Z","ts_ms":1782873258259}}

{"type":"orderbook_delta","sid":1,"seq":1598,"msg":{"market_ticker":"KXNEXTTEAMNBA-26LJAM-MIA","market_id":"492cb255-91da-4c91-bc9e-f83d090cc6dd","price_dollars":"0.0100","delta_fp":"1.00","side":"yes","ts":"2026-07-01T02:34:18.260377Z","ts_ms":1782873258260}}

{"type":"orderbook_delta","sid":1,"seq":1599,"msg":{"market_ticker":"KXNEXTTEAMNBA-26LJAM-MIA","market_id":"492cb255-91da-4c91-bc9e-f83d090cc6dd","price_dollars":"0.0100","delta_fp":"1.00","side":"yes","ts":"2026-07-01T02:34:18.260779Z","ts_ms":1782873258260}}

{"type":"orderbook_delta","sid":1,"seq":1600,"msg":{"market_ticker":"KXNEXTTEAMNBA-26LJAM-MIA","market_id":"492cb255-91da-4c91-bc9e-f83d090cc6dd","price_dollars":"0.0100","delta_fp":"1.00","side":"yes","ts":"2026-07-01T02:34:18.261388Z","ts_ms":1782873258261}}

{"type":"orderbook_delta","sid":1,"seq":1601,"msg":{"market_ticker":"KXNEXTTEAMNBA-26LJAM-MIA","market_id":"492cb255-91da-4c91-bc9e-f83d090cc6dd","price_dollars":"0.0100","delta_fp":"1.00","side":"yes","ts":"2026-07-01T02:34:18.261882Z","ts_ms":1782873258261}}

{"type":"orderbook_delta","sid":1,"seq":1602,"msg":{"market_ticker":"KXNEXTTEAMNBA-26LJAM-MIA","market_id":"492cb255-91da-4c91-bc9e-f83d090cc6dd","price_dollars":"0.0100","delta_fp":"1.00","side":"yes","ts":"2026-07-01T02:34:18.262289Z","ts_ms":1782873258262}}

{"type":"orderbook_delta","sid":1,"seq":1603,"msg":{"market_ticker":"KXNEXTTEAMNBA-26LJAM-MIA","market_id":"492cb255-91da-4c91-bc9e-f83d090cc6dd","price_dollars":"0.0100","delta_fp":"1.00","side":"yes","ts":"2026-07-01T02:34:18.262857Z","ts_ms":1782873258262}}

{"type":"orderbook_delta","sid":1,"seq":1604,"msg":{"market_ticker":"KXNEXTTEAMNBA-26LJAM-MIA","market_id":"492cb255-91da-4c91-bc9e-f83d090cc6dd","price_dollars":"0.0100","delta_fp":"1.00","side":"yes","ts":"2026-07-01T02:34:18.26348Z","ts_ms":1782873258263}}

{"type":"orderbook_delta","sid":1,"seq":1605,"msg":{"market_ticker":"KXNEXTTEAMNBA-26LJAM-MIA","market_id":"492cb255-91da-4c91-bc9e-f83d090cc6dd","price_dollars":"0.0100","delta_fp":"1.00","side":"yes","ts":"2026-07-01T02:34:18.26418Z","ts_ms":1782873258264}}

{"type":"orderbook_delta","sid":1,"seq":1606,"msg":{"market_ticker":"KXNEXTTEAMNBA-26LJAM-MIA","market_id":"492cb255-91da-4c91-bc9e-f83d090cc6dd","price_dollars":"0.0100","delta_fp":"1.00","side":"yes","ts":"2026-07-01T02:34:18.26482Z","ts_ms":1782873258264}}

{"type":"orderbook_delta","sid":1,"seq":1607,"msg":{"market_ticker":"KXNEXTTEAMNBA-26LJAM-MIA","market_id":"492cb255-91da-4c91-bc9e-f83d090cc6dd","price_dollars":"0.0100","delta_fp":"1.00","side":"yes","ts":"2026-07-01T02:34:18.265327Z","ts_ms":1782873258265}}

{"type":"orderbook_delta","sid":1,"seq":1608,"msg":{"market_ticker":"KXNEXTTEAMNBA-26LJAM-MIA","market_id":"492cb255-91da-4c91-bc9e-f83d090cc6dd","price_dollars":"0.0100","delta_fp":"1.00","side":"yes","ts":"2026-07-01T02:34:18.265941Z","ts_ms":1782873258265}}

{"type":"orderbook_delta","sid":1,"seq":1609,"msg":{"market_ticker":"KXNEXTTEAMNBA-26LJAM-MIA","market_id":"492cb255-91da-4c91-bc9e-f83d090cc6dd","price_dollars":"0.0100","delta_fp":"1.00","side":"yes","ts":"2026-07-01T02:34:18.266311Z","ts_ms":1782873258266}}

{"type":"orderbook_delta","sid":1,"seq":1610,"msg":{"market_ticker":"KXNEXTTEAMNBA-26LJAM-MIA","market_id":"492cb255-91da-4c91-bc9e-f83d090cc6dd","price_dollars":"0.0100","delta_fp":"1.00","side":"yes","ts":"2026-07-01T02:34:18.266808Z","ts_ms":1782873258266}}

{"type":"orderbook_delta","sid":1,"seq":1611,"msg":{"market_ticker":"KXNEXTTEAMNBA-26LJAM-MIA","market_id":"492cb255-91da-4c91-bc9e-f83d090cc6dd","price_dollars":"0.0100","delta_fp":"1.00","side":"yes","ts":"2026-07-01T02:34:18.267416Z","ts_ms":1782873258267}}

{"type":"orderbook_delta","sid":1,"seq":1612,"msg":{"market_ticker":"KXNEXTTEAMNBA-26LJAM-MIA","market_id":"492cb255-91da-4c91-bc9e-f83d090cc6dd","price_dollars":"0.0100","delta_fp":"1.00","side":"yes","ts":"2026-07-01T02:34:18.267872Z","ts_ms":1782873258267}}

{"type":"orderbook_delta","sid":1,"seq":1613,"msg":{"market_ticker":"KXNEXTTEAMNBA-26LJAM-MIA","market_id":"492cb255-91da-4c91-bc9e-f83d090cc6dd","price_dollars":"0.0100","delta_fp":"1.00","side":"yes","ts":"2026-07-01T02:34:18.268356Z","ts_ms":1782873258268}}

{"type":"orderbook_delta","sid":1,"seq":1614,"msg":{"market_ticker":"KXNEXTTEAMNBA-26LJAM-MIA","market_id":"492cb255-91da-4c91-bc9e-f83d090cc6dd","price_dollars":"0.0100","delta_fp":"1.00","side":"yes","ts":"2026-07-01T02:34:18.268936Z","ts_ms":1782873258268}}

{"type":"orderbook_delta","sid":1,"seq":1615,"msg":{"market_ticker":"KXNEXTTEAMNBA-26LJAM-MIA","market_id":"492cb255-91da-4c91-bc9e-f83d090cc6dd","price_dollars":"0.0100","delta_fp":"1.00","side":"yes","ts":"2026-07-01T02:34:18.269503Z","ts_ms":1782873258269}}

{"type":"orderbook_delta","sid":1,"seq":1616,"msg":{"market_ticker":"KXNEXTTEAMNBA-26LJAM-MIA","market_id":"492cb255-91da-4c91-bc9e-f83d090cc6dd","price_dollars":"0.0100","delta_fp":"1.00","side":"yes","ts":"2026-07-01T02:34:18.269955Z","ts_ms":1782873258269}}

{"type":"orderbook_delta","sid":1,"seq":1617,"msg":{"market_ticker":"KXNEXTTEAMNBA-26LJAM-CLE","market_id":"7552b8d4-05de-4e41-84a8-97b0684da4a9","price_dollars":"0.7400","delta_fp":"-1.40","side":"no","ts":"2026-07-01T02:34:18.758445Z","ts_ms":1782873258758}}

{"type":"orderbook_delta","sid":1,"seq":1618,"msg":{"market_ticker":"KXNEXTTEAMNBA-26LJAM-GSW","market_id":"abbbad28-f309-4dd5-af38-2ad7ebf2acc3","price_dollars":"0.5200","delta_fp":"-1.04","side":"no","ts":"2026-07-01T02:34:19.288724Z","ts_ms":1782873259288}}

{"type":"orderbook_delta","sid":1,"seq":1619,"msg":{"market_ticker":"KXNEXTTEAMNBA-26LJAM-GSW","market_id":"abbbad28-f309-4dd5-af38-2ad7ebf2acc3","price_dollars":"0.5200","delta_fp":"-0.95","side":"no","ts":"2026-07-01T02:34:19.555739Z","ts_ms":1782873259555}}

{"type":"orderbook_delta","sid":1,"seq":1620,"msg":{"market_ticker":"KXNEXTTEAMNBA-26LJAM-GSW","market_id":"abbbad28-f309-4dd5-af38-2ad7ebf2acc3","price_dollars":"0.5200","delta_fp":"-1.38","side":"no","ts":"2026-07-01T02:34:20.462529Z","ts_ms":1782873260462}}

{"type":"orderbook_delta","sid":1,"seq":1621,"msg":{"market_ticker":"KXNEXTTEAMNBA-26LJAM-CLE","market_id":"7552b8d4-05de-4e41-84a8-97b0684da4a9","price_dollars":"0.7400","delta_fp":"-2.00","side":"no","ts":"2026-07-01T02:34:21.056715Z","ts_ms":1782873261056}}

{"type":"orderbook_delta","sid":1,"seq":1622,"msg":{"market_ticker":"KXNEXTTEAMNBA-26LJAM-GSW","market_id":"abbbad28-f309-4dd5-af38-2ad7ebf2acc3","price_dollars":"0.5200","delta_fp":"-1.12","side":"no","ts":"2026-07-01T02:34:22.056605Z","ts_ms":1782873262056}}

{"type":"orderbook_delta","sid":1,"seq":1623,"msg":{"market_ticker":"KXNEXTTEAMNBA-26LJAM-GSW","market_id":"abbbad28-f309-4dd5-af38-2ad7ebf2acc3","price_dollars":"0.0100","delta_fp":"1.00","side":"yes","ts":"2026-07-01T02:34:23.922157Z","ts_ms":1782873263922}}

{"type":"orderbook_delta","sid":1,"seq":1624,"msg":{"market_ticker":"KXNEXTTEAMNBA-26LJAM-GSW","market_id":"abbbad28-f309-4dd5-af38-2ad7ebf2acc3","price_dollars":"0.0100","delta_fp":"1.00","side":"yes","ts":"2026-07-01T02:34:23.922718Z","ts_ms":1782873263922}}

{"type":"orderbook_delta","sid":1,"seq":1625,"msg":{"market_ticker":"KXNEXTTEAMNBA-26LJAM-GSW","market_id":"abbbad28-f309-4dd5-af38-2ad7ebf2acc3","price_dollars":"0.0100","delta_fp":"1.00","side":"yes","ts":"2026-07-01T02:34:23.923397Z","ts_ms":1782873263923}}

{"type":"orderbook_delta","sid":1,"seq":1626,"msg":{"market_ticker":"KXNEXTTEAMNBA-26LJAM-GSW","market_id":"abbbad28-f309-4dd5-af38-2ad7ebf2acc3","price_dollars":"0.0100","delta_fp":"1.00","side":"yes","ts":"2026-07-01T02:34:23.924014Z","ts_ms":1782873263924}}

{"type":"orderbook_delta","sid":1,"seq":1627,"msg":{"market_ticker":"KXNEXTTEAMNBA-26LJAM-GSW","market_id":"abbbad28-f309-4dd5-af38-2ad7ebf2acc3","price_dollars":"0.0100","delta_fp":"1.00","side":"yes","ts":"2026-07-01T02:34:23.924698Z","ts_ms":1782873263924}}

{"type":"orderbook_delta","sid":1,"seq":1628,"msg":{"market_ticker":"KXNEXTTEAMNBA-26LJAM-GSW","market_id":"abbbad28-f309-4dd5-af38-2ad7ebf2acc3","price_dollars":"0.0100","delta_fp":"1.00","side":"yes","ts":"2026-07-01T02:34:23.925196Z","ts_ms":1782873263925}}

{"type":"orderbook_delta","sid":1,"seq":1629,"msg":{"market_ticker":"KXNEXTTEAMNBA-26LJAM-GSW","market_id":"abbbad28-f309-4dd5-af38-2ad7ebf2acc3","price_dollars":"0.0100","delta_fp":"1.00","side":"yes","ts":"2026-07-01T02:34:23.926247Z","ts_ms":1782873263926}}

{"type":"orderbook_delta","sid":1,"seq":1630,"msg":{"market_ticker":"KXNEXTTEAMNBA-26LJAM-GSW","market_id":"abbbad28-f309-4dd5-af38-2ad7ebf2acc3","price_dollars":"0.0100","delta_fp":"1.00","side":"yes","ts":"2026-07-01T02:34:23.926923Z","ts_ms":1782873263926}}

{"type":"orderbook_delta","sid":1,"seq":1631,"msg":{"market_ticker":"KXNEXTTEAMNBA-26LJAM-GSW","market_id":"abbbad28-f309-4dd5-af38-2ad7ebf2acc3","price_dollars":"0.0100","delta_fp":"1.00","side":"yes","ts":"2026-07-01T02:34:23.927574Z","ts_ms":1782873263927}}

{"type":"orderbook_delta","sid":1,"seq":1632,"msg":{"market_ticker":"KXNEXTTEAMNBA-26LJAM-GSW","market_id":"abbbad28-f309-4dd5-af38-2ad7ebf2acc3","price_dollars":"0.0100","delta_fp":"1.00","side":"yes","ts":"2026-07-01T02:34:23.928352Z","ts_ms":1782873263928}}

{"type":"orderbook_delta","sid":1,"seq":1633,"msg":{"market_ticker":"KXNEXTTEAMNBA-26LJAM-GSW","market_id":"abbbad28-f309-4dd5-af38-2ad7ebf2acc3","price_dollars":"0.0100","delta_fp":"1.00","side":"yes","ts":"2026-07-01T02:34:23.928861Z","ts_ms":1782873263928}}

{"type":"orderbook_delta","sid":1,"seq":1634,"msg":{"market_ticker":"KXNEXTTEAMNBA-26LJAM-GSW","market_id":"abbbad28-f309-4dd5-af38-2ad7ebf2acc3","price_dollars":"0.0100","delta_fp":"1.00","side":"yes","ts":"2026-07-01T02:34:23.929503Z","ts_ms":1782873263929}}

{"type":"orderbook_delta","sid":1,"seq":1635,"msg":{"market_ticker":"KXNEXTTEAMNBA-26LJAM-GSW","market_id":"abbbad28-f309-4dd5-af38-2ad7ebf2acc3","price_dollars":"0.0100","delta_fp":"1.00","side":"yes","ts":"2026-07-01T02:34:23.930055Z","ts_ms":1782873263930}}

{"type":"orderbook_delta","sid":1,"seq":1636,"msg":{"market_ticker":"KXNEXTTEAMNBA-26LJAM-GSW","market_id":"abbbad28-f309-4dd5-af38-2ad7ebf2acc3","price_dollars":"0.0100","delta_fp":"1.00","side":"yes","ts":"2026-07-01T02:34:23.930618Z","ts_ms":1782873263930}}

{"type":"orderbook_delta","sid":1,"seq":1637,"msg":{"market_ticker":"KXNEXTTEAMNBA-26LJAM-GSW","market_id":"abbbad28-f309-4dd5-af38-2ad7ebf2acc3","price_dollars":"0.0100","delta_fp":"1.00","side":"yes","ts":"2026-07-01T02:34:23.931052Z","ts_ms":1782873263931}}

{"type":"orderbook_delta","sid":1,"seq":1638,"msg":{"market_ticker":"KXNEXTTEAMNBA-26LJAM-GSW","market_id":"abbbad28-f309-4dd5-af38-2ad7ebf2acc3","price_dollars":"0.0100","delta_fp":"1.00","side":"yes","ts":"2026-07-01T02:34:23.931458Z","ts_ms":1782873263931}}

{"type":"orderbook_delta","sid":1,"seq":1639,"msg":{"market_ticker":"KXNEXTTEAMNBA-26LJAM-GSW","market_id":"abbbad28-f309-4dd5-af38-2ad7ebf2acc3","price_dollars":"0.0100","delta_fp":"1.00","side":"yes","ts":"2026-07-01T02:34:23.931924Z","ts_ms":1782873263931}}

{"type":"orderbook_delta","sid":1,"seq":1640,"msg":{"market_ticker":"KXNEXTTEAMNBA-26LJAM-GSW","market_id":"abbbad28-f309-4dd5-af38-2ad7ebf2acc3","price_dollars":"0.0100","delta_fp":"1.00","side":"yes","ts":"2026-07-01T02:34:23.932343Z","ts_ms":1782873263932}}

{"type":"orderbook_delta","sid":1,"seq":1641,"msg":{"market_ticker":"KXNEXTTEAMNBA-26LJAM-GSW","market_id":"abbbad28-f309-4dd5-af38-2ad7ebf2acc3","price_dollars":"0.0100","delta_fp":"1.00","side":"yes","ts":"2026-07-01T02:34:23.932875Z","ts_ms":1782873263932}}

{"type":"orderbook_delta","sid":1,"seq":1642,"msg":{"market_ticker":"KXNEXTTEAMNBA-26LJAM-GSW","market_id":"abbbad28-f309-4dd5-af38-2ad7ebf2acc3","price_dollars":"0.0100","delta_fp":"1.00","side":"yes","ts":"2026-07-01T02:34:23.933367Z","ts_ms":1782873263933}}

{"type":"orderbook_delta","sid":1,"seq":1643,"msg":{"market_ticker":"KXNEXTTEAMNBA-26LJAM-CLE","market_id":"7552b8d4-05de-4e41-84a8-97b0684da4a9","price_dollars":"0.7400","delta_fp":"-2.00","side":"no","ts":"2026-07-01T02:34:24.485634Z","ts_ms":1782873264485}}

{"type":"orderbook_delta","sid":1,"seq":1644,"msg":{"market_ticker":"KXNEXTTEAMNBA-26LJAM-MIA","market_id":"492cb255-91da-4c91-bc9e-f83d090cc6dd","price_dollars":"0.0100","delta_fp":"1.00","side":"yes","ts":"2026-07-01T02:34:25.118358Z","ts_ms":1782873265118}}

{"type":"orderbook_delta","sid":1,"seq":1645,"msg":{"market_ticker":"KXNEXTTEAMNBA-26LJAM-MIA","market_id":"492cb255-91da-4c91-bc9e-f83d090cc6dd","price_dollars":"0.0100","delta_fp":"1.00","side":"yes","ts":"2026-07-01T02:34:25.118741Z","ts_ms":1782873265118}}

{"type":"orderbook_delta","sid":1,"seq":1646,"msg":{"market_ticker":"KXNEXTTEAMNBA-26LJAM-MIA","market_id":"492cb255-91da-4c91-bc9e-f83d090cc6dd","price_dollars":"0.0100","delta_fp":"1.00","side":"yes","ts":"2026-07-01T02:34:25.119052Z","ts_ms":1782873265119}}

{"type":"orderbook_delta","sid":1,"seq":1647,"msg":{"market_ticker":"KXNEXTTEAMNBA-26LJAM-MIA","market_id":"492cb255-91da-4c91-bc9e-f83d090cc6dd","price_dollars":"0.0100","delta_fp":"1.00","side":"yes","ts":"2026-07-01T02:34:25.119411Z","ts_ms":1782873265119}}

{"type":"orderbook_delta","sid":1,"seq":1648,"msg":{"market_ticker":"KXNEXTTEAMNBA-26LJAM-MIA","market_id":"492cb255-91da-4c91-bc9e-f83d090cc6dd","price_dollars":"0.0100","delta_fp":"1.00","side":"yes","ts":"2026-07-01T02:34:25.119705Z","ts_ms":1782873265119}}

{"type":"orderbook_delta","sid":1,"seq":1649,"msg":{"market_ticker":"KXNEXTTEAMNBA-26LJAM-MIA","market_id":"492cb255-91da-4c91-bc9e-f83d090cc6dd","price_dollars":"0.0100","delta_fp":"1.00","side":"yes","ts":"2026-07-01T02:34:25.120001Z","ts_ms":1782873265120}}

{"type":"orderbook_delta","sid":1,"seq":1650,"msg":{"market_ticker":"KXNEXTTEAMNBA-26LJAM-MIA","market_id":"492cb255-91da-4c91-bc9e-f83d090cc6dd","price_dollars":"0.0100","delta_fp":"1.00","side":"yes","ts":"2026-07-01T02:34:25.120304Z","ts_ms":1782873265120}}

{"type":"orderbook_delta","sid":1,"seq":1651,"msg":{"market_ticker":"KXNEXTTEAMNBA-26LJAM-MIA","market_id":"492cb255-91da-4c91-bc9e-f83d090cc6dd","price_dollars":"0.0100","delta_fp":"1.00","side":"yes","ts":"2026-07-01T02:34:25.120657Z","ts_ms":1782873265120}}

{"type":"orderbook_delta","sid":1,"seq":1652,"msg":{"market_ticker":"KXNEXTTEAMNBA-26LJAM-MIA","market_id":"492cb255-91da-4c91-bc9e-f83d090cc6dd","price_dollars":"0.0100","delta_fp":"1.00","side":"yes","ts":"2026-07-01T02:34:25.121025Z","ts_ms":1782873265121}}

{"type":"orderbook_delta","sid":1,"seq":1653,"msg":{"market_ticker":"KXNEXTTEAMNBA-26LJAM-MIA","market_id":"492cb255-91da-4c91-bc9e-f83d090cc6dd","price_dollars":"0.0100","delta_fp":"1.00","side":"yes","ts":"2026-07-01T02:34:25.121463Z","ts_ms":1782873265121}}

{"type":"orderbook_delta","sid":1,"seq":1654,"msg":{"market_ticker":"KXNEXTTEAMNBA-26LJAM-MIA","market_id":"492cb255-91da-4c91-bc9e-f83d090cc6dd","price_dollars":"0.0100","delta_fp":"1.00","side":"yes","ts":"2026-07-01T02:34:25.121779Z","ts_ms":1782873265121}}

{"type":"orderbook_delta","sid":1,"seq":1655,"msg":{"market_ticker":"KXNEXTTEAMNBA-26LJAM-MIA","market_id":"492cb255-91da-4c91-bc9e-f83d090cc6dd","price_dollars":"0.0100","delta_fp":"1.00","side":"yes","ts":"2026-07-01T02:34:25.122102Z","ts_ms":1782873265122}}

{"type":"orderbook_delta","sid":1,"seq":1656,"msg":{"market_ticker":"KXNEXTTEAMNBA-26LJAM-MIA","market_id":"492cb255-91da-4c91-bc9e-f83d090cc6dd","price_dollars":"0.0100","delta_fp":"1.00","side":"yes","ts":"2026-07-01T02:34:25.122444Z","ts_ms":1782873265122}}

{"type":"orderbook_delta","sid":1,"seq":1657,"msg":{"market_ticker":"KXNEXTTEAMNBA-26LJAM-MIA","market_id":"492cb255-91da-4c91-bc9e-f83d090cc6dd","price_dollars":"0.0100","delta_fp":"1.00","side":"yes","ts":"2026-07-01T02:34:25.122717Z","ts_ms":1782873265122}}

{"type":"orderbook_delta","sid":1,"seq":1658,"msg":{"market_ticker":"KXNEXTTEAMNBA-26LJAM-MIA","market_id":"492cb255-91da-4c91-bc9e-f83d090cc6dd","price_dollars":"0.0100","delta_fp":"1.00","side":"yes","ts":"2026-07-01T02:34:25.123132Z","ts_ms":1782873265123}}

{"type":"orderbook_delta","sid":1,"seq":1659,"msg":{"market_ticker":"KXNEXTTEAMNBA-26LJAM-MIA","market_id":"492cb255-91da-4c91-bc9e-f83d090cc6dd","price_dollars":"0.0100","delta_fp":"1.00","side":"yes","ts":"2026-07-01T02:34:25.123407Z","ts_ms":1782873265123}}

{"type":"orderbook_delta","sid":1,"seq":1660,"msg":{"market_ticker":"KXNEXTTEAMNBA-26LJAM-MIA","market_id":"492cb255-91da-4c91-bc9e-f83d090cc6dd","price_dollars":"0.0100","delta_fp":"1.00","side":"yes","ts":"2026-07-01T02:34:25.123799Z","ts_ms":1782873265123}}

{"type":"orderbook_delta","sid":1,"seq":1661,"msg":{"market_ticker":"KXNEXTTEAMNBA-26LJAM-MIA","market_id":"492cb255-91da-4c91-bc9e-f83d090cc6dd","price_dollars":"0.0100","delta_fp":"1.00","side":"yes","ts":"2026-07-01T02:34:25.124124Z","ts_ms":1782873265124}}

{"type":"orderbook_delta","sid":1,"seq":1662,"msg":{"market_ticker":"KXNEXTTEAMNBA-26LJAM-MIA","market_id":"492cb255-91da-4c91-bc9e-f83d090cc6dd","price_dollars":"0.0100","delta_fp":"1.00","side":"yes","ts":"2026-07-01T02:34:25.124473Z","ts_ms":1782873265124}}

{"type":"orderbook_delta","sid":1,"seq":1663,"msg":{"market_ticker":"KXNEXTTEAMNBA-26LJAM-MIA","market_id":"492cb255-91da-4c91-bc9e-f83d090cc6dd","price_dollars":"0.0100","delta_fp":"1.00","side":"yes","ts":"2026-07-01T02:34:25.124834Z","ts_ms":1782873265124}}

{"type":"orderbook_delta","sid":1,"seq":1664,"msg":{"market_ticker":"KXNEXTTEAMNBA-26LJAM-GSW","market_id":"abbbad28-f309-4dd5-af38-2ad7ebf2acc3","price_dollars":"0.5200","delta_fp":"-1.86","side":"no","ts":"2026-07-01T02:34:25.371226Z","ts_ms":1782873265371}}

{"type":"orderbook_delta","sid":1,"seq":1665,"msg":{"market_ticker":"KXNEXTTEAMNBA-26LJAM-GSW","market_id":"abbbad28-f309-4dd5-af38-2ad7ebf2acc3","price_dollars":"0.5200","delta_fp":"-0.17","side":"no","ts":"2026-07-01T02:34:26.171549Z","ts_ms":1782873266171}}

{"type":"orderbook_delta","sid":1,"seq":1666,"msg":{"market_ticker":"KXNEXTTEAMNBA-26LJAM-CLE","market_id":"7552b8d4-05de-4e41-84a8-97b0684da4a9","price_dollars":"0.7400","delta_fp":"-1.43","side":"no","ts":"2026-07-01T02:34:26.888166Z","ts_ms":1782873266888}}

{"type":"orderbook_delta","sid":1,"seq":1667,"msg":{"market_ticker":"KXNEXTTEAMNBA-26LJAM-CLE","market_id":"7552b8d4-05de-4e41-84a8-97b0684da4a9","price_dollars":"0.7400","delta_fp":"-1.14","side":"no","ts":"2026-07-01T02:34:28.577411Z","ts_ms":1782873268577}}

{"type":"orderbook_delta","sid":1,"seq":1668,"msg":{"market_ticker":"KXNEXTTEAMNBA-26LJAM-MIA","market_id":"492cb255-91da-4c91-bc9e-f83d090cc6dd","price_dollars":"0.8300","delta_fp":"-0.51","side":"no","ts":"2026-07-01T02:34:28.673984Z","ts_ms":1782873268673}}

{"type":"orderbook_delta","sid":1,"seq":1669,"msg":{"market_ticker":"KXNEXTTEAMNBA-26LJAM-CLE","market_id":"7552b8d4-05de-4e41-84a8-97b0684da4a9","price_dollars":"0.7400","delta_fp":"-0.72","side":"no","ts":"2026-07-01T02:34:28.675825Z","ts_ms":1782873268675}}

{"type":"orderbook_delta","sid":1,"seq":1670,"msg":{"market_ticker":"KXNEXTTEAMNBA-26LJAM-CLE","market_id":"7552b8d4-05de-4e41-84a8-97b0684da4a9","price_dollars":"0.7400","delta_fp":"-1.03","side":"no","ts":"2026-07-01T02:34:29.384095Z","ts_ms":1782873269384}}

{"type":"orderbook_delta","sid":1,"seq":1671,"msg":{"market_ticker":"KXNEXTTEAMNBA-26LJAM-GSW","market_id":"abbbad28-f309-4dd5-af38-2ad7ebf2acc3","price_dollars":"0.5200","delta_fp":"-0.55","side":"no","ts":"2026-07-01T02:34:29.473025Z","ts_ms":1782873269473}}

{"type":"orderbook_delta","sid":1,"seq":1672,"msg":{"market_ticker":"KXNEXTTEAMNBA-26LJAM-CLE","market_id":"7552b8d4-05de-4e41-84a8-97b0684da4a9","price_dollars":"0.7400","delta_fp":"-1.08","side":"no","ts":"2026-07-01T02:34:30.038432Z","ts_ms":1782873270038}}

{"type":"orderbook_delta","sid":1,"seq":1673,"msg":{"market_ticker":"KXNEXTTEAMNBA-26LJAM-GSW","market_id":"abbbad28-f309-4dd5-af38-2ad7ebf2acc3","price_dollars":"0.0100","delta_fp":"1.00","side":"yes","ts":"2026-07-01T02:34:30.231034Z","ts_ms":1782873270231}}

{"type":"orderbook_delta","sid":1,"seq":1674,"msg":{"market_ticker":"KXNEXTTEAMNBA-26LJAM-GSW","market_id":"abbbad28-f309-4dd5-af38-2ad7ebf2acc3","price_dollars":"0.0100","delta_fp":"1.00","side":"yes","ts":"2026-07-01T02:34:30.231781Z","ts_ms":1782873270231}}

{"type":"orderbook_delta","sid":1,"seq":1675,"msg":{"market_ticker":"KXNEXTTEAMNBA-26LJAM-GSW","market_id":"abbbad28-f309-4dd5-af38-2ad7ebf2acc3","price_dollars":"0.0100","delta_fp":"1.00","side":"yes","ts":"2026-07-01T02:34:30.232431Z","ts_ms":1782873270232}}

{"type":"orderbook_delta","sid":1,"seq":1676,"msg":{"market_ticker":"KXNEXTTEAMNBA-26LJAM-GSW","market_id":"abbbad28-f309-4dd5-af38-2ad7ebf2acc3","price_dollars":"0.0100","delta_fp":"1.00","side":"yes","ts":"2026-07-01T02:34:30.233362Z","ts_ms":1782873270233}}

{"type":"orderbook_delta","sid":1,"seq":1677,"msg":{"market_ticker":"KXNEXTTEAMNBA-26LJAM-GSW","market_id":"abbbad28-f309-4dd5-af38-2ad7ebf2acc3","price_dollars":"0.0100","delta_fp":"1.00","side":"yes","ts":"2026-07-01T02:34:30.234024Z","ts_ms":1782873270234}}

{"type":"orderbook_delta","sid":1,"seq":1678,"msg":{"market_ticker":"KXNEXTTEAMNBA-26LJAM-GSW","market_id":"abbbad28-f309-4dd5-af38-2ad7ebf2acc3","price_dollars":"0.0100","delta_fp":"1.00","side":"yes","ts":"2026-07-01T02:34:30.234726Z","ts_ms":1782873270234}}

{"type":"orderbook_delta","sid":1,"seq":1679,"msg":{"market_ticker":"KXNEXTTEAMNBA-26LJAM-GSW","market_id":"abbbad28-f309-4dd5-af38-2ad7ebf2acc3","price_dollars":"0.0100","delta_fp":"1.00","side":"yes","ts":"2026-07-01T02:34:30.235511Z","ts_ms":1782873270235}}

{"type":"orderbook_delta","sid":1,"seq":1680,"msg":{"market_ticker":"KXNEXTTEAMNBA-26LJAM-GSW","market_id":"abbbad28-f309-4dd5-af38-2ad7ebf2acc3","price_dollars":"0.0100","delta_fp":"1.00","side":"yes","ts":"2026-07-01T02:34:30.236138Z","ts_ms":1782873270236}}

{"type":"orderbook_delta","sid":1,"seq":1681,"msg":{"market_ticker":"KXNEXTTEAMNBA-26LJAM-GSW","market_id":"abbbad28-f309-4dd5-af38-2ad7ebf2acc3","price_dollars":"0.0100","delta_fp":"1.00","side":"yes","ts":"2026-07-01T02:34:30.236698Z","ts_ms":1782873270236}}

{"type":"orderbook_delta","sid":1,"seq":1682,"msg":{"market_ticker":"KXNEXTTEAMNBA-26LJAM-GSW","market_id":"abbbad28-f309-4dd5-af38-2ad7ebf2acc3","price_dollars":"0.0100","delta_fp":"1.00","side":"yes","ts":"2026-07-01T02:34:30.237418Z","ts_ms":1782873270237}}

{"type":"orderbook_delta","sid":1,"seq":1683,"msg":{"market_ticker":"KXNEXTTEAMNBA-26LJAM-GSW","market_id":"abbbad28-f309-4dd5-af38-2ad7ebf2acc3","price_dollars":"0.0100","delta_fp":"1.00","side":"yes","ts":"2026-07-01T02:34:30.238109Z","ts_ms":1782873270238}}

{"type":"orderbook_delta","sid":1,"seq":1684,"msg":{"market_ticker":"KXNEXTTEAMNBA-26LJAM-GSW","market_id":"abbbad28-f309-4dd5-af38-2ad7ebf2acc3","price_dollars":"0.0100","delta_fp":"1.00","side":"yes","ts":"2026-07-01T02:34:30.238636Z","ts_ms":1782873270238}}

{"type":"orderbook_delta","sid":1,"seq":1685,"msg":{"market_ticker":"KXNEXTTEAMNBA-26LJAM-GSW","market_id":"abbbad28-f309-4dd5-af38-2ad7ebf2acc3","price_dollars":"0.0100","delta_fp":"1.00","side":"yes","ts":"2026-07-01T02:34:30.239162Z","ts_ms":1782873270239}}

{"type":"orderbook_delta","sid":1,"seq":1686,"msg":{"market_ticker":"KXNEXTTEAMNBA-26LJAM-GSW","market_id":"abbbad28-f309-4dd5-af38-2ad7ebf2acc3","price_dollars":"0.0100","delta_fp":"1.00","side":"yes","ts":"2026-07-01T02:34:30.239708Z","ts_ms":1782873270239}}

{"type":"orderbook_delta","sid":1,"seq":1687,"msg":{"market_ticker":"KXNEXTTEAMNBA-26LJAM-GSW","market_id":"abbbad28-f309-4dd5-af38-2ad7ebf2acc3","price_dollars":"0.0100","delta_fp":"1.00","side":"yes","ts":"2026-07-01T02:34:30.240208Z","ts_ms":1782873270240}}

{"type":"orderbook_delta","sid":1,"seq":1688,"msg":{"market_ticker":"KXNEXTTEAMNBA-26LJAM-GSW","market_id":"abbbad28-f309-4dd5-af38-2ad7ebf2acc3","price_dollars":"0.0100","delta_fp":"1.00","side":"yes","ts":"2026-07-01T02:34:30.240658Z","ts_ms":1782873270240}}

{"type":"orderbook_delta","sid":1,"seq":1689,"msg":{"market_ticker":"KXNEXTTEAMNBA-26LJAM-GSW","market_id":"abbbad28-f309-4dd5-af38-2ad7ebf2acc3","price_dollars":"0.0100","delta_fp":"1.00","side":"yes","ts":"2026-07-01T02:34:30.241222Z","ts_ms":1782873270241}}

{"type":"orderbook_delta","sid":1,"seq":1690,"msg":{"market_ticker":"KXNEXTTEAMNBA-26LJAM-GSW","market_id":"abbbad28-f309-4dd5-af38-2ad7ebf2acc3","price_dollars":"0.0100","delta_fp":"1.00","side":"yes","ts":"2026-07-01T02:34:30.241741Z","ts_ms":1782873270241}}

{"type":"orderbook_delta","sid":1,"seq":1691,"msg":{"market_ticker":"KXNEXTTEAMNBA-26LJAM-GSW","market_id":"abbbad28-f309-4dd5-af38-2ad7ebf2acc3","price_dollars":"0.0100","delta_fp":"1.00","side":"yes","ts":"2026-07-01T02:34:30.242149Z","ts_ms":1782873270242}}

{"type":"orderbook_delta","sid":1,"seq":1692,"msg":{"market_ticker":"KXNEXTTEAMNBA-26LJAM-GSW","market_id":"abbbad28-f309-4dd5-af38-2ad7ebf2acc3","price_dollars":"0.0100","delta_fp":"1.00","side":"yes","ts":"2026-07-01T02:34:30.242623Z","ts_ms":1782873270242}}

{"type":"orderbook_delta","sid":1,"seq":1693,"msg":{"market_ticker":"KXNEXTTEAMNBA-26LJAM-GSW","market_id":"abbbad28-f309-4dd5-af38-2ad7ebf2acc3","price_dollars":"0.5200","delta_fp":"-1.76","side":"no","ts":"2026-07-01T02:34:30.799778Z","ts_ms":1782873270799}}

{"type":"orderbook_delta","sid":1,"seq":1694,"msg":{"market_ticker":"KXNEXTTEAMNBA-26LJAM-MIA","market_id":"492cb255-91da-4c91-bc9e-f83d090cc6dd","price_dollars":"0.8300","delta_fp":"-0.38","side":"no","ts":"2026-07-01T02:34:31.05933Z","ts_ms":1782873271059}}

{"type":"orderbook_delta","sid":1,"seq":1695,"msg":{"market_ticker":"KXNEXTTEAMNBA-26LJAM-MIA","market_id":"492cb255-91da-4c91-bc9e-f83d090cc6dd","price_dollars":"0.0100","delta_fp":"1.00","side":"yes","ts":"2026-07-01T02:34:31.442785Z","ts_ms":1782873271442}}

{"type":"orderbook_delta","sid":1,"seq":1696,"msg":{"market_ticker":"KXNEXTTEAMNBA-26LJAM-MIA","market_id":"492cb255-91da-4c91-bc9e-f83d090cc6dd","price_dollars":"0.0100","delta_fp":"1.00","side":"yes","ts":"2026-07-01T02:34:31.443379Z","ts_ms":1782873271443}}

{"type":"orderbook_delta","sid":1,"seq":1697,"msg":{"market_ticker":"KXNEXTTEAMNBA-26LJAM-MIA","market_id":"492cb255-91da-4c91-bc9e-f83d090cc6dd","price_dollars":"0.0100","delta_fp":"1.00","side":"yes","ts":"2026-07-01T02:34:31.444003Z","ts_ms":1782873271444}}

{"type":"orderbook_delta","sid":1,"seq":1698,"msg":{"market_ticker":"KXNEXTTEAMNBA-26LJAM-MIA","market_id":"492cb255-91da-4c91-bc9e-f83d090cc6dd","price_dollars":"0.0100","delta_fp":"1.00","side":"yes","ts":"2026-07-01T02:34:31.444444Z","ts_ms":1782873271444}}

{"type":"orderbook_delta","sid":1,"seq":1699,"msg":{"market_ticker":"KXNEXTTEAMNBA-26LJAM-MIA","market_id":"492cb255-91da-4c91-bc9e-f83d090cc6dd","price_dollars":"0.0100","delta_fp":"1.00","side":"yes","ts":"2026-07-01T02:34:31.445064Z","ts_ms":1782873271445}}

{"type":"orderbook_delta","sid":1,"seq":1700,"msg":{"market_ticker":"KXNEXTTEAMNBA-26LJAM-MIA","market_id":"492cb255-91da-4c91-bc9e-f83d090cc6dd","price_dollars":"0.0100","delta_fp":"1.00","side":"yes","ts":"2026-07-01T02:34:31.445493Z","ts_ms":1782873271445}}

{"type":"orderbook_delta","sid":1,"seq":1701,"msg":{"market_ticker":"KXNEXTTEAMNBA-26LJAM-MIA","market_id":"492cb255-91da-4c91-bc9e-f83d090cc6dd","price_dollars":"0.0100","delta_fp":"1.00","side":"yes","ts":"2026-07-01T02:34:31.446069Z","ts_ms":1782873271446}}

{"type":"orderbook_delta","sid":1,"seq":1702,"msg":{"market_ticker":"KXNEXTTEAMNBA-26LJAM-MIA","market_id":"492cb255-91da-4c91-bc9e-f83d090cc6dd","price_dollars":"0.0100","delta_fp":"1.00","side":"yes","ts":"2026-07-01T02:34:31.446378Z","ts_ms":1782873271446}}

{"type":"orderbook_delta","sid":1,"seq":1703,"msg":{"market_ticker":"KXNEXTTEAMNBA-26LJAM-MIA","market_id":"492cb255-91da-4c91-bc9e-f83d090cc6dd","price_dollars":"0.0100","delta_fp":"1.00","side":"yes","ts":"2026-07-01T02:34:31.446851Z","ts_ms":1782873271446}}

{"type":"orderbook_delta","sid":1,"seq":1704,"msg":{"market_ticker":"KXNEXTTEAMNBA-26LJAM-MIA","market_id":"492cb255-91da-4c91-bc9e-f83d090cc6dd","price_dollars":"0.0100","delta_fp":"1.00","side":"yes","ts":"2026-07-01T02:34:31.447418Z","ts_ms":1782873271447}}

{"type":"orderbook_delta","sid":1,"seq":1705,"msg":{"market_ticker":"KXNEXTTEAMNBA-26LJAM-MIA","market_id":"492cb255-91da-4c91-bc9e-f83d090cc6dd","price_dollars":"0.0100","delta_fp":"1.00","side":"yes","ts":"2026-07-01T02:34:31.448021Z","ts_ms":1782873271448}}

{"type":"orderbook_delta","sid":1,"seq":1706,"msg":{"market_ticker":"KXNEXTTEAMNBA-26LJAM-MIA","market_id":"492cb255-91da-4c91-bc9e-f83d090cc6dd","price_dollars":"0.0100","delta_fp":"1.00","side":"yes","ts":"2026-07-01T02:34:31.448614Z","ts_ms":1782873271448}}

{"type":"orderbook_delta","sid":1,"seq":1707,"msg":{"market_ticker":"KXNEXTTEAMNBA-26LJAM-MIA","market_id":"492cb255-91da-4c91-bc9e-f83d090cc6dd","price_dollars":"0.0100","delta_fp":"1.00","side":"yes","ts":"2026-07-01T02:34:31.449306Z","ts_ms":1782873271449}}

{"type":"orderbook_delta","sid":1,"seq":1708,"msg":{"market_ticker":"KXNEXTTEAMNBA-26LJAM-MIA","market_id":"492cb255-91da-4c91-bc9e-f83d090cc6dd","price_dollars":"0.0100","delta_fp":"1.00","side":"yes","ts":"2026-07-01T02:34:31.449621Z","ts_ms":1782873271449}}

{"type":"orderbook_delta","sid":1,"seq":1709,"msg":{"market_ticker":"KXNEXTTEAMNBA-26LJAM-MIA","market_id":"492cb255-91da-4c91-bc9e-f83d090cc6dd","price_dollars":"0.0100","delta_fp":"1.00","side":"yes","ts":"2026-07-01T02:34:31.450037Z","ts_ms":1782873271450}}

{"type":"orderbook_delta","sid":1,"seq":1710,"msg":{"market_ticker":"KXNEXTTEAMNBA-26LJAM-MIA","market_id":"492cb255-91da-4c91-bc9e-f83d090cc6dd","price_dollars":"0.0100","delta_fp":"1.00","side":"yes","ts":"2026-07-01T02:34:31.450529Z","ts_ms":1782873271450}}

{"type":"orderbook_delta","sid":1,"seq":1711,"msg":{"market_ticker":"KXNEXTTEAMNBA-26LJAM-MIA","market_id":"492cb255-91da-4c91-bc9e-f83d090cc6dd","price_dollars":"0.0100","delta_fp":"1.00","side":"yes","ts":"2026-07-01T02:34:31.450943Z","ts_ms":1782873271450}}

{"type":"orderbook_delta","sid":1,"seq":1712,"msg":{"market_ticker":"KXNEXTTEAMNBA-26LJAM-MIA","market_id":"492cb255-91da-4c91-bc9e-f83d090cc6dd","price_dollars":"0.0100","delta_fp":"1.00","side":"yes","ts":"2026-07-01T02:34:31.451265Z","ts_ms":1782873271451}}

{"type":"orderbook_delta","sid":1,"seq":1713,"msg":{"market_ticker":"KXNEXTTEAMNBA-26LJAM-MIA","market_id":"492cb255-91da-4c91-bc9e-f83d090cc6dd","price_dollars":"0.0100","delta_fp":"1.00","side":"yes","ts":"2026-07-01T02:34:31.451683Z","ts_ms":1782873271451}}

{"type":"orderbook_delta","sid":1,"seq":1714,"msg":{"market_ticker":"KXNEXTTEAMNBA-26LJAM-MIA","market_id":"492cb255-91da-4c91-bc9e-f83d090cc6dd","price_dollars":"0.0100","delta_fp":"1.00","side":"yes","ts":"2026-07-01T02:34:31.452104Z","ts_ms":1782873271452}}

{"type":"orderbook_delta","sid":1,"seq":1715,"msg":{"market_ticker":"KXNEXTTEAMNBA-26LJAM-GSW","market_id":"abbbad28-f309-4dd5-af38-2ad7ebf2acc3","price_dollars":"0.5200","delta_fp":"-1.39","side":"no","ts":"2026-07-01T02:34:31.764506Z","ts_ms":1782873271764}}

{"type":"orderbook_delta","sid":1,"seq":1716,"msg":{"market_ticker":"KXNEXTTEAMNBA-26LJAM-CLE","market_id":"7552b8d4-05de-4e41-84a8-97b0684da4a9","price_dollars":"0.7400","delta_fp":"-0.40","side":"no","ts":"2026-07-01T02:34:31.777805Z","ts_ms":1782873271777}}

{"type":"orderbook_delta","sid":1,"seq":1717,"msg":{"market_ticker":"KXNEXTTEAMNBA-26LJAM-GSW","market_id":"abbbad28-f309-4dd5-af38-2ad7ebf2acc3","price_dollars":"0.5200","delta_fp":"-0.65","side":"no","ts":"2026-07-01T02:34:31.873516Z","ts_ms":1782873271873}}

{"type":"orderbook_delta","sid":1,"seq":1718,"msg":{"market_ticker":"KXNEXTTEAMNBA-26LJAM-GSW","market_id":"abbbad28-f309-4dd5-af38-2ad7ebf2acc3","price_dollars":"0.0100","delta_fp":"-1.00","side":"yes","ts":"2026-07-01T02:34:32.065207Z","ts_ms":1782873272065}}

{"type":"orderbook_delta","sid":1,"seq":1719,"msg":{"market_ticker":"KXNEXTTEAMNBA-26LJAM-GSW","market_id":"abbbad28-f309-4dd5-af38-2ad7ebf2acc3","price_dollars":"0.0100","delta_fp":"-1.00","side":"yes","ts":"2026-07-01T02:34:32.066029Z","ts_ms":1782873272066}}

{"type":"orderbook_delta","sid":1,"seq":1720,"msg":{"market_ticker":"KXNEXTTEAMNBA-26LJAM-GSW","market_id":"abbbad28-f309-4dd5-af38-2ad7ebf2acc3","price_dollars":"0.0100","delta_fp":"-1.00","side":"yes","ts":"2026-07-01T02:34:32.066671Z","ts_ms":1782873272066}}

{"type":"orderbook_delta","sid":1,"seq":1721,"msg":{"market_ticker":"KXNEXTTEAMNBA-26LJAM-GSW","market_id":"abbbad28-f309-4dd5-af38-2ad7ebf2acc3","price_dollars":"0.0100","delta_fp":"-1.00","side":"yes","ts":"2026-07-01T02:34:32.067383Z","ts_ms":1782873272067}}

{"type":"orderbook_delta","sid":1,"seq":1722,"msg":{"market_ticker":"KXNEXTTEAMNBA-26LJAM-GSW","market_id":"abbbad28-f309-4dd5-af38-2ad7ebf2acc3","price_dollars":"0.0100","delta_fp":"-1.00","side":"yes","ts":"2026-07-01T02:34:32.06805Z","ts_ms":1782873272068}}

{"type":"orderbook_delta","sid":1,"seq":1723,"msg":{"market_ticker":"KXNEXTTEAMNBA-26LJAM-GSW","market_id":"abbbad28-f309-4dd5-af38-2ad7ebf2acc3","price_dollars":"0.0100","delta_fp":"-1.00","side":"yes","ts":"2026-07-01T02:34:32.06868Z","ts_ms":1782873272068}}

{"type":"orderbook_delta","sid":1,"seq":1724,"msg":{"market_ticker":"KXNEXTTEAMNBA-26LJAM-GSW","market_id":"abbbad28-f309-4dd5-af38-2ad7ebf2acc3","price_dollars":"0.0100","delta_fp":"-1.00","side":"yes","ts":"2026-07-01T02:34:32.069517Z","ts_ms":1782873272069}}

{"type":"orderbook_delta","sid":1,"seq":1725,"msg":{"market_ticker":"KXNEXTTEAMNBA-26LJAM-GSW","market_id":"abbbad28-f309-4dd5-af38-2ad7ebf2acc3","price_dollars":"0.0100","delta_fp":"-1.00","side":"yes","ts":"2026-07-01T02:34:32.07042Z","ts_ms":1782873272070}}

{"type":"orderbook_delta","sid":1,"seq":1726,"msg":{"market_ticker":"KXNEXTTEAMNBA-26LJAM-GSW","market_id":"abbbad28-f309-4dd5-af38-2ad7ebf2acc3","price_dollars":"0.0100","delta_fp":"-1.00","side":"yes","ts":"2026-07-01T02:34:32.071463Z","ts_ms":1782873272071}}

{"type":"orderbook_delta","sid":1,"seq":1727,"msg":{"market_ticker":"KXNEXTTEAMNBA-26LJAM-GSW","market_id":"abbbad28-f309-4dd5-af38-2ad7ebf2acc3","price_dollars":"0.0100","delta_fp":"-1.00","side":"yes","ts":"2026-07-01T02:34:32.072244Z","ts_ms":1782873272072}}

{"type":"orderbook_delta","sid":1,"seq":1728,"msg":{"market_ticker":"KXNEXTTEAMNBA-26LJAM-GSW","market_id":"abbbad28-f309-4dd5-af38-2ad7ebf2acc3","price_dollars":"0.0100","delta_fp":"-1.00","side":"yes","ts":"2026-07-01T02:34:32.073016Z","ts_ms":1782873272073}}

{"type":"orderbook_delta","sid":1,"seq":1729,"msg":{"market_ticker":"KXNEXTTEAMNBA-26LJAM-GSW","market_id":"abbbad28-f309-4dd5-af38-2ad7ebf2acc3","price_dollars":"0.0100","delta_fp":"-1.00","side":"yes","ts":"2026-07-01T02:34:32.073837Z","ts_ms":1782873272073}}

{"type":"orderbook_delta","sid":1,"seq":1730,"msg":{"market_ticker":"KXNEXTTEAMNBA-26LJAM-GSW","market_id":"abbbad28-f309-4dd5-af38-2ad7ebf2acc3","price_dollars":"0.0100","delta_fp":"-1.00","side":"yes","ts":"2026-07-01T02:34:32.074516Z","ts_ms":1782873272074}}

{"type":"orderbook_delta","sid":1,"seq":1731,"msg":{"market_ticker":"KXNEXTTEAMNBA-26LJAM-GSW","market_id":"abbbad28-f309-4dd5-af38-2ad7ebf2acc3","price_dollars":"0.0100","delta_fp":"-1.00","side":"yes","ts":"2026-07-01T02:34:32.075033Z","ts_ms":1782873272075}}

{"type":"orderbook_delta","sid":1,"seq":1732,"msg":{"market_ticker":"KXNEXTTEAMNBA-26LJAM-GSW","market_id":"abbbad28-f309-4dd5-af38-2ad7ebf2acc3","price_dollars":"0.0100","delta_fp":"-1.00","side":"yes","ts":"2026-07-01T02:34:32.075466Z","ts_ms":1782873272075}}

{"type":"orderbook_delta","sid":1,"seq":1733,"msg":{"market_ticker":"KXNEXTTEAMNBA-26LJAM-GSW","market_id":"abbbad28-f309-4dd5-af38-2ad7ebf2acc3","price_dollars":"0.0100","delta_fp":"-1.00","side":"yes","ts":"2026-07-01T02:34:32.075898Z","ts_ms":1782873272075}}

{"type":"orderbook_delta","sid":1,"seq":1734,"msg":{"market_ticker":"KXNEXTTEAMNBA-26LJAM-GSW","market_id":"abbbad28-f309-4dd5-af38-2ad7ebf2acc3","price_dollars":"0.0100","delta_fp":"-1.00","side":"yes","ts":"2026-07-01T02:34:32.076202Z","ts_ms":1782873272076}}

{"type":"orderbook_delta","sid":1,"seq":1735,"msg":{"market_ticker":"KXNEXTTEAMNBA-26LJAM-GSW","market_id":"abbbad28-f309-4dd5-af38-2ad7ebf2acc3","price_dollars":"0.0100","delta_fp":"-1.00","side":"yes","ts":"2026-07-01T02:34:32.076612Z","ts_ms":1782873272076}}

{"type":"orderbook_delta","sid":1,"seq":1736,"msg":{"market_ticker":"KXNEXTTEAMNBA-26LJAM-GSW","market_id":"abbbad28-f309-4dd5-af38-2ad7ebf2acc3","price_dollars":"0.0100","delta_fp":"-1.00","side":"yes","ts":"2026-07-01T02:34:32.07699Z","ts_ms":1782873272076}}

{"type":"orderbook_delta","sid":1,"seq":1737,"msg":{"market_ticker":"KXNEXTTEAMNBA-26LJAM-GSW","market_id":"abbbad28-f309-4dd5-af38-2ad7ebf2acc3","price_dollars":"0.0100","delta_fp":"-1.00","side":"yes","ts":"2026-07-01T02:34:32.077325Z","ts_ms":1782873272077}}

{"type":"orderbook_delta","sid":1,"seq":1738,"msg":{"market_ticker":"KXNEXTTEAMNBA-26LJAM-GSW","market_id":"abbbad28-f309-4dd5-af38-2ad7ebf2acc3","price_dollars":"0.5200","delta_fp":"-0.76","side":"no","ts":"2026-07-01T02:34:33.390587Z","ts_ms":1782873273390}}

{"type":"orderbook_delta","sid":1,"seq":1739,"msg":{"market_ticker":"KXNEXTTEAMNBA-26LJAM-MIA","market_id":"492cb255-91da-4c91-bc9e-f83d090cc6dd","price_dollars":"0.8300","delta_fp":"-0.77","side":"no","ts":"2026-07-01T02:34:34.164799Z","ts_ms":1782873274164}}

{"type":"orderbook_delta","sid":1,"seq":1740,"msg":{"market_ticker":"KXNEXTTEAMNBA-26LJAM-MIA","market_id":"492cb255-91da-4c91-bc9e-f83d090cc6dd","price_dollars":"0.8300","delta_fp":"-0.61","side":"no","ts":"2026-07-01T02:34:34.170462Z","ts_ms":1782873274170}}

{"type":"orderbook_delta","sid":1,"seq":1741,"msg":{"market_ticker":"KXNEXTTEAMNBA-26LJAM-MIA","market_id":"492cb255-91da-4c91-bc9e-f83d090cc6dd","price_dollars":"0.8300","delta_fp":"-0.40","side":"no","ts":"2026-07-01T02:34:35.066547Z","ts_ms":1782873275066}}

{"type":"orderbook_delta","sid":1,"seq":1742,"msg":{"market_ticker":"KXNEXTTEAMNBA-26LJAM-GSW","market_id":"abbbad28-f309-4dd5-af38-2ad7ebf2acc3","price_dollars":"0.0100","delta_fp":"1.00","side":"yes","ts":"2026-07-01T02:34:36.442306Z","ts_ms":1782873276442}}

{"type":"orderbook_delta","sid":1,"seq":1743,"msg":{"market_ticker":"KXNEXTTEAMNBA-26LJAM-GSW","market_id":"abbbad28-f309-4dd5-af38-2ad7ebf2acc3","price_dollars":"0.0100","delta_fp":"1.00","side":"yes","ts":"2026-07-01T02:34:36.442911Z","ts_ms":1782873276442}}

{"type":"orderbook_delta","sid":1,"seq":1744,"msg":{"market_ticker":"KXNEXTTEAMNBA-26LJAM-GSW","market_id":"abbbad28-f309-4dd5-af38-2ad7ebf2acc3","price_dollars":"0.0100","delta_fp":"1.00","side":"yes","ts":"2026-07-01T02:34:36.44362Z","ts_ms":1782873276443}}

{"type":"orderbook_delta","sid":1,"seq":1745,"msg":{"market_ticker":"KXNEXTTEAMNBA-26LJAM-GSW","market_id":"abbbad28-f309-4dd5-af38-2ad7ebf2acc3","price_dollars":"0.0100","delta_fp":"1.00","side":"yes","ts":"2026-07-01T02:34:36.444468Z","ts_ms":1782873276444}}

{"type":"orderbook_delta","sid":1,"seq":1746,"msg":{"market_ticker":"KXNEXTTEAMNBA-26LJAM-GSW","market_id":"abbbad28-f309-4dd5-af38-2ad7ebf2acc3","price_dollars":"0.0100","delta_fp":"1.00","side":"yes","ts":"2026-07-01T02:34:36.445271Z","ts_ms":1782873276445}}

{"type":"orderbook_delta","sid":1,"seq":1747,"msg":{"market_ticker":"KXNEXTTEAMNBA-26LJAM-GSW","market_id":"abbbad28-f309-4dd5-af38-2ad7ebf2acc3","price_dollars":"0.0100","delta_fp":"1.00","side":"yes","ts":"2026-07-01T02:34:36.446033Z","ts_ms":1782873276446}}

{"type":"orderbook_delta","sid":1,"seq":1748,"msg":{"market_ticker":"KXNEXTTEAMNBA-26LJAM-GSW","market_id":"abbbad28-f309-4dd5-af38-2ad7ebf2acc3","price_dollars":"0.0100","delta_fp":"1.00","side":"yes","ts":"2026-07-01T02:34:36.446877Z","ts_ms":1782873276446}}

{"type":"orderbook_delta","sid":1,"seq":1749,"msg":{"market_ticker":"KXNEXTTEAMNBA-26LJAM-GSW","market_id":"abbbad28-f309-4dd5-af38-2ad7ebf2acc3","price_dollars":"0.0100","delta_fp":"1.00","side":"yes","ts":"2026-07-01T02:34:36.447966Z","ts_ms":1782873276447}}

{"type":"orderbook_delta","sid":1,"seq":1750,"msg":{"market_ticker":"KXNEXTTEAMNBA-26LJAM-GSW","market_id":"abbbad28-f309-4dd5-af38-2ad7ebf2acc3","price_dollars":"0.0100","delta_fp":"1.00","side":"yes","ts":"2026-07-01T02:34:36.449036Z","ts_ms":1782873276449}}

{"type":"orderbook_delta","sid":1,"seq":1751,"msg":{"market_ticker":"KXNEXTTEAMNBA-26LJAM-GSW","market_id":"abbbad28-f309-4dd5-af38-2ad7ebf2acc3","price_dollars":"0.0100","delta_fp":"1.00","side":"yes","ts":"2026-07-01T02:34:36.449767Z","ts_ms":1782873276449}}

{"type":"orderbook_delta","sid":1,"seq":1752,"msg":{"market_ticker":"KXNEXTTEAMNBA-26LJAM-GSW","market_id":"abbbad28-f309-4dd5-af38-2ad7ebf2acc3","price_dollars":"0.0100","delta_fp":"1.00","side":"yes","ts":"2026-07-01T02:34:36.450665Z","ts_ms":1782873276450}}

{"type":"orderbook_delta","sid":1,"seq":1753,"msg":{"market_ticker":"KXNEXTTEAMNBA-26LJAM-GSW","market_id":"abbbad28-f309-4dd5-af38-2ad7ebf2acc3","price_dollars":"0.0100","delta_fp":"1.00","side":"yes","ts":"2026-07-01T02:34:36.451421Z","ts_ms":1782873276451}}

{"type":"orderbook_delta","sid":1,"seq":1754,"msg":{"market_ticker":"KXNEXTTEAMNBA-26LJAM-GSW","market_id":"abbbad28-f309-4dd5-af38-2ad7ebf2acc3","price_dollars":"0.0100","delta_fp":"1.00","side":"yes","ts":"2026-07-01T02:34:36.452049Z","ts_ms":1782873276452}}

{"type":"orderbook_delta","sid":1,"seq":1755,"msg":{"market_ticker":"KXNEXTTEAMNBA-26LJAM-GSW","market_id":"abbbad28-f309-4dd5-af38-2ad7ebf2acc3","price_dollars":"0.0100","delta_fp":"1.00","side":"yes","ts":"2026-07-01T02:34:36.452645Z","ts_ms":1782873276452}}

{"type":"orderbook_delta","sid":1,"seq":1756,"msg":{"market_ticker":"KXNEXTTEAMNBA-26LJAM-GSW","market_id":"abbbad28-f309-4dd5-af38-2ad7ebf2acc3","price_dollars":"0.0100","delta_fp":"1.00","side":"yes","ts":"2026-07-01T02:34:36.453402Z","ts_ms":1782873276453}}

{"type":"orderbook_delta","sid":1,"seq":1757,"msg":{"market_ticker":"KXNEXTTEAMNBA-26LJAM-GSW","market_id":"abbbad28-f309-4dd5-af38-2ad7ebf2acc3","price_dollars":"0.0100","delta_fp":"1.00","side":"yes","ts":"2026-07-01T02:34:36.453974Z","ts_ms":1782873276453}}

{"type":"orderbook_delta","sid":1,"seq":1758,"msg":{"market_ticker":"KXNEXTTEAMNBA-26LJAM-GSW","market_id":"abbbad28-f309-4dd5-af38-2ad7ebf2acc3","price_dollars":"0.0100","delta_fp":"1.00","side":"yes","ts":"2026-07-01T02:34:36.454584Z","ts_ms":1782873276454}}

{"type":"orderbook_delta","sid":1,"seq":1759,"msg":{"market_ticker":"KXNEXTTEAMNBA-26LJAM-GSW","market_id":"abbbad28-f309-4dd5-af38-2ad7ebf2acc3","price_dollars":"0.0100","delta_fp":"1.00","side":"yes","ts":"2026-07-01T02:34:36.455119Z","ts_ms":1782873276455}}

{"type":"orderbook_delta","sid":1,"seq":1760,"msg":{"market_ticker":"KXNEXTTEAMNBA-26LJAM-GSW","market_id":"abbbad28-f309-4dd5-af38-2ad7ebf2acc3","price_dollars":"0.0100","delta_fp":"1.00","side":"yes","ts":"2026-07-01T02:34:36.455594Z","ts_ms":1782873276455}}

{"type":"orderbook_delta","sid":1,"seq":1761,"msg":{"market_ticker":"KXNEXTTEAMNBA-26LJAM-GSW","market_id":"abbbad28-f309-4dd5-af38-2ad7ebf2acc3","price_dollars":"0.0100","delta_fp":"1.00","side":"yes","ts":"2026-07-01T02:34:36.456034Z","ts_ms":1782873276456}}

{"type":"orderbook_delta","sid":1,"seq":1762,"msg":{"market_ticker":"KXNEXTTEAMNBA-26LJAM-MIA","market_id":"492cb255-91da-4c91-bc9e-f83d090cc6dd","price_dollars":"0.8300","delta_fp":"-0.72","side":"no","ts":"2026-07-01T02:34:36.470773Z","ts_ms":1782873276470}}

{"type":"orderbook_delta","sid":1,"seq":1763,"msg":{"market_ticker":"KXNEXTTEAMNBA-26LJAM-CLE","market_id":"7552b8d4-05de-4e41-84a8-97b0684da4a9","price_dollars":"0.7400","delta_fp":"-1.25","side":"no","ts":"2026-07-01T02:34:36.615551Z","ts_ms":1782873276615}}

{"type":"orderbook_delta","sid":1,"seq":1764,"msg":{"market_ticker":"KXNEXTTEAMNBA-26LJAM-GSW","market_id":"abbbad28-f309-4dd5-af38-2ad7ebf2acc3","price_dollars":"0.5200","delta_fp":"-1.22","side":"no","ts":"2026-07-01T02:34:36.666629Z","ts_ms":1782873276666}}

{"type":"orderbook_delta","sid":1,"seq":1765,"msg":{"market_ticker":"KXNEXTTEAMNBA-26LJAM-CLE","market_id":"7552b8d4-05de-4e41-84a8-97b0684da4a9","price_dollars":"0.7400","delta_fp":"-0.01","side":"no","ts":"2026-07-01T02:34:37.477409Z","ts_ms":1782873277477}}

{"type":"orderbook_delta","sid":1,"seq":1766,"msg":{"market_ticker":"KXNEXTTEAMNBA-26LJAM-GSW","market_id":"abbbad28-f309-4dd5-af38-2ad7ebf2acc3","price_dollars":"0.5200","delta_fp":"-1.25","side":"no","ts":"2026-07-01T02:34:38.000879Z","ts_ms":1782873278000}}

{"type":"orderbook_delta","sid":1,"seq":1767,"msg":{"market_ticker":"KXNEXTTEAMNBA-26LJAM-GSW","market_id":"abbbad28-f309-4dd5-af38-2ad7ebf2acc3","price_dollars":"0.5200","delta_fp":"-0.22","side":"no","ts":"2026-07-01T02:34:38.188161Z","ts_ms":1782873278188}}

{"type":"orderbook_delta","sid":1,"seq":1768,"msg":{"market_ticker":"KXNEXTTEAMNBA-26LJAM-MIA","market_id":"492cb255-91da-4c91-bc9e-f83d090cc6dd","price_dollars":"0.8300","delta_fp":"-1.13","side":"no","ts":"2026-07-01T02:34:38.189701Z","ts_ms":1782873278189}}

{"type":"orderbook_delta","sid":1,"seq":1769,"msg":{"market_ticker":"KXNEXTTEAMNBA-26LJAM-MIA","market_id":"492cb255-91da-4c91-bc9e-f83d090cc6dd","price_dollars":"0.1600","delta_fp":"2083.33","side":"yes","ts":"2026-07-01T02:34:39.429195Z","ts_ms":1782873279429}}

{"type":"orderbook_delta","sid":1,"seq":1770,"msg":{"market_ticker":"KXNEXTTEAMNBA-26LJAM-MIA","market_id":"492cb255-91da-4c91-bc9e-f83d090cc6dd","price_dollars":"0.1500","delta_fp":"2222.22","side":"yes","ts":"2026-07-01T02:34:39.429549Z","ts_ms":1782873279429}}

{"type":"orderbook_delta","sid":1,"seq":1771,"msg":{"market_ticker":"KXNEXTTEAMNBA-26LJAM-MIA","market_id":"492cb255-91da-4c91-bc9e-f83d090cc6dd","price_dollars":"0.1400","delta_fp":"2380.95","side":"yes","ts":"2026-07-01T02:34:39.430037Z","ts_ms":1782873279430}}

{"type":"orderbook_delta","sid":1,"seq":1772,"msg":{"market_ticker":"KXNEXTTEAMNBA-26LJAM-MIA","market_id":"492cb255-91da-4c91-bc9e-f83d090cc6dd","price_dollars":"0.8300","delta_fp":"1960.78","side":"no","ts":"2026-07-01T02:34:39.430391Z","ts_ms":1782873279430}}

{"type":"orderbook_delta","sid":1,"seq":1773,"msg":{"market_ticker":"KXNEXTTEAMNBA-26LJAM-MIA","market_id":"492cb255-91da-4c91-bc9e-f83d090cc6dd","price_dollars":"0.8200","delta_fp":"1851.85","side":"no","ts":"2026-07-01T02:34:39.4308Z","ts_ms":1782873279430}}

{"type":"orderbook_delta","sid":1,"seq":1774,"msg":{"market_ticker":"KXNEXTTEAMNBA-26LJAM-MIA","market_id":"492cb255-91da-4c91-bc9e-f83d090cc6dd","price_dollars":"0.8100","delta_fp":"1754.38","side":"no","ts":"2026-07-01T02:34:39.43119Z","ts_ms":1782873279431}}

{"type":"orderbook_delta","sid":1,"seq":1775,"msg":{"market_ticker":"KXNEXTTEAMNBA-26LJAM-GSW","market_id":"abbbad28-f309-4dd5-af38-2ad7ebf2acc3","price_dollars":"0.5200","delta_fp":"-1.43","side":"no","ts":"2026-07-01T02:34:40.678197Z","ts_ms":1782873280678}}

{"type":"orderbook_delta","sid":1,"seq":1776,"msg":{"market_ticker":"KXNEXTTEAMNBA-26LJAM-CLE","market_id":"7552b8d4-05de-4e41-84a8-97b0684da4a9","price_dollars":"0.7400","delta_fp":"-1.82","side":"no","ts":"2026-07-01T02:34:41.396564Z","ts_ms":1782873281396}}

{"type":"orderbook_delta","sid":1,"seq":1777,"msg":{"market_ticker":"KXNEXTTEAMNBA-26LJAM-MIA","market_id":"492cb255-91da-4c91-bc9e-f83d090cc6dd","price_dollars":"0.8300","delta_fp":"-0.38","side":"no","ts":"2026-07-01T02:34:41.472374Z","ts_ms":1782873281472}}

{"type":"orderbook_delta","sid":1,"seq":1778,"msg":{"market_ticker":"KXNEXTTEAMNBA-26LJAM-CLE","market_id":"7552b8d4-05de-4e41-84a8-97b0684da4a9","price_dollars":"0.7400","delta_fp":"-0.88","side":"no","ts":"2026-07-01T02:34:42.25524Z","ts_ms":1782873282255}}

{"type":"orderbook_delta","sid":1,"seq":1779,"msg":{"market_ticker":"KXNEXTTEAMNBA-26LJAM-MIA","market_id":"492cb255-91da-4c91-bc9e-f83d090cc6dd","price_dollars":"0.8300","delta_fp":"-1.17","side":"no","ts":"2026-07-01T02:34:42.261485Z","ts_ms":1782873282261}}

{"type":"orderbook_delta","sid":1,"seq":1780,"msg":{"market_ticker":"KXNEXTTEAMNBA-26LJAM-CLE","market_id":"7552b8d4-05de-4e41-84a8-97b0684da4a9","price_dollars":"0.7400","delta_fp":"-0.94","side":"no","ts":"2026-07-01T02:34:43.864232Z","ts_ms":1782873283864}}

{"type":"orderbook_delta","sid":1,"seq":1781,"msg":{"market_ticker":"KXNEXTTEAMNBA-26LJAM-CLE","market_id":"7552b8d4-05de-4e41-84a8-97b0684da4a9","price_dollars":"0.7400","delta_fp":"-1.86","side":"no","ts":"2026-07-01T02:34:43.871349Z","ts_ms":1782873283871}}

{"type":"orderbook_delta","sid":1,"seq":1782,"msg":{"market_ticker":"KXNEXTTEAMNBA-26LJAM-MIA","market_id":"492cb255-91da-4c91-bc9e-f83d090cc6dd","price_dollars":"0.8300","delta_fp":"-0.94","side":"no","ts":"2026-07-01T02:34:43.873487Z","ts_ms":1782873283873}}

{"type":"orderbook_delta","sid":1,"seq":1783,"msg":{"market_ticker":"KXNEXTTEAMNBA-26LJAM-MIA","market_id":"492cb255-91da-4c91-bc9e-f83d090cc6dd","price_dollars":"0.0100","delta_fp":"1.00","side":"yes","ts":"2026-07-01T02:34:44.124116Z","ts_ms":1782873284124}}

{"type":"orderbook_delta","sid":1,"seq":1784,"msg":{"market_ticker":"KXNEXTTEAMNBA-26LJAM-MIA","market_id":"492cb255-91da-4c91-bc9e-f83d090cc6dd","price_dollars":"0.0100","delta_fp":"1.00","side":"yes","ts":"2026-07-01T02:34:44.124741Z","ts_ms":1782873284124}}

{"type":"orderbook_delta","sid":1,"seq":1785,"msg":{"market_ticker":"KXNEXTTEAMNBA-26LJAM-MIA","market_id":"492cb255-91da-4c91-bc9e-f83d090cc6dd","price_dollars":"0.0100","delta_fp":"1.00","side":"yes","ts":"2026-07-01T02:34:44.125271Z","ts_ms":1782873284125}}

{"type":"orderbook_delta","sid":1,"seq":1786,"msg":{"market_ticker":"KXNEXTTEAMNBA-26LJAM-MIA","market_id":"492cb255-91da-4c91-bc9e-f83d090cc6dd","price_dollars":"0.0100","delta_fp":"1.00","side":"yes","ts":"2026-07-01T02:34:44.125626Z","ts_ms":1782873284125}}

{"type":"orderbook_delta","sid":1,"seq":1787,"msg":{"market_ticker":"KXNEXTTEAMNBA-26LJAM-MIA","market_id":"492cb255-91da-4c91-bc9e-f83d090cc6dd","price_dollars":"0.0100","delta_fp":"1.00","side":"yes","ts":"2026-07-01T02:34:44.126107Z","ts_ms":1782873284126}}

{"type":"orderbook_delta","sid":1,"seq":1788,"msg":{"market_ticker":"KXNEXTTEAMNBA-26LJAM-MIA","market_id":"492cb255-91da-4c91-bc9e-f83d090cc6dd","price_dollars":"0.0100","delta_fp":"1.00","side":"yes","ts":"2026-07-01T02:34:44.126618Z","ts_ms":1782873284126}}

{"type":"orderbook_delta","sid":1,"seq":1789,"msg":{"market_ticker":"KXNEXTTEAMNBA-26LJAM-MIA","market_id":"492cb255-91da-4c91-bc9e-f83d090cc6dd","price_dollars":"0.0100","delta_fp":"1.00","side":"yes","ts":"2026-07-01T02:34:44.127078Z","ts_ms":1782873284127}}

{"type":"orderbook_delta","sid":1,"seq":1790,"msg":{"market_ticker":"KXNEXTTEAMNBA-26LJAM-MIA","market_id":"492cb255-91da-4c91-bc9e-f83d090cc6dd","price_dollars":"0.0100","delta_fp":"1.00","side":"yes","ts":"2026-07-01T02:34:44.127514Z","ts_ms":1782873284127}}

{"type":"orderbook_delta","sid":1,"seq":1791,"msg":{"market_ticker":"KXNEXTTEAMNBA-26LJAM-MIA","market_id":"492cb255-91da-4c91-bc9e-f83d090cc6dd","price_dollars":"0.0100","delta_fp":"1.00","side":"yes","ts":"2026-07-01T02:34:44.128062Z","ts_ms":1782873284128}}

{"type":"orderbook_delta","sid":1,"seq":1792,"msg":{"market_ticker":"KXNEXTTEAMNBA-26LJAM-MIA","market_id":"492cb255-91da-4c91-bc9e-f83d090cc6dd","price_dollars":"0.0100","delta_fp":"1.00","side":"yes","ts":"2026-07-01T02:34:44.128563Z","ts_ms":1782873284128}}

{"type":"orderbook_delta","sid":1,"seq":1793,"msg":{"market_ticker":"KXNEXTTEAMNBA-26LJAM-MIA","market_id":"492cb255-91da-4c91-bc9e-f83d090cc6dd","price_dollars":"0.0100","delta_fp":"1.00","side":"yes","ts":"2026-07-01T02:34:44.129142Z","ts_ms":1782873284129}}

{"type":"orderbook_delta","sid":1,"seq":1794,"msg":{"market_ticker":"KXNEXTTEAMNBA-26LJAM-MIA","market_id":"492cb255-91da-4c91-bc9e-f83d090cc6dd","price_dollars":"0.0100","delta_fp":"1.00","side":"yes","ts":"2026-07-01T02:34:44.129993Z","ts_ms":1782873284129}}

{"type":"orderbook_delta","sid":1,"seq":1795,"msg":{"market_ticker":"KXNEXTTEAMNBA-26LJAM-MIA","market_id":"492cb255-91da-4c91-bc9e-f83d090cc6dd","price_dollars":"0.0100","delta_fp":"1.00","side":"yes","ts":"2026-07-01T02:34:44.130697Z","ts_ms":1782873284130}}

{"type":"orderbook_delta","sid":1,"seq":1796,"msg":{"market_ticker":"KXNEXTTEAMNBA-26LJAM-MIA","market_id":"492cb255-91da-4c91-bc9e-f83d090cc6dd","price_dollars":"0.0100","delta_fp":"1.00","side":"yes","ts":"2026-07-01T02:34:44.1312Z","ts_ms":1782873284131}}

{"type":"orderbook_delta","sid":1,"seq":1797,"msg":{"market_ticker":"KXNEXTTEAMNBA-26LJAM-MIA","market_id":"492cb255-91da-4c91-bc9e-f83d090cc6dd","price_dollars":"0.0100","delta_fp":"1.00","side":"yes","ts":"2026-07-01T02:34:44.131908Z","ts_ms":1782873284131}}

{"type":"orderbook_delta","sid":1,"seq":1798,"msg":{"market_ticker":"KXNEXTTEAMNBA-26LJAM-MIA","market_id":"492cb255-91da-4c91-bc9e-f83d090cc6dd","price_dollars":"0.0100","delta_fp":"1.00","side":"yes","ts":"2026-07-01T02:34:44.132671Z","ts_ms":1782873284132}}

{"type":"orderbook_delta","sid":1,"seq":1799,"msg":{"market_ticker":"KXNEXTTEAMNBA-26LJAM-MIA","market_id":"492cb255-91da-4c91-bc9e-f83d090cc6dd","price_dollars":"0.0100","delta_fp":"1.00","side":"yes","ts":"2026-07-01T02:34:44.133586Z","ts_ms":1782873284133}}

{"type":"orderbook_delta","sid":1,"seq":1800,"msg":{"market_ticker":"KXNEXTTEAMNBA-26LJAM-MIA","market_id":"492cb255-91da-4c91-bc9e-f83d090cc6dd","price_dollars":"0.0100","delta_fp":"1.00","side":"yes","ts":"2026-07-01T02:34:44.134569Z","ts_ms":1782873284134}}

{"type":"orderbook_delta","sid":1,"seq":1801,"msg":{"market_ticker":"KXNEXTTEAMNBA-26LJAM-MIA","market_id":"492cb255-91da-4c91-bc9e-f83d090cc6dd","price_dollars":"0.0100","delta_fp":"1.00","side":"yes","ts":"2026-07-01T02:34:44.135476Z","ts_ms":1782873284135}}

{"type":"orderbook_delta","sid":1,"seq":1802,"msg":{"market_ticker":"KXNEXTTEAMNBA-26LJAM-MIA","market_id":"492cb255-91da-4c91-bc9e-f83d090cc6dd","price_dollars":"0.0100","delta_fp":"1.00","side":"yes","ts":"2026-07-01T02:34:44.136096Z","ts_ms":1782873284136}}

{"type":"orderbook_delta","sid":1,"seq":1803,"msg":{"market_ticker":"KXNEXTTEAMNBA-26LJAM-GSW","market_id":"abbbad28-f309-4dd5-af38-2ad7ebf2acc3","price_dollars":"0.4700","delta_fp":"709.21","side":"yes","ts":"2026-07-01T02:34:44.748401Z","ts_ms":1782873284748}}

{"type":"orderbook_delta","sid":1,"seq":1804,"msg":{"market_ticker":"KXNEXTTEAMNBA-26LJAM-GSW","market_id":"abbbad28-f309-4dd5-af38-2ad7ebf2acc3","price_dollars":"0.4600","delta_fp":"724.63","side":"yes","ts":"2026-07-01T02:34:44.749233Z","ts_ms":1782873284749}}

{"type":"orderbook_delta","sid":1,"seq":1805,"msg":{"market_ticker":"KXNEXTTEAMNBA-26LJAM-GSW","market_id":"abbbad28-f309-4dd5-af38-2ad7ebf2acc3","price_dollars":"0.4500","delta_fp":"740.74","side":"yes","ts":"2026-07-01T02:34:44.749861Z","ts_ms":1782873284749}}

{"type":"orderbook_delta","sid":1,"seq":1806,"msg":{"market_ticker":"KXNEXTTEAMNBA-26LJAM-GSW","market_id":"abbbad28-f309-4dd5-af38-2ad7ebf2acc3","price_dollars":"0.5200","delta_fp":"694.44","side":"no","ts":"2026-07-01T02:34:44.750496Z","ts_ms":1782873284750}}

{"type":"orderbook_delta","sid":1,"seq":1807,"msg":{"market_ticker":"KXNEXTTEAMNBA-26LJAM-GSW","market_id":"abbbad28-f309-4dd5-af38-2ad7ebf2acc3","price_dollars":"0.5100","delta_fp":"680.27","side":"no","ts":"2026-07-01T02:34:44.750998Z","ts_ms":1782873284750}}

{"type":"orderbook_delta","sid":1,"seq":1808,"msg":{"market_ticker":"KXNEXTTEAMNBA-26LJAM-GSW","market_id":"abbbad28-f309-4dd5-af38-2ad7ebf2acc3","price_dollars":"0.5000","delta_fp":"666.66","side":"no","ts":"2026-07-01T02:34:44.751492Z","ts_ms":1782873284751}}

{"type":"orderbook_delta","sid":1,"seq":1809,"msg":{"market_ticker":"KXNEXTTEAMNBA-26LJAM-CLE","market_id":"7552b8d4-05de-4e41-84a8-97b0684da4a9","price_dollars":"0.7400","delta_fp":"-1.34","side":"no","ts":"2026-07-01T02:34:45.457976Z","ts_ms":1782873285457}}

{"type":"orderbook_delta","sid":1,"seq":1810,"msg":{"market_ticker":"KXNEXTTEAMNBA-26LJAM-GSW","market_id":"abbbad28-f309-4dd5-af38-2ad7ebf2acc3","price_dollars":"0.5200","delta_fp":"-0.46","side":"no","ts":"2026-07-01T02:34:45.476801Z","ts_ms":1782873285476}}

{"type":"orderbook_delta","sid":1,"seq":1811,"msg":{"market_ticker":"KXNEXTTEAMNBA-26LJAM-MIA","market_id":"492cb255-91da-4c91-bc9e-f83d090cc6dd","price_dollars":"0.8300","delta_fp":"-0.42","side":"no","ts":"2026-07-01T02:34:45.499013Z","ts_ms":1782873285499}}

{"type":"orderbook_delta","sid":1,"seq":1812,"msg":{"market_ticker":"KXNEXTTEAMNBA-26LJAM-CLE","market_id":"7552b8d4-05de-4e41-84a8-97b0684da4a9","price_dollars":"0.7400","delta_fp":"-1.52","side":"no","ts":"2026-07-01T02:34:46.257438Z","ts_ms":1782873286257}}

{"type":"orderbook_delta","sid":1,"seq":1813,"msg":{"market_ticker":"KXNEXTTEAMNBA-26LJAM-GSW","market_id":"abbbad28-f309-4dd5-af38-2ad7ebf2acc3","price_dollars":"0.5200","delta_fp":"-1.86","side":"no","ts":"2026-07-01T02:34:47.0017Z","ts_ms":1782873287001}}

{"type":"orderbook_delta","sid":1,"seq":1814,"msg":{"market_ticker":"KXNEXTTEAMNBA-26LJAM-GSW","market_id":"abbbad28-f309-4dd5-af38-2ad7ebf2acc3","price_dollars":"0.5200","delta_fp":"-1.07","side":"no","ts":"2026-07-01T02:34:47.00736Z","ts_ms":1782873287007}}

{"type":"orderbook_delta","sid":1,"seq":1815,"msg":{"market_ticker":"KXNEXTTEAMNBA-26LJAM-MIA","market_id":"492cb255-91da-4c91-bc9e-f83d090cc6dd","price_dollars":"0.8300","delta_fp":"-0.67","side":"no","ts":"2026-07-01T02:34:47.775875Z","ts_ms":1782873287775}}

{"type":"orderbook_delta","sid":1,"seq":1816,"msg":{"market_ticker":"KXNEXTTEAMNBA-26LJAM-CLE","market_id":"7552b8d4-05de-4e41-84a8-97b0684da4a9","price_dollars":"0.7400","delta_fp":"-0.30","side":"no","ts":"2026-07-01T02:34:48.581717Z","ts_ms":1782873288581}}

{"type":"orderbook_delta","sid":1,"seq":1817,"msg":{"market_ticker":"KXNEXTTEAMNBA-26LJAM-GSW","market_id":"abbbad28-f309-4dd5-af38-2ad7ebf2acc3","price_dollars":"0.0100","delta_fp":"1.00","side":"yes","ts":"2026-07-01T02:34:49.168101Z","ts_ms":1782873289168}}

{"type":"orderbook_delta","sid":1,"seq":1818,"msg":{"market_ticker":"KXNEXTTEAMNBA-26LJAM-GSW","market_id":"abbbad28-f309-4dd5-af38-2ad7ebf2acc3","price_dollars":"0.0100","delta_fp":"1.00","side":"yes","ts":"2026-07-01T02:34:49.169607Z","ts_ms":1782873289169}}

{"type":"orderbook_delta","sid":1,"seq":1819,"msg":{"market_ticker":"KXNEXTTEAMNBA-26LJAM-GSW","market_id":"abbbad28-f309-4dd5-af38-2ad7ebf2acc3","price_dollars":"0.0100","delta_fp":"1.00","side":"yes","ts":"2026-07-01T02:34:49.170407Z","ts_ms":1782873289170}}

{"type":"orderbook_delta","sid":1,"seq":1820,"msg":{"market_ticker":"KXNEXTTEAMNBA-26LJAM-GSW","market_id":"abbbad28-f309-4dd5-af38-2ad7ebf2acc3","price_dollars":"0.0100","delta_fp":"1.00","side":"yes","ts":"2026-07-01T02:34:49.171415Z","ts_ms":1782873289171}}

{"type":"orderbook_delta","sid":1,"seq":1821,"msg":{"market_ticker":"KXNEXTTEAMNBA-26LJAM-GSW","market_id":"abbbad28-f309-4dd5-af38-2ad7ebf2acc3","price_dollars":"0.0100","delta_fp":"1.00","side":"yes","ts":"2026-07-01T02:34:49.172368Z","ts_ms":1782873289172}}

{"type":"orderbook_delta","sid":1,"seq":1822,"msg":{"market_ticker":"KXNEXTTEAMNBA-26LJAM-GSW","market_id":"abbbad28-f309-4dd5-af38-2ad7ebf2acc3","price_dollars":"0.0100","delta_fp":"1.00","side":"yes","ts":"2026-07-01T02:34:49.173197Z","ts_ms":1782873289173}}

{"type":"orderbook_delta","sid":1,"seq":1823,"msg":{"market_ticker":"KXNEXTTEAMNBA-26LJAM-GSW","market_id":"abbbad28-f309-4dd5-af38-2ad7ebf2acc3","price_dollars":"0.0100","delta_fp":"1.00","side":"yes","ts":"2026-07-01T02:34:49.173895Z","ts_ms":1782873289173}}

{"type":"orderbook_delta","sid":1,"seq":1824,"msg":{"market_ticker":"KXNEXTTEAMNBA-26LJAM-GSW","market_id":"abbbad28-f309-4dd5-af38-2ad7ebf2acc3","price_dollars":"0.0100","delta_fp":"1.00","side":"yes","ts":"2026-07-01T02:34:49.174461Z","ts_ms":1782873289174}}

{"type":"orderbook_delta","sid":1,"seq":1825,"msg":{"market_ticker":"KXNEXTTEAMNBA-26LJAM-GSW","market_id":"abbbad28-f309-4dd5-af38-2ad7ebf2acc3","price_dollars":"0.0100","delta_fp":"1.00","side":"yes","ts":"2026-07-01T02:34:49.175075Z","ts_ms":1782873289175}}

{"type":"orderbook_delta","sid":1,"seq":1826,"msg":{"market_ticker":"KXNEXTTEAMNBA-26LJAM-GSW","market_id":"abbbad28-f309-4dd5-af38-2ad7ebf2acc3","price_dollars":"0.0100","delta_fp":"1.00","side":"yes","ts":"2026-07-01T02:34:49.175606Z","ts_ms":1782873289175}}

{"type":"orderbook_delta","sid":1,"seq":1827,"msg":{"market_ticker":"KXNEXTTEAMNBA-26LJAM-GSW","market_id":"abbbad28-f309-4dd5-af38-2ad7ebf2acc3","price_dollars":"0.0100","delta_fp":"1.00","side":"yes","ts":"2026-07-01T02:34:49.176245Z","ts_ms":1782873289176}}

{"type":"orderbook_delta","sid":1,"seq":1828,"msg":{"market_ticker":"KXNEXTTEAMNBA-26LJAM-GSW","market_id":"abbbad28-f309-4dd5-af38-2ad7ebf2acc3","price_dollars":"0.0100","delta_fp":"1.00","side":"yes","ts":"2026-07-01T02:34:49.176829Z","ts_ms":1782873289176}}

{"type":"orderbook_delta","sid":1,"seq":1829,"msg":{"market_ticker":"KXNEXTTEAMNBA-26LJAM-GSW","market_id":"abbbad28-f309-4dd5-af38-2ad7ebf2acc3","price_dollars":"0.0100","delta_fp":"1.00","side":"yes","ts":"2026-07-01T02:34:49.177449Z","ts_ms":1782873289177}}

{"type":"orderbook_delta","sid":1,"seq":1830,"msg":{"market_ticker":"KXNEXTTEAMNBA-26LJAM-GSW","market_id":"abbbad28-f309-4dd5-af38-2ad7ebf2acc3","price_dollars":"0.0100","delta_fp":"1.00","side":"yes","ts":"2026-07-01T02:34:49.177971Z","ts_ms":1782873289177}}

{"type":"orderbook_delta","sid":1,"seq":1831,"msg":{"market_ticker":"KXNEXTTEAMNBA-26LJAM-GSW","market_id":"abbbad28-f309-4dd5-af38-2ad7ebf2acc3","price_dollars":"0.0100","delta_fp":"1.00","side":"yes","ts":"2026-07-01T02:34:49.178467Z","ts_ms":1782873289178}}

{"type":"orderbook_delta","sid":1,"seq":1832,"msg":{"market_ticker":"KXNEXTTEAMNBA-26LJAM-GSW","market_id":"abbbad28-f309-4dd5-af38-2ad7ebf2acc3","price_dollars":"0.0100","delta_fp":"1.00","side":"yes","ts":"2026-07-01T02:34:49.178917Z","ts_ms":1782873289178}}

{"type":"orderbook_delta","sid":1,"seq":1833,"msg":{"market_ticker":"KXNEXTTEAMNBA-26LJAM-GSW","market_id":"abbbad28-f309-4dd5-af38-2ad7ebf2acc3","price_dollars":"0.0100","delta_fp":"1.00","side":"yes","ts":"2026-07-01T02:34:49.179315Z","ts_ms":1782873289179}}

{"type":"orderbook_delta","sid":1,"seq":1834,"msg":{"market_ticker":"KXNEXTTEAMNBA-26LJAM-GSW","market_id":"abbbad28-f309-4dd5-af38-2ad7ebf2acc3","price_dollars":"0.0100","delta_fp":"1.00","side":"yes","ts":"2026-07-01T02:34:49.179748Z","ts_ms":1782873289179}}

{"type":"orderbook_delta","sid":1,"seq":1835,"msg":{"market_ticker":"KXNEXTTEAMNBA-26LJAM-GSW","market_id":"abbbad28-f309-4dd5-af38-2ad7ebf2acc3","price_dollars":"0.0100","delta_fp":"1.00","side":"yes","ts":"2026-07-01T02:34:49.180183Z","ts_ms":1782873289180}}

{"type":"orderbook_delta","sid":1,"seq":1836,"msg":{"market_ticker":"KXNEXTTEAMNBA-26LJAM-GSW","market_id":"abbbad28-f309-4dd5-af38-2ad7ebf2acc3","price_dollars":"0.0100","delta_fp":"1.00","side":"yes","ts":"2026-07-01T02:34:49.180595Z","ts_ms":1782873289180}}

{"type":"orderbook_delta","sid":1,"seq":1837,"msg":{"market_ticker":"KXNEXTTEAMNBA-26LJAM-MIA","market_id":"492cb255-91da-4c91-bc9e-f83d090cc6dd","price_dollars":"0.8300","delta_fp":"-0.09","side":"no","ts":"2026-07-01T02:34:50.275465Z","ts_ms":1782873290275}}

{"type":"orderbook_delta","sid":1,"seq":1838,"msg":{"market_ticker":"KXNEXTTEAMNBA-26LJAM-MIA","market_id":"492cb255-91da-4c91-bc9e-f83d090cc6dd","price_dollars":"0.0100","delta_fp":"1.00","side":"yes","ts":"2026-07-01T02:34:50.326857Z","ts_ms":1782873290326}}

{"type":"orderbook_delta","sid":1,"seq":1839,"msg":{"market_ticker":"KXNEXTTEAMNBA-26LJAM-MIA","market_id":"492cb255-91da-4c91-bc9e-f83d090cc6dd","price_dollars":"0.0100","delta_fp":"1.00","side":"yes","ts":"2026-07-01T02:34:50.327265Z","ts_ms":1782873290327}}

{"type":"orderbook_delta","sid":1,"seq":1840,"msg":{"market_ticker":"KXNEXTTEAMNBA-26LJAM-MIA","market_id":"492cb255-91da-4c91-bc9e-f83d090cc6dd","price_dollars":"0.0100","delta_fp":"1.00","side":"yes","ts":"2026-07-01T02:34:50.32757Z","ts_ms":1782873290327}}

{"type":"orderbook_delta","sid":1,"seq":1841,"msg":{"market_ticker":"KXNEXTTEAMNBA-26LJAM-MIA","market_id":"492cb255-91da-4c91-bc9e-f83d090cc6dd","price_dollars":"0.0100","delta_fp":"1.00","side":"yes","ts":"2026-07-01T02:34:50.327968Z","ts_ms":1782873290327}}

{"type":"orderbook_delta","sid":1,"seq":1842,"msg":{"market_ticker":"KXNEXTTEAMNBA-26LJAM-MIA","market_id":"492cb255-91da-4c91-bc9e-f83d090cc6dd","price_dollars":"0.0100","delta_fp":"1.00","side":"yes","ts":"2026-07-01T02:34:50.328255Z","ts_ms":1782873290328}}

{"type":"orderbook_delta","sid":1,"seq":1843,"msg":{"market_ticker":"KXNEXTTEAMNBA-26LJAM-MIA","market_id":"492cb255-91da-4c91-bc9e-f83d090cc6dd","price_dollars":"0.0100","delta_fp":"1.00","side":"yes","ts":"2026-07-01T02:34:50.328561Z","ts_ms":1782873290328}}

{"type":"orderbook_delta","sid":1,"seq":1844,"msg":{"market_ticker":"KXNEXTTEAMNBA-26LJAM-MIA","market_id":"492cb255-91da-4c91-bc9e-f83d090cc6dd","price_dollars":"0.0100","delta_fp":"1.00","side":"yes","ts":"2026-07-01T02:34:50.328994Z","ts_ms":1782873290328}}

{"type":"orderbook_delta","sid":1,"seq":1845,"msg":{"market_ticker":"KXNEXTTEAMNBA-26LJAM-MIA","market_id":"492cb255-91da-4c91-bc9e-f83d090cc6dd","price_dollars":"0.0100","delta_fp":"1.00","side":"yes","ts":"2026-07-01T02:34:50.329423Z","ts_ms":1782873290329}}

{"type":"orderbook_delta","sid":1,"seq":1846,"msg":{"market_ticker":"KXNEXTTEAMNBA-26LJAM-MIA","market_id":"492cb255-91da-4c91-bc9e-f83d090cc6dd","price_dollars":"0.0100","delta_fp":"1.00","side":"yes","ts":"2026-07-01T02:34:50.32993Z","ts_ms":1782873290329}}

{"type":"orderbook_delta","sid":1,"seq":1847,"msg":{"market_ticker":"KXNEXTTEAMNBA-26LJAM-MIA","market_id":"492cb255-91da-4c91-bc9e-f83d090cc6dd","price_dollars":"0.0100","delta_fp":"1.00","side":"yes","ts":"2026-07-01T02:34:50.330351Z","ts_ms":1782873290330}}

{"type":"orderbook_delta","sid":1,"seq":1848,"msg":{"market_ticker":"KXNEXTTEAMNBA-26LJAM-MIA","market_id":"492cb255-91da-4c91-bc9e-f83d090cc6dd","price_dollars":"0.0100","delta_fp":"1.00","side":"yes","ts":"2026-07-01T02:34:50.330899Z","ts_ms":1782873290330}}

{"type":"orderbook_delta","sid":1,"seq":1849,"msg":{"market_ticker":"KXNEXTTEAMNBA-26LJAM-MIA","market_id":"492cb255-91da-4c91-bc9e-f83d090cc6dd","price_dollars":"0.0100","delta_fp":"1.00","side":"yes","ts":"2026-07-01T02:34:50.331339Z","ts_ms":1782873290331}}

{"type":"orderbook_delta","sid":1,"seq":1850,"msg":{"market_ticker":"KXNEXTTEAMNBA-26LJAM-MIA","market_id":"492cb255-91da-4c91-bc9e-f83d090cc6dd","price_dollars":"0.0100","delta_fp":"1.00","side":"yes","ts":"2026-07-01T02:34:50.331859Z","ts_ms":1782873290331}}

{"type":"orderbook_delta","sid":1,"seq":1851,"msg":{"market_ticker":"KXNEXTTEAMNBA-26LJAM-MIA","market_id":"492cb255-91da-4c91-bc9e-f83d090cc6dd","price_dollars":"0.0100","delta_fp":"1.00","side":"yes","ts":"2026-07-01T02:34:50.332239Z","ts_ms":1782873290332}}

{"type":"orderbook_delta","sid":1,"seq":1852,"msg":{"market_ticker":"KXNEXTTEAMNBA-26LJAM-MIA","market_id":"492cb255-91da-4c91-bc9e-f83d090cc6dd","price_dollars":"0.0100","delta_fp":"1.00","side":"yes","ts":"2026-07-01T02:34:50.332697Z","ts_ms":1782873290332}}

{"type":"orderbook_delta","sid":1,"seq":1853,"msg":{"market_ticker":"KXNEXTTEAMNBA-26LJAM-MIA","market_id":"492cb255-91da-4c91-bc9e-f83d090cc6dd","price_dollars":"0.0100","delta_fp":"1.00","side":"yes","ts":"2026-07-01T02:34:50.333053Z","ts_ms":1782873290333}}

{"type":"orderbook_delta","sid":1,"seq":1854,"msg":{"market_ticker":"KXNEXTTEAMNBA-26LJAM-MIA","market_id":"492cb255-91da-4c91-bc9e-f83d090cc6dd","price_dollars":"0.0100","delta_fp":"1.00","side":"yes","ts":"2026-07-01T02:34:50.333431Z","ts_ms":1782873290333}}

{"type":"orderbook_delta","sid":1,"seq":1855,"msg":{"market_ticker":"KXNEXTTEAMNBA-26LJAM-MIA","market_id":"492cb255-91da-4c91-bc9e-f83d090cc6dd","price_dollars":"0.0100","delta_fp":"1.00","side":"yes","ts":"2026-07-01T02:34:50.33388Z","ts_ms":1782873290333}}

{"type":"orderbook_delta","sid":1,"seq":1856,"msg":{"market_ticker":"KXNEXTTEAMNBA-26LJAM-MIA","market_id":"492cb255-91da-4c91-bc9e-f83d090cc6dd","price_dollars":"0.0100","delta_fp":"1.00","side":"yes","ts":"2026-07-01T02:34:50.334271Z","ts_ms":1782873290334}}

{"type":"orderbook_delta","sid":1,"seq":1857,"msg":{"market_ticker":"KXNEXTTEAMNBA-26LJAM-MIA","market_id":"492cb255-91da-4c91-bc9e-f83d090cc6dd","price_dollars":"0.0100","delta_fp":"1.00","side":"yes","ts":"2026-07-01T02:34:50.334672Z","ts_ms":1782873290334}}

{"type":"orderbook_delta","sid":1,"seq":1858,"msg":{"market_ticker":"KXNEXTTEAMNBA-26LJAM-CLE","market_id":"7552b8d4-05de-4e41-84a8-97b0684da4a9","price_dollars":"0.7400","delta_fp":"-0.55","side":"no","ts":"2026-07-01T02:34:51.085601Z","ts_ms":1782873291085}}

{"type":"orderbook_delta","sid":1,"seq":1859,"msg":{"market_ticker":"KXNEXTTEAMNBA-26LJAM-MIA","market_id":"492cb255-91da-4c91-bc9e-f83d090cc6dd","price_dollars":"0.8300","delta_fp":"-0.80","side":"no","ts":"2026-07-01T02:34:51.839031Z","ts_ms":1782873291839}}

{"type":"orderbook_delta","sid":1,"seq":1860,"msg":{"market_ticker":"KXNEXTTEAMNBA-26LJAM-MIA","market_id":"492cb255-91da-4c91-bc9e-f83d090cc6dd","price_dollars":"0.0100","delta_fp":"-1.00","side":"yes","ts":"2026-07-01T02:34:52.339214Z","ts_ms":1782873292339}}

{"type":"orderbook_delta","sid":1,"seq":1861,"msg":{"market_ticker":"KXNEXTTEAMNBA-26LJAM-MIA","market_id":"492cb255-91da-4c91-bc9e-f83d090cc6dd","price_dollars":"0.0100","delta_fp":"-1.00","side":"yes","ts":"2026-07-01T02:34:52.339762Z","ts_ms":1782873292339}}

{"type":"orderbook_delta","sid":1,"seq":1862,"msg":{"market_ticker":"KXNEXTTEAMNBA-26LJAM-MIA","market_id":"492cb255-91da-4c91-bc9e-f83d090cc6dd","price_dollars":"0.0100","delta_fp":"-1.00","side":"yes","ts":"2026-07-01T02:34:52.340306Z","ts_ms":1782873292340}}

{"type":"orderbook_delta","sid":1,"seq":1863,"msg":{"market_ticker":"KXNEXTTEAMNBA-26LJAM-MIA","market_id":"492cb255-91da-4c91-bc9e-f83d090cc6dd","price_dollars":"0.0100","delta_fp":"-1.00","side":"yes","ts":"2026-07-01T02:34:52.340826Z","ts_ms":1782873292340}}

{"type":"orderbook_delta","sid":1,"seq":1864,"msg":{"market_ticker":"KXNEXTTEAMNBA-26LJAM-MIA","market_id":"492cb255-91da-4c91-bc9e-f83d090cc6dd","price_dollars":"0.0100","delta_fp":"-1.00","side":"yes","ts":"2026-07-01T02:34:52.341361Z","ts_ms":1782873292341}}

{"type":"orderbook_delta","sid":1,"seq":1865,"msg":{"market_ticker":"KXNEXTTEAMNBA-26LJAM-MIA","market_id":"492cb255-91da-4c91-bc9e-f83d090cc6dd","price_dollars":"0.0100","delta_fp":"-1.00","side":"yes","ts":"2026-07-01T02:34:52.341849Z","ts_ms":1782873292341}}

{"type":"orderbook_delta","sid":1,"seq":1866,"msg":{"market_ticker":"KXNEXTTEAMNBA-26LJAM-MIA","market_id":"492cb255-91da-4c91-bc9e-f83d090cc6dd","price_dollars":"0.0100","delta_fp":"-1.00","side":"yes","ts":"2026-07-01T02:34:52.342458Z","ts_ms":1782873292342}}

{"type":"orderbook_delta","sid":1,"seq":1867,"msg":{"market_ticker":"KXNEXTTEAMNBA-26LJAM-MIA","market_id":"492cb255-91da-4c91-bc9e-f83d090cc6dd","price_dollars":"0.0100","delta_fp":"-1.00","side":"yes","ts":"2026-07-01T02:34:52.342944Z","ts_ms":1782873292342}}

{"type":"orderbook_delta","sid":1,"seq":1868,"msg":{"market_ticker":"KXNEXTTEAMNBA-26LJAM-MIA","market_id":"492cb255-91da-4c91-bc9e-f83d090cc6dd","price_dollars":"0.0100","delta_fp":"-1.00","side":"yes","ts":"2026-07-01T02:34:52.34358Z","ts_ms":1782873292343}}

{"type":"orderbook_delta","sid":1,"seq":1869,"msg":{"market_ticker":"KXNEXTTEAMNBA-26LJAM-MIA","market_id":"492cb255-91da-4c91-bc9e-f83d090cc6dd","price_dollars":"0.0100","delta_fp":"-1.00","side":"yes","ts":"2026-07-01T02:34:52.344092Z","ts_ms":1782873292344}}

{"type":"orderbook_delta","sid":1,"seq":1870,"msg":{"market_ticker":"KXNEXTTEAMNBA-26LJAM-MIA","market_id":"492cb255-91da-4c91-bc9e-f83d090cc6dd","price_dollars":"0.0100","delta_fp":"-1.00","side":"yes","ts":"2026-07-01T02:34:52.344645Z","ts_ms":1782873292344}}

{"type":"orderbook_delta","sid":1,"seq":1871,"msg":{"market_ticker":"KXNEXTTEAMNBA-26LJAM-MIA","market_id":"492cb255-91da-4c91-bc9e-f83d090cc6dd","price_dollars":"0.0100","delta_fp":"-1.00","side":"yes","ts":"2026-07-01T02:34:52.345059Z","ts_ms":1782873292345}}

{"type":"orderbook_delta","sid":1,"seq":1872,"msg":{"market_ticker":"KXNEXTTEAMNBA-26LJAM-MIA","market_id":"492cb255-91da-4c91-bc9e-f83d090cc6dd","price_dollars":"0.0100","delta_fp":"-1.00","side":"yes","ts":"2026-07-01T02:34:52.34555Z","ts_ms":1782873292345}}

{"type":"orderbook_delta","sid":1,"seq":1873,"msg":{"market_ticker":"KXNEXTTEAMNBA-26LJAM-MIA","market_id":"492cb255-91da-4c91-bc9e-f83d090cc6dd","price_dollars":"0.0100","delta_fp":"-1.00","side":"yes","ts":"2026-07-01T02:34:52.3461Z","ts_ms":1782873292346}}

{"type":"orderbook_delta","sid":1,"seq":1874,"msg":{"market_ticker":"KXNEXTTEAMNBA-26LJAM-MIA","market_id":"492cb255-91da-4c91-bc9e-f83d090cc6dd","price_dollars":"0.0100","delta_fp":"-1.00","side":"yes","ts":"2026-07-01T02:34:52.346784Z","ts_ms":1782873292346}}

{"type":"orderbook_delta","sid":1,"seq":1875,"msg":{"market_ticker":"KXNEXTTEAMNBA-26LJAM-MIA","market_id":"492cb255-91da-4c91-bc9e-f83d090cc6dd","price_dollars":"0.0100","delta_fp":"-1.00","side":"yes","ts":"2026-07-01T02:34:52.347367Z","ts_ms":1782873292347}}

{"type":"orderbook_delta","sid":1,"seq":1876,"msg":{"market_ticker":"KXNEXTTEAMNBA-26LJAM-MIA","market_id":"492cb255-91da-4c91-bc9e-f83d090cc6dd","price_dollars":"0.0100","delta_fp":"-1.00","side":"yes","ts":"2026-07-01T02:34:52.347897Z","ts_ms":1782873292347}}

{"type":"orderbook_delta","sid":1,"seq":1877,"msg":{"market_ticker":"KXNEXTTEAMNBA-26LJAM-MIA","market_id":"492cb255-91da-4c91-bc9e-f83d090cc6dd","price_dollars":"0.0100","delta_fp":"-1.00","side":"yes","ts":"2026-07-01T02:34:52.348474Z","ts_ms":1782873292348}}

{"type":"orderbook_delta","sid":1,"seq":1878,"msg":{"market_ticker":"KXNEXTTEAMNBA-26LJAM-MIA","market_id":"492cb255-91da-4c91-bc9e-f83d090cc6dd","price_dollars":"0.0100","delta_fp":"-1.00","side":"yes","ts":"2026-07-01T02:34:52.348856Z","ts_ms":1782873292348}}

{"type":"orderbook_delta","sid":1,"seq":1879,"msg":{"market_ticker":"KXNEXTTEAMNBA-26LJAM-MIA","market_id":"492cb255-91da-4c91-bc9e-f83d090cc6dd","price_dollars":"0.0100","delta_fp":"-1.00","side":"yes","ts":"2026-07-01T02:34:52.349323Z","ts_ms":1782873292349}}

{"type":"orderbook_delta","sid":1,"seq":1880,"msg":{"market_ticker":"KXNEXTTEAMNBA-26LJAM-GSW","market_id":"abbbad28-f309-4dd5-af38-2ad7ebf2acc3","price_dollars":"0.5200","delta_fp":"-0.28","side":"no","ts":"2026-07-01T02:34:52.773365Z","ts_ms":1782873292773}}

{"type":"orderbook_delta","sid":1,"seq":1881,"msg":{"market_ticker":"KXNEXTTEAMNBA-26LJAM-MIA","market_id":"492cb255-91da-4c91-bc9e-f83d090cc6dd","price_dollars":"0.8300","delta_fp":"-0.48","side":"no","ts":"2026-07-01T02:34:55.199527Z","ts_ms":1782873295199}}

{"type":"orderbook_delta","sid":1,"seq":1882,"msg":{"market_ticker":"KXNEXTTEAMNBA-26LJAM-GSW","market_id":"abbbad28-f309-4dd5-af38-2ad7ebf2acc3","price_dollars":"0.0100","delta_fp":"1.00","side":"yes","ts":"2026-07-01T02:34:55.819201Z","ts_ms":1782873295819}}

{"type":"orderbook_delta","sid":1,"seq":1883,"msg":{"market_ticker":"KXNEXTTEAMNBA-26LJAM-GSW","market_id":"abbbad28-f309-4dd5-af38-2ad7ebf2acc3","price_dollars":"0.0100","delta_fp":"1.00","side":"yes","ts":"2026-07-01T02:34:55.819654Z","ts_ms":1782873295819}}

{"type":"orderbook_delta","sid":1,"seq":1884,"msg":{"market_ticker":"KXNEXTTEAMNBA-26LJAM-GSW","market_id":"abbbad28-f309-4dd5-af38-2ad7ebf2acc3","price_dollars":"0.0100","delta_fp":"1.00","side":"yes","ts":"2026-07-01T02:34:55.820089Z","ts_ms":1782873295820}}

{"type":"orderbook_delta","sid":1,"seq":1885,"msg":{"market_ticker":"KXNEXTTEAMNBA-26LJAM-GSW","market_id":"abbbad28-f309-4dd5-af38-2ad7ebf2acc3","price_dollars":"0.0100","delta_fp":"1.00","side":"yes","ts":"2026-07-01T02:34:55.820542Z","ts_ms":1782873295820}}

{"type":"orderbook_delta","sid":1,"seq":1886,"msg":{"market_ticker":"KXNEXTTEAMNBA-26LJAM-GSW","market_id":"abbbad28-f309-4dd5-af38-2ad7ebf2acc3","price_dollars":"0.0100","delta_fp":"1.00","side":"yes","ts":"2026-07-01T02:34:55.820979Z","ts_ms":1782873295820}}

{"type":"orderbook_delta","sid":1,"seq":1887,"msg":{"market_ticker":"KXNEXTTEAMNBA-26LJAM-GSW","market_id":"abbbad28-f309-4dd5-af38-2ad7ebf2acc3","price_dollars":"0.0100","delta_fp":"1.00","side":"yes","ts":"2026-07-01T02:34:55.821719Z","ts_ms":1782873295821}}

{"type":"orderbook_delta","sid":1,"seq":1888,"msg":{"market_ticker":"KXNEXTTEAMNBA-26LJAM-GSW","market_id":"abbbad28-f309-4dd5-af38-2ad7ebf2acc3","price_dollars":"0.0100","delta_fp":"1.00","side":"yes","ts":"2026-07-01T02:34:55.822357Z","ts_ms":1782873295822}}

{"type":"orderbook_delta","sid":1,"seq":1889,"msg":{"market_ticker":"KXNEXTTEAMNBA-26LJAM-GSW","market_id":"abbbad28-f309-4dd5-af38-2ad7ebf2acc3","price_dollars":"0.0100","delta_fp":"1.00","side":"yes","ts":"2026-07-01T02:34:55.822938Z","ts_ms":1782873295822}}

{"type":"orderbook_delta","sid":1,"seq":1890,"msg":{"market_ticker":"KXNEXTTEAMNBA-26LJAM-GSW","market_id":"abbbad28-f309-4dd5-af38-2ad7ebf2acc3","price_dollars":"0.0100","delta_fp":"1.00","side":"yes","ts":"2026-07-01T02:34:55.823466Z","ts_ms":1782873295823}}

{"type":"orderbook_delta","sid":1,"seq":1891,"msg":{"market_ticker":"KXNEXTTEAMNBA-26LJAM-GSW","market_id":"abbbad28-f309-4dd5-af38-2ad7ebf2acc3","price_dollars":"0.0100","delta_fp":"1.00","side":"yes","ts":"2026-07-01T02:34:55.824196Z","ts_ms":1782873295824}}

{"type":"orderbook_delta","sid":1,"seq":1892,"msg":{"market_ticker":"KXNEXTTEAMNBA-26LJAM-GSW","market_id":"abbbad28-f309-4dd5-af38-2ad7ebf2acc3","price_dollars":"0.0100","delta_fp":"1.00","side":"yes","ts":"2026-07-01T02:34:55.82472Z","ts_ms":1782873295824}}

{"type":"orderbook_delta","sid":1,"seq":1893,"msg":{"market_ticker":"KXNEXTTEAMNBA-26LJAM-GSW","market_id":"abbbad28-f309-4dd5-af38-2ad7ebf2acc3","price_dollars":"0.0100","delta_fp":"1.00","side":"yes","ts":"2026-07-01T02:34:55.82509Z","ts_ms":1782873295825}}

{"type":"orderbook_delta","sid":1,"seq":1894,"msg":{"market_ticker":"KXNEXTTEAMNBA-26LJAM-GSW","market_id":"abbbad28-f309-4dd5-af38-2ad7ebf2acc3","price_dollars":"0.0100","delta_fp":"1.00","side":"yes","ts":"2026-07-01T02:34:55.825536Z","ts_ms":1782873295825}}

{"type":"orderbook_delta","sid":1,"seq":1895,"msg":{"market_ticker":"KXNEXTTEAMNBA-26LJAM-GSW","market_id":"abbbad28-f309-4dd5-af38-2ad7ebf2acc3","price_dollars":"0.0100","delta_fp":"1.00","side":"yes","ts":"2026-07-01T02:34:55.825942Z","ts_ms":1782873295825}}

{"type":"orderbook_delta","sid":1,"seq":1896,"msg":{"market_ticker":"KXNEXTTEAMNBA-26LJAM-GSW","market_id":"abbbad28-f309-4dd5-af38-2ad7ebf2acc3","price_dollars":"0.0100","delta_fp":"1.00","side":"yes","ts":"2026-07-01T02:34:55.826367Z","ts_ms":1782873295826}}

{"type":"orderbook_delta","sid":1,"seq":1897,"msg":{"market_ticker":"KXNEXTTEAMNBA-26LJAM-GSW","market_id":"abbbad28-f309-4dd5-af38-2ad7ebf2acc3","price_dollars":"0.0100","delta_fp":"1.00","side":"yes","ts":"2026-07-01T02:34:55.826886Z","ts_ms":1782873295826}}

{"type":"orderbook_delta","sid":1,"seq":1898,"msg":{"market_ticker":"KXNEXTTEAMNBA-26LJAM-GSW","market_id":"abbbad28-f309-4dd5-af38-2ad7ebf2acc3","price_dollars":"0.0100","delta_fp":"1.00","side":"yes","ts":"2026-07-01T02:34:55.827492Z","ts_ms":1782873295827}}

{"type":"orderbook_delta","sid":1,"seq":1899,"msg":{"market_ticker":"KXNEXTTEAMNBA-26LJAM-GSW","market_id":"abbbad28-f309-4dd5-af38-2ad7ebf2acc3","price_dollars":"0.0100","delta_fp":"1.00","side":"yes","ts":"2026-07-01T02:34:55.82793Z","ts_ms":1782873295827}}

{"type":"orderbook_delta","sid":1,"seq":1900,"msg":{"market_ticker":"KXNEXTTEAMNBA-26LJAM-GSW","market_id":"abbbad28-f309-4dd5-af38-2ad7ebf2acc3","price_dollars":"0.0100","delta_fp":"1.00","side":"yes","ts":"2026-07-01T02:34:55.828558Z","ts_ms":1782873295828}}

{"type":"orderbook_delta","sid":1,"seq":1901,"msg":{"market_ticker":"KXNEXTTEAMNBA-26LJAM-GSW","market_id":"abbbad28-f309-4dd5-af38-2ad7ebf2acc3","price_dollars":"0.0100","delta_fp":"1.00","side":"yes","ts":"2026-07-01T02:34:55.828845Z","ts_ms":1782873295828}}

{"type":"orderbook_delta","sid":1,"seq":1902,"msg":{"market_ticker":"KXNEXTTEAMNBA-26LJAM-MIA","market_id":"492cb255-91da-4c91-bc9e-f83d090cc6dd","price_dollars":"0.0100","delta_fp":"1.00","side":"yes","ts":"2026-07-01T02:34:56.944574Z","ts_ms":1782873296944}}

{"type":"orderbook_delta","sid":1,"seq":1903,"msg":{"market_ticker":"KXNEXTTEAMNBA-26LJAM-MIA","market_id":"492cb255-91da-4c91-bc9e-f83d090cc6dd","price_dollars":"0.0100","delta_fp":"1.00","side":"yes","ts":"2026-07-01T02:34:56.945087Z","ts_ms":1782873296945}}

{"type":"orderbook_delta","sid":1,"seq":1904,"msg":{"market_ticker":"KXNEXTTEAMNBA-26LJAM-MIA","market_id":"492cb255-91da-4c91-bc9e-f83d090cc6dd","price_dollars":"0.0100","delta_fp":"1.00","side":"yes","ts":"2026-07-01T02:34:56.945607Z","ts_ms":1782873296945}}

{"type":"orderbook_delta","sid":1,"seq":1905,"msg":{"market_ticker":"KXNEXTTEAMNBA-26LJAM-MIA","market_id":"492cb255-91da-4c91-bc9e-f83d090cc6dd","price_dollars":"0.0100","delta_fp":"1.00","side":"yes","ts":"2026-07-01T02:34:56.94626Z","ts_ms":1782873296946}}

{"type":"orderbook_delta","sid":1,"seq":1906,"msg":{"market_ticker":"KXNEXTTEAMNBA-26LJAM-MIA","market_id":"492cb255-91da-4c91-bc9e-f83d090cc6dd","price_dollars":"0.0100","delta_fp":"1.00","side":"yes","ts":"2026-07-01T02:34:56.947187Z","ts_ms":1782873296947}}

{"type":"orderbook_delta","sid":1,"seq":1907,"msg":{"market_ticker":"KXNEXTTEAMNBA-26LJAM-MIA","market_id":"492cb255-91da-4c91-bc9e-f83d090cc6dd","price_dollars":"0.0100","delta_fp":"1.00","side":"yes","ts":"2026-07-01T02:34:56.947522Z","ts_ms":1782873296947}}

{"type":"orderbook_delta","sid":1,"seq":1908,"msg":{"market_ticker":"KXNEXTTEAMNBA-26LJAM-MIA","market_id":"492cb255-91da-4c91-bc9e-f83d090cc6dd","price_dollars":"0.0100","delta_fp":"1.00","side":"yes","ts":"2026-07-01T02:34:56.947827Z","ts_ms":1782873296947}}

{"type":"orderbook_delta","sid":1,"seq":1909,"msg":{"market_ticker":"KXNEXTTEAMNBA-26LJAM-MIA","market_id":"492cb255-91da-4c91-bc9e-f83d090cc6dd","price_dollars":"0.0100","delta_fp":"1.00","side":"yes","ts":"2026-07-01T02:34:56.948242Z","ts_ms":1782873296948}}

{"type":"orderbook_delta","sid":1,"seq":1910,"msg":{"market_ticker":"KXNEXTTEAMNBA-26LJAM-MIA","market_id":"492cb255-91da-4c91-bc9e-f83d090cc6dd","price_dollars":"0.0100","delta_fp":"1.00","side":"yes","ts":"2026-07-01T02:34:56.948826Z","ts_ms":1782873296948}}

{"type":"orderbook_delta","sid":1,"seq":1911,"msg":{"market_ticker":"KXNEXTTEAMNBA-26LJAM-MIA","market_id":"492cb255-91da-4c91-bc9e-f83d090cc6dd","price_dollars":"0.0100","delta_fp":"1.00","side":"yes","ts":"2026-07-01T02:34:56.949319Z","ts_ms":1782873296949}}

{"type":"orderbook_delta","sid":1,"seq":1912,"msg":{"market_ticker":"KXNEXTTEAMNBA-26LJAM-MIA","market_id":"492cb255-91da-4c91-bc9e-f83d090cc6dd","price_dollars":"0.0100","delta_fp":"1.00","side":"yes","ts":"2026-07-01T02:34:56.949802Z","ts_ms":1782873296949}}

{"type":"orderbook_delta","sid":1,"seq":1913,"msg":{"market_ticker":"KXNEXTTEAMNBA-26LJAM-MIA","market_id":"492cb255-91da-4c91-bc9e-f83d090cc6dd","price_dollars":"0.0100","delta_fp":"1.00","side":"yes","ts":"2026-07-01T02:34:56.950204Z","ts_ms":1782873296950}}

{"type":"orderbook_delta","sid":1,"seq":1914,"msg":{"market_ticker":"KXNEXTTEAMNBA-26LJAM-MIA","market_id":"492cb255-91da-4c91-bc9e-f83d090cc6dd","price_dollars":"0.0100","delta_fp":"1.00","side":"yes","ts":"2026-07-01T02:34:56.950718Z","ts_ms":1782873296950}}

{"type":"orderbook_delta","sid":1,"seq":1915,"msg":{"market_ticker":"KXNEXTTEAMNBA-26LJAM-MIA","market_id":"492cb255-91da-4c91-bc9e-f83d090cc6dd","price_dollars":"0.0100","delta_fp":"1.00","side":"yes","ts":"2026-07-01T02:34:56.95128Z","ts_ms":1782873296951}}

{"type":"orderbook_delta","sid":1,"seq":1916,"msg":{"market_ticker":"KXNEXTTEAMNBA-26LJAM-MIA","market_id":"492cb255-91da-4c91-bc9e-f83d090cc6dd","price_dollars":"0.0100","delta_fp":"1.00","side":"yes","ts":"2026-07-01T02:34:56.951778Z","ts_ms":1782873296951}}

{"type":"orderbook_delta","sid":1,"seq":1917,"msg":{"market_ticker":"KXNEXTTEAMNBA-26LJAM-MIA","market_id":"492cb255-91da-4c91-bc9e-f83d090cc6dd","price_dollars":"0.0100","delta_fp":"1.00","side":"yes","ts":"2026-07-01T02:34:56.952327Z","ts_ms":1782873296952}}

{"type":"orderbook_delta","sid":1,"seq":1918,"msg":{"market_ticker":"KXNEXTTEAMNBA-26LJAM-MIA","market_id":"492cb255-91da-4c91-bc9e-f83d090cc6dd","price_dollars":"0.0100","delta_fp":"1.00","side":"yes","ts":"2026-07-01T02:34:56.952876Z","ts_ms":1782873296952}}

{"type":"orderbook_delta","sid":1,"seq":1919,"msg":{"market_ticker":"KXNEXTTEAMNBA-26LJAM-MIA","market_id":"492cb255-91da-4c91-bc9e-f83d090cc6dd","price_dollars":"0.0100","delta_fp":"1.00","side":"yes","ts":"2026-07-01T02:34:56.95343Z","ts_ms":1782873296953}}

{"type":"orderbook_delta","sid":1,"seq":1920,"msg":{"market_ticker":"KXNEXTTEAMNBA-26LJAM-MIA","market_id":"492cb255-91da-4c91-bc9e-f83d090cc6dd","price_dollars":"0.0100","delta_fp":"1.00","side":"yes","ts":"2026-07-01T02:34:56.953905Z","ts_ms":1782873296953}}

{"type":"orderbook_delta","sid":1,"seq":1921,"msg":{"market_ticker":"KXNEXTTEAMNBA-26LJAM-MIA","market_id":"492cb255-91da-4c91-bc9e-f83d090cc6dd","price_dollars":"0.0100","delta_fp":"1.00","side":"yes","ts":"2026-07-01T02:34:56.954515Z","ts_ms":1782873296954}}

{"type":"orderbook_delta","sid":1,"seq":1922,"msg":{"market_ticker":"KXNEXTTEAMNBA-26LJAM-GSW","market_id":"abbbad28-f309-4dd5-af38-2ad7ebf2acc3","price_dollars":"0.5200","delta_fp":"-1.54","side":"no","ts":"2026-07-01T02:34:58.664106Z","ts_ms":1782873298664}}

{"type":"orderbook_delta","sid":1,"seq":1923,"msg":{"market_ticker":"KXNEXTTEAMNBA-26LJAM-MIA","market_id":"492cb255-91da-4c91-bc9e-f83d090cc6dd","price_dollars":"0.8300","delta_fp":"-1.29","side":"no","ts":"2026-07-01T02:34:59.474786Z","ts_ms":1782873299474}}

{"type":"orderbook_delta","sid":1,"seq":1924,"msg":{"market_ticker":"KXNEXTTEAMNBA-26LJAM-CLE","market_id":"7552b8d4-05de-4e41-84a8-97b0684da4a9","price_dollars":"0.7400","delta_fp":"-0.93","side":"no","ts":"2026-07-01T02:35:00.255377Z","ts_ms":1782873300255}}

{"type":"orderbook_delta","sid":1,"seq":1925,"msg":{"market_ticker":"KXNEXTTEAMNBA-26LJAM-MIA","market_id":"492cb255-91da-4c91-bc9e-f83d090cc6dd","price_dollars":"0.8300","delta_fp":"-0.22","side":"no","ts":"2026-07-01T02:35:01.855879Z","ts_ms":1782873301855}}

{"type":"orderbook_delta","sid":1,"seq":1926,"msg":{"market_ticker":"KXNEXTTEAMNBA-26LJAM-MIA","market_id":"492cb255-91da-4c91-bc9e-f83d090cc6dd","price_dollars":"0.8300","delta_fp":"-1.63","side":"no","ts":"2026-07-01T02:35:01.864578Z","ts_ms":1782873301864}}

{"type":"orderbook_delta","sid":1,"seq":1927,"msg":{"market_ticker":"KXNEXTTEAMNBA-26LJAM-GSW","market_id":"abbbad28-f309-4dd5-af38-2ad7ebf2acc3","price_dollars":"0.5200","delta_fp":"-0.57","side":"no","ts":"2026-07-01T02:35:01.897323Z","ts_ms":1782873301897}}

{"type":"orderbook_delta","sid":1,"seq":1928,"msg":{"market_ticker":"KXNEXTTEAMNBA-26LJAM-GSW","market_id":"abbbad28-f309-4dd5-af38-2ad7ebf2acc3","price_dollars":"0.0100","delta_fp":"1.00","side":"yes","ts":"2026-07-01T02:35:02.842589Z","ts_ms":1782873302842}}

{"type":"orderbook_delta","sid":1,"seq":1929,"msg":{"market_ticker":"KXNEXTTEAMNBA-26LJAM-GSW","market_id":"abbbad28-f309-4dd5-af38-2ad7ebf2acc3","price_dollars":"0.0100","delta_fp":"1.00","side":"yes","ts":"2026-07-01T02:35:02.843218Z","ts_ms":1782873302843}}

{"type":"orderbook_delta","sid":1,"seq":1930,"msg":{"market_ticker":"KXNEXTTEAMNBA-26LJAM-GSW","market_id":"abbbad28-f309-4dd5-af38-2ad7ebf2acc3","price_dollars":"0.0100","delta_fp":"1.00","side":"yes","ts":"2026-07-01T02:35:02.843958Z","ts_ms":1782873302843}}

{"type":"orderbook_delta","sid":1,"seq":1931,"msg":{"market_ticker":"KXNEXTTEAMNBA-26LJAM-GSW","market_id":"abbbad28-f309-4dd5-af38-2ad7ebf2acc3","price_dollars":"0.0100","delta_fp":"1.00","side":"yes","ts":"2026-07-01T02:35:02.844613Z","ts_ms":1782873302844}}

{"type":"orderbook_delta","sid":1,"seq":1932,"msg":{"market_ticker":"KXNEXTTEAMNBA-26LJAM-GSW","market_id":"abbbad28-f309-4dd5-af38-2ad7ebf2acc3","price_dollars":"0.0100","delta_fp":"1.00","side":"yes","ts":"2026-07-01T02:35:02.84518Z","ts_ms":1782873302845}}

{"type":"orderbook_delta","sid":1,"seq":1933,"msg":{"market_ticker":"KXNEXTTEAMNBA-26LJAM-GSW","market_id":"abbbad28-f309-4dd5-af38-2ad7ebf2acc3","price_dollars":"0.0100","delta_fp":"1.00","side":"yes","ts":"2026-07-01T02:35:02.84574Z","ts_ms":1782873302845}}

{"type":"orderbook_delta","sid":1,"seq":1934,"msg":{"market_ticker":"KXNEXTTEAMNBA-26LJAM-GSW","market_id":"abbbad28-f309-4dd5-af38-2ad7ebf2acc3","price_dollars":"0.0100","delta_fp":"1.00","side":"yes","ts":"2026-07-01T02:35:02.846173Z","ts_ms":1782873302846}}

{"type":"orderbook_delta","sid":1,"seq":1935,"msg":{"market_ticker":"KXNEXTTEAMNBA-26LJAM-GSW","market_id":"abbbad28-f309-4dd5-af38-2ad7ebf2acc3","price_dollars":"0.0100","delta_fp":"1.00","side":"yes","ts":"2026-07-01T02:35:02.846587Z","ts_ms":1782873302846}}

{"type":"orderbook_delta","sid":1,"seq":1936,"msg":{"market_ticker":"KXNEXTTEAMNBA-26LJAM-GSW","market_id":"abbbad28-f309-4dd5-af38-2ad7ebf2acc3","price_dollars":"0.0100","delta_fp":"1.00","side":"yes","ts":"2026-07-01T02:35:02.84732Z","ts_ms":1782873302847}}

{"type":"orderbook_delta","sid":1,"seq":1937,"msg":{"market_ticker":"KXNEXTTEAMNBA-26LJAM-GSW","market_id":"abbbad28-f309-4dd5-af38-2ad7ebf2acc3","price_dollars":"0.0100","delta_fp":"1.00","side":"yes","ts":"2026-07-01T02:35:02.847862Z","ts_ms":1782873302847}}

{"type":"orderbook_delta","sid":1,"seq":1938,"msg":{"market_ticker":"KXNEXTTEAMNBA-26LJAM-GSW","market_id":"abbbad28-f309-4dd5-af38-2ad7ebf2acc3","price_dollars":"0.0100","delta_fp":"1.00","side":"yes","ts":"2026-07-01T02:35:02.848598Z","ts_ms":1782873302848}}

{"type":"orderbook_delta","sid":1,"seq":1939,"msg":{"market_ticker":"KXNEXTTEAMNBA-26LJAM-GSW","market_id":"abbbad28-f309-4dd5-af38-2ad7ebf2acc3","price_dollars":"0.0100","delta_fp":"1.00","side":"yes","ts":"2026-07-01T02:35:02.849247Z","ts_ms":1782873302849}}

{"type":"orderbook_delta","sid":1,"seq":1940,"msg":{"market_ticker":"KXNEXTTEAMNBA-26LJAM-GSW","market_id":"abbbad28-f309-4dd5-af38-2ad7ebf2acc3","price_dollars":"0.0100","delta_fp":"1.00","side":"yes","ts":"2026-07-01T02:35:02.849852Z","ts_ms":1782873302849}}

{"type":"orderbook_delta","sid":1,"seq":1941,"msg":{"market_ticker":"KXNEXTTEAMNBA-26LJAM-GSW","market_id":"abbbad28-f309-4dd5-af38-2ad7ebf2acc3","price_dollars":"0.0100","delta_fp":"1.00","side":"yes","ts":"2026-07-01T02:35:02.850261Z","ts_ms":1782873302850}}

{"type":"orderbook_delta","sid":1,"seq":1942,"msg":{"market_ticker":"KXNEXTTEAMNBA-26LJAM-GSW","market_id":"abbbad28-f309-4dd5-af38-2ad7ebf2acc3","price_dollars":"0.0100","delta_fp":"1.00","side":"yes","ts":"2026-07-01T02:35:02.850663Z","ts_ms":1782873302850}}

{"type":"orderbook_delta","sid":1,"seq":1943,"msg":{"market_ticker":"KXNEXTTEAMNBA-26LJAM-GSW","market_id":"abbbad28-f309-4dd5-af38-2ad7ebf2acc3","price_dollars":"0.0100","delta_fp":"1.00","side":"yes","ts":"2026-07-01T02:35:02.851154Z","ts_ms":1782873302851}}

{"type":"orderbook_delta","sid":1,"seq":1944,"msg":{"market_ticker":"KXNEXTTEAMNBA-26LJAM-GSW","market_id":"abbbad28-f309-4dd5-af38-2ad7ebf2acc3","price_dollars":"0.0100","delta_fp":"1.00","side":"yes","ts":"2026-07-01T02:35:02.85172Z","ts_ms":1782873302851}}

{"type":"orderbook_delta","sid":1,"seq":1945,"msg":{"market_ticker":"KXNEXTTEAMNBA-26LJAM-GSW","market_id":"abbbad28-f309-4dd5-af38-2ad7ebf2acc3","price_dollars":"0.0100","delta_fp":"1.00","side":"yes","ts":"2026-07-01T02:35:02.852192Z","ts_ms":1782873302852}}

{"type":"orderbook_delta","sid":1,"seq":1946,"msg":{"market_ticker":"KXNEXTTEAMNBA-26LJAM-GSW","market_id":"abbbad28-f309-4dd5-af38-2ad7ebf2acc3","price_dollars":"0.0100","delta_fp":"1.00","side":"yes","ts":"2026-07-01T02:35:02.852692Z","ts_ms":1782873302852}}

{"type":"orderbook_delta","sid":1,"seq":1947,"msg":{"market_ticker":"KXNEXTTEAMNBA-26LJAM-GSW","market_id":"abbbad28-f309-4dd5-af38-2ad7ebf2acc3","price_dollars":"0.0100","delta_fp":"1.00","side":"yes","ts":"2026-07-01T02:35:02.853204Z","ts_ms":1782873302853}}

{"type":"orderbook_delta","sid":1,"seq":1948,"msg":{"market_ticker":"KXNEXTTEAMNBA-26LJAM-MIA","market_id":"492cb255-91da-4c91-bc9e-f83d090cc6dd","price_dollars":"0.0100","delta_fp":"1.00","side":"yes","ts":"2026-07-01T02:35:04.128086Z","ts_ms":1782873304128}}

{"type":"orderbook_delta","sid":1,"seq":1949,"msg":{"market_ticker":"KXNEXTTEAMNBA-26LJAM-MIA","market_id":"492cb255-91da-4c91-bc9e-f83d090cc6dd","price_dollars":"0.0100","delta_fp":"1.00","side":"yes","ts":"2026-07-01T02:35:04.128689Z","ts_ms":1782873304128}}

{"type":"orderbook_delta","sid":1,"seq":1950,"msg":{"market_ticker":"KXNEXTTEAMNBA-26LJAM-MIA","market_id":"492cb255-91da-4c91-bc9e-f83d090cc6dd","price_dollars":"0.0100","delta_fp":"1.00","side":"yes","ts":"2026-07-01T02:35:04.129225Z","ts_ms":1782873304129}}

{"type":"orderbook_delta","sid":1,"seq":1951,"msg":{"market_ticker":"KXNEXTTEAMNBA-26LJAM-MIA","market_id":"492cb255-91da-4c91-bc9e-f83d090cc6dd","price_dollars":"0.0100","delta_fp":"1.00","side":"yes","ts":"2026-07-01T02:35:04.129678Z","ts_ms":1782873304129}}

{"type":"orderbook_delta","sid":1,"seq":1952,"msg":{"market_ticker":"KXNEXTTEAMNBA-26LJAM-MIA","market_id":"492cb255-91da-4c91-bc9e-f83d090cc6dd","price_dollars":"0.0100","delta_fp":"1.00","side":"yes","ts":"2026-07-01T02:35:04.130213Z","ts_ms":1782873304130}}

{"type":"orderbook_delta","sid":1,"seq":1953,"msg":{"market_ticker":"KXNEXTTEAMNBA-26LJAM-MIA","market_id":"492cb255-91da-4c91-bc9e-f83d090cc6dd","price_dollars":"0.0100","delta_fp":"1.00","side":"yes","ts":"2026-07-01T02:35:04.130788Z","ts_ms":1782873304130}}

{"type":"orderbook_delta","sid":1,"seq":1954,"msg":{"market_ticker":"KXNEXTTEAMNBA-26LJAM-MIA","market_id":"492cb255-91da-4c91-bc9e-f83d090cc6dd","price_dollars":"0.0100","delta_fp":"1.00","side":"yes","ts":"2026-07-01T02:35:04.131147Z","ts_ms":1782873304131}}

{"type":"orderbook_delta","sid":1,"seq":1955,"msg":{"market_ticker":"KXNEXTTEAMNBA-26LJAM-MIA","market_id":"492cb255-91da-4c91-bc9e-f83d090cc6dd","price_dollars":"0.0100","delta_fp":"1.00","side":"yes","ts":"2026-07-01T02:35:04.131585Z","ts_ms":1782873304131}}

{"type":"orderbook_delta","sid":1,"seq":1956,"msg":{"market_ticker":"KXNEXTTEAMNBA-26LJAM-MIA","market_id":"492cb255-91da-4c91-bc9e-f83d090cc6dd","price_dollars":"0.0100","delta_fp":"1.00","side":"yes","ts":"2026-07-01T02:35:04.132358Z","ts_ms":1782873304132}}

{"type":"orderbook_delta","sid":1,"seq":1957,"msg":{"market_ticker":"KXNEXTTEAMNBA-26LJAM-MIA","market_id":"492cb255-91da-4c91-bc9e-f83d090cc6dd","price_dollars":"0.0100","delta_fp":"1.00","side":"yes","ts":"2026-07-01T02:35:04.132859Z","ts_ms":1782873304132}}

{"type":"orderbook_delta","sid":1,"seq":1958,"msg":{"market_ticker":"KXNEXTTEAMNBA-26LJAM-MIA","market_id":"492cb255-91da-4c91-bc9e-f83d090cc6dd","price_dollars":"0.0100","delta_fp":"1.00","side":"yes","ts":"2026-07-01T02:35:04.133326Z","ts_ms":1782873304133}}

{"type":"orderbook_delta","sid":1,"seq":1959,"msg":{"market_ticker":"KXNEXTTEAMNBA-26LJAM-MIA","market_id":"492cb255-91da-4c91-bc9e-f83d090cc6dd","price_dollars":"0.0100","delta_fp":"1.00","side":"yes","ts":"2026-07-01T02:35:04.133736Z","ts_ms":1782873304133}}

{"type":"orderbook_delta","sid":1,"seq":1960,"msg":{"market_ticker":"KXNEXTTEAMNBA-26LJAM-MIA","market_id":"492cb255-91da-4c91-bc9e-f83d090cc6dd","price_dollars":"0.0100","delta_fp":"1.00","side":"yes","ts":"2026-07-01T02:35:04.134177Z","ts_ms":1782873304134}}

{"type":"orderbook_delta","sid":1,"seq":1961,"msg":{"market_ticker":"KXNEXTTEAMNBA-26LJAM-MIA","market_id":"492cb255-91da-4c91-bc9e-f83d090cc6dd","price_dollars":"0.0100","delta_fp":"1.00","side":"yes","ts":"2026-07-01T02:35:04.134669Z","ts_ms":1782873304134}}

{"type":"orderbook_delta","sid":1,"seq":1962,"msg":{"market_ticker":"KXNEXTTEAMNBA-26LJAM-MIA","market_id":"492cb255-91da-4c91-bc9e-f83d090cc6dd","price_dollars":"0.0100","delta_fp":"1.00","side":"yes","ts":"2026-07-01T02:35:04.134989Z","ts_ms":1782873304134}}

{"type":"orderbook_delta","sid":1,"seq":1963,"msg":{"market_ticker":"KXNEXTTEAMNBA-26LJAM-MIA","market_id":"492cb255-91da-4c91-bc9e-f83d090cc6dd","price_dollars":"0.0100","delta_fp":"1.00","side":"yes","ts":"2026-07-01T02:35:04.135335Z","ts_ms":1782873304135}}

{"type":"orderbook_delta","sid":1,"seq":1964,"msg":{"market_ticker":"KXNEXTTEAMNBA-26LJAM-MIA","market_id":"492cb255-91da-4c91-bc9e-f83d090cc6dd","price_dollars":"0.0100","delta_fp":"1.00","side":"yes","ts":"2026-07-01T02:35:04.135772Z","ts_ms":1782873304135}}

{"type":"orderbook_delta","sid":1,"seq":1965,"msg":{"market_ticker":"KXNEXTTEAMNBA-26LJAM-MIA","market_id":"492cb255-91da-4c91-bc9e-f83d090cc6dd","price_dollars":"0.0100","delta_fp":"1.00","side":"yes","ts":"2026-07-01T02:35:04.13616Z","ts_ms":1782873304136}}

{"type":"orderbook_delta","sid":1,"seq":1966,"msg":{"market_ticker":"KXNEXTTEAMNBA-26LJAM-MIA","market_id":"492cb255-91da-4c91-bc9e-f83d090cc6dd","price_dollars":"0.0100","delta_fp":"1.00","side":"yes","ts":"2026-07-01T02:35:04.136575Z","ts_ms":1782873304136}}

{"type":"orderbook_delta","sid":1,"seq":1967,"msg":{"market_ticker":"KXNEXTTEAMNBA-26LJAM-MIA","market_id":"492cb255-91da-4c91-bc9e-f83d090cc6dd","price_dollars":"0.0100","delta_fp":"1.00","side":"yes","ts":"2026-07-01T02:35:04.137175Z","ts_ms":1782873304137}}

{"type":"orderbook_delta","sid":1,"seq":1968,"msg":{"market_ticker":"KXNEXTTEAMNBA-26LJAM-CLE","market_id":"7552b8d4-05de-4e41-84a8-97b0684da4a9","price_dollars":"0.7400","delta_fp":"-0.96","side":"no","ts":"2026-07-01T02:35:04.362451Z","ts_ms":1782873304362}}

{"type":"orderbook_delta","sid":1,"seq":1969,"msg":{"market_ticker":"KXNEXTTEAMNBA-26LJAM-MIA","market_id":"492cb255-91da-4c91-bc9e-f83d090cc6dd","price_dollars":"0.8300","delta_fp":"-1.08","side":"no","ts":"2026-07-01T02:35:04.37081Z","ts_ms":1782873304370}}

{"type":"orderbook_delta","sid":1,"seq":1970,"msg":{"market_ticker":"KXNEXTTEAMNBA-26LJAM-CLE","market_id":"7552b8d4-05de-4e41-84a8-97b0684da4a9","price_dollars":"0.7400","delta_fp":"-1.61","side":"no","ts":"2026-07-01T02:35:04.38048Z","ts_ms":1782873304380}}

{"type":"orderbook_delta","sid":1,"seq":1971,"msg":{"market_ticker":"KXNEXTTEAMNBA-26LJAM-CLE","market_id":"7552b8d4-05de-4e41-84a8-97b0684da4a9","price_dollars":"0.7400","delta_fp":"-1.15","side":"no","ts":"2026-07-01T02:35:05.364079Z","ts_ms":1782873305364}}

{"type":"orderbook_delta","sid":1,"seq":1972,"msg":{"market_ticker":"KXNEXTTEAMNBA-26LJAM-GSW","market_id":"abbbad28-f309-4dd5-af38-2ad7ebf2acc3","price_dollars":"0.5200","delta_fp":"-0.66","side":"no","ts":"2026-07-01T02:35:07.761549Z","ts_ms":1782873307761}}

{"type":"orderbook_delta","sid":1,"seq":1973,"msg":{"market_ticker":"KXNEXTTEAMNBA-26LJAM-MIA","market_id":"492cb255-91da-4c91-bc9e-f83d090cc6dd","price_dollars":"0.8300","delta_fp":"-0.79","side":"no","ts":"2026-07-01T02:35:07.790645Z","ts_ms":1782873307790}}

{"type":"orderbook_delta","sid":1,"seq":1974,"msg":{"market_ticker":"KXNEXTTEAMNBA-26LJAM-GSW","market_id":"abbbad28-f309-4dd5-af38-2ad7ebf2acc3","price_dollars":"0.5200","delta_fp":"-1.92","side":"no","ts":"2026-07-01T02:35:08.583945Z","ts_ms":1782873308583}}

{"type":"orderbook_delta","sid":1,"seq":1975,"msg":{"market_ticker":"KXNEXTTEAMNBA-26LJAM-MIA","market_id":"492cb255-91da-4c91-bc9e-f83d090cc6dd","price_dollars":"0.8300","delta_fp":"-1.75","side":"no","ts":"2026-07-01T02:35:09.271327Z","ts_ms":1782873309271}}

{"type":"orderbook_delta","sid":1,"seq":1976,"msg":{"market_ticker":"KXNEXTTEAMNBA-26LJAM-GSW","market_id":"abbbad28-f309-4dd5-af38-2ad7ebf2acc3","price_dollars":"0.5200","delta_fp":"-1.01","side":"no","ts":"2026-07-01T02:35:09.39452Z","ts_ms":1782873309394}}

{"type":"orderbook_delta","sid":1,"seq":1977,"msg":{"market_ticker":"KXNEXTTEAMNBA-26LJAM-GSW","market_id":"abbbad28-f309-4dd5-af38-2ad7ebf2acc3","price_dollars":"0.0100","delta_fp":"1.00","side":"yes","ts":"2026-07-01T02:35:09.432599Z","ts_ms":1782873309432}}

{"type":"orderbook_delta","sid":1,"seq":1978,"msg":{"market_ticker":"KXNEXTTEAMNBA-26LJAM-GSW","market_id":"abbbad28-f309-4dd5-af38-2ad7ebf2acc3","price_dollars":"0.0100","delta_fp":"1.00","side":"yes","ts":"2026-07-01T02:35:09.433722Z","ts_ms":1782873309433}}

{"type":"orderbook_delta","sid":1,"seq":1979,"msg":{"market_ticker":"KXNEXTTEAMNBA-26LJAM-GSW","market_id":"abbbad28-f309-4dd5-af38-2ad7ebf2acc3","price_dollars":"0.0100","delta_fp":"1.00","side":"yes","ts":"2026-07-01T02:35:09.434761Z","ts_ms":1782873309434}}

{"type":"orderbook_delta","sid":1,"seq":1980,"msg":{"market_ticker":"KXNEXTTEAMNBA-26LJAM-GSW","market_id":"abbbad28-f309-4dd5-af38-2ad7ebf2acc3","price_dollars":"0.0100","delta_fp":"1.00","side":"yes","ts":"2026-07-01T02:35:09.435444Z","ts_ms":1782873309435}}

{"type":"orderbook_delta","sid":1,"seq":1981,"msg":{"market_ticker":"KXNEXTTEAMNBA-26LJAM-GSW","market_id":"abbbad28-f309-4dd5-af38-2ad7ebf2acc3","price_dollars":"0.0100","delta_fp":"1.00","side":"yes","ts":"2026-07-01T02:35:09.435918Z","ts_ms":1782873309435}}

{"type":"orderbook_delta","sid":1,"seq":1982,"msg":{"market_ticker":"KXNEXTTEAMNBA-26LJAM-GSW","market_id":"abbbad28-f309-4dd5-af38-2ad7ebf2acc3","price_dollars":"0.0100","delta_fp":"1.00","side":"yes","ts":"2026-07-01T02:35:09.43667Z","ts_ms":1782873309436}}

{"type":"orderbook_delta","sid":1,"seq":1983,"msg":{"market_ticker":"KXNEXTTEAMNBA-26LJAM-GSW","market_id":"abbbad28-f309-4dd5-af38-2ad7ebf2acc3","price_dollars":"0.0100","delta_fp":"1.00","side":"yes","ts":"2026-07-01T02:35:09.43757Z","ts_ms":1782873309437}}

{"type":"orderbook_delta","sid":1,"seq":1984,"msg":{"market_ticker":"KXNEXTTEAMNBA-26LJAM-GSW","market_id":"abbbad28-f309-4dd5-af38-2ad7ebf2acc3","price_dollars":"0.0100","delta_fp":"1.00","side":"yes","ts":"2026-07-01T02:35:09.438232Z","ts_ms":1782873309438}}

{"type":"orderbook_delta","sid":1,"seq":1985,"msg":{"market_ticker":"KXNEXTTEAMNBA-26LJAM-GSW","market_id":"abbbad28-f309-4dd5-af38-2ad7ebf2acc3","price_dollars":"0.0100","delta_fp":"1.00","side":"yes","ts":"2026-07-01T02:35:09.439078Z","ts_ms":1782873309439}}

{"type":"orderbook_delta","sid":1,"seq":1986,"msg":{"market_ticker":"KXNEXTTEAMNBA-26LJAM-GSW","market_id":"abbbad28-f309-4dd5-af38-2ad7ebf2acc3","price_dollars":"0.0100","delta_fp":"1.00","side":"yes","ts":"2026-07-01T02:35:09.439995Z","ts_ms":1782873309439}}

{"type":"orderbook_delta","sid":1,"seq":1987,"msg":{"market_ticker":"KXNEXTTEAMNBA-26LJAM-GSW","market_id":"abbbad28-f309-4dd5-af38-2ad7ebf2acc3","price_dollars":"0.0100","delta_fp":"1.00","side":"yes","ts":"2026-07-01T02:35:09.44071Z","ts_ms":1782873309440}}

{"type":"orderbook_delta","sid":1,"seq":1988,"msg":{"market_ticker":"KXNEXTTEAMNBA-26LJAM-GSW","market_id":"abbbad28-f309-4dd5-af38-2ad7ebf2acc3","price_dollars":"0.0100","delta_fp":"1.00","side":"yes","ts":"2026-07-01T02:35:09.441847Z","ts_ms":1782873309441}}

{"type":"orderbook_delta","sid":1,"seq":1989,"msg":{"market_ticker":"KXNEXTTEAMNBA-26LJAM-GSW","market_id":"abbbad28-f309-4dd5-af38-2ad7ebf2acc3","price_dollars":"0.0100","delta_fp":"1.00","side":"yes","ts":"2026-07-01T02:35:09.442576Z","ts_ms":1782873309442}}

{"type":"orderbook_delta","sid":1,"seq":1990,"msg":{"market_ticker":"KXNEXTTEAMNBA-26LJAM-GSW","market_id":"abbbad28-f309-4dd5-af38-2ad7ebf2acc3","price_dollars":"0.0100","delta_fp":"1.00","side":"yes","ts":"2026-07-01T02:35:09.443399Z","ts_ms":1782873309443}}

{"type":"orderbook_delta","sid":1,"seq":1991,"msg":{"market_ticker":"KXNEXTTEAMNBA-26LJAM-GSW","market_id":"abbbad28-f309-4dd5-af38-2ad7ebf2acc3","price_dollars":"0.0100","delta_fp":"1.00","side":"yes","ts":"2026-07-01T02:35:09.443997Z","ts_ms":1782873309443}}

{"type":"orderbook_delta","sid":1,"seq":1992,"msg":{"market_ticker":"KXNEXTTEAMNBA-26LJAM-GSW","market_id":"abbbad28-f309-4dd5-af38-2ad7ebf2acc3","price_dollars":"0.0100","delta_fp":"1.00","side":"yes","ts":"2026-07-01T02:35:09.444738Z","ts_ms":1782873309444}}

{"type":"orderbook_delta","sid":1,"seq":1993,"msg":{"market_ticker":"KXNEXTTEAMNBA-26LJAM-GSW","market_id":"abbbad28-f309-4dd5-af38-2ad7ebf2acc3","price_dollars":"0.0100","delta_fp":"1.00","side":"yes","ts":"2026-07-01T02:35:09.445315Z","ts_ms":1782873309445}}

{"type":"orderbook_delta","sid":1,"seq":1994,"msg":{"market_ticker":"KXNEXTTEAMNBA-26LJAM-GSW","market_id":"abbbad28-f309-4dd5-af38-2ad7ebf2acc3","price_dollars":"0.0100","delta_fp":"1.00","side":"yes","ts":"2026-07-01T02:35:09.445625Z","ts_ms":1782873309445}}

{"type":"orderbook_delta","sid":1,"seq":1995,"msg":{"market_ticker":"KXNEXTTEAMNBA-26LJAM-GSW","market_id":"abbbad28-f309-4dd5-af38-2ad7ebf2acc3","price_dollars":"0.0100","delta_fp":"1.00","side":"yes","ts":"2026-07-01T02:35:09.446184Z","ts_ms":1782873309446}}

{"type":"orderbook_delta","sid":1,"seq":1996,"msg":{"market_ticker":"KXNEXTTEAMNBA-26LJAM-GSW","market_id":"abbbad28-f309-4dd5-af38-2ad7ebf2acc3","price_dollars":"0.0100","delta_fp":"1.00","side":"yes","ts":"2026-07-01T02:35:09.446668Z","ts_ms":1782873309446}}

{"type":"orderbook_delta","sid":1,"seq":1997,"msg":{"market_ticker":"KXNEXTTEAMNBA-26LJAM-MIA","market_id":"492cb255-91da-4c91-bc9e-f83d090cc6dd","price_dollars":"0.0100","delta_fp":"1.00","side":"yes","ts":"2026-07-01T02:35:10.565655Z","ts_ms":1782873310565}}

{"type":"orderbook_delta","sid":1,"seq":1998,"msg":{"market_ticker":"KXNEXTTEAMNBA-26LJAM-MIA","market_id":"492cb255-91da-4c91-bc9e-f83d090cc6dd","price_dollars":"0.0100","delta_fp":"1.00","side":"yes","ts":"2026-07-01T02:35:10.566102Z","ts_ms":1782873310566}}

{"type":"orderbook_delta","sid":1,"seq":1999,"msg":{"market_ticker":"KXNEXTTEAMNBA-26LJAM-MIA","market_id":"492cb255-91da-4c91-bc9e-f83d090cc6dd","price_dollars":"0.0100","delta_fp":"1.00","side":"yes","ts":"2026-07-01T02:35:10.566754Z","ts_ms":1782873310566}}

{"type":"orderbook_delta","sid":1,"seq":2000,"msg":{"market_ticker":"KXNEXTTEAMNBA-26LJAM-MIA","market_id":"492cb255-91da-4c91-bc9e-f83d090cc6dd","price_dollars":"0.0100","delta_fp":"1.00","side":"yes","ts":"2026-07-01T02:35:10.567301Z","ts_ms":1782873310567}}

{"type":"orderbook_delta","sid":1,"seq":2001,"msg":{"market_ticker":"KXNEXTTEAMNBA-26LJAM-MIA","market_id":"492cb255-91da-4c91-bc9e-f83d090cc6dd","price_dollars":"0.0100","delta_fp":"1.00","side":"yes","ts":"2026-07-01T02:35:10.567834Z","ts_ms":1782873310567}}

{"type":"orderbook_delta","sid":1,"seq":2002,"msg":{"market_ticker":"KXNEXTTEAMNBA-26LJAM-MIA","market_id":"492cb255-91da-4c91-bc9e-f83d090cc6dd","price_dollars":"0.0100","delta_fp":"1.00","side":"yes","ts":"2026-07-01T02:35:10.568282Z","ts_ms":1782873310568}}

{"type":"orderbook_delta","sid":1,"seq":2003,"msg":{"market_ticker":"KXNEXTTEAMNBA-26LJAM-MIA","market_id":"492cb255-91da-4c91-bc9e-f83d090cc6dd","price_dollars":"0.0100","delta_fp":"1.00","side":"yes","ts":"2026-07-01T02:35:10.568746Z","ts_ms":1782873310568}}

{"type":"orderbook_delta","sid":1,"seq":2004,"msg":{"market_ticker":"KXNEXTTEAMNBA-26LJAM-MIA","market_id":"492cb255-91da-4c91-bc9e-f83d090cc6dd","price_dollars":"0.0100","delta_fp":"1.00","side":"yes","ts":"2026-07-01T02:35:10.569294Z","ts_ms":1782873310569}}

{"type":"orderbook_delta","sid":1,"seq":2005,"msg":{"market_ticker":"KXNEXTTEAMNBA-26LJAM-MIA","market_id":"492cb255-91da-4c91-bc9e-f83d090cc6dd","price_dollars":"0.0100","delta_fp":"1.00","side":"yes","ts":"2026-07-01T02:35:10.569931Z","ts_ms":1782873310569}}

{"type":"orderbook_delta","sid":1,"seq":2006,"msg":{"market_ticker":"KXNEXTTEAMNBA-26LJAM-MIA","market_id":"492cb255-91da-4c91-bc9e-f83d090cc6dd","price_dollars":"0.0100","delta_fp":"1.00","side":"yes","ts":"2026-07-01T02:35:10.570656Z","ts_ms":1782873310570}}

{"type":"orderbook_delta","sid":1,"seq":2007,"msg":{"market_ticker":"KXNEXTTEAMNBA-26LJAM-MIA","market_id":"492cb255-91da-4c91-bc9e-f83d090cc6dd","price_dollars":"0.0100","delta_fp":"1.00","side":"yes","ts":"2026-07-01T02:35:10.571196Z","ts_ms":1782873310571}}

{"type":"orderbook_delta","sid":1,"seq":2008,"msg":{"market_ticker":"KXNEXTTEAMNBA-26LJAM-MIA","market_id":"492cb255-91da-4c91-bc9e-f83d090cc6dd","price_dollars":"0.0100","delta_fp":"1.00","side":"yes","ts":"2026-07-01T02:35:10.571875Z","ts_ms":1782873310571}}

{"type":"orderbook_delta","sid":1,"seq":2009,"msg":{"market_ticker":"KXNEXTTEAMNBA-26LJAM-MIA","market_id":"492cb255-91da-4c91-bc9e-f83d090cc6dd","price_dollars":"0.0100","delta_fp":"1.00","side":"yes","ts":"2026-07-01T02:35:10.572483Z","ts_ms":1782873310572}}

{"type":"orderbook_delta","sid":1,"seq":2010,"msg":{"market_ticker":"KXNEXTTEAMNBA-26LJAM-MIA","market_id":"492cb255-91da-4c91-bc9e-f83d090cc6dd","price_dollars":"0.0100","delta_fp":"1.00","side":"yes","ts":"2026-07-01T02:35:10.57293Z","ts_ms":1782873310572}}

{"type":"orderbook_delta","sid":1,"seq":2011,"msg":{"market_ticker":"KXNEXTTEAMNBA-26LJAM-MIA","market_id":"492cb255-91da-4c91-bc9e-f83d090cc6dd","price_dollars":"0.0100","delta_fp":"1.00","side":"yes","ts":"2026-07-01T02:35:10.573465Z","ts_ms":1782873310573}}

{"type":"orderbook_delta","sid":1,"seq":2012,"msg":{"market_ticker":"KXNEXTTEAMNBA-26LJAM-MIA","market_id":"492cb255-91da-4c91-bc9e-f83d090cc6dd","price_dollars":"0.0100","delta_fp":"1.00","side":"yes","ts":"2026-07-01T02:35:10.573913Z","ts_ms":1782873310573}}

{"type":"orderbook_delta","sid":1,"seq":2013,"msg":{"market_ticker":"KXNEXTTEAMNBA-26LJAM-MIA","market_id":"492cb255-91da-4c91-bc9e-f83d090cc6dd","price_dollars":"0.0100","delta_fp":"1.00","side":"yes","ts":"2026-07-01T02:35:10.574246Z","ts_ms":1782873310574}}

{"type":"orderbook_delta","sid":1,"seq":2014,"msg":{"market_ticker":"KXNEXTTEAMNBA-26LJAM-MIA","market_id":"492cb255-91da-4c91-bc9e-f83d090cc6dd","price_dollars":"0.0100","delta_fp":"1.00","side":"yes","ts":"2026-07-01T02:35:10.574708Z","ts_ms":1782873310574}}

{"type":"orderbook_delta","sid":1,"seq":2015,"msg":{"market_ticker":"KXNEXTTEAMNBA-26LJAM-MIA","market_id":"492cb255-91da-4c91-bc9e-f83d090cc6dd","price_dollars":"0.0100","delta_fp":"1.00","side":"yes","ts":"2026-07-01T02:35:10.575167Z","ts_ms":1782873310575}}

{"type":"orderbook_delta","sid":1,"seq":2016,"msg":{"market_ticker":"KXNEXTTEAMNBA-26LJAM-MIA","market_id":"492cb255-91da-4c91-bc9e-f83d090cc6dd","price_dollars":"0.0100","delta_fp":"1.00","side":"yes","ts":"2026-07-01T02:35:10.575583Z","ts_ms":1782873310575}}

{"type":"orderbook_delta","sid":1,"seq":2017,"msg":{"market_ticker":"KXNEXTTEAMNBA-26LJAM-GSW","market_id":"abbbad28-f309-4dd5-af38-2ad7ebf2acc3","price_dollars":"0.5200","delta_fp":"-2.00","side":"no","ts":"2026-07-01T02:35:10.97511Z","ts_ms":1782873310975}}

{"type":"orderbook_delta","sid":1,"seq":2018,"msg":{"market_ticker":"KXNEXTTEAMNBA-26LJAM-CLE","market_id":"7552b8d4-05de-4e41-84a8-97b0684da4a9","price_dollars":"0.7400","delta_fp":"-0.28","side":"no","ts":"2026-07-01T02:35:11.003504Z","ts_ms":1782873311003}}

{"type":"orderbook_delta","sid":1,"seq":2019,"msg":{"market_ticker":"KXNEXTTEAMNBA-26LJAM-GSW","market_id":"abbbad28-f309-4dd5-af38-2ad7ebf2acc3","price_dollars":"0.5200","delta_fp":"-0.53","side":"no","ts":"2026-07-01T02:35:11.005406Z","ts_ms":1782873311005}}

{"type":"orderbook_delta","sid":1,"seq":2020,"msg":{"market_ticker":"KXNEXTTEAMNBA-26LJAM-GSW","market_id":"abbbad28-f309-4dd5-af38-2ad7ebf2acc3","price_dollars":"0.0100","delta_fp":"-1.00","side":"yes","ts":"2026-07-01T02:35:11.248343Z","ts_ms":1782873311248}}

{"type":"orderbook_delta","sid":1,"seq":2021,"msg":{"market_ticker":"KXNEXTTEAMNBA-26LJAM-GSW","market_id":"abbbad28-f309-4dd5-af38-2ad7ebf2acc3","price_dollars":"0.0100","delta_fp":"-1.00","side":"yes","ts":"2026-07-01T02:35:11.248922Z","ts_ms":1782873311248}}

{"type":"orderbook_delta","sid":1,"seq":2022,"msg":{"market_ticker":"KXNEXTTEAMNBA-26LJAM-GSW","market_id":"abbbad28-f309-4dd5-af38-2ad7ebf2acc3","price_dollars":"0.0100","delta_fp":"-1.00","side":"yes","ts":"2026-07-01T02:35:11.250027Z","ts_ms":1782873311250}}

{"type":"orderbook_delta","sid":1,"seq":2023,"msg":{"market_ticker":"KXNEXTTEAMNBA-26LJAM-GSW","market_id":"abbbad28-f309-4dd5-af38-2ad7ebf2acc3","price_dollars":"0.0100","delta_fp":"-1.00","side":"yes","ts":"2026-07-01T02:35:11.250597Z","ts_ms":1782873311250}}

{"type":"orderbook_delta","sid":1,"seq":2024,"msg":{"market_ticker":"KXNEXTTEAMNBA-26LJAM-GSW","market_id":"abbbad28-f309-4dd5-af38-2ad7ebf2acc3","price_dollars":"0.0100","delta_fp":"-1.00","side":"yes","ts":"2026-07-01T02:35:11.252418Z","ts_ms":1782873311252}}

{"type":"orderbook_delta","sid":1,"seq":2025,"msg":{"market_ticker":"KXNEXTTEAMNBA-26LJAM-GSW","market_id":"abbbad28-f309-4dd5-af38-2ad7ebf2acc3","price_dollars":"0.0100","delta_fp":"-1.00","side":"yes","ts":"2026-07-01T02:35:11.25299Z","ts_ms":1782873311252}}

{"type":"orderbook_delta","sid":1,"seq":2026,"msg":{"market_ticker":"KXNEXTTEAMNBA-26LJAM-GSW","market_id":"abbbad28-f309-4dd5-af38-2ad7ebf2acc3","price_dollars":"0.0100","delta_fp":"-1.00","side":"yes","ts":"2026-07-01T02:35:11.253548Z","ts_ms":1782873311253}}

{"type":"orderbook_delta","sid":1,"seq":2027,"msg":{"market_ticker":"KXNEXTTEAMNBA-26LJAM-GSW","market_id":"abbbad28-f309-4dd5-af38-2ad7ebf2acc3","price_dollars":"0.0100","delta_fp":"-1.00","side":"yes","ts":"2026-07-01T02:35:11.254253Z","ts_ms":1782873311254}}

{"type":"orderbook_delta","sid":1,"seq":2028,"msg":{"market_ticker":"KXNEXTTEAMNBA-26LJAM-GSW","market_id":"abbbad28-f309-4dd5-af38-2ad7ebf2acc3","price_dollars":"0.0100","delta_fp":"-1.00","side":"yes","ts":"2026-07-01T02:35:11.254812Z","ts_ms":1782873311254}}

{"type":"orderbook_delta","sid":1,"seq":2029,"msg":{"market_ticker":"KXNEXTTEAMNBA-26LJAM-GSW","market_id":"abbbad28-f309-4dd5-af38-2ad7ebf2acc3","price_dollars":"0.0100","delta_fp":"-1.00","side":"yes","ts":"2026-07-01T02:35:11.255198Z","ts_ms":1782873311255}}

{"type":"orderbook_delta","sid":1,"seq":2030,"msg":{"market_ticker":"KXNEXTTEAMNBA-26LJAM-GSW","market_id":"abbbad28-f309-4dd5-af38-2ad7ebf2acc3","price_dollars":"0.0100","delta_fp":"-1.00","side":"yes","ts":"2026-07-01T02:35:11.255737Z","ts_ms":1782873311255}}

{"type":"orderbook_delta","sid":1,"seq":2031,"msg":{"market_ticker":"KXNEXTTEAMNBA-26LJAM-GSW","market_id":"abbbad28-f309-4dd5-af38-2ad7ebf2acc3","price_dollars":"0.0100","delta_fp":"-1.00","side":"yes","ts":"2026-07-01T02:35:11.256301Z","ts_ms":1782873311256}}

{"type":"orderbook_delta","sid":1,"seq":2032,"msg":{"market_ticker":"KXNEXTTEAMNBA-26LJAM-GSW","market_id":"abbbad28-f309-4dd5-af38-2ad7ebf2acc3","price_dollars":"0.0100","delta_fp":"-1.00","side":"yes","ts":"2026-07-01T02:35:11.256818Z","ts_ms":1782873311256}}

{"type":"orderbook_delta","sid":1,"seq":2033,"msg":{"market_ticker":"KXNEXTTEAMNBA-26LJAM-GSW","market_id":"abbbad28-f309-4dd5-af38-2ad7ebf2acc3","price_dollars":"0.0100","delta_fp":"-1.00","side":"yes","ts":"2026-07-01T02:35:11.257355Z","ts_ms":1782873311257}}

{"type":"orderbook_delta","sid":1,"seq":2034,"msg":{"market_ticker":"KXNEXTTEAMNBA-26LJAM-GSW","market_id":"abbbad28-f309-4dd5-af38-2ad7ebf2acc3","price_dollars":"0.0100","delta_fp":"-1.00","side":"yes","ts":"2026-07-01T02:35:11.257771Z","ts_ms":1782873311257}}

{"type":"orderbook_delta","sid":1,"seq":2035,"msg":{"market_ticker":"KXNEXTTEAMNBA-26LJAM-GSW","market_id":"abbbad28-f309-4dd5-af38-2ad7ebf2acc3","price_dollars":"0.0100","delta_fp":"-1.00","side":"yes","ts":"2026-07-01T02:35:11.258235Z","ts_ms":1782873311258}}

{"type":"orderbook_delta","sid":1,"seq":2036,"msg":{"market_ticker":"KXNEXTTEAMNBA-26LJAM-GSW","market_id":"abbbad28-f309-4dd5-af38-2ad7ebf2acc3","price_dollars":"0.0100","delta_fp":"-1.00","side":"yes","ts":"2026-07-01T02:35:11.25883Z","ts_ms":1782873311258}}

{"type":"orderbook_delta","sid":1,"seq":2037,"msg":{"market_ticker":"KXNEXTTEAMNBA-26LJAM-GSW","market_id":"abbbad28-f309-4dd5-af38-2ad7ebf2acc3","price_dollars":"0.0100","delta_fp":"-1.00","side":"yes","ts":"2026-07-01T02:35:11.259393Z","ts_ms":1782873311259}}

{"type":"orderbook_delta","sid":1,"seq":2038,"msg":{"market_ticker":"KXNEXTTEAMNBA-26LJAM-GSW","market_id":"abbbad28-f309-4dd5-af38-2ad7ebf2acc3","price_dollars":"0.0100","delta_fp":"-1.00","side":"yes","ts":"2026-07-01T02:35:11.259852Z","ts_ms":1782873311259}}

{"type":"orderbook_delta","sid":1,"seq":2039,"msg":{"market_ticker":"KXNEXTTEAMNBA-26LJAM-GSW","market_id":"abbbad28-f309-4dd5-af38-2ad7ebf2acc3","price_dollars":"0.0100","delta_fp":"-1.00","side":"yes","ts":"2026-07-01T02:35:11.260235Z","ts_ms":1782873311260}}

{"type":"orderbook_delta","sid":1,"seq":2040,"msg":{"market_ticker":"KXNEXTTEAMNBA-26LJAM-GSW","market_id":"abbbad28-f309-4dd5-af38-2ad7ebf2acc3","price_dollars":"0.5200","delta_fp":"-1.32","side":"no","ts":"2026-07-01T02:35:12.363162Z","ts_ms":1782873312363}}

{"type":"orderbook_delta","sid":1,"seq":2041,"msg":{"market_ticker":"KXNEXTTEAMNBA-26LJAM-MIA","market_id":"492cb255-91da-4c91-bc9e-f83d090cc6dd","price_dollars":"0.0100","delta_fp":"-1.00","side":"yes","ts":"2026-07-01T02:35:12.44528Z","ts_ms":1782873312445}}

{"type":"orderbook_delta","sid":1,"seq":2042,"msg":{"market_ticker":"KXNEXTTEAMNBA-26LJAM-MIA","market_id":"492cb255-91da-4c91-bc9e-f83d090cc6dd","price_dollars":"0.0100","delta_fp":"-1.00","side":"yes","ts":"2026-07-01T02:35:12.445722Z","ts_ms":1782873312445}}

{"type":"orderbook_delta","sid":1,"seq":2043,"msg":{"market_ticker":"KXNEXTTEAMNBA-26LJAM-MIA","market_id":"492cb255-91da-4c91-bc9e-f83d090cc6dd","price_dollars":"0.0100","delta_fp":"-1.00","side":"yes","ts":"2026-07-01T02:35:12.446197Z","ts_ms":1782873312446}}

{"type":"orderbook_delta","sid":1,"seq":2044,"msg":{"market_ticker":"KXNEXTTEAMNBA-26LJAM-MIA","market_id":"492cb255-91da-4c91-bc9e-f83d090cc6dd","price_dollars":"0.0100","delta_fp":"-1.00","side":"yes","ts":"2026-07-01T02:35:12.44648Z","ts_ms":1782873312446}}

{"type":"orderbook_delta","sid":1,"seq":2045,"msg":{"market_ticker":"KXNEXTTEAMNBA-26LJAM-MIA","market_id":"492cb255-91da-4c91-bc9e-f83d090cc6dd","price_dollars":"0.0100","delta_fp":"-1.00","side":"yes","ts":"2026-07-01T02:35:12.446856Z","ts_ms":1782873312446}}

{"type":"orderbook_delta","sid":1,"seq":2046,"msg":{"market_ticker":"KXNEXTTEAMNBA-26LJAM-MIA","market_id":"492cb255-91da-4c91-bc9e-f83d090cc6dd","price_dollars":"0.0100","delta_fp":"-1.00","side":"yes","ts":"2026-07-01T02:35:12.447367Z","ts_ms":1782873312447}}

{"type":"orderbook_delta","sid":1,"seq":2047,"msg":{"market_ticker":"KXNEXTTEAMNBA-26LJAM-MIA","market_id":"492cb255-91da-4c91-bc9e-f83d090cc6dd","price_dollars":"0.0100","delta_fp":"-1.00","side":"yes","ts":"2026-07-01T02:35:12.447865Z","ts_ms":1782873312447}}

{"type":"orderbook_delta","sid":1,"seq":2048,"msg":{"market_ticker":"KXNEXTTEAMNBA-26LJAM-MIA","market_id":"492cb255-91da-4c91-bc9e-f83d090cc6dd","price_dollars":"0.0100","delta_fp":"-1.00","side":"yes","ts":"2026-07-01T02:35:12.448437Z","ts_ms":1782873312448}}

{"type":"orderbook_delta","sid":1,"seq":2049,"msg":{"market_ticker":"KXNEXTTEAMNBA-26LJAM-MIA","market_id":"492cb255-91da-4c91-bc9e-f83d090cc6dd","price_dollars":"0.0100","delta_fp":"-1.00","side":"yes","ts":"2026-07-01T02:35:12.448964Z","ts_ms":1782873312448}}

{"type":"orderbook_delta","sid":1,"seq":2050,"msg":{"market_ticker":"KXNEXTTEAMNBA-26LJAM-MIA","market_id":"492cb255-91da-4c91-bc9e-f83d090cc6dd","price_dollars":"0.0100","delta_fp":"-1.00","side":"yes","ts":"2026-07-01T02:35:12.449794Z","ts_ms":1782873312449}}

{"type":"orderbook_delta","sid":1,"seq":2051,"msg":{"market_ticker":"KXNEXTTEAMNBA-26LJAM-MIA","market_id":"492cb255-91da-4c91-bc9e-f83d090cc6dd","price_dollars":"0.0100","delta_fp":"-1.00","side":"yes","ts":"2026-07-01T02:35:12.450335Z","ts_ms":1782873312450}}

{"type":"orderbook_delta","sid":1,"seq":2052,"msg":{"market_ticker":"KXNEXTTEAMNBA-26LJAM-MIA","market_id":"492cb255-91da-4c91-bc9e-f83d090cc6dd","price_dollars":"0.0100","delta_fp":"-1.00","side":"yes","ts":"2026-07-01T02:35:12.450665Z","ts_ms":1782873312450}}

{"type":"orderbook_delta","sid":1,"seq":2053,"msg":{"market_ticker":"KXNEXTTEAMNBA-26LJAM-MIA","market_id":"492cb255-91da-4c91-bc9e-f83d090cc6dd","price_dollars":"0.0100","delta_fp":"-1.00","side":"yes","ts":"2026-07-01T02:35:12.451108Z","ts_ms":1782873312451}}

{"type":"orderbook_delta","sid":1,"seq":2054,"msg":{"market_ticker":"KXNEXTTEAMNBA-26LJAM-MIA","market_id":"492cb255-91da-4c91-bc9e-f83d090cc6dd","price_dollars":"0.0100","delta_fp":"-1.00","side":"yes","ts":"2026-07-01T02:35:12.45159Z","ts_ms":1782873312451}}

{"type":"orderbook_delta","sid":1,"seq":2055,"msg":{"market_ticker":"KXNEXTTEAMNBA-26LJAM-MIA","market_id":"492cb255-91da-4c91-bc9e-f83d090cc6dd","price_dollars":"0.0100","delta_fp":"-1.00","side":"yes","ts":"2026-07-01T02:35:12.452242Z","ts_ms":1782873312452}}

{"type":"orderbook_delta","sid":1,"seq":2056,"msg":{"market_ticker":"KXNEXTTEAMNBA-26LJAM-MIA","market_id":"492cb255-91da-4c91-bc9e-f83d090cc6dd","price_dollars":"0.0100","delta_fp":"-1.00","side":"yes","ts":"2026-07-01T02:35:12.452765Z","ts_ms":1782873312452}}

{"type":"orderbook_delta","sid":1,"seq":2057,"msg":{"market_ticker":"KXNEXTTEAMNBA-26LJAM-MIA","market_id":"492cb255-91da-4c91-bc9e-f83d090cc6dd","price_dollars":"0.0100","delta_fp":"-1.00","side":"yes","ts":"2026-07-01T02:35:12.453281Z","ts_ms":1782873312453}}

{"type":"orderbook_delta","sid":1,"seq":2058,"msg":{"market_ticker":"KXNEXTTEAMNBA-26LJAM-MIA","market_id":"492cb255-91da-4c91-bc9e-f83d090cc6dd","price_dollars":"0.0100","delta_fp":"-1.00","side":"yes","ts":"2026-07-01T02:35:12.453888Z","ts_ms":1782873312453}}

{"type":"orderbook_delta","sid":1,"seq":2059,"msg":{"market_ticker":"KXNEXTTEAMNBA-26LJAM-MIA","market_id":"492cb255-91da-4c91-bc9e-f83d090cc6dd","price_dollars":"0.0100","delta_fp":"-1.00","side":"yes","ts":"2026-07-01T02:35:12.454536Z","ts_ms":1782873312454}}

{"type":"orderbook_delta","sid":1,"seq":2060,"msg":{"market_ticker":"KXNEXTTEAMNBA-26LJAM-MIA","market_id":"492cb255-91da-4c91-bc9e-f83d090cc6dd","price_dollars":"0.0100","delta_fp":"-1.00","side":"yes","ts":"2026-07-01T02:35:12.45514Z","ts_ms":1782873312455}}

{"type":"orderbook_delta","sid":1,"seq":2061,"msg":{"market_ticker":"KXNEXTTEAMNBA-26LJAM-CLE","market_id":"7552b8d4-05de-4e41-84a8-97b0684da4a9","price_dollars":"0.7400","delta_fp":"-0.91","side":"no","ts":"2026-07-01T02:35:12.561447Z","ts_ms":1782873312561}}

{"type":"orderbook_delta","sid":1,"seq":2062,"msg":{"market_ticker":"KXNEXTTEAMNBA-26LJAM-MIA","market_id":"492cb255-91da-4c91-bc9e-f83d090cc6dd","price_dollars":"0.8300","delta_fp":"-1.47","side":"no","ts":"2026-07-01T02:35:12.681672Z","ts_ms":1782873312681}}

{"type":"orderbook_delta","sid":1,"seq":2063,"msg":{"market_ticker":"KXNEXTTEAMNBA-26LJAM-CLE","market_id":"7552b8d4-05de-4e41-84a8-97b0684da4a9","price_dollars":"0.7400","delta_fp":"-0.65","side":"no","ts":"2026-07-01T02:35:14.271848Z","ts_ms":1782873314271}}

{"type":"orderbook_delta","sid":1,"seq":2064,"msg":{"market_ticker":"KXNEXTTEAMNBA-26LJAM-GSW","market_id":"abbbad28-f309-4dd5-af38-2ad7ebf2acc3","price_dollars":"0.0100","delta_fp":"1.00","side":"yes","ts":"2026-07-01T02:35:15.468879Z","ts_ms":1782873315468}}

{"type":"orderbook_delta","sid":1,"seq":2065,"msg":{"market_ticker":"KXNEXTTEAMNBA-26LJAM-GSW","market_id":"abbbad28-f309-4dd5-af38-2ad7ebf2acc3","price_dollars":"0.0100","delta_fp":"1.00","side":"yes","ts":"2026-07-01T02:35:15.469695Z","ts_ms":1782873315469}}

{"type":"orderbook_delta","sid":1,"seq":2066,"msg":{"market_ticker":"KXNEXTTEAMNBA-26LJAM-GSW","market_id":"abbbad28-f309-4dd5-af38-2ad7ebf2acc3","price_dollars":"0.0100","delta_fp":"1.00","side":"yes","ts":"2026-07-01T02:35:15.470723Z","ts_ms":1782873315470}}

{"type":"orderbook_delta","sid":1,"seq":2067,"msg":{"market_ticker":"KXNEXTTEAMNBA-26LJAM-GSW","market_id":"abbbad28-f309-4dd5-af38-2ad7ebf2acc3","price_dollars":"0.0100","delta_fp":"1.00","side":"yes","ts":"2026-07-01T02:35:15.471867Z","ts_ms":1782873315471}}

{"type":"orderbook_delta","sid":1,"seq":2068,"msg":{"market_ticker":"KXNEXTTEAMNBA-26LJAM-GSW","market_id":"abbbad28-f309-4dd5-af38-2ad7ebf2acc3","price_dollars":"0.0100","delta_fp":"1.00","side":"yes","ts":"2026-07-01T02:35:15.472765Z","ts_ms":1782873315472}}

{"type":"orderbook_delta","sid":1,"seq":2069,"msg":{"market_ticker":"KXNEXTTEAMNBA-26LJAM-GSW","market_id":"abbbad28-f309-4dd5-af38-2ad7ebf2acc3","price_dollars":"0.0100","delta_fp":"1.00","side":"yes","ts":"2026-07-01T02:35:15.473523Z","ts_ms":1782873315473}}

{"type":"orderbook_delta","sid":1,"seq":2070,"msg":{"market_ticker":"KXNEXTTEAMNBA-26LJAM-GSW","market_id":"abbbad28-f309-4dd5-af38-2ad7ebf2acc3","price_dollars":"0.0100","delta_fp":"1.00","side":"yes","ts":"2026-07-01T02:35:15.474355Z","ts_ms":1782873315474}}

{"type":"orderbook_delta","sid":1,"seq":2071,"msg":{"market_ticker":"KXNEXTTEAMNBA-26LJAM-GSW","market_id":"abbbad28-f309-4dd5-af38-2ad7ebf2acc3","price_dollars":"0.0100","delta_fp":"1.00","side":"yes","ts":"2026-07-01T02:35:15.475007Z","ts_ms":1782873315475}}

{"type":"orderbook_delta","sid":1,"seq":2072,"msg":{"market_ticker":"KXNEXTTEAMNBA-26LJAM-GSW","market_id":"abbbad28-f309-4dd5-af38-2ad7ebf2acc3","price_dollars":"0.0100","delta_fp":"1.00","side":"yes","ts":"2026-07-01T02:35:15.475623Z","ts_ms":1782873315475}}

{"type":"orderbook_delta","sid":1,"seq":2073,"msg":{"market_ticker":"KXNEXTTEAMNBA-26LJAM-GSW","market_id":"abbbad28-f309-4dd5-af38-2ad7ebf2acc3","price_dollars":"0.0100","delta_fp":"1.00","side":"yes","ts":"2026-07-01T02:35:15.476353Z","ts_ms":1782873315476}}

{"type":"orderbook_delta","sid":1,"seq":2074,"msg":{"market_ticker":"KXNEXTTEAMNBA-26LJAM-GSW","market_id":"abbbad28-f309-4dd5-af38-2ad7ebf2acc3","price_dollars":"0.0100","delta_fp":"1.00","side":"yes","ts":"2026-07-01T02:35:15.477157Z","ts_ms":1782873315477}}

{"type":"orderbook_delta","sid":1,"seq":2075,"msg":{"market_ticker":"KXNEXTTEAMNBA-26LJAM-GSW","market_id":"abbbad28-f309-4dd5-af38-2ad7ebf2acc3","price_dollars":"0.0100","delta_fp":"1.00","side":"yes","ts":"2026-07-01T02:35:15.477845Z","ts_ms":1782873315477}}

{"type":"orderbook_delta","sid":1,"seq":2076,"msg":{"market_ticker":"KXNEXTTEAMNBA-26LJAM-GSW","market_id":"abbbad28-f309-4dd5-af38-2ad7ebf2acc3","price_dollars":"0.0100","delta_fp":"1.00","side":"yes","ts":"2026-07-01T02:35:15.478279Z","ts_ms":1782873315478}}

{"type":"orderbook_delta","sid":1,"seq":2077,"msg":{"market_ticker":"KXNEXTTEAMNBA-26LJAM-GSW","market_id":"abbbad28-f309-4dd5-af38-2ad7ebf2acc3","price_dollars":"0.0100","delta_fp":"1.00","side":"yes","ts":"2026-07-01T02:35:15.478895Z","ts_ms":1782873315478}}

{"type":"orderbook_delta","sid":1,"seq":2078,"msg":{"market_ticker":"KXNEXTTEAMNBA-26LJAM-GSW","market_id":"abbbad28-f309-4dd5-af38-2ad7ebf2acc3","price_dollars":"0.0100","delta_fp":"1.00","side":"yes","ts":"2026-07-01T02:35:15.479539Z","ts_ms":1782873315479}}

{"type":"orderbook_delta","sid":1,"seq":2079,"msg":{"market_ticker":"KXNEXTTEAMNBA-26LJAM-GSW","market_id":"abbbad28-f309-4dd5-af38-2ad7ebf2acc3","price_dollars":"0.0100","delta_fp":"1.00","side":"yes","ts":"2026-07-01T02:35:15.480155Z","ts_ms":1782873315480}}

{"type":"orderbook_delta","sid":1,"seq":2080,"msg":{"market_ticker":"KXNEXTTEAMNBA-26LJAM-GSW","market_id":"abbbad28-f309-4dd5-af38-2ad7ebf2acc3","price_dollars":"0.0100","delta_fp":"1.00","side":"yes","ts":"2026-07-01T02:35:15.480495Z","ts_ms":1782873315480}}

{"type":"orderbook_delta","sid":1,"seq":2081,"msg":{"market_ticker":"KXNEXTTEAMNBA-26LJAM-GSW","market_id":"abbbad28-f309-4dd5-af38-2ad7ebf2acc3","price_dollars":"0.0100","delta_fp":"1.00","side":"yes","ts":"2026-07-01T02:35:15.480955Z","ts_ms":1782873315480}}

{"type":"orderbook_delta","sid":1,"seq":2082,"msg":{"market_ticker":"KXNEXTTEAMNBA-26LJAM-GSW","market_id":"abbbad28-f309-4dd5-af38-2ad7ebf2acc3","price_dollars":"0.0100","delta_fp":"1.00","side":"yes","ts":"2026-07-01T02:35:15.481349Z","ts_ms":1782873315481}}

{"type":"orderbook_delta","sid":1,"seq":2083,"msg":{"market_ticker":"KXNEXTTEAMNBA-26LJAM-GSW","market_id":"abbbad28-f309-4dd5-af38-2ad7ebf2acc3","price_dollars":"0.0100","delta_fp":"1.00","side":"yes","ts":"2026-07-01T02:35:15.481801Z","ts_ms":1782873315481}}

{"type":"orderbook_delta","sid":1,"seq":2084,"msg":{"market_ticker":"KXNEXTTEAMNBA-26LJAM-GSW","market_id":"abbbad28-f309-4dd5-af38-2ad7ebf2acc3","price_dollars":"0.5200","delta_fp":"-0.91","side":"no","ts":"2026-07-01T02:35:15.763772Z","ts_ms":1782873315763}}

{"type":"orderbook_delta","sid":1,"seq":2085,"msg":{"market_ticker":"KXNEXTTEAMNBA-26LJAM-CLE","market_id":"7552b8d4-05de-4e41-84a8-97b0684da4a9","price_dollars":"0.7400","delta_fp":"-0.62","side":"no","ts":"2026-07-01T02:35:15.776359Z","ts_ms":1782873315776}}

{"type":"orderbook_delta","sid":1,"seq":2086,"msg":{"market_ticker":"KXNEXTTEAMNBA-26LJAM-MIA","market_id":"492cb255-91da-4c91-bc9e-f83d090cc6dd","price_dollars":"0.0100","delta_fp":"1.00","side":"yes","ts":"2026-07-01T02:35:16.642918Z","ts_ms":1782873316642}}

{"type":"orderbook_delta","sid":1,"seq":2087,"msg":{"market_ticker":"KXNEXTTEAMNBA-26LJAM-MIA","market_id":"492cb255-91da-4c91-bc9e-f83d090cc6dd","price_dollars":"0.0100","delta_fp":"1.00","side":"yes","ts":"2026-07-01T02:35:16.643523Z","ts_ms":1782873316643}}

{"type":"orderbook_delta","sid":1,"seq":2088,"msg":{"market_ticker":"KXNEXTTEAMNBA-26LJAM-MIA","market_id":"492cb255-91da-4c91-bc9e-f83d090cc6dd","price_dollars":"0.0100","delta_fp":"1.00","side":"yes","ts":"2026-07-01T02:35:16.64405Z","ts_ms":1782873316644}}

{"type":"orderbook_delta","sid":1,"seq":2089,"msg":{"market_ticker":"KXNEXTTEAMNBA-26LJAM-MIA","market_id":"492cb255-91da-4c91-bc9e-f83d090cc6dd","price_dollars":"0.0100","delta_fp":"1.00","side":"yes","ts":"2026-07-01T02:35:16.644729Z","ts_ms":1782873316644}}

{"type":"orderbook_delta","sid":1,"seq":2090,"msg":{"market_ticker":"KXNEXTTEAMNBA-26LJAM-MIA","market_id":"492cb255-91da-4c91-bc9e-f83d090cc6dd","price_dollars":"0.0100","delta_fp":"1.00","side":"yes","ts":"2026-07-01T02:35:16.645174Z","ts_ms":1782873316645}}

{"type":"orderbook_delta","sid":1,"seq":2091,"msg":{"market_ticker":"KXNEXTTEAMNBA-26LJAM-MIA","market_id":"492cb255-91da-4c91-bc9e-f83d090cc6dd","price_dollars":"0.0100","delta_fp":"1.00","side":"yes","ts":"2026-07-01T02:35:16.645865Z","ts_ms":1782873316645}}

{"type":"orderbook_delta","sid":1,"seq":2092,"msg":{"market_ticker":"KXNEXTTEAMNBA-26LJAM-MIA","market_id":"492cb255-91da-4c91-bc9e-f83d090cc6dd","price_dollars":"0.0100","delta_fp":"1.00","side":"yes","ts":"2026-07-01T02:35:16.646433Z","ts_ms":1782873316646}}

{"type":"orderbook_delta","sid":1,"seq":2093,"msg":{"market_ticker":"KXNEXTTEAMNBA-26LJAM-MIA","market_id":"492cb255-91da-4c91-bc9e-f83d090cc6dd","price_dollars":"0.0100","delta_fp":"1.00","side":"yes","ts":"2026-07-01T02:35:16.646707Z","ts_ms":1782873316646}}

{"type":"orderbook_delta","sid":1,"seq":2094,"msg":{"market_ticker":"KXNEXTTEAMNBA-26LJAM-MIA","market_id":"492cb255-91da-4c91-bc9e-f83d090cc6dd","price_dollars":"0.0100","delta_fp":"1.00","side":"yes","ts":"2026-07-01T02:35:16.647024Z","ts_ms":1782873316647}}

{"type":"orderbook_delta","sid":1,"seq":2095,"msg":{"market_ticker":"KXNEXTTEAMNBA-26LJAM-MIA","market_id":"492cb255-91da-4c91-bc9e-f83d090cc6dd","price_dollars":"0.0100","delta_fp":"1.00","side":"yes","ts":"2026-07-01T02:35:16.647668Z","ts_ms":1782873316647}}

{"type":"orderbook_delta","sid":1,"seq":2096,"msg":{"market_ticker":"KXNEXTTEAMNBA-26LJAM-MIA","market_id":"492cb255-91da-4c91-bc9e-f83d090cc6dd","price_dollars":"0.0100","delta_fp":"1.00","side":"yes","ts":"2026-07-01T02:35:16.648266Z","ts_ms":1782873316648}}

{"type":"orderbook_delta","sid":1,"seq":2097,"msg":{"market_ticker":"KXNEXTTEAMNBA-26LJAM-MIA","market_id":"492cb255-91da-4c91-bc9e-f83d090cc6dd","price_dollars":"0.0100","delta_fp":"1.00","side":"yes","ts":"2026-07-01T02:35:16.648829Z","ts_ms":1782873316648}}

{"type":"orderbook_delta","sid":1,"seq":2098,"msg":{"market_ticker":"KXNEXTTEAMNBA-26LJAM-MIA","market_id":"492cb255-91da-4c91-bc9e-f83d090cc6dd","price_dollars":"0.0100","delta_fp":"1.00","side":"yes","ts":"2026-07-01T02:35:16.649485Z","ts_ms":1782873316649}}

{"type":"orderbook_delta","sid":1,"seq":2099,"msg":{"market_ticker":"KXNEXTTEAMNBA-26LJAM-MIA","market_id":"492cb255-91da-4c91-bc9e-f83d090cc6dd","price_dollars":"0.0100","delta_fp":"1.00","side":"yes","ts":"2026-07-01T02:35:16.649993Z","ts_ms":1782873316649}}

{"type":"orderbook_delta","sid":1,"seq":2100,"msg":{"market_ticker":"KXNEXTTEAMNBA-26LJAM-MIA","market_id":"492cb255-91da-4c91-bc9e-f83d090cc6dd","price_dollars":"0.0100","delta_fp":"1.00","side":"yes","ts":"2026-07-01T02:35:16.650712Z","ts_ms":1782873316650}}

{"type":"orderbook_delta","sid":1,"seq":2101,"msg":{"market_ticker":"KXNEXTTEAMNBA-26LJAM-MIA","market_id":"492cb255-91da-4c91-bc9e-f83d090cc6dd","price_dollars":"0.0100","delta_fp":"1.00","side":"yes","ts":"2026-07-01T02:35:16.6512Z","ts_ms":1782873316651}}

{"type":"orderbook_delta","sid":1,"seq":2102,"msg":{"market_ticker":"KXNEXTTEAMNBA-26LJAM-MIA","market_id":"492cb255-91da-4c91-bc9e-f83d090cc6dd","price_dollars":"0.0100","delta_fp":"1.00","side":"yes","ts":"2026-07-01T02:35:16.651677Z","ts_ms":1782873316651}}

{"type":"orderbook_delta","sid":1,"seq":2103,"msg":{"market_ticker":"KXNEXTTEAMNBA-26LJAM-MIA","market_id":"492cb255-91da-4c91-bc9e-f83d090cc6dd","price_dollars":"0.0100","delta_fp":"1.00","side":"yes","ts":"2026-07-01T02:35:16.652222Z","ts_ms":1782873316652}}

{"type":"orderbook_delta","sid":1,"seq":2104,"msg":{"market_ticker":"KXNEXTTEAMNBA-26LJAM-MIA","market_id":"492cb255-91da-4c91-bc9e-f83d090cc6dd","price_dollars":"0.0100","delta_fp":"1.00","side":"yes","ts":"2026-07-01T02:35:16.652724Z","ts_ms":1782873316652}}

{"type":"orderbook_delta","sid":1,"seq":2105,"msg":{"market_ticker":"KXNEXTTEAMNBA-26LJAM-MIA","market_id":"492cb255-91da-4c91-bc9e-f83d090cc6dd","price_dollars":"0.0100","delta_fp":"1.00","side":"yes","ts":"2026-07-01T02:35:16.653207Z","ts_ms":1782873316653}}

{"type":"orderbook_delta","sid":1,"seq":2106,"msg":{"market_ticker":"KXNEXTTEAMNBA-26LJAM-CLE","market_id":"7552b8d4-05de-4e41-84a8-97b0684da4a9","price_dollars":"0.7400","delta_fp":"-1.00","side":"no","ts":"2026-07-01T02:35:17.078094Z","ts_ms":1782873317078}}

{"type":"orderbook_delta","sid":1,"seq":2107,"msg":{"market_ticker":"KXNEXTTEAMNBA-26LJAM-CLE","market_id":"7552b8d4-05de-4e41-84a8-97b0684da4a9","price_dollars":"0.7400","delta_fp":"-1.05","side":"no","ts":"2026-07-01T02:35:17.36902Z","ts_ms":1782873317369}}

{"type":"orderbook_delta","sid":1,"seq":2108,"msg":{"market_ticker":"KXNEXTTEAMNBA-26LJAM-MIA","market_id":"492cb255-91da-4c91-bc9e-f83d090cc6dd","price_dollars":"0.8300","delta_fp":"-0.71","side":"no","ts":"2026-07-01T02:35:20.581779Z","ts_ms":1782873320581}}

{"type":"orderbook_delta","sid":1,"seq":2109,"msg":{"market_ticker":"KXNEXTTEAMNBA-26LJAM-CLE","market_id":"7552b8d4-05de-4e41-84a8-97b0684da4a9","price_dollars":"0.7400","delta_fp":"-0.54","side":"no","ts":"2026-07-01T02:35:20.604346Z","ts_ms":1782873320604}}

{"type":"orderbook_delta","sid":1,"seq":2110,"msg":{"market_ticker":"KXNEXTTEAMNBA-26LJAM-GSW","market_id":"abbbad28-f309-4dd5-af38-2ad7ebf2acc3","price_dollars":"0.0100","delta_fp":"1.00","side":"yes","ts":"2026-07-01T02:35:21.958848Z","ts_ms":1782873321958}}

{"type":"orderbook_delta","sid":1,"seq":2111,"msg":{"market_ticker":"KXNEXTTEAMNBA-26LJAM-GSW","market_id":"abbbad28-f309-4dd5-af38-2ad7ebf2acc3","price_dollars":"0.0100","delta_fp":"1.00","side":"yes","ts":"2026-07-01T02:35:21.960059Z","ts_ms":1782873321960}}

{"type":"orderbook_delta","sid":1,"seq":2112,"msg":{"market_ticker":"KXNEXTTEAMNBA-26LJAM-GSW","market_id":"abbbad28-f309-4dd5-af38-2ad7ebf2acc3","price_dollars":"0.0100","delta_fp":"1.00","side":"yes","ts":"2026-07-01T02:35:21.961385Z","ts_ms":1782873321961}}

{"type":"orderbook_delta","sid":1,"seq":2113,"msg":{"market_ticker":"KXNEXTTEAMNBA-26LJAM-GSW","market_id":"abbbad28-f309-4dd5-af38-2ad7ebf2acc3","price_dollars":"0.0100","delta_fp":"1.00","side":"yes","ts":"2026-07-01T02:35:21.962332Z","ts_ms":1782873321962}}

{"type":"orderbook_delta","sid":1,"seq":2114,"msg":{"market_ticker":"KXNEXTTEAMNBA-26LJAM-GSW","market_id":"abbbad28-f309-4dd5-af38-2ad7ebf2acc3","price_dollars":"0.0100","delta_fp":"1.00","side":"yes","ts":"2026-07-01T02:35:21.962891Z","ts_ms":1782873321962}}

{"type":"orderbook_delta","sid":1,"seq":2115,"msg":{"market_ticker":"KXNEXTTEAMNBA-26LJAM-GSW","market_id":"abbbad28-f309-4dd5-af38-2ad7ebf2acc3","price_dollars":"0.0100","delta_fp":"1.00","side":"yes","ts":"2026-07-01T02:35:21.963574Z","ts_ms":1782873321963}}

{"type":"orderbook_delta","sid":1,"seq":2116,"msg":{"market_ticker":"KXNEXTTEAMNBA-26LJAM-GSW","market_id":"abbbad28-f309-4dd5-af38-2ad7ebf2acc3","price_dollars":"0.0100","delta_fp":"1.00","side":"yes","ts":"2026-07-01T02:35:21.964226Z","ts_ms":1782873321964}}

{"type":"orderbook_delta","sid":1,"seq":2117,"msg":{"market_ticker":"KXNEXTTEAMNBA-26LJAM-GSW","market_id":"abbbad28-f309-4dd5-af38-2ad7ebf2acc3","price_dollars":"0.0100","delta_fp":"1.00","side":"yes","ts":"2026-07-01T02:35:21.964703Z","ts_ms":1782873321964}}

{"type":"orderbook_delta","sid":1,"seq":2118,"msg":{"market_ticker":"KXNEXTTEAMNBA-26LJAM-GSW","market_id":"abbbad28-f309-4dd5-af38-2ad7ebf2acc3","price_dollars":"0.0100","delta_fp":"1.00","side":"yes","ts":"2026-07-01T02:35:21.965202Z","ts_ms":1782873321965}}

{"type":"orderbook_delta","sid":1,"seq":2119,"msg":{"market_ticker":"KXNEXTTEAMNBA-26LJAM-GSW","market_id":"abbbad28-f309-4dd5-af38-2ad7ebf2acc3","price_dollars":"0.0100","delta_fp":"1.00","side":"yes","ts":"2026-07-01T02:35:21.96602Z","ts_ms":1782873321966}}

{"type":"orderbook_delta","sid":1,"seq":2120,"msg":{"market_ticker":"KXNEXTTEAMNBA-26LJAM-GSW","market_id":"abbbad28-f309-4dd5-af38-2ad7ebf2acc3","price_dollars":"0.0100","delta_fp":"1.00","side":"yes","ts":"2026-07-01T02:35:21.966786Z","ts_ms":1782873321966}}

{"type":"orderbook_delta","sid":1,"seq":2121,"msg":{"market_ticker":"KXNEXTTEAMNBA-26LJAM-GSW","market_id":"abbbad28-f309-4dd5-af38-2ad7ebf2acc3","price_dollars":"0.0100","delta_fp":"1.00","side":"yes","ts":"2026-07-01T02:35:21.967388Z","ts_ms":1782873321967}}

{"type":"orderbook_delta","sid":1,"seq":2122,"msg":{"market_ticker":"KXNEXTTEAMNBA-26LJAM-GSW","market_id":"abbbad28-f309-4dd5-af38-2ad7ebf2acc3","price_dollars":"0.0100","delta_fp":"1.00","side":"yes","ts":"2026-07-01T02:35:21.967859Z","ts_ms":1782873321967}}

{"type":"orderbook_delta","sid":1,"seq":2123,"msg":{"market_ticker":"KXNEXTTEAMNBA-26LJAM-GSW","market_id":"abbbad28-f309-4dd5-af38-2ad7ebf2acc3","price_dollars":"0.0100","delta_fp":"1.00","side":"yes","ts":"2026-07-01T02:35:21.968629Z","ts_ms":1782873321968}}

{"type":"orderbook_delta","sid":1,"seq":2124,"msg":{"market_ticker":"KXNEXTTEAMNBA-26LJAM-GSW","market_id":"abbbad28-f309-4dd5-af38-2ad7ebf2acc3","price_dollars":"0.0100","delta_fp":"1.00","side":"yes","ts":"2026-07-01T02:35:21.969209Z","ts_ms":1782873321969}}

{"type":"orderbook_delta","sid":1,"seq":2125,"msg":{"market_ticker":"KXNEXTTEAMNBA-26LJAM-GSW","market_id":"abbbad28-f309-4dd5-af38-2ad7ebf2acc3","price_dollars":"0.0100","delta_fp":"1.00","side":"yes","ts":"2026-07-01T02:35:21.969733Z","ts_ms":1782873321969}}

{"type":"orderbook_delta","sid":1,"seq":2126,"msg":{"market_ticker":"KXNEXTTEAMNBA-26LJAM-GSW","market_id":"abbbad28-f309-4dd5-af38-2ad7ebf2acc3","price_dollars":"0.0100","delta_fp":"1.00","side":"yes","ts":"2026-07-01T02:35:21.970205Z","ts_ms":1782873321970}}

{"type":"orderbook_delta","sid":1,"seq":2127,"msg":{"market_ticker":"KXNEXTTEAMNBA-26LJAM-GSW","market_id":"abbbad28-f309-4dd5-af38-2ad7ebf2acc3","price_dollars":"0.0100","delta_fp":"1.00","side":"yes","ts":"2026-07-01T02:35:21.97061Z","ts_ms":1782873321970}}

{"type":"orderbook_delta","sid":1,"seq":2128,"msg":{"market_ticker":"KXNEXTTEAMNBA-26LJAM-GSW","market_id":"abbbad28-f309-4dd5-af38-2ad7ebf2acc3","price_dollars":"0.0100","delta_fp":"1.00","side":"yes","ts":"2026-07-01T02:35:21.971117Z","ts_ms":1782873321971}}

{"type":"orderbook_delta","sid":1,"seq":2129,"msg":{"market_ticker":"KXNEXTTEAMNBA-26LJAM-GSW","market_id":"abbbad28-f309-4dd5-af38-2ad7ebf2acc3","price_dollars":"0.0100","delta_fp":"1.00","side":"yes","ts":"2026-07-01T02:35:21.971694Z","ts_ms":1782873321971}}

{"type":"orderbook_delta","sid":1,"seq":2130,"msg":{"market_ticker":"KXNEXTTEAMNBA-26LJAM-MIA","market_id":"492cb255-91da-4c91-bc9e-f83d090cc6dd","price_dollars":"0.0100","delta_fp":"1.00","side":"yes","ts":"2026-07-01T02:35:23.149529Z","ts_ms":1782873323149}}

{"type":"orderbook_delta","sid":1,"seq":2131,"msg":{"market_ticker":"KXNEXTTEAMNBA-26LJAM-MIA","market_id":"492cb255-91da-4c91-bc9e-f83d090cc6dd","price_dollars":"0.0100","delta_fp":"1.00","side":"yes","ts":"2026-07-01T02:35:23.15001Z","ts_ms":1782873323150}}

{"type":"orderbook_delta","sid":1,"seq":2132,"msg":{"market_ticker":"KXNEXTTEAMNBA-26LJAM-MIA","market_id":"492cb255-91da-4c91-bc9e-f83d090cc6dd","price_dollars":"0.0100","delta_fp":"1.00","side":"yes","ts":"2026-07-01T02:35:23.150491Z","ts_ms":1782873323150}}

{"type":"orderbook_delta","sid":1,"seq":2133,"msg":{"market_ticker":"KXNEXTTEAMNBA-26LJAM-MIA","market_id":"492cb255-91da-4c91-bc9e-f83d090cc6dd","price_dollars":"0.0100","delta_fp":"1.00","side":"yes","ts":"2026-07-01T02:35:23.151096Z","ts_ms":1782873323151}}

{"type":"orderbook_delta","sid":1,"seq":2134,"msg":{"market_ticker":"KXNEXTTEAMNBA-26LJAM-MIA","market_id":"492cb255-91da-4c91-bc9e-f83d090cc6dd","price_dollars":"0.0100","delta_fp":"1.00","side":"yes","ts":"2026-07-01T02:35:23.151625Z","ts_ms":1782873323151}}

{"type":"orderbook_delta","sid":1,"seq":2135,"msg":{"market_ticker":"KXNEXTTEAMNBA-26LJAM-MIA","market_id":"492cb255-91da-4c91-bc9e-f83d090cc6dd","price_dollars":"0.0100","delta_fp":"1.00","side":"yes","ts":"2026-07-01T02:35:23.152034Z","ts_ms":1782873323152}}

{"type":"orderbook_delta","sid":1,"seq":2136,"msg":{"market_ticker":"KXNEXTTEAMNBA-26LJAM-MIA","market_id":"492cb255-91da-4c91-bc9e-f83d090cc6dd","price_dollars":"0.0100","delta_fp":"1.00","side":"yes","ts":"2026-07-01T02:35:23.152451Z","ts_ms":1782873323152}}

{"type":"orderbook_delta","sid":1,"seq":2137,"msg":{"market_ticker":"KXNEXTTEAMNBA-26LJAM-MIA","market_id":"492cb255-91da-4c91-bc9e-f83d090cc6dd","price_dollars":"0.0100","delta_fp":"1.00","side":"yes","ts":"2026-07-01T02:35:23.152808Z","ts_ms":1782873323152}}

{"type":"orderbook_delta","sid":1,"seq":2138,"msg":{"market_ticker":"KXNEXTTEAMNBA-26LJAM-MIA","market_id":"492cb255-91da-4c91-bc9e-f83d090cc6dd","price_dollars":"0.0100","delta_fp":"1.00","side":"yes","ts":"2026-07-01T02:35:23.153198Z","ts_ms":1782873323153}}

{"type":"orderbook_delta","sid":1,"seq":2139,"msg":{"market_ticker":"KXNEXTTEAMNBA-26LJAM-MIA","market_id":"492cb255-91da-4c91-bc9e-f83d090cc6dd","price_dollars":"0.0100","delta_fp":"1.00","side":"yes","ts":"2026-07-01T02:35:23.153663Z","ts_ms":1782873323153}}

{"type":"orderbook_delta","sid":1,"seq":2140,"msg":{"market_ticker":"KXNEXTTEAMNBA-26LJAM-MIA","market_id":"492cb255-91da-4c91-bc9e-f83d090cc6dd","price_dollars":"0.0100","delta_fp":"1.00","side":"yes","ts":"2026-07-01T02:35:23.154195Z","ts_ms":1782873323154}}

{"type":"orderbook_delta","sid":1,"seq":2141,"msg":{"market_ticker":"KXNEXTTEAMNBA-26LJAM-MIA","market_id":"492cb255-91da-4c91-bc9e-f83d090cc6dd","price_dollars":"0.0100","delta_fp":"1.00","side":"yes","ts":"2026-07-01T02:35:23.154744Z","ts_ms":1782873323154}}

{"type":"orderbook_delta","sid":1,"seq":2142,"msg":{"market_ticker":"KXNEXTTEAMNBA-26LJAM-MIA","market_id":"492cb255-91da-4c91-bc9e-f83d090cc6dd","price_dollars":"0.0100","delta_fp":"1.00","side":"yes","ts":"2026-07-01T02:35:23.155077Z","ts_ms":1782873323155}}

{"type":"orderbook_delta","sid":1,"seq":2143,"msg":{"market_ticker":"KXNEXTTEAMNBA-26LJAM-MIA","market_id":"492cb255-91da-4c91-bc9e-f83d090cc6dd","price_dollars":"0.0100","delta_fp":"1.00","side":"yes","ts":"2026-07-01T02:35:23.155484Z","ts_ms":1782873323155}}

{"type":"orderbook_delta","sid":1,"seq":2144,"msg":{"market_ticker":"KXNEXTTEAMNBA-26LJAM-MIA","market_id":"492cb255-91da-4c91-bc9e-f83d090cc6dd","price_dollars":"0.0100","delta_fp":"1.00","side":"yes","ts":"2026-07-01T02:35:23.155898Z","ts_ms":1782873323155}}

{"type":"orderbook_delta","sid":1,"seq":2145,"msg":{"market_ticker":"KXNEXTTEAMNBA-26LJAM-MIA","market_id":"492cb255-91da-4c91-bc9e-f83d090cc6dd","price_dollars":"0.0100","delta_fp":"1.00","side":"yes","ts":"2026-07-01T02:35:23.156384Z","ts_ms":1782873323156}}

{"type":"orderbook_delta","sid":1,"seq":2146,"msg":{"market_ticker":"KXNEXTTEAMNBA-26LJAM-MIA","market_id":"492cb255-91da-4c91-bc9e-f83d090cc6dd","price_dollars":"0.0100","delta_fp":"1.00","side":"yes","ts":"2026-07-01T02:35:23.156839Z","ts_ms":1782873323156}}

{"type":"orderbook_delta","sid":1,"seq":2147,"msg":{"market_ticker":"KXNEXTTEAMNBA-26LJAM-MIA","market_id":"492cb255-91da-4c91-bc9e-f83d090cc6dd","price_dollars":"0.0100","delta_fp":"1.00","side":"yes","ts":"2026-07-01T02:35:23.157279Z","ts_ms":1782873323157}}

{"type":"orderbook_delta","sid":1,"seq":2148,"msg":{"market_ticker":"KXNEXTTEAMNBA-26LJAM-MIA","market_id":"492cb255-91da-4c91-bc9e-f83d090cc6dd","price_dollars":"0.0100","delta_fp":"1.00","side":"yes","ts":"2026-07-01T02:35:23.157574Z","ts_ms":1782873323157}}

{"type":"orderbook_delta","sid":1,"seq":2149,"msg":{"market_ticker":"KXNEXTTEAMNBA-26LJAM-MIA","market_id":"492cb255-91da-4c91-bc9e-f83d090cc6dd","price_dollars":"0.0100","delta_fp":"1.00","side":"yes","ts":"2026-07-01T02:35:23.157956Z","ts_ms":1782873323157}}

{"type":"orderbook_delta","sid":1,"seq":2150,"msg":{"market_ticker":"KXNEXTTEAMNBA-26LJAM-MIA","market_id":"492cb255-91da-4c91-bc9e-f83d090cc6dd","price_dollars":"0.8300","delta_fp":"-0.85","side":"no","ts":"2026-07-01T02:35:23.768973Z","ts_ms":1782873323768}}

{"type":"orderbook_delta","sid":1,"seq":2151,"msg":{"market_ticker":"KXNEXTTEAMNBA-26LJAM-GSW","market_id":"abbbad28-f309-4dd5-af38-2ad7ebf2acc3","price_dollars":"0.5200","delta_fp":"-0.52","side":"no","ts":"2026-07-01T02:35:25.257017Z","ts_ms":1782873325257}}

{"type":"orderbook_delta","sid":1,"seq":2152,"msg":{"market_ticker":"KXNEXTTEAMNBA-26LJAM-GSW","market_id":"abbbad28-f309-4dd5-af38-2ad7ebf2acc3","price_dollars":"0.5200","delta_fp":"-1.91","side":"no","ts":"2026-07-01T02:35:26.677158Z","ts_ms":1782873326677}}

{"type":"orderbook_delta","sid":1,"seq":2153,"msg":{"market_ticker":"KXNEXTTEAMNBA-26LJAM-CLE","market_id":"7552b8d4-05de-4e41-84a8-97b0684da4a9","price_dollars":"0.7400","delta_fp":"-1.42","side":"no","ts":"2026-07-01T02:35:28.256933Z","ts_ms":1782873328256}}

{"type":"orderbook_delta","sid":1,"seq":2154,"msg":{"market_ticker":"KXNEXTTEAMNBA-26LJAM-CLE","market_id":"7552b8d4-05de-4e41-84a8-97b0684da4a9","price_dollars":"0.7400","delta_fp":"-0.02","side":"no","ts":"2026-07-01T02:35:28.572585Z","ts_ms":1782873328572}}

{"type":"orderbook_delta","sid":1,"seq":2155,"msg":{"market_ticker":"KXNEXTTEAMNBA-26LJAM-GSW","market_id":"abbbad28-f309-4dd5-af38-2ad7ebf2acc3","price_dollars":"0.5200","delta_fp":"694.44","side":"no","ts":"2026-07-01T02:35:29.9396Z","ts_ms":1782873329939}}

{"type":"orderbook_delta","sid":1,"seq":2156,"msg":{"market_ticker":"KXNEXTTEAMNBA-26LJAM-GSW","market_id":"abbbad28-f309-4dd5-af38-2ad7ebf2acc3","price_dollars":"0.5100","delta_fp":"680.27","side":"no","ts":"2026-07-01T02:35:29.940438Z","ts_ms":1782873329940}}

{"type":"orderbook_delta","sid":1,"seq":2157,"msg":{"market_ticker":"KXNEXTTEAMNBA-26LJAM-GSW","market_id":"abbbad28-f309-4dd5-af38-2ad7ebf2acc3","price_dollars":"0.5000","delta_fp":"666.66","side":"no","ts":"2026-07-01T02:35:29.941125Z","ts_ms":1782873329941}}

{"type":"orderbook_delta","sid":1,"seq":2158,"msg":{"market_ticker":"KXNEXTTEAMNBA-26LJAM-GSW","market_id":"abbbad28-f309-4dd5-af38-2ad7ebf2acc3","price_dollars":"0.5200","delta_fp":"-0.99","side":"no","ts":"2026-07-01T02:35:30.068418Z","ts_ms":1782873330068}}

{"type":"orderbook_delta","sid":1,"seq":2159,"msg":{"market_ticker":"KXNEXTTEAMNBA-26LJAM-MIA","market_id":"492cb255-91da-4c91-bc9e-f83d090cc6dd","price_dollars":"0.8300","delta_fp":"-0.72","side":"no","ts":"2026-07-01T02:35:30.0738Z","ts_ms":1782873330073}}

{"type":"orderbook_delta","sid":1,"seq":2160,"msg":{"market_ticker":"KXNEXTTEAMNBA-26LJAM-GSW","market_id":"abbbad28-f309-4dd5-af38-2ad7ebf2acc3","price_dollars":"0.5200","delta_fp":"-1.53","side":"no","ts":"2026-07-01T02:35:30.101215Z","ts_ms":1782873330101}}

{"type":"orderbook_delta","sid":1,"seq":2161,"msg":{"market_ticker":"KXNEXTTEAMNBA-26LJAM-MIA","market_id":"492cb255-91da-4c91-bc9e-f83d090cc6dd","price_dollars":"0.1600","delta_fp":"2083.33","side":"yes","ts":"2026-07-01T02:35:31.147197Z","ts_ms":1782873331147}}

{"type":"orderbook_delta","sid":1,"seq":2162,"msg":{"market_ticker":"KXNEXTTEAMNBA-26LJAM-MIA","market_id":"492cb255-91da-4c91-bc9e-f83d090cc6dd","price_dollars":"0.1500","delta_fp":"2222.22","side":"yes","ts":"2026-07-01T02:35:31.147577Z","ts_ms":1782873331147}}

{"type":"orderbook_delta","sid":1,"seq":2163,"msg":{"market_ticker":"KXNEXTTEAMNBA-26LJAM-MIA","market_id":"492cb255-91da-4c91-bc9e-f83d090cc6dd","price_dollars":"0.1400","delta_fp":"2380.95","side":"yes","ts":"2026-07-01T02:35:31.147967Z","ts_ms":1782873331147}}

{"type":"orderbook_delta","sid":1,"seq":2164,"msg":{"market_ticker":"KXNEXTTEAMNBA-26LJAM-MIA","market_id":"492cb255-91da-4c91-bc9e-f83d090cc6dd","price_dollars":"0.8300","delta_fp":"1960.78","side":"no","ts":"2026-07-01T02:35:31.148541Z","ts_ms":1782873331148}}

{"type":"orderbook_delta","sid":1,"seq":2165,"msg":{"market_ticker":"KXNEXTTEAMNBA-26LJAM-MIA","market_id":"492cb255-91da-4c91-bc9e-f83d090cc6dd","price_dollars":"0.8200","delta_fp":"1851.85","side":"no","ts":"2026-07-01T02:35:31.148918Z","ts_ms":1782873331148}}

{"type":"orderbook_delta","sid":1,"seq":2166,"msg":{"market_ticker":"KXNEXTTEAMNBA-26LJAM-MIA","market_id":"492cb255-91da-4c91-bc9e-f83d090cc6dd","price_dollars":"0.8100","delta_fp":"1754.38","side":"no","ts":"2026-07-01T02:35:31.149369Z","ts_ms":1782873331149}}

{"type":"orderbook_delta","sid":1,"seq":2167,"msg":{"market_ticker":"KXNEXTTEAMNBA-26LJAM-CLE","market_id":"7552b8d4-05de-4e41-84a8-97b0684da4a9","price_dollars":"0.7400","delta_fp":"-0.19","side":"no","ts":"2026-07-01T02:35:31.593852Z","ts_ms":1782873331593}}

{"type":"orderbook_delta","sid":1,"seq":2168,"msg":{"market_ticker":"KXNEXTTEAMNBA-26LJAM-CLE","market_id":"7552b8d4-05de-4e41-84a8-97b0684da4a9","price_dollars":"0.7400","delta_fp":"-1.53","side":"no","ts":"2026-07-01T02:35:31.598687Z","ts_ms":1782873331598}}

{"type":"orderbook_delta","sid":1,"seq":2169,"msg":{"market_ticker":"KXNEXTTEAMNBA-26LJAM-MIA","market_id":"492cb255-91da-4c91-bc9e-f83d090cc6dd","price_dollars":"0.8300","delta_fp":"-0.74","side":"no","ts":"2026-07-01T02:35:31.669591Z","ts_ms":1782873331669}}

{"type":"orderbook_delta","sid":1,"seq":2170,"msg":{"market_ticker":"KXNEXTTEAMNBA-26LJAM-GSW","market_id":"abbbad28-f309-4dd5-af38-2ad7ebf2acc3","price_dollars":"0.5200","delta_fp":"-0.34","side":"no","ts":"2026-07-01T02:35:34.882189Z","ts_ms":1782873334882}}

{"type":"orderbook_delta","sid":1,"seq":2171,"msg":{"market_ticker":"KXNEXTTEAMNBA-26LJAM-MIA","market_id":"492cb255-91da-4c91-bc9e-f83d090cc6dd","price_dollars":"0.0100","delta_fp":"1.00","side":"yes","ts":"2026-07-01T02:35:35.421616Z","ts_ms":1782873335421}}

{"type":"orderbook_delta","sid":1,"seq":2172,"msg":{"market_ticker":"KXNEXTTEAMNBA-26LJAM-MIA","market_id":"492cb255-91da-4c91-bc9e-f83d090cc6dd","price_dollars":"0.0100","delta_fp":"1.00","side":"yes","ts":"2026-07-01T02:35:35.422106Z","ts_ms":1782873335422}}

{"type":"orderbook_delta","sid":1,"seq":2173,"msg":{"market_ticker":"KXNEXTTEAMNBA-26LJAM-MIA","market_id":"492cb255-91da-4c91-bc9e-f83d090cc6dd","price_dollars":"0.0100","delta_fp":"1.00","side":"yes","ts":"2026-07-01T02:35:35.422686Z","ts_ms":1782873335422}}

{"type":"orderbook_delta","sid":1,"seq":2174,"msg":{"market_ticker":"KXNEXTTEAMNBA-26LJAM-MIA","market_id":"492cb255-91da-4c91-bc9e-f83d090cc6dd","price_dollars":"0.0100","delta_fp":"1.00","side":"yes","ts":"2026-07-01T02:35:35.423231Z","ts_ms":1782873335423}}

{"type":"orderbook_delta","sid":1,"seq":2175,"msg":{"market_ticker":"KXNEXTTEAMNBA-26LJAM-MIA","market_id":"492cb255-91da-4c91-bc9e-f83d090cc6dd","price_dollars":"0.0100","delta_fp":"1.00","side":"yes","ts":"2026-07-01T02:35:35.42373Z","ts_ms":1782873335423}}

{"type":"orderbook_delta","sid":1,"seq":2176,"msg":{"market_ticker":"KXNEXTTEAMNBA-26LJAM-MIA","market_id":"492cb255-91da-4c91-bc9e-f83d090cc6dd","price_dollars":"0.0100","delta_fp":"1.00","side":"yes","ts":"2026-07-01T02:35:35.424118Z","ts_ms":1782873335424}}

{"type":"orderbook_delta","sid":1,"seq":2177,"msg":{"market_ticker":"KXNEXTTEAMNBA-26LJAM-MIA","market_id":"492cb255-91da-4c91-bc9e-f83d090cc6dd","price_dollars":"0.0100","delta_fp":"1.00","side":"yes","ts":"2026-07-01T02:35:35.42468Z","ts_ms":1782873335424}}

{"type":"orderbook_delta","sid":1,"seq":2178,"msg":{"market_ticker":"KXNEXTTEAMNBA-26LJAM-MIA","market_id":"492cb255-91da-4c91-bc9e-f83d090cc6dd","price_dollars":"0.0100","delta_fp":"1.00","side":"yes","ts":"2026-07-01T02:35:35.425237Z","ts_ms":1782873335425}}

{"type":"orderbook_delta","sid":1,"seq":2179,"msg":{"market_ticker":"KXNEXTTEAMNBA-26LJAM-MIA","market_id":"492cb255-91da-4c91-bc9e-f83d090cc6dd","price_dollars":"0.0100","delta_fp":"1.00","side":"yes","ts":"2026-07-01T02:35:35.425951Z","ts_ms":1782873335425}}

{"type":"orderbook_delta","sid":1,"seq":2180,"msg":{"market_ticker":"KXNEXTTEAMNBA-26LJAM-MIA","market_id":"492cb255-91da-4c91-bc9e-f83d090cc6dd","price_dollars":"0.0100","delta_fp":"1.00","side":"yes","ts":"2026-07-01T02:35:35.426536Z","ts_ms":1782873335426}}

{"type":"orderbook_delta","sid":1,"seq":2181,"msg":{"market_ticker":"KXNEXTTEAMNBA-26LJAM-MIA","market_id":"492cb255-91da-4c91-bc9e-f83d090cc6dd","price_dollars":"0.0100","delta_fp":"1.00","side":"yes","ts":"2026-07-01T02:35:35.4272Z","ts_ms":1782873335427}}

{"type":"orderbook_delta","sid":1,"seq":2182,"msg":{"market_ticker":"KXNEXTTEAMNBA-26LJAM-MIA","market_id":"492cb255-91da-4c91-bc9e-f83d090cc6dd","price_dollars":"0.0100","delta_fp":"1.00","side":"yes","ts":"2026-07-01T02:35:35.432298Z","ts_ms":1782873335432}}

{"type":"orderbook_delta","sid":1,"seq":2183,"msg":{"market_ticker":"KXNEXTTEAMNBA-26LJAM-MIA","market_id":"492cb255-91da-4c91-bc9e-f83d090cc6dd","price_dollars":"0.0100","delta_fp":"1.00","side":"yes","ts":"2026-07-01T02:35:35.432696Z","ts_ms":1782873335432}}

{"type":"orderbook_delta","sid":1,"seq":2184,"msg":{"market_ticker":"KXNEXTTEAMNBA-26LJAM-MIA","market_id":"492cb255-91da-4c91-bc9e-f83d090cc6dd","price_dollars":"0.0100","delta_fp":"1.00","side":"yes","ts":"2026-07-01T02:35:35.43318Z","ts_ms":1782873335433}}

{"type":"orderbook_delta","sid":1,"seq":2185,"msg":{"market_ticker":"KXNEXTTEAMNBA-26LJAM-MIA","market_id":"492cb255-91da-4c91-bc9e-f83d090cc6dd","price_dollars":"0.0100","delta_fp":"1.00","side":"yes","ts":"2026-07-01T02:35:35.433592Z","ts_ms":1782873335433}}

{"type":"orderbook_delta","sid":1,"seq":2186,"msg":{"market_ticker":"KXNEXTTEAMNBA-26LJAM-MIA","market_id":"492cb255-91da-4c91-bc9e-f83d090cc6dd","price_dollars":"0.0100","delta_fp":"1.00","side":"yes","ts":"2026-07-01T02:35:35.434327Z","ts_ms":1782873335434}}

{"type":"orderbook_delta","sid":1,"seq":2187,"msg":{"market_ticker":"KXNEXTTEAMNBA-26LJAM-MIA","market_id":"492cb255-91da-4c91-bc9e-f83d090cc6dd","price_dollars":"0.0100","delta_fp":"1.00","side":"yes","ts":"2026-07-01T02:35:35.434781Z","ts_ms":1782873335434}}

{"type":"orderbook_delta","sid":1,"seq":2188,"msg":{"market_ticker":"KXNEXTTEAMNBA-26LJAM-MIA","market_id":"492cb255-91da-4c91-bc9e-f83d090cc6dd","price_dollars":"0.0100","delta_fp":"1.00","side":"yes","ts":"2026-07-01T02:35:35.435236Z","ts_ms":1782873335435}}

{"type":"orderbook_delta","sid":1,"seq":2189,"msg":{"market_ticker":"KXNEXTTEAMNBA-26LJAM-MIA","market_id":"492cb255-91da-4c91-bc9e-f83d090cc6dd","price_dollars":"0.0100","delta_fp":"1.00","side":"yes","ts":"2026-07-01T02:35:35.435647Z","ts_ms":1782873335435}}

{"type":"orderbook_delta","sid":1,"seq":2190,"msg":{"market_ticker":"KXNEXTTEAMNBA-26LJAM-MIA","market_id":"492cb255-91da-4c91-bc9e-f83d090cc6dd","price_dollars":"0.0100","delta_fp":"1.00","side":"yes","ts":"2026-07-01T02:35:35.43606Z","ts_ms":1782873335436}}

{"type":"orderbook_delta","sid":1,"seq":2191,"msg":{"market_ticker":"KXNEXTTEAMNBA-26LJAM-GSW","market_id":"abbbad28-f309-4dd5-af38-2ad7ebf2acc3","price_dollars":"0.4700","delta_fp":"709.21","side":"yes","ts":"2026-07-01T02:35:36.461885Z","ts_ms":1782873336461}}

{"type":"orderbook_delta","sid":1,"seq":2192,"msg":{"market_ticker":"KXNEXTTEAMNBA-26LJAM-GSW","market_id":"abbbad28-f309-4dd5-af38-2ad7ebf2acc3","price_dollars":"0.4600","delta_fp":"724.63","side":"yes","ts":"2026-07-01T02:35:36.462632Z","ts_ms":1782873336462}}

{"type":"orderbook_delta","sid":1,"seq":2193,"msg":{"market_ticker":"KXNEXTTEAMNBA-26LJAM-GSW","market_id":"abbbad28-f309-4dd5-af38-2ad7ebf2acc3","price_dollars":"0.4500","delta_fp":"740.74","side":"yes","ts":"2026-07-01T02:35:36.463227Z","ts_ms":1782873336463}}

{"type":"orderbook_delta","sid":1,"seq":2194,"msg":{"market_ticker":"KXNEXTTEAMNBA-26LJAM-GSW","market_id":"abbbad28-f309-4dd5-af38-2ad7ebf2acc3","price_dollars":"0.5200","delta_fp":"694.44","side":"no","ts":"2026-07-01T02:35:36.463839Z","ts_ms":1782873336463}}

{"type":"orderbook_delta","sid":1,"seq":2195,"msg":{"market_ticker":"KXNEXTTEAMNBA-26LJAM-GSW","market_id":"abbbad28-f309-4dd5-af38-2ad7ebf2acc3","price_dollars":"0.5100","delta_fp":"680.27","side":"no","ts":"2026-07-01T02:35:36.464656Z","ts_ms":1782873336464}}

{"type":"orderbook_delta","sid":1,"seq":2196,"msg":{"market_ticker":"KXNEXTTEAMNBA-26LJAM-GSW","market_id":"abbbad28-f309-4dd5-af38-2ad7ebf2acc3","price_dollars":"0.5000","delta_fp":"666.66","side":"no","ts":"2026-07-01T02:35:36.465511Z","ts_ms":1782873336465}}

{"type":"orderbook_delta","sid":1,"seq":2197,"msg":{"market_ticker":"KXNEXTTEAMNBA-26LJAM-CLE","market_id":"7552b8d4-05de-4e41-84a8-97b0684da4a9","price_dollars":"0.7400","delta_fp":"-1.28","side":"no","ts":"2026-07-01T02:35:37.984579Z","ts_ms":1782873337984}}

{"type":"orderbook_delta","sid":1,"seq":2198,"msg":{"market_ticker":"KXNEXTTEAMNBA-26LJAM-GSW","market_id":"abbbad28-f309-4dd5-af38-2ad7ebf2acc3","price_dollars":"0.5200","delta_fp":"-1.17","side":"no","ts":"2026-07-01T02:35:38.063295Z","ts_ms":1782873338063}}

{"type":"orderbook_delta","sid":1,"seq":2199,"msg":{"market_ticker":"KXNEXTTEAMNBA-26LJAM-CLE","market_id":"7552b8d4-05de-4e41-84a8-97b0684da4a9","price_dollars":"0.7400","delta_fp":"-0.21","side":"no","ts":"2026-07-01T02:35:38.071438Z","ts_ms":1782873338071}}

{"type":"orderbook_delta","sid":1,"seq":2200,"msg":{"market_ticker":"KXNEXTTEAMNBA-26LJAM-CLE","market_id":"7552b8d4-05de-4e41-84a8-97b0684da4a9","price_dollars":"0.7400","delta_fp":"-0.09","side":"no","ts":"2026-07-01T02:35:39.360107Z","ts_ms":1782873339360}}

{"type":"orderbook_delta","sid":1,"seq":2201,"msg":{"market_ticker":"KXNEXTTEAMNBA-26LJAM-GSW","market_id":"abbbad28-f309-4dd5-af38-2ad7ebf2acc3","price_dollars":"0.0100","delta_fp":"1.00","side":"yes","ts":"2026-07-01T02:35:40.71608Z","ts_ms":1782873340716}}

{"type":"orderbook_delta","sid":1,"seq":2202,"msg":{"market_ticker":"KXNEXTTEAMNBA-26LJAM-GSW","market_id":"abbbad28-f309-4dd5-af38-2ad7ebf2acc3","price_dollars":"0.0100","delta_fp":"1.00","side":"yes","ts":"2026-07-01T02:35:40.716431Z","ts_ms":1782873340716}}

{"type":"orderbook_delta","sid":1,"seq":2203,"msg":{"market_ticker":"KXNEXTTEAMNBA-26LJAM-GSW","market_id":"abbbad28-f309-4dd5-af38-2ad7ebf2acc3","price_dollars":"0.0100","delta_fp":"1.00","side":"yes","ts":"2026-07-01T02:35:40.716722Z","ts_ms":1782873340716}}

{"type":"orderbook_delta","sid":1,"seq":2204,"msg":{"market_ticker":"KXNEXTTEAMNBA-26LJAM-GSW","market_id":"abbbad28-f309-4dd5-af38-2ad7ebf2acc3","price_dollars":"0.0100","delta_fp":"1.00","side":"yes","ts":"2026-07-01T02:35:40.717069Z","ts_ms":1782873340717}}

{"type":"orderbook_delta","sid":1,"seq":2205,"msg":{"market_ticker":"KXNEXTTEAMNBA-26LJAM-GSW","market_id":"abbbad28-f309-4dd5-af38-2ad7ebf2acc3","price_dollars":"0.0100","delta_fp":"1.00","side":"yes","ts":"2026-07-01T02:35:40.717425Z","ts_ms":1782873340717}}

{"type":"orderbook_delta","sid":1,"seq":2206,"msg":{"market_ticker":"KXNEXTTEAMNBA-26LJAM-GSW","market_id":"abbbad28-f309-4dd5-af38-2ad7ebf2acc3","price_dollars":"0.0100","delta_fp":"1.00","side":"yes","ts":"2026-07-01T02:35:40.717789Z","ts_ms":1782873340717}}

{"type":"orderbook_delta","sid":1,"seq":2207,"msg":{"market_ticker":"KXNEXTTEAMNBA-26LJAM-GSW","market_id":"abbbad28-f309-4dd5-af38-2ad7ebf2acc3","price_dollars":"0.0100","delta_fp":"1.00","side":"yes","ts":"2026-07-01T02:35:40.718148Z","ts_ms":1782873340718}}

{"type":"orderbook_delta","sid":1,"seq":2208,"msg":{"market_ticker":"KXNEXTTEAMNBA-26LJAM-GSW","market_id":"abbbad28-f309-4dd5-af38-2ad7ebf2acc3","price_dollars":"0.0100","delta_fp":"1.00","side":"yes","ts":"2026-07-01T02:35:40.718426Z","ts_ms":1782873340718}}

{"type":"orderbook_delta","sid":1,"seq":2209,"msg":{"market_ticker":"KXNEXTTEAMNBA-26LJAM-GSW","market_id":"abbbad28-f309-4dd5-af38-2ad7ebf2acc3","price_dollars":"0.0100","delta_fp":"1.00","side":"yes","ts":"2026-07-01T02:35:40.718677Z","ts_ms":1782873340718}}

{"type":"orderbook_delta","sid":1,"seq":2210,"msg":{"market_ticker":"KXNEXTTEAMNBA-26LJAM-GSW","market_id":"abbbad28-f309-4dd5-af38-2ad7ebf2acc3","price_dollars":"0.0100","delta_fp":"1.00","side":"yes","ts":"2026-07-01T02:35:40.718954Z","ts_ms":1782873340718}}

{"type":"orderbook_delta","sid":1,"seq":2211,"msg":{"market_ticker":"KXNEXTTEAMNBA-26LJAM-GSW","market_id":"abbbad28-f309-4dd5-af38-2ad7ebf2acc3","price_dollars":"0.0100","delta_fp":"1.00","side":"yes","ts":"2026-07-01T02:35:40.719231Z","ts_ms":1782873340719}}

{"type":"orderbook_delta","sid":1,"seq":2212,"msg":{"market_ticker":"KXNEXTTEAMNBA-26LJAM-GSW","market_id":"abbbad28-f309-4dd5-af38-2ad7ebf2acc3","price_dollars":"0.0100","delta_fp":"1.00","side":"yes","ts":"2026-07-01T02:35:40.719484Z","ts_ms":1782873340719}}

{"type":"orderbook_delta","sid":1,"seq":2213,"msg":{"market_ticker":"KXNEXTTEAMNBA-26LJAM-GSW","market_id":"abbbad28-f309-4dd5-af38-2ad7ebf2acc3","price_dollars":"0.0100","delta_fp":"1.00","side":"yes","ts":"2026-07-01T02:35:40.719741Z","ts_ms":1782873340719}}

{"type":"orderbook_delta","sid":1,"seq":2214,"msg":{"market_ticker":"KXNEXTTEAMNBA-26LJAM-GSW","market_id":"abbbad28-f309-4dd5-af38-2ad7ebf2acc3","price_dollars":"0.0100","delta_fp":"1.00","side":"yes","ts":"2026-07-01T02:35:40.719982Z","ts_ms":1782873340719}}

{"type":"orderbook_delta","sid":1,"seq":2215,"msg":{"market_ticker":"KXNEXTTEAMNBA-26LJAM-GSW","market_id":"abbbad28-f309-4dd5-af38-2ad7ebf2acc3","price_dollars":"0.0100","delta_fp":"1.00","side":"yes","ts":"2026-07-01T02:35:40.720257Z","ts_ms":1782873340720}}

{"type":"orderbook_delta","sid":1,"seq":2216,"msg":{"market_ticker":"KXNEXTTEAMNBA-26LJAM-GSW","market_id":"abbbad28-f309-4dd5-af38-2ad7ebf2acc3","price_dollars":"0.0100","delta_fp":"1.00","side":"yes","ts":"2026-07-01T02:35:40.720492Z","ts_ms":1782873340720}}

{"type":"orderbook_delta","sid":1,"seq":2217,"msg":{"market_ticker":"KXNEXTTEAMNBA-26LJAM-GSW","market_id":"abbbad28-f309-4dd5-af38-2ad7ebf2acc3","price_dollars":"0.0100","delta_fp":"1.00","side":"yes","ts":"2026-07-01T02:35:40.72075Z","ts_ms":1782873340720}}

{"type":"orderbook_delta","sid":1,"seq":2218,"msg":{"market_ticker":"KXNEXTTEAMNBA-26LJAM-GSW","market_id":"abbbad28-f309-4dd5-af38-2ad7ebf2acc3","price_dollars":"0.0100","delta_fp":"1.00","side":"yes","ts":"2026-07-01T02:35:40.721117Z","ts_ms":1782873340721}}

{"type":"orderbook_delta","sid":1,"seq":2219,"msg":{"market_ticker":"KXNEXTTEAMNBA-26LJAM-GSW","market_id":"abbbad28-f309-4dd5-af38-2ad7ebf2acc3","price_dollars":"0.0100","delta_fp":"1.00","side":"yes","ts":"2026-07-01T02:35:40.721529Z","ts_ms":1782873340721}}

{"type":"orderbook_delta","sid":1,"seq":2220,"msg":{"market_ticker":"KXNEXTTEAMNBA-26LJAM-GSW","market_id":"abbbad28-f309-4dd5-af38-2ad7ebf2acc3","price_dollars":"0.0100","delta_fp":"1.00","side":"yes","ts":"2026-07-01T02:35:40.721779Z","ts_ms":1782873340721}}

{"type":"orderbook_delta","sid":1,"seq":2221,"msg":{"market_ticker":"KXNEXTTEAMNBA-26LJAM-MIA","market_id":"492cb255-91da-4c91-bc9e-f83d090cc6dd","price_dollars":"0.8300","delta_fp":"-1.09","side":"no","ts":"2026-07-01T02:35:40.979066Z","ts_ms":1782873340979}}

{"type":"orderbook_delta","sid":1,"seq":2222,"msg":{"market_ticker":"KXNEXTTEAMNBA-26LJAM-MIA","market_id":"492cb255-91da-4c91-bc9e-f83d090cc6dd","price_dollars":"0.0100","delta_fp":"1.00","side":"yes","ts":"2026-07-01T02:35:41.920022Z","ts_ms":1782873341920}}

{"type":"orderbook_delta","sid":1,"seq":2223,"msg":{"market_ticker":"KXNEXTTEAMNBA-26LJAM-MIA","market_id":"492cb255-91da-4c91-bc9e-f83d090cc6dd","price_dollars":"0.0100","delta_fp":"1.00","side":"yes","ts":"2026-07-01T02:35:41.920537Z","ts_ms":1782873341920}}

{"type":"orderbook_delta","sid":1,"seq":2224,"msg":{"market_ticker":"KXNEXTTEAMNBA-26LJAM-MIA","market_id":"492cb255-91da-4c91-bc9e-f83d090cc6dd","price_dollars":"0.0100","delta_fp":"1.00","side":"yes","ts":"2026-07-01T02:35:41.92098Z","ts_ms":1782873341920}}

{"type":"orderbook_delta","sid":1,"seq":2225,"msg":{"market_ticker":"KXNEXTTEAMNBA-26LJAM-MIA","market_id":"492cb255-91da-4c91-bc9e-f83d090cc6dd","price_dollars":"0.0100","delta_fp":"1.00","side":"yes","ts":"2026-07-01T02:35:41.921481Z","ts_ms":1782873341921}}

{"type":"orderbook_delta","sid":1,"seq":2226,"msg":{"market_ticker":"KXNEXTTEAMNBA-26LJAM-MIA","market_id":"492cb255-91da-4c91-bc9e-f83d090cc6dd","price_dollars":"0.0100","delta_fp":"1.00","side":"yes","ts":"2026-07-01T02:35:41.922009Z","ts_ms":1782873341922}}

{"type":"orderbook_delta","sid":1,"seq":2227,"msg":{"market_ticker":"KXNEXTTEAMNBA-26LJAM-MIA","market_id":"492cb255-91da-4c91-bc9e-f83d090cc6dd","price_dollars":"0.0100","delta_fp":"1.00","side":"yes","ts":"2026-07-01T02:35:41.922408Z","ts_ms":1782873341922}}

{"type":"orderbook_delta","sid":1,"seq":2228,"msg":{"market_ticker":"KXNEXTTEAMNBA-26LJAM-MIA","market_id":"492cb255-91da-4c91-bc9e-f83d090cc6dd","price_dollars":"0.0100","delta_fp":"1.00","side":"yes","ts":"2026-07-01T02:35:41.923041Z","ts_ms":1782873341923}}

{"type":"orderbook_delta","sid":1,"seq":2229,"msg":{"market_ticker":"KXNEXTTEAMNBA-26LJAM-MIA","market_id":"492cb255-91da-4c91-bc9e-f83d090cc6dd","price_dollars":"0.0100","delta_fp":"1.00","side":"yes","ts":"2026-07-01T02:35:41.923505Z","ts_ms":1782873341923}}

{"type":"orderbook_delta","sid":1,"seq":2230,"msg":{"market_ticker":"KXNEXTTEAMNBA-26LJAM-MIA","market_id":"492cb255-91da-4c91-bc9e-f83d090cc6dd","price_dollars":"0.0100","delta_fp":"1.00","side":"yes","ts":"2026-07-01T02:35:41.92394Z","ts_ms":1782873341923}}

{"type":"orderbook_delta","sid":1,"seq":2231,"msg":{"market_ticker":"KXNEXTTEAMNBA-26LJAM-MIA","market_id":"492cb255-91da-4c91-bc9e-f83d090cc6dd","price_dollars":"0.0100","delta_fp":"1.00","side":"yes","ts":"2026-07-01T02:35:41.924326Z","ts_ms":1782873341924}}

{"type":"orderbook_delta","sid":1,"seq":2232,"msg":{"market_ticker":"KXNEXTTEAMNBA-26LJAM-MIA","market_id":"492cb255-91da-4c91-bc9e-f83d090cc6dd","price_dollars":"0.0100","delta_fp":"1.00","side":"yes","ts":"2026-07-01T02:35:41.924755Z","ts_ms":1782873341924}}

{"type":"orderbook_delta","sid":1,"seq":2233,"msg":{"market_ticker":"KXNEXTTEAMNBA-26LJAM-MIA","market_id":"492cb255-91da-4c91-bc9e-f83d090cc6dd","price_dollars":"0.0100","delta_fp":"1.00","side":"yes","ts":"2026-07-01T02:35:41.925227Z","ts_ms":1782873341925}}

{"type":"orderbook_delta","sid":1,"seq":2234,"msg":{"market_ticker":"KXNEXTTEAMNBA-26LJAM-MIA","market_id":"492cb255-91da-4c91-bc9e-f83d090cc6dd","price_dollars":"0.0100","delta_fp":"1.00","side":"yes","ts":"2026-07-01T02:35:41.925829Z","ts_ms":1782873341925}}

{"type":"orderbook_delta","sid":1,"seq":2235,"msg":{"market_ticker":"KXNEXTTEAMNBA-26LJAM-MIA","market_id":"492cb255-91da-4c91-bc9e-f83d090cc6dd","price_dollars":"0.0100","delta_fp":"1.00","side":"yes","ts":"2026-07-01T02:35:41.926226Z","ts_ms":1782873341926}}

{"type":"orderbook_delta","sid":1,"seq":2236,"msg":{"market_ticker":"KXNEXTTEAMNBA-26LJAM-MIA","market_id":"492cb255-91da-4c91-bc9e-f83d090cc6dd","price_dollars":"0.0100","delta_fp":"1.00","side":"yes","ts":"2026-07-01T02:35:41.926637Z","ts_ms":1782873341926}}

{"type":"orderbook_delta","sid":1,"seq":2237,"msg":{"market_ticker":"KXNEXTTEAMNBA-26LJAM-MIA","market_id":"492cb255-91da-4c91-bc9e-f83d090cc6dd","price_dollars":"0.0100","delta_fp":"1.00","side":"yes","ts":"2026-07-01T02:35:41.927053Z","ts_ms":1782873341927}}

{"type":"orderbook_delta","sid":1,"seq":2238,"msg":{"market_ticker":"KXNEXTTEAMNBA-26LJAM-MIA","market_id":"492cb255-91da-4c91-bc9e-f83d090cc6dd","price_dollars":"0.0100","delta_fp":"1.00","side":"yes","ts":"2026-07-01T02:35:41.927495Z","ts_ms":1782873341927}}

{"type":"orderbook_delta","sid":1,"seq":2239,"msg":{"market_ticker":"KXNEXTTEAMNBA-26LJAM-MIA","market_id":"492cb255-91da-4c91-bc9e-f83d090cc6dd","price_dollars":"0.0100","delta_fp":"1.00","side":"yes","ts":"2026-07-01T02:35:41.927907Z","ts_ms":1782873341927}}

{"type":"orderbook_delta","sid":1,"seq":2240,"msg":{"market_ticker":"KXNEXTTEAMNBA-26LJAM-MIA","market_id":"492cb255-91da-4c91-bc9e-f83d090cc6dd","price_dollars":"0.0100","delta_fp":"1.00","side":"yes","ts":"2026-07-01T02:35:41.928354Z","ts_ms":1782873341928}}

{"type":"orderbook_delta","sid":1,"seq":2241,"msg":{"market_ticker":"KXNEXTTEAMNBA-26LJAM-MIA","market_id":"492cb255-91da-4c91-bc9e-f83d090cc6dd","price_dollars":"0.0100","delta_fp":"1.00","side":"yes","ts":"2026-07-01T02:35:41.928745Z","ts_ms":1782873341928}}

{"type":"orderbook_delta","sid":1,"seq":2242,"msg":{"market_ticker":"KXNEXTTEAMNBA-26LJAM-GSW","market_id":"abbbad28-f309-4dd5-af38-2ad7ebf2acc3","price_dollars":"0.0100","delta_fp":"-1.00","side":"yes","ts":"2026-07-01T02:35:42.638096Z","ts_ms":1782873342638}}

{"type":"orderbook_delta","sid":1,"seq":2243,"msg":{"market_ticker":"KXNEXTTEAMNBA-26LJAM-GSW","market_id":"abbbad28-f309-4dd5-af38-2ad7ebf2acc3","price_dollars":"0.0100","delta_fp":"-1.00","side":"yes","ts":"2026-07-01T02:35:42.638658Z","ts_ms":1782873342638}}

{"type":"orderbook_delta","sid":1,"seq":2244,"msg":{"market_ticker":"KXNEXTTEAMNBA-26LJAM-GSW","market_id":"abbbad28-f309-4dd5-af38-2ad7ebf2acc3","price_dollars":"0.0100","delta_fp":"-1.00","side":"yes","ts":"2026-07-01T02:35:42.639385Z","ts_ms":1782873342639}}

{"type":"orderbook_delta","sid":1,"seq":2245,"msg":{"market_ticker":"KXNEXTTEAMNBA-26LJAM-GSW","market_id":"abbbad28-f309-4dd5-af38-2ad7ebf2acc3","price_dollars":"0.0100","delta_fp":"-1.00","side":"yes","ts":"2026-07-01T02:35:42.640106Z","ts_ms":1782873342640}}

{"type":"orderbook_delta","sid":1,"seq":2246,"msg":{"market_ticker":"KXNEXTTEAMNBA-26LJAM-GSW","market_id":"abbbad28-f309-4dd5-af38-2ad7ebf2acc3","price_dollars":"0.0100","delta_fp":"-1.00","side":"yes","ts":"2026-07-01T02:35:42.640793Z","ts_ms":1782873342640}}

{"type":"orderbook_delta","sid":1,"seq":2247,"msg":{"market_ticker":"KXNEXTTEAMNBA-26LJAM-GSW","market_id":"abbbad28-f309-4dd5-af38-2ad7ebf2acc3","price_dollars":"0.0100","delta_fp":"-1.00","side":"yes","ts":"2026-07-01T02:35:42.641416Z","ts_ms":1782873342641}}

{"type":"orderbook_delta","sid":1,"seq":2248,"msg":{"market_ticker":"KXNEXTTEAMNBA-26LJAM-GSW","market_id":"abbbad28-f309-4dd5-af38-2ad7ebf2acc3","price_dollars":"0.0100","delta_fp":"-1.00","side":"yes","ts":"2026-07-01T02:35:42.641938Z","ts_ms":1782873342641}}

{"type":"orderbook_delta","sid":1,"seq":2249,"msg":{"market_ticker":"KXNEXTTEAMNBA-26LJAM-GSW","market_id":"abbbad28-f309-4dd5-af38-2ad7ebf2acc3","price_dollars":"0.0100","delta_fp":"-1.00","side":"yes","ts":"2026-07-01T02:35:42.642445Z","ts_ms":1782873342642}}

{"type":"orderbook_delta","sid":1,"seq":2250,"msg":{"market_ticker":"KXNEXTTEAMNBA-26LJAM-GSW","market_id":"abbbad28-f309-4dd5-af38-2ad7ebf2acc3","price_dollars":"0.0100","delta_fp":"-1.00","side":"yes","ts":"2026-07-01T02:35:42.642999Z","ts_ms":1782873342642}}

{"type":"orderbook_delta","sid":1,"seq":2251,"msg":{"market_ticker":"KXNEXTTEAMNBA-26LJAM-GSW","market_id":"abbbad28-f309-4dd5-af38-2ad7ebf2acc3","price_dollars":"0.0100","delta_fp":"-1.00","side":"yes","ts":"2026-07-01T02:35:42.64353Z","ts_ms":1782873342643}}

{"type":"orderbook_delta","sid":1,"seq":2252,"msg":{"market_ticker":"KXNEXTTEAMNBA-26LJAM-GSW","market_id":"abbbad28-f309-4dd5-af38-2ad7ebf2acc3","price_dollars":"0.0100","delta_fp":"-1.00","side":"yes","ts":"2026-07-01T02:35:42.644086Z","ts_ms":1782873342644}}

{"type":"orderbook_delta","sid":1,"seq":2253,"msg":{"market_ticker":"KXNEXTTEAMNBA-26LJAM-GSW","market_id":"abbbad28-f309-4dd5-af38-2ad7ebf2acc3","price_dollars":"0.0100","delta_fp":"-1.00","side":"yes","ts":"2026-07-01T02:35:42.644604Z","ts_ms":1782873342644}}

{"type":"orderbook_delta","sid":1,"seq":2254,"msg":{"market_ticker":"KXNEXTTEAMNBA-26LJAM-GSW","market_id":"abbbad28-f309-4dd5-af38-2ad7ebf2acc3","price_dollars":"0.0100","delta_fp":"-1.00","side":"yes","ts":"2026-07-01T02:35:42.645112Z","ts_ms":1782873342645}}

{"type":"orderbook_delta","sid":1,"seq":2255,"msg":{"market_ticker":"KXNEXTTEAMNBA-26LJAM-GSW","market_id":"abbbad28-f309-4dd5-af38-2ad7ebf2acc3","price_dollars":"0.0100","delta_fp":"-1.00","side":"yes","ts":"2026-07-01T02:35:42.645661Z","ts_ms":1782873342645}}

{"type":"orderbook_delta","sid":1,"seq":2256,"msg":{"market_ticker":"KXNEXTTEAMNBA-26LJAM-GSW","market_id":"abbbad28-f309-4dd5-af38-2ad7ebf2acc3","price_dollars":"0.0100","delta_fp":"-1.00","side":"yes","ts":"2026-07-01T02:35:42.645946Z","ts_ms":1782873342645}}

{"type":"orderbook_delta","sid":1,"seq":2257,"msg":{"market_ticker":"KXNEXTTEAMNBA-26LJAM-GSW","market_id":"abbbad28-f309-4dd5-af38-2ad7ebf2acc3","price_dollars":"0.0100","delta_fp":"-1.00","side":"yes","ts":"2026-07-01T02:35:42.646394Z","ts_ms":1782873342646}}

{"type":"orderbook_delta","sid":1,"seq":2258,"msg":{"market_ticker":"KXNEXTTEAMNBA-26LJAM-GSW","market_id":"abbbad28-f309-4dd5-af38-2ad7ebf2acc3","price_dollars":"0.0100","delta_fp":"-1.00","side":"yes","ts":"2026-07-01T02:35:42.646848Z","ts_ms":1782873342646}}

{"type":"orderbook_delta","sid":1,"seq":2259,"msg":{"market_ticker":"KXNEXTTEAMNBA-26LJAM-GSW","market_id":"abbbad28-f309-4dd5-af38-2ad7ebf2acc3","price_dollars":"0.0100","delta_fp":"-1.00","side":"yes","ts":"2026-07-01T02:35:42.647229Z","ts_ms":1782873342647}}

{"type":"orderbook_delta","sid":1,"seq":2260,"msg":{"market_ticker":"KXNEXTTEAMNBA-26LJAM-GSW","market_id":"abbbad28-f309-4dd5-af38-2ad7ebf2acc3","price_dollars":"0.0100","delta_fp":"-1.00","side":"yes","ts":"2026-07-01T02:35:42.647635Z","ts_ms":1782873342647}}

{"type":"orderbook_delta","sid":1,"seq":2261,"msg":{"market_ticker":"KXNEXTTEAMNBA-26LJAM-GSW","market_id":"abbbad28-f309-4dd5-af38-2ad7ebf2acc3","price_dollars":"0.0100","delta_fp":"-1.00","side":"yes","ts":"2026-07-01T02:35:42.648112Z","ts_ms":1782873342648}}

{"type":"orderbook_delta","sid":1,"seq":2262,"msg":{"market_ticker":"KXNEXTTEAMNBA-26LJAM-GSW","market_id":"abbbad28-f309-4dd5-af38-2ad7ebf2acc3","price_dollars":"0.5200","delta_fp":"-0.52","side":"no","ts":"2026-07-01T02:35:42.877579Z","ts_ms":1782873342877}}

{"type":"orderbook_delta","sid":1,"seq":2263,"msg":{"market_ticker":"KXNEXTTEAMNBA-26LJAM-CLE","market_id":"7552b8d4-05de-4e41-84a8-97b0684da4a9","price_dollars":"0.7400","delta_fp":"-0.95","side":"no","ts":"2026-07-01T02:35:44.477106Z","ts_ms":1782873344477}}

{"type":"orderbook_delta","sid":1,"seq":2264,"msg":{"market_ticker":"KXNEXTTEAMNBA-26LJAM-MIA","market_id":"492cb255-91da-4c91-bc9e-f83d090cc6dd","price_dollars":"0.8300","delta_fp":"-1.22","side":"no","ts":"2026-07-01T02:35:44.485322Z","ts_ms":1782873344485}}

{"type":"orderbook_delta","sid":1,"seq":2265,"msg":{"market_ticker":"KXNEXTTEAMNBA-26LJAM-GSW","market_id":"abbbad28-f309-4dd5-af38-2ad7ebf2acc3","price_dollars":"0.0100","delta_fp":"1.00","side":"yes","ts":"2026-07-01T02:35:46.914348Z","ts_ms":1782873346914}}

{"type":"orderbook_delta","sid":1,"seq":2266,"msg":{"market_ticker":"KXNEXTTEAMNBA-26LJAM-GSW","market_id":"abbbad28-f309-4dd5-af38-2ad7ebf2acc3","price_dollars":"0.0100","delta_fp":"1.00","side":"yes","ts":"2026-07-01T02:35:46.91472Z","ts_ms":1782873346914}}

{"type":"orderbook_delta","sid":1,"seq":2267,"msg":{"market_ticker":"KXNEXTTEAMNBA-26LJAM-GSW","market_id":"abbbad28-f309-4dd5-af38-2ad7ebf2acc3","price_dollars":"0.0100","delta_fp":"1.00","side":"yes","ts":"2026-07-01T02:35:46.915039Z","ts_ms":1782873346915}}

{"type":"orderbook_delta","sid":1,"seq":2268,"msg":{"market_ticker":"KXNEXTTEAMNBA-26LJAM-GSW","market_id":"abbbad28-f309-4dd5-af38-2ad7ebf2acc3","price_dollars":"0.0100","delta_fp":"1.00","side":"yes","ts":"2026-07-01T02:35:46.915512Z","ts_ms":1782873346915}}

{"type":"orderbook_delta","sid":1,"seq":2269,"msg":{"market_ticker":"KXNEXTTEAMNBA-26LJAM-GSW","market_id":"abbbad28-f309-4dd5-af38-2ad7ebf2acc3","price_dollars":"0.0100","delta_fp":"1.00","side":"yes","ts":"2026-07-01T02:35:46.915902Z","ts_ms":1782873346915}}

{"type":"orderbook_delta","sid":1,"seq":2270,"msg":{"market_ticker":"KXNEXTTEAMNBA-26LJAM-GSW","market_id":"abbbad28-f309-4dd5-af38-2ad7ebf2acc3","price_dollars":"0.0100","delta_fp":"1.00","side":"yes","ts":"2026-07-01T02:35:46.916341Z","ts_ms":1782873346916}}

{"type":"orderbook_delta","sid":1,"seq":2271,"msg":{"market_ticker":"KXNEXTTEAMNBA-26LJAM-GSW","market_id":"abbbad28-f309-4dd5-af38-2ad7ebf2acc3","price_dollars":"0.0100","delta_fp":"1.00","side":"yes","ts":"2026-07-01T02:35:46.916679Z","ts_ms":1782873346916}}

{"type":"orderbook_delta","sid":1,"seq":2272,"msg":{"market_ticker":"KXNEXTTEAMNBA-26LJAM-GSW","market_id":"abbbad28-f309-4dd5-af38-2ad7ebf2acc3","price_dollars":"0.0100","delta_fp":"1.00","side":"yes","ts":"2026-07-01T02:35:46.917099Z","ts_ms":1782873346917}}

{"type":"orderbook_delta","sid":1,"seq":2273,"msg":{"market_ticker":"KXNEXTTEAMNBA-26LJAM-GSW","market_id":"abbbad28-f309-4dd5-af38-2ad7ebf2acc3","price_dollars":"0.0100","delta_fp":"1.00","side":"yes","ts":"2026-07-01T02:35:46.917528Z","ts_ms":1782873346917}}

{"type":"orderbook_delta","sid":1,"seq":2274,"msg":{"market_ticker":"KXNEXTTEAMNBA-26LJAM-GSW","market_id":"abbbad28-f309-4dd5-af38-2ad7ebf2acc3","price_dollars":"0.0100","delta_fp":"1.00","side":"yes","ts":"2026-07-01T02:35:46.917857Z","ts_ms":1782873346917}}

{"type":"orderbook_delta","sid":1,"seq":2275,"msg":{"market_ticker":"KXNEXTTEAMNBA-26LJAM-GSW","market_id":"abbbad28-f309-4dd5-af38-2ad7ebf2acc3","price_dollars":"0.0100","delta_fp":"1.00","side":"yes","ts":"2026-07-01T02:35:46.918197Z","ts_ms":1782873346918}}

{"type":"orderbook_delta","sid":1,"seq":2276,"msg":{"market_ticker":"KXNEXTTEAMNBA-26LJAM-GSW","market_id":"abbbad28-f309-4dd5-af38-2ad7ebf2acc3","price_dollars":"0.0100","delta_fp":"1.00","side":"yes","ts":"2026-07-01T02:35:46.918668Z","ts_ms":1782873346918}}

{"type":"orderbook_delta","sid":1,"seq":2277,"msg":{"market_ticker":"KXNEXTTEAMNBA-26LJAM-GSW","market_id":"abbbad28-f309-4dd5-af38-2ad7ebf2acc3","price_dollars":"0.0100","delta_fp":"1.00","side":"yes","ts":"2026-07-01T02:35:46.919033Z","ts_ms":1782873346919}}

{"type":"orderbook_delta","sid":1,"seq":2278,"msg":{"market_ticker":"KXNEXTTEAMNBA-26LJAM-GSW","market_id":"abbbad28-f309-4dd5-af38-2ad7ebf2acc3","price_dollars":"0.0100","delta_fp":"1.00","side":"yes","ts":"2026-07-01T02:35:46.919401Z","ts_ms":1782873346919}}

{"type":"orderbook_delta","sid":1,"seq":2279,"msg":{"market_ticker":"KXNEXTTEAMNBA-26LJAM-GSW","market_id":"abbbad28-f309-4dd5-af38-2ad7ebf2acc3","price_dollars":"0.0100","delta_fp":"1.00","side":"yes","ts":"2026-07-01T02:35:46.919714Z","ts_ms":1782873346919}}

{"type":"orderbook_delta","sid":1,"seq":2280,"msg":{"market_ticker":"KXNEXTTEAMNBA-26LJAM-GSW","market_id":"abbbad28-f309-4dd5-af38-2ad7ebf2acc3","price_dollars":"0.0100","delta_fp":"1.00","side":"yes","ts":"2026-07-01T02:35:46.920059Z","ts_ms":1782873346920}}

{"type":"orderbook_delta","sid":1,"seq":2281,"msg":{"market_ticker":"KXNEXTTEAMNBA-26LJAM-GSW","market_id":"abbbad28-f309-4dd5-af38-2ad7ebf2acc3","price_dollars":"0.0100","delta_fp":"1.00","side":"yes","ts":"2026-07-01T02:35:46.92049Z","ts_ms":1782873346920}}

{"type":"orderbook_delta","sid":1,"seq":2282,"msg":{"market_ticker":"KXNEXTTEAMNBA-26LJAM-GSW","market_id":"abbbad28-f309-4dd5-af38-2ad7ebf2acc3","price_dollars":"0.0100","delta_fp":"1.00","side":"yes","ts":"2026-07-01T02:35:46.920827Z","ts_ms":1782873346920}}

{"type":"orderbook_delta","sid":1,"seq":2283,"msg":{"market_ticker":"KXNEXTTEAMNBA-26LJAM-GSW","market_id":"abbbad28-f309-4dd5-af38-2ad7ebf2acc3","price_dollars":"0.0100","delta_fp":"1.00","side":"yes","ts":"2026-07-01T02:35:46.921309Z","ts_ms":1782873346921}}

