{"type":"subscribed","id":2,"msg":{"channel":"orderbook_delta","sid":1}}

{"type":"ok","id":6,"sid":1,"seq":1,"msg":{"market_tickers":["KXBTCD-26JUL0317-T60499.99","KXNEXTTEAMNBA-26LJAM-MIA"]}}

{"type":"orderbook_snapshot","sid":1,"seq":2,"msg":{"market_ticker":"KXNEXTTEAMNBA-26LJAM-MIA","market_id":"492cb255-91da-4c91-bc9e-f83d090cc6dd","yes_dollars_fp":[["0.0100","1406474.86"],["0.0200","849999.66"],["0.0300","711111.04"],["0.0400","199999.92"],["0.0500","79999.92"],["0.0600","22222.20"],["0.0700","23809.50"],["0.0800","20833.30"],["0.0900","3703.70"],["0.1000","3333.33"],["0.1100","3030.30"],["0.1400","49999.95"],["0.1500","179999.82"],["0.1600","168749.73"]],"no_dollars_fp":[["0.7300","55555.20"],["0.7400","126922.95"],["0.7500","131999.67"],["0.7600","72914.36"],["0.8100","21052.56"],["0.8200","22222.20"],["0.8300","25271.76"]]}}

{"type":"ok","id":5,"sid":1,"seq":3,"msg":{"market_tickers":["KXBTCD-26JUL0317-T60499.99","KXBTCD-26JUL0317-T60999.99","KXNEXTTEAMNBA-26LJAM-MIA"]}}

{"type":"ok","id":3,"sid":1,"seq":4,"msg":{"market_tickers":["KXBTCD-26JUL0317-T60499.99","KXBTCD-26JUL0317-T60999.99","KXNEXTTEAMNBA-26LJAM-CLE","KXNEXTTEAMNBA-26LJAM-MIA"]}}

{"type":"orderbook_snapshot","sid":1,"seq":5,"msg":{"market_ticker":"KXBTCD-26JUL0317-T60499.99","market_id":"abbcf0e5-58fe-4b36-ae0d-b0eb685858c6","yes_dollars_fp":[["0.0100","23891.00"],["0.1200","1.00"],["0.1800","55555.50"],["0.1900","68420.82"],["0.2000","283332.20"],["0.2100","15873.00"],["0.2200","7575.75"]],"no_dollars_fp":[["0.4600","2469.12"],["0.4700","3773.58"],["0.4800","28204.88"],["0.4900","24836.42"],["0.5000","24666.42"],["0.5100","13666.37"],["0.6200","19298.18"],["0.6300","19819.80"],["0.6400","15133.54"],["0.7200","3571.41"],["0.7300","3703.68"],["0.7400","16666.65"],["0.7500","18666.62"],["0.7600","31944.24"],["0.7700","20289.78"]]}}

{"type":"ok","id":4,"sid":1,"seq":6,"msg":{"market_tickers":["KXBTCD-26JUL0317-T60499.99","KXBTCD-26JUL0317-T60999.99","KXNEXTTEAMNBA-26LJAM-CLE","KXNEXTTEAMNBA-26LJAM-GSW","KXNEXTTEAMNBA-26LJAM-MIA"]}}

{"type":"orderbook_snapshot","sid":1,"seq":7,"msg":{"market_ticker":"KXNEXTTEAMNBA-26LJAM-GSW","market_id":"abbbad28-f309-4dd5-af38-2ad7ebf2acc3","yes_dollars_fp":[["0.0100","42477.00"],["0.0400","366666.52"],["0.0500","593332.74"],["0.0600","494443.95"],["0.0700","166666.50"],["0.2200","115151.40"],["0.2300","166666.05"],["0.2400","108332.64"],["0.2900","116091.42"],["0.3000","117777.66"],["0.3100","115052.82"],["0.3300","1010.10"],["0.3600","925.92"],["0.3900","5982.90"],["0.4000","5833.31"],["0.4100","17836.00"],["0.4200","26984.10"],["0.4300","26356.46"],["0.4400","56817.75"],["0.4500","49626.58"],["0.4600","45886.77"],["0.4700","2745.32"]],"no_dollars_fp":[["0.0500","3139.09"],["0.2800","30555.36"],["0.2900","30985.68"],["0.3000","31428.54"],["0.3500","49743.54"],["0.3600","86457.78"],["0.3700","95346.91"],["0.4900","32679.50"],["0.5000","50666.16"],["0.5100","56663.51"],["0.5200","22672.82"]]}}

{"type":"orderbook_snapshot","sid":1,"seq":8,"msg":{"market_ticker":"KXBTCD-26JUL0317-T60999.99","market_id":"6295c1be-a688-4363-b1e2-3c08428a53aa","yes_dollars_fp":[["0.0100","10134.00"],["0.1200","200000.44"],["0.1300","238461.30"],["0.1400","221428.35"],["0.1500","59999.94"],["0.1700","7843.12"],["0.1800","5555.55"],["0.1900","3485.76"]],"no_dollars_fp":[["0.5400","25362.05"],["0.5500","62962.90"],["0.5600","81817.56"],["0.5700","61240.01"],["0.5800","37921.23"],["0.7000","2187.77"],["0.7800","1515.15"],["0.7900","1587.30"],["0.8000","1666.66"]]}}

{"type":"orderbook_snapshot","sid":1,"seq":9,"msg":{"market_ticker":"KXNEXTTEAMNBA-26LJAM-CLE","market_id":"7552b8d4-05de-4e41-84a8-97b0684da4a9","yes_dollars_fp":[["0.0100","32013.00"],["0.0600","5555.55"],["0.0700","176190.30"],["0.0800","466665.92"],["0.0900","477777.30"],["0.1000","299596.33"],["0.2300","62318.61"],["0.2400","62499.60"],["0.2500","57333.19"]],"no_dollars_fp":[["0.5700","29457.22"],["0.5800","30158.70"],["0.5900","30894.00"],["0.6300","900.90"],["0.6400","925.92"],["0.6500","952.38"],["0.6600","3921.56"],["0.6700","24242.40"],["0.6800","29166.48"],["0.6900","32257.80"],["0.7000","45907.08"],["0.7200","23809.40"],["0.7300","27160.32"],["0.7400","10693.58"]]}}

{"type":"subscribed","id":1,"msg":{"channel":"fill","sid":2}}

{"type":"orderbook_delta","sid":1,"seq":10,"msg":{"market_ticker":"KXNEXTTEAMNBA-26LJAM-CLE","market_id":"7552b8d4-05de-4e41-84a8-97b0684da4a9","price_dollars":"0.7400","delta_fp":"-1.84","side":"no","ts":"2026-07-01T02:31:45.308599Z","ts_ms":1782873105308}}

{"type":"orderbook_delta","sid":1,"seq":11,"msg":{"market_ticker":"KXNEXTTEAMNBA-26LJAM-MIA","market_id":"492cb255-91da-4c91-bc9e-f83d090cc6dd","price_dollars":"0.8300","delta_fp":"-1.43","side":"no","ts":"2026-07-01T02:31:45.309673Z","ts_ms":1782873105309}}

{"type":"orderbook_delta","sid":1,"seq":12,"msg":{"market_ticker":"KXNEXTTEAMNBA-26LJAM-GSW","market_id":"abbbad28-f309-4dd5-af38-2ad7ebf2acc3","price_dollars":"0.5200","delta_fp":"-1.37","side":"no","ts":"2026-07-01T02:31:45.370893Z","ts_ms":1782873105370}}

{"type":"orderbook_delta","sid":1,"seq":13,"msg":{"market_ticker":"KXNEXTTEAMNBA-26LJAM-MIA","market_id":"492cb255-91da-4c91-bc9e-f83d090cc6dd","price_dollars":"0.8300","delta_fp":"-0.01","side":"no","ts":"2026-07-01T02:31:45.385796Z","ts_ms":1782873105385}}

{"type":"orderbook_delta","sid":1,"seq":14,"msg":{"market_ticker":"KXNEXTTEAMNBA-26LJAM-CLE","market_id":"7552b8d4-05de-4e41-84a8-97b0684da4a9","price_dollars":"0.7400","delta_fp":"-0.27","side":"no","ts":"2026-07-01T02:31:46.871654Z","ts_ms":1782873106871}}

{"type":"orderbook_delta","sid":1,"seq":15,"msg":{"market_ticker":"KXNEXTTEAMNBA-26LJAM-GSW","market_id":"abbbad28-f309-4dd5-af38-2ad7ebf2acc3","price_dollars":"0.5200","delta_fp":"-1.32","side":"no","ts":"2026-07-01T02:31:46.876762Z","ts_ms":1782873106876}}

{"type":"orderbook_delta","sid":1,"seq":16,"msg":{"market_ticker":"KXNEXTTEAMNBA-26LJAM-CLE","market_id":"7552b8d4-05de-4e41-84a8-97b0684da4a9","price_dollars":"0.7400","delta_fp":"-0.95","side":"no","ts":"2026-07-01T02:31:46.976263Z","ts_ms":1782873106976}}

{"type":"orderbook_delta","sid":1,"seq":17,"msg":{"market_ticker":"KXNEXTTEAMNBA-26LJAM-GSW","market_id":"abbbad28-f309-4dd5-af38-2ad7ebf2acc3","price_dollars":"0.0100","delta_fp":"1.00","side":"yes","ts":"2026-07-01T02:31:48.138629Z","ts_ms":1782873108138}}

{"type":"orderbook_delta","sid":1,"seq":18,"msg":{"market_ticker":"KXNEXTTEAMNBA-26LJAM-GSW","market_id":"abbbad28-f309-4dd5-af38-2ad7ebf2acc3","price_dollars":"0.0100","delta_fp":"1.00","side":"yes","ts":"2026-07-01T02:31:48.139595Z","ts_ms":1782873108139}}

{"type":"orderbook_delta","sid":1,"seq":19,"msg":{"market_ticker":"KXNEXTTEAMNBA-26LJAM-GSW","market_id":"abbbad28-f309-4dd5-af38-2ad7ebf2acc3","price_dollars":"0.0100","delta_fp":"1.00","side":"yes","ts":"2026-07-01T02:31:48.140552Z","ts_ms":1782873108140}}

{"type":"orderbook_delta","sid":1,"seq":20,"msg":{"market_ticker":"KXNEXTTEAMNBA-26LJAM-GSW","market_id":"abbbad28-f309-4dd5-af38-2ad7ebf2acc3","price_dollars":"0.0100","delta_fp":"1.00","side":"yes","ts":"2026-07-01T02:31:48.141407Z","ts_ms":1782873108141}}

{"type":"orderbook_delta","sid":1,"seq":21,"msg":{"market_ticker":"KXNEXTTEAMNBA-26LJAM-GSW","market_id":"abbbad28-f309-4dd5-af38-2ad7ebf2acc3","price_dollars":"0.0100","delta_fp":"1.00","side":"yes","ts":"2026-07-01T02:31:48.142274Z","ts_ms":1782873108142}}

{"type":"orderbook_delta","sid":1,"seq":22,"msg":{"market_ticker":"KXNEXTTEAMNBA-26LJAM-GSW","market_id":"abbbad28-f309-4dd5-af38-2ad7ebf2acc3","price_dollars":"0.0100","delta_fp":"1.00","side":"yes","ts":"2026-07-01T02:31:48.143028Z","ts_ms":1782873108143}}

{"type":"orderbook_delta","sid":1,"seq":23,"msg":{"market_ticker":"KXNEXTTEAMNBA-26LJAM-GSW","market_id":"abbbad28-f309-4dd5-af38-2ad7ebf2acc3","price_dollars":"0.0100","delta_fp":"1.00","side":"yes","ts":"2026-07-01T02:31:48.144133Z","ts_ms":1782873108144}}

{"type":"orderbook_delta","sid":1,"seq":24,"msg":{"market_ticker":"KXNEXTTEAMNBA-26LJAM-GSW","market_id":"abbbad28-f309-4dd5-af38-2ad7ebf2acc3","price_dollars":"0.0100","delta_fp":"1.00","side":"yes","ts":"2026-07-01T02:31:48.144988Z","ts_ms":1782873108144}}

{"type":"orderbook_delta","sid":1,"seq":25,"msg":{"market_ticker":"KXNEXTTEAMNBA-26LJAM-GSW","market_id":"abbbad28-f309-4dd5-af38-2ad7ebf2acc3","price_dollars":"0.0100","delta_fp":"1.00","side":"yes","ts":"2026-07-01T02:31:48.145633Z","ts_ms":1782873108145}}

{"type":"orderbook_delta","sid":1,"seq":26,"msg":{"market_ticker":"KXNEXTTEAMNBA-26LJAM-GSW","market_id":"abbbad28-f309-4dd5-af38-2ad7ebf2acc3","price_dollars":"0.0100","delta_fp":"1.00","side":"yes","ts":"2026-07-01T02:31:48.146388Z","ts_ms":1782873108146}}

{"type":"orderbook_delta","sid":1,"seq":27,"msg":{"market_ticker":"KXNEXTTEAMNBA-26LJAM-GSW","market_id":"abbbad28-f309-4dd5-af38-2ad7ebf2acc3","price_dollars":"0.0100","delta_fp":"1.00","side":"yes","ts":"2026-07-01T02:31:48.147027Z","ts_ms":1782873108147}}

{"type":"orderbook_delta","sid":1,"seq":28,"msg":{"market_ticker":"KXNEXTTEAMNBA-26LJAM-GSW","market_id":"abbbad28-f309-4dd5-af38-2ad7ebf2acc3","price_dollars":"0.0100","delta_fp":"1.00","side":"yes","ts":"2026-07-01T02:31:48.147787Z","ts_ms":1782873108147}}

{"type":"orderbook_delta","sid":1,"seq":29,"msg":{"market_ticker":"KXNEXTTEAMNBA-26LJAM-GSW","market_id":"abbbad28-f309-4dd5-af38-2ad7ebf2acc3","price_dollars":"0.0100","delta_fp":"1.00","side":"yes","ts":"2026-07-01T02:31:48.148397Z","ts_ms":1782873108148}}

{"type":"orderbook_delta","sid":1,"seq":30,"msg":{"market_ticker":"KXNEXTTEAMNBA-26LJAM-GSW","market_id":"abbbad28-f309-4dd5-af38-2ad7ebf2acc3","price_dollars":"0.0100","delta_fp":"1.00","side":"yes","ts":"2026-07-01T02:31:48.148959Z","ts_ms":1782873108148}}

{"type":"orderbook_delta","sid":1,"seq":31,"msg":{"market_ticker":"KXNEXTTEAMNBA-26LJAM-GSW","market_id":"abbbad28-f309-4dd5-af38-2ad7ebf2acc3","price_dollars":"0.0100","delta_fp":"1.00","side":"yes","ts":"2026-07-01T02:31:48.149468Z","ts_ms":1782873108149}}

{"type":"orderbook_delta","sid":1,"seq":32,"msg":{"market_ticker":"KXNEXTTEAMNBA-26LJAM-GSW","market_id":"abbbad28-f309-4dd5-af38-2ad7ebf2acc3","price_dollars":"0.0100","delta_fp":"1.00","side":"yes","ts":"2026-07-01T02:31:48.149857Z","ts_ms":1782873108149}}

{"type":"orderbook_delta","sid":1,"seq":33,"msg":{"market_ticker":"KXNEXTTEAMNBA-26LJAM-GSW","market_id":"abbbad28-f309-4dd5-af38-2ad7ebf2acc3","price_dollars":"0.0100","delta_fp":"1.00","side":"yes","ts":"2026-07-01T02:31:48.150275Z","ts_ms":1782873108150}}

{"type":"orderbook_delta","sid":1,"seq":34,"msg":{"market_ticker":"KXNEXTTEAMNBA-26LJAM-GSW","market_id":"abbbad28-f309-4dd5-af38-2ad7ebf2acc3","price_dollars":"0.0100","delta_fp":"1.00","side":"yes","ts":"2026-07-01T02:31:48.150758Z","ts_ms":1782873108150}}

{"type":"orderbook_delta","sid":1,"seq":35,"msg":{"market_ticker":"KXNEXTTEAMNBA-26LJAM-GSW","market_id":"abbbad28-f309-4dd5-af38-2ad7ebf2acc3","price_dollars":"0.0100","delta_fp":"1.00","side":"yes","ts":"2026-07-01T02:31:48.151445Z","ts_ms":1782873108151}}

{"type":"orderbook_delta","sid":1,"seq":36,"msg":{"market_ticker":"KXNEXTTEAMNBA-26LJAM-GSW","market_id":"abbbad28-f309-4dd5-af38-2ad7ebf2acc3","price_dollars":"0.0100","delta_fp":"1.00","side":"yes","ts":"2026-07-01T02:31:48.152027Z","ts_ms":1782873108152}}

{"type":"orderbook_delta","sid":1,"seq":37,"msg":{"market_ticker":"KXNEXTTEAMNBA-26LJAM-GSW","market_id":"abbbad28-f309-4dd5-af38-2ad7ebf2acc3","price_dollars":"0.5200","delta_fp":"-0.45","side":"no","ts":"2026-07-01T02:31:48.488001Z","ts_ms":1782873108488}}

{"type":"orderbook_delta","sid":1,"seq":38,"msg":{"market_ticker":"KXNEXTTEAMNBA-26LJAM-CLE","market_id":"7552b8d4-05de-4e41-84a8-97b0684da4a9","price_dollars":"0.7400","delta_fp":"-1.55","side":"no","ts":"2026-07-01T02:31:48.566705Z","ts_ms":1782873108566}}

{"type":"orderbook_delta","sid":1,"seq":39,"msg":{"market_ticker":"KXNEXTTEAMNBA-26LJAM-MIA","market_id":"492cb255-91da-4c91-bc9e-f83d090cc6dd","price_dollars":"0.0100","delta_fp":"1.00","side":"yes","ts":"2026-07-01T02:31:48.638776Z","ts_ms":1782873108638}}

{"type":"orderbook_delta","sid":1,"seq":40,"msg":{"market_ticker":"KXNEXTTEAMNBA-26LJAM-MIA","market_id":"492cb255-91da-4c91-bc9e-f83d090cc6dd","price_dollars":"0.0100","delta_fp":"1.00","side":"yes","ts":"2026-07-01T02:31:48.639229Z","ts_ms":1782873108639}}

{"type":"orderbook_delta","sid":1,"seq":41,"msg":{"market_ticker":"KXNEXTTEAMNBA-26LJAM-MIA","market_id":"492cb255-91da-4c91-bc9e-f83d090cc6dd","price_dollars":"0.0100","delta_fp":"1.00","side":"yes","ts":"2026-07-01T02:31:48.639533Z","ts_ms":1782873108639}}

{"type":"orderbook_delta","sid":1,"seq":42,"msg":{"market_ticker":"KXNEXTTEAMNBA-26LJAM-MIA","market_id":"492cb255-91da-4c91-bc9e-f83d090cc6dd","price_dollars":"0.0100","delta_fp":"1.00","side":"yes","ts":"2026-07-01T02:31:48.639973Z","ts_ms":1782873108639}}

{"type":"orderbook_delta","sid":1,"seq":43,"msg":{"market_ticker":"KXNEXTTEAMNBA-26LJAM-MIA","market_id":"492cb255-91da-4c91-bc9e-f83d090cc6dd","price_dollars":"0.0100","delta_fp":"1.00","side":"yes","ts":"2026-07-01T02:31:48.640423Z","ts_ms":1782873108640}}

{"type":"orderbook_delta","sid":1,"seq":44,"msg":{"market_ticker":"KXNEXTTEAMNBA-26LJAM-MIA","market_id":"492cb255-91da-4c91-bc9e-f83d090cc6dd","price_dollars":"0.0100","delta_fp":"1.00","side":"yes","ts":"2026-07-01T02:31:48.640912Z","ts_ms":1782873108640}}

{"type":"orderbook_delta","sid":1,"seq":45,"msg":{"market_ticker":"KXNEXTTEAMNBA-26LJAM-MIA","market_id":"492cb255-91da-4c91-bc9e-f83d090cc6dd","price_dollars":"0.0100","delta_fp":"1.00","side":"yes","ts":"2026-07-01T02:31:48.641221Z","ts_ms":1782873108641}}

{"type":"orderbook_delta","sid":1,"seq":46,"msg":{"market_ticker":"KXNEXTTEAMNBA-26LJAM-MIA","market_id":"492cb255-91da-4c91-bc9e-f83d090cc6dd","price_dollars":"0.0100","delta_fp":"1.00","side":"yes","ts":"2026-07-01T02:31:48.641548Z","ts_ms":1782873108641}}

{"type":"orderbook_delta","sid":1,"seq":47,"msg":{"market_ticker":"KXNEXTTEAMNBA-26LJAM-MIA","market_id":"492cb255-91da-4c91-bc9e-f83d090cc6dd","price_dollars":"0.0100","delta_fp":"1.00","side":"yes","ts":"2026-07-01T02:31:48.641884Z","ts_ms":1782873108641}}

{"type":"orderbook_delta","sid":1,"seq":48,"msg":{"market_ticker":"KXNEXTTEAMNBA-26LJAM-MIA","market_id":"492cb255-91da-4c91-bc9e-f83d090cc6dd","price_dollars":"0.0100","delta_fp":"1.00","side":"yes","ts":"2026-07-01T02:31:48.642227Z","ts_ms":1782873108642}}

{"type":"orderbook_delta","sid":1,"seq":49,"msg":{"market_ticker":"KXNEXTTEAMNBA-26LJAM-MIA","market_id":"492cb255-91da-4c91-bc9e-f83d090cc6dd","price_dollars":"0.0100","delta_fp":"1.00","side":"yes","ts":"2026-07-01T02:31:48.64258Z","ts_ms":1782873108642}}

{"type":"orderbook_delta","sid":1,"seq":50,"msg":{"market_ticker":"KXNEXTTEAMNBA-26LJAM-MIA","market_id":"492cb255-91da-4c91-bc9e-f83d090cc6dd","price_dollars":"0.0100","delta_fp":"1.00","side":"yes","ts":"2026-07-01T02:31:48.643051Z","ts_ms":1782873108643}}

{"type":"orderbook_delta","sid":1,"seq":51,"msg":{"market_ticker":"KXNEXTTEAMNBA-26LJAM-MIA","market_id":"492cb255-91da-4c91-bc9e-f83d090cc6dd","price_dollars":"0.0100","delta_fp":"1.00","side":"yes","ts":"2026-07-01T02:31:48.643361Z","ts_ms":1782873108643}}

{"type":"orderbook_delta","sid":1,"seq":52,"msg":{"market_ticker":"KXNEXTTEAMNBA-26LJAM-MIA","market_id":"492cb255-91da-4c91-bc9e-f83d090cc6dd","price_dollars":"0.0100","delta_fp":"1.00","side":"yes","ts":"2026-07-01T02:31:48.643908Z","ts_ms":1782873108643}}

{"type":"orderbook_delta","sid":1,"seq":53,"msg":{"market_ticker":"KXNEXTTEAMNBA-26LJAM-MIA","market_id":"492cb255-91da-4c91-bc9e-f83d090cc6dd","price_dollars":"0.0100","delta_fp":"1.00","side":"yes","ts":"2026-07-01T02:31:48.644684Z","ts_ms":1782873108644}}

{"type":"orderbook_delta","sid":1,"seq":54,"msg":{"market_ticker":"KXNEXTTEAMNBA-26LJAM-MIA","market_id":"492cb255-91da-4c91-bc9e-f83d090cc6dd","price_dollars":"0.0100","delta_fp":"1.00","side":"yes","ts":"2026-07-01T02:31:48.645327Z","ts_ms":1782873108645}}

{"type":"orderbook_delta","sid":1,"seq":55,"msg":{"market_ticker":"KXNEXTTEAMNBA-26LJAM-MIA","market_id":"492cb255-91da-4c91-bc9e-f83d090cc6dd","price_dollars":"0.0100","delta_fp":"1.00","side":"yes","ts":"2026-07-01T02:31:48.645994Z","ts_ms":1782873108645}}

{"type":"orderbook_delta","sid":1,"seq":56,"msg":{"market_ticker":"KXNEXTTEAMNBA-26LJAM-MIA","market_id":"492cb255-91da-4c91-bc9e-f83d090cc6dd","price_dollars":"0.0100","delta_fp":"1.00","side":"yes","ts":"2026-07-01T02:31:48.646731Z","ts_ms":1782873108646}}

{"type":"orderbook_delta","sid":1,"seq":57,"msg":{"market_ticker":"KXNEXTTEAMNBA-26LJAM-MIA","market_id":"492cb255-91da-4c91-bc9e-f83d090cc6dd","price_dollars":"0.0100","delta_fp":"1.00","side":"yes","ts":"2026-07-01T02:31:48.647254Z","ts_ms":1782873108647}}

{"type":"orderbook_delta","sid":1,"seq":58,"msg":{"market_ticker":"KXNEXTTEAMNBA-26LJAM-MIA","market_id":"492cb255-91da-4c91-bc9e-f83d090cc6dd","price_dollars":"0.0100","delta_fp":"1.00","side":"yes","ts":"2026-07-01T02:31:48.648Z","ts_ms":1782873108648}}

{"type":"orderbook_delta","sid":1,"seq":59,"msg":{"market_ticker":"KXNEXTTEAMNBA-26LJAM-MIA","market_id":"492cb255-91da-4c91-bc9e-f83d090cc6dd","price_dollars":"0.8300","delta_fp":"-1.18","side":"no","ts":"2026-07-01T02:31:50.082698Z","ts_ms":1782873110082}}

{"type":"orderbook_delta","sid":1,"seq":60,"msg":{"market_ticker":"KXNEXTTEAMNBA-26LJAM-MIA","market_id":"492cb255-91da-4c91-bc9e-f83d090cc6dd","price_dollars":"0.0100","delta_fp":"-1.00","side":"yes","ts":"2026-07-01T02:31:50.660335Z","ts_ms":1782873110660}}

{"type":"orderbook_delta","sid":1,"seq":61,"msg":{"market_ticker":"KXNEXTTEAMNBA-26LJAM-MIA","market_id":"492cb255-91da-4c91-bc9e-f83d090cc6dd","price_dollars":"0.0100","delta_fp":"-1.00","side":"yes","ts":"2026-07-01T02:31:50.660834Z","ts_ms":1782873110660}}

{"type":"orderbook_delta","sid":1,"seq":62,"msg":{"market_ticker":"KXNEXTTEAMNBA-26LJAM-MIA","market_id":"492cb255-91da-4c91-bc9e-f83d090cc6dd","price_dollars":"0.0100","delta_fp":"-1.00","side":"yes","ts":"2026-07-01T02:31:50.661226Z","ts_ms":1782873110661}}

{"type":"orderbook_delta","sid":1,"seq":63,"msg":{"market_ticker":"KXNEXTTEAMNBA-26LJAM-MIA","market_id":"492cb255-91da-4c91-bc9e-f83d090cc6dd","price_dollars":"0.0100","delta_fp":"-1.00","side":"yes","ts":"2026-07-01T02:31:50.661714Z","ts_ms":1782873110661}}

{"type":"orderbook_delta","sid":1,"seq":64,"msg":{"market_ticker":"KXNEXTTEAMNBA-26LJAM-MIA","market_id":"492cb255-91da-4c91-bc9e-f83d090cc6dd","price_dollars":"0.0100","delta_fp":"-1.00","side":"yes","ts":"2026-07-01T02:31:50.662189Z","ts_ms":1782873110662}}

{"type":"orderbook_delta","sid":1,"seq":65,"msg":{"market_ticker":"KXNEXTTEAMNBA-26LJAM-MIA","market_id":"492cb255-91da-4c91-bc9e-f83d090cc6dd","price_dollars":"0.0100","delta_fp":"-1.00","side":"yes","ts":"2026-07-01T02:31:50.662589Z","ts_ms":1782873110662}}

{"type":"orderbook_delta","sid":1,"seq":66,"msg":{"market_ticker":"KXNEXTTEAMNBA-26LJAM-MIA","market_id":"492cb255-91da-4c91-bc9e-f83d090cc6dd","price_dollars":"0.0100","delta_fp":"-1.00","side":"yes","ts":"2026-07-01T02:31:50.663078Z","ts_ms":1782873110663}}

{"type":"orderbook_delta","sid":1,"seq":67,"msg":{"market_ticker":"KXNEXTTEAMNBA-26LJAM-MIA","market_id":"492cb255-91da-4c91-bc9e-f83d090cc6dd","price_dollars":"0.0100","delta_fp":"-1.00","side":"yes","ts":"2026-07-01T02:31:50.663487Z","ts_ms":1782873110663}}

{"type":"orderbook_delta","sid":1,"seq":68,"msg":{"market_ticker":"KXNEXTTEAMNBA-26LJAM-MIA","market_id":"492cb255-91da-4c91-bc9e-f83d090cc6dd","price_dollars":"0.0100","delta_fp":"-1.00","side":"yes","ts":"2026-07-01T02:31:50.663902Z","ts_ms":1782873110663}}

{"type":"orderbook_delta","sid":1,"seq":69,"msg":{"market_ticker":"KXNEXTTEAMNBA-26LJAM-MIA","market_id":"492cb255-91da-4c91-bc9e-f83d090cc6dd","price_dollars":"0.0100","delta_fp":"-1.00","side":"yes","ts":"2026-07-01T02:31:50.664393Z","ts_ms":1782873110664}}

{"type":"orderbook_delta","sid":1,"seq":70,"msg":{"market_ticker":"KXNEXTTEAMNBA-26LJAM-MIA","market_id":"492cb255-91da-4c91-bc9e-f83d090cc6dd","price_dollars":"0.0100","delta_fp":"-1.00","side":"yes","ts":"2026-07-01T02:31:50.665008Z","ts_ms":1782873110665}}

{"type":"orderbook_delta","sid":1,"seq":71,"msg":{"market_ticker":"KXNEXTTEAMNBA-26LJAM-MIA","market_id":"492cb255-91da-4c91-bc9e-f83d090cc6dd","price_dollars":"0.0100","delta_fp":"-1.00","side":"yes","ts":"2026-07-01T02:31:50.665418Z","ts_ms":1782873110665}}

{"type":"orderbook_delta","sid":1,"seq":72,"msg":{"market_ticker":"KXNEXTTEAMNBA-26LJAM-MIA","market_id":"492cb255-91da-4c91-bc9e-f83d090cc6dd","price_dollars":"0.0100","delta_fp":"-1.00","side":"yes","ts":"2026-07-01T02:31:50.665824Z","ts_ms":1782873110665}}

{"type":"orderbook_delta","sid":1,"seq":73,"msg":{"market_ticker":"KXNEXTTEAMNBA-26LJAM-MIA","market_id":"492cb255-91da-4c91-bc9e-f83d090cc6dd","price_dollars":"0.0100","delta_fp":"-1.00","side":"yes","ts":"2026-07-01T02:31:50.666269Z","ts_ms":1782873110666}}

{"type":"orderbook_delta","sid":1,"seq":74,"msg":{"market_ticker":"KXNEXTTEAMNBA-26LJAM-MIA","market_id":"492cb255-91da-4c91-bc9e-f83d090cc6dd","price_dollars":"0.0100","delta_fp":"-1.00","side":"yes","ts":"2026-07-01T02:31:50.666718Z","ts_ms":1782873110666}}

{"type":"orderbook_delta","sid":1,"seq":75,"msg":{"market_ticker":"KXNEXTTEAMNBA-26LJAM-MIA","market_id":"492cb255-91da-4c91-bc9e-f83d090cc6dd","price_dollars":"0.0100","delta_fp":"-1.00","side":"yes","ts":"2026-07-01T02:31:50.667156Z","ts_ms":1782873110667}}

{"type":"orderbook_delta","sid":1,"seq":76,"msg":{"market_ticker":"KXNEXTTEAMNBA-26LJAM-MIA","market_id":"492cb255-91da-4c91-bc9e-f83d090cc6dd","price_dollars":"0.0100","delta_fp":"-1.00","side":"yes","ts":"2026-07-01T02:31:50.667612Z","ts_ms":1782873110667}}

{"type":"orderbook_delta","sid":1,"seq":77,"msg":{"market_ticker":"KXNEXTTEAMNBA-26LJAM-MIA","market_id":"492cb255-91da-4c91-bc9e-f83d090cc6dd","price_dollars":"0.0100","delta_fp":"-1.00","side":"yes","ts":"2026-07-01T02:31:50.668309Z","ts_ms":1782873110668}}

{"type":"orderbook_delta","sid":1,"seq":78,"msg":{"market_ticker":"KXNEXTTEAMNBA-26LJAM-MIA","market_id":"492cb255-91da-4c91-bc9e-f83d090cc6dd","price_dollars":"0.0100","delta_fp":"-1.00","side":"yes","ts":"2026-07-01T02:31:50.669159Z","ts_ms":1782873110669}}

{"type":"orderbook_delta","sid":1,"seq":79,"msg":{"market_ticker":"KXNEXTTEAMNBA-26LJAM-MIA","market_id":"492cb255-91da-4c91-bc9e-f83d090cc6dd","price_dollars":"0.0100","delta_fp":"-1.00","side":"yes","ts":"2026-07-01T02:31:50.669782Z","ts_ms":1782873110669}}

{"type":"orderbook_delta","sid":1,"seq":80,"msg":{"market_ticker":"KXNEXTTEAMNBA-26LJAM-GSW","market_id":"abbbad28-f309-4dd5-af38-2ad7ebf2acc3","price_dollars":"0.5200","delta_fp":"-0.38","side":"no","ts":"2026-07-01T02:31:51.689127Z","ts_ms":1782873111689}}

{"type":"orderbook_delta","sid":1,"seq":81,"msg":{"market_ticker":"KXNEXTTEAMNBA-26LJAM-MIA","market_id":"492cb255-91da-4c91-bc9e-f83d090cc6dd","price_dollars":"0.8300","delta_fp":"-1.69","side":"no","ts":"2026-07-01T02:31:51.699995Z","ts_ms":1782873111699}}

{"type":"orderbook_delta","sid":1,"seq":82,"msg":{"market_ticker":"KXNEXTTEAMNBA-26LJAM-GSW","market_id":"abbbad28-f309-4dd5-af38-2ad7ebf2acc3","price_dollars":"0.5200","delta_fp":"-1.48","side":"no","ts":"2026-07-01T02:31:53.270636Z","ts_ms":1782873113270}}

{"type":"orderbook_delta","sid":1,"seq":83,"msg":{"market_ticker":"KXNEXTTEAMNBA-26LJAM-MIA","market_id":"492cb255-91da-4c91-bc9e-f83d090cc6dd","price_dollars":"0.8300","delta_fp":"-0.35","side":"no","ts":"2026-07-01T02:31:53.272578Z","ts_ms":1782873113272}}

{"type":"orderbook_delta","sid":1,"seq":84,"msg":{"market_ticker":"KXNEXTTEAMNBA-26LJAM-CLE","market_id":"7552b8d4-05de-4e41-84a8-97b0684da4a9","price_dollars":"0.7400","delta_fp":"-1.52","side":"no","ts":"2026-07-01T02:31:53.311658Z","ts_ms":1782873113311}}

{"type":"orderbook_delta","sid":1,"seq":85,"msg":{"market_ticker":"KXNEXTTEAMNBA-26LJAM-MIA","market_id":"492cb255-91da-4c91-bc9e-f83d090cc6dd","price_dollars":"0.8300","delta_fp":"-0.51","side":"no","ts":"2026-07-01T02:31:54.053826Z","ts_ms":1782873114053}}

{"type":"orderbook_delta","sid":1,"seq":86,"msg":{"market_ticker":"KXNEXTTEAMNBA-26LJAM-MIA","market_id":"492cb255-91da-4c91-bc9e-f83d090cc6dd","price_dollars":"0.0100","delta_fp":"1.00","side":"yes","ts":"2026-07-01T02:31:54.819316Z","ts_ms":1782873114819}}

{"type":"orderbook_delta","sid":1,"seq":87,"msg":{"market_ticker":"KXNEXTTEAMNBA-26LJAM-MIA","market_id":"492cb255-91da-4c91-bc9e-f83d090cc6dd","price_dollars":"0.0100","delta_fp":"1.00","side":"yes","ts":"2026-07-01T02:31:54.819657Z","ts_ms":1782873114819}}

{"type":"orderbook_delta","sid":1,"seq":88,"msg":{"market_ticker":"KXNEXTTEAMNBA-26LJAM-MIA","market_id":"492cb255-91da-4c91-bc9e-f83d090cc6dd","price_dollars":"0.0100","delta_fp":"1.00","side":"yes","ts":"2026-07-01T02:31:54.820116Z","ts_ms":1782873114820}}

{"type":"orderbook_delta","sid":1,"seq":89,"msg":{"market_ticker":"KXNEXTTEAMNBA-26LJAM-MIA","market_id":"492cb255-91da-4c91-bc9e-f83d090cc6dd","price_dollars":"0.0100","delta_fp":"1.00","side":"yes","ts":"2026-07-01T02:31:54.820462Z","ts_ms":1782873114820}}

{"type":"orderbook_delta","sid":1,"seq":90,"msg":{"market_ticker":"KXNEXTTEAMNBA-26LJAM-MIA","market_id":"492cb255-91da-4c91-bc9e-f83d090cc6dd","price_dollars":"0.0100","delta_fp":"1.00","side":"yes","ts":"2026-07-01T02:31:54.820903Z","ts_ms":1782873114820}}

{"type":"orderbook_delta","sid":1,"seq":91,"msg":{"market_ticker":"KXNEXTTEAMNBA-26LJAM-MIA","market_id":"492cb255-91da-4c91-bc9e-f83d090cc6dd","price_dollars":"0.0100","delta_fp":"1.00","side":"yes","ts":"2026-07-01T02:31:54.821345Z","ts_ms":1782873114821}}

{"type":"orderbook_delta","sid":1,"seq":92,"msg":{"market_ticker":"KXNEXTTEAMNBA-26LJAM-MIA","market_id":"492cb255-91da-4c91-bc9e-f83d090cc6dd","price_dollars":"0.0100","delta_fp":"1.00","side":"yes","ts":"2026-07-01T02:31:54.821776Z","ts_ms":1782873114821}}

{"type":"orderbook_delta","sid":1,"seq":93,"msg":{"market_ticker":"KXNEXTTEAMNBA-26LJAM-MIA","market_id":"492cb255-91da-4c91-bc9e-f83d090cc6dd","price_dollars":"0.0100","delta_fp":"1.00","side":"yes","ts":"2026-07-01T02:31:54.822391Z","ts_ms":1782873114822}}

{"type":"orderbook_delta","sid":1,"seq":94,"msg":{"market_ticker":"KXNEXTTEAMNBA-26LJAM-MIA","market_id":"492cb255-91da-4c91-bc9e-f83d090cc6dd","price_dollars":"0.0100","delta_fp":"1.00","side":"yes","ts":"2026-07-01T02:31:54.822898Z","ts_ms":1782873114822}}

{"type":"orderbook_delta","sid":1,"seq":95,"msg":{"market_ticker":"KXNEXTTEAMNBA-26LJAM-MIA","market_id":"492cb255-91da-4c91-bc9e-f83d090cc6dd","price_dollars":"0.0100","delta_fp":"1.00","side":"yes","ts":"2026-07-01T02:31:54.823343Z","ts_ms":1782873114823}}

{"type":"orderbook_delta","sid":1,"seq":96,"msg":{"market_ticker":"KXNEXTTEAMNBA-26LJAM-MIA","market_id":"492cb255-91da-4c91-bc9e-f83d090cc6dd","price_dollars":"0.0100","delta_fp":"1.00","side":"yes","ts":"2026-07-01T02:31:54.823858Z","ts_ms":1782873114823}}

{"type":"orderbook_delta","sid":1,"seq":97,"msg":{"market_ticker":"KXNEXTTEAMNBA-26LJAM-MIA","market_id":"492cb255-91da-4c91-bc9e-f83d090cc6dd","price_dollars":"0.0100","delta_fp":"1.00","side":"yes","ts":"2026-07-01T02:31:54.824384Z","ts_ms":1782873114824}}

{"type":"orderbook_delta","sid":1,"seq":98,"msg":{"market_ticker":"KXNEXTTEAMNBA-26LJAM-MIA","market_id":"492cb255-91da-4c91-bc9e-f83d090cc6dd","price_dollars":"0.0100","delta_fp":"1.00","side":"yes","ts":"2026-07-01T02:31:54.824985Z","ts_ms":1782873114824}}

{"type":"orderbook_delta","sid":1,"seq":99,"msg":{"market_ticker":"KXNEXTTEAMNBA-26LJAM-MIA","market_id":"492cb255-91da-4c91-bc9e-f83d090cc6dd","price_dollars":"0.0100","delta_fp":"1.00","side":"yes","ts":"2026-07-01T02:31:54.825576Z","ts_ms":1782873114825}}

{"type":"orderbook_delta","sid":1,"seq":100,"msg":{"market_ticker":"KXNEXTTEAMNBA-26LJAM-MIA","market_id":"492cb255-91da-4c91-bc9e-f83d090cc6dd","price_dollars":"0.0100","delta_fp":"1.00","side":"yes","ts":"2026-07-01T02:31:54.825923Z","ts_ms":1782873114825}}

{"type":"orderbook_delta","sid":1,"seq":101,"msg":{"market_ticker":"KXNEXTTEAMNBA-26LJAM-MIA","market_id":"492cb255-91da-4c91-bc9e-f83d090cc6dd","price_dollars":"0.0100","delta_fp":"1.00","side":"yes","ts":"2026-07-01T02:31:54.826476Z","ts_ms":1782873114826}}

{"type":"orderbook_delta","sid":1,"seq":102,"msg":{"market_ticker":"KXNEXTTEAMNBA-26LJAM-MIA","market_id":"492cb255-91da-4c91-bc9e-f83d090cc6dd","price_dollars":"0.0100","delta_fp":"1.00","side":"yes","ts":"2026-07-01T02:31:54.827071Z","ts_ms":1782873114827}}

{"type":"orderbook_delta","sid":1,"seq":103,"msg":{"market_ticker":"KXNEXTTEAMNBA-26LJAM-MIA","market_id":"492cb255-91da-4c91-bc9e-f83d090cc6dd","price_dollars":"0.0100","delta_fp":"1.00","side":"yes","ts":"2026-07-01T02:31:54.827596Z","ts_ms":1782873114827}}

{"type":"orderbook_delta","sid":1,"seq":104,"msg":{"market_ticker":"KXNEXTTEAMNBA-26LJAM-MIA","market_id":"492cb255-91da-4c91-bc9e-f83d090cc6dd","price_dollars":"0.0100","delta_fp":"1.00","side":"yes","ts":"2026-07-01T02:31:54.828304Z","ts_ms":1782873114828}}

{"type":"orderbook_delta","sid":1,"seq":105,"msg":{"market_ticker":"KXNEXTTEAMNBA-26LJAM-MIA","market_id":"492cb255-91da-4c91-bc9e-f83d090cc6dd","price_dollars":"0.0100","delta_fp":"1.00","side":"yes","ts":"2026-07-01T02:31:54.829129Z","ts_ms":1782873114829}}

{"type":"orderbook_delta","sid":1,"seq":106,"msg":{"market_ticker":"KXNEXTTEAMNBA-26LJAM-MIA","market_id":"492cb255-91da-4c91-bc9e-f83d090cc6dd","price_dollars":"0.8300","delta_fp":"-0.58","side":"no","ts":"2026-07-01T02:31:54.894135Z","ts_ms":1782873114894}}

{"type":"orderbook_delta","sid":1,"seq":107,"msg":{"market_ticker":"KXNEXTTEAMNBA-26LJAM-GSW","market_id":"abbbad28-f309-4dd5-af38-2ad7ebf2acc3","price_dollars":"0.4700","delta_fp":"709.21","side":"yes","ts":"2026-07-01T02:31:56.052559Z","ts_ms":1782873116052}}

{"type":"orderbook_delta","sid":1,"seq":108,"msg":{"market_ticker":"KXNEXTTEAMNBA-26LJAM-GSW","market_id":"abbbad28-f309-4dd5-af38-2ad7ebf2acc3","price_dollars":"0.4600","delta_fp":"724.63","side":"yes","ts":"2026-07-01T02:31:56.053109Z","ts_ms":1782873116053}}

{"type":"orderbook_delta","sid":1,"seq":109,"msg":{"market_ticker":"KXNEXTTEAMNBA-26LJAM-GSW","market_id":"abbbad28-f309-4dd5-af38-2ad7ebf2acc3","price_dollars":"0.4500","delta_fp":"740.74","side":"yes","ts":"2026-07-01T02:31:56.053724Z","ts_ms":1782873116053}}

{"type":"orderbook_delta","sid":1,"seq":110,"msg":{"market_ticker":"KXNEXTTEAMNBA-26LJAM-GSW","market_id":"abbbad28-f309-4dd5-af38-2ad7ebf2acc3","price_dollars":"0.5200","delta_fp":"694.44","side":"no","ts":"2026-07-01T02:31:56.054163Z","ts_ms":1782873116054}}

{"type":"orderbook_delta","sid":1,"seq":111,"msg":{"market_ticker":"KXNEXTTEAMNBA-26LJAM-GSW","market_id":"abbbad28-f309-4dd5-af38-2ad7ebf2acc3","price_dollars":"0.5100","delta_fp":"680.27","side":"no","ts":"2026-07-01T02:31:56.054692Z","ts_ms":1782873116054}}

{"type":"orderbook_delta","sid":1,"seq":112,"msg":{"market_ticker":"KXNEXTTEAMNBA-26LJAM-GSW","market_id":"abbbad28-f309-4dd5-af38-2ad7ebf2acc3","price_dollars":"0.5000","delta_fp":"666.66","side":"no","ts":"2026-07-01T02:31:56.055584Z","ts_ms":1782873116055}}

{"type":"orderbook_delta","sid":1,"seq":113,"msg":{"market_ticker":"KXNEXTTEAMNBA-26LJAM-CLE","market_id":"7552b8d4-05de-4e41-84a8-97b0684da4a9","price_dollars":"0.7400","delta_fp":"-0.09","side":"no","ts":"2026-07-01T02:31:56.476563Z","ts_ms":1782873116476}}

{"type":"orderbook_delta","sid":1,"seq":114,"msg":{"market_ticker":"KXNEXTTEAMNBA-26LJAM-CLE","market_id":"7552b8d4-05de-4e41-84a8-97b0684da4a9","price_dollars":"0.7400","delta_fp":"-0.17","side":"no","ts":"2026-07-01T02:31:57.758034Z","ts_ms":1782873117758}}

{"type":"orderbook_delta","sid":1,"seq":115,"msg":{"market_ticker":"KXNEXTTEAMNBA-26LJAM-MIA","market_id":"492cb255-91da-4c91-bc9e-f83d090cc6dd","price_dollars":"0.8300","delta_fp":"-1.90","side":"no","ts":"2026-07-01T02:31:57.970688Z","ts_ms":1782873117970}}

{"type":"orderbook_delta","sid":1,"seq":116,"msg":{"market_ticker":"KXNEXTTEAMNBA-26LJAM-MIA","market_id":"492cb255-91da-4c91-bc9e-f83d090cc6dd","price_dollars":"0.8300","delta_fp":"-1.82","side":"no","ts":"2026-07-01T02:31:57.975566Z","ts_ms":1782873117975}}

{"type":"orderbook_delta","sid":1,"seq":117,"msg":{"market_ticker":"KXNEXTTEAMNBA-26LJAM-GSW","market_id":"abbbad28-f309-4dd5-af38-2ad7ebf2acc3","price_dollars":"0.5200","delta_fp":"-0.22","side":"no","ts":"2026-07-01T02:31:59.598403Z","ts_ms":1782873119598}}

{"type":"orderbook_delta","sid":1,"seq":118,"msg":{"market_ticker":"KXNEXTTEAMNBA-26LJAM-GSW","market_id":"abbbad28-f309-4dd5-af38-2ad7ebf2acc3","price_dollars":"0.0100","delta_fp":"1.00","side":"yes","ts":"2026-07-01T02:32:00.757438Z","ts_ms":1782873120757}}

{"type":"orderbook_delta","sid":1,"seq":119,"msg":{"market_ticker":"KXNEXTTEAMNBA-26LJAM-GSW","market_id":"abbbad28-f309-4dd5-af38-2ad7ebf2acc3","price_dollars":"0.0100","delta_fp":"1.00","side":"yes","ts":"2026-07-01T02:32:00.758201Z","ts_ms":1782873120758}}

{"type":"orderbook_delta","sid":1,"seq":120,"msg":{"market_ticker":"KXNEXTTEAMNBA-26LJAM-GSW","market_id":"abbbad28-f309-4dd5-af38-2ad7ebf2acc3","price_dollars":"0.0100","delta_fp":"1.00","side":"yes","ts":"2026-07-01T02:32:00.759023Z","ts_ms":1782873120759}}

{"type":"orderbook_delta","sid":1,"seq":121,"msg":{"market_ticker":"KXNEXTTEAMNBA-26LJAM-GSW","market_id":"abbbad28-f309-4dd5-af38-2ad7ebf2acc3","price_dollars":"0.0100","delta_fp":"1.00","side":"yes","ts":"2026-07-01T02:32:00.759981Z","ts_ms":1782873120759}}

{"type":"orderbook_delta","sid":1,"seq":122,"msg":{"market_ticker":"KXNEXTTEAMNBA-26LJAM-GSW","market_id":"abbbad28-f309-4dd5-af38-2ad7ebf2acc3","price_dollars":"0.0100","delta_fp":"1.00","side":"yes","ts":"2026-07-01T02:32:00.761178Z","ts_ms":1782873120761}}

{"type":"orderbook_delta","sid":1,"seq":123,"msg":{"market_ticker":"KXNEXTTEAMNBA-26LJAM-GSW","market_id":"abbbad28-f309-4dd5-af38-2ad7ebf2acc3","price_dollars":"0.0100","delta_fp":"1.00","side":"yes","ts":"2026-07-01T02:32:00.762186Z","ts_ms":1782873120762}}

{"type":"orderbook_delta","sid":1,"seq":124,"msg":{"market_ticker":"KXNEXTTEAMNBA-26LJAM-GSW","market_id":"abbbad28-f309-4dd5-af38-2ad7ebf2acc3","price_dollars":"0.0100","delta_fp":"1.00","side":"yes","ts":"2026-07-01T02:32:00.762928Z","ts_ms":1782873120762}}

{"type":"orderbook_delta","sid":1,"seq":125,"msg":{"market_ticker":"KXNEXTTEAMNBA-26LJAM-GSW","market_id":"abbbad28-f309-4dd5-af38-2ad7ebf2acc3","price_dollars":"0.0100","delta_fp":"1.00","side":"yes","ts":"2026-07-01T02:32:00.763929Z","ts_ms":1782873120763}}

{"type":"orderbook_delta","sid":1,"seq":126,"msg":{"market_ticker":"KXNEXTTEAMNBA-26LJAM-GSW","market_id":"abbbad28-f309-4dd5-af38-2ad7ebf2acc3","price_dollars":"0.0100","delta_fp":"1.00","side":"yes","ts":"2026-07-01T02:32:00.764472Z","ts_ms":1782873120764}}

{"type":"orderbook_delta","sid":1,"seq":127,"msg":{"market_ticker":"KXNEXTTEAMNBA-26LJAM-GSW","market_id":"abbbad28-f309-4dd5-af38-2ad7ebf2acc3","price_dollars":"0.0100","delta_fp":"1.00","side":"yes","ts":"2026-07-01T02:32:00.7651Z","ts_ms":1782873120765}}

{"type":"orderbook_delta","sid":1,"seq":128,"msg":{"market_ticker":"KXNEXTTEAMNBA-26LJAM-GSW","market_id":"abbbad28-f309-4dd5-af38-2ad7ebf2acc3","price_dollars":"0.0100","delta_fp":"1.00","side":"yes","ts":"2026-07-01T02:32:00.765521Z","ts_ms":1782873120765}}

{"type":"orderbook_delta","sid":1,"seq":129,"msg":{"market_ticker":"KXNEXTTEAMNBA-26LJAM-GSW","market_id":"abbbad28-f309-4dd5-af38-2ad7ebf2acc3","price_dollars":"0.0100","delta_fp":"1.00","side":"yes","ts":"2026-07-01T02:32:00.766238Z","ts_ms":1782873120766}}

{"type":"orderbook_delta","sid":1,"seq":130,"msg":{"market_ticker":"KXNEXTTEAMNBA-26LJAM-GSW","market_id":"abbbad28-f309-4dd5-af38-2ad7ebf2acc3","price_dollars":"0.0100","delta_fp":"1.00","side":"yes","ts":"2026-07-01T02:32:00.76672Z","ts_ms":1782873120766}}

{"type":"orderbook_delta","sid":1,"seq":131,"msg":{"market_ticker":"KXNEXTTEAMNBA-26LJAM-GSW","market_id":"abbbad28-f309-4dd5-af38-2ad7ebf2acc3","price_dollars":"0.0100","delta_fp":"1.00","side":"yes","ts":"2026-07-01T02:32:00.767247Z","ts_ms":1782873120767}}

{"type":"orderbook_delta","sid":1,"seq":132,"msg":{"market_ticker":"KXNEXTTEAMNBA-26LJAM-GSW","market_id":"abbbad28-f309-4dd5-af38-2ad7ebf2acc3","price_dollars":"0.0100","delta_fp":"1.00","side":"yes","ts":"2026-07-01T02:32:00.767931Z","ts_ms":1782873120767}}

{"type":"orderbook_delta","sid":1,"seq":133,"msg":{"market_ticker":"KXNEXTTEAMNBA-26LJAM-GSW","market_id":"abbbad28-f309-4dd5-af38-2ad7ebf2acc3","price_dollars":"0.0100","delta_fp":"1.00","side":"yes","ts":"2026-07-01T02:32:00.768489Z","ts_ms":1782873120768}}

{"type":"orderbook_delta","sid":1,"seq":134,"msg":{"market_ticker":"KXNEXTTEAMNBA-26LJAM-GSW","market_id":"abbbad28-f309-4dd5-af38-2ad7ebf2acc3","price_dollars":"0.0100","delta_fp":"1.00","side":"yes","ts":"2026-07-01T02:32:00.768937Z","ts_ms":1782873120768}}

{"type":"orderbook_delta","sid":1,"seq":135,"msg":{"market_ticker":"KXNEXTTEAMNBA-26LJAM-GSW","market_id":"abbbad28-f309-4dd5-af38-2ad7ebf2acc3","price_dollars":"0.0100","delta_fp":"1.00","side":"yes","ts":"2026-07-01T02:32:00.769413Z","ts_ms":1782873120769}}

{"type":"orderbook_delta","sid":1,"seq":136,"msg":{"market_ticker":"KXNEXTTEAMNBA-26LJAM-GSW","market_id":"abbbad28-f309-4dd5-af38-2ad7ebf2acc3","price_dollars":"0.0100","delta_fp":"1.00","side":"yes","ts":"2026-07-01T02:32:00.770042Z","ts_ms":1782873120770}}

{"type":"orderbook_delta","sid":1,"seq":137,"msg":{"market_ticker":"KXNEXTTEAMNBA-26LJAM-GSW","market_id":"abbbad28-f309-4dd5-af38-2ad7ebf2acc3","price_dollars":"0.0100","delta_fp":"1.00","side":"yes","ts":"2026-07-01T02:32:00.77051Z","ts_ms":1782873120770}}

{"type":"orderbook_delta","sid":1,"seq":138,"msg":{"market_ticker":"KXNEXTTEAMNBA-26LJAM-MIA","market_id":"492cb255-91da-4c91-bc9e-f83d090cc6dd","price_dollars":"0.8300","delta_fp":"-0.14","side":"no","ts":"2026-07-01T02:32:00.886591Z","ts_ms":1782873120886}}

{"type":"orderbook_delta","sid":1,"seq":139,"msg":{"market_ticker":"KXNEXTTEAMNBA-26LJAM-MIA","market_id":"492cb255-91da-4c91-bc9e-f83d090cc6dd","price_dollars":"0.0100","delta_fp":"1.00","side":"yes","ts":"2026-07-01T02:32:01.356614Z","ts_ms":1782873121356}}

{"type":"orderbook_delta","sid":1,"seq":140,"msg":{"market_ticker":"KXNEXTTEAMNBA-26LJAM-MIA","market_id":"492cb255-91da-4c91-bc9e-f83d090cc6dd","price_dollars":"0.0100","delta_fp":"1.00","side":"yes","ts":"2026-07-01T02:32:01.356963Z","ts_ms":1782873121356}}

{"type":"orderbook_delta","sid":1,"seq":141,"msg":{"market_ticker":"KXNEXTTEAMNBA-26LJAM-MIA","market_id":"492cb255-91da-4c91-bc9e-f83d090cc6dd","price_dollars":"0.0100","delta_fp":"1.00","side":"yes","ts":"2026-07-01T02:32:01.357316Z","ts_ms":1782873121357}}

{"type":"orderbook_delta","sid":1,"seq":142,"msg":{"market_ticker":"KXNEXTTEAMNBA-26LJAM-MIA","market_id":"492cb255-91da-4c91-bc9e-f83d090cc6dd","price_dollars":"0.0100","delta_fp":"1.00","side":"yes","ts":"2026-07-01T02:32:01.357921Z","ts_ms":1782873121357}}

{"type":"orderbook_delta","sid":1,"seq":143,"msg":{"market_ticker":"KXNEXTTEAMNBA-26LJAM-MIA","market_id":"492cb255-91da-4c91-bc9e-f83d090cc6dd","price_dollars":"0.0100","delta_fp":"1.00","side":"yes","ts":"2026-07-01T02:32:01.358429Z","ts_ms":1782873121358}}

{"type":"orderbook_delta","sid":1,"seq":144,"msg":{"market_ticker":"KXNEXTTEAMNBA-26LJAM-MIA","market_id":"492cb255-91da-4c91-bc9e-f83d090cc6dd","price_dollars":"0.0100","delta_fp":"1.00","side":"yes","ts":"2026-07-01T02:32:01.358976Z","ts_ms":1782873121358}}

{"type":"orderbook_delta","sid":1,"seq":145,"msg":{"market_ticker":"KXNEXTTEAMNBA-26LJAM-MIA","market_id":"492cb255-91da-4c91-bc9e-f83d090cc6dd","price_dollars":"0.0100","delta_fp":"1.00","side":"yes","ts":"2026-07-01T02:32:01.359565Z","ts_ms":1782873121359}}

{"type":"orderbook_delta","sid":1,"seq":146,"msg":{"market_ticker":"KXNEXTTEAMNBA-26LJAM-MIA","market_id":"492cb255-91da-4c91-bc9e-f83d090cc6dd","price_dollars":"0.0100","delta_fp":"1.00","side":"yes","ts":"2026-07-01T02:32:01.360087Z","ts_ms":1782873121360}}

{"type":"orderbook_delta","sid":1,"seq":147,"msg":{"market_ticker":"KXNEXTTEAMNBA-26LJAM-MIA","market_id":"492cb255-91da-4c91-bc9e-f83d090cc6dd","price_dollars":"0.0100","delta_fp":"1.00","side":"yes","ts":"2026-07-01T02:32:01.360434Z","ts_ms":1782873121360}}

{"type":"orderbook_delta","sid":1,"seq":148,"msg":{"market_ticker":"KXNEXTTEAMNBA-26LJAM-MIA","market_id":"492cb255-91da-4c91-bc9e-f83d090cc6dd","price_dollars":"0.0100","delta_fp":"1.00","side":"yes","ts":"2026-07-01T02:32:01.360804Z","ts_ms":1782873121360}}

{"type":"orderbook_delta","sid":1,"seq":149,"msg":{"market_ticker":"KXNEXTTEAMNBA-26LJAM-MIA","market_id":"492cb255-91da-4c91-bc9e-f83d090cc6dd","price_dollars":"0.0100","delta_fp":"1.00","side":"yes","ts":"2026-07-01T02:32:01.361231Z","ts_ms":1782873121361}}

{"type":"orderbook_delta","sid":1,"seq":150,"msg":{"market_ticker":"KXNEXTTEAMNBA-26LJAM-MIA","market_id":"492cb255-91da-4c91-bc9e-f83d090cc6dd","price_dollars":"0.0100","delta_fp":"1.00","side":"yes","ts":"2026-07-01T02:32:01.361606Z","ts_ms":1782873121361}}

{"type":"orderbook_delta","sid":1,"seq":151,"msg":{"market_ticker":"KXNEXTTEAMNBA-26LJAM-MIA","market_id":"492cb255-91da-4c91-bc9e-f83d090cc6dd","price_dollars":"0.0100","delta_fp":"1.00","side":"yes","ts":"2026-07-01T02:32:01.36205Z","ts_ms":1782873121362}}

{"type":"orderbook_delta","sid":1,"seq":152,"msg":{"market_ticker":"KXNEXTTEAMNBA-26LJAM-MIA","market_id":"492cb255-91da-4c91-bc9e-f83d090cc6dd","price_dollars":"0.0100","delta_fp":"1.00","side":"yes","ts":"2026-07-01T02:32:01.362493Z","ts_ms":1782873121362}}

{"type":"orderbook_delta","sid":1,"seq":153,"msg":{"market_ticker":"KXNEXTTEAMNBA-26LJAM-MIA","market_id":"492cb255-91da-4c91-bc9e-f83d090cc6dd","price_dollars":"0.0100","delta_fp":"1.00","side":"yes","ts":"2026-07-01T02:32:01.362902Z","ts_ms":1782873121362}}

{"type":"orderbook_delta","sid":1,"seq":154,"msg":{"market_ticker":"KXNEXTTEAMNBA-26LJAM-MIA","market_id":"492cb255-91da-4c91-bc9e-f83d090cc6dd","price_dollars":"0.0100","delta_fp":"1.00","side":"yes","ts":"2026-07-01T02:32:01.363211Z","ts_ms":1782873121363}}

{"type":"orderbook_delta","sid":1,"seq":155,"msg":{"market_ticker":"KXNEXTTEAMNBA-26LJAM-MIA","market_id":"492cb255-91da-4c91-bc9e-f83d090cc6dd","price_dollars":"0.0100","delta_fp":"1.00","side":"yes","ts":"2026-07-01T02:32:01.363602Z","ts_ms":1782873121363}}

{"type":"orderbook_delta","sid":1,"seq":156,"msg":{"market_ticker":"KXNEXTTEAMNBA-26LJAM-MIA","market_id":"492cb255-91da-4c91-bc9e-f83d090cc6dd","price_dollars":"0.0100","delta_fp":"1.00","side":"yes","ts":"2026-07-01T02:32:01.363958Z","ts_ms":1782873121363}}

{"type":"orderbook_delta","sid":1,"seq":157,"msg":{"market_ticker":"KXNEXTTEAMNBA-26LJAM-MIA","market_id":"492cb255-91da-4c91-bc9e-f83d090cc6dd","price_dollars":"0.0100","delta_fp":"1.00","side":"yes","ts":"2026-07-01T02:32:01.364327Z","ts_ms":1782873121364}}

{"type":"orderbook_delta","sid":1,"seq":158,"msg":{"market_ticker":"KXNEXTTEAMNBA-26LJAM-MIA","market_id":"492cb255-91da-4c91-bc9e-f83d090cc6dd","price_dollars":"0.0100","delta_fp":"1.00","side":"yes","ts":"2026-07-01T02:32:01.364658Z","ts_ms":1782873121364}}

{"type":"orderbook_delta","sid":1,"seq":159,"msg":{"market_ticker":"KXNEXTTEAMNBA-26LJAM-GSW","market_id":"abbbad28-f309-4dd5-af38-2ad7ebf2acc3","price_dollars":"0.0100","delta_fp":"-1.00","side":"yes","ts":"2026-07-01T02:32:02.5322Z","ts_ms":1782873122532}}

{"type":"orderbook_delta","sid":1,"seq":160,"msg":{"market_ticker":"KXNEXTTEAMNBA-26LJAM-GSW","market_id":"abbbad28-f309-4dd5-af38-2ad7ebf2acc3","price_dollars":"0.0100","delta_fp":"-1.00","side":"yes","ts":"2026-07-01T02:32:02.532784Z","ts_ms":1782873122532}}

{"type":"orderbook_delta","sid":1,"seq":161,"msg":{"market_ticker":"KXNEXTTEAMNBA-26LJAM-GSW","market_id":"abbbad28-f309-4dd5-af38-2ad7ebf2acc3","price_dollars":"0.0100","delta_fp":"-1.00","side":"yes","ts":"2026-07-01T02:32:02.533476Z","ts_ms":1782873122533}}

{"type":"orderbook_delta","sid":1,"seq":162,"msg":{"market_ticker":"KXNEXTTEAMNBA-26LJAM-GSW","market_id":"abbbad28-f309-4dd5-af38-2ad7ebf2acc3","price_dollars":"0.0100","delta_fp":"-1.00","side":"yes","ts":"2026-07-01T02:32:02.533936Z","ts_ms":1782873122533}}

{"type":"orderbook_delta","sid":1,"seq":163,"msg":{"market_ticker":"KXNEXTTEAMNBA-26LJAM-GSW","market_id":"abbbad28-f309-4dd5-af38-2ad7ebf2acc3","price_dollars":"0.0100","delta_fp":"-1.00","side":"yes","ts":"2026-07-01T02:32:02.534631Z","ts_ms":1782873122534}}

{"type":"orderbook_delta","sid":1,"seq":164,"msg":{"market_ticker":"KXNEXTTEAMNBA-26LJAM-GSW","market_id":"abbbad28-f309-4dd5-af38-2ad7ebf2acc3","price_dollars":"0.0100","delta_fp":"-1.00","side":"yes","ts":"2026-07-01T02:32:02.53527Z","ts_ms":1782873122535}}

{"type":"orderbook_delta","sid":1,"seq":165,"msg":{"market_ticker":"KXNEXTTEAMNBA-26LJAM-GSW","market_id":"abbbad28-f309-4dd5-af38-2ad7ebf2acc3","price_dollars":"0.0100","delta_fp":"-1.00","side":"yes","ts":"2026-07-01T02:32:02.544258Z","ts_ms":1782873122544}}

{"type":"orderbook_delta","sid":1,"seq":166,"msg":{"market_ticker":"KXNEXTTEAMNBA-26LJAM-GSW","market_id":"abbbad28-f309-4dd5-af38-2ad7ebf2acc3","price_dollars":"0.0100","delta_fp":"-1.00","side":"yes","ts":"2026-07-01T02:32:02.544788Z","ts_ms":1782873122544}}

{"type":"orderbook_delta","sid":1,"seq":167,"msg":{"market_ticker":"KXNEXTTEAMNBA-26LJAM-GSW","market_id":"abbbad28-f309-4dd5-af38-2ad7ebf2acc3","price_dollars":"0.0100","delta_fp":"-1.00","side":"yes","ts":"2026-07-01T02:32:02.545463Z","ts_ms":1782873122545}}

{"type":"orderbook_delta","sid":1,"seq":168,"msg":{"market_ticker":"KXNEXTTEAMNBA-26LJAM-GSW","market_id":"abbbad28-f309-4dd5-af38-2ad7ebf2acc3","price_dollars":"0.0100","delta_fp":"-1.00","side":"yes","ts":"2026-07-01T02:32:02.54583Z","ts_ms":1782873122545}}

{"type":"orderbook_delta","sid":1,"seq":169,"msg":{"market_ticker":"KXNEXTTEAMNBA-26LJAM-GSW","market_id":"abbbad28-f309-4dd5-af38-2ad7ebf2acc3","price_dollars":"0.0100","delta_fp":"-1.00","side":"yes","ts":"2026-07-01T02:32:02.546244Z","ts_ms":1782873122546}}

{"type":"orderbook_delta","sid":1,"seq":170,"msg":{"market_ticker":"KXNEXTTEAMNBA-26LJAM-GSW","market_id":"abbbad28-f309-4dd5-af38-2ad7ebf2acc3","price_dollars":"0.0100","delta_fp":"-1.00","side":"yes","ts":"2026-07-01T02:32:02.546584Z","ts_ms":1782873122546}}

{"type":"orderbook_delta","sid":1,"seq":171,"msg":{"market_ticker":"KXNEXTTEAMNBA-26LJAM-GSW","market_id":"abbbad28-f309-4dd5-af38-2ad7ebf2acc3","price_dollars":"0.0100","delta_fp":"-1.00","side":"yes","ts":"2026-07-01T02:32:02.546896Z","ts_ms":1782873122546}}

{"type":"orderbook_delta","sid":1,"seq":172,"msg":{"market_ticker":"KXNEXTTEAMNBA-26LJAM-GSW","market_id":"abbbad28-f309-4dd5-af38-2ad7ebf2acc3","price_dollars":"0.0100","delta_fp":"-1.00","side":"yes","ts":"2026-07-01T02:32:02.547245Z","ts_ms":1782873122547}}

{"type":"orderbook_delta","sid":1,"seq":173,"msg":{"market_ticker":"KXNEXTTEAMNBA-26LJAM-GSW","market_id":"abbbad28-f309-4dd5-af38-2ad7ebf2acc3","price_dollars":"0.0100","delta_fp":"-1.00","side":"yes","ts":"2026-07-01T02:32:02.547605Z","ts_ms":1782873122547}}

{"type":"orderbook_delta","sid":1,"seq":174,"msg":{"market_ticker":"KXNEXTTEAMNBA-26LJAM-GSW","market_id":"abbbad28-f309-4dd5-af38-2ad7ebf2acc3","price_dollars":"0.0100","delta_fp":"-1.00","side":"yes","ts":"2026-07-01T02:32:02.547886Z","ts_ms":1782873122547}}

{"type":"orderbook_delta","sid":1,"seq":175,"msg":{"market_ticker":"KXNEXTTEAMNBA-26LJAM-GSW","market_id":"abbbad28-f309-4dd5-af38-2ad7ebf2acc3","price_dollars":"0.0100","delta_fp":"-1.00","side":"yes","ts":"2026-07-01T02:32:02.548155Z","ts_ms":1782873122548}}

{"type":"orderbook_delta","sid":1,"seq":176,"msg":{"market_ticker":"KXNEXTTEAMNBA-26LJAM-GSW","market_id":"abbbad28-f309-4dd5-af38-2ad7ebf2acc3","price_dollars":"0.0100","delta_fp":"-1.00","side":"yes","ts":"2026-07-01T02:32:02.548424Z","ts_ms":1782873122548}}

{"type":"orderbook_delta","sid":1,"seq":177,"msg":{"market_ticker":"KXNEXTTEAMNBA-26LJAM-GSW","market_id":"abbbad28-f309-4dd5-af38-2ad7ebf2acc3","price_dollars":"0.0100","delta_fp":"-1.00","side":"yes","ts":"2026-07-01T02:32:02.548777Z","ts_ms":1782873122548}}

{"type":"orderbook_delta","sid":1,"seq":178,"msg":{"market_ticker":"KXNEXTTEAMNBA-26LJAM-GSW","market_id":"abbbad28-f309-4dd5-af38-2ad7ebf2acc3","price_dollars":"0.0100","delta_fp":"-1.00","side":"yes","ts":"2026-07-01T02:32:02.549087Z","ts_ms":1782873122549}}

{"type":"orderbook_delta","sid":1,"seq":179,"msg":{"market_ticker":"KXNEXTTEAMNBA-26LJAM-MIA","market_id":"492cb255-91da-4c91-bc9e-f83d090cc6dd","price_dollars":"0.8300","delta_fp":"-1.52","side":"no","ts":"2026-07-01T02:32:02.759722Z","ts_ms":1782873122759}}

{"type":"orderbook_delta","sid":1,"seq":180,"msg":{"market_ticker":"KXNEXTTEAMNBA-26LJAM-CLE","market_id":"7552b8d4-05de-4e41-84a8-97b0684da4a9","price_dollars":"0.7400","delta_fp":"-1.45","side":"no","ts":"2026-07-01T02:32:05.886096Z","ts_ms":1782873125886}}

{"type":"orderbook_delta","sid":1,"seq":181,"msg":{"market_ticker":"KXNEXTTEAMNBA-26LJAM-GSW","market_id":"abbbad28-f309-4dd5-af38-2ad7ebf2acc3","price_dollars":"0.0100","delta_fp":"1.00","side":"yes","ts":"2026-07-01T02:32:06.849468Z","ts_ms":1782873126849}}

{"type":"orderbook_delta","sid":1,"seq":182,"msg":{"market_ticker":"KXNEXTTEAMNBA-26LJAM-GSW","market_id":"abbbad28-f309-4dd5-af38-2ad7ebf2acc3","price_dollars":"0.0100","delta_fp":"1.00","side":"yes","ts":"2026-07-01T02:32:06.850201Z","ts_ms":1782873126850}}

{"type":"orderbook_delta","sid":1,"seq":183,"msg":{"market_ticker":"KXNEXTTEAMNBA-26LJAM-GSW","market_id":"abbbad28-f309-4dd5-af38-2ad7ebf2acc3","price_dollars":"0.0100","delta_fp":"1.00","side":"yes","ts":"2026-07-01T02:32:06.850671Z","ts_ms":1782873126850}}

{"type":"orderbook_delta","sid":1,"seq":184,"msg":{"market_ticker":"KXNEXTTEAMNBA-26LJAM-GSW","market_id":"abbbad28-f309-4dd5-af38-2ad7ebf2acc3","price_dollars":"0.0100","delta_fp":"1.00","side":"yes","ts":"2026-07-01T02:32:06.85198Z","ts_ms":1782873126851}}

{"type":"orderbook_delta","sid":1,"seq":185,"msg":{"market_ticker":"KXNEXTTEAMNBA-26LJAM-GSW","market_id":"abbbad28-f309-4dd5-af38-2ad7ebf2acc3","price_dollars":"0.0100","delta_fp":"1.00","side":"yes","ts":"2026-07-01T02:32:06.85281Z","ts_ms":1782873126852}}

{"type":"orderbook_delta","sid":1,"seq":186,"msg":{"market_ticker":"KXNEXTTEAMNBA-26LJAM-GSW","market_id":"abbbad28-f309-4dd5-af38-2ad7ebf2acc3","price_dollars":"0.0100","delta_fp":"1.00","side":"yes","ts":"2026-07-01T02:32:06.85346Z","ts_ms":1782873126853}}

{"type":"orderbook_delta","sid":1,"seq":187,"msg":{"market_ticker":"KXNEXTTEAMNBA-26LJAM-GSW","market_id":"abbbad28-f309-4dd5-af38-2ad7ebf2acc3","price_dollars":"0.0100","delta_fp":"1.00","side":"yes","ts":"2026-07-01T02:32:06.854135Z","ts_ms":1782873126854}}

{"type":"orderbook_delta","sid":1,"seq":188,"msg":{"market_ticker":"KXNEXTTEAMNBA-26LJAM-GSW","market_id":"abbbad28-f309-4dd5-af38-2ad7ebf2acc3","price_dollars":"0.0100","delta_fp":"1.00","side":"yes","ts":"2026-07-01T02:32:06.854798Z","ts_ms":1782873126854}}

{"type":"orderbook_delta","sid":1,"seq":189,"msg":{"market_ticker":"KXNEXTTEAMNBA-26LJAM-GSW","market_id":"abbbad28-f309-4dd5-af38-2ad7ebf2acc3","price_dollars":"0.0100","delta_fp":"1.00","side":"yes","ts":"2026-07-01T02:32:06.855468Z","ts_ms":1782873126855}}

{"type":"orderbook_delta","sid":1,"seq":190,"msg":{"market_ticker":"KXNEXTTEAMNBA-26LJAM-GSW","market_id":"abbbad28-f309-4dd5-af38-2ad7ebf2acc3","price_dollars":"0.0100","delta_fp":"1.00","side":"yes","ts":"2026-07-01T02:32:06.85602Z","ts_ms":1782873126856}}

{"type":"orderbook_delta","sid":1,"seq":191,"msg":{"market_ticker":"KXNEXTTEAMNBA-26LJAM-GSW","market_id":"abbbad28-f309-4dd5-af38-2ad7ebf2acc3","price_dollars":"0.0100","delta_fp":"1.00","side":"yes","ts":"2026-07-01T02:32:06.856841Z","ts_ms":1782873126856}}

{"type":"orderbook_delta","sid":1,"seq":192,"msg":{"market_ticker":"KXNEXTTEAMNBA-26LJAM-GSW","market_id":"abbbad28-f309-4dd5-af38-2ad7ebf2acc3","price_dollars":"0.0100","delta_fp":"1.00","side":"yes","ts":"2026-07-01T02:32:06.857396Z","ts_ms":1782873126857}}

{"type":"orderbook_delta","sid":1,"seq":193,"msg":{"market_ticker":"KXNEXTTEAMNBA-26LJAM-GSW","market_id":"abbbad28-f309-4dd5-af38-2ad7ebf2acc3","price_dollars":"0.0100","delta_fp":"1.00","side":"yes","ts":"2026-07-01T02:32:06.858067Z","ts_ms":1782873126858}}

{"type":"orderbook_delta","sid":1,"seq":194,"msg":{"market_ticker":"KXNEXTTEAMNBA-26LJAM-GSW","market_id":"abbbad28-f309-4dd5-af38-2ad7ebf2acc3","price_dollars":"0.0100","delta_fp":"1.00","side":"yes","ts":"2026-07-01T02:32:06.858774Z","ts_ms":1782873126858}}

{"type":"orderbook_delta","sid":1,"seq":195,"msg":{"market_ticker":"KXNEXTTEAMNBA-26LJAM-GSW","market_id":"abbbad28-f309-4dd5-af38-2ad7ebf2acc3","price_dollars":"0.0100","delta_fp":"1.00","side":"yes","ts":"2026-07-01T02:32:06.859397Z","ts_ms":1782873126859}}

{"type":"orderbook_delta","sid":1,"seq":196,"msg":{"market_ticker":"KXNEXTTEAMNBA-26LJAM-GSW","market_id":"abbbad28-f309-4dd5-af38-2ad7ebf2acc3","price_dollars":"0.0100","delta_fp":"1.00","side":"yes","ts":"2026-07-01T02:32:06.859975Z","ts_ms":1782873126859}}

{"type":"orderbook_delta","sid":1,"seq":197,"msg":{"market_ticker":"KXNEXTTEAMNBA-26LJAM-GSW","market_id":"abbbad28-f309-4dd5-af38-2ad7ebf2acc3","price_dollars":"0.0100","delta_fp":"1.00","side":"yes","ts":"2026-07-01T02:32:06.860394Z","ts_ms":1782873126860}}

{"type":"orderbook_delta","sid":1,"seq":198,"msg":{"market_ticker":"KXNEXTTEAMNBA-26LJAM-GSW","market_id":"abbbad28-f309-4dd5-af38-2ad7ebf2acc3","price_dollars":"0.0100","delta_fp":"1.00","side":"yes","ts":"2026-07-01T02:32:06.861111Z","ts_ms":1782873126861}}

{"type":"orderbook_delta","sid":1,"seq":199,"msg":{"market_ticker":"KXNEXTTEAMNBA-26LJAM-GSW","market_id":"abbbad28-f309-4dd5-af38-2ad7ebf2acc3","price_dollars":"0.0100","delta_fp":"1.00","side":"yes","ts":"2026-07-01T02:32:06.861615Z","ts_ms":1782873126861}}

{"type":"orderbook_delta","sid":1,"seq":200,"msg":{"market_ticker":"KXNEXTTEAMNBA-26LJAM-GSW","market_id":"abbbad28-f309-4dd5-af38-2ad7ebf2acc3","price_dollars":"0.0100","delta_fp":"1.00","side":"yes","ts":"2026-07-01T02:32:06.862061Z","ts_ms":1782873126862}}

{"type":"orderbook_delta","sid":1,"seq":201,"msg":{"market_ticker":"KXNEXTTEAMNBA-26LJAM-MIA","market_id":"492cb255-91da-4c91-bc9e-f83d090cc6dd","price_dollars":"0.0100","delta_fp":"1.00","side":"yes","ts":"2026-07-01T02:32:07.355841Z","ts_ms":1782873127355}}

{"type":"orderbook_delta","sid":1,"seq":202,"msg":{"market_ticker":"KXNEXTTEAMNBA-26LJAM-MIA","market_id":"492cb255-91da-4c91-bc9e-f83d090cc6dd","price_dollars":"0.0100","delta_fp":"1.00","side":"yes","ts":"2026-07-01T02:32:07.35632Z","ts_ms":1782873127356}}

{"type":"orderbook_delta","sid":1,"seq":203,"msg":{"market_ticker":"KXNEXTTEAMNBA-26LJAM-MIA","market_id":"492cb255-91da-4c91-bc9e-f83d090cc6dd","price_dollars":"0.0100","delta_fp":"1.00","side":"yes","ts":"2026-07-01T02:32:07.357034Z","ts_ms":1782873127357}}

{"type":"orderbook_delta","sid":1,"seq":204,"msg":{"market_ticker":"KXNEXTTEAMNBA-26LJAM-MIA","market_id":"492cb255-91da-4c91-bc9e-f83d090cc6dd","price_dollars":"0.0100","delta_fp":"1.00","side":"yes","ts":"2026-07-01T02:32:07.357689Z","ts_ms":1782873127357}}

{"type":"orderbook_delta","sid":1,"seq":205,"msg":{"market_ticker":"KXNEXTTEAMNBA-26LJAM-MIA","market_id":"492cb255-91da-4c91-bc9e-f83d090cc6dd","price_dollars":"0.0100","delta_fp":"1.00","side":"yes","ts":"2026-07-01T02:32:07.358366Z","ts_ms":1782873127358}}

{"type":"orderbook_delta","sid":1,"seq":206,"msg":{"market_ticker":"KXNEXTTEAMNBA-26LJAM-MIA","market_id":"492cb255-91da-4c91-bc9e-f83d090cc6dd","price_dollars":"0.0100","delta_fp":"1.00","side":"yes","ts":"2026-07-01T02:32:07.35896Z","ts_ms":1782873127358}}

{"type":"orderbook_delta","sid":1,"seq":207,"msg":{"market_ticker":"KXNEXTTEAMNBA-26LJAM-MIA","market_id":"492cb255-91da-4c91-bc9e-f83d090cc6dd","price_dollars":"0.0100","delta_fp":"1.00","side":"yes","ts":"2026-07-01T02:32:07.359507Z","ts_ms":1782873127359}}

{"type":"orderbook_delta","sid":1,"seq":208,"msg":{"market_ticker":"KXNEXTTEAMNBA-26LJAM-MIA","market_id":"492cb255-91da-4c91-bc9e-f83d090cc6dd","price_dollars":"0.0100","delta_fp":"1.00","side":"yes","ts":"2026-07-01T02:32:07.360078Z","ts_ms":1782873127360}}

{"type":"orderbook_delta","sid":1,"seq":209,"msg":{"market_ticker":"KXNEXTTEAMNBA-26LJAM-MIA","market_id":"492cb255-91da-4c91-bc9e-f83d090cc6dd","price_dollars":"0.0100","delta_fp":"1.00","side":"yes","ts":"2026-07-01T02:32:07.360581Z","ts_ms":1782873127360}}

{"type":"orderbook_delta","sid":1,"seq":210,"msg":{"market_ticker":"KXNEXTTEAMNBA-26LJAM-MIA","market_id":"492cb255-91da-4c91-bc9e-f83d090cc6dd","price_dollars":"0.0100","delta_fp":"1.00","side":"yes","ts":"2026-07-01T02:32:07.361063Z","ts_ms":1782873127361}}

{"type":"orderbook_delta","sid":1,"seq":211,"msg":{"market_ticker":"KXNEXTTEAMNBA-26LJAM-MIA","market_id":"492cb255-91da-4c91-bc9e-f83d090cc6dd","price_dollars":"0.0100","delta_fp":"1.00","side":"yes","ts":"2026-07-01T02:32:07.361597Z","ts_ms":1782873127361}}

{"type":"orderbook_delta","sid":1,"seq":212,"msg":{"market_ticker":"KXNEXTTEAMNBA-26LJAM-MIA","market_id":"492cb255-91da-4c91-bc9e-f83d090cc6dd","price_dollars":"0.0100","delta_fp":"1.00","side":"yes","ts":"2026-07-01T02:32:07.362196Z","ts_ms":1782873127362}}

{"type":"orderbook_delta","sid":1,"seq":213,"msg":{"market_ticker":"KXNEXTTEAMNBA-26LJAM-MIA","market_id":"492cb255-91da-4c91-bc9e-f83d090cc6dd","price_dollars":"0.0100","delta_fp":"1.00","side":"yes","ts":"2026-07-01T02:32:07.362691Z","ts_ms":1782873127362}}

{"type":"orderbook_delta","sid":1,"seq":214,"msg":{"market_ticker":"KXNEXTTEAMNBA-26LJAM-MIA","market_id":"492cb255-91da-4c91-bc9e-f83d090cc6dd","price_dollars":"0.0100","delta_fp":"1.00","side":"yes","ts":"2026-07-01T02:32:07.363104Z","ts_ms":1782873127363}}

{"type":"orderbook_delta","sid":1,"seq":215,"msg":{"market_ticker":"KXNEXTTEAMNBA-26LJAM-MIA","market_id":"492cb255-91da-4c91-bc9e-f83d090cc6dd","price_dollars":"0.0100","delta_fp":"1.00","side":"yes","ts":"2026-07-01T02:32:07.363419Z","ts_ms":1782873127363}}

{"type":"orderbook_delta","sid":1,"seq":216,"msg":{"market_ticker":"KXNEXTTEAMNBA-26LJAM-MIA","market_id":"492cb255-91da-4c91-bc9e-f83d090cc6dd","price_dollars":"0.0100","delta_fp":"1.00","side":"yes","ts":"2026-07-01T02:32:07.363963Z","ts_ms":1782873127363}}

{"type":"orderbook_delta","sid":1,"seq":217,"msg":{"market_ticker":"KXNEXTTEAMNBA-26LJAM-MIA","market_id":"492cb255-91da-4c91-bc9e-f83d090cc6dd","price_dollars":"0.0100","delta_fp":"1.00","side":"yes","ts":"2026-07-01T02:32:07.364421Z","ts_ms":1782873127364}}

{"type":"orderbook_delta","sid":1,"seq":218,"msg":{"market_ticker":"KXNEXTTEAMNBA-26LJAM-MIA","market_id":"492cb255-91da-4c91-bc9e-f83d090cc6dd","price_dollars":"0.0100","delta_fp":"1.00","side":"yes","ts":"2026-07-01T02:32:07.364881Z","ts_ms":1782873127364}}

{"type":"orderbook_delta","sid":1,"seq":219,"msg":{"market_ticker":"KXNEXTTEAMNBA-26LJAM-MIA","market_id":"492cb255-91da-4c91-bc9e-f83d090cc6dd","price_dollars":"0.0100","delta_fp":"1.00","side":"yes","ts":"2026-07-01T02:32:07.365208Z","ts_ms":1782873127365}}

{"type":"orderbook_delta","sid":1,"seq":220,"msg":{"market_ticker":"KXNEXTTEAMNBA-26LJAM-MIA","market_id":"492cb255-91da-4c91-bc9e-f83d090cc6dd","price_dollars":"0.0100","delta_fp":"1.00","side":"yes","ts":"2026-07-01T02:32:07.365522Z","ts_ms":1782873127365}}

{"type":"orderbook_delta","sid":1,"seq":221,"msg":{"market_ticker":"KXNEXTTEAMNBA-26LJAM-MIA","market_id":"492cb255-91da-4c91-bc9e-f83d090cc6dd","price_dollars":"0.8300","delta_fp":"-1.66","side":"no","ts":"2026-07-01T02:32:07.468966Z","ts_ms":1782873127468}}

{"type":"orderbook_delta","sid":1,"seq":222,"msg":{"market_ticker":"KXNEXTTEAMNBA-26LJAM-CLE","market_id":"7552b8d4-05de-4e41-84a8-97b0684da4a9","price_dollars":"0.7400","delta_fp":"-0.59","side":"no","ts":"2026-07-01T02:32:07.497538Z","ts_ms":1782873127497}}

{"type":"orderbook_delta","sid":1,"seq":223,"msg":{"market_ticker":"KXNEXTTEAMNBA-26LJAM-MIA","market_id":"492cb255-91da-4c91-bc9e-f83d090cc6dd","price_dollars":"0.8300","delta_fp":"-1.46","side":"no","ts":"2026-07-01T02:32:09.05937Z","ts_ms":1782873129059}}

{"type":"orderbook_delta","sid":1,"seq":224,"msg":{"market_ticker":"KXNEXTTEAMNBA-26LJAM-CLE","market_id":"7552b8d4-05de-4e41-84a8-97b0684da4a9","price_dollars":"0.7400","delta_fp":"-0.52","side":"no","ts":"2026-07-01T02:32:09.099058Z","ts_ms":1782873129099}}

{"type":"orderbook_delta","sid":1,"seq":225,"msg":{"market_ticker":"KXNEXTTEAMNBA-26LJAM-GSW","market_id":"abbbad28-f309-4dd5-af38-2ad7ebf2acc3","price_dollars":"0.5200","delta_fp":"-0.40","side":"no","ts":"2026-07-01T02:32:09.10165Z","ts_ms":1782873129101}}

{"type":"orderbook_delta","sid":1,"seq":226,"msg":{"market_ticker":"KXNEXTTEAMNBA-26LJAM-CLE","market_id":"7552b8d4-05de-4e41-84a8-97b0684da4a9","price_dollars":"0.7400","delta_fp":"-1.23","side":"no","ts":"2026-07-01T02:32:10.648372Z","ts_ms":1782873130648}}

{"type":"orderbook_delta","sid":1,"seq":227,"msg":{"market_ticker":"KXNEXTTEAMNBA-26LJAM-GSW","market_id":"abbbad28-f309-4dd5-af38-2ad7ebf2acc3","price_dollars":"0.5200","delta_fp":"-0.19","side":"no","ts":"2026-07-01T02:32:10.6536Z","ts_ms":1782873130653}}

{"type":"orderbook_delta","sid":1,"seq":228,"msg":{"market_ticker":"KXNEXTTEAMNBA-26LJAM-GSW","market_id":"abbbad28-f309-4dd5-af38-2ad7ebf2acc3","price_dollars":"0.0100","delta_fp":"1.00","side":"yes","ts":"2026-07-01T02:32:12.863642Z","ts_ms":1782873132863}}

{"type":"orderbook_delta","sid":1,"seq":229,"msg":{"market_ticker":"KXNEXTTEAMNBA-26LJAM-GSW","market_id":"abbbad28-f309-4dd5-af38-2ad7ebf2acc3","price_dollars":"0.0100","delta_fp":"1.00","side":"yes","ts":"2026-07-01T02:32:12.86484Z","ts_ms":1782873132864}}

{"type":"orderbook_delta","sid":1,"seq":230,"msg":{"market_ticker":"KXNEXTTEAMNBA-26LJAM-GSW","market_id":"abbbad28-f309-4dd5-af38-2ad7ebf2acc3","price_dollars":"0.0100","delta_fp":"1.00","side":"yes","ts":"2026-07-01T02:32:12.865918Z","ts_ms":1782873132865}}

{"type":"orderbook_delta","sid":1,"seq":231,"msg":{"market_ticker":"KXNEXTTEAMNBA-26LJAM-GSW","market_id":"abbbad28-f309-4dd5-af38-2ad7ebf2acc3","price_dollars":"0.0100","delta_fp":"1.00","side":"yes","ts":"2026-07-01T02:32:12.866793Z","ts_ms":1782873132866}}

{"type":"orderbook_delta","sid":1,"seq":232,"msg":{"market_ticker":"KXNEXTTEAMNBA-26LJAM-GSW","market_id":"abbbad28-f309-4dd5-af38-2ad7ebf2acc3","price_dollars":"0.0100","delta_fp":"1.00","side":"yes","ts":"2026-07-01T02:32:12.86782Z","ts_ms":1782873132867}}

{"type":"orderbook_delta","sid":1,"seq":233,"msg":{"market_ticker":"KXNEXTTEAMNBA-26LJAM-GSW","market_id":"abbbad28-f309-4dd5-af38-2ad7ebf2acc3","price_dollars":"0.0100","delta_fp":"1.00","side":"yes","ts":"2026-07-01T02:32:12.86904Z","ts_ms":1782873132869}}

{"type":"orderbook_delta","sid":1,"seq":234,"msg":{"market_ticker":"KXNEXTTEAMNBA-26LJAM-GSW","market_id":"abbbad28-f309-4dd5-af38-2ad7ebf2acc3","price_dollars":"0.0100","delta_fp":"1.00","side":"yes","ts":"2026-07-01T02:32:12.869777Z","ts_ms":1782873132869}}

{"type":"orderbook_delta","sid":1,"seq":235,"msg":{"market_ticker":"KXNEXTTEAMNBA-26LJAM-GSW","market_id":"abbbad28-f309-4dd5-af38-2ad7ebf2acc3","price_dollars":"0.0100","delta_fp":"1.00","side":"yes","ts":"2026-07-01T02:32:12.870887Z","ts_ms":1782873132870}}

{"type":"orderbook_delta","sid":1,"seq":236,"msg":{"market_ticker":"KXNEXTTEAMNBA-26LJAM-GSW","market_id":"abbbad28-f309-4dd5-af38-2ad7ebf2acc3","price_dollars":"0.0100","delta_fp":"1.00","side":"yes","ts":"2026-07-01T02:32:12.87164Z","ts_ms":1782873132871}}

{"type":"orderbook_delta","sid":1,"seq":237,"msg":{"market_ticker":"KXNEXTTEAMNBA-26LJAM-GSW","market_id":"abbbad28-f309-4dd5-af38-2ad7ebf2acc3","price_dollars":"0.0100","delta_fp":"1.00","side":"yes","ts":"2026-07-01T02:32:12.87228Z","ts_ms":1782873132872}}

{"type":"orderbook_delta","sid":1,"seq":238,"msg":{"market_ticker":"KXNEXTTEAMNBA-26LJAM-GSW","market_id":"abbbad28-f309-4dd5-af38-2ad7ebf2acc3","price_dollars":"0.0100","delta_fp":"1.00","side":"yes","ts":"2026-07-01T02:32:12.873199Z","ts_ms":1782873132873}}

{"type":"orderbook_delta","sid":1,"seq":239,"msg":{"market_ticker":"KXNEXTTEAMNBA-26LJAM-GSW","market_id":"abbbad28-f309-4dd5-af38-2ad7ebf2acc3","price_dollars":"0.0100","delta_fp":"1.00","side":"yes","ts":"2026-07-01T02:32:12.873976Z","ts_ms":1782873132873}}

{"type":"orderbook_delta","sid":1,"seq":240,"msg":{"market_ticker":"KXNEXTTEAMNBA-26LJAM-GSW","market_id":"abbbad28-f309-4dd5-af38-2ad7ebf2acc3","price_dollars":"0.0100","delta_fp":"1.00","side":"yes","ts":"2026-07-01T02:32:12.874612Z","ts_ms":1782873132874}}

{"type":"orderbook_delta","sid":1,"seq":241,"msg":{"market_ticker":"KXNEXTTEAMNBA-26LJAM-GSW","market_id":"abbbad28-f309-4dd5-af38-2ad7ebf2acc3","price_dollars":"0.0100","delta_fp":"1.00","side":"yes","ts":"2026-07-01T02:32:12.875181Z","ts_ms":1782873132875}}

{"type":"orderbook_delta","sid":1,"seq":242,"msg":{"market_ticker":"KXNEXTTEAMNBA-26LJAM-GSW","market_id":"abbbad28-f309-4dd5-af38-2ad7ebf2acc3","price_dollars":"0.0100","delta_fp":"1.00","side":"yes","ts":"2026-07-01T02:32:12.875695Z","ts_ms":1782873132875}}

{"type":"orderbook_delta","sid":1,"seq":243,"msg":{"market_ticker":"KXNEXTTEAMNBA-26LJAM-GSW","market_id":"abbbad28-f309-4dd5-af38-2ad7ebf2acc3","price_dollars":"0.0100","delta_fp":"1.00","side":"yes","ts":"2026-07-01T02:32:12.876154Z","ts_ms":1782873132876}}

{"type":"orderbook_delta","sid":1,"seq":244,"msg":{"market_ticker":"KXNEXTTEAMNBA-26LJAM-GSW","market_id":"abbbad28-f309-4dd5-af38-2ad7ebf2acc3","price_dollars":"0.0100","delta_fp":"1.00","side":"yes","ts":"2026-07-01T02:32:12.876761Z","ts_ms":1782873132876}}

{"type":"orderbook_delta","sid":1,"seq":245,"msg":{"market_ticker":"KXNEXTTEAMNBA-26LJAM-GSW","market_id":"abbbad28-f309-4dd5-af38-2ad7ebf2acc3","price_dollars":"0.0100","delta_fp":"1.00","side":"yes","ts":"2026-07-01T02:32:12.877167Z","ts_ms":1782873132877}}

{"type":"orderbook_delta","sid":1,"seq":246,"msg":{"market_ticker":"KXNEXTTEAMNBA-26LJAM-GSW","market_id":"abbbad28-f309-4dd5-af38-2ad7ebf2acc3","price_dollars":"0.0100","delta_fp":"1.00","side":"yes","ts":"2026-07-01T02:32:12.877589Z","ts_ms":1782873132877}}

{"type":"orderbook_delta","sid":1,"seq":247,"msg":{"market_ticker":"KXNEXTTEAMNBA-26LJAM-GSW","market_id":"abbbad28-f309-4dd5-af38-2ad7ebf2acc3","price_dollars":"0.0100","delta_fp":"1.00","side":"yes","ts":"2026-07-01T02:32:12.878025Z","ts_ms":1782873132878}}

{"type":"orderbook_delta","sid":1,"seq":248,"msg":{"market_ticker":"KXNEXTTEAMNBA-26LJAM-MIA","market_id":"492cb255-91da-4c91-bc9e-f83d090cc6dd","price_dollars":"0.8300","delta_fp":"-0.16","side":"no","ts":"2026-07-01T02:32:13.870736Z","ts_ms":1782873133870}}

{"type":"orderbook_delta","sid":1,"seq":249,"msg":{"market_ticker":"KXNEXTTEAMNBA-26LJAM-MIA","market_id":"492cb255-91da-4c91-bc9e-f83d090cc6dd","price_dollars":"0.1600","delta_fp":"2083.33","side":"yes","ts":"2026-07-01T02:32:15.747294Z","ts_ms":1782873135747}}

{"type":"orderbook_delta","sid":1,"seq":250,"msg":{"market_ticker":"KXNEXTTEAMNBA-26LJAM-MIA","market_id":"492cb255-91da-4c91-bc9e-f83d090cc6dd","price_dollars":"0.1500","delta_fp":"2222.22","side":"yes","ts":"2026-07-01T02:32:15.747643Z","ts_ms":1782873135747}}

{"type":"orderbook_delta","sid":1,"seq":251,"msg":{"market_ticker":"KXNEXTTEAMNBA-26LJAM-MIA","market_id":"492cb255-91da-4c91-bc9e-f83d090cc6dd","price_dollars":"0.1400","delta_fp":"2380.95","side":"yes","ts":"2026-07-01T02:32:15.748007Z","ts_ms":1782873135748}}

{"type":"orderbook_delta","sid":1,"seq":252,"msg":{"market_ticker":"KXNEXTTEAMNBA-26LJAM-MIA","market_id":"492cb255-91da-4c91-bc9e-f83d090cc6dd","price_dollars":"0.8300","delta_fp":"1960.78","side":"no","ts":"2026-07-01T02:32:15.748348Z","ts_ms":1782873135748}}

{"type":"orderbook_delta","sid":1,"seq":253,"msg":{"market_ticker":"KXNEXTTEAMNBA-26LJAM-MIA","market_id":"492cb255-91da-4c91-bc9e-f83d090cc6dd","price_dollars":"0.8200","delta_fp":"1851.85","side":"no","ts":"2026-07-01T02:32:15.748821Z","ts_ms":1782873135748}}

{"type":"orderbook_delta","sid":1,"seq":254,"msg":{"market_ticker":"KXNEXTTEAMNBA-26LJAM-MIA","market_id":"492cb255-91da-4c91-bc9e-f83d090cc6dd","price_dollars":"0.8100","delta_fp":"1754.38","side":"no","ts":"2026-07-01T02:32:15.749082Z","ts_ms":1782873135749}}

{"type":"orderbook_delta","sid":1,"seq":255,"msg":{"market_ticker":"KXNEXTTEAMNBA-26LJAM-GSW","market_id":"abbbad28-f309-4dd5-af38-2ad7ebf2acc3","price_dollars":"0.5200","delta_fp":"-0.38","side":"no","ts":"2026-07-01T02:32:18.565427Z","ts_ms":1782873138565}}

{"type":"orderbook_delta","sid":1,"seq":256,"msg":{"market_ticker":"KXNEXTTEAMNBA-26LJAM-GSW","market_id":"abbbad28-f309-4dd5-af38-2ad7ebf2acc3","price_dollars":"0.0100","delta_fp":"1.00","side":"yes","ts":"2026-07-01T02:32:18.962632Z","ts_ms":1782873138962}}

{"type":"orderbook_delta","sid":1,"seq":257,"msg":{"market_ticker":"KXNEXTTEAMNBA-26LJAM-GSW","market_id":"abbbad28-f309-4dd5-af38-2ad7ebf2acc3","price_dollars":"0.0100","delta_fp":"1.00","side":"yes","ts":"2026-07-01T02:32:18.963287Z","ts_ms":1782873138963}}

{"type":"orderbook_delta","sid":1,"seq":258,"msg":{"market_ticker":"KXNEXTTEAMNBA-26LJAM-GSW","market_id":"abbbad28-f309-4dd5-af38-2ad7ebf2acc3","price_dollars":"0.0100","delta_fp":"1.00","side":"yes","ts":"2026-07-01T02:32:18.966291Z","ts_ms":1782873138966}}

{"type":"orderbook_delta","sid":1,"seq":259,"msg":{"market_ticker":"KXNEXTTEAMNBA-26LJAM-GSW","market_id":"abbbad28-f309-4dd5-af38-2ad7ebf2acc3","price_dollars":"0.0100","delta_fp":"1.00","side":"yes","ts":"2026-07-01T02:32:18.966874Z","ts_ms":1782873138966}}

{"type":"orderbook_delta","sid":1,"seq":260,"msg":{"market_ticker":"KXNEXTTEAMNBA-26LJAM-GSW","market_id":"abbbad28-f309-4dd5-af38-2ad7ebf2acc3","price_dollars":"0.0100","delta_fp":"1.00","side":"yes","ts":"2026-07-01T02:32:18.967525Z","ts_ms":1782873138967}}

{"type":"orderbook_delta","sid":1,"seq":261,"msg":{"market_ticker":"KXNEXTTEAMNBA-26LJAM-GSW","market_id":"abbbad28-f309-4dd5-af38-2ad7ebf2acc3","price_dollars":"0.0100","delta_fp":"1.00","side":"yes","ts":"2026-07-01T02:32:18.968119Z","ts_ms":1782873138968}}

{"type":"orderbook_delta","sid":1,"seq":262,"msg":{"market_ticker":"KXNEXTTEAMNBA-26LJAM-GSW","market_id":"abbbad28-f309-4dd5-af38-2ad7ebf2acc3","price_dollars":"0.0100","delta_fp":"1.00","side":"yes","ts":"2026-07-01T02:32:18.969289Z","ts_ms":1782873138969}}

{"type":"orderbook_delta","sid":1,"seq":263,"msg":{"market_ticker":"KXNEXTTEAMNBA-26LJAM-GSW","market_id":"abbbad28-f309-4dd5-af38-2ad7ebf2acc3","price_dollars":"0.0100","delta_fp":"1.00","side":"yes","ts":"2026-07-01T02:32:18.969936Z","ts_ms":1782873138969}}

{"type":"orderbook_delta","sid":1,"seq":264,"msg":{"market_ticker":"KXNEXTTEAMNBA-26LJAM-GSW","market_id":"abbbad28-f309-4dd5-af38-2ad7ebf2acc3","price_dollars":"0.0100","delta_fp":"1.00","side":"yes","ts":"2026-07-01T02:32:18.970577Z","ts_ms":1782873138970}}

{"type":"orderbook_delta","sid":1,"seq":265,"msg":{"market_ticker":"KXNEXTTEAMNBA-26LJAM-GSW","market_id":"abbbad28-f309-4dd5-af38-2ad7ebf2acc3","price_dollars":"0.0100","delta_fp":"1.00","side":"yes","ts":"2026-07-01T02:32:18.971123Z","ts_ms":1782873138971}}

{"type":"orderbook_delta","sid":1,"seq":266,"msg":{"market_ticker":"KXNEXTTEAMNBA-26LJAM-GSW","market_id":"abbbad28-f309-4dd5-af38-2ad7ebf2acc3","price_dollars":"0.0100","delta_fp":"1.00","side":"yes","ts":"2026-07-01T02:32:18.971514Z","ts_ms":1782873138971}}

{"type":"orderbook_delta","sid":1,"seq":267,"msg":{"market_ticker":"KXNEXTTEAMNBA-26LJAM-GSW","market_id":"abbbad28-f309-4dd5-af38-2ad7ebf2acc3","price_dollars":"0.0100","delta_fp":"1.00","side":"yes","ts":"2026-07-01T02:32:18.971989Z","ts_ms":1782873138971}}

{"type":"orderbook_delta","sid":1,"seq":268,"msg":{"market_ticker":"KXNEXTTEAMNBA-26LJAM-GSW","market_id":"abbbad28-f309-4dd5-af38-2ad7ebf2acc3","price_dollars":"0.0100","delta_fp":"1.00","side":"yes","ts":"2026-07-01T02:32:18.972561Z","ts_ms":1782873138972}}

{"type":"orderbook_delta","sid":1,"seq":269,"msg":{"market_ticker":"KXNEXTTEAMNBA-26LJAM-GSW","market_id":"abbbad28-f309-4dd5-af38-2ad7ebf2acc3","price_dollars":"0.0100","delta_fp":"1.00","side":"yes","ts":"2026-07-01T02:32:18.973046Z","ts_ms":1782873138973}}

{"type":"orderbook_delta","sid":1,"seq":270,"msg":{"market_ticker":"KXNEXTTEAMNBA-26LJAM-GSW","market_id":"abbbad28-f309-4dd5-af38-2ad7ebf2acc3","price_dollars":"0.0100","delta_fp":"1.00","side":"yes","ts":"2026-07-01T02:32:18.973533Z","ts_ms":1782873138973}}

{"type":"orderbook_delta","sid":1,"seq":271,"msg":{"market_ticker":"KXNEXTTEAMNBA-26LJAM-GSW","market_id":"abbbad28-f309-4dd5-af38-2ad7ebf2acc3","price_dollars":"0.0100","delta_fp":"1.00","side":"yes","ts":"2026-07-01T02:32:18.973973Z","ts_ms":1782873138973}}

{"type":"orderbook_delta","sid":1,"seq":272,"msg":{"market_ticker":"KXNEXTTEAMNBA-26LJAM-GSW","market_id":"abbbad28-f309-4dd5-af38-2ad7ebf2acc3","price_dollars":"0.0100","delta_fp":"1.00","side":"yes","ts":"2026-07-01T02:32:18.974426Z","ts_ms":1782873138974}}

{"type":"orderbook_delta","sid":1,"seq":273,"msg":{"market_ticker":"KXNEXTTEAMNBA-26LJAM-GSW","market_id":"abbbad28-f309-4dd5-af38-2ad7ebf2acc3","price_dollars":"0.0100","delta_fp":"1.00","side":"yes","ts":"2026-07-01T02:32:18.974965Z","ts_ms":1782873138974}}

{"type":"orderbook_delta","sid":1,"seq":274,"msg":{"market_ticker":"KXNEXTTEAMNBA-26LJAM-GSW","market_id":"abbbad28-f309-4dd5-af38-2ad7ebf2acc3","price_dollars":"0.0100","delta_fp":"1.00","side":"yes","ts":"2026-07-01T02:32:18.975443Z","ts_ms":1782873138975}}

{"type":"orderbook_delta","sid":1,"seq":275,"msg":{"market_ticker":"KXNEXTTEAMNBA-26LJAM-GSW","market_id":"abbbad28-f309-4dd5-af38-2ad7ebf2acc3","price_dollars":"0.0100","delta_fp":"1.00","side":"yes","ts":"2026-07-01T02:32:18.975751Z","ts_ms":1782873138975}}

{"type":"orderbook_delta","sid":1,"seq":276,"msg":{"market_ticker":"KXNEXTTEAMNBA-26LJAM-GSW","market_id":"abbbad28-f309-4dd5-af38-2ad7ebf2acc3","price_dollars":"0.5200","delta_fp":"-0.06","side":"no","ts":"2026-07-01T02:32:19.374602Z","ts_ms":1782873139374}}

{"type":"orderbook_delta","sid":1,"seq":277,"msg":{"market_ticker":"KXNEXTTEAMNBA-26LJAM-MIA","market_id":"492cb255-91da-4c91-bc9e-f83d090cc6dd","price_dollars":"0.8300","delta_fp":"-0.61","side":"no","ts":"2026-07-01T02:32:19.388051Z","ts_ms":1782873139388}}

{"type":"orderbook_delta","sid":1,"seq":278,"msg":{"market_ticker":"KXNEXTTEAMNBA-26LJAM-GSW","market_id":"abbbad28-f309-4dd5-af38-2ad7ebf2acc3","price_dollars":"0.5200","delta_fp":"-0.57","side":"no","ts":"2026-07-01T02:32:20.173042Z","ts_ms":1782873140173}}

{"type":"orderbook_delta","sid":1,"seq":279,"msg":{"market_ticker":"KXNEXTTEAMNBA-26LJAM-GSW","market_id":"abbbad28-f309-4dd5-af38-2ad7ebf2acc3","price_dollars":"0.5200","delta_fp":"-0.35","side":"no","ts":"2026-07-01T02:32:20.18213Z","ts_ms":1782873140182}}

{"type":"orderbook_delta","sid":1,"seq":280,"msg":{"market_ticker":"KXNEXTTEAMNBA-26LJAM-MIA","market_id":"492cb255-91da-4c91-bc9e-f83d090cc6dd","price_dollars":"0.0100","delta_fp":"1.00","side":"yes","ts":"2026-07-01T02:32:20.541068Z","ts_ms":1782873140541}}

{"type":"orderbook_delta","sid":1,"seq":281,"msg":{"market_ticker":"KXNEXTTEAMNBA-26LJAM-MIA","market_id":"492cb255-91da-4c91-bc9e-f83d090cc6dd","price_dollars":"0.0100","delta_fp":"1.00","side":"yes","ts":"2026-07-01T02:32:20.541555Z","ts_ms":1782873140541}}

{"type":"orderbook_delta","sid":1,"seq":282,"msg":{"market_ticker":"KXNEXTTEAMNBA-26LJAM-MIA","market_id":"492cb255-91da-4c91-bc9e-f83d090cc6dd","price_dollars":"0.0100","delta_fp":"1.00","side":"yes","ts":"2026-07-01T02:32:20.542004Z","ts_ms":1782873140542}}

{"type":"orderbook_delta","sid":1,"seq":283,"msg":{"market_ticker":"KXNEXTTEAMNBA-26LJAM-MIA","market_id":"492cb255-91da-4c91-bc9e-f83d090cc6dd","price_dollars":"0.0100","delta_fp":"1.00","side":"yes","ts":"2026-07-01T02:32:20.542677Z","ts_ms":1782873140542}}

{"type":"orderbook_delta","sid":1,"seq":284,"msg":{"market_ticker":"KXNEXTTEAMNBA-26LJAM-MIA","market_id":"492cb255-91da-4c91-bc9e-f83d090cc6dd","price_dollars":"0.0100","delta_fp":"1.00","side":"yes","ts":"2026-07-01T02:32:20.543153Z","ts_ms":1782873140543}}

{"type":"orderbook_delta","sid":1,"seq":285,"msg":{"market_ticker":"KXNEXTTEAMNBA-26LJAM-MIA","market_id":"492cb255-91da-4c91-bc9e-f83d090cc6dd","price_dollars":"0.0100","delta_fp":"1.00","side":"yes","ts":"2026-07-01T02:32:20.54365Z","ts_ms":1782873140543}}

{"type":"orderbook_delta","sid":1,"seq":286,"msg":{"market_ticker":"KXNEXTTEAMNBA-26LJAM-MIA","market_id":"492cb255-91da-4c91-bc9e-f83d090cc6dd","price_dollars":"0.0100","delta_fp":"1.00","side":"yes","ts":"2026-07-01T02:32:20.544274Z","ts_ms":1782873140544}}

{"type":"orderbook_delta","sid":1,"seq":287,"msg":{"market_ticker":"KXNEXTTEAMNBA-26LJAM-MIA","market_id":"492cb255-91da-4c91-bc9e-f83d090cc6dd","price_dollars":"0.0100","delta_fp":"1.00","side":"yes","ts":"2026-07-01T02:32:20.544582Z","ts_ms":1782873140544}}

{"type":"orderbook_delta","sid":1,"seq":288,"msg":{"market_ticker":"KXNEXTTEAMNBA-26LJAM-MIA","market_id":"492cb255-91da-4c91-bc9e-f83d090cc6dd","price_dollars":"0.0100","delta_fp":"1.00","side":"yes","ts":"2026-07-01T02:32:20.545319Z","ts_ms":1782873140545}}

{"type":"orderbook_delta","sid":1,"seq":289,"msg":{"market_ticker":"KXNEXTTEAMNBA-26LJAM-MIA","market_id":"492cb255-91da-4c91-bc9e-f83d090cc6dd","price_dollars":"0.0100","delta_fp":"1.00","side":"yes","ts":"2026-07-01T02:32:20.545879Z","ts_ms":1782873140545}}

{"type":"orderbook_delta","sid":1,"seq":290,"msg":{"market_ticker":"KXNEXTTEAMNBA-26LJAM-MIA","market_id":"492cb255-91da-4c91-bc9e-f83d090cc6dd","price_dollars":"0.0100","delta_fp":"1.00","side":"yes","ts":"2026-07-01T02:32:20.546367Z","ts_ms":1782873140546}}

{"type":"orderbook_delta","sid":1,"seq":291,"msg":{"market_ticker":"KXNEXTTEAMNBA-26LJAM-MIA","market_id":"492cb255-91da-4c91-bc9e-f83d090cc6dd","price_dollars":"0.0100","delta_fp":"1.00","side":"yes","ts":"2026-07-01T02:32:20.54686Z","ts_ms":1782873140546}}

{"type":"orderbook_delta","sid":1,"seq":292,"msg":{"market_ticker":"KXNEXTTEAMNBA-26LJAM-MIA","market_id":"492cb255-91da-4c91-bc9e-f83d090cc6dd","price_dollars":"0.0100","delta_fp":"1.00","side":"yes","ts":"2026-07-01T02:32:20.547465Z","ts_ms":1782873140547}}

{"type":"orderbook_delta","sid":1,"seq":293,"msg":{"market_ticker":"KXNEXTTEAMNBA-26LJAM-MIA","market_id":"492cb255-91da-4c91-bc9e-f83d090cc6dd","price_dollars":"0.0100","delta_fp":"1.00","side":"yes","ts":"2026-07-01T02:32:20.547891Z","ts_ms":1782873140547}}

{"type":"orderbook_delta","sid":1,"seq":294,"msg":{"market_ticker":"KXNEXTTEAMNBA-26LJAM-MIA","market_id":"492cb255-91da-4c91-bc9e-f83d090cc6dd","price_dollars":"0.0100","delta_fp":"1.00","side":"yes","ts":"2026-07-01T02:32:20.548445Z","ts_ms":1782873140548}}

{"type":"orderbook_delta","sid":1,"seq":295,"msg":{"market_ticker":"KXNEXTTEAMNBA-26LJAM-MIA","market_id":"492cb255-91da-4c91-bc9e-f83d090cc6dd","price_dollars":"0.0100","delta_fp":"1.00","side":"yes","ts":"2026-07-01T02:32:20.548717Z","ts_ms":1782873140548}}

{"type":"orderbook_delta","sid":1,"seq":296,"msg":{"market_ticker":"KXNEXTTEAMNBA-26LJAM-MIA","market_id":"492cb255-91da-4c91-bc9e-f83d090cc6dd","price_dollars":"0.0100","delta_fp":"1.00","side":"yes","ts":"2026-07-01T02:32:20.549081Z","ts_ms":1782873140549}}

{"type":"orderbook_delta","sid":1,"seq":297,"msg":{"market_ticker":"KXNEXTTEAMNBA-26LJAM-MIA","market_id":"492cb255-91da-4c91-bc9e-f83d090cc6dd","price_dollars":"0.0100","delta_fp":"1.00","side":"yes","ts":"2026-07-01T02:32:20.549504Z","ts_ms":1782873140549}}

{"type":"orderbook_delta","sid":1,"seq":298,"msg":{"market_ticker":"KXNEXTTEAMNBA-26LJAM-MIA","market_id":"492cb255-91da-4c91-bc9e-f83d090cc6dd","price_dollars":"0.0100","delta_fp":"1.00","side":"yes","ts":"2026-07-01T02:32:20.549926Z","ts_ms":1782873140549}}

{"type":"orderbook_delta","sid":1,"seq":299,"msg":{"market_ticker":"KXNEXTTEAMNBA-26LJAM-MIA","market_id":"492cb255-91da-4c91-bc9e-f83d090cc6dd","price_dollars":"0.0100","delta_fp":"1.00","side":"yes","ts":"2026-07-01T02:32:20.550311Z","ts_ms":1782873140550}}

{"type":"orderbook_delta","sid":1,"seq":300,"msg":{"market_ticker":"KXNEXTTEAMNBA-26LJAM-MIA","market_id":"492cb255-91da-4c91-bc9e-f83d090cc6dd","price_dollars":"0.8300","delta_fp":"-0.35","side":"no","ts":"2026-07-01T02:32:20.983403Z","ts_ms":1782873140983}}

{"type":"orderbook_delta","sid":1,"seq":301,"msg":{"market_ticker":"KXNEXTTEAMNBA-26LJAM-MIA","market_id":"492cb255-91da-4c91-bc9e-f83d090cc6dd","price_dollars":"0.8300","delta_fp":"-0.39","side":"no","ts":"2026-07-01T02:32:22.560347Z","ts_ms":1782873142560}}

{"type":"orderbook_delta","sid":1,"seq":302,"msg":{"market_ticker":"KXNEXTTEAMNBA-26LJAM-MIA","market_id":"492cb255-91da-4c91-bc9e-f83d090cc6dd","price_dollars":"0.8300","delta_fp":"-1.53","side":"no","ts":"2026-07-01T02:32:22.561103Z","ts_ms":1782873142561}}

{"type":"orderbook_delta","sid":1,"seq":303,"msg":{"market_ticker":"KXNEXTTEAMNBA-26LJAM-GSW","market_id":"abbbad28-f309-4dd5-af38-2ad7ebf2acc3","price_dollars":"0.5200","delta_fp":"-0.01","side":"no","ts":"2026-07-01T02:32:22.567249Z","ts_ms":1782873142567}}

{"type":"orderbook_delta","sid":1,"seq":304,"msg":{"market_ticker":"KXNEXTTEAMNBA-26LJAM-GSW","market_id":"abbbad28-f309-4dd5-af38-2ad7ebf2acc3","price_dollars":"0.5200","delta_fp":"-1.21","side":"no","ts":"2026-07-01T02:32:24.036136Z","ts_ms":1782873144036}}

{"type":"orderbook_delta","sid":1,"seq":305,"msg":{"market_ticker":"KXNEXTTEAMNBA-26LJAM-MIA","market_id":"492cb255-91da-4c91-bc9e-f83d090cc6dd","price_dollars":"0.8300","delta_fp":"-1.92","side":"no","ts":"2026-07-01T02:32:24.979256Z","ts_ms":1782873144979}}

{"type":"orderbook_delta","sid":1,"seq":306,"msg":{"market_ticker":"KXNEXTTEAMNBA-26LJAM-GSW","market_id":"abbbad28-f309-4dd5-af38-2ad7ebf2acc3","price_dollars":"0.0100","delta_fp":"1.00","side":"yes","ts":"2026-07-01T02:32:25.538003Z","ts_ms":1782873145538}}

{"type":"orderbook_delta","sid":1,"seq":307,"msg":{"market_ticker":"KXNEXTTEAMNBA-26LJAM-GSW","market_id":"abbbad28-f309-4dd5-af38-2ad7ebf2acc3","price_dollars":"0.0100","delta_fp":"1.00","side":"yes","ts":"2026-07-01T02:32:25.539071Z","ts_ms":1782873145539}}

{"type":"orderbook_delta","sid":1,"seq":308,"msg":{"market_ticker":"KXNEXTTEAMNBA-26LJAM-GSW","market_id":"abbbad28-f309-4dd5-af38-2ad7ebf2acc3","price_dollars":"0.0100","delta_fp":"1.00","side":"yes","ts":"2026-07-01T02:32:25.539796Z","ts_ms":1782873145539}}

{"type":"orderbook_delta","sid":1,"seq":309,"msg":{"market_ticker":"KXNEXTTEAMNBA-26LJAM-GSW","market_id":"abbbad28-f309-4dd5-af38-2ad7ebf2acc3","price_dollars":"0.0100","delta_fp":"1.00","side":"yes","ts":"2026-07-01T02:32:25.540686Z","ts_ms":1782873145540}}

{"type":"orderbook_delta","sid":1,"seq":310,"msg":{"market_ticker":"KXNEXTTEAMNBA-26LJAM-GSW","market_id":"abbbad28-f309-4dd5-af38-2ad7ebf2acc3","price_dollars":"0.0100","delta_fp":"1.00","side":"yes","ts":"2026-07-01T02:32:25.541519Z","ts_ms":1782873145541}}

{"type":"orderbook_delta","sid":1,"seq":311,"msg":{"market_ticker":"KXNEXTTEAMNBA-26LJAM-GSW","market_id":"abbbad28-f309-4dd5-af38-2ad7ebf2acc3","price_dollars":"0.0100","delta_fp":"1.00","side":"yes","ts":"2026-07-01T02:32:25.542313Z","ts_ms":1782873145542}}

{"type":"orderbook_delta","sid":1,"seq":312,"msg":{"market_ticker":"KXNEXTTEAMNBA-26LJAM-GSW","market_id":"abbbad28-f309-4dd5-af38-2ad7ebf2acc3","price_dollars":"0.0100","delta_fp":"1.00","side":"yes","ts":"2026-07-01T02:32:25.54295Z","ts_ms":1782873145542}}

{"type":"orderbook_delta","sid":1,"seq":313,"msg":{"market_ticker":"KXNEXTTEAMNBA-26LJAM-GSW","market_id":"abbbad28-f309-4dd5-af38-2ad7ebf2acc3","price_dollars":"0.0100","delta_fp":"1.00","side":"yes","ts":"2026-07-01T02:32:25.543624Z","ts_ms":1782873145543}}

{"type":"orderbook_delta","sid":1,"seq":314,"msg":{"market_ticker":"KXNEXTTEAMNBA-26LJAM-GSW","market_id":"abbbad28-f309-4dd5-af38-2ad7ebf2acc3","price_dollars":"0.0100","delta_fp":"1.00","side":"yes","ts":"2026-07-01T02:32:25.544302Z","ts_ms":1782873145544}}

{"type":"orderbook_delta","sid":1,"seq":315,"msg":{"market_ticker":"KXNEXTTEAMNBA-26LJAM-GSW","market_id":"abbbad28-f309-4dd5-af38-2ad7ebf2acc3","price_dollars":"0.0100","delta_fp":"1.00","side":"yes","ts":"2026-07-01T02:32:25.544893Z","ts_ms":1782873145544}}

{"type":"orderbook_delta","sid":1,"seq":316,"msg":{"market_ticker":"KXNEXTTEAMNBA-26LJAM-GSW","market_id":"abbbad28-f309-4dd5-af38-2ad7ebf2acc3","price_dollars":"0.0100","delta_fp":"1.00","side":"yes","ts":"2026-07-01T02:32:25.545593Z","ts_ms":1782873145545}}

{"type":"orderbook_delta","sid":1,"seq":317,"msg":{"market_ticker":"KXNEXTTEAMNBA-26LJAM-GSW","market_id":"abbbad28-f309-4dd5-af38-2ad7ebf2acc3","price_dollars":"0.0100","delta_fp":"1.00","side":"yes","ts":"2026-07-01T02:32:25.546208Z","ts_ms":1782873145546}}

{"type":"orderbook_delta","sid":1,"seq":318,"msg":{"market_ticker":"KXNEXTTEAMNBA-26LJAM-GSW","market_id":"abbbad28-f309-4dd5-af38-2ad7ebf2acc3","price_dollars":"0.0100","delta_fp":"1.00","side":"yes","ts":"2026-07-01T02:32:25.5467Z","ts_ms":1782873145546}}

{"type":"orderbook_delta","sid":1,"seq":319,"msg":{"market_ticker":"KXNEXTTEAMNBA-26LJAM-GSW","market_id":"abbbad28-f309-4dd5-af38-2ad7ebf2acc3","price_dollars":"0.0100","delta_fp":"1.00","side":"yes","ts":"2026-07-01T02:32:25.547166Z","ts_ms":1782873145547}}

{"type":"orderbook_delta","sid":1,"seq":320,"msg":{"market_ticker":"KXNEXTTEAMNBA-26LJAM-GSW","market_id":"abbbad28-f309-4dd5-af38-2ad7ebf2acc3","price_dollars":"0.0100","delta_fp":"1.00","side":"yes","ts":"2026-07-01T02:32:25.547721Z","ts_ms":1782873145547}}

{"type":"orderbook_delta","sid":1,"seq":321,"msg":{"market_ticker":"KXNEXTTEAMNBA-26LJAM-GSW","market_id":"abbbad28-f309-4dd5-af38-2ad7ebf2acc3","price_dollars":"0.0100","delta_fp":"1.00","side":"yes","ts":"2026-07-01T02:32:25.548144Z","ts_ms":1782873145548}}

{"type":"orderbook_delta","sid":1,"seq":322,"msg":{"market_ticker":"KXNEXTTEAMNBA-26LJAM-GSW","market_id":"abbbad28-f309-4dd5-af38-2ad7ebf2acc3","price_dollars":"0.0100","delta_fp":"1.00","side":"yes","ts":"2026-07-01T02:32:25.548465Z","ts_ms":1782873145548}}

{"type":"orderbook_delta","sid":1,"seq":323,"msg":{"market_ticker":"KXNEXTTEAMNBA-26LJAM-GSW","market_id":"abbbad28-f309-4dd5-af38-2ad7ebf2acc3","price_dollars":"0.0100","delta_fp":"1.00","side":"yes","ts":"2026-07-01T02:32:25.548969Z","ts_ms":1782873145548}}

{"type":"orderbook_delta","sid":1,"seq":324,"msg":{"market_ticker":"KXNEXTTEAMNBA-26LJAM-GSW","market_id":"abbbad28-f309-4dd5-af38-2ad7ebf2acc3","price_dollars":"0.0100","delta_fp":"1.00","side":"yes","ts":"2026-07-01T02:32:25.549495Z","ts_ms":1782873145549}}

{"type":"orderbook_delta","sid":1,"seq":325,"msg":{"market_ticker":"KXNEXTTEAMNBA-26LJAM-GSW","market_id":"abbbad28-f309-4dd5-af38-2ad7ebf2acc3","price_dollars":"0.0100","delta_fp":"1.00","side":"yes","ts":"2026-07-01T02:32:25.550111Z","ts_ms":1782873145550}}

{"type":"orderbook_delta","sid":1,"seq":326,"msg":{"market_ticker":"KXNEXTTEAMNBA-26LJAM-MIA","market_id":"492cb255-91da-4c91-bc9e-f83d090cc6dd","price_dollars":"0.0100","delta_fp":"1.00","side":"yes","ts":"2026-07-01T02:32:26.537313Z","ts_ms":1782873146537}}

{"type":"orderbook_delta","sid":1,"seq":327,"msg":{"market_ticker":"KXNEXTTEAMNBA-26LJAM-MIA","market_id":"492cb255-91da-4c91-bc9e-f83d090cc6dd","price_dollars":"0.0100","delta_fp":"1.00","side":"yes","ts":"2026-07-01T02:32:26.537771Z","ts_ms":1782873146537}}

{"type":"orderbook_delta","sid":1,"seq":328,"msg":{"market_ticker":"KXNEXTTEAMNBA-26LJAM-MIA","market_id":"492cb255-91da-4c91-bc9e-f83d090cc6dd","price_dollars":"0.0100","delta_fp":"1.00","side":"yes","ts":"2026-07-01T02:32:26.538351Z","ts_ms":1782873146538}}

{"type":"orderbook_delta","sid":1,"seq":329,"msg":{"market_ticker":"KXNEXTTEAMNBA-26LJAM-MIA","market_id":"492cb255-91da-4c91-bc9e-f83d090cc6dd","price_dollars":"0.0100","delta_fp":"1.00","side":"yes","ts":"2026-07-01T02:32:26.538784Z","ts_ms":1782873146538}}

{"type":"orderbook_delta","sid":1,"seq":330,"msg":{"market_ticker":"KXNEXTTEAMNBA-26LJAM-MIA","market_id":"492cb255-91da-4c91-bc9e-f83d090cc6dd","price_dollars":"0.0100","delta_fp":"1.00","side":"yes","ts":"2026-07-01T02:32:26.53964Z","ts_ms":1782873146539}}

{"type":"orderbook_delta","sid":1,"seq":331,"msg":{"market_ticker":"KXNEXTTEAMNBA-26LJAM-MIA","market_id":"492cb255-91da-4c91-bc9e-f83d090cc6dd","price_dollars":"0.0100","delta_fp":"1.00","side":"yes","ts":"2026-07-01T02:32:26.540373Z","ts_ms":1782873146540}}

{"type":"orderbook_delta","sid":1,"seq":332,"msg":{"market_ticker":"KXNEXTTEAMNBA-26LJAM-MIA","market_id":"492cb255-91da-4c91-bc9e-f83d090cc6dd","price_dollars":"0.0100","delta_fp":"1.00","side":"yes","ts":"2026-07-01T02:32:26.540903Z","ts_ms":1782873146540}}

{"type":"orderbook_delta","sid":1,"seq":333,"msg":{"market_ticker":"KXNEXTTEAMNBA-26LJAM-MIA","market_id":"492cb255-91da-4c91-bc9e-f83d090cc6dd","price_dollars":"0.0100","delta_fp":"1.00","side":"yes","ts":"2026-07-01T02:32:26.541423Z","ts_ms":1782873146541}}

{"type":"orderbook_delta","sid":1,"seq":334,"msg":{"market_ticker":"KXNEXTTEAMNBA-26LJAM-MIA","market_id":"492cb255-91da-4c91-bc9e-f83d090cc6dd","price_dollars":"0.0100","delta_fp":"1.00","side":"yes","ts":"2026-07-01T02:32:26.546157Z","ts_ms":1782873146546}}

{"type":"orderbook_delta","sid":1,"seq":335,"msg":{"market_ticker":"KXNEXTTEAMNBA-26LJAM-MIA","market_id":"492cb255-91da-4c91-bc9e-f83d090cc6dd","price_dollars":"0.0100","delta_fp":"1.00","side":"yes","ts":"2026-07-01T02:32:26.546896Z","ts_ms":1782873146546}}

{"type":"orderbook_delta","sid":1,"seq":336,"msg":{"market_ticker":"KXNEXTTEAMNBA-26LJAM-MIA","market_id":"492cb255-91da-4c91-bc9e-f83d090cc6dd","price_dollars":"0.0100","delta_fp":"1.00","side":"yes","ts":"2026-07-01T02:32:26.547351Z","ts_ms":1782873146547}}

{"type":"orderbook_delta","sid":1,"seq":337,"msg":{"market_ticker":"KXNEXTTEAMNBA-26LJAM-MIA","market_id":"492cb255-91da-4c91-bc9e-f83d090cc6dd","price_dollars":"0.0100","delta_fp":"1.00","side":"yes","ts":"2026-07-01T02:32:26.54778Z","ts_ms":1782873146547}}

{"type":"orderbook_delta","sid":1,"seq":338,"msg":{"market_ticker":"KXNEXTTEAMNBA-26LJAM-MIA","market_id":"492cb255-91da-4c91-bc9e-f83d090cc6dd","price_dollars":"0.0100","delta_fp":"1.00","side":"yes","ts":"2026-07-01T02:32:26.548248Z","ts_ms":1782873146548}}

{"type":"orderbook_delta","sid":1,"seq":339,"msg":{"market_ticker":"KXNEXTTEAMNBA-26LJAM-MIA","market_id":"492cb255-91da-4c91-bc9e-f83d090cc6dd","price_dollars":"0.0100","delta_fp":"1.00","side":"yes","ts":"2026-07-01T02:32:26.54886Z","ts_ms":1782873146548}}

{"type":"orderbook_delta","sid":1,"seq":340,"msg":{"market_ticker":"KXNEXTTEAMNBA-26LJAM-MIA","market_id":"492cb255-91da-4c91-bc9e-f83d090cc6dd","price_dollars":"0.0100","delta_fp":"1.00","side":"yes","ts":"2026-07-01T02:32:26.549346Z","ts_ms":1782873146549}}

{"type":"orderbook_delta","sid":1,"seq":341,"msg":{"market_ticker":"KXNEXTTEAMNBA-26LJAM-MIA","market_id":"492cb255-91da-4c91-bc9e-f83d090cc6dd","price_dollars":"0.0100","delta_fp":"1.00","side":"yes","ts":"2026-07-01T02:32:26.549811Z","ts_ms":1782873146549}}

{"type":"orderbook_delta","sid":1,"seq":342,"msg":{"market_ticker":"KXNEXTTEAMNBA-26LJAM-MIA","market_id":"492cb255-91da-4c91-bc9e-f83d090cc6dd","price_dollars":"0.0100","delta_fp":"1.00","side":"yes","ts":"2026-07-01T02:32:26.550191Z","ts_ms":1782873146550}}

{"type":"orderbook_delta","sid":1,"seq":343,"msg":{"market_ticker":"KXNEXTTEAMNBA-26LJAM-MIA","market_id":"492cb255-91da-4c91-bc9e-f83d090cc6dd","price_dollars":"0.0100","delta_fp":"1.00","side":"yes","ts":"2026-07-01T02:32:26.550703Z","ts_ms":1782873146550}}

{"type":"orderbook_delta","sid":1,"seq":344,"msg":{"market_ticker":"KXNEXTTEAMNBA-26LJAM-MIA","market_id":"492cb255-91da-4c91-bc9e-f83d090cc6dd","price_dollars":"0.0100","delta_fp":"1.00","side":"yes","ts":"2026-07-01T02:32:26.551248Z","ts_ms":1782873146551}}

{"type":"orderbook_delta","sid":1,"seq":345,"msg":{"market_ticker":"KXNEXTTEAMNBA-26LJAM-MIA","market_id":"492cb255-91da-4c91-bc9e-f83d090cc6dd","price_dollars":"0.0100","delta_fp":"1.00","side":"yes","ts":"2026-07-01T02:32:26.551709Z","ts_ms":1782873146551}}

{"type":"orderbook_delta","sid":1,"seq":346,"msg":{"market_ticker":"KXNEXTTEAMNBA-26LJAM-MIA","market_id":"492cb255-91da-4c91-bc9e-f83d090cc6dd","price_dollars":"0.8300","delta_fp":"-0.03","side":"no","ts":"2026-07-01T02:32:26.560133Z","ts_ms":1782873146560}}

{"type":"orderbook_delta","sid":1,"seq":347,"msg":{"market_ticker":"KXNEXTTEAMNBA-26LJAM-CLE","market_id":"7552b8d4-05de-4e41-84a8-97b0684da4a9","price_dollars":"0.7400","delta_fp":"-1.45","side":"no","ts":"2026-07-01T02:32:26.659804Z","ts_ms":1782873146659}}

{"type":"orderbook_delta","sid":1,"seq":348,"msg":{"market_ticker":"KXNEXTTEAMNBA-26LJAM-CLE","market_id":"7552b8d4-05de-4e41-84a8-97b0684da4a9","price_dollars":"0.7400","delta_fp":"-0.27","side":"no","ts":"2026-07-01T02:32:27.381101Z","ts_ms":1782873147381}}

{"type":"orderbook_delta","sid":1,"seq":349,"msg":{"market_ticker":"KXNEXTTEAMNBA-26LJAM-GSW","market_id":"abbbad28-f309-4dd5-af38-2ad7ebf2acc3","price_dollars":"0.5200","delta_fp":"-694.44","side":"no","ts":"2026-07-01T02:32:27.919247Z","ts_ms":1782873147919}}

{"type":"orderbook_delta","sid":1,"seq":350,"msg":{"market_ticker":"KXNEXTTEAMNBA-26LJAM-GSW","market_id":"abbbad28-f309-4dd5-af38-2ad7ebf2acc3","price_dollars":"0.5100","delta_fp":"-680.27","side":"no","ts":"2026-07-01T02:32:27.919247Z","ts_ms":1782873147919}}

{"type":"orderbook_delta","sid":1,"seq":351,"msg":{"market_ticker":"KXNEXTTEAMNBA-26LJAM-GSW","market_id":"abbbad28-f309-4dd5-af38-2ad7ebf2acc3","price_dollars":"0.5000","delta_fp":"-666.66","side":"no","ts":"2026-07-01T02:32:27.919247Z","ts_ms":1782873147919}}

{"type":"orderbook_delta","sid":1,"seq":352,"msg":{"market_ticker":"KXNEXTTEAMNBA-26LJAM-MIA","market_id":"492cb255-91da-4c91-bc9e-f83d090cc6dd","price_dollars":"0.8300","delta_fp":"-1.92","side":"no","ts":"2026-07-01T02:32:28.199026Z","ts_ms":1782873148199}}

{"type":"orderbook_delta","sid":1,"seq":353,"msg":{"market_ticker":"KXNEXTTEAMNBA-26LJAM-MIA","market_id":"492cb255-91da-4c91-bc9e-f83d090cc6dd","price_dollars":"0.8300","delta_fp":"-0.71","side":"no","ts":"2026-07-01T02:32:28.972484Z","ts_ms":1782873148972}}

{"type":"orderbook_delta","sid":1,"seq":354,"msg":{"market_ticker":"KXNEXTTEAMNBA-26LJAM-GSW","market_id":"abbbad28-f309-4dd5-af38-2ad7ebf2acc3","price_dollars":"0.5200","delta_fp":"-0.25","side":"no","ts":"2026-07-01T02:32:28.977268Z","ts_ms":1782873148977}}

{"type":"orderbook_delta","sid":1,"seq":355,"msg":{"market_ticker":"KXNEXTTEAMNBA-26LJAM-MIA","market_id":"492cb255-91da-4c91-bc9e-f83d090cc6dd","price_dollars":"0.8300","delta_fp":"-0.12","side":"no","ts":"2026-07-01T02:32:31.382871Z","ts_ms":1782873151382}}

{"type":"orderbook_delta","sid":1,"seq":356,"msg":{"market_ticker":"KXNEXTTEAMNBA-26LJAM-GSW","market_id":"abbbad28-f309-4dd5-af38-2ad7ebf2acc3","price_dollars":"0.5200","delta_fp":"-0.27","side":"no","ts":"2026-07-01T02:32:31.383156Z","ts_ms":1782873151383}}

{"type":"orderbook_delta","sid":1,"seq":357,"msg":{"market_ticker":"KXNEXTTEAMNBA-26LJAM-CLE","market_id":"7552b8d4-05de-4e41-84a8-97b0684da4a9","price_dollars":"0.7400","delta_fp":"-1.86","side":"no","ts":"2026-07-01T02:32:31.462284Z","ts_ms":1782873151462}}

{"type":"orderbook_delta","sid":1,"seq":358,"msg":{"market_ticker":"KXNEXTTEAMNBA-26LJAM-GSW","market_id":"abbbad28-f309-4dd5-af38-2ad7ebf2acc3","price_dollars":"0.0100","delta_fp":"1.00","side":"yes","ts":"2026-07-01T02:32:31.564413Z","ts_ms":1782873151564}}

{"type":"orderbook_delta","sid":1,"seq":359,"msg":{"market_ticker":"KXNEXTTEAMNBA-26LJAM-GSW","market_id":"abbbad28-f309-4dd5-af38-2ad7ebf2acc3","price_dollars":"0.0100","delta_fp":"1.00","side":"yes","ts":"2026-07-01T02:32:31.565001Z","ts_ms":1782873151565}}

{"type":"orderbook_delta","sid":1,"seq":360,"msg":{"market_ticker":"KXNEXTTEAMNBA-26LJAM-GSW","market_id":"abbbad28-f309-4dd5-af38-2ad7ebf2acc3","price_dollars":"0.0100","delta_fp":"1.00","side":"yes","ts":"2026-07-01T02:32:31.565699Z","ts_ms":1782873151565}}

{"type":"orderbook_delta","sid":1,"seq":361,"msg":{"market_ticker":"KXNEXTTEAMNBA-26LJAM-GSW","market_id":"abbbad28-f309-4dd5-af38-2ad7ebf2acc3","price_dollars":"0.0100","delta_fp":"1.00","side":"yes","ts":"2026-07-01T02:32:31.56662Z","ts_ms":1782873151566}}

{"type":"orderbook_delta","sid":1,"seq":362,"msg":{"market_ticker":"KXNEXTTEAMNBA-26LJAM-GSW","market_id":"abbbad28-f309-4dd5-af38-2ad7ebf2acc3","price_dollars":"0.0100","delta_fp":"1.00","side":"yes","ts":"2026-07-01T02:32:31.567439Z","ts_ms":1782873151567}}

{"type":"orderbook_delta","sid":1,"seq":363,"msg":{"market_ticker":"KXNEXTTEAMNBA-26LJAM-GSW","market_id":"abbbad28-f309-4dd5-af38-2ad7ebf2acc3","price_dollars":"0.0100","delta_fp":"1.00","side":"yes","ts":"2026-07-01T02:32:31.568225Z","ts_ms":1782873151568}}

{"type":"orderbook_delta","sid":1,"seq":364,"msg":{"market_ticker":"KXNEXTTEAMNBA-26LJAM-GSW","market_id":"abbbad28-f309-4dd5-af38-2ad7ebf2acc3","price_dollars":"0.0100","delta_fp":"1.00","side":"yes","ts":"2026-07-01T02:32:31.569462Z","ts_ms":1782873151569}}

{"type":"orderbook_delta","sid":1,"seq":365,"msg":{"market_ticker":"KXNEXTTEAMNBA-26LJAM-GSW","market_id":"abbbad28-f309-4dd5-af38-2ad7ebf2acc3","price_dollars":"0.0100","delta_fp":"1.00","side":"yes","ts":"2026-07-01T02:32:31.570297Z","ts_ms":1782873151570}}

{"type":"orderbook_delta","sid":1,"seq":366,"msg":{"market_ticker":"KXNEXTTEAMNBA-26LJAM-GSW","market_id":"abbbad28-f309-4dd5-af38-2ad7ebf2acc3","price_dollars":"0.0100","delta_fp":"1.00","side":"yes","ts":"2026-07-01T02:32:31.571097Z","ts_ms":1782873151571}}

{"type":"orderbook_delta","sid":1,"seq":367,"msg":{"market_ticker":"KXNEXTTEAMNBA-26LJAM-GSW","market_id":"abbbad28-f309-4dd5-af38-2ad7ebf2acc3","price_dollars":"0.0100","delta_fp":"1.00","side":"yes","ts":"2026-07-01T02:32:31.571974Z","ts_ms":1782873151571}}

{"type":"orderbook_delta","sid":1,"seq":368,"msg":{"market_ticker":"KXNEXTTEAMNBA-26LJAM-GSW","market_id":"abbbad28-f309-4dd5-af38-2ad7ebf2acc3","price_dollars":"0.0100","delta_fp":"1.00","side":"yes","ts":"2026-07-01T02:32:31.572859Z","ts_ms":1782873151572}}

{"type":"orderbook_delta","sid":1,"seq":369,"msg":{"market_ticker":"KXNEXTTEAMNBA-26LJAM-GSW","market_id":"abbbad28-f309-4dd5-af38-2ad7ebf2acc3","price_dollars":"0.0100","delta_fp":"1.00","side":"yes","ts":"2026-07-01T02:32:31.573579Z","ts_ms":1782873151573}}

{"type":"orderbook_delta","sid":1,"seq":370,"msg":{"market_ticker":"KXNEXTTEAMNBA-26LJAM-GSW","market_id":"abbbad28-f309-4dd5-af38-2ad7ebf2acc3","price_dollars":"0.0100","delta_fp":"1.00","side":"yes","ts":"2026-07-01T02:32:31.574132Z","ts_ms":1782873151574}}

{"type":"orderbook_delta","sid":1,"seq":371,"msg":{"market_ticker":"KXNEXTTEAMNBA-26LJAM-GSW","market_id":"abbbad28-f309-4dd5-af38-2ad7ebf2acc3","price_dollars":"0.0100","delta_fp":"1.00","side":"yes","ts":"2026-07-01T02:32:31.574801Z","ts_ms":1782873151574}}

{"type":"orderbook_delta","sid":1,"seq":372,"msg":{"market_ticker":"KXNEXTTEAMNBA-26LJAM-GSW","market_id":"abbbad28-f309-4dd5-af38-2ad7ebf2acc3","price_dollars":"0.0100","delta_fp":"1.00","side":"yes","ts":"2026-07-01T02:32:31.575411Z","ts_ms":1782873151575}}

{"type":"orderbook_delta","sid":1,"seq":373,"msg":{"market_ticker":"KXNEXTTEAMNBA-26LJAM-GSW","market_id":"abbbad28-f309-4dd5-af38-2ad7ebf2acc3","price_dollars":"0.0100","delta_fp":"1.00","side":"yes","ts":"2026-07-01T02:32:31.575793Z","ts_ms":1782873151575}}

{"type":"orderbook_delta","sid":1,"seq":374,"msg":{"market_ticker":"KXNEXTTEAMNBA-26LJAM-GSW","market_id":"abbbad28-f309-4dd5-af38-2ad7ebf2acc3","price_dollars":"0.0100","delta_fp":"1.00","side":"yes","ts":"2026-07-01T02:32:31.57628Z","ts_ms":1782873151576}}

{"type":"orderbook_delta","sid":1,"seq":375,"msg":{"market_ticker":"KXNEXTTEAMNBA-26LJAM-GSW","market_id":"abbbad28-f309-4dd5-af38-2ad7ebf2acc3","price_dollars":"0.0100","delta_fp":"1.00","side":"yes","ts":"2026-07-01T02:32:31.576848Z","ts_ms":1782873151576}}

{"type":"orderbook_delta","sid":1,"seq":376,"msg":{"market_ticker":"KXNEXTTEAMNBA-26LJAM-GSW","market_id":"abbbad28-f309-4dd5-af38-2ad7ebf2acc3","price_dollars":"0.0100","delta_fp":"1.00","side":"yes","ts":"2026-07-01T02:32:31.577293Z","ts_ms":1782873151577}}

{"type":"orderbook_delta","sid":1,"seq":377,"msg":{"market_ticker":"KXNEXTTEAMNBA-26LJAM-GSW","market_id":"abbbad28-f309-4dd5-af38-2ad7ebf2acc3","price_dollars":"0.0100","delta_fp":"1.00","side":"yes","ts":"2026-07-01T02:32:31.577818Z","ts_ms":1782873151577}}

{"type":"orderbook_delta","sid":1,"seq":378,"msg":{"market_ticker":"KXNEXTTEAMNBA-26LJAM-GSW","market_id":"abbbad28-f309-4dd5-af38-2ad7ebf2acc3","price_dollars":"0.5200","delta_fp":"-0.26","side":"no","ts":"2026-07-01T02:32:32.254549Z","ts_ms":1782873152254}}

{"type":"orderbook_delta","sid":1,"seq":379,"msg":{"market_ticker":"KXNEXTTEAMNBA-26LJAM-MIA","market_id":"492cb255-91da-4c91-bc9e-f83d090cc6dd","price_dollars":"0.0100","delta_fp":"1.00","side":"yes","ts":"2026-07-01T02:32:32.7371Z","ts_ms":1782873152737}}

{"type":"orderbook_delta","sid":1,"seq":380,"msg":{"market_ticker":"KXNEXTTEAMNBA-26LJAM-MIA","market_id":"492cb255-91da-4c91-bc9e-f83d090cc6dd","price_dollars":"0.0100","delta_fp":"1.00","side":"yes","ts":"2026-07-01T02:32:32.737703Z","ts_ms":1782873152737}}

{"type":"orderbook_delta","sid":1,"seq":381,"msg":{"market_ticker":"KXNEXTTEAMNBA-26LJAM-MIA","market_id":"492cb255-91da-4c91-bc9e-f83d090cc6dd","price_dollars":"0.0100","delta_fp":"1.00","side":"yes","ts":"2026-07-01T02:32:32.738144Z","ts_ms":1782873152738}}

{"type":"orderbook_delta","sid":1,"seq":382,"msg":{"market_ticker":"KXNEXTTEAMNBA-26LJAM-MIA","market_id":"492cb255-91da-4c91-bc9e-f83d090cc6dd","price_dollars":"0.0100","delta_fp":"1.00","side":"yes","ts":"2026-07-01T02:32:32.738623Z","ts_ms":1782873152738}}

{"type":"orderbook_delta","sid":1,"seq":383,"msg":{"market_ticker":"KXNEXTTEAMNBA-26LJAM-MIA","market_id":"492cb255-91da-4c91-bc9e-f83d090cc6dd","price_dollars":"0.0100","delta_fp":"1.00","side":"yes","ts":"2026-07-01T02:32:32.739148Z","ts_ms":1782873152739}}

{"type":"orderbook_delta","sid":1,"seq":384,"msg":{"market_ticker":"KXNEXTTEAMNBA-26LJAM-MIA","market_id":"492cb255-91da-4c91-bc9e-f83d090cc6dd","price_dollars":"0.0100","delta_fp":"1.00","side":"yes","ts":"2026-07-01T02:32:32.739578Z","ts_ms":1782873152739}}

{"type":"orderbook_delta","sid":1,"seq":385,"msg":{"market_ticker":"KXNEXTTEAMNBA-26LJAM-MIA","market_id":"492cb255-91da-4c91-bc9e-f83d090cc6dd","price_dollars":"0.0100","delta_fp":"1.00","side":"yes","ts":"2026-07-01T02:32:32.740121Z","ts_ms":1782873152740}}

{"type":"orderbook_delta","sid":1,"seq":386,"msg":{"market_ticker":"KXNEXTTEAMNBA-26LJAM-MIA","market_id":"492cb255-91da-4c91-bc9e-f83d090cc6dd","price_dollars":"0.0100","delta_fp":"1.00","side":"yes","ts":"2026-07-01T02:32:32.740699Z","ts_ms":1782873152740}}

{"type":"orderbook_delta","sid":1,"seq":387,"msg":{"market_ticker":"KXNEXTTEAMNBA-26LJAM-MIA","market_id":"492cb255-91da-4c91-bc9e-f83d090cc6dd","price_dollars":"0.0100","delta_fp":"1.00","side":"yes","ts":"2026-07-01T02:32:32.741167Z","ts_ms":1782873152741}}

{"type":"orderbook_delta","sid":1,"seq":388,"msg":{"market_ticker":"KXNEXTTEAMNBA-26LJAM-MIA","market_id":"492cb255-91da-4c91-bc9e-f83d090cc6dd","price_dollars":"0.0100","delta_fp":"1.00","side":"yes","ts":"2026-07-01T02:32:32.741615Z","ts_ms":1782873152741}}

{"type":"orderbook_delta","sid":1,"seq":389,"msg":{"market_ticker":"KXNEXTTEAMNBA-26LJAM-MIA","market_id":"492cb255-91da-4c91-bc9e-f83d090cc6dd","price_dollars":"0.0100","delta_fp":"1.00","side":"yes","ts":"2026-07-01T02:32:32.742063Z","ts_ms":1782873152742}}

{"type":"orderbook_delta","sid":1,"seq":390,"msg":{"market_ticker":"KXNEXTTEAMNBA-26LJAM-MIA","market_id":"492cb255-91da-4c91-bc9e-f83d090cc6dd","price_dollars":"0.0100","delta_fp":"1.00","side":"yes","ts":"2026-07-01T02:32:32.742544Z","ts_ms":1782873152742}}

{"type":"orderbook_delta","sid":1,"seq":391,"msg":{"market_ticker":"KXNEXTTEAMNBA-26LJAM-MIA","market_id":"492cb255-91da-4c91-bc9e-f83d090cc6dd","price_dollars":"0.0100","delta_fp":"1.00","side":"yes","ts":"2026-07-01T02:32:32.742972Z","ts_ms":1782873152742}}

{"type":"orderbook_delta","sid":1,"seq":392,"msg":{"market_ticker":"KXNEXTTEAMNBA-26LJAM-MIA","market_id":"492cb255-91da-4c91-bc9e-f83d090cc6dd","price_dollars":"0.0100","delta_fp":"1.00","side":"yes","ts":"2026-07-01T02:32:32.743625Z","ts_ms":1782873152743}}

{"type":"orderbook_delta","sid":1,"seq":393,"msg":{"market_ticker":"KXNEXTTEAMNBA-26LJAM-MIA","market_id":"492cb255-91da-4c91-bc9e-f83d090cc6dd","price_dollars":"0.0100","delta_fp":"1.00","side":"yes","ts":"2026-07-01T02:32:32.744198Z","ts_ms":1782873152744}}

{"type":"orderbook_delta","sid":1,"seq":394,"msg":{"market_ticker":"KXNEXTTEAMNBA-26LJAM-MIA","market_id":"492cb255-91da-4c91-bc9e-f83d090cc6dd","price_dollars":"0.0100","delta_fp":"1.00","side":"yes","ts":"2026-07-01T02:32:32.744601Z","ts_ms":1782873152744}}

{"type":"orderbook_delta","sid":1,"seq":395,"msg":{"market_ticker":"KXNEXTTEAMNBA-26LJAM-MIA","market_id":"492cb255-91da-4c91-bc9e-f83d090cc6dd","price_dollars":"0.0100","delta_fp":"1.00","side":"yes","ts":"2026-07-01T02:32:32.745104Z","ts_ms":1782873152745}}

{"type":"orderbook_delta","sid":1,"seq":396,"msg":{"market_ticker":"KXNEXTTEAMNBA-26LJAM-MIA","market_id":"492cb255-91da-4c91-bc9e-f83d090cc6dd","price_dollars":"0.0100","delta_fp":"1.00","side":"yes","ts":"2026-07-01T02:32:32.745692Z","ts_ms":1782873152745}}

{"type":"orderbook_delta","sid":1,"seq":397,"msg":{"market_ticker":"KXNEXTTEAMNBA-26LJAM-MIA","market_id":"492cb255-91da-4c91-bc9e-f83d090cc6dd","price_dollars":"0.0100","delta_fp":"1.00","side":"yes","ts":"2026-07-01T02:32:32.746283Z","ts_ms":1782873152746}}

{"type":"orderbook_delta","sid":1,"seq":398,"msg":{"market_ticker":"KXNEXTTEAMNBA-26LJAM-MIA","market_id":"492cb255-91da-4c91-bc9e-f83d090cc6dd","price_dollars":"0.0100","delta_fp":"1.00","side":"yes","ts":"2026-07-01T02:32:32.746777Z","ts_ms":1782873152746}}

{"type":"orderbook_delta","sid":1,"seq":399,"msg":{"market_ticker":"KXNEXTTEAMNBA-26LJAM-GSW","market_id":"abbbad28-f309-4dd5-af38-2ad7ebf2acc3","price_dollars":"0.5200","delta_fp":"-1.21","side":"no","ts":"2026-07-01T02:32:33.066759Z","ts_ms":1782873153066}}

{"type":"orderbook_delta","sid":1,"seq":400,"msg":{"market_ticker":"KXNEXTTEAMNBA-26LJAM-MIA","market_id":"492cb255-91da-4c91-bc9e-f83d090cc6dd","price_dollars":"0.8300","delta_fp":"-1.46","side":"no","ts":"2026-07-01T02:32:35.908002Z","ts_ms":1782873155908}}

{"type":"orderbook_delta","sid":1,"seq":401,"msg":{"market_ticker":"KXNEXTTEAMNBA-26LJAM-CLE","market_id":"7552b8d4-05de-4e41-84a8-97b0684da4a9","price_dollars":"0.7400","delta_fp":"-1.34","side":"no","ts":"2026-07-01T02:32:35.908019Z","ts_ms":1782873155908}}

{"type":"orderbook_delta","sid":1,"seq":402,"msg":{"market_ticker":"KXNEXTTEAMNBA-26LJAM-GSW","market_id":"abbbad28-f309-4dd5-af38-2ad7ebf2acc3","price_dollars":"0.5200","delta_fp":"-1.18","side":"no","ts":"2026-07-01T02:32:37.55789Z","ts_ms":1782873157557}}

{"type":"orderbook_delta","sid":1,"seq":403,"msg":{"market_ticker":"KXNEXTTEAMNBA-26LJAM-MIA","market_id":"492cb255-91da-4c91-bc9e-f83d090cc6dd","price_dollars":"0.8300","delta_fp":"-1.18","side":"no","ts":"2026-07-01T02:32:37.876925Z","ts_ms":1782873157876}}

{"type":"orderbook_delta","sid":1,"seq":404,"msg":{"market_ticker":"KXNEXTTEAMNBA-26LJAM-CLE","market_id":"7552b8d4-05de-4e41-84a8-97b0684da4a9","price_dollars":"0.7400","delta_fp":"-0.52","side":"no","ts":"2026-07-01T02:32:37.957584Z","ts_ms":1782873157957}}

{"type":"orderbook_delta","sid":1,"seq":405,"msg":{"market_ticker":"KXNEXTTEAMNBA-26LJAM-MIA","market_id":"492cb255-91da-4c91-bc9e-f83d090cc6dd","price_dollars":"0.0100","delta_fp":"1.00","side":"yes","ts":"2026-07-01T02:32:38.930025Z","ts_ms":1782873158930}}

{"type":"orderbook_delta","sid":1,"seq":406,"msg":{"market_ticker":"KXNEXTTEAMNBA-26LJAM-MIA","market_id":"492cb255-91da-4c91-bc9e-f83d090cc6dd","price_dollars":"0.0100","delta_fp":"1.00","side":"yes","ts":"2026-07-01T02:32:38.930497Z","ts_ms":1782873158930}}

{"type":"orderbook_delta","sid":1,"seq":407,"msg":{"market_ticker":"KXNEXTTEAMNBA-26LJAM-MIA","market_id":"492cb255-91da-4c91-bc9e-f83d090cc6dd","price_dollars":"0.0100","delta_fp":"1.00","side":"yes","ts":"2026-07-01T02:32:38.930779Z","ts_ms":1782873158930}}

{"type":"orderbook_delta","sid":1,"seq":408,"msg":{"market_ticker":"KXNEXTTEAMNBA-26LJAM-MIA","market_id":"492cb255-91da-4c91-bc9e-f83d090cc6dd","price_dollars":"0.0100","delta_fp":"1.00","side":"yes","ts":"2026-07-01T02:32:38.931047Z","ts_ms":1782873158931}}

{"type":"orderbook_delta","sid":1,"seq":409,"msg":{"market_ticker":"KXNEXTTEAMNBA-26LJAM-MIA","market_id":"492cb255-91da-4c91-bc9e-f83d090cc6dd","price_dollars":"0.0100","delta_fp":"1.00","side":"yes","ts":"2026-07-01T02:32:38.931441Z","ts_ms":1782873158931}}

{"type":"orderbook_delta","sid":1,"seq":410,"msg":{"market_ticker":"KXNEXTTEAMNBA-26LJAM-MIA","market_id":"492cb255-91da-4c91-bc9e-f83d090cc6dd","price_dollars":"0.0100","delta_fp":"1.00","side":"yes","ts":"2026-07-01T02:32:38.931692Z","ts_ms":1782873158931}}

{"type":"orderbook_delta","sid":1,"seq":411,"msg":{"market_ticker":"KXNEXTTEAMNBA-26LJAM-MIA","market_id":"492cb255-91da-4c91-bc9e-f83d090cc6dd","price_dollars":"0.0100","delta_fp":"1.00","side":"yes","ts":"2026-07-01T02:32:38.932227Z","ts_ms":1782873158932}}

{"type":"orderbook_delta","sid":1,"seq":412,"msg":{"market_ticker":"KXNEXTTEAMNBA-26LJAM-MIA","market_id":"492cb255-91da-4c91-bc9e-f83d090cc6dd","price_dollars":"0.0100","delta_fp":"1.00","side":"yes","ts":"2026-07-01T02:32:38.932691Z","ts_ms":1782873158932}}

{"type":"orderbook_delta","sid":1,"seq":413,"msg":{"market_ticker":"KXNEXTTEAMNBA-26LJAM-MIA","market_id":"492cb255-91da-4c91-bc9e-f83d090cc6dd","price_dollars":"0.0100","delta_fp":"1.00","side":"yes","ts":"2026-07-01T02:32:38.933281Z","ts_ms":1782873158933}}

{"type":"orderbook_delta","sid":1,"seq":414,"msg":{"market_ticker":"KXNEXTTEAMNBA-26LJAM-MIA","market_id":"492cb255-91da-4c91-bc9e-f83d090cc6dd","price_dollars":"0.0100","delta_fp":"1.00","side":"yes","ts":"2026-07-01T02:32:38.933952Z","ts_ms":1782873158933}}

{"type":"orderbook_delta","sid":1,"seq":415,"msg":{"market_ticker":"KXNEXTTEAMNBA-26LJAM-MIA","market_id":"492cb255-91da-4c91-bc9e-f83d090cc6dd","price_dollars":"0.0100","delta_fp":"1.00","side":"yes","ts":"2026-07-01T02:32:38.934421Z","ts_ms":1782873158934}}

{"type":"orderbook_delta","sid":1,"seq":416,"msg":{"market_ticker":"KXNEXTTEAMNBA-26LJAM-MIA","market_id":"492cb255-91da-4c91-bc9e-f83d090cc6dd","price_dollars":"0.0100","delta_fp":"1.00","side":"yes","ts":"2026-07-01T02:32:38.935012Z","ts_ms":1782873158935}}

{"type":"orderbook_delta","sid":1,"seq":417,"msg":{"market_ticker":"KXNEXTTEAMNBA-26LJAM-MIA","market_id":"492cb255-91da-4c91-bc9e-f83d090cc6dd","price_dollars":"0.0100","delta_fp":"1.00","side":"yes","ts":"2026-07-01T02:32:38.935647Z","ts_ms":1782873158935}}

{"type":"orderbook_delta","sid":1,"seq":418,"msg":{"market_ticker":"KXNEXTTEAMNBA-26LJAM-MIA","market_id":"492cb255-91da-4c91-bc9e-f83d090cc6dd","price_dollars":"0.0100","delta_fp":"1.00","side":"yes","ts":"2026-07-01T02:32:38.936784Z","ts_ms":1782873158936}}

{"type":"orderbook_delta","sid":1,"seq":419,"msg":{"market_ticker":"KXNEXTTEAMNBA-26LJAM-MIA","market_id":"492cb255-91da-4c91-bc9e-f83d090cc6dd","price_dollars":"0.0100","delta_fp":"1.00","side":"yes","ts":"2026-07-01T02:32:38.937426Z","ts_ms":1782873158937}}

{"type":"orderbook_delta","sid":1,"seq":420,"msg":{"market_ticker":"KXNEXTTEAMNBA-26LJAM-MIA","market_id":"492cb255-91da-4c91-bc9e-f83d090cc6dd","price_dollars":"0.0100","delta_fp":"1.00","side":"yes","ts":"2026-07-01T02:32:38.96058Z","ts_ms":1782873158960}}

{"type":"orderbook_delta","sid":1,"seq":421,"msg":{"market_ticker":"KXNEXTTEAMNBA-26LJAM-MIA","market_id":"492cb255-91da-4c91-bc9e-f83d090cc6dd","price_dollars":"0.0100","delta_fp":"1.00","side":"yes","ts":"2026-07-01T02:32:38.961151Z","ts_ms":1782873158961}}

{"type":"orderbook_delta","sid":1,"seq":422,"msg":{"market_ticker":"KXNEXTTEAMNBA-26LJAM-MIA","market_id":"492cb255-91da-4c91-bc9e-f83d090cc6dd","price_dollars":"0.0100","delta_fp":"1.00","side":"yes","ts":"2026-07-01T02:32:38.961577Z","ts_ms":1782873158961}}

{"type":"orderbook_delta","sid":1,"seq":423,"msg":{"market_ticker":"KXNEXTTEAMNBA-26LJAM-MIA","market_id":"492cb255-91da-4c91-bc9e-f83d090cc6dd","price_dollars":"0.0100","delta_fp":"1.00","side":"yes","ts":"2026-07-01T02:32:38.962139Z","ts_ms":1782873158962}}

{"type":"orderbook_delta","sid":1,"seq":424,"msg":{"market_ticker":"KXNEXTTEAMNBA-26LJAM-MIA","market_id":"492cb255-91da-4c91-bc9e-f83d090cc6dd","price_dollars":"0.0100","delta_fp":"1.00","side":"yes","ts":"2026-07-01T02:32:38.962632Z","ts_ms":1782873158962}}

{"type":"orderbook_delta","sid":1,"seq":425,"msg":{"market_ticker":"KXNEXTTEAMNBA-26LJAM-GSW","market_id":"abbbad28-f309-4dd5-af38-2ad7ebf2acc3","price_dollars":"0.5200","delta_fp":"-1.54","side":"no","ts":"2026-07-01T02:32:39.420017Z","ts_ms":1782873159420}}

{"type":"orderbook_delta","sid":1,"seq":426,"msg":{"market_ticker":"KXNEXTTEAMNBA-26LJAM-CLE","market_id":"7552b8d4-05de-4e41-84a8-97b0684da4a9","price_dollars":"0.7400","delta_fp":"-0.50","side":"no","ts":"2026-07-01T02:32:39.553019Z","ts_ms":1782873159553}}

{"type":"orderbook_delta","sid":1,"seq":427,"msg":{"market_ticker":"KXNEXTTEAMNBA-26LJAM-GSW","market_id":"abbbad28-f309-4dd5-af38-2ad7ebf2acc3","price_dollars":"0.4700","delta_fp":"709.21","side":"yes","ts":"2026-07-01T02:32:40.215889Z","ts_ms":1782873160215}}

{"type":"orderbook_delta","sid":1,"seq":428,"msg":{"market_ticker":"KXNEXTTEAMNBA-26LJAM-GSW","market_id":"abbbad28-f309-4dd5-af38-2ad7ebf2acc3","price_dollars":"0.4600","delta_fp":"724.63","side":"yes","ts":"2026-07-01T02:32:40.216339Z","ts_ms":1782873160216}}

{"type":"orderbook_delta","sid":1,"seq":429,"msg":{"market_ticker":"KXNEXTTEAMNBA-26LJAM-GSW","market_id":"abbbad28-f309-4dd5-af38-2ad7ebf2acc3","price_dollars":"0.4500","delta_fp":"740.74","side":"yes","ts":"2026-07-01T02:32:40.216979Z","ts_ms":1782873160216}}

{"type":"orderbook_delta","sid":1,"seq":430,"msg":{"market_ticker":"KXNEXTTEAMNBA-26LJAM-GSW","market_id":"abbbad28-f309-4dd5-af38-2ad7ebf2acc3","price_dollars":"0.5200","delta_fp":"694.44","side":"no","ts":"2026-07-01T02:32:40.217429Z","ts_ms":1782873160217}}

{"type":"orderbook_delta","sid":1,"seq":431,"msg":{"market_ticker":"KXNEXTTEAMNBA-26LJAM-GSW","market_id":"abbbad28-f309-4dd5-af38-2ad7ebf2acc3","price_dollars":"0.5100","delta_fp":"680.27","side":"no","ts":"2026-07-01T02:32:40.217887Z","ts_ms":1782873160217}}

{"type":"orderbook_delta","sid":1,"seq":432,"msg":{"market_ticker":"KXNEXTTEAMNBA-26LJAM-GSW","market_id":"abbbad28-f309-4dd5-af38-2ad7ebf2acc3","price_dollars":"0.5000","delta_fp":"666.66","side":"no","ts":"2026-07-01T02:32:40.218314Z","ts_ms":1782873160218}}

{"type":"orderbook_delta","sid":1,"seq":433,"msg":{"market_ticker":"KXNEXTTEAMNBA-26LJAM-MIA","market_id":"492cb255-91da-4c91-bc9e-f83d090cc6dd","price_dollars":"0.8300","delta_fp":"-0.41","side":"no","ts":"2026-07-01T02:32:41.867193Z","ts_ms":1782873161867}}

{"type":"orderbook_delta","sid":1,"seq":434,"msg":{"market_ticker":"KXNEXTTEAMNBA-26LJAM-GSW","market_id":"abbbad28-f309-4dd5-af38-2ad7ebf2acc3","price_dollars":"0.5200","delta_fp":"-1.19","side":"no","ts":"2026-07-01T02:32:41.972129Z","ts_ms":1782873161972}}

{"type":"orderbook_delta","sid":1,"seq":435,"msg":{"market_ticker":"KXNEXTTEAMNBA-26LJAM-CLE","market_id":"7552b8d4-05de-4e41-84a8-97b0684da4a9","price_dollars":"0.7400","delta_fp":"-0.12","side":"no","ts":"2026-07-01T02:32:42.75595Z","ts_ms":1782873162755}}

{"type":"orderbook_delta","sid":1,"seq":436,"msg":{"market_ticker":"KXNEXTTEAMNBA-26LJAM-MIA","market_id":"492cb255-91da-4c91-bc9e-f83d090cc6dd","price_dollars":"0.8300","delta_fp":"-1.59","side":"no","ts":"2026-07-01T02:32:43.554342Z","ts_ms":1782873163554}}

{"type":"orderbook_delta","sid":1,"seq":437,"msg":{"market_ticker":"KXNEXTTEAMNBA-26LJAM-GSW","market_id":"abbbad28-f309-4dd5-af38-2ad7ebf2acc3","price_dollars":"0.5200","delta_fp":"-0.91","side":"no","ts":"2026-07-01T02:32:43.559188Z","ts_ms":1782873163559}}

{"type":"orderbook_delta","sid":1,"seq":438,"msg":{"market_ticker":"KXNEXTTEAMNBA-26LJAM-CLE","market_id":"7552b8d4-05de-4e41-84a8-97b0684da4a9","price_dollars":"0.7400","delta_fp":"-0.95","side":"no","ts":"2026-07-01T02:32:43.570876Z","ts_ms":1782873163570}}

{"type":"orderbook_delta","sid":1,"seq":439,"msg":{"market_ticker":"KXNEXTTEAMNBA-26LJAM-MIA","market_id":"492cb255-91da-4c91-bc9e-f83d090cc6dd","price_dollars":"0.8300","delta_fp":"-0.77","side":"no","ts":"2026-07-01T02:32:44.379436Z","ts_ms":1782873164379}}

{"type":"orderbook_delta","sid":1,"seq":440,"msg":{"market_ticker":"KXNEXTTEAMNBA-26LJAM-GSW","market_id":"abbbad28-f309-4dd5-af38-2ad7ebf2acc3","price_dollars":"0.0100","delta_fp":"1.00","side":"yes","ts":"2026-07-01T02:32:44.563113Z","ts_ms":1782873164563}}

{"type":"orderbook_delta","sid":1,"seq":441,"msg":{"market_ticker":"KXNEXTTEAMNBA-26LJAM-GSW","market_id":"abbbad28-f309-4dd5-af38-2ad7ebf2acc3","price_dollars":"0.0100","delta_fp":"1.00","side":"yes","ts":"2026-07-01T02:32:44.56386Z","ts_ms":1782873164563}}

{"type":"orderbook_delta","sid":1,"seq":442,"msg":{"market_ticker":"KXNEXTTEAMNBA-26LJAM-GSW","market_id":"abbbad28-f309-4dd5-af38-2ad7ebf2acc3","price_dollars":"0.0100","delta_fp":"1.00","side":"yes","ts":"2026-07-01T02:32:44.564526Z","ts_ms":1782873164564}}

{"type":"orderbook_delta","sid":1,"seq":443,"msg":{"market_ticker":"KXNEXTTEAMNBA-26LJAM-GSW","market_id":"abbbad28-f309-4dd5-af38-2ad7ebf2acc3","price_dollars":"0.0100","delta_fp":"1.00","side":"yes","ts":"2026-07-01T02:32:44.565463Z","ts_ms":1782873164565}}

{"type":"orderbook_delta","sid":1,"seq":444,"msg":{"market_ticker":"KXNEXTTEAMNBA-26LJAM-GSW","market_id":"abbbad28-f309-4dd5-af38-2ad7ebf2acc3","price_dollars":"0.0100","delta_fp":"1.00","side":"yes","ts":"2026-07-01T02:32:44.566114Z","ts_ms":1782873164566}}

{"type":"orderbook_delta","sid":1,"seq":445,"msg":{"market_ticker":"KXNEXTTEAMNBA-26LJAM-GSW","market_id":"abbbad28-f309-4dd5-af38-2ad7ebf2acc3","price_dollars":"0.0100","delta_fp":"1.00","side":"yes","ts":"2026-07-01T02:32:44.566941Z","ts_ms":1782873164566}}

{"type":"orderbook_delta","sid":1,"seq":446,"msg":{"market_ticker":"KXNEXTTEAMNBA-26LJAM-GSW","market_id":"abbbad28-f309-4dd5-af38-2ad7ebf2acc3","price_dollars":"0.0100","delta_fp":"1.00","side":"yes","ts":"2026-07-01T02:32:44.567694Z","ts_ms":1782873164567}}

{"type":"orderbook_delta","sid":1,"seq":447,"msg":{"market_ticker":"KXNEXTTEAMNBA-26LJAM-GSW","market_id":"abbbad28-f309-4dd5-af38-2ad7ebf2acc3","price_dollars":"0.0100","delta_fp":"1.00","side":"yes","ts":"2026-07-01T02:32:44.568463Z","ts_ms":1782873164568}}

{"type":"orderbook_delta","sid":1,"seq":448,"msg":{"market_ticker":"KXNEXTTEAMNBA-26LJAM-GSW","market_id":"abbbad28-f309-4dd5-af38-2ad7ebf2acc3","price_dollars":"0.0100","delta_fp":"1.00","side":"yes","ts":"2026-07-01T02:32:44.569146Z","ts_ms":1782873164569}}

{"type":"orderbook_delta","sid":1,"seq":449,"msg":{"market_ticker":"KXNEXTTEAMNBA-26LJAM-GSW","market_id":"abbbad28-f309-4dd5-af38-2ad7ebf2acc3","price_dollars":"0.0100","delta_fp":"1.00","side":"yes","ts":"2026-07-01T02:32:44.570167Z","ts_ms":1782873164570}}

{"type":"orderbook_delta","sid":1,"seq":450,"msg":{"market_ticker":"KXNEXTTEAMNBA-26LJAM-GSW","market_id":"abbbad28-f309-4dd5-af38-2ad7ebf2acc3","price_dollars":"0.0100","delta_fp":"1.00","side":"yes","ts":"2026-07-01T02:32:44.571139Z","ts_ms":1782873164571}}

{"type":"orderbook_delta","sid":1,"seq":451,"msg":{"market_ticker":"KXNEXTTEAMNBA-26LJAM-GSW","market_id":"abbbad28-f309-4dd5-af38-2ad7ebf2acc3","price_dollars":"0.0100","delta_fp":"1.00","side":"yes","ts":"2026-07-01T02:32:44.571884Z","ts_ms":1782873164571}}

{"type":"orderbook_delta","sid":1,"seq":452,"msg":{"market_ticker":"KXNEXTTEAMNBA-26LJAM-GSW","market_id":"abbbad28-f309-4dd5-af38-2ad7ebf2acc3","price_dollars":"0.0100","delta_fp":"1.00","side":"yes","ts":"2026-07-01T02:32:44.572618Z","ts_ms":1782873164572}}

{"type":"orderbook_delta","sid":1,"seq":453,"msg":{"market_ticker":"KXNEXTTEAMNBA-26LJAM-GSW","market_id":"abbbad28-f309-4dd5-af38-2ad7ebf2acc3","price_dollars":"0.0100","delta_fp":"1.00","side":"yes","ts":"2026-07-01T02:32:44.573153Z","ts_ms":1782873164573}}

{"type":"orderbook_delta","sid":1,"seq":454,"msg":{"market_ticker":"KXNEXTTEAMNBA-26LJAM-GSW","market_id":"abbbad28-f309-4dd5-af38-2ad7ebf2acc3","price_dollars":"0.0100","delta_fp":"1.00","side":"yes","ts":"2026-07-01T02:32:44.573727Z","ts_ms":1782873164573}}

{"type":"orderbook_delta","sid":1,"seq":455,"msg":{"market_ticker":"KXNEXTTEAMNBA-26LJAM-GSW","market_id":"abbbad28-f309-4dd5-af38-2ad7ebf2acc3","price_dollars":"0.0100","delta_fp":"1.00","side":"yes","ts":"2026-07-01T02:32:44.574205Z","ts_ms":1782873164574}}

{"type":"orderbook_delta","sid":1,"seq":456,"msg":{"market_ticker":"KXNEXTTEAMNBA-26LJAM-GSW","market_id":"abbbad28-f309-4dd5-af38-2ad7ebf2acc3","price_dollars":"0.0100","delta_fp":"1.00","side":"yes","ts":"2026-07-01T02:32:44.57477Z","ts_ms":1782873164574}}

{"type":"orderbook_delta","sid":1,"seq":457,"msg":{"market_ticker":"KXNEXTTEAMNBA-26LJAM-GSW","market_id":"abbbad28-f309-4dd5-af38-2ad7ebf2acc3","price_dollars":"0.0100","delta_fp":"1.00","side":"yes","ts":"2026-07-01T02:32:44.575232Z","ts_ms":1782873164575}}

{"type":"orderbook_delta","sid":1,"seq":458,"msg":{"market_ticker":"KXNEXTTEAMNBA-26LJAM-GSW","market_id":"abbbad28-f309-4dd5-af38-2ad7ebf2acc3","price_dollars":"0.0100","delta_fp":"1.00","side":"yes","ts":"2026-07-01T02:32:44.575715Z","ts_ms":1782873164575}}

{"type":"orderbook_delta","sid":1,"seq":459,"msg":{"market_ticker":"KXNEXTTEAMNBA-26LJAM-GSW","market_id":"abbbad28-f309-4dd5-af38-2ad7ebf2acc3","price_dollars":"0.0100","delta_fp":"1.00","side":"yes","ts":"2026-07-01T02:32:44.576124Z","ts_ms":1782873164576}}

{"type":"orderbook_delta","sid":1,"seq":460,"msg":{"market_ticker":"KXNEXTTEAMNBA-26LJAM-CLE","market_id":"7552b8d4-05de-4e41-84a8-97b0684da4a9","price_dollars":"0.7400","delta_fp":"-1.89","side":"no","ts":"2026-07-01T02:32:45.09076Z","ts_ms":1782873165090}}

{"type":"orderbook_delta","sid":1,"seq":461,"msg":{"market_ticker":"KXNEXTTEAMNBA-26LJAM-CLE","market_id":"7552b8d4-05de-4e41-84a8-97b0684da4a9","price_dollars":"0.7400","delta_fp":"-1.16","side":"no","ts":"2026-07-01T02:32:45.168502Z","ts_ms":1782873165168}}

{"type":"orderbook_delta","sid":1,"seq":462,"msg":{"market_ticker":"KXNEXTTEAMNBA-26LJAM-MIA","market_id":"492cb255-91da-4c91-bc9e-f83d090cc6dd","price_dollars":"0.0100","delta_fp":"1.00","side":"yes","ts":"2026-07-01T02:32:45.752264Z","ts_ms":1782873165752}}

{"type":"orderbook_delta","sid":1,"seq":463,"msg":{"market_ticker":"KXNEXTTEAMNBA-26LJAM-MIA","market_id":"492cb255-91da-4c91-bc9e-f83d090cc6dd","price_dollars":"0.0100","delta_fp":"1.00","side":"yes","ts":"2026-07-01T02:32:45.752706Z","ts_ms":1782873165752}}

{"type":"orderbook_delta","sid":1,"seq":464,"msg":{"market_ticker":"KXNEXTTEAMNBA-26LJAM-MIA","market_id":"492cb255-91da-4c91-bc9e-f83d090cc6dd","price_dollars":"0.0100","delta_fp":"1.00","side":"yes","ts":"2026-07-01T02:32:45.753251Z","ts_ms":1782873165753}}

{"type":"orderbook_delta","sid":1,"seq":465,"msg":{"market_ticker":"KXNEXTTEAMNBA-26LJAM-MIA","market_id":"492cb255-91da-4c91-bc9e-f83d090cc6dd","price_dollars":"0.0100","delta_fp":"1.00","side":"yes","ts":"2026-07-01T02:32:45.7537Z","ts_ms":1782873165753}}

{"type":"orderbook_delta","sid":1,"seq":466,"msg":{"market_ticker":"KXNEXTTEAMNBA-26LJAM-MIA","market_id":"492cb255-91da-4c91-bc9e-f83d090cc6dd","price_dollars":"0.0100","delta_fp":"1.00","side":"yes","ts":"2026-07-01T02:32:45.75423Z","ts_ms":1782873165754}}

{"type":"orderbook_delta","sid":1,"seq":467,"msg":{"market_ticker":"KXNEXTTEAMNBA-26LJAM-MIA","market_id":"492cb255-91da-4c91-bc9e-f83d090cc6dd","price_dollars":"0.0100","delta_fp":"1.00","side":"yes","ts":"2026-07-01T02:32:45.754709Z","ts_ms":1782873165754}}

{"type":"orderbook_delta","sid":1,"seq":468,"msg":{"market_ticker":"KXNEXTTEAMNBA-26LJAM-MIA","market_id":"492cb255-91da-4c91-bc9e-f83d090cc6dd","price_dollars":"0.0100","delta_fp":"1.00","side":"yes","ts":"2026-07-01T02:32:45.755299Z","ts_ms":1782873165755}}

{"type":"orderbook_delta","sid":1,"seq":469,"msg":{"market_ticker":"KXNEXTTEAMNBA-26LJAM-MIA","market_id":"492cb255-91da-4c91-bc9e-f83d090cc6dd","price_dollars":"0.0100","delta_fp":"1.00","side":"yes","ts":"2026-07-01T02:32:45.75575Z","ts_ms":1782873165755}}

{"type":"orderbook_delta","sid":1,"seq":470,"msg":{"market_ticker":"KXNEXTTEAMNBA-26LJAM-MIA","market_id":"492cb255-91da-4c91-bc9e-f83d090cc6dd","price_dollars":"0.0100","delta_fp":"1.00","side":"yes","ts":"2026-07-01T02:32:45.756273Z","ts_ms":1782873165756}}

{"type":"orderbook_delta","sid":1,"seq":471,"msg":{"market_ticker":"KXNEXTTEAMNBA-26LJAM-MIA","market_id":"492cb255-91da-4c91-bc9e-f83d090cc6dd","price_dollars":"0.0100","delta_fp":"1.00","side":"yes","ts":"2026-07-01T02:32:45.756804Z","ts_ms":1782873165756}}

{"type":"orderbook_delta","sid":1,"seq":472,"msg":{"market_ticker":"KXNEXTTEAMNBA-26LJAM-MIA","market_id":"492cb255-91da-4c91-bc9e-f83d090cc6dd","price_dollars":"0.0100","delta_fp":"1.00","side":"yes","ts":"2026-07-01T02:32:45.757152Z","ts_ms":1782873165757}}

{"type":"orderbook_delta","sid":1,"seq":473,"msg":{"market_ticker":"KXNEXTTEAMNBA-26LJAM-MIA","market_id":"492cb255-91da-4c91-bc9e-f83d090cc6dd","price_dollars":"0.0100","delta_fp":"1.00","side":"yes","ts":"2026-07-01T02:32:45.75761Z","ts_ms":1782873165757}}

{"type":"orderbook_delta","sid":1,"seq":474,"msg":{"market_ticker":"KXNEXTTEAMNBA-26LJAM-MIA","market_id":"492cb255-91da-4c91-bc9e-f83d090cc6dd","price_dollars":"0.0100","delta_fp":"1.00","side":"yes","ts":"2026-07-01T02:32:45.758376Z","ts_ms":1782873165758}}

{"type":"orderbook_delta","sid":1,"seq":475,"msg":{"market_ticker":"KXNEXTTEAMNBA-26LJAM-MIA","market_id":"492cb255-91da-4c91-bc9e-f83d090cc6dd","price_dollars":"0.0100","delta_fp":"1.00","side":"yes","ts":"2026-07-01T02:32:45.758989Z","ts_ms":1782873165758}}

{"type":"orderbook_delta","sid":1,"seq":476,"msg":{"market_ticker":"KXNEXTTEAMNBA-26LJAM-MIA","market_id":"492cb255-91da-4c91-bc9e-f83d090cc6dd","price_dollars":"0.0100","delta_fp":"1.00","side":"yes","ts":"2026-07-01T02:32:45.75958Z","ts_ms":1782873165759}}

{"type":"orderbook_delta","sid":1,"seq":477,"msg":{"market_ticker":"KXNEXTTEAMNBA-26LJAM-MIA","market_id":"492cb255-91da-4c91-bc9e-f83d090cc6dd","price_dollars":"0.0100","delta_fp":"1.00","side":"yes","ts":"2026-07-01T02:32:45.760027Z","ts_ms":1782873165760}}

{"type":"orderbook_delta","sid":1,"seq":478,"msg":{"market_ticker":"KXNEXTTEAMNBA-26LJAM-MIA","market_id":"492cb255-91da-4c91-bc9e-f83d090cc6dd","price_dollars":"0.0100","delta_fp":"1.00","side":"yes","ts":"2026-07-01T02:32:45.760657Z","ts_ms":1782873165760}}

{"type":"orderbook_delta","sid":1,"seq":479,"msg":{"market_ticker":"KXNEXTTEAMNBA-26LJAM-MIA","market_id":"492cb255-91da-4c91-bc9e-f83d090cc6dd","price_dollars":"0.0100","delta_fp":"1.00","side":"yes","ts":"2026-07-01T02:32:45.761156Z","ts_ms":1782873165761}}

{"type":"orderbook_delta","sid":1,"seq":480,"msg":{"market_ticker":"KXNEXTTEAMNBA-26LJAM-MIA","market_id":"492cb255-91da-4c91-bc9e-f83d090cc6dd","price_dollars":"0.0100","delta_fp":"1.00","side":"yes","ts":"2026-07-01T02:32:45.761713Z","ts_ms":1782873165761}}

{"type":"orderbook_delta","sid":1,"seq":481,"msg":{"market_ticker":"KXNEXTTEAMNBA-26LJAM-MIA","market_id":"492cb255-91da-4c91-bc9e-f83d090cc6dd","price_dollars":"0.0100","delta_fp":"1.00","side":"yes","ts":"2026-07-01T02:32:45.762342Z","ts_ms":1782873165762}}

{"type":"orderbook_delta","sid":1,"seq":482,"msg":{"market_ticker":"KXNEXTTEAMNBA-26LJAM-GSW","market_id":"abbbad28-f309-4dd5-af38-2ad7ebf2acc3","price_dollars":"0.0100","delta_fp":"-1.00","side":"yes","ts":"2026-07-01T02:32:46.360104Z","ts_ms":1782873166360}}

{"type":"orderbook_delta","sid":1,"seq":483,"msg":{"market_ticker":"KXNEXTTEAMNBA-26LJAM-GSW","market_id":"abbbad28-f309-4dd5-af38-2ad7ebf2acc3","price_dollars":"0.0100","delta_fp":"-1.00","side":"yes","ts":"2026-07-01T02:32:46.36072Z","ts_ms":1782873166360}}

{"type":"orderbook_delta","sid":1,"seq":484,"msg":{"market_ticker":"KXNEXTTEAMNBA-26LJAM-GSW","market_id":"abbbad28-f309-4dd5-af38-2ad7ebf2acc3","price_dollars":"0.0100","delta_fp":"-1.00","side":"yes","ts":"2026-07-01T02:32:46.361386Z","ts_ms":1782873166361}}

{"type":"orderbook_delta","sid":1,"seq":485,"msg":{"market_ticker":"KXNEXTTEAMNBA-26LJAM-GSW","market_id":"abbbad28-f309-4dd5-af38-2ad7ebf2acc3","price_dollars":"0.0100","delta_fp":"-1.00","side":"yes","ts":"2026-07-01T02:32:46.36202Z","ts_ms":1782873166362}}

{"type":"orderbook_delta","sid":1,"seq":486,"msg":{"market_ticker":"KXNEXTTEAMNBA-26LJAM-GSW","market_id":"abbbad28-f309-4dd5-af38-2ad7ebf2acc3","price_dollars":"0.0100","delta_fp":"-1.00","side":"yes","ts":"2026-07-01T02:32:46.362514Z","ts_ms":1782873166362}}

{"type":"orderbook_delta","sid":1,"seq":487,"msg":{"market_ticker":"KXNEXTTEAMNBA-26LJAM-GSW","market_id":"abbbad28-f309-4dd5-af38-2ad7ebf2acc3","price_dollars":"0.0100","delta_fp":"-1.00","side":"yes","ts":"2026-07-01T02:32:46.363109Z","ts_ms":1782873166363}}

{"type":"orderbook_delta","sid":1,"seq":488,"msg":{"market_ticker":"KXNEXTTEAMNBA-26LJAM-GSW","market_id":"abbbad28-f309-4dd5-af38-2ad7ebf2acc3","price_dollars":"0.0100","delta_fp":"-1.00","side":"yes","ts":"2026-07-01T02:32:46.363754Z","ts_ms":1782873166363}}

{"type":"orderbook_delta","sid":1,"seq":489,"msg":{"market_ticker":"KXNEXTTEAMNBA-26LJAM-GSW","market_id":"abbbad28-f309-4dd5-af38-2ad7ebf2acc3","price_dollars":"0.0100","delta_fp":"-1.00","side":"yes","ts":"2026-07-01T02:32:46.36448Z","ts_ms":1782873166364}}

{"type":"orderbook_delta","sid":1,"seq":490,"msg":{"market_ticker":"KXNEXTTEAMNBA-26LJAM-GSW","market_id":"abbbad28-f309-4dd5-af38-2ad7ebf2acc3","price_dollars":"0.0100","delta_fp":"-1.00","side":"yes","ts":"2026-07-01T02:32:46.365177Z","ts_ms":1782873166365}}

{"type":"orderbook_delta","sid":1,"seq":491,"msg":{"market_ticker":"KXNEXTTEAMNBA-26LJAM-GSW","market_id":"abbbad28-f309-4dd5-af38-2ad7ebf2acc3","price_dollars":"0.0100","delta_fp":"-1.00","side":"yes","ts":"2026-07-01T02:32:46.365821Z","ts_ms":1782873166365}}

{"type":"orderbook_delta","sid":1,"seq":492,"msg":{"market_ticker":"KXNEXTTEAMNBA-26LJAM-GSW","market_id":"abbbad28-f309-4dd5-af38-2ad7ebf2acc3","price_dollars":"0.0100","delta_fp":"-1.00","side":"yes","ts":"2026-07-01T02:32:46.366704Z","ts_ms":1782873166366}}

{"type":"orderbook_delta","sid":1,"seq":493,"msg":{"market_ticker":"KXNEXTTEAMNBA-26LJAM-GSW","market_id":"abbbad28-f309-4dd5-af38-2ad7ebf2acc3","price_dollars":"0.0100","delta_fp":"-1.00","side":"yes","ts":"2026-07-01T02:32:46.367527Z","ts_ms":1782873166367}}

{"type":"orderbook_delta","sid":1,"seq":494,"msg":{"market_ticker":"KXNEXTTEAMNBA-26LJAM-GSW","market_id":"abbbad28-f309-4dd5-af38-2ad7ebf2acc3","price_dollars":"0.0100","delta_fp":"-1.00","side":"yes","ts":"2026-07-01T02:32:46.368599Z","ts_ms":1782873166368}}

{"type":"orderbook_delta","sid":1,"seq":495,"msg":{"market_ticker":"KXNEXTTEAMNBA-26LJAM-GSW","market_id":"abbbad28-f309-4dd5-af38-2ad7ebf2acc3","price_dollars":"0.0100","delta_fp":"-1.00","side":"yes","ts":"2026-07-01T02:32:46.36936Z","ts_ms":1782873166369}}

{"type":"orderbook_delta","sid":1,"seq":496,"msg":{"market_ticker":"KXNEXTTEAMNBA-26LJAM-GSW","market_id":"abbbad28-f309-4dd5-af38-2ad7ebf2acc3","price_dollars":"0.0100","delta_fp":"-1.00","side":"yes","ts":"2026-07-01T02:32:46.36994Z","ts_ms":1782873166369}}

{"type":"orderbook_delta","sid":1,"seq":497,"msg":{"market_ticker":"KXNEXTTEAMNBA-26LJAM-GSW","market_id":"abbbad28-f309-4dd5-af38-2ad7ebf2acc3","price_dollars":"0.0100","delta_fp":"-1.00","side":"yes","ts":"2026-07-01T02:32:46.370575Z","ts_ms":1782873166370}}

{"type":"orderbook_delta","sid":1,"seq":498,"msg":{"market_ticker":"KXNEXTTEAMNBA-26LJAM-GSW","market_id":"abbbad28-f309-4dd5-af38-2ad7ebf2acc3","price_dollars":"0.0100","delta_fp":"-1.00","side":"yes","ts":"2026-07-01T02:32:46.371254Z","ts_ms":1782873166371}}

{"type":"orderbook_delta","sid":1,"seq":499,"msg":{"market_ticker":"KXNEXTTEAMNBA-26LJAM-GSW","market_id":"abbbad28-f309-4dd5-af38-2ad7ebf2acc3","price_dollars":"0.0100","delta_fp":"-1.00","side":"yes","ts":"2026-07-01T02:32:46.371971Z","ts_ms":1782873166371}}

{"type":"orderbook_delta","sid":1,"seq":500,"msg":{"market_ticker":"KXNEXTTEAMNBA-26LJAM-GSW","market_id":"abbbad28-f309-4dd5-af38-2ad7ebf2acc3","price_dollars":"0.0100","delta_fp":"-1.00","side":"yes","ts":"2026-07-01T02:32:46.37243Z","ts_ms":1782873166372}}

{"type":"orderbook_delta","sid":1,"seq":501,"msg":{"market_ticker":"KXNEXTTEAMNBA-26LJAM-GSW","market_id":"abbbad28-f309-4dd5-af38-2ad7ebf2acc3","price_dollars":"0.0100","delta_fp":"-1.00","side":"yes","ts":"2026-07-01T02:32:46.373104Z","ts_ms":1782873166373}}

{"type":"orderbook_delta","sid":1,"seq":502,"msg":{"market_ticker":"KXNEXTTEAMNBA-26LJAM-GSW","market_id":"abbbad28-f309-4dd5-af38-2ad7ebf2acc3","price_dollars":"0.5200","delta_fp":"-0.92","side":"no","ts":"2026-07-01T02:32:48.455288Z","ts_ms":1782873168455}}

{"type":"orderbook_delta","sid":1,"seq":503,"msg":{"market_ticker":"KXNEXTTEAMNBA-26LJAM-CLE","market_id":"7552b8d4-05de-4e41-84a8-97b0684da4a9","price_dollars":"0.7400","delta_fp":"-1.70","side":"no","ts":"2026-07-01T02:32:48.468997Z","ts_ms":1782873168468}}

{"type":"orderbook_delta","sid":1,"seq":504,"msg":{"market_ticker":"KXNEXTTEAMNBA-26LJAM-GSW","market_id":"abbbad28-f309-4dd5-af38-2ad7ebf2acc3","price_dollars":"0.5200","delta_fp":"-1.77","side":"no","ts":"2026-07-01T02:32:49.995671Z","ts_ms":1782873169995}}

{"type":"orderbook_delta","sid":1,"seq":505,"msg":{"market_ticker":"KXNEXTTEAMNBA-26LJAM-GSW","market_id":"abbbad28-f309-4dd5-af38-2ad7ebf2acc3","price_dollars":"0.5200","delta_fp":"-0.16","side":"no","ts":"2026-07-01T02:32:50.083992Z","ts_ms":1782873170083}}

{"type":"orderbook_delta","sid":1,"seq":506,"msg":{"market_ticker":"KXNEXTTEAMNBA-26LJAM-CLE","market_id":"7552b8d4-05de-4e41-84a8-97b0684da4a9","price_dollars":"0.7400","delta_fp":"-0.08","side":"no","ts":"2026-07-01T02:32:50.159304Z","ts_ms":1782873170159}}

{"type":"orderbook_delta","sid":1,"seq":507,"msg":{"market_ticker":"KXNEXTTEAMNBA-26LJAM-GSW","market_id":"abbbad28-f309-4dd5-af38-2ad7ebf2acc3","price_dollars":"0.0100","delta_fp":"1.00","side":"yes","ts":"2026-07-01T02:32:50.864796Z","ts_ms":1782873170864}}

{"type":"orderbook_delta","sid":1,"seq":508,"msg":{"market_ticker":"KXNEXTTEAMNBA-26LJAM-GSW","market_id":"abbbad28-f309-4dd5-af38-2ad7ebf2acc3","price_dollars":"0.0100","delta_fp":"1.00","side":"yes","ts":"2026-07-01T02:32:50.866033Z","ts_ms":1782873170866}}

{"type":"orderbook_delta","sid":1,"seq":509,"msg":{"market_ticker":"KXNEXTTEAMNBA-26LJAM-GSW","market_id":"abbbad28-f309-4dd5-af38-2ad7ebf2acc3","price_dollars":"0.0100","delta_fp":"1.00","side":"yes","ts":"2026-07-01T02:32:50.866905Z","ts_ms":1782873170866}}

{"type":"orderbook_delta","sid":1,"seq":510,"msg":{"market_ticker":"KXNEXTTEAMNBA-26LJAM-GSW","market_id":"abbbad28-f309-4dd5-af38-2ad7ebf2acc3","price_dollars":"0.0100","delta_fp":"1.00","side":"yes","ts":"2026-07-01T02:32:50.867399Z","ts_ms":1782873170867}}

{"type":"orderbook_delta","sid":1,"seq":511,"msg":{"market_ticker":"KXNEXTTEAMNBA-26LJAM-GSW","market_id":"abbbad28-f309-4dd5-af38-2ad7ebf2acc3","price_dollars":"0.0100","delta_fp":"1.00","side":"yes","ts":"2026-07-01T02:32:50.868293Z","ts_ms":1782873170868}}

{"type":"orderbook_delta","sid":1,"seq":512,"msg":{"market_ticker":"KXNEXTTEAMNBA-26LJAM-GSW","market_id":"abbbad28-f309-4dd5-af38-2ad7ebf2acc3","price_dollars":"0.0100","delta_fp":"1.00","side":"yes","ts":"2026-07-01T02:32:50.869346Z","ts_ms":1782873170869}}

{"type":"orderbook_delta","sid":1,"seq":513,"msg":{"market_ticker":"KXNEXTTEAMNBA-26LJAM-GSW","market_id":"abbbad28-f309-4dd5-af38-2ad7ebf2acc3","price_dollars":"0.0100","delta_fp":"1.00","side":"yes","ts":"2026-07-01T02:32:50.870389Z","ts_ms":1782873170870}}

{"type":"orderbook_delta","sid":1,"seq":514,"msg":{"market_ticker":"KXNEXTTEAMNBA-26LJAM-GSW","market_id":"abbbad28-f309-4dd5-af38-2ad7ebf2acc3","price_dollars":"0.0100","delta_fp":"1.00","side":"yes","ts":"2026-07-01T02:32:50.871155Z","ts_ms":1782873170871}}

{"type":"orderbook_delta","sid":1,"seq":515,"msg":{"market_ticker":"KXNEXTTEAMNBA-26LJAM-GSW","market_id":"abbbad28-f309-4dd5-af38-2ad7ebf2acc3","price_dollars":"0.0100","delta_fp":"1.00","side":"yes","ts":"2026-07-01T02:32:50.872041Z","ts_ms":1782873170872}}

{"type":"orderbook_delta","sid":1,"seq":516,"msg":{"market_ticker":"KXNEXTTEAMNBA-26LJAM-GSW","market_id":"abbbad28-f309-4dd5-af38-2ad7ebf2acc3","price_dollars":"0.0100","delta_fp":"1.00","side":"yes","ts":"2026-07-01T02:32:50.872773Z","ts_ms":1782873170872}}

{"type":"orderbook_delta","sid":1,"seq":517,"msg":{"market_ticker":"KXNEXTTEAMNBA-26LJAM-GSW","market_id":"abbbad28-f309-4dd5-af38-2ad7ebf2acc3","price_dollars":"0.0100","delta_fp":"1.00","side":"yes","ts":"2026-07-01T02:32:50.873585Z","ts_ms":1782873170873}}

{"type":"orderbook_delta","sid":1,"seq":518,"msg":{"market_ticker":"KXNEXTTEAMNBA-26LJAM-GSW","market_id":"abbbad28-f309-4dd5-af38-2ad7ebf2acc3","price_dollars":"0.0100","delta_fp":"1.00","side":"yes","ts":"2026-07-01T02:32:50.874313Z","ts_ms":1782873170874}}

{"type":"orderbook_delta","sid":1,"seq":519,"msg":{"market_ticker":"KXNEXTTEAMNBA-26LJAM-GSW","market_id":"abbbad28-f309-4dd5-af38-2ad7ebf2acc3","price_dollars":"0.0100","delta_fp":"1.00","side":"yes","ts":"2026-07-01T02:32:50.874697Z","ts_ms":1782873170874}}

{"type":"orderbook_delta","sid":1,"seq":520,"msg":{"market_ticker":"KXNEXTTEAMNBA-26LJAM-GSW","market_id":"abbbad28-f309-4dd5-af38-2ad7ebf2acc3","price_dollars":"0.0100","delta_fp":"1.00","side":"yes","ts":"2026-07-01T02:32:50.875354Z","ts_ms":1782873170875}}

{"type":"orderbook_delta","sid":1,"seq":521,"msg":{"market_ticker":"KXNEXTTEAMNBA-26LJAM-GSW","market_id":"abbbad28-f309-4dd5-af38-2ad7ebf2acc3","price_dollars":"0.0100","delta_fp":"1.00","side":"yes","ts":"2026-07-01T02:32:50.87581Z","ts_ms":1782873170875}}

{"type":"orderbook_delta","sid":1,"seq":522,"msg":{"market_ticker":"KXNEXTTEAMNBA-26LJAM-GSW","market_id":"abbbad28-f309-4dd5-af38-2ad7ebf2acc3","price_dollars":"0.0100","delta_fp":"1.00","side":"yes","ts":"2026-07-01T02:32:50.876327Z","ts_ms":1782873170876}}

{"type":"orderbook_delta","sid":1,"seq":523,"msg":{"market_ticker":"KXNEXTTEAMNBA-26LJAM-GSW","market_id":"abbbad28-f309-4dd5-af38-2ad7ebf2acc3","price_dollars":"0.0100","delta_fp":"1.00","side":"yes","ts":"2026-07-01T02:32:50.876845Z","ts_ms":1782873170876}}

{"type":"orderbook_delta","sid":1,"seq":524,"msg":{"market_ticker":"KXNEXTTEAMNBA-26LJAM-GSW","market_id":"abbbad28-f309-4dd5-af38-2ad7ebf2acc3","price_dollars":"0.0100","delta_fp":"1.00","side":"yes","ts":"2026-07-01T02:32:50.877237Z","ts_ms":1782873170877}}

{"type":"orderbook_delta","sid":1,"seq":525,"msg":{"market_ticker":"KXNEXTTEAMNBA-26LJAM-GSW","market_id":"abbbad28-f309-4dd5-af38-2ad7ebf2acc3","price_dollars":"0.0100","delta_fp":"1.00","side":"yes","ts":"2026-07-01T02:32:50.877851Z","ts_ms":1782873170877}}

{"type":"orderbook_delta","sid":1,"seq":526,"msg":{"market_ticker":"KXNEXTTEAMNBA-26LJAM-GSW","market_id":"abbbad28-f309-4dd5-af38-2ad7ebf2acc3","price_dollars":"0.0100","delta_fp":"1.00","side":"yes","ts":"2026-07-01T02:32:50.87821Z","ts_ms":1782873170878}}

{"type":"orderbook_delta","sid":1,"seq":527,"msg":{"market_ticker":"KXNEXTTEAMNBA-26LJAM-GSW","market_id":"abbbad28-f309-4dd5-af38-2ad7ebf2acc3","price_dollars":"0.5200","delta_fp":"-1.92","side":"no","ts":"2026-07-01T02:32:51.689423Z","ts_ms":1782873171689}}

{"type":"orderbook_delta","sid":1,"seq":528,"msg":{"market_ticker":"KXNEXTTEAMNBA-26LJAM-CLE","market_id":"7552b8d4-05de-4e41-84a8-97b0684da4a9","price_dollars":"0.7400","delta_fp":"-1.58","side":"no","ts":"2026-07-01T02:32:51.702624Z","ts_ms":1782873171702}}

{"type":"orderbook_delta","sid":1,"seq":529,"msg":{"market_ticker":"KXNEXTTEAMNBA-26LJAM-GSW","market_id":"abbbad28-f309-4dd5-af38-2ad7ebf2acc3","price_dollars":"0.5200","delta_fp":"-1.49","side":"no","ts":"2026-07-01T02:32:53.364867Z","ts_ms":1782873173364}}

{"type":"orderbook_delta","sid":1,"seq":530,"msg":{"market_ticker":"KXNEXTTEAMNBA-26LJAM-CLE","market_id":"7552b8d4-05de-4e41-84a8-97b0684da4a9","price_dollars":"0.7400","delta_fp":"-0.87","side":"no","ts":"2026-07-01T02:32:53.384742Z","ts_ms":1782873173384}}

{"type":"orderbook_delta","sid":1,"seq":531,"msg":{"market_ticker":"KXNEXTTEAMNBA-26LJAM-MIA","market_id":"492cb255-91da-4c91-bc9e-f83d090cc6dd","price_dollars":"0.8300","delta_fp":"-0.49","side":"no","ts":"2026-07-01T02:32:53.391585Z","ts_ms":1782873173391}}

{"type":"orderbook_delta","sid":1,"seq":532,"msg":{"market_ticker":"KXNEXTTEAMNBA-26LJAM-MIA","market_id":"492cb255-91da-4c91-bc9e-f83d090cc6dd","price_dollars":"0.1600","delta_fp":"2083.33","side":"yes","ts":"2026-07-01T02:32:53.956566Z","ts_ms":1782873173956}}

{"type":"orderbook_delta","sid":1,"seq":533,"msg":{"market_ticker":"KXNEXTTEAMNBA-26LJAM-MIA","market_id":"492cb255-91da-4c91-bc9e-f83d090cc6dd","price_dollars":"0.1500","delta_fp":"2222.22","side":"yes","ts":"2026-07-01T02:32:53.95701Z","ts_ms":1782873173957}}

{"type":"orderbook_delta","sid":1,"seq":534,"msg":{"market_ticker":"KXNEXTTEAMNBA-26LJAM-MIA","market_id":"492cb255-91da-4c91-bc9e-f83d090cc6dd","price_dollars":"0.1400","delta_fp":"2380.95","side":"yes","ts":"2026-07-01T02:32:53.95743Z","ts_ms":1782873173957}}

{"type":"orderbook_delta","sid":1,"seq":535,"msg":{"market_ticker":"KXNEXTTEAMNBA-26LJAM-MIA","market_id":"492cb255-91da-4c91-bc9e-f83d090cc6dd","price_dollars":"0.8300","delta_fp":"1960.78","side":"no","ts":"2026-07-01T02:32:53.957768Z","ts_ms":1782873173957}}

{"type":"orderbook_delta","sid":1,"seq":536,"msg":{"market_ticker":"KXNEXTTEAMNBA-26LJAM-MIA","market_id":"492cb255-91da-4c91-bc9e-f83d090cc6dd","price_dollars":"0.8200","delta_fp":"1851.85","side":"no","ts":"2026-07-01T02:32:53.958242Z","ts_ms":1782873173958}}

{"type":"orderbook_delta","sid":1,"seq":537,"msg":{"market_ticker":"KXNEXTTEAMNBA-26LJAM-MIA","market_id":"492cb255-91da-4c91-bc9e-f83d090cc6dd","price_dollars":"0.8100","delta_fp":"1754.38","side":"no","ts":"2026-07-01T02:32:53.958677Z","ts_ms":1782873173958}}

{"type":"orderbook_delta","sid":1,"seq":538,"msg":{"market_ticker":"KXNEXTTEAMNBA-26LJAM-MIA","market_id":"492cb255-91da-4c91-bc9e-f83d090cc6dd","price_dollars":"0.8300","delta_fp":"-0.26","side":"no","ts":"2026-07-01T02:32:54.91133Z","ts_ms":1782873174911}}

{"type":"orderbook_delta","sid":1,"seq":539,"msg":{"market_ticker":"KXNEXTTEAMNBA-26LJAM-MIA","market_id":"492cb255-91da-4c91-bc9e-f83d090cc6dd","price_dollars":"0.8300","delta_fp":"-1.86","side":"no","ts":"2026-07-01T02:32:54.973339Z","ts_ms":1782873174973}}

{"type":"orderbook_delta","sid":1,"seq":540,"msg":{"market_ticker":"KXNEXTTEAMNBA-26LJAM-GSW","market_id":"abbbad28-f309-4dd5-af38-2ad7ebf2acc3","price_dollars":"0.5200","delta_fp":"-1.16","side":"no","ts":"2026-07-01T02:32:56.497872Z","ts_ms":1782873176497}}

{"type":"orderbook_delta","sid":1,"seq":541,"msg":{"market_ticker":"KXNEXTTEAMNBA-26LJAM-GSW","market_id":"abbbad28-f309-4dd5-af38-2ad7ebf2acc3","price_dollars":"0.0100","delta_fp":"1.00","side":"yes","ts":"2026-07-01T02:32:57.14515Z","ts_ms":1782873177145}}

{"type":"orderbook_delta","sid":1,"seq":542,"msg":{"market_ticker":"KXNEXTTEAMNBA-26LJAM-GSW","market_id":"abbbad28-f309-4dd5-af38-2ad7ebf2acc3","price_dollars":"0.0100","delta_fp":"1.00","side":"yes","ts":"2026-07-01T02:32:57.146272Z","ts_ms":1782873177146}}

{"type":"orderbook_delta","sid":1,"seq":543,"msg":{"market_ticker":"KXNEXTTEAMNBA-26LJAM-GSW","market_id":"abbbad28-f309-4dd5-af38-2ad7ebf2acc3","price_dollars":"0.0100","delta_fp":"1.00","side":"yes","ts":"2026-07-01T02:32:57.147323Z","ts_ms":1782873177147}}

{"type":"orderbook_delta","sid":1,"seq":544,"msg":{"market_ticker":"KXNEXTTEAMNBA-26LJAM-GSW","market_id":"abbbad28-f309-4dd5-af38-2ad7ebf2acc3","price_dollars":"0.0100","delta_fp":"1.00","side":"yes","ts":"2026-07-01T02:32:57.151261Z","ts_ms":1782873177151}}

{"type":"orderbook_delta","sid":1,"seq":545,"msg":{"market_ticker":"KXNEXTTEAMNBA-26LJAM-GSW","market_id":"abbbad28-f309-4dd5-af38-2ad7ebf2acc3","price_dollars":"0.0100","delta_fp":"1.00","side":"yes","ts":"2026-07-01T02:32:57.158644Z","ts_ms":1782873177158}}

{"type":"orderbook_delta","sid":1,"seq":546,"msg":{"market_ticker":"KXNEXTTEAMNBA-26LJAM-GSW","market_id":"abbbad28-f309-4dd5-af38-2ad7ebf2acc3","price_dollars":"0.0100","delta_fp":"1.00","side":"yes","ts":"2026-07-01T02:32:57.159398Z","ts_ms":1782873177159}}

{"type":"orderbook_delta","sid":1,"seq":547,"msg":{"market_ticker":"KXNEXTTEAMNBA-26LJAM-GSW","market_id":"abbbad28-f309-4dd5-af38-2ad7ebf2acc3","price_dollars":"0.0100","delta_fp":"1.00","side":"yes","ts":"2026-07-01T02:32:57.159886Z","ts_ms":1782873177159}}

{"type":"orderbook_delta","sid":1,"seq":548,"msg":{"market_ticker":"KXNEXTTEAMNBA-26LJAM-GSW","market_id":"abbbad28-f309-4dd5-af38-2ad7ebf2acc3","price_dollars":"0.0100","delta_fp":"1.00","side":"yes","ts":"2026-07-01T02:32:57.160305Z","ts_ms":1782873177160}}

{"type":"orderbook_delta","sid":1,"seq":549,"msg":{"market_ticker":"KXNEXTTEAMNBA-26LJAM-GSW","market_id":"abbbad28-f309-4dd5-af38-2ad7ebf2acc3","price_dollars":"0.0100","delta_fp":"1.00","side":"yes","ts":"2026-07-01T02:32:57.161111Z","ts_ms":1782873177161}}

{"type":"orderbook_delta","sid":1,"seq":550,"msg":{"market_ticker":"KXNEXTTEAMNBA-26LJAM-GSW","market_id":"abbbad28-f309-4dd5-af38-2ad7ebf2acc3","price_dollars":"0.0100","delta_fp":"1.00","side":"yes","ts":"2026-07-01T02:32:57.161762Z","ts_ms":1782873177161}}

{"type":"orderbook_delta","sid":1,"seq":551,"msg":{"market_ticker":"KXNEXTTEAMNBA-26LJAM-GSW","market_id":"abbbad28-f309-4dd5-af38-2ad7ebf2acc3","price_dollars":"0.0100","delta_fp":"1.00","side":"yes","ts":"2026-07-01T02:32:57.162401Z","ts_ms":1782873177162}}

{"type":"orderbook_delta","sid":1,"seq":552,"msg":{"market_ticker":"KXNEXTTEAMNBA-26LJAM-GSW","market_id":"abbbad28-f309-4dd5-af38-2ad7ebf2acc3","price_dollars":"0.0100","delta_fp":"1.00","side":"yes","ts":"2026-07-01T02:32:57.163081Z","ts_ms":1782873177163}}

{"type":"orderbook_delta","sid":1,"seq":553,"msg":{"market_ticker":"KXNEXTTEAMNBA-26LJAM-GSW","market_id":"abbbad28-f309-4dd5-af38-2ad7ebf2acc3","price_dollars":"0.0100","delta_fp":"1.00","side":"yes","ts":"2026-07-01T02:32:57.163682Z","ts_ms":1782873177163}}

{"type":"orderbook_delta","sid":1,"seq":554,"msg":{"market_ticker":"KXNEXTTEAMNBA-26LJAM-GSW","market_id":"abbbad28-f309-4dd5-af38-2ad7ebf2acc3","price_dollars":"0.0100","delta_fp":"1.00","side":"yes","ts":"2026-07-01T02:32:57.164226Z","ts_ms":1782873177164}}

{"type":"orderbook_delta","sid":1,"seq":555,"msg":{"market_ticker":"KXNEXTTEAMNBA-26LJAM-GSW","market_id":"abbbad28-f309-4dd5-af38-2ad7ebf2acc3","price_dollars":"0.0100","delta_fp":"1.00","side":"yes","ts":"2026-07-01T02:32:57.164781Z","ts_ms":1782873177164}}

{"type":"orderbook_delta","sid":1,"seq":556,"msg":{"market_ticker":"KXNEXTTEAMNBA-26LJAM-GSW","market_id":"abbbad28-f309-4dd5-af38-2ad7ebf2acc3","price_dollars":"0.0100","delta_fp":"1.00","side":"yes","ts":"2026-07-01T02:32:57.16531Z","ts_ms":1782873177165}}

{"type":"orderbook_delta","sid":1,"seq":557,"msg":{"market_ticker":"KXNEXTTEAMNBA-26LJAM-GSW","market_id":"abbbad28-f309-4dd5-af38-2ad7ebf2acc3","price_dollars":"0.0100","delta_fp":"1.00","side":"yes","ts":"2026-07-01T02:32:57.165696Z","ts_ms":1782873177165}}

{"type":"orderbook_delta","sid":1,"seq":558,"msg":{"market_ticker":"KXNEXTTEAMNBA-26LJAM-GSW","market_id":"abbbad28-f309-4dd5-af38-2ad7ebf2acc3","price_dollars":"0.0100","delta_fp":"1.00","side":"yes","ts":"2026-07-01T02:32:57.166046Z","ts_ms":1782873177166}}

{"type":"orderbook_delta","sid":1,"seq":559,"msg":{"market_ticker":"KXNEXTTEAMNBA-26LJAM-GSW","market_id":"abbbad28-f309-4dd5-af38-2ad7ebf2acc3","price_dollars":"0.0100","delta_fp":"1.00","side":"yes","ts":"2026-07-01T02:32:57.166356Z","ts_ms":1782873177166}}

{"type":"orderbook_delta","sid":1,"seq":560,"msg":{"market_ticker":"KXNEXTTEAMNBA-26LJAM-GSW","market_id":"abbbad28-f309-4dd5-af38-2ad7ebf2acc3","price_dollars":"0.0100","delta_fp":"1.00","side":"yes","ts":"2026-07-01T02:32:57.166621Z","ts_ms":1782873177166}}

{"type":"orderbook_delta","sid":1,"seq":561,"msg":{"market_ticker":"KXNEXTTEAMNBA-26LJAM-CLE","market_id":"7552b8d4-05de-4e41-84a8-97b0684da4a9","price_dollars":"0.7400","delta_fp":"-0.02","side":"no","ts":"2026-07-01T02:32:58.186153Z","ts_ms":1782873178186}}

{"type":"orderbook_delta","sid":1,"seq":562,"msg":{"market_ticker":"KXNEXTTEAMNBA-26LJAM-MIA","market_id":"492cb255-91da-4c91-bc9e-f83d090cc6dd","price_dollars":"0.0100","delta_fp":"1.00","side":"yes","ts":"2026-07-01T02:32:58.34083Z","ts_ms":1782873178340}}

{"type":"orderbook_delta","sid":1,"seq":563,"msg":{"market_ticker":"KXNEXTTEAMNBA-26LJAM-MIA","market_id":"492cb255-91da-4c91-bc9e-f83d090cc6dd","price_dollars":"0.0100","delta_fp":"1.00","side":"yes","ts":"2026-07-01T02:32:58.341502Z","ts_ms":1782873178341}}

{"type":"orderbook_delta","sid":1,"seq":564,"msg":{"market_ticker":"KXNEXTTEAMNBA-26LJAM-MIA","market_id":"492cb255-91da-4c91-bc9e-f83d090cc6dd","price_dollars":"0.0100","delta_fp":"1.00","side":"yes","ts":"2026-07-01T02:32:58.342125Z","ts_ms":1782873178342}}

{"type":"orderbook_delta","sid":1,"seq":565,"msg":{"market_ticker":"KXNEXTTEAMNBA-26LJAM-MIA","market_id":"492cb255-91da-4c91-bc9e-f83d090cc6dd","price_dollars":"0.0100","delta_fp":"1.00","side":"yes","ts":"2026-07-01T02:32:58.342704Z","ts_ms":1782873178342}}

{"type":"orderbook_delta","sid":1,"seq":566,"msg":{"market_ticker":"KXNEXTTEAMNBA-26LJAM-MIA","market_id":"492cb255-91da-4c91-bc9e-f83d090cc6dd","price_dollars":"0.0100","delta_fp":"1.00","side":"yes","ts":"2026-07-01T02:32:58.343346Z","ts_ms":1782873178343}}

{"type":"orderbook_delta","sid":1,"seq":567,"msg":{"market_ticker":"KXNEXTTEAMNBA-26LJAM-MIA","market_id":"492cb255-91da-4c91-bc9e-f83d090cc6dd","price_dollars":"0.0100","delta_fp":"1.00","side":"yes","ts":"2026-07-01T02:32:58.344028Z","ts_ms":1782873178344}}

{"type":"orderbook_delta","sid":1,"seq":568,"msg":{"market_ticker":"KXNEXTTEAMNBA-26LJAM-MIA","market_id":"492cb255-91da-4c91-bc9e-f83d090cc6dd","price_dollars":"0.0100","delta_fp":"1.00","side":"yes","ts":"2026-07-01T02:32:58.344574Z","ts_ms":1782873178344}}

{"type":"orderbook_delta","sid":1,"seq":569,"msg":{"market_ticker":"KXNEXTTEAMNBA-26LJAM-MIA","market_id":"492cb255-91da-4c91-bc9e-f83d090cc6dd","price_dollars":"0.0100","delta_fp":"1.00","side":"yes","ts":"2026-07-01T02:32:58.344987Z","ts_ms":1782873178344}}

{"type":"orderbook_delta","sid":1,"seq":570,"msg":{"market_ticker":"KXNEXTTEAMNBA-26LJAM-MIA","market_id":"492cb255-91da-4c91-bc9e-f83d090cc6dd","price_dollars":"0.0100","delta_fp":"1.00","side":"yes","ts":"2026-07-01T02:32:58.345457Z","ts_ms":1782873178345}}

{"type":"orderbook_delta","sid":1,"seq":571,"msg":{"market_ticker":"KXNEXTTEAMNBA-26LJAM-MIA","market_id":"492cb255-91da-4c91-bc9e-f83d090cc6dd","price_dollars":"0.0100","delta_fp":"1.00","side":"yes","ts":"2026-07-01T02:32:58.345865Z","ts_ms":1782873178345}}

{"type":"orderbook_delta","sid":1,"seq":572,"msg":{"market_ticker":"KXNEXTTEAMNBA-26LJAM-MIA","market_id":"492cb255-91da-4c91-bc9e-f83d090cc6dd","price_dollars":"0.0100","delta_fp":"1.00","side":"yes","ts":"2026-07-01T02:32:58.346283Z","ts_ms":1782873178346}}

{"type":"orderbook_delta","sid":1,"seq":573,"msg":{"market_ticker":"KXNEXTTEAMNBA-26LJAM-MIA","market_id":"492cb255-91da-4c91-bc9e-f83d090cc6dd","price_dollars":"0.0100","delta_fp":"1.00","side":"yes","ts":"2026-07-01T02:32:58.346644Z","ts_ms":1782873178346}}

{"type":"orderbook_delta","sid":1,"seq":574,"msg":{"market_ticker":"KXNEXTTEAMNBA-26LJAM-MIA","market_id":"492cb255-91da-4c91-bc9e-f83d090cc6dd","price_dollars":"0.0100","delta_fp":"1.00","side":"yes","ts":"2026-07-01T02:32:58.347155Z","ts_ms":1782873178347}}

{"type":"orderbook_delta","sid":1,"seq":575,"msg":{"market_ticker":"KXNEXTTEAMNBA-26LJAM-MIA","market_id":"492cb255-91da-4c91-bc9e-f83d090cc6dd","price_dollars":"0.0100","delta_fp":"1.00","side":"yes","ts":"2026-07-01T02:32:58.347618Z","ts_ms":1782873178347}}

{"type":"orderbook_delta","sid":1,"seq":576,"msg":{"market_ticker":"KXNEXTTEAMNBA-26LJAM-MIA","market_id":"492cb255-91da-4c91-bc9e-f83d090cc6dd","price_dollars":"0.0100","delta_fp":"1.00","side":"yes","ts":"2026-07-01T02:32:58.347929Z","ts_ms":1782873178347}}

{"type":"orderbook_delta","sid":1,"seq":577,"msg":{"market_ticker":"KXNEXTTEAMNBA-26LJAM-MIA","market_id":"492cb255-91da-4c91-bc9e-f83d090cc6dd","price_dollars":"0.0100","delta_fp":"1.00","side":"yes","ts":"2026-07-01T02:32:58.348389Z","ts_ms":1782873178348}}

{"type":"orderbook_delta","sid":1,"seq":578,"msg":{"market_ticker":"KXNEXTTEAMNBA-26LJAM-MIA","market_id":"492cb255-91da-4c91-bc9e-f83d090cc6dd","price_dollars":"0.0100","delta_fp":"1.00","side":"yes","ts":"2026-07-01T02:32:58.348761Z","ts_ms":1782873178348}}

{"type":"orderbook_delta","sid":1,"seq":579,"msg":{"market_ticker":"KXNEXTTEAMNBA-26LJAM-MIA","market_id":"492cb255-91da-4c91-bc9e-f83d090cc6dd","price_dollars":"0.0100","delta_fp":"1.00","side":"yes","ts":"2026-07-01T02:32:58.349221Z","ts_ms":1782873178349}}

{"type":"orderbook_delta","sid":1,"seq":580,"msg":{"market_ticker":"KXNEXTTEAMNBA-26LJAM-MIA","market_id":"492cb255-91da-4c91-bc9e-f83d090cc6dd","price_dollars":"0.0100","delta_fp":"1.00","side":"yes","ts":"2026-07-01T02:32:58.349613Z","ts_ms":1782873178349}}

{"type":"orderbook_delta","sid":1,"seq":581,"msg":{"market_ticker":"KXNEXTTEAMNBA-26LJAM-MIA","market_id":"492cb255-91da-4c91-bc9e-f83d090cc6dd","price_dollars":"0.0100","delta_fp":"1.00","side":"yes","ts":"2026-07-01T02:32:58.350145Z","ts_ms":1782873178350}}

{"type":"orderbook_delta","sid":1,"seq":582,"msg":{"market_ticker":"KXNEXTTEAMNBA-26LJAM-MIA","market_id":"492cb255-91da-4c91-bc9e-f83d090cc6dd","price_dollars":"0.8300","delta_fp":"-0.24","side":"no","ts":"2026-07-01T02:32:59.759715Z","ts_ms":1782873179759}}

{"type":"orderbook_delta","sid":1,"seq":583,"msg":{"market_ticker":"KXNEXTTEAMNBA-26LJAM-CLE","market_id":"7552b8d4-05de-4e41-84a8-97b0684da4a9","price_dollars":"0.7400","delta_fp":"-0.68","side":"no","ts":"2026-07-01T02:32:59.762257Z","ts_ms":1782873179762}}

{"type":"orderbook_delta","sid":1,"seq":584,"msg":{"market_ticker":"KXNEXTTEAMNBA-26LJAM-MIA","market_id":"492cb255-91da-4c91-bc9e-f83d090cc6dd","price_dollars":"0.8300","delta_fp":"-0.27","side":"no","ts":"2026-07-01T02:32:59.771104Z","ts_ms":1782873179771}}

{"type":"orderbook_delta","sid":1,"seq":585,"msg":{"market_ticker":"KXNEXTTEAMNBA-26LJAM-GSW","market_id":"abbbad28-f309-4dd5-af38-2ad7ebf2acc3","price_dollars":"0.5200","delta_fp":"-1.30","side":"no","ts":"2026-07-01T02:32:59.783262Z","ts_ms":1782873179783}}

{"type":"orderbook_delta","sid":1,"seq":586,"msg":{"market_ticker":"KXNEXTTEAMNBA-26LJAM-CLE","market_id":"7552b8d4-05de-4e41-84a8-97b0684da4a9","price_dollars":"0.7400","delta_fp":"-0.70","side":"no","ts":"2026-07-01T02:32:59.870255Z","ts_ms":1782873179870}}

{"type":"orderbook_delta","sid":1,"seq":587,"msg":{"market_ticker":"KXNEXTTEAMNBA-26LJAM-MIA","market_id":"492cb255-91da-4c91-bc9e-f83d090cc6dd","price_dollars":"0.0100","delta_fp":"-1.00","side":"yes","ts":"2026-07-01T02:33:00.761503Z","ts_ms":1782873180761}}

{"type":"orderbook_delta","sid":1,"seq":588,"msg":{"market_ticker":"KXNEXTTEAMNBA-26LJAM-MIA","market_id":"492cb255-91da-4c91-bc9e-f83d090cc6dd","price_dollars":"0.0100","delta_fp":"-1.00","side":"yes","ts":"2026-07-01T02:33:00.761874Z","ts_ms":1782873180761}}

{"type":"orderbook_delta","sid":1,"seq":589,"msg":{"market_ticker":"KXNEXTTEAMNBA-26LJAM-MIA","market_id":"492cb255-91da-4c91-bc9e-f83d090cc6dd","price_dollars":"0.0100","delta_fp":"-1.00","side":"yes","ts":"2026-07-01T02:33:00.762316Z","ts_ms":1782873180762}}

{"type":"orderbook_delta","sid":1,"seq":590,"msg":{"market_ticker":"KXNEXTTEAMNBA-26LJAM-MIA","market_id":"492cb255-91da-4c91-bc9e-f83d090cc6dd","price_dollars":"0.0100","delta_fp":"-1.00","side":"yes","ts":"2026-07-01T02:33:00.762694Z","ts_ms":1782873180762}}

{"type":"orderbook_delta","sid":1,"seq":591,"msg":{"market_ticker":"KXNEXTTEAMNBA-26LJAM-MIA","market_id":"492cb255-91da-4c91-bc9e-f83d090cc6dd","price_dollars":"0.0100","delta_fp":"-1.00","side":"yes","ts":"2026-07-01T02:33:00.763022Z","ts_ms":1782873180763}}

{"type":"orderbook_delta","sid":1,"seq":592,"msg":{"market_ticker":"KXNEXTTEAMNBA-26LJAM-MIA","market_id":"492cb255-91da-4c91-bc9e-f83d090cc6dd","price_dollars":"0.0100","delta_fp":"-1.00","side":"yes","ts":"2026-07-01T02:33:00.763346Z","ts_ms":1782873180763}}

{"type":"orderbook_delta","sid":1,"seq":593,"msg":{"market_ticker":"KXNEXTTEAMNBA-26LJAM-MIA","market_id":"492cb255-91da-4c91-bc9e-f83d090cc6dd","price_dollars":"0.0100","delta_fp":"-1.00","side":"yes","ts":"2026-07-01T02:33:00.763719Z","ts_ms":1782873180763}}

{"type":"orderbook_delta","sid":1,"seq":594,"msg":{"market_ticker":"KXNEXTTEAMNBA-26LJAM-MIA","market_id":"492cb255-91da-4c91-bc9e-f83d090cc6dd","price_dollars":"0.0100","delta_fp":"-1.00","side":"yes","ts":"2026-07-01T02:33:00.764091Z","ts_ms":1782873180764}}

{"type":"orderbook_delta","sid":1,"seq":595,"msg":{"market_ticker":"KXNEXTTEAMNBA-26LJAM-MIA","market_id":"492cb255-91da-4c91-bc9e-f83d090cc6dd","price_dollars":"0.0100","delta_fp":"-1.00","side":"yes","ts":"2026-07-01T02:33:00.764527Z","ts_ms":1782873180764}}

{"type":"orderbook_delta","sid":1,"seq":596,"msg":{"market_ticker":"KXNEXTTEAMNBA-26LJAM-MIA","market_id":"492cb255-91da-4c91-bc9e-f83d090cc6dd","price_dollars":"0.0100","delta_fp":"-1.00","side":"yes","ts":"2026-07-01T02:33:00.764922Z","ts_ms":1782873180764}}

{"type":"orderbook_delta","sid":1,"seq":597,"msg":{"market_ticker":"KXNEXTTEAMNBA-26LJAM-MIA","market_id":"492cb255-91da-4c91-bc9e-f83d090cc6dd","price_dollars":"0.0100","delta_fp":"-1.00","side":"yes","ts":"2026-07-01T02:33:00.765272Z","ts_ms":1782873180765}}

{"type":"orderbook_delta","sid":1,"seq":598,"msg":{"market_ticker":"KXNEXTTEAMNBA-26LJAM-MIA","market_id":"492cb255-91da-4c91-bc9e-f83d090cc6dd","price_dollars":"0.0100","delta_fp":"-1.00","side":"yes","ts":"2026-07-01T02:33:00.765585Z","ts_ms":1782873180765}}

{"type":"orderbook_delta","sid":1,"seq":599,"msg":{"market_ticker":"KXNEXTTEAMNBA-26LJAM-MIA","market_id":"492cb255-91da-4c91-bc9e-f83d090cc6dd","price_dollars":"0.0100","delta_fp":"-1.00","side":"yes","ts":"2026-07-01T02:33:00.765871Z","ts_ms":1782873180765}}

{"type":"orderbook_delta","sid":1,"seq":600,"msg":{"market_ticker":"KXNEXTTEAMNBA-26LJAM-MIA","market_id":"492cb255-91da-4c91-bc9e-f83d090cc6dd","price_dollars":"0.0100","delta_fp":"-1.00","side":"yes","ts":"2026-07-01T02:33:00.76634Z","ts_ms":1782873180766}}

{"type":"orderbook_delta","sid":1,"seq":601,"msg":{"market_ticker":"KXNEXTTEAMNBA-26LJAM-MIA","market_id":"492cb255-91da-4c91-bc9e-f83d090cc6dd","price_dollars":"0.0100","delta_fp":"-1.00","side":"yes","ts":"2026-07-01T02:33:00.766696Z","ts_ms":1782873180766}}

{"type":"orderbook_delta","sid":1,"seq":602,"msg":{"market_ticker":"KXNEXTTEAMNBA-26LJAM-MIA","market_id":"492cb255-91da-4c91-bc9e-f83d090cc6dd","price_dollars":"0.0100","delta_fp":"-1.00","side":"yes","ts":"2026-07-01T02:33:00.767031Z","ts_ms":1782873180767}}

{"type":"orderbook_delta","sid":1,"seq":603,"msg":{"market_ticker":"KXNEXTTEAMNBA-26LJAM-MIA","market_id":"492cb255-91da-4c91-bc9e-f83d090cc6dd","price_dollars":"0.0100","delta_fp":"-1.00","side":"yes","ts":"2026-07-01T02:33:00.76743Z","ts_ms":1782873180767}}

{"type":"orderbook_delta","sid":1,"seq":604,"msg":{"market_ticker":"KXNEXTTEAMNBA-26LJAM-MIA","market_id":"492cb255-91da-4c91-bc9e-f83d090cc6dd","price_dollars":"0.0100","delta_fp":"-1.00","side":"yes","ts":"2026-07-01T02:33:00.767719Z","ts_ms":1782873180767}}

{"type":"orderbook_delta","sid":1,"seq":605,"msg":{"market_ticker":"KXNEXTTEAMNBA-26LJAM-MIA","market_id":"492cb255-91da-4c91-bc9e-f83d090cc6dd","price_dollars":"0.0100","delta_fp":"-1.00","side":"yes","ts":"2026-07-01T02:33:00.76808Z","ts_ms":1782873180768}}

{"type":"orderbook_delta","sid":1,"seq":606,"msg":{"market_ticker":"KXNEXTTEAMNBA-26LJAM-MIA","market_id":"492cb255-91da-4c91-bc9e-f83d090cc6dd","price_dollars":"0.0100","delta_fp":"-1.00","side":"yes","ts":"2026-07-01T02:33:00.76838Z","ts_ms":1782873180768}}

{"type":"orderbook_delta","sid":1,"seq":607,"msg":{"market_ticker":"KXNEXTTEAMNBA-26LJAM-GSW","market_id":"abbbad28-f309-4dd5-af38-2ad7ebf2acc3","price_dollars":"0.5200","delta_fp":"-1.79","side":"no","ts":"2026-07-01T02:33:01.465476Z","ts_ms":1782873181465}}

{"type":"orderbook_delta","sid":1,"seq":608,"msg":{"market_ticker":"KXNEXTTEAMNBA-26LJAM-GSW","market_id":"abbbad28-f309-4dd5-af38-2ad7ebf2acc3","price_dollars":"0.5200","delta_fp":"-1.83","side":"no","ts":"2026-07-01T02:33:03.066238Z","ts_ms":1782873183066}}

{"type":"orderbook_delta","sid":1,"seq":609,"msg":{"market_ticker":"KXNEXTTEAMNBA-26LJAM-GSW","market_id":"abbbad28-f309-4dd5-af38-2ad7ebf2acc3","price_dollars":"0.5200","delta_fp":"-1.17","side":"no","ts":"2026-07-01T02:33:03.076441Z","ts_ms":1782873183076}}

{"type":"orderbook_delta","sid":1,"seq":610,"msg":{"market_ticker":"KXNEXTTEAMNBA-26LJAM-GSW","market_id":"abbbad28-f309-4dd5-af38-2ad7ebf2acc3","price_dollars":"0.0100","delta_fp":"1.00","side":"yes","ts":"2026-07-01T02:33:04.122823Z","ts_ms":1782873184122}}

{"type":"orderbook_delta","sid":1,"seq":611,"msg":{"market_ticker":"KXNEXTTEAMNBA-26LJAM-GSW","market_id":"abbbad28-f309-4dd5-af38-2ad7ebf2acc3","price_dollars":"0.0100","delta_fp":"1.00","side":"yes","ts":"2026-07-01T02:33:04.123375Z","ts_ms":1782873184123}}

{"type":"orderbook_delta","sid":1,"seq":612,"msg":{"market_ticker":"KXNEXTTEAMNBA-26LJAM-GSW","market_id":"abbbad28-f309-4dd5-af38-2ad7ebf2acc3","price_dollars":"0.0100","delta_fp":"1.00","side":"yes","ts":"2026-07-01T02:33:04.123914Z","ts_ms":1782873184123}}

{"type":"orderbook_delta","sid":1,"seq":613,"msg":{"market_ticker":"KXNEXTTEAMNBA-26LJAM-GSW","market_id":"abbbad28-f309-4dd5-af38-2ad7ebf2acc3","price_dollars":"0.0100","delta_fp":"1.00","side":"yes","ts":"2026-07-01T02:33:04.1246Z","ts_ms":1782873184124}}

{"type":"orderbook_delta","sid":1,"seq":614,"msg":{"market_ticker":"KXNEXTTEAMNBA-26LJAM-GSW","market_id":"abbbad28-f309-4dd5-af38-2ad7ebf2acc3","price_dollars":"0.0100","delta_fp":"1.00","side":"yes","ts":"2026-07-01T02:33:04.125191Z","ts_ms":1782873184125}}

{"type":"orderbook_delta","sid":1,"seq":615,"msg":{"market_ticker":"KXNEXTTEAMNBA-26LJAM-GSW","market_id":"abbbad28-f309-4dd5-af38-2ad7ebf2acc3","price_dollars":"0.0100","delta_fp":"1.00","side":"yes","ts":"2026-07-01T02:33:04.125651Z","ts_ms":1782873184125}}

{"type":"orderbook_delta","sid":1,"seq":616,"msg":{"market_ticker":"KXNEXTTEAMNBA-26LJAM-GSW","market_id":"abbbad28-f309-4dd5-af38-2ad7ebf2acc3","price_dollars":"0.0100","delta_fp":"1.00","side":"yes","ts":"2026-07-01T02:33:04.126116Z","ts_ms":1782873184126}}

{"type":"orderbook_delta","sid":1,"seq":617,"msg":{"market_ticker":"KXNEXTTEAMNBA-26LJAM-GSW","market_id":"abbbad28-f309-4dd5-af38-2ad7ebf2acc3","price_dollars":"0.0100","delta_fp":"1.00","side":"yes","ts":"2026-07-01T02:33:04.126749Z","ts_ms":1782873184126}}

{"type":"orderbook_delta","sid":1,"seq":618,"msg":{"market_ticker":"KXNEXTTEAMNBA-26LJAM-GSW","market_id":"abbbad28-f309-4dd5-af38-2ad7ebf2acc3","price_dollars":"0.0100","delta_fp":"1.00","side":"yes","ts":"2026-07-01T02:33:04.127335Z","ts_ms":1782873184127}}

{"type":"orderbook_delta","sid":1,"seq":619,"msg":{"market_ticker":"KXNEXTTEAMNBA-26LJAM-GSW","market_id":"abbbad28-f309-4dd5-af38-2ad7ebf2acc3","price_dollars":"0.0100","delta_fp":"1.00","side":"yes","ts":"2026-07-01T02:33:04.127795Z","ts_ms":1782873184127}}

{"type":"orderbook_delta","sid":1,"seq":620,"msg":{"market_ticker":"KXNEXTTEAMNBA-26LJAM-GSW","market_id":"abbbad28-f309-4dd5-af38-2ad7ebf2acc3","price_dollars":"0.0100","delta_fp":"1.00","side":"yes","ts":"2026-07-01T02:33:04.128183Z","ts_ms":1782873184128}}

{"type":"orderbook_delta","sid":1,"seq":621,"msg":{"market_ticker":"KXNEXTTEAMNBA-26LJAM-GSW","market_id":"abbbad28-f309-4dd5-af38-2ad7ebf2acc3","price_dollars":"0.0100","delta_fp":"1.00","side":"yes","ts":"2026-07-01T02:33:04.128593Z","ts_ms":1782873184128}}

{"type":"orderbook_delta","sid":1,"seq":622,"msg":{"market_ticker":"KXNEXTTEAMNBA-26LJAM-GSW","market_id":"abbbad28-f309-4dd5-af38-2ad7ebf2acc3","price_dollars":"0.0100","delta_fp":"1.00","side":"yes","ts":"2026-07-01T02:33:04.12901Z","ts_ms":1782873184129}}

{"type":"orderbook_delta","sid":1,"seq":623,"msg":{"market_ticker":"KXNEXTTEAMNBA-26LJAM-GSW","market_id":"abbbad28-f309-4dd5-af38-2ad7ebf2acc3","price_dollars":"0.0100","delta_fp":"1.00","side":"yes","ts":"2026-07-01T02:33:04.129422Z","ts_ms":1782873184129}}

{"type":"orderbook_delta","sid":1,"seq":624,"msg":{"market_ticker":"KXNEXTTEAMNBA-26LJAM-GSW","market_id":"abbbad28-f309-4dd5-af38-2ad7ebf2acc3","price_dollars":"0.0100","delta_fp":"1.00","side":"yes","ts":"2026-07-01T02:33:04.129848Z","ts_ms":1782873184129}}

{"type":"orderbook_delta","sid":1,"seq":625,"msg":{"market_ticker":"KXNEXTTEAMNBA-26LJAM-GSW","market_id":"abbbad28-f309-4dd5-af38-2ad7ebf2acc3","price_dollars":"0.0100","delta_fp":"1.00","side":"yes","ts":"2026-07-01T02:33:04.130109Z","ts_ms":1782873184130}}

{"type":"orderbook_delta","sid":1,"seq":626,"msg":{"market_ticker":"KXNEXTTEAMNBA-26LJAM-GSW","market_id":"abbbad28-f309-4dd5-af38-2ad7ebf2acc3","price_dollars":"0.0100","delta_fp":"1.00","side":"yes","ts":"2026-07-01T02:33:04.130373Z","ts_ms":1782873184130}}

{"type":"orderbook_delta","sid":1,"seq":627,"msg":{"market_ticker":"KXNEXTTEAMNBA-26LJAM-GSW","market_id":"abbbad28-f309-4dd5-af38-2ad7ebf2acc3","price_dollars":"0.0100","delta_fp":"1.00","side":"yes","ts":"2026-07-01T02:33:04.130796Z","ts_ms":1782873184130}}

{"type":"orderbook_delta","sid":1,"seq":628,"msg":{"market_ticker":"KXNEXTTEAMNBA-26LJAM-GSW","market_id":"abbbad28-f309-4dd5-af38-2ad7ebf2acc3","price_dollars":"0.0100","delta_fp":"1.00","side":"yes","ts":"2026-07-01T02:33:04.131063Z","ts_ms":1782873184131}}

{"type":"orderbook_delta","sid":1,"seq":629,"msg":{"market_ticker":"KXNEXTTEAMNBA-26LJAM-GSW","market_id":"abbbad28-f309-4dd5-af38-2ad7ebf2acc3","price_dollars":"0.0100","delta_fp":"1.00","side":"yes","ts":"2026-07-01T02:33:04.131423Z","ts_ms":1782873184131}}

{"type":"orderbook_delta","sid":1,"seq":630,"msg":{"market_ticker":"KXNEXTTEAMNBA-26LJAM-MIA","market_id":"492cb255-91da-4c91-bc9e-f83d090cc6dd","price_dollars":"0.0100","delta_fp":"1.00","side":"yes","ts":"2026-07-01T02:33:05.345399Z","ts_ms":1782873185345}}

{"type":"orderbook_delta","sid":1,"seq":631,"msg":{"market_ticker":"KXNEXTTEAMNBA-26LJAM-MIA","market_id":"492cb255-91da-4c91-bc9e-f83d090cc6dd","price_dollars":"0.0100","delta_fp":"1.00","side":"yes","ts":"2026-07-01T02:33:05.345764Z","ts_ms":1782873185345}}

{"type":"orderbook_delta","sid":1,"seq":632,"msg":{"market_ticker":"KXNEXTTEAMNBA-26LJAM-MIA","market_id":"492cb255-91da-4c91-bc9e-f83d090cc6dd","price_dollars":"0.0100","delta_fp":"1.00","side":"yes","ts":"2026-07-01T02:33:05.346108Z","ts_ms":1782873185346}}

{"type":"orderbook_delta","sid":1,"seq":633,"msg":{"market_ticker":"KXNEXTTEAMNBA-26LJAM-MIA","market_id":"492cb255-91da-4c91-bc9e-f83d090cc6dd","price_dollars":"0.0100","delta_fp":"1.00","side":"yes","ts":"2026-07-01T02:33:05.346667Z","ts_ms":1782873185346}}

{"type":"orderbook_delta","sid":1,"seq":634,"msg":{"market_ticker":"KXNEXTTEAMNBA-26LJAM-MIA","market_id":"492cb255-91da-4c91-bc9e-f83d090cc6dd","price_dollars":"0.0100","delta_fp":"1.00","side":"yes","ts":"2026-07-01T02:33:05.347157Z","ts_ms":1782873185347}}

{"type":"orderbook_delta","sid":1,"seq":635,"msg":{"market_ticker":"KXNEXTTEAMNBA-26LJAM-MIA","market_id":"492cb255-91da-4c91-bc9e-f83d090cc6dd","price_dollars":"0.0100","delta_fp":"1.00","side":"yes","ts":"2026-07-01T02:33:05.347527Z","ts_ms":1782873185347}}

{"type":"orderbook_delta","sid":1,"seq":636,"msg":{"market_ticker":"KXNEXTTEAMNBA-26LJAM-MIA","market_id":"492cb255-91da-4c91-bc9e-f83d090cc6dd","price_dollars":"0.0100","delta_fp":"1.00","side":"yes","ts":"2026-07-01T02:33:05.347899Z","ts_ms":1782873185347}}

{"type":"orderbook_delta","sid":1,"seq":637,"msg":{"market_ticker":"KXNEXTTEAMNBA-26LJAM-MIA","market_id":"492cb255-91da-4c91-bc9e-f83d090cc6dd","price_dollars":"0.0100","delta_fp":"1.00","side":"yes","ts":"2026-07-01T02:33:05.34838Z","ts_ms":1782873185348}}

{"type":"orderbook_delta","sid":1,"seq":638,"msg":{"market_ticker":"KXNEXTTEAMNBA-26LJAM-MIA","market_id":"492cb255-91da-4c91-bc9e-f83d090cc6dd","price_dollars":"0.0100","delta_fp":"1.00","side":"yes","ts":"2026-07-01T02:33:05.348971Z","ts_ms":1782873185348}}

{"type":"orderbook_delta","sid":1,"seq":639,"msg":{"market_ticker":"KXNEXTTEAMNBA-26LJAM-MIA","market_id":"492cb255-91da-4c91-bc9e-f83d090cc6dd","price_dollars":"0.0100","delta_fp":"1.00","side":"yes","ts":"2026-07-01T02:33:05.349771Z","ts_ms":1782873185349}}

{"type":"orderbook_delta","sid":1,"seq":640,"msg":{"market_ticker":"KXNEXTTEAMNBA-26LJAM-MIA","market_id":"492cb255-91da-4c91-bc9e-f83d090cc6dd","price_dollars":"0.0100","delta_fp":"1.00","side":"yes","ts":"2026-07-01T02:33:05.350227Z","ts_ms":1782873185350}}

{"type":"orderbook_delta","sid":1,"seq":641,"msg":{"market_ticker":"KXNEXTTEAMNBA-26LJAM-MIA","market_id":"492cb255-91da-4c91-bc9e-f83d090cc6dd","price_dollars":"0.0100","delta_fp":"1.00","side":"yes","ts":"2026-07-01T02:33:05.350957Z","ts_ms":1782873185350}}

{"type":"orderbook_delta","sid":1,"seq":642,"msg":{"market_ticker":"KXNEXTTEAMNBA-26LJAM-MIA","market_id":"492cb255-91da-4c91-bc9e-f83d090cc6dd","price_dollars":"0.0100","delta_fp":"1.00","side":"yes","ts":"2026-07-01T02:33:05.351395Z","ts_ms":1782873185351}}

{"type":"orderbook_delta","sid":1,"seq":643,"msg":{"market_ticker":"KXNEXTTEAMNBA-26LJAM-MIA","market_id":"492cb255-91da-4c91-bc9e-f83d090cc6dd","price_dollars":"0.0100","delta_fp":"1.00","side":"yes","ts":"2026-07-01T02:33:05.351825Z","ts_ms":1782873185351}}

{"type":"orderbook_delta","sid":1,"seq":644,"msg":{"market_ticker":"KXNEXTTEAMNBA-26LJAM-MIA","market_id":"492cb255-91da-4c91-bc9e-f83d090cc6dd","price_dollars":"0.0100","delta_fp":"1.00","side":"yes","ts":"2026-07-01T02:33:05.352224Z","ts_ms":1782873185352}}

{"type":"orderbook_delta","sid":1,"seq":645,"msg":{"market_ticker":"KXNEXTTEAMNBA-26LJAM-MIA","market_id":"492cb255-91da-4c91-bc9e-f83d090cc6dd","price_dollars":"0.0100","delta_fp":"1.00","side":"yes","ts":"2026-07-01T02:33:05.352655Z","ts_ms":1782873185352}}

{"type":"orderbook_delta","sid":1,"seq":646,"msg":{"market_ticker":"KXNEXTTEAMNBA-26LJAM-MIA","market_id":"492cb255-91da-4c91-bc9e-f83d090cc6dd","price_dollars":"0.0100","delta_fp":"1.00","side":"yes","ts":"2026-07-01T02:33:05.35315Z","ts_ms":1782873185353}}

{"type":"orderbook_delta","sid":1,"seq":647,"msg":{"market_ticker":"KXNEXTTEAMNBA-26LJAM-MIA","market_id":"492cb255-91da-4c91-bc9e-f83d090cc6dd","price_dollars":"0.0100","delta_fp":"1.00","side":"yes","ts":"2026-07-01T02:33:05.353513Z","ts_ms":1782873185353}}

{"type":"orderbook_delta","sid":1,"seq":648,"msg":{"market_ticker":"KXNEXTTEAMNBA-26LJAM-MIA","market_id":"492cb255-91da-4c91-bc9e-f83d090cc6dd","price_dollars":"0.0100","delta_fp":"1.00","side":"yes","ts":"2026-07-01T02:33:05.353816Z","ts_ms":1782873185353}}

{"type":"orderbook_delta","sid":1,"seq":649,"msg":{"market_ticker":"KXNEXTTEAMNBA-26LJAM-MIA","market_id":"492cb255-91da-4c91-bc9e-f83d090cc6dd","price_dollars":"0.0100","delta_fp":"1.00","side":"yes","ts":"2026-07-01T02:33:05.354212Z","ts_ms":1782873185354}}

{"type":"orderbook_delta","sid":1,"seq":650,"msg":{"market_ticker":"KXNEXTTEAMNBA-26LJAM-GSW","market_id":"abbbad28-f309-4dd5-af38-2ad7ebf2acc3","price_dollars":"0.5200","delta_fp":"-0.59","side":"no","ts":"2026-07-01T02:33:06.37527Z","ts_ms":1782873186375}}

{"type":"orderbook_delta","sid":1,"seq":651,"msg":{"market_ticker":"KXNEXTTEAMNBA-26LJAM-MIA","market_id":"492cb255-91da-4c91-bc9e-f83d090cc6dd","price_dollars":"0.8300","delta_fp":"-1.02","side":"no","ts":"2026-07-01T02:33:06.375475Z","ts_ms":1782873186375}}

{"type":"orderbook_delta","sid":1,"seq":652,"msg":{"market_ticker":"KXNEXTTEAMNBA-26LJAM-GSW","market_id":"abbbad28-f309-4dd5-af38-2ad7ebf2acc3","price_dollars":"0.5200","delta_fp":"-1.38","side":"no","ts":"2026-07-01T02:33:06.418653Z","ts_ms":1782873186418}}

{"type":"orderbook_delta","sid":1,"seq":653,"msg":{"market_ticker":"KXNEXTTEAMNBA-26LJAM-GSW","market_id":"abbbad28-f309-4dd5-af38-2ad7ebf2acc3","price_dollars":"0.0100","delta_fp":"-1.00","side":"yes","ts":"2026-07-01T02:33:06.670556Z","ts_ms":1782873186670}}

{"type":"orderbook_delta","sid":1,"seq":654,"msg":{"market_ticker":"KXNEXTTEAMNBA-26LJAM-GSW","market_id":"abbbad28-f309-4dd5-af38-2ad7ebf2acc3","price_dollars":"0.0100","delta_fp":"-1.00","side":"yes","ts":"2026-07-01T02:33:06.670556Z","ts_ms":1782873186670}}

{"type":"orderbook_delta","sid":1,"seq":655,"msg":{"market_ticker":"KXNEXTTEAMNBA-26LJAM-GSW","market_id":"abbbad28-f309-4dd5-af38-2ad7ebf2acc3","price_dollars":"0.0100","delta_fp":"-1.00","side":"yes","ts":"2026-07-01T02:33:06.670556Z","ts_ms":1782873186670}}

{"type":"orderbook_delta","sid":1,"seq":656,"msg":{"market_ticker":"KXNEXTTEAMNBA-26LJAM-GSW","market_id":"abbbad28-f309-4dd5-af38-2ad7ebf2acc3","price_dollars":"0.0100","delta_fp":"-1.00","side":"yes","ts":"2026-07-01T02:33:06.670556Z","ts_ms":1782873186670}}

{"type":"orderbook_delta","sid":1,"seq":657,"msg":{"market_ticker":"KXNEXTTEAMNBA-26LJAM-GSW","market_id":"abbbad28-f309-4dd5-af38-2ad7ebf2acc3","price_dollars":"0.0100","delta_fp":"-1.00","side":"yes","ts":"2026-07-01T02:33:06.670556Z","ts_ms":1782873186670}}

{"type":"orderbook_delta","sid":1,"seq":658,"msg":{"market_ticker":"KXNEXTTEAMNBA-26LJAM-GSW","market_id":"abbbad28-f309-4dd5-af38-2ad7ebf2acc3","price_dollars":"0.0100","delta_fp":"-1.00","side":"yes","ts":"2026-07-01T02:33:06.670556Z","ts_ms":1782873186670}}

{"type":"orderbook_delta","sid":1,"seq":659,"msg":{"market_ticker":"KXNEXTTEAMNBA-26LJAM-GSW","market_id":"abbbad28-f309-4dd5-af38-2ad7ebf2acc3","price_dollars":"0.0100","delta_fp":"-1.00","side":"yes","ts":"2026-07-01T02:33:06.670556Z","ts_ms":1782873186670}}

{"type":"orderbook_delta","sid":1,"seq":660,"msg":{"market_ticker":"KXNEXTTEAMNBA-26LJAM-GSW","market_id":"abbbad28-f309-4dd5-af38-2ad7ebf2acc3","price_dollars":"0.0100","delta_fp":"-1.00","side":"yes","ts":"2026-07-01T02:33:06.670556Z","ts_ms":1782873186670}}

{"type":"orderbook_delta","sid":1,"seq":661,"msg":{"market_ticker":"KXNEXTTEAMNBA-26LJAM-GSW","market_id":"abbbad28-f309-4dd5-af38-2ad7ebf2acc3","price_dollars":"0.0100","delta_fp":"-1.00","side":"yes","ts":"2026-07-01T02:33:06.670556Z","ts_ms":1782873186670}}

{"type":"orderbook_delta","sid":1,"seq":662,"msg":{"market_ticker":"KXNEXTTEAMNBA-26LJAM-GSW","market_id":"abbbad28-f309-4dd5-af38-2ad7ebf2acc3","price_dollars":"0.0100","delta_fp":"-1.00","side":"yes","ts":"2026-07-01T02:33:06.670556Z","ts_ms":1782873186670}}

{"type":"orderbook_delta","sid":1,"seq":663,"msg":{"market_ticker":"KXNEXTTEAMNBA-26LJAM-GSW","market_id":"abbbad28-f309-4dd5-af38-2ad7ebf2acc3","price_dollars":"0.0100","delta_fp":"-1.00","side":"yes","ts":"2026-07-01T02:33:06.670556Z","ts_ms":1782873186670}}

{"type":"orderbook_delta","sid":1,"seq":664,"msg":{"market_ticker":"KXNEXTTEAMNBA-26LJAM-GSW","market_id":"abbbad28-f309-4dd5-af38-2ad7ebf2acc3","price_dollars":"0.0100","delta_fp":"-1.00","side":"yes","ts":"2026-07-01T02:33:06.670556Z","ts_ms":1782873186670}}

{"type":"orderbook_delta","sid":1,"seq":665,"msg":{"market_ticker":"KXNEXTTEAMNBA-26LJAM-GSW","market_id":"abbbad28-f309-4dd5-af38-2ad7ebf2acc3","price_dollars":"0.0100","delta_fp":"-1.00","side":"yes","ts":"2026-07-01T02:33:06.670556Z","ts_ms":1782873186670}}

{"type":"orderbook_delta","sid":1,"seq":666,"msg":{"market_ticker":"KXNEXTTEAMNBA-26LJAM-GSW","market_id":"abbbad28-f309-4dd5-af38-2ad7ebf2acc3","price_dollars":"0.0100","delta_fp":"-1.00","side":"yes","ts":"2026-07-01T02:33:06.670556Z","ts_ms":1782873186670}}

{"type":"orderbook_delta","sid":1,"seq":667,"msg":{"market_ticker":"KXNEXTTEAMNBA-26LJAM-GSW","market_id":"abbbad28-f309-4dd5-af38-2ad7ebf2acc3","price_dollars":"0.0100","delta_fp":"-1.00","side":"yes","ts":"2026-07-01T02:33:06.670556Z","ts_ms":1782873186670}}

{"type":"orderbook_delta","sid":1,"seq":668,"msg":{"market_ticker":"KXNEXTTEAMNBA-26LJAM-GSW","market_id":"abbbad28-f309-4dd5-af38-2ad7ebf2acc3","price_dollars":"0.0100","delta_fp":"-1.00","side":"yes","ts":"2026-07-01T02:33:06.670556Z","ts_ms":1782873186670}}

{"type":"orderbook_delta","sid":1,"seq":669,"msg":{"market_ticker":"KXNEXTTEAMNBA-26LJAM-GSW","market_id":"abbbad28-f309-4dd5-af38-2ad7ebf2acc3","price_dollars":"0.0100","delta_fp":"-1.00","side":"yes","ts":"2026-07-01T02:33:06.670556Z","ts_ms":1782873186670}}

{"type":"orderbook_delta","sid":1,"seq":670,"msg":{"market_ticker":"KXNEXTTEAMNBA-26LJAM-GSW","market_id":"abbbad28-f309-4dd5-af38-2ad7ebf2acc3","price_dollars":"0.0100","delta_fp":"-1.00","side":"yes","ts":"2026-07-01T02:33:06.670556Z","ts_ms":1782873186670}}

{"type":"orderbook_delta","sid":1,"seq":671,"msg":{"market_ticker":"KXNEXTTEAMNBA-26LJAM-GSW","market_id":"abbbad28-f309-4dd5-af38-2ad7ebf2acc3","price_dollars":"0.0100","delta_fp":"-1.00","side":"yes","ts":"2026-07-01T02:33:06.670556Z","ts_ms":1782873186670}}

{"type":"orderbook_delta","sid":1,"seq":672,"msg":{"market_ticker":"KXNEXTTEAMNBA-26LJAM-GSW","market_id":"abbbad28-f309-4dd5-af38-2ad7ebf2acc3","price_dollars":"0.0100","delta_fp":"-1.00","side":"yes","ts":"2026-07-01T02:33:06.670556Z","ts_ms":1782873186670}}

{"type":"orderbook_delta","sid":1,"seq":673,"msg":{"market_ticker":"KXNEXTTEAMNBA-26LJAM-GSW","market_id":"abbbad28-f309-4dd5-af38-2ad7ebf2acc3","price_dollars":"0.0100","delta_fp":"-1.00","side":"yes","ts":"2026-07-01T02:33:06.670556Z","ts_ms":1782873186670}}

{"type":"orderbook_delta","sid":1,"seq":674,"msg":{"market_ticker":"KXNEXTTEAMNBA-26LJAM-GSW","market_id":"abbbad28-f309-4dd5-af38-2ad7ebf2acc3","price_dollars":"0.0100","delta_fp":"-1.00","side":"yes","ts":"2026-07-01T02:33:06.670556Z","ts_ms":1782873186670}}

{"type":"orderbook_delta","sid":1,"seq":675,"msg":{"market_ticker":"KXNEXTTEAMNBA-26LJAM-GSW","market_id":"abbbad28-f309-4dd5-af38-2ad7ebf2acc3","price_dollars":"0.0100","delta_fp":"-1.00","side":"yes","ts":"2026-07-01T02:33:06.670556Z","ts_ms":1782873186670}}

{"type":"orderbook_delta","sid":1,"seq":676,"msg":{"market_ticker":"KXNEXTTEAMNBA-26LJAM-GSW","market_id":"abbbad28-f309-4dd5-af38-2ad7ebf2acc3","price_dollars":"0.0100","delta_fp":"-1.00","side":"yes","ts":"2026-07-01T02:33:06.670556Z","ts_ms":1782873186670}}

{"type":"orderbook_delta","sid":1,"seq":677,"msg":{"market_ticker":"KXNEXTTEAMNBA-26LJAM-GSW","market_id":"abbbad28-f309-4dd5-af38-2ad7ebf2acc3","price_dollars":"0.0100","delta_fp":"-1.00","side":"yes","ts":"2026-07-01T02:33:06.670556Z","ts_ms":1782873186670}}

{"type":"orderbook_delta","sid":1,"seq":678,"msg":{"market_ticker":"KXNEXTTEAMNBA-26LJAM-GSW","market_id":"abbbad28-f309-4dd5-af38-2ad7ebf2acc3","price_dollars":"0.0100","delta_fp":"-1.00","side":"yes","ts":"2026-07-01T02:33:06.670556Z","ts_ms":1782873186670}}

{"type":"orderbook_delta","sid":1,"seq":679,"msg":{"market_ticker":"KXNEXTTEAMNBA-26LJAM-GSW","market_id":"abbbad28-f309-4dd5-af38-2ad7ebf2acc3","price_dollars":"0.0100","delta_fp":"-1.00","side":"yes","ts":"2026-07-01T02:33:06.670556Z","ts_ms":1782873186670}}

{"type":"orderbook_delta","sid":1,"seq":680,"msg":{"market_ticker":"KXNEXTTEAMNBA-26LJAM-GSW","market_id":"abbbad28-f309-4dd5-af38-2ad7ebf2acc3","price_dollars":"0.0100","delta_fp":"-1.00","side":"yes","ts":"2026-07-01T02:33:06.670556Z","ts_ms":1782873186670}}

{"type":"orderbook_delta","sid":1,"seq":681,"msg":{"market_ticker":"KXNEXTTEAMNBA-26LJAM-GSW","market_id":"abbbad28-f309-4dd5-af38-2ad7ebf2acc3","price_dollars":"0.0100","delta_fp":"-1.00","side":"yes","ts":"2026-07-01T02:33:06.670556Z","ts_ms":1782873186670}}

{"type":"orderbook_delta","sid":1,"seq":682,"msg":{"market_ticker":"KXNEXTTEAMNBA-26LJAM-GSW","market_id":"abbbad28-f309-4dd5-af38-2ad7ebf2acc3","price_dollars":"0.0100","delta_fp":"-1.00","side":"yes","ts":"2026-07-01T02:33:06.670556Z","ts_ms":1782873186670}}

{"type":"orderbook_delta","sid":1,"seq":683,"msg":{"market_ticker":"KXNEXTTEAMNBA-26LJAM-GSW","market_id":"abbbad28-f309-4dd5-af38-2ad7ebf2acc3","price_dollars":"0.0100","delta_fp":"-1.00","side":"yes","ts":"2026-07-01T02:33:06.670556Z","ts_ms":1782873186670}}

{"type":"orderbook_delta","sid":1,"seq":684,"msg":{"market_ticker":"KXNEXTTEAMNBA-26LJAM-GSW","market_id":"abbbad28-f309-4dd5-af38-2ad7ebf2acc3","price_dollars":"0.0100","delta_fp":"-1.00","side":"yes","ts":"2026-07-01T02:33:06.670556Z","ts_ms":1782873186670}}

{"type":"orderbook_delta","sid":1,"seq":685,"msg":{"market_ticker":"KXNEXTTEAMNBA-26LJAM-GSW","market_id":"abbbad28-f309-4dd5-af38-2ad7ebf2acc3","price_dollars":"0.0100","delta_fp":"-1.00","side":"yes","ts":"2026-07-01T02:33:06.670556Z","ts_ms":1782873186670}}

{"type":"orderbook_delta","sid":1,"seq":686,"msg":{"market_ticker":"KXNEXTTEAMNBA-26LJAM-GSW","market_id":"abbbad28-f309-4dd5-af38-2ad7ebf2acc3","price_dollars":"0.0100","delta_fp":"-1.00","side":"yes","ts":"2026-07-01T02:33:06.670556Z","ts_ms":1782873186670}}

{"type":"orderbook_delta","sid":1,"seq":687,"msg":{"market_ticker":"KXNEXTTEAMNBA-26LJAM-GSW","market_id":"abbbad28-f309-4dd5-af38-2ad7ebf2acc3","price_dollars":"0.0100","delta_fp":"-1.00","side":"yes","ts":"2026-07-01T02:33:06.670556Z","ts_ms":1782873186670}}

{"type":"orderbook_delta","sid":1,"seq":688,"msg":{"market_ticker":"KXNEXTTEAMNBA-26LJAM-GSW","market_id":"abbbad28-f309-4dd5-af38-2ad7ebf2acc3","price_dollars":"0.0100","delta_fp":"-1.00","side":"yes","ts":"2026-07-01T02:33:06.670556Z","ts_ms":1782873186670}}

{"type":"orderbook_delta","sid":1,"seq":689,"msg":{"market_ticker":"KXNEXTTEAMNBA-26LJAM-GSW","market_id":"abbbad28-f309-4dd5-af38-2ad7ebf2acc3","price_dollars":"0.0100","delta_fp":"-1.00","side":"yes","ts":"2026-07-01T02:33:06.670556Z","ts_ms":1782873186670}}

{"type":"orderbook_delta","sid":1,"seq":690,"msg":{"market_ticker":"KXNEXTTEAMNBA-26LJAM-GSW","market_id":"abbbad28-f309-4dd5-af38-2ad7ebf2acc3","price_dollars":"0.0100","delta_fp":"-1.00","side":"yes","ts":"2026-07-01T02:33:06.670556Z","ts_ms":1782873186670}}

{"type":"orderbook_delta","sid":1,"seq":691,"msg":{"market_ticker":"KXNEXTTEAMNBA-26LJAM-GSW","market_id":"abbbad28-f309-4dd5-af38-2ad7ebf2acc3","price_dollars":"0.0100","delta_fp":"-1.00","side":"yes","ts":"2026-07-01T02:33:06.670556Z","ts_ms":1782873186670}}

{"type":"orderbook_delta","sid":1,"seq":692,"msg":{"market_ticker":"KXNEXTTEAMNBA-26LJAM-GSW","market_id":"abbbad28-f309-4dd5-af38-2ad7ebf2acc3","price_dollars":"0.0100","delta_fp":"-1.00","side":"yes","ts":"2026-07-01T02:33:06.670556Z","ts_ms":1782873186670}}

{"type":"orderbook_delta","sid":1,"seq":693,"msg":{"market_ticker":"KXNEXTTEAMNBA-26LJAM-GSW","market_id":"abbbad28-f309-4dd5-af38-2ad7ebf2acc3","price_dollars":"0.0100","delta_fp":"-1.00","side":"yes","ts":"2026-07-01T02:33:06.670556Z","ts_ms":1782873186670}}

{"type":"orderbook_delta","sid":1,"seq":694,"msg":{"market_ticker":"KXNEXTTEAMNBA-26LJAM-GSW","market_id":"abbbad28-f309-4dd5-af38-2ad7ebf2acc3","price_dollars":"0.0100","delta_fp":"-1.00","side":"yes","ts":"2026-07-01T02:33:06.670556Z","ts_ms":1782873186670}}

{"type":"orderbook_delta","sid":1,"seq":695,"msg":{"market_ticker":"KXNEXTTEAMNBA-26LJAM-GSW","market_id":"abbbad28-f309-4dd5-af38-2ad7ebf2acc3","price_dollars":"0.0100","delta_fp":"-1.00","side":"yes","ts":"2026-07-01T02:33:06.670556Z","ts_ms":1782873186670}}

{"type":"orderbook_delta","sid":1,"seq":696,"msg":{"market_ticker":"KXNEXTTEAMNBA-26LJAM-GSW","market_id":"abbbad28-f309-4dd5-af38-2ad7ebf2acc3","price_dollars":"0.0100","delta_fp":"-1.00","side":"yes","ts":"2026-07-01T02:33:06.670556Z","ts_ms":1782873186670}}

{"type":"orderbook_delta","sid":1,"seq":697,"msg":{"market_ticker":"KXNEXTTEAMNBA-26LJAM-GSW","market_id":"abbbad28-f309-4dd5-af38-2ad7ebf2acc3","price_dollars":"0.0100","delta_fp":"-1.00","side":"yes","ts":"2026-07-01T02:33:06.670556Z","ts_ms":1782873186670}}

{"type":"orderbook_delta","sid":1,"seq":698,"msg":{"market_ticker":"KXNEXTTEAMNBA-26LJAM-GSW","market_id":"abbbad28-f309-4dd5-af38-2ad7ebf2acc3","price_dollars":"0.0100","delta_fp":"-1.00","side":"yes","ts":"2026-07-01T02:33:06.670556Z","ts_ms":1782873186670}}

{"type":"orderbook_delta","sid":1,"seq":699,"msg":{"market_ticker":"KXNEXTTEAMNBA-26LJAM-GSW","market_id":"abbbad28-f309-4dd5-af38-2ad7ebf2acc3","price_dollars":"0.0100","delta_fp":"-1.00","side":"yes","ts":"2026-07-01T02:33:06.670556Z","ts_ms":1782873186670}}

{"type":"orderbook_delta","sid":1,"seq":700,"msg":{"market_ticker":"KXNEXTTEAMNBA-26LJAM-GSW","market_id":"abbbad28-f309-4dd5-af38-2ad7ebf2acc3","price_dollars":"0.0100","delta_fp":"-1.00","side":"yes","ts":"2026-07-01T02:33:06.670556Z","ts_ms":1782873186670}}

{"type":"orderbook_delta","sid":1,"seq":701,"msg":{"market_ticker":"KXNEXTTEAMNBA-26LJAM-GSW","market_id":"abbbad28-f309-4dd5-af38-2ad7ebf2acc3","price_dollars":"0.0100","delta_fp":"-1.00","side":"yes","ts":"2026-07-01T02:33:06.670556Z","ts_ms":1782873186670}}

{"type":"orderbook_delta","sid":1,"seq":702,"msg":{"market_ticker":"KXNEXTTEAMNBA-26LJAM-GSW","market_id":"abbbad28-f309-4dd5-af38-2ad7ebf2acc3","price_dollars":"0.0100","delta_fp":"-1.00","side":"yes","ts":"2026-07-01T02:33:06.670556Z","ts_ms":1782873186670}}

{"type":"orderbook_delta","sid":1,"seq":703,"msg":{"market_ticker":"KXNEXTTEAMNBA-26LJAM-GSW","market_id":"abbbad28-f309-4dd5-af38-2ad7ebf2acc3","price_dollars":"0.0100","delta_fp":"-1.00","side":"yes","ts":"2026-07-01T02:33:06.670556Z","ts_ms":1782873186670}}

{"type":"orderbook_delta","sid":1,"seq":704,"msg":{"market_ticker":"KXNEXTTEAMNBA-26LJAM-GSW","market_id":"abbbad28-f309-4dd5-af38-2ad7ebf2acc3","price_dollars":"0.0100","delta_fp":"-1.00","side":"yes","ts":"2026-07-01T02:33:06.670556Z","ts_ms":1782873186670}}

{"type":"orderbook_delta","sid":1,"seq":705,"msg":{"market_ticker":"KXNEXTTEAMNBA-26LJAM-GSW","market_id":"abbbad28-f309-4dd5-af38-2ad7ebf2acc3","price_dollars":"0.0100","delta_fp":"-1.00","side":"yes","ts":"2026-07-01T02:33:06.670556Z","ts_ms":1782873186670}}

{"type":"orderbook_delta","sid":1,"seq":706,"msg":{"market_ticker":"KXNEXTTEAMNBA-26LJAM-GSW","market_id":"abbbad28-f309-4dd5-af38-2ad7ebf2acc3","price_dollars":"0.0100","delta_fp":"-1.00","side":"yes","ts":"2026-07-01T02:33:06.670556Z","ts_ms":1782873186670}}

{"type":"orderbook_delta","sid":1,"seq":707,"msg":{"market_ticker":"KXNEXTTEAMNBA-26LJAM-GSW","market_id":"abbbad28-f309-4dd5-af38-2ad7ebf2acc3","price_dollars":"0.0100","delta_fp":"-1.00","side":"yes","ts":"2026-07-01T02:33:06.670556Z","ts_ms":1782873186670}}

{"type":"orderbook_delta","sid":1,"seq":708,"msg":{"market_ticker":"KXNEXTTEAMNBA-26LJAM-GSW","market_id":"abbbad28-f309-4dd5-af38-2ad7ebf2acc3","price_dollars":"0.0100","delta_fp":"-1.00","side":"yes","ts":"2026-07-01T02:33:06.670556Z","ts_ms":1782873186670}}

{"type":"orderbook_delta","sid":1,"seq":709,"msg":{"market_ticker":"KXNEXTTEAMNBA-26LJAM-GSW","market_id":"abbbad28-f309-4dd5-af38-2ad7ebf2acc3","price_dollars":"0.0100","delta_fp":"-1.00","side":"yes","ts":"2026-07-01T02:33:06.670556Z","ts_ms":1782873186670}}

{"type":"orderbook_delta","sid":1,"seq":710,"msg":{"market_ticker":"KXNEXTTEAMNBA-26LJAM-GSW","market_id":"abbbad28-f309-4dd5-af38-2ad7ebf2acc3","price_dollars":"0.0100","delta_fp":"-1.00","side":"yes","ts":"2026-07-01T02:33:06.670556Z","ts_ms":1782873186670}}

{"type":"orderbook_delta","sid":1,"seq":711,"msg":{"market_ticker":"KXNEXTTEAMNBA-26LJAM-GSW","market_id":"abbbad28-f309-4dd5-af38-2ad7ebf2acc3","price_dollars":"0.0100","delta_fp":"-1.00","side":"yes","ts":"2026-07-01T02:33:06.670556Z","ts_ms":1782873186670}}

{"type":"orderbook_delta","sid":1,"seq":712,"msg":{"market_ticker":"KXNEXTTEAMNBA-26LJAM-GSW","market_id":"abbbad28-f309-4dd5-af38-2ad7ebf2acc3","price_dollars":"0.0100","delta_fp":"-1.00","side":"yes","ts":"2026-07-01T02:33:06.670556Z","ts_ms":1782873186670}}

{"type":"orderbook_delta","sid":1,"seq":713,"msg":{"market_ticker":"KXNEXTTEAMNBA-26LJAM-GSW","market_id":"abbbad28-f309-4dd5-af38-2ad7ebf2acc3","price_dollars":"0.0100","delta_fp":"-1.00","side":"yes","ts":"2026-07-01T02:33:06.670556Z","ts_ms":1782873186670}}

{"type":"orderbook_delta","sid":1,"seq":714,"msg":{"market_ticker":"KXNEXTTEAMNBA-26LJAM-GSW","market_id":"abbbad28-f309-4dd5-af38-2ad7ebf2acc3","price_dollars":"0.0100","delta_fp":"-1.00","side":"yes","ts":"2026-07-01T02:33:06.670556Z","ts_ms":1782873186670}}

{"type":"orderbook_delta","sid":1,"seq":715,"msg":{"market_ticker":"KXNEXTTEAMNBA-26LJAM-GSW","market_id":"abbbad28-f309-4dd5-af38-2ad7ebf2acc3","price_dollars":"0.0100","delta_fp":"-1.00","side":"yes","ts":"2026-07-01T02:33:06.670556Z","ts_ms":1782873186670}}

{"type":"orderbook_delta","sid":1,"seq":716,"msg":{"market_ticker":"KXNEXTTEAMNBA-26LJAM-GSW","market_id":"abbbad28-f309-4dd5-af38-2ad7ebf2acc3","price_dollars":"0.0100","delta_fp":"-1.00","side":"yes","ts":"2026-07-01T02:33:06.670556Z","ts_ms":1782873186670}}

{"type":"orderbook_delta","sid":1,"seq":717,"msg":{"market_ticker":"KXNEXTTEAMNBA-26LJAM-GSW","market_id":"abbbad28-f309-4dd5-af38-2ad7ebf2acc3","price_dollars":"0.0100","delta_fp":"-1.00","side":"yes","ts":"2026-07-01T02:33:06.670556Z","ts_ms":1782873186670}}

{"type":"orderbook_delta","sid":1,"seq":718,"msg":{"market_ticker":"KXNEXTTEAMNBA-26LJAM-GSW","market_id":"abbbad28-f309-4dd5-af38-2ad7ebf2acc3","price_dollars":"0.0100","delta_fp":"-1.00","side":"yes","ts":"2026-07-01T02:33:06.670556Z","ts_ms":1782873186670}}

{"type":"orderbook_delta","sid":1,"seq":719,"msg":{"market_ticker":"KXNEXTTEAMNBA-26LJAM-GSW","market_id":"abbbad28-f309-4dd5-af38-2ad7ebf2acc3","price_dollars":"0.0100","delta_fp":"-1.00","side":"yes","ts":"2026-07-01T02:33:06.670556Z","ts_ms":1782873186670}}

{"type":"orderbook_delta","sid":1,"seq":720,"msg":{"market_ticker":"KXNEXTTEAMNBA-26LJAM-GSW","market_id":"abbbad28-f309-4dd5-af38-2ad7ebf2acc3","price_dollars":"0.0100","delta_fp":"-1.00","side":"yes","ts":"2026-07-01T02:33:06.670556Z","ts_ms":1782873186670}}

{"type":"orderbook_delta","sid":1,"seq":721,"msg":{"market_ticker":"KXNEXTTEAMNBA-26LJAM-GSW","market_id":"abbbad28-f309-4dd5-af38-2ad7ebf2acc3","price_dollars":"0.0100","delta_fp":"-1.00","side":"yes","ts":"2026-07-01T02:33:06.670556Z","ts_ms":1782873186670}}

{"type":"orderbook_delta","sid":1,"seq":722,"msg":{"market_ticker":"KXNEXTTEAMNBA-26LJAM-GSW","market_id":"abbbad28-f309-4dd5-af38-2ad7ebf2acc3","price_dollars":"0.0100","delta_fp":"-1.00","side":"yes","ts":"2026-07-01T02:33:06.670556Z","ts_ms":1782873186670}}

{"type":"orderbook_delta","sid":1,"seq":723,"msg":{"market_ticker":"KXNEXTTEAMNBA-26LJAM-GSW","market_id":"abbbad28-f309-4dd5-af38-2ad7ebf2acc3","price_dollars":"0.0100","delta_fp":"-1.00","side":"yes","ts":"2026-07-01T02:33:06.670556Z","ts_ms":1782873186670}}

{"type":"orderbook_delta","sid":1,"seq":724,"msg":{"market_ticker":"KXNEXTTEAMNBA-26LJAM-GSW","market_id":"abbbad28-f309-4dd5-af38-2ad7ebf2acc3","price_dollars":"0.0100","delta_fp":"-1.00","side":"yes","ts":"2026-07-01T02:33:06.670556Z","ts_ms":1782873186670}}

{"type":"orderbook_delta","sid":1,"seq":725,"msg":{"market_ticker":"KXNEXTTEAMNBA-26LJAM-GSW","market_id":"abbbad28-f309-4dd5-af38-2ad7ebf2acc3","price_dollars":"0.0100","delta_fp":"-1.00","side":"yes","ts":"2026-07-01T02:33:06.670556Z","ts_ms":1782873186670}}

{"type":"orderbook_delta","sid":1,"seq":726,"msg":{"market_ticker":"KXNEXTTEAMNBA-26LJAM-GSW","market_id":"abbbad28-f309-4dd5-af38-2ad7ebf2acc3","price_dollars":"0.0100","delta_fp":"-1.00","side":"yes","ts":"2026-07-01T02:33:06.670556Z","ts_ms":1782873186670}}

{"type":"orderbook_delta","sid":1,"seq":727,"msg":{"market_ticker":"KXNEXTTEAMNBA-26LJAM-GSW","market_id":"abbbad28-f309-4dd5-af38-2ad7ebf2acc3","price_dollars":"0.0100","delta_fp":"-1.00","side":"yes","ts":"2026-07-01T02:33:06.670556Z","ts_ms":1782873186670}}

{"type":"orderbook_delta","sid":1,"seq":728,"msg":{"market_ticker":"KXNEXTTEAMNBA-26LJAM-GSW","market_id":"abbbad28-f309-4dd5-af38-2ad7ebf2acc3","price_dollars":"0.0100","delta_fp":"-1.00","side":"yes","ts":"2026-07-01T02:33:06.670556Z","ts_ms":1782873186670}}

{"type":"orderbook_delta","sid":1,"seq":729,"msg":{"market_ticker":"KXNEXTTEAMNBA-26LJAM-GSW","market_id":"abbbad28-f309-4dd5-af38-2ad7ebf2acc3","price_dollars":"0.0100","delta_fp":"-1.00","side":"yes","ts":"2026-07-01T02:33:06.670556Z","ts_ms":1782873186670}}

{"type":"orderbook_delta","sid":1,"seq":730,"msg":{"market_ticker":"KXNEXTTEAMNBA-26LJAM-GSW","market_id":"abbbad28-f309-4dd5-af38-2ad7ebf2acc3","price_dollars":"0.0100","delta_fp":"-1.00","side":"yes","ts":"2026-07-01T02:33:06.670556Z","ts_ms":1782873186670}}

{"type":"orderbook_delta","sid":1,"seq":731,"msg":{"market_ticker":"KXNEXTTEAMNBA-26LJAM-GSW","market_id":"abbbad28-f309-4dd5-af38-2ad7ebf2acc3","price_dollars":"0.0100","delta_fp":"-1.00","side":"yes","ts":"2026-07-01T02:33:06.670556Z","ts_ms":1782873186670}}

{"type":"orderbook_delta","sid":1,"seq":732,"msg":{"market_ticker":"KXNEXTTEAMNBA-26LJAM-GSW","market_id":"abbbad28-f309-4dd5-af38-2ad7ebf2acc3","price_dollars":"0.0100","delta_fp":"-1.00","side":"yes","ts":"2026-07-01T02:33:06.670556Z","ts_ms":1782873186670}}

{"type":"orderbook_delta","sid":1,"seq":733,"msg":{"market_ticker":"KXNEXTTEAMNBA-26LJAM-GSW","market_id":"abbbad28-f309-4dd5-af38-2ad7ebf2acc3","price_dollars":"0.0100","delta_fp":"-1.00","side":"yes","ts":"2026-07-01T02:33:06.670556Z","ts_ms":1782873186670}}

{"type":"orderbook_delta","sid":1,"seq":734,"msg":{"market_ticker":"KXNEXTTEAMNBA-26LJAM-GSW","market_id":"abbbad28-f309-4dd5-af38-2ad7ebf2acc3","price_dollars":"0.0100","delta_fp":"-1.00","side":"yes","ts":"2026-07-01T02:33:06.670556Z","ts_ms":1782873186670}}

{"type":"orderbook_delta","sid":1,"seq":735,"msg":{"market_ticker":"KXNEXTTEAMNBA-26LJAM-GSW","market_id":"abbbad28-f309-4dd5-af38-2ad7ebf2acc3","price_dollars":"0.0100","delta_fp":"-1.00","side":"yes","ts":"2026-07-01T02:33:06.670556Z","ts_ms":1782873186670}}

{"type":"orderbook_delta","sid":1,"seq":736,"msg":{"market_ticker":"KXNEXTTEAMNBA-26LJAM-GSW","market_id":"abbbad28-f309-4dd5-af38-2ad7ebf2acc3","price_dollars":"0.0100","delta_fp":"-1.00","side":"yes","ts":"2026-07-01T02:33:06.670556Z","ts_ms":1782873186670}}

{"type":"orderbook_delta","sid":1,"seq":737,"msg":{"market_ticker":"KXNEXTTEAMNBA-26LJAM-GSW","market_id":"abbbad28-f309-4dd5-af38-2ad7ebf2acc3","price_dollars":"0.0100","delta_fp":"-1.00","side":"yes","ts":"2026-07-01T02:33:06.670556Z","ts_ms":1782873186670}}

{"type":"orderbook_delta","sid":1,"seq":738,"msg":{"market_ticker":"KXNEXTTEAMNBA-26LJAM-GSW","market_id":"abbbad28-f309-4dd5-af38-2ad7ebf2acc3","price_dollars":"0.0100","delta_fp":"-1.00","side":"yes","ts":"2026-07-01T02:33:06.670556Z","ts_ms":1782873186670}}

{"type":"orderbook_delta","sid":1,"seq":739,"msg":{"market_ticker":"KXNEXTTEAMNBA-26LJAM-GSW","market_id":"abbbad28-f309-4dd5-af38-2ad7ebf2acc3","price_dollars":"0.0100","delta_fp":"-1.00","side":"yes","ts":"2026-07-01T02:33:06.670556Z","ts_ms":1782873186670}}

{"type":"orderbook_delta","sid":1,"seq":740,"msg":{"market_ticker":"KXNEXTTEAMNBA-26LJAM-GSW","market_id":"abbbad28-f309-4dd5-af38-2ad7ebf2acc3","price_dollars":"0.0100","delta_fp":"-1.00","side":"yes","ts":"2026-07-01T02:33:06.670556Z","ts_ms":1782873186670}}

{"type":"orderbook_delta","sid":1,"seq":741,"msg":{"market_ticker":"KXNEXTTEAMNBA-26LJAM-GSW","market_id":"abbbad28-f309-4dd5-af38-2ad7ebf2acc3","price_dollars":"0.0100","delta_fp":"-1.00","side":"yes","ts":"2026-07-01T02:33:06.670556Z","ts_ms":1782873186670}}

{"type":"orderbook_delta","sid":1,"seq":742,"msg":{"market_ticker":"KXNEXTTEAMNBA-26LJAM-GSW","market_id":"abbbad28-f309-4dd5-af38-2ad7ebf2acc3","price_dollars":"0.0100","delta_fp":"-1.00","side":"yes","ts":"2026-07-01T02:33:06.670556Z","ts_ms":1782873186670}}

{"type":"orderbook_delta","sid":1,"seq":743,"msg":{"market_ticker":"KXNEXTTEAMNBA-26LJAM-GSW","market_id":"abbbad28-f309-4dd5-af38-2ad7ebf2acc3","price_dollars":"0.0100","delta_fp":"-1.00","side":"yes","ts":"2026-07-01T02:33:06.670556Z","ts_ms":1782873186670}}

{"type":"orderbook_delta","sid":1,"seq":744,"msg":{"market_ticker":"KXNEXTTEAMNBA-26LJAM-GSW","market_id":"abbbad28-f309-4dd5-af38-2ad7ebf2acc3","price_dollars":"0.0100","delta_fp":"-1.00","side":"yes","ts":"2026-07-01T02:33:06.670556Z","ts_ms":1782873186670}}

{"type":"orderbook_delta","sid":1,"seq":745,"msg":{"market_ticker":"KXNEXTTEAMNBA-26LJAM-GSW","market_id":"abbbad28-f309-4dd5-af38-2ad7ebf2acc3","price_dollars":"0.0100","delta_fp":"-1.00","side":"yes","ts":"2026-07-01T02:33:06.670556Z","ts_ms":1782873186670}}

{"type":"orderbook_delta","sid":1,"seq":746,"msg":{"market_ticker":"KXNEXTTEAMNBA-26LJAM-GSW","market_id":"abbbad28-f309-4dd5-af38-2ad7ebf2acc3","price_dollars":"0.0100","delta_fp":"-1.00","side":"yes","ts":"2026-07-01T02:33:06.670556Z","ts_ms":1782873186670}}

{"type":"orderbook_delta","sid":1,"seq":747,"msg":{"market_ticker":"KXNEXTTEAMNBA-26LJAM-GSW","market_id":"abbbad28-f309-4dd5-af38-2ad7ebf2acc3","price_dollars":"0.0100","delta_fp":"-1.00","side":"yes","ts":"2026-07-01T02:33:06.670556Z","ts_ms":1782873186670}}

{"type":"orderbook_delta","sid":1,"seq":748,"msg":{"market_ticker":"KXNEXTTEAMNBA-26LJAM-GSW","market_id":"abbbad28-f309-4dd5-af38-2ad7ebf2acc3","price_dollars":"0.0100","delta_fp":"-1.00","side":"yes","ts":"2026-07-01T02:33:06.670556Z","ts_ms":1782873186670}}

{"type":"orderbook_delta","sid":1,"seq":749,"msg":{"market_ticker":"KXNEXTTEAMNBA-26LJAM-GSW","market_id":"abbbad28-f309-4dd5-af38-2ad7ebf2acc3","price_dollars":"0.0100","delta_fp":"-1.00","side":"yes","ts":"2026-07-01T02:33:06.670556Z","ts_ms":1782873186670}}

{"type":"orderbook_delta","sid":1,"seq":750,"msg":{"market_ticker":"KXNEXTTEAMNBA-26LJAM-GSW","market_id":"abbbad28-f309-4dd5-af38-2ad7ebf2acc3","price_dollars":"0.0100","delta_fp":"-1.00","side":"yes","ts":"2026-07-01T02:33:06.670556Z","ts_ms":1782873186670}}

{"type":"orderbook_delta","sid":1,"seq":751,"msg":{"market_ticker":"KXNEXTTEAMNBA-26LJAM-GSW","market_id":"abbbad28-f309-4dd5-af38-2ad7ebf2acc3","price_dollars":"0.0100","delta_fp":"-1.00","side":"yes","ts":"2026-07-01T02:33:06.670556Z","ts_ms":1782873186670}}

{"type":"orderbook_delta","sid":1,"seq":752,"msg":{"market_ticker":"KXNEXTTEAMNBA-26LJAM-GSW","market_id":"abbbad28-f309-4dd5-af38-2ad7ebf2acc3","price_dollars":"0.0100","delta_fp":"-1.00","side":"yes","ts":"2026-07-01T02:33:06.670556Z","ts_ms":1782873186670}}

{"type":"orderbook_delta","sid":1,"seq":753,"msg":{"market_ticker":"KXNEXTTEAMNBA-26LJAM-GSW","market_id":"abbbad28-f309-4dd5-af38-2ad7ebf2acc3","price_dollars":"0.0100","delta_fp":"-1.00","side":"yes","ts":"2026-07-01T02:33:06.670556Z","ts_ms":1782873186670}}

{"type":"orderbook_delta","sid":1,"seq":754,"msg":{"market_ticker":"KXNEXTTEAMNBA-26LJAM-GSW","market_id":"abbbad28-f309-4dd5-af38-2ad7ebf2acc3","price_dollars":"0.0100","delta_fp":"-1.00","side":"yes","ts":"2026-07-01T02:33:06.670556Z","ts_ms":1782873186670}}

{"type":"orderbook_delta","sid":1,"seq":755,"msg":{"market_ticker":"KXNEXTTEAMNBA-26LJAM-GSW","market_id":"abbbad28-f309-4dd5-af38-2ad7ebf2acc3","price_dollars":"0.0100","delta_fp":"-1.00","side":"yes","ts":"2026-07-01T02:33:06.670556Z","ts_ms":1782873186670}}

{"type":"orderbook_delta","sid":1,"seq":756,"msg":{"market_ticker":"KXNEXTTEAMNBA-26LJAM-GSW","market_id":"abbbad28-f309-4dd5-af38-2ad7ebf2acc3","price_dollars":"0.0100","delta_fp":"-1.00","side":"yes","ts":"2026-07-01T02:33:06.670556Z","ts_ms":1782873186670}}

{"type":"orderbook_delta","sid":1,"seq":757,"msg":{"market_ticker":"KXNEXTTEAMNBA-26LJAM-GSW","market_id":"abbbad28-f309-4dd5-af38-2ad7ebf2acc3","price_dollars":"0.0100","delta_fp":"-1.00","side":"yes","ts":"2026-07-01T02:33:06.670556Z","ts_ms":1782873186670}}

{"type":"orderbook_delta","sid":1,"seq":758,"msg":{"market_ticker":"KXNEXTTEAMNBA-26LJAM-GSW","market_id":"abbbad28-f309-4dd5-af38-2ad7ebf2acc3","price_dollars":"0.0100","delta_fp":"-1.00","side":"yes","ts":"2026-07-01T02:33:06.670556Z","ts_ms":1782873186670}}

