{"type":"orderbook_delta","sid":1,"seq":2284,"msg":{"market_ticker":"KXNEXTTEAMNBA-26LJAM-GSW","market_id":"abbbad28-f309-4dd5-af38-2ad7ebf2acc3","price_dollars":"0.0100","delta_fp":"1.00","side":"yes","ts":"2026-07-01T02:35:46.921712Z","ts_ms":1782873346921}}

{"type":"orderbook_delta","sid":1,"seq":2285,"msg":{"market_ticker":"KXNEXTTEAMNBA-26LJAM-CLE","market_id":"7552b8d4-05de-4e41-84a8-97b0684da4a9","price_dollars":"0.7400","delta_fp":"-0.10","side":"no","ts":"2026-07-01T02:35:47.653051Z","ts_ms":1782873347653}}

{"type":"orderbook_delta","sid":1,"seq":2286,"msg":{"market_ticker":"KXNEXTTEAMNBA-26LJAM-MIA","market_id":"492cb255-91da-4c91-bc9e-f83d090cc6dd","price_dollars":"0.0100","delta_fp":"1.00","side":"yes","ts":"2026-07-01T02:35:48.046728Z","ts_ms":1782873348046}}

{"type":"orderbook_delta","sid":1,"seq":2287,"msg":{"market_ticker":"KXNEXTTEAMNBA-26LJAM-MIA","market_id":"492cb255-91da-4c91-bc9e-f83d090cc6dd","price_dollars":"0.0100","delta_fp":"1.00","side":"yes","ts":"2026-07-01T02:35:48.047184Z","ts_ms":1782873348047}}

{"type":"orderbook_delta","sid":1,"seq":2288,"msg":{"market_ticker":"KXNEXTTEAMNBA-26LJAM-MIA","market_id":"492cb255-91da-4c91-bc9e-f83d090cc6dd","price_dollars":"0.0100","delta_fp":"1.00","side":"yes","ts":"2026-07-01T02:35:48.047511Z","ts_ms":1782873348047}}

{"type":"orderbook_delta","sid":1,"seq":2289,"msg":{"market_ticker":"KXNEXTTEAMNBA-26LJAM-MIA","market_id":"492cb255-91da-4c91-bc9e-f83d090cc6dd","price_dollars":"0.0100","delta_fp":"1.00","side":"yes","ts":"2026-07-01T02:35:48.0479Z","ts_ms":1782873348047}}

{"type":"orderbook_delta","sid":1,"seq":2290,"msg":{"market_ticker":"KXNEXTTEAMNBA-26LJAM-MIA","market_id":"492cb255-91da-4c91-bc9e-f83d090cc6dd","price_dollars":"0.0100","delta_fp":"1.00","side":"yes","ts":"2026-07-01T02:35:48.048341Z","ts_ms":1782873348048}}

{"type":"orderbook_delta","sid":1,"seq":2291,"msg":{"market_ticker":"KXNEXTTEAMNBA-26LJAM-MIA","market_id":"492cb255-91da-4c91-bc9e-f83d090cc6dd","price_dollars":"0.0100","delta_fp":"1.00","side":"yes","ts":"2026-07-01T02:35:48.048942Z","ts_ms":1782873348048}}

{"type":"orderbook_delta","sid":1,"seq":2292,"msg":{"market_ticker":"KXNEXTTEAMNBA-26LJAM-MIA","market_id":"492cb255-91da-4c91-bc9e-f83d090cc6dd","price_dollars":"0.0100","delta_fp":"1.00","side":"yes","ts":"2026-07-01T02:35:48.049429Z","ts_ms":1782873348049}}

{"type":"orderbook_delta","sid":1,"seq":2293,"msg":{"market_ticker":"KXNEXTTEAMNBA-26LJAM-MIA","market_id":"492cb255-91da-4c91-bc9e-f83d090cc6dd","price_dollars":"0.0100","delta_fp":"1.00","side":"yes","ts":"2026-07-01T02:35:48.049797Z","ts_ms":1782873348049}}

{"type":"orderbook_delta","sid":1,"seq":2294,"msg":{"market_ticker":"KXNEXTTEAMNBA-26LJAM-MIA","market_id":"492cb255-91da-4c91-bc9e-f83d090cc6dd","price_dollars":"0.0100","delta_fp":"1.00","side":"yes","ts":"2026-07-01T02:35:48.050202Z","ts_ms":1782873348050}}

{"type":"orderbook_delta","sid":1,"seq":2295,"msg":{"market_ticker":"KXNEXTTEAMNBA-26LJAM-MIA","market_id":"492cb255-91da-4c91-bc9e-f83d090cc6dd","price_dollars":"0.0100","delta_fp":"1.00","side":"yes","ts":"2026-07-01T02:35:48.050618Z","ts_ms":1782873348050}}

{"type":"orderbook_delta","sid":1,"seq":2296,"msg":{"market_ticker":"KXNEXTTEAMNBA-26LJAM-MIA","market_id":"492cb255-91da-4c91-bc9e-f83d090cc6dd","price_dollars":"0.0100","delta_fp":"1.00","side":"yes","ts":"2026-07-01T02:35:48.051031Z","ts_ms":1782873348051}}

{"type":"orderbook_delta","sid":1,"seq":2297,"msg":{"market_ticker":"KXNEXTTEAMNBA-26LJAM-MIA","market_id":"492cb255-91da-4c91-bc9e-f83d090cc6dd","price_dollars":"0.0100","delta_fp":"1.00","side":"yes","ts":"2026-07-01T02:35:48.051402Z","ts_ms":1782873348051}}

{"type":"orderbook_delta","sid":1,"seq":2298,"msg":{"market_ticker":"KXNEXTTEAMNBA-26LJAM-MIA","market_id":"492cb255-91da-4c91-bc9e-f83d090cc6dd","price_dollars":"0.0100","delta_fp":"1.00","side":"yes","ts":"2026-07-01T02:35:48.051753Z","ts_ms":1782873348051}}

{"type":"orderbook_delta","sid":1,"seq":2299,"msg":{"market_ticker":"KXNEXTTEAMNBA-26LJAM-MIA","market_id":"492cb255-91da-4c91-bc9e-f83d090cc6dd","price_dollars":"0.0100","delta_fp":"1.00","side":"yes","ts":"2026-07-01T02:35:48.052106Z","ts_ms":1782873348052}}

{"type":"orderbook_delta","sid":1,"seq":2300,"msg":{"market_ticker":"KXNEXTTEAMNBA-26LJAM-MIA","market_id":"492cb255-91da-4c91-bc9e-f83d090cc6dd","price_dollars":"0.0100","delta_fp":"1.00","side":"yes","ts":"2026-07-01T02:35:48.052446Z","ts_ms":1782873348052}}

{"type":"orderbook_delta","sid":1,"seq":2301,"msg":{"market_ticker":"KXNEXTTEAMNBA-26LJAM-MIA","market_id":"492cb255-91da-4c91-bc9e-f83d090cc6dd","price_dollars":"0.0100","delta_fp":"1.00","side":"yes","ts":"2026-07-01T02:35:48.05276Z","ts_ms":1782873348052}}

{"type":"orderbook_delta","sid":1,"seq":2302,"msg":{"market_ticker":"KXNEXTTEAMNBA-26LJAM-MIA","market_id":"492cb255-91da-4c91-bc9e-f83d090cc6dd","price_dollars":"0.0100","delta_fp":"1.00","side":"yes","ts":"2026-07-01T02:35:48.053086Z","ts_ms":1782873348053}}

{"type":"orderbook_delta","sid":1,"seq":2303,"msg":{"market_ticker":"KXNEXTTEAMNBA-26LJAM-MIA","market_id":"492cb255-91da-4c91-bc9e-f83d090cc6dd","price_dollars":"0.0100","delta_fp":"1.00","side":"yes","ts":"2026-07-01T02:35:48.0534Z","ts_ms":1782873348053}}

{"type":"orderbook_delta","sid":1,"seq":2304,"msg":{"market_ticker":"KXNEXTTEAMNBA-26LJAM-MIA","market_id":"492cb255-91da-4c91-bc9e-f83d090cc6dd","price_dollars":"0.0100","delta_fp":"1.00","side":"yes","ts":"2026-07-01T02:35:48.053776Z","ts_ms":1782873348053}}

{"type":"orderbook_delta","sid":1,"seq":2305,"msg":{"market_ticker":"KXNEXTTEAMNBA-26LJAM-MIA","market_id":"492cb255-91da-4c91-bc9e-f83d090cc6dd","price_dollars":"0.0100","delta_fp":"1.00","side":"yes","ts":"2026-07-01T02:35:48.054096Z","ts_ms":1782873348054}}

{"type":"orderbook_delta","sid":1,"seq":2306,"msg":{"market_ticker":"KXNEXTTEAMNBA-26LJAM-CLE","market_id":"7552b8d4-05de-4e41-84a8-97b0684da4a9","price_dollars":"0.7400","delta_fp":"-0.44","side":"no","ts":"2026-07-01T02:35:49.154071Z","ts_ms":1782873349154}}

{"type":"orderbook_delta","sid":1,"seq":2307,"msg":{"market_ticker":"KXNEXTTEAMNBA-26LJAM-CLE","market_id":"7552b8d4-05de-4e41-84a8-97b0684da4a9","price_dollars":"0.7400","delta_fp":"-1.76","side":"no","ts":"2026-07-01T02:35:49.276822Z","ts_ms":1782873349276}}

{"type":"orderbook_delta","sid":1,"seq":2308,"msg":{"market_ticker":"KXNEXTTEAMNBA-26LJAM-GSW","market_id":"abbbad28-f309-4dd5-af38-2ad7ebf2acc3","price_dollars":"0.5200","delta_fp":"-0.07","side":"no","ts":"2026-07-01T02:35:50.555503Z","ts_ms":1782873350555}}

{"type":"orderbook_delta","sid":1,"seq":2309,"msg":{"market_ticker":"KXNEXTTEAMNBA-26LJAM-MIA","market_id":"492cb255-91da-4c91-bc9e-f83d090cc6dd","price_dollars":"0.8300","delta_fp":"-0.20","side":"no","ts":"2026-07-01T02:35:50.795103Z","ts_ms":1782873350795}}

{"type":"orderbook_delta","sid":1,"seq":2310,"msg":{"market_ticker":"KXNEXTTEAMNBA-26LJAM-CLE","market_id":"7552b8d4-05de-4e41-84a8-97b0684da4a9","price_dollars":"0.7400","delta_fp":"-0.33","side":"no","ts":"2026-07-01T02:35:52.375682Z","ts_ms":1782873352375}}

{"type":"orderbook_delta","sid":1,"seq":2311,"msg":{"market_ticker":"KXNEXTTEAMNBA-26LJAM-MIA","market_id":"492cb255-91da-4c91-bc9e-f83d090cc6dd","price_dollars":"0.8300","delta_fp":"-1.94","side":"no","ts":"2026-07-01T02:35:52.376833Z","ts_ms":1782873352376}}

{"type":"orderbook_delta","sid":1,"seq":2312,"msg":{"market_ticker":"KXNEXTTEAMNBA-26LJAM-GSW","market_id":"abbbad28-f309-4dd5-af38-2ad7ebf2acc3","price_dollars":"0.0100","delta_fp":"1.00","side":"yes","ts":"2026-07-01T02:35:53.050061Z","ts_ms":1782873353050}}

{"type":"orderbook_delta","sid":1,"seq":2313,"msg":{"market_ticker":"KXNEXTTEAMNBA-26LJAM-GSW","market_id":"abbbad28-f309-4dd5-af38-2ad7ebf2acc3","price_dollars":"0.0100","delta_fp":"1.00","side":"yes","ts":"2026-07-01T02:35:53.050842Z","ts_ms":1782873353050}}

{"type":"orderbook_delta","sid":1,"seq":2314,"msg":{"market_ticker":"KXNEXTTEAMNBA-26LJAM-GSW","market_id":"abbbad28-f309-4dd5-af38-2ad7ebf2acc3","price_dollars":"0.0100","delta_fp":"1.00","side":"yes","ts":"2026-07-01T02:35:53.051742Z","ts_ms":1782873353051}}

{"type":"orderbook_delta","sid":1,"seq":2315,"msg":{"market_ticker":"KXNEXTTEAMNBA-26LJAM-GSW","market_id":"abbbad28-f309-4dd5-af38-2ad7ebf2acc3","price_dollars":"0.0100","delta_fp":"1.00","side":"yes","ts":"2026-07-01T02:35:53.052647Z","ts_ms":1782873353052}}

{"type":"orderbook_delta","sid":1,"seq":2316,"msg":{"market_ticker":"KXNEXTTEAMNBA-26LJAM-GSW","market_id":"abbbad28-f309-4dd5-af38-2ad7ebf2acc3","price_dollars":"0.0100","delta_fp":"1.00","side":"yes","ts":"2026-07-01T02:35:53.053122Z","ts_ms":1782873353053}}

{"type":"orderbook_delta","sid":1,"seq":2317,"msg":{"market_ticker":"KXNEXTTEAMNBA-26LJAM-GSW","market_id":"abbbad28-f309-4dd5-af38-2ad7ebf2acc3","price_dollars":"0.0100","delta_fp":"1.00","side":"yes","ts":"2026-07-01T02:35:53.053863Z","ts_ms":1782873353053}}

{"type":"orderbook_delta","sid":1,"seq":2318,"msg":{"market_ticker":"KXNEXTTEAMNBA-26LJAM-GSW","market_id":"abbbad28-f309-4dd5-af38-2ad7ebf2acc3","price_dollars":"0.0100","delta_fp":"1.00","side":"yes","ts":"2026-07-01T02:35:53.054468Z","ts_ms":1782873353054}}

{"type":"orderbook_delta","sid":1,"seq":2319,"msg":{"market_ticker":"KXNEXTTEAMNBA-26LJAM-GSW","market_id":"abbbad28-f309-4dd5-af38-2ad7ebf2acc3","price_dollars":"0.0100","delta_fp":"1.00","side":"yes","ts":"2026-07-01T02:35:53.055401Z","ts_ms":1782873353055}}

{"type":"orderbook_delta","sid":1,"seq":2320,"msg":{"market_ticker":"KXNEXTTEAMNBA-26LJAM-GSW","market_id":"abbbad28-f309-4dd5-af38-2ad7ebf2acc3","price_dollars":"0.0100","delta_fp":"1.00","side":"yes","ts":"2026-07-01T02:35:53.05622Z","ts_ms":1782873353056}}

{"type":"orderbook_delta","sid":1,"seq":2321,"msg":{"market_ticker":"KXNEXTTEAMNBA-26LJAM-GSW","market_id":"abbbad28-f309-4dd5-af38-2ad7ebf2acc3","price_dollars":"0.0100","delta_fp":"1.00","side":"yes","ts":"2026-07-01T02:35:53.057176Z","ts_ms":1782873353057}}

{"type":"orderbook_delta","sid":1,"seq":2322,"msg":{"market_ticker":"KXNEXTTEAMNBA-26LJAM-GSW","market_id":"abbbad28-f309-4dd5-af38-2ad7ebf2acc3","price_dollars":"0.0100","delta_fp":"1.00","side":"yes","ts":"2026-07-01T02:35:53.057829Z","ts_ms":1782873353057}}

{"type":"orderbook_delta","sid":1,"seq":2323,"msg":{"market_ticker":"KXNEXTTEAMNBA-26LJAM-GSW","market_id":"abbbad28-f309-4dd5-af38-2ad7ebf2acc3","price_dollars":"0.0100","delta_fp":"1.00","side":"yes","ts":"2026-07-01T02:35:53.058419Z","ts_ms":1782873353058}}

{"type":"orderbook_delta","sid":1,"seq":2324,"msg":{"market_ticker":"KXNEXTTEAMNBA-26LJAM-GSW","market_id":"abbbad28-f309-4dd5-af38-2ad7ebf2acc3","price_dollars":"0.0100","delta_fp":"1.00","side":"yes","ts":"2026-07-01T02:35:53.05917Z","ts_ms":1782873353059}}

{"type":"orderbook_delta","sid":1,"seq":2325,"msg":{"market_ticker":"KXNEXTTEAMNBA-26LJAM-GSW","market_id":"abbbad28-f309-4dd5-af38-2ad7ebf2acc3","price_dollars":"0.0100","delta_fp":"1.00","side":"yes","ts":"2026-07-01T02:35:53.059856Z","ts_ms":1782873353059}}

{"type":"orderbook_delta","sid":1,"seq":2326,"msg":{"market_ticker":"KXNEXTTEAMNBA-26LJAM-GSW","market_id":"abbbad28-f309-4dd5-af38-2ad7ebf2acc3","price_dollars":"0.0100","delta_fp":"1.00","side":"yes","ts":"2026-07-01T02:35:53.060529Z","ts_ms":1782873353060}}

{"type":"orderbook_delta","sid":1,"seq":2327,"msg":{"market_ticker":"KXNEXTTEAMNBA-26LJAM-GSW","market_id":"abbbad28-f309-4dd5-af38-2ad7ebf2acc3","price_dollars":"0.0100","delta_fp":"1.00","side":"yes","ts":"2026-07-01T02:35:53.06118Z","ts_ms":1782873353061}}

{"type":"orderbook_delta","sid":1,"seq":2328,"msg":{"market_ticker":"KXNEXTTEAMNBA-26LJAM-GSW","market_id":"abbbad28-f309-4dd5-af38-2ad7ebf2acc3","price_dollars":"0.0100","delta_fp":"1.00","side":"yes","ts":"2026-07-01T02:35:53.061656Z","ts_ms":1782873353061}}

{"type":"orderbook_delta","sid":1,"seq":2329,"msg":{"market_ticker":"KXNEXTTEAMNBA-26LJAM-GSW","market_id":"abbbad28-f309-4dd5-af38-2ad7ebf2acc3","price_dollars":"0.0100","delta_fp":"1.00","side":"yes","ts":"2026-07-01T02:35:53.062286Z","ts_ms":1782873353062}}

{"type":"orderbook_delta","sid":1,"seq":2330,"msg":{"market_ticker":"KXNEXTTEAMNBA-26LJAM-GSW","market_id":"abbbad28-f309-4dd5-af38-2ad7ebf2acc3","price_dollars":"0.0100","delta_fp":"1.00","side":"yes","ts":"2026-07-01T02:35:53.06282Z","ts_ms":1782873353062}}

{"type":"orderbook_delta","sid":1,"seq":2331,"msg":{"market_ticker":"KXNEXTTEAMNBA-26LJAM-GSW","market_id":"abbbad28-f309-4dd5-af38-2ad7ebf2acc3","price_dollars":"0.0100","delta_fp":"1.00","side":"yes","ts":"2026-07-01T02:35:53.063286Z","ts_ms":1782873353063}}

{"type":"orderbook_delta","sid":1,"seq":2332,"msg":{"market_ticker":"KXNEXTTEAMNBA-26LJAM-CLE","market_id":"7552b8d4-05de-4e41-84a8-97b0684da4a9","price_dollars":"0.7400","delta_fp":"-0.68","side":"no","ts":"2026-07-01T02:35:53.970526Z","ts_ms":1782873353970}}

{"type":"orderbook_delta","sid":1,"seq":2333,"msg":{"market_ticker":"KXNEXTTEAMNBA-26LJAM-GSW","market_id":"abbbad28-f309-4dd5-af38-2ad7ebf2acc3","price_dollars":"0.5200","delta_fp":"-1.71","side":"no","ts":"2026-07-01T02:35:54.057616Z","ts_ms":1782873354057}}

{"type":"orderbook_delta","sid":1,"seq":2334,"msg":{"market_ticker":"KXNEXTTEAMNBA-26LJAM-MIA","market_id":"492cb255-91da-4c91-bc9e-f83d090cc6dd","price_dollars":"0.8300","delta_fp":"-0.25","side":"no","ts":"2026-07-01T02:35:54.058063Z","ts_ms":1782873354058}}

{"type":"orderbook_delta","sid":1,"seq":2335,"msg":{"market_ticker":"KXNEXTTEAMNBA-26LJAM-MIA","market_id":"492cb255-91da-4c91-bc9e-f83d090cc6dd","price_dollars":"0.0100","delta_fp":"1.00","side":"yes","ts":"2026-07-01T02:35:54.252071Z","ts_ms":1782873354252}}

{"type":"orderbook_delta","sid":1,"seq":2336,"msg":{"market_ticker":"KXNEXTTEAMNBA-26LJAM-MIA","market_id":"492cb255-91da-4c91-bc9e-f83d090cc6dd","price_dollars":"0.0100","delta_fp":"1.00","side":"yes","ts":"2026-07-01T02:35:54.252705Z","ts_ms":1782873354252}}

{"type":"orderbook_delta","sid":1,"seq":2337,"msg":{"market_ticker":"KXNEXTTEAMNBA-26LJAM-MIA","market_id":"492cb255-91da-4c91-bc9e-f83d090cc6dd","price_dollars":"0.0100","delta_fp":"1.00","side":"yes","ts":"2026-07-01T02:35:54.25314Z","ts_ms":1782873354253}}

{"type":"orderbook_delta","sid":1,"seq":2338,"msg":{"market_ticker":"KXNEXTTEAMNBA-26LJAM-MIA","market_id":"492cb255-91da-4c91-bc9e-f83d090cc6dd","price_dollars":"0.0100","delta_fp":"1.00","side":"yes","ts":"2026-07-01T02:35:54.253593Z","ts_ms":1782873354253}}

{"type":"orderbook_delta","sid":1,"seq":2339,"msg":{"market_ticker":"KXNEXTTEAMNBA-26LJAM-MIA","market_id":"492cb255-91da-4c91-bc9e-f83d090cc6dd","price_dollars":"0.0100","delta_fp":"1.00","side":"yes","ts":"2026-07-01T02:35:54.254134Z","ts_ms":1782873354254}}

{"type":"orderbook_delta","sid":1,"seq":2340,"msg":{"market_ticker":"KXNEXTTEAMNBA-26LJAM-MIA","market_id":"492cb255-91da-4c91-bc9e-f83d090cc6dd","price_dollars":"0.0100","delta_fp":"1.00","side":"yes","ts":"2026-07-01T02:35:54.254493Z","ts_ms":1782873354254}}

{"type":"orderbook_delta","sid":1,"seq":2341,"msg":{"market_ticker":"KXNEXTTEAMNBA-26LJAM-MIA","market_id":"492cb255-91da-4c91-bc9e-f83d090cc6dd","price_dollars":"0.0100","delta_fp":"1.00","side":"yes","ts":"2026-07-01T02:35:54.254934Z","ts_ms":1782873354254}}

{"type":"orderbook_delta","sid":1,"seq":2342,"msg":{"market_ticker":"KXNEXTTEAMNBA-26LJAM-MIA","market_id":"492cb255-91da-4c91-bc9e-f83d090cc6dd","price_dollars":"0.0100","delta_fp":"1.00","side":"yes","ts":"2026-07-01T02:35:54.255393Z","ts_ms":1782873354255}}

{"type":"orderbook_delta","sid":1,"seq":2343,"msg":{"market_ticker":"KXNEXTTEAMNBA-26LJAM-MIA","market_id":"492cb255-91da-4c91-bc9e-f83d090cc6dd","price_dollars":"0.0100","delta_fp":"1.00","side":"yes","ts":"2026-07-01T02:35:54.255856Z","ts_ms":1782873354255}}

{"type":"orderbook_delta","sid":1,"seq":2344,"msg":{"market_ticker":"KXNEXTTEAMNBA-26LJAM-MIA","market_id":"492cb255-91da-4c91-bc9e-f83d090cc6dd","price_dollars":"0.0100","delta_fp":"1.00","side":"yes","ts":"2026-07-01T02:35:54.256336Z","ts_ms":1782873354256}}

{"type":"orderbook_delta","sid":1,"seq":2345,"msg":{"market_ticker":"KXNEXTTEAMNBA-26LJAM-MIA","market_id":"492cb255-91da-4c91-bc9e-f83d090cc6dd","price_dollars":"0.0100","delta_fp":"1.00","side":"yes","ts":"2026-07-01T02:35:54.256747Z","ts_ms":1782873354256}}

{"type":"orderbook_delta","sid":1,"seq":2346,"msg":{"market_ticker":"KXNEXTTEAMNBA-26LJAM-MIA","market_id":"492cb255-91da-4c91-bc9e-f83d090cc6dd","price_dollars":"0.0100","delta_fp":"1.00","side":"yes","ts":"2026-07-01T02:35:54.257177Z","ts_ms":1782873354257}}

{"type":"orderbook_delta","sid":1,"seq":2347,"msg":{"market_ticker":"KXNEXTTEAMNBA-26LJAM-MIA","market_id":"492cb255-91da-4c91-bc9e-f83d090cc6dd","price_dollars":"0.0100","delta_fp":"1.00","side":"yes","ts":"2026-07-01T02:35:54.257799Z","ts_ms":1782873354257}}

{"type":"orderbook_delta","sid":1,"seq":2348,"msg":{"market_ticker":"KXNEXTTEAMNBA-26LJAM-MIA","market_id":"492cb255-91da-4c91-bc9e-f83d090cc6dd","price_dollars":"0.0100","delta_fp":"1.00","side":"yes","ts":"2026-07-01T02:35:54.258255Z","ts_ms":1782873354258}}

{"type":"orderbook_delta","sid":1,"seq":2349,"msg":{"market_ticker":"KXNEXTTEAMNBA-26LJAM-MIA","market_id":"492cb255-91da-4c91-bc9e-f83d090cc6dd","price_dollars":"0.0100","delta_fp":"1.00","side":"yes","ts":"2026-07-01T02:35:54.258685Z","ts_ms":1782873354258}}

{"type":"orderbook_delta","sid":1,"seq":2350,"msg":{"market_ticker":"KXNEXTTEAMNBA-26LJAM-MIA","market_id":"492cb255-91da-4c91-bc9e-f83d090cc6dd","price_dollars":"0.0100","delta_fp":"1.00","side":"yes","ts":"2026-07-01T02:35:54.259095Z","ts_ms":1782873354259}}

{"type":"orderbook_delta","sid":1,"seq":2351,"msg":{"market_ticker":"KXNEXTTEAMNBA-26LJAM-MIA","market_id":"492cb255-91da-4c91-bc9e-f83d090cc6dd","price_dollars":"0.0100","delta_fp":"1.00","side":"yes","ts":"2026-07-01T02:35:54.259489Z","ts_ms":1782873354259}}

{"type":"orderbook_delta","sid":1,"seq":2352,"msg":{"market_ticker":"KXNEXTTEAMNBA-26LJAM-MIA","market_id":"492cb255-91da-4c91-bc9e-f83d090cc6dd","price_dollars":"0.0100","delta_fp":"1.00","side":"yes","ts":"2026-07-01T02:35:54.260023Z","ts_ms":1782873354260}}

{"type":"orderbook_delta","sid":1,"seq":2353,"msg":{"market_ticker":"KXNEXTTEAMNBA-26LJAM-MIA","market_id":"492cb255-91da-4c91-bc9e-f83d090cc6dd","price_dollars":"0.0100","delta_fp":"1.00","side":"yes","ts":"2026-07-01T02:35:54.260568Z","ts_ms":1782873354260}}

{"type":"orderbook_delta","sid":1,"seq":2354,"msg":{"market_ticker":"KXNEXTTEAMNBA-26LJAM-MIA","market_id":"492cb255-91da-4c91-bc9e-f83d090cc6dd","price_dollars":"0.0100","delta_fp":"1.00","side":"yes","ts":"2026-07-01T02:35:54.285815Z","ts_ms":1782873354285}}

{"type":"orderbook_delta","sid":1,"seq":2355,"msg":{"market_ticker":"KXNEXTTEAMNBA-26LJAM-GSW","market_id":"abbbad28-f309-4dd5-af38-2ad7ebf2acc3","price_dollars":"0.0100","delta_fp":"-1.00","side":"yes","ts":"2026-07-01T02:35:55.647379Z","ts_ms":1782873355647}}

{"type":"orderbook_delta","sid":1,"seq":2356,"msg":{"market_ticker":"KXNEXTTEAMNBA-26LJAM-GSW","market_id":"abbbad28-f309-4dd5-af38-2ad7ebf2acc3","price_dollars":"0.0100","delta_fp":"-1.00","side":"yes","ts":"2026-07-01T02:35:55.648345Z","ts_ms":1782873355648}}

{"type":"orderbook_delta","sid":1,"seq":2357,"msg":{"market_ticker":"KXNEXTTEAMNBA-26LJAM-GSW","market_id":"abbbad28-f309-4dd5-af38-2ad7ebf2acc3","price_dollars":"0.0100","delta_fp":"-1.00","side":"yes","ts":"2026-07-01T02:35:55.64951Z","ts_ms":1782873355649}}

{"type":"orderbook_delta","sid":1,"seq":2358,"msg":{"market_ticker":"KXNEXTTEAMNBA-26LJAM-GSW","market_id":"abbbad28-f309-4dd5-af38-2ad7ebf2acc3","price_dollars":"0.0100","delta_fp":"-1.00","side":"yes","ts":"2026-07-01T02:35:55.650267Z","ts_ms":1782873355650}}

{"type":"orderbook_delta","sid":1,"seq":2359,"msg":{"market_ticker":"KXNEXTTEAMNBA-26LJAM-GSW","market_id":"abbbad28-f309-4dd5-af38-2ad7ebf2acc3","price_dollars":"0.0100","delta_fp":"-1.00","side":"yes","ts":"2026-07-01T02:35:55.651029Z","ts_ms":1782873355651}}

{"type":"orderbook_delta","sid":1,"seq":2360,"msg":{"market_ticker":"KXNEXTTEAMNBA-26LJAM-GSW","market_id":"abbbad28-f309-4dd5-af38-2ad7ebf2acc3","price_dollars":"0.0100","delta_fp":"-1.00","side":"yes","ts":"2026-07-01T02:35:55.651806Z","ts_ms":1782873355651}}

{"type":"orderbook_delta","sid":1,"seq":2361,"msg":{"market_ticker":"KXNEXTTEAMNBA-26LJAM-GSW","market_id":"abbbad28-f309-4dd5-af38-2ad7ebf2acc3","price_dollars":"0.0100","delta_fp":"-1.00","side":"yes","ts":"2026-07-01T02:35:55.6523Z","ts_ms":1782873355652}}

{"type":"orderbook_delta","sid":1,"seq":2362,"msg":{"market_ticker":"KXNEXTTEAMNBA-26LJAM-GSW","market_id":"abbbad28-f309-4dd5-af38-2ad7ebf2acc3","price_dollars":"0.0100","delta_fp":"-1.00","side":"yes","ts":"2026-07-01T02:35:55.652853Z","ts_ms":1782873355652}}

{"type":"orderbook_delta","sid":1,"seq":2363,"msg":{"market_ticker":"KXNEXTTEAMNBA-26LJAM-GSW","market_id":"abbbad28-f309-4dd5-af38-2ad7ebf2acc3","price_dollars":"0.0100","delta_fp":"-1.00","side":"yes","ts":"2026-07-01T02:35:55.653325Z","ts_ms":1782873355653}}

{"type":"orderbook_delta","sid":1,"seq":2364,"msg":{"market_ticker":"KXNEXTTEAMNBA-26LJAM-GSW","market_id":"abbbad28-f309-4dd5-af38-2ad7ebf2acc3","price_dollars":"0.0100","delta_fp":"-1.00","side":"yes","ts":"2026-07-01T02:35:55.653741Z","ts_ms":1782873355653}}

{"type":"orderbook_delta","sid":1,"seq":2365,"msg":{"market_ticker":"KXNEXTTEAMNBA-26LJAM-GSW","market_id":"abbbad28-f309-4dd5-af38-2ad7ebf2acc3","price_dollars":"0.0100","delta_fp":"-1.00","side":"yes","ts":"2026-07-01T02:35:55.654142Z","ts_ms":1782873355654}}

{"type":"orderbook_delta","sid":1,"seq":2366,"msg":{"market_ticker":"KXNEXTTEAMNBA-26LJAM-GSW","market_id":"abbbad28-f309-4dd5-af38-2ad7ebf2acc3","price_dollars":"0.0100","delta_fp":"-1.00","side":"yes","ts":"2026-07-01T02:35:55.654643Z","ts_ms":1782873355654}}

{"type":"orderbook_delta","sid":1,"seq":2367,"msg":{"market_ticker":"KXNEXTTEAMNBA-26LJAM-GSW","market_id":"abbbad28-f309-4dd5-af38-2ad7ebf2acc3","price_dollars":"0.0100","delta_fp":"-1.00","side":"yes","ts":"2026-07-01T02:35:55.654993Z","ts_ms":1782873355654}}

{"type":"orderbook_delta","sid":1,"seq":2368,"msg":{"market_ticker":"KXNEXTTEAMNBA-26LJAM-GSW","market_id":"abbbad28-f309-4dd5-af38-2ad7ebf2acc3","price_dollars":"0.0100","delta_fp":"-1.00","side":"yes","ts":"2026-07-01T02:35:55.655452Z","ts_ms":1782873355655}}

{"type":"orderbook_delta","sid":1,"seq":2369,"msg":{"market_ticker":"KXNEXTTEAMNBA-26LJAM-GSW","market_id":"abbbad28-f309-4dd5-af38-2ad7ebf2acc3","price_dollars":"0.0100","delta_fp":"-1.00","side":"yes","ts":"2026-07-01T02:35:55.655875Z","ts_ms":1782873355655}}

{"type":"orderbook_delta","sid":1,"seq":2370,"msg":{"market_ticker":"KXNEXTTEAMNBA-26LJAM-GSW","market_id":"abbbad28-f309-4dd5-af38-2ad7ebf2acc3","price_dollars":"0.0100","delta_fp":"-1.00","side":"yes","ts":"2026-07-01T02:35:55.656335Z","ts_ms":1782873355656}}

{"type":"orderbook_delta","sid":1,"seq":2371,"msg":{"market_ticker":"KXNEXTTEAMNBA-26LJAM-GSW","market_id":"abbbad28-f309-4dd5-af38-2ad7ebf2acc3","price_dollars":"0.0100","delta_fp":"-1.00","side":"yes","ts":"2026-07-01T02:35:55.65662Z","ts_ms":1782873355656}}

{"type":"orderbook_delta","sid":1,"seq":2372,"msg":{"market_ticker":"KXNEXTTEAMNBA-26LJAM-GSW","market_id":"abbbad28-f309-4dd5-af38-2ad7ebf2acc3","price_dollars":"0.0100","delta_fp":"-1.00","side":"yes","ts":"2026-07-01T02:35:55.657168Z","ts_ms":1782873355657}}

{"type":"orderbook_delta","sid":1,"seq":2373,"msg":{"market_ticker":"KXNEXTTEAMNBA-26LJAM-GSW","market_id":"abbbad28-f309-4dd5-af38-2ad7ebf2acc3","price_dollars":"0.0100","delta_fp":"-1.00","side":"yes","ts":"2026-07-01T02:35:55.657604Z","ts_ms":1782873355657}}

{"type":"orderbook_delta","sid":1,"seq":2374,"msg":{"market_ticker":"KXNEXTTEAMNBA-26LJAM-GSW","market_id":"abbbad28-f309-4dd5-af38-2ad7ebf2acc3","price_dollars":"0.0100","delta_fp":"-1.00","side":"yes","ts":"2026-07-01T02:35:55.658019Z","ts_ms":1782873355658}}

{"type":"orderbook_delta","sid":1,"seq":2375,"msg":{"market_ticker":"KXNEXTTEAMNBA-26LJAM-GSW","market_id":"abbbad28-f309-4dd5-af38-2ad7ebf2acc3","price_dollars":"0.5200","delta_fp":"-0.08","side":"no","ts":"2026-07-01T02:35:55.695843Z","ts_ms":1782873355695}}

{"type":"orderbook_delta","sid":1,"seq":2376,"msg":{"market_ticker":"KXNEXTTEAMNBA-26LJAM-CLE","market_id":"7552b8d4-05de-4e41-84a8-97b0684da4a9","price_dollars":"0.7400","delta_fp":"-0.23","side":"no","ts":"2026-07-01T02:35:59.177747Z","ts_ms":1782873359177}}

{"type":"orderbook_delta","sid":1,"seq":2377,"msg":{"market_ticker":"KXNEXTTEAMNBA-26LJAM-GSW","market_id":"abbbad28-f309-4dd5-af38-2ad7ebf2acc3","price_dollars":"0.0100","delta_fp":"1.00","side":"yes","ts":"2026-07-01T02:36:00.24861Z","ts_ms":1782873360248}}

{"type":"orderbook_delta","sid":1,"seq":2378,"msg":{"market_ticker":"KXNEXTTEAMNBA-26LJAM-GSW","market_id":"abbbad28-f309-4dd5-af38-2ad7ebf2acc3","price_dollars":"0.0100","delta_fp":"1.00","side":"yes","ts":"2026-07-01T02:36:00.24911Z","ts_ms":1782873360249}}

{"type":"orderbook_delta","sid":1,"seq":2379,"msg":{"market_ticker":"KXNEXTTEAMNBA-26LJAM-GSW","market_id":"abbbad28-f309-4dd5-af38-2ad7ebf2acc3","price_dollars":"0.0100","delta_fp":"1.00","side":"yes","ts":"2026-07-01T02:36:00.249396Z","ts_ms":1782873360249}}

{"type":"orderbook_delta","sid":1,"seq":2380,"msg":{"market_ticker":"KXNEXTTEAMNBA-26LJAM-GSW","market_id":"abbbad28-f309-4dd5-af38-2ad7ebf2acc3","price_dollars":"0.0100","delta_fp":"1.00","side":"yes","ts":"2026-07-01T02:36:00.249851Z","ts_ms":1782873360249}}

{"type":"orderbook_delta","sid":1,"seq":2381,"msg":{"market_ticker":"KXNEXTTEAMNBA-26LJAM-GSW","market_id":"abbbad28-f309-4dd5-af38-2ad7ebf2acc3","price_dollars":"0.0100","delta_fp":"1.00","side":"yes","ts":"2026-07-01T02:36:00.250324Z","ts_ms":1782873360250}}

{"type":"orderbook_delta","sid":1,"seq":2382,"msg":{"market_ticker":"KXNEXTTEAMNBA-26LJAM-GSW","market_id":"abbbad28-f309-4dd5-af38-2ad7ebf2acc3","price_dollars":"0.0100","delta_fp":"1.00","side":"yes","ts":"2026-07-01T02:36:00.250753Z","ts_ms":1782873360250}}

{"type":"orderbook_delta","sid":1,"seq":2383,"msg":{"market_ticker":"KXNEXTTEAMNBA-26LJAM-GSW","market_id":"abbbad28-f309-4dd5-af38-2ad7ebf2acc3","price_dollars":"0.0100","delta_fp":"1.00","side":"yes","ts":"2026-07-01T02:36:00.251077Z","ts_ms":1782873360251}}

{"type":"orderbook_delta","sid":1,"seq":2384,"msg":{"market_ticker":"KXNEXTTEAMNBA-26LJAM-GSW","market_id":"abbbad28-f309-4dd5-af38-2ad7ebf2acc3","price_dollars":"0.0100","delta_fp":"1.00","side":"yes","ts":"2026-07-01T02:36:00.251493Z","ts_ms":1782873360251}}

{"type":"orderbook_delta","sid":1,"seq":2385,"msg":{"market_ticker":"KXNEXTTEAMNBA-26LJAM-GSW","market_id":"abbbad28-f309-4dd5-af38-2ad7ebf2acc3","price_dollars":"0.0100","delta_fp":"1.00","side":"yes","ts":"2026-07-01T02:36:00.25178Z","ts_ms":1782873360251}}

{"type":"orderbook_delta","sid":1,"seq":2386,"msg":{"market_ticker":"KXNEXTTEAMNBA-26LJAM-GSW","market_id":"abbbad28-f309-4dd5-af38-2ad7ebf2acc3","price_dollars":"0.0100","delta_fp":"1.00","side":"yes","ts":"2026-07-01T02:36:00.252249Z","ts_ms":1782873360252}}

{"type":"orderbook_delta","sid":1,"seq":2387,"msg":{"market_ticker":"KXNEXTTEAMNBA-26LJAM-GSW","market_id":"abbbad28-f309-4dd5-af38-2ad7ebf2acc3","price_dollars":"0.0100","delta_fp":"1.00","side":"yes","ts":"2026-07-01T02:36:00.252665Z","ts_ms":1782873360252}}

{"type":"orderbook_delta","sid":1,"seq":2388,"msg":{"market_ticker":"KXNEXTTEAMNBA-26LJAM-GSW","market_id":"abbbad28-f309-4dd5-af38-2ad7ebf2acc3","price_dollars":"0.0100","delta_fp":"1.00","side":"yes","ts":"2026-07-01T02:36:00.252957Z","ts_ms":1782873360252}}

{"type":"orderbook_delta","sid":1,"seq":2389,"msg":{"market_ticker":"KXNEXTTEAMNBA-26LJAM-GSW","market_id":"abbbad28-f309-4dd5-af38-2ad7ebf2acc3","price_dollars":"0.0100","delta_fp":"1.00","side":"yes","ts":"2026-07-01T02:36:00.253347Z","ts_ms":1782873360253}}

{"type":"orderbook_delta","sid":1,"seq":2390,"msg":{"market_ticker":"KXNEXTTEAMNBA-26LJAM-GSW","market_id":"abbbad28-f309-4dd5-af38-2ad7ebf2acc3","price_dollars":"0.0100","delta_fp":"1.00","side":"yes","ts":"2026-07-01T02:36:00.253777Z","ts_ms":1782873360253}}

{"type":"orderbook_delta","sid":1,"seq":2391,"msg":{"market_ticker":"KXNEXTTEAMNBA-26LJAM-GSW","market_id":"abbbad28-f309-4dd5-af38-2ad7ebf2acc3","price_dollars":"0.0100","delta_fp":"1.00","side":"yes","ts":"2026-07-01T02:36:00.254047Z","ts_ms":1782873360254}}

{"type":"orderbook_delta","sid":1,"seq":2392,"msg":{"market_ticker":"KXNEXTTEAMNBA-26LJAM-GSW","market_id":"abbbad28-f309-4dd5-af38-2ad7ebf2acc3","price_dollars":"0.0100","delta_fp":"1.00","side":"yes","ts":"2026-07-01T02:36:00.25454Z","ts_ms":1782873360254}}

{"type":"orderbook_delta","sid":1,"seq":2393,"msg":{"market_ticker":"KXNEXTTEAMNBA-26LJAM-GSW","market_id":"abbbad28-f309-4dd5-af38-2ad7ebf2acc3","price_dollars":"0.0100","delta_fp":"1.00","side":"yes","ts":"2026-07-01T02:36:00.254961Z","ts_ms":1782873360254}}

{"type":"orderbook_delta","sid":1,"seq":2394,"msg":{"market_ticker":"KXNEXTTEAMNBA-26LJAM-GSW","market_id":"abbbad28-f309-4dd5-af38-2ad7ebf2acc3","price_dollars":"0.0100","delta_fp":"1.00","side":"yes","ts":"2026-07-01T02:36:00.255406Z","ts_ms":1782873360255}}

{"type":"orderbook_delta","sid":1,"seq":2395,"msg":{"market_ticker":"KXNEXTTEAMNBA-26LJAM-GSW","market_id":"abbbad28-f309-4dd5-af38-2ad7ebf2acc3","price_dollars":"0.0100","delta_fp":"1.00","side":"yes","ts":"2026-07-01T02:36:00.255875Z","ts_ms":1782873360255}}

{"type":"orderbook_delta","sid":1,"seq":2396,"msg":{"market_ticker":"KXNEXTTEAMNBA-26LJAM-GSW","market_id":"abbbad28-f309-4dd5-af38-2ad7ebf2acc3","price_dollars":"0.0100","delta_fp":"1.00","side":"yes","ts":"2026-07-01T02:36:00.256325Z","ts_ms":1782873360256}}

{"type":"orderbook_delta","sid":1,"seq":2397,"msg":{"market_ticker":"KXNEXTTEAMNBA-26LJAM-CLE","market_id":"7552b8d4-05de-4e41-84a8-97b0684da4a9","price_dollars":"0.7400","delta_fp":"-1.91","side":"no","ts":"2026-07-01T02:36:00.664854Z","ts_ms":1782873360664}}

{"type":"orderbook_delta","sid":1,"seq":2398,"msg":{"market_ticker":"KXNEXTTEAMNBA-26LJAM-MIA","market_id":"492cb255-91da-4c91-bc9e-f83d090cc6dd","price_dollars":"0.8300","delta_fp":"-1.63","side":"no","ts":"2026-07-01T02:36:00.775873Z","ts_ms":1782873360775}}

{"type":"orderbook_delta","sid":1,"seq":2399,"msg":{"market_ticker":"KXNEXTTEAMNBA-26LJAM-GSW","market_id":"abbbad28-f309-4dd5-af38-2ad7ebf2acc3","price_dollars":"0.5200","delta_fp":"-0.12","side":"no","ts":"2026-07-01T02:36:00.785971Z","ts_ms":1782873360785}}

{"type":"orderbook_delta","sid":1,"seq":2400,"msg":{"market_ticker":"KXNEXTTEAMNBA-26LJAM-MIA","market_id":"492cb255-91da-4c91-bc9e-f83d090cc6dd","price_dollars":"0.0100","delta_fp":"1.00","side":"yes","ts":"2026-07-01T02:36:01.522201Z","ts_ms":1782873361522}}

{"type":"orderbook_delta","sid":1,"seq":2401,"msg":{"market_ticker":"KXNEXTTEAMNBA-26LJAM-MIA","market_id":"492cb255-91da-4c91-bc9e-f83d090cc6dd","price_dollars":"0.0100","delta_fp":"1.00","side":"yes","ts":"2026-07-01T02:36:01.522924Z","ts_ms":1782873361522}}

{"type":"orderbook_delta","sid":1,"seq":2402,"msg":{"market_ticker":"KXNEXTTEAMNBA-26LJAM-MIA","market_id":"492cb255-91da-4c91-bc9e-f83d090cc6dd","price_dollars":"0.0100","delta_fp":"1.00","side":"yes","ts":"2026-07-01T02:36:01.52352Z","ts_ms":1782873361523}}

{"type":"orderbook_delta","sid":1,"seq":2403,"msg":{"market_ticker":"KXNEXTTEAMNBA-26LJAM-MIA","market_id":"492cb255-91da-4c91-bc9e-f83d090cc6dd","price_dollars":"0.0100","delta_fp":"1.00","side":"yes","ts":"2026-07-01T02:36:01.524204Z","ts_ms":1782873361524}}

{"type":"orderbook_delta","sid":1,"seq":2404,"msg":{"market_ticker":"KXNEXTTEAMNBA-26LJAM-MIA","market_id":"492cb255-91da-4c91-bc9e-f83d090cc6dd","price_dollars":"0.0100","delta_fp":"1.00","side":"yes","ts":"2026-07-01T02:36:01.524629Z","ts_ms":1782873361524}}

{"type":"orderbook_delta","sid":1,"seq":2405,"msg":{"market_ticker":"KXNEXTTEAMNBA-26LJAM-MIA","market_id":"492cb255-91da-4c91-bc9e-f83d090cc6dd","price_dollars":"0.0100","delta_fp":"1.00","side":"yes","ts":"2026-07-01T02:36:01.525263Z","ts_ms":1782873361525}}

{"type":"orderbook_delta","sid":1,"seq":2406,"msg":{"market_ticker":"KXNEXTTEAMNBA-26LJAM-MIA","market_id":"492cb255-91da-4c91-bc9e-f83d090cc6dd","price_dollars":"0.0100","delta_fp":"1.00","side":"yes","ts":"2026-07-01T02:36:01.52573Z","ts_ms":1782873361525}}

{"type":"orderbook_delta","sid":1,"seq":2407,"msg":{"market_ticker":"KXNEXTTEAMNBA-26LJAM-MIA","market_id":"492cb255-91da-4c91-bc9e-f83d090cc6dd","price_dollars":"0.0100","delta_fp":"1.00","side":"yes","ts":"2026-07-01T02:36:01.52633Z","ts_ms":1782873361526}}

{"type":"orderbook_delta","sid":1,"seq":2408,"msg":{"market_ticker":"KXNEXTTEAMNBA-26LJAM-MIA","market_id":"492cb255-91da-4c91-bc9e-f83d090cc6dd","price_dollars":"0.0100","delta_fp":"1.00","side":"yes","ts":"2026-07-01T02:36:01.526827Z","ts_ms":1782873361526}}

{"type":"orderbook_delta","sid":1,"seq":2409,"msg":{"market_ticker":"KXNEXTTEAMNBA-26LJAM-MIA","market_id":"492cb255-91da-4c91-bc9e-f83d090cc6dd","price_dollars":"0.0100","delta_fp":"1.00","side":"yes","ts":"2026-07-01T02:36:01.527347Z","ts_ms":1782873361527}}

{"type":"orderbook_delta","sid":1,"seq":2410,"msg":{"market_ticker":"KXNEXTTEAMNBA-26LJAM-MIA","market_id":"492cb255-91da-4c91-bc9e-f83d090cc6dd","price_dollars":"0.0100","delta_fp":"1.00","side":"yes","ts":"2026-07-01T02:36:01.527852Z","ts_ms":1782873361527}}

{"type":"orderbook_delta","sid":1,"seq":2411,"msg":{"market_ticker":"KXNEXTTEAMNBA-26LJAM-MIA","market_id":"492cb255-91da-4c91-bc9e-f83d090cc6dd","price_dollars":"0.0100","delta_fp":"1.00","side":"yes","ts":"2026-07-01T02:36:01.528315Z","ts_ms":1782873361528}}

{"type":"orderbook_delta","sid":1,"seq":2412,"msg":{"market_ticker":"KXNEXTTEAMNBA-26LJAM-MIA","market_id":"492cb255-91da-4c91-bc9e-f83d090cc6dd","price_dollars":"0.0100","delta_fp":"1.00","side":"yes","ts":"2026-07-01T02:36:01.528802Z","ts_ms":1782873361528}}

{"type":"orderbook_delta","sid":1,"seq":2413,"msg":{"market_ticker":"KXNEXTTEAMNBA-26LJAM-MIA","market_id":"492cb255-91da-4c91-bc9e-f83d090cc6dd","price_dollars":"0.0100","delta_fp":"1.00","side":"yes","ts":"2026-07-01T02:36:01.529251Z","ts_ms":1782873361529}}

{"type":"orderbook_delta","sid":1,"seq":2414,"msg":{"market_ticker":"KXNEXTTEAMNBA-26LJAM-MIA","market_id":"492cb255-91da-4c91-bc9e-f83d090cc6dd","price_dollars":"0.0100","delta_fp":"1.00","side":"yes","ts":"2026-07-01T02:36:01.529934Z","ts_ms":1782873361529}}

{"type":"orderbook_delta","sid":1,"seq":2415,"msg":{"market_ticker":"KXNEXTTEAMNBA-26LJAM-MIA","market_id":"492cb255-91da-4c91-bc9e-f83d090cc6dd","price_dollars":"0.0100","delta_fp":"1.00","side":"yes","ts":"2026-07-01T02:36:01.53323Z","ts_ms":1782873361533}}

{"type":"orderbook_delta","sid":1,"seq":2416,"msg":{"market_ticker":"KXNEXTTEAMNBA-26LJAM-MIA","market_id":"492cb255-91da-4c91-bc9e-f83d090cc6dd","price_dollars":"0.0100","delta_fp":"1.00","side":"yes","ts":"2026-07-01T02:36:01.533663Z","ts_ms":1782873361533}}

{"type":"orderbook_delta","sid":1,"seq":2417,"msg":{"market_ticker":"KXNEXTTEAMNBA-26LJAM-MIA","market_id":"492cb255-91da-4c91-bc9e-f83d090cc6dd","price_dollars":"0.0100","delta_fp":"1.00","side":"yes","ts":"2026-07-01T02:36:01.534191Z","ts_ms":1782873361534}}

{"type":"orderbook_delta","sid":1,"seq":2418,"msg":{"market_ticker":"KXNEXTTEAMNBA-26LJAM-MIA","market_id":"492cb255-91da-4c91-bc9e-f83d090cc6dd","price_dollars":"0.0100","delta_fp":"1.00","side":"yes","ts":"2026-07-01T02:36:01.534786Z","ts_ms":1782873361534}}

{"type":"orderbook_delta","sid":1,"seq":2419,"msg":{"market_ticker":"KXNEXTTEAMNBA-26LJAM-MIA","market_id":"492cb255-91da-4c91-bc9e-f83d090cc6dd","price_dollars":"0.0100","delta_fp":"1.00","side":"yes","ts":"2026-07-01T02:36:01.535318Z","ts_ms":1782873361535}}

{"type":"orderbook_delta","sid":1,"seq":2420,"msg":{"market_ticker":"KXNEXTTEAMNBA-26LJAM-GSW","market_id":"abbbad28-f309-4dd5-af38-2ad7ebf2acc3","price_dollars":"0.0100","delta_fp":"-1.00","side":"yes","ts":"2026-07-01T02:36:02.167039Z","ts_ms":1782873362167}}

{"type":"orderbook_delta","sid":1,"seq":2421,"msg":{"market_ticker":"KXNEXTTEAMNBA-26LJAM-GSW","market_id":"abbbad28-f309-4dd5-af38-2ad7ebf2acc3","price_dollars":"0.0100","delta_fp":"-1.00","side":"yes","ts":"2026-07-01T02:36:02.167576Z","ts_ms":1782873362167}}

{"type":"orderbook_delta","sid":1,"seq":2422,"msg":{"market_ticker":"KXNEXTTEAMNBA-26LJAM-GSW","market_id":"abbbad28-f309-4dd5-af38-2ad7ebf2acc3","price_dollars":"0.0100","delta_fp":"-1.00","side":"yes","ts":"2026-07-01T02:36:02.168141Z","ts_ms":1782873362168}}

{"type":"orderbook_delta","sid":1,"seq":2423,"msg":{"market_ticker":"KXNEXTTEAMNBA-26LJAM-GSW","market_id":"abbbad28-f309-4dd5-af38-2ad7ebf2acc3","price_dollars":"0.0100","delta_fp":"-1.00","side":"yes","ts":"2026-07-01T02:36:02.168529Z","ts_ms":1782873362168}}

{"type":"orderbook_delta","sid":1,"seq":2424,"msg":{"market_ticker":"KXNEXTTEAMNBA-26LJAM-GSW","market_id":"abbbad28-f309-4dd5-af38-2ad7ebf2acc3","price_dollars":"0.0100","delta_fp":"-1.00","side":"yes","ts":"2026-07-01T02:36:02.169006Z","ts_ms":1782873362169}}

{"type":"orderbook_delta","sid":1,"seq":2425,"msg":{"market_ticker":"KXNEXTTEAMNBA-26LJAM-GSW","market_id":"abbbad28-f309-4dd5-af38-2ad7ebf2acc3","price_dollars":"0.0100","delta_fp":"-1.00","side":"yes","ts":"2026-07-01T02:36:02.169405Z","ts_ms":1782873362169}}

{"type":"orderbook_delta","sid":1,"seq":2426,"msg":{"market_ticker":"KXNEXTTEAMNBA-26LJAM-GSW","market_id":"abbbad28-f309-4dd5-af38-2ad7ebf2acc3","price_dollars":"0.0100","delta_fp":"-1.00","side":"yes","ts":"2026-07-01T02:36:02.169796Z","ts_ms":1782873362169}}

{"type":"orderbook_delta","sid":1,"seq":2427,"msg":{"market_ticker":"KXNEXTTEAMNBA-26LJAM-GSW","market_id":"abbbad28-f309-4dd5-af38-2ad7ebf2acc3","price_dollars":"0.0100","delta_fp":"-1.00","side":"yes","ts":"2026-07-01T02:36:02.170289Z","ts_ms":1782873362170}}

{"type":"orderbook_delta","sid":1,"seq":2428,"msg":{"market_ticker":"KXNEXTTEAMNBA-26LJAM-GSW","market_id":"abbbad28-f309-4dd5-af38-2ad7ebf2acc3","price_dollars":"0.0100","delta_fp":"-1.00","side":"yes","ts":"2026-07-01T02:36:02.170674Z","ts_ms":1782873362170}}

{"type":"orderbook_delta","sid":1,"seq":2429,"msg":{"market_ticker":"KXNEXTTEAMNBA-26LJAM-GSW","market_id":"abbbad28-f309-4dd5-af38-2ad7ebf2acc3","price_dollars":"0.0100","delta_fp":"-1.00","side":"yes","ts":"2026-07-01T02:36:02.17121Z","ts_ms":1782873362171}}

{"type":"orderbook_delta","sid":1,"seq":2430,"msg":{"market_ticker":"KXNEXTTEAMNBA-26LJAM-GSW","market_id":"abbbad28-f309-4dd5-af38-2ad7ebf2acc3","price_dollars":"0.0100","delta_fp":"-1.00","side":"yes","ts":"2026-07-01T02:36:02.171579Z","ts_ms":1782873362171}}

{"type":"orderbook_delta","sid":1,"seq":2431,"msg":{"market_ticker":"KXNEXTTEAMNBA-26LJAM-GSW","market_id":"abbbad28-f309-4dd5-af38-2ad7ebf2acc3","price_dollars":"0.0100","delta_fp":"-1.00","side":"yes","ts":"2026-07-01T02:36:02.17188Z","ts_ms":1782873362171}}

{"type":"orderbook_delta","sid":1,"seq":2432,"msg":{"market_ticker":"KXNEXTTEAMNBA-26LJAM-GSW","market_id":"abbbad28-f309-4dd5-af38-2ad7ebf2acc3","price_dollars":"0.0100","delta_fp":"-1.00","side":"yes","ts":"2026-07-01T02:36:02.172215Z","ts_ms":1782873362172}}

{"type":"orderbook_delta","sid":1,"seq":2433,"msg":{"market_ticker":"KXNEXTTEAMNBA-26LJAM-GSW","market_id":"abbbad28-f309-4dd5-af38-2ad7ebf2acc3","price_dollars":"0.0100","delta_fp":"-1.00","side":"yes","ts":"2026-07-01T02:36:02.17255Z","ts_ms":1782873362172}}

{"type":"orderbook_delta","sid":1,"seq":2434,"msg":{"market_ticker":"KXNEXTTEAMNBA-26LJAM-GSW","market_id":"abbbad28-f309-4dd5-af38-2ad7ebf2acc3","price_dollars":"0.0100","delta_fp":"-1.00","side":"yes","ts":"2026-07-01T02:36:02.172848Z","ts_ms":1782873362172}}

{"type":"orderbook_delta","sid":1,"seq":2435,"msg":{"market_ticker":"KXNEXTTEAMNBA-26LJAM-GSW","market_id":"abbbad28-f309-4dd5-af38-2ad7ebf2acc3","price_dollars":"0.0100","delta_fp":"-1.00","side":"yes","ts":"2026-07-01T02:36:02.173161Z","ts_ms":1782873362173}}

{"type":"orderbook_delta","sid":1,"seq":2436,"msg":{"market_ticker":"KXNEXTTEAMNBA-26LJAM-GSW","market_id":"abbbad28-f309-4dd5-af38-2ad7ebf2acc3","price_dollars":"0.0100","delta_fp":"-1.00","side":"yes","ts":"2026-07-01T02:36:02.173436Z","ts_ms":1782873362173}}

{"type":"orderbook_delta","sid":1,"seq":2437,"msg":{"market_ticker":"KXNEXTTEAMNBA-26LJAM-GSW","market_id":"abbbad28-f309-4dd5-af38-2ad7ebf2acc3","price_dollars":"0.0100","delta_fp":"-1.00","side":"yes","ts":"2026-07-01T02:36:02.17372Z","ts_ms":1782873362173}}

{"type":"orderbook_delta","sid":1,"seq":2438,"msg":{"market_ticker":"KXNEXTTEAMNBA-26LJAM-GSW","market_id":"abbbad28-f309-4dd5-af38-2ad7ebf2acc3","price_dollars":"0.0100","delta_fp":"-1.00","side":"yes","ts":"2026-07-01T02:36:02.173997Z","ts_ms":1782873362173}}

{"type":"orderbook_delta","sid":1,"seq":2439,"msg":{"market_ticker":"KXNEXTTEAMNBA-26LJAM-GSW","market_id":"abbbad28-f309-4dd5-af38-2ad7ebf2acc3","price_dollars":"0.0100","delta_fp":"-1.00","side":"yes","ts":"2026-07-01T02:36:02.174243Z","ts_ms":1782873362174}}

{"type":"orderbook_delta","sid":1,"seq":2440,"msg":{"market_ticker":"KXNEXTTEAMNBA-26LJAM-MIA","market_id":"492cb255-91da-4c91-bc9e-f83d090cc6dd","price_dollars":"0.8300","delta_fp":"-1.36","side":"no","ts":"2026-07-01T02:36:02.393907Z","ts_ms":1782873362393}}

{"type":"orderbook_delta","sid":1,"seq":2441,"msg":{"market_ticker":"KXNEXTTEAMNBA-26LJAM-CLE","market_id":"7552b8d4-05de-4e41-84a8-97b0684da4a9","price_dollars":"0.7400","delta_fp":"-1.41","side":"no","ts":"2026-07-01T02:36:02.490642Z","ts_ms":1782873362490}}

{"type":"orderbook_delta","sid":1,"seq":2442,"msg":{"market_ticker":"KXNEXTTEAMNBA-26LJAM-GSW","market_id":"abbbad28-f309-4dd5-af38-2ad7ebf2acc3","price_dollars":"0.5200","delta_fp":"-0.27","side":"no","ts":"2026-07-01T02:36:02.490771Z","ts_ms":1782873362490}}

{"type":"orderbook_delta","sid":1,"seq":2443,"msg":{"market_ticker":"KXNEXTTEAMNBA-26LJAM-GSW","market_id":"abbbad28-f309-4dd5-af38-2ad7ebf2acc3","price_dollars":"0.5200","delta_fp":"-0.16","side":"no","ts":"2026-07-01T02:36:02.500122Z","ts_ms":1782873362500}}

{"type":"orderbook_delta","sid":1,"seq":2444,"msg":{"market_ticker":"KXNEXTTEAMNBA-26LJAM-CLE","market_id":"7552b8d4-05de-4e41-84a8-97b0684da4a9","price_dollars":"0.7400","delta_fp":"-0.03","side":"no","ts":"2026-07-01T02:36:03.863915Z","ts_ms":1782873363863}}

{"type":"orderbook_delta","sid":1,"seq":2445,"msg":{"market_ticker":"KXNEXTTEAMNBA-26LJAM-GSW","market_id":"abbbad28-f309-4dd5-af38-2ad7ebf2acc3","price_dollars":"0.0100","delta_fp":"1.00","side":"yes","ts":"2026-07-01T02:36:06.936862Z","ts_ms":1782873366936}}

{"type":"orderbook_delta","sid":1,"seq":2446,"msg":{"market_ticker":"KXNEXTTEAMNBA-26LJAM-GSW","market_id":"abbbad28-f309-4dd5-af38-2ad7ebf2acc3","price_dollars":"0.0100","delta_fp":"1.00","side":"yes","ts":"2026-07-01T02:36:06.937978Z","ts_ms":1782873366937}}

{"type":"orderbook_delta","sid":1,"seq":2447,"msg":{"market_ticker":"KXNEXTTEAMNBA-26LJAM-GSW","market_id":"abbbad28-f309-4dd5-af38-2ad7ebf2acc3","price_dollars":"0.0100","delta_fp":"1.00","side":"yes","ts":"2026-07-01T02:36:06.938702Z","ts_ms":1782873366938}}

{"type":"orderbook_delta","sid":1,"seq":2448,"msg":{"market_ticker":"KXNEXTTEAMNBA-26LJAM-GSW","market_id":"abbbad28-f309-4dd5-af38-2ad7ebf2acc3","price_dollars":"0.0100","delta_fp":"1.00","side":"yes","ts":"2026-07-01T02:36:06.939508Z","ts_ms":1782873366939}}

{"type":"orderbook_delta","sid":1,"seq":2449,"msg":{"market_ticker":"KXNEXTTEAMNBA-26LJAM-GSW","market_id":"abbbad28-f309-4dd5-af38-2ad7ebf2acc3","price_dollars":"0.0100","delta_fp":"1.00","side":"yes","ts":"2026-07-01T02:36:06.940356Z","ts_ms":1782873366940}}

{"type":"orderbook_delta","sid":1,"seq":2450,"msg":{"market_ticker":"KXNEXTTEAMNBA-26LJAM-GSW","market_id":"abbbad28-f309-4dd5-af38-2ad7ebf2acc3","price_dollars":"0.0100","delta_fp":"1.00","side":"yes","ts":"2026-07-01T02:36:06.941157Z","ts_ms":1782873366941}}

{"type":"orderbook_delta","sid":1,"seq":2451,"msg":{"market_ticker":"KXNEXTTEAMNBA-26LJAM-GSW","market_id":"abbbad28-f309-4dd5-af38-2ad7ebf2acc3","price_dollars":"0.0100","delta_fp":"1.00","side":"yes","ts":"2026-07-01T02:36:06.942129Z","ts_ms":1782873366942}}

{"type":"orderbook_delta","sid":1,"seq":2452,"msg":{"market_ticker":"KXNEXTTEAMNBA-26LJAM-GSW","market_id":"abbbad28-f309-4dd5-af38-2ad7ebf2acc3","price_dollars":"0.0100","delta_fp":"1.00","side":"yes","ts":"2026-07-01T02:36:06.942879Z","ts_ms":1782873366942}}

{"type":"orderbook_delta","sid":1,"seq":2453,"msg":{"market_ticker":"KXNEXTTEAMNBA-26LJAM-GSW","market_id":"abbbad28-f309-4dd5-af38-2ad7ebf2acc3","price_dollars":"0.0100","delta_fp":"1.00","side":"yes","ts":"2026-07-01T02:36:06.943702Z","ts_ms":1782873366943}}

{"type":"orderbook_delta","sid":1,"seq":2454,"msg":{"market_ticker":"KXNEXTTEAMNBA-26LJAM-GSW","market_id":"abbbad28-f309-4dd5-af38-2ad7ebf2acc3","price_dollars":"0.0100","delta_fp":"1.00","side":"yes","ts":"2026-07-01T02:36:06.944605Z","ts_ms":1782873366944}}

{"type":"orderbook_delta","sid":1,"seq":2455,"msg":{"market_ticker":"KXNEXTTEAMNBA-26LJAM-GSW","market_id":"abbbad28-f309-4dd5-af38-2ad7ebf2acc3","price_dollars":"0.0100","delta_fp":"1.00","side":"yes","ts":"2026-07-01T02:36:06.945416Z","ts_ms":1782873366945}}

{"type":"orderbook_delta","sid":1,"seq":2456,"msg":{"market_ticker":"KXNEXTTEAMNBA-26LJAM-GSW","market_id":"abbbad28-f309-4dd5-af38-2ad7ebf2acc3","price_dollars":"0.0100","delta_fp":"1.00","side":"yes","ts":"2026-07-01T02:36:06.946209Z","ts_ms":1782873366946}}

{"type":"orderbook_delta","sid":1,"seq":2457,"msg":{"market_ticker":"KXNEXTTEAMNBA-26LJAM-GSW","market_id":"abbbad28-f309-4dd5-af38-2ad7ebf2acc3","price_dollars":"0.0100","delta_fp":"1.00","side":"yes","ts":"2026-07-01T02:36:06.946985Z","ts_ms":1782873366946}}

{"type":"orderbook_delta","sid":1,"seq":2458,"msg":{"market_ticker":"KXNEXTTEAMNBA-26LJAM-GSW","market_id":"abbbad28-f309-4dd5-af38-2ad7ebf2acc3","price_dollars":"0.0100","delta_fp":"1.00","side":"yes","ts":"2026-07-01T02:36:06.947734Z","ts_ms":1782873366947}}

{"type":"orderbook_delta","sid":1,"seq":2459,"msg":{"market_ticker":"KXNEXTTEAMNBA-26LJAM-GSW","market_id":"abbbad28-f309-4dd5-af38-2ad7ebf2acc3","price_dollars":"0.0100","delta_fp":"1.00","side":"yes","ts":"2026-07-01T02:36:06.948581Z","ts_ms":1782873366948}}

{"type":"orderbook_delta","sid":1,"seq":2460,"msg":{"market_ticker":"KXNEXTTEAMNBA-26LJAM-GSW","market_id":"abbbad28-f309-4dd5-af38-2ad7ebf2acc3","price_dollars":"0.0100","delta_fp":"1.00","side":"yes","ts":"2026-07-01T02:36:06.949292Z","ts_ms":1782873366949}}

{"type":"orderbook_delta","sid":1,"seq":2461,"msg":{"market_ticker":"KXNEXTTEAMNBA-26LJAM-GSW","market_id":"abbbad28-f309-4dd5-af38-2ad7ebf2acc3","price_dollars":"0.0100","delta_fp":"1.00","side":"yes","ts":"2026-07-01T02:36:06.950142Z","ts_ms":1782873366950}}

{"type":"orderbook_delta","sid":1,"seq":2462,"msg":{"market_ticker":"KXNEXTTEAMNBA-26LJAM-GSW","market_id":"abbbad28-f309-4dd5-af38-2ad7ebf2acc3","price_dollars":"0.0100","delta_fp":"1.00","side":"yes","ts":"2026-07-01T02:36:06.950769Z","ts_ms":1782873366950}}

{"type":"orderbook_delta","sid":1,"seq":2463,"msg":{"market_ticker":"KXNEXTTEAMNBA-26LJAM-GSW","market_id":"abbbad28-f309-4dd5-af38-2ad7ebf2acc3","price_dollars":"0.0100","delta_fp":"1.00","side":"yes","ts":"2026-07-01T02:36:06.951395Z","ts_ms":1782873366951}}

{"type":"orderbook_delta","sid":1,"seq":2464,"msg":{"market_ticker":"KXNEXTTEAMNBA-26LJAM-GSW","market_id":"abbbad28-f309-4dd5-af38-2ad7ebf2acc3","price_dollars":"0.0100","delta_fp":"1.00","side":"yes","ts":"2026-07-01T02:36:06.951938Z","ts_ms":1782873366951}}

{"type":"orderbook_delta","sid":1,"seq":2465,"msg":{"market_ticker":"KXNEXTTEAMNBA-26LJAM-MIA","market_id":"492cb255-91da-4c91-bc9e-f83d090cc6dd","price_dollars":"0.8300","delta_fp":"-1.65","side":"no","ts":"2026-07-01T02:36:07.325772Z","ts_ms":1782873367325}}

{"type":"orderbook_delta","sid":1,"seq":2466,"msg":{"market_ticker":"KXNEXTTEAMNBA-26LJAM-CLE","market_id":"7552b8d4-05de-4e41-84a8-97b0684da4a9","price_dollars":"0.0100","delta_fp":"1.00","side":"yes","ts":"2026-07-01T02:36:08.163944Z","ts_ms":1782873368163}}

{"type":"orderbook_delta","sid":1,"seq":2467,"msg":{"market_ticker":"KXNEXTTEAMNBA-26LJAM-CLE","market_id":"7552b8d4-05de-4e41-84a8-97b0684da4a9","price_dollars":"0.7400","delta_fp":"-0.89","side":"no","ts":"2026-07-01T02:36:09.07906Z","ts_ms":1782873369079}}

{"type":"orderbook_delta","sid":1,"seq":2468,"msg":{"market_ticker":"KXNEXTTEAMNBA-26LJAM-MIA","market_id":"492cb255-91da-4c91-bc9e-f83d090cc6dd","price_dollars":"0.1600","delta_fp":"2083.33","side":"yes","ts":"2026-07-01T02:36:10.123993Z","ts_ms":1782873370123}}

{"type":"orderbook_delta","sid":1,"seq":2469,"msg":{"market_ticker":"KXNEXTTEAMNBA-26LJAM-MIA","market_id":"492cb255-91da-4c91-bc9e-f83d090cc6dd","price_dollars":"0.1500","delta_fp":"2222.22","side":"yes","ts":"2026-07-01T02:36:10.124559Z","ts_ms":1782873370124}}

{"type":"orderbook_delta","sid":1,"seq":2470,"msg":{"market_ticker":"KXNEXTTEAMNBA-26LJAM-MIA","market_id":"492cb255-91da-4c91-bc9e-f83d090cc6dd","price_dollars":"0.1400","delta_fp":"2380.95","side":"yes","ts":"2026-07-01T02:36:10.125099Z","ts_ms":1782873370125}}

{"type":"orderbook_delta","sid":1,"seq":2471,"msg":{"market_ticker":"KXNEXTTEAMNBA-26LJAM-MIA","market_id":"492cb255-91da-4c91-bc9e-f83d090cc6dd","price_dollars":"0.8300","delta_fp":"1960.78","side":"no","ts":"2026-07-01T02:36:10.12573Z","ts_ms":1782873370125}}

{"type":"orderbook_delta","sid":1,"seq":2472,"msg":{"market_ticker":"KXNEXTTEAMNBA-26LJAM-MIA","market_id":"492cb255-91da-4c91-bc9e-f83d090cc6dd","price_dollars":"0.8200","delta_fp":"1851.85","side":"no","ts":"2026-07-01T02:36:10.126209Z","ts_ms":1782873370126}}

{"type":"orderbook_delta","sid":1,"seq":2473,"msg":{"market_ticker":"KXNEXTTEAMNBA-26LJAM-MIA","market_id":"492cb255-91da-4c91-bc9e-f83d090cc6dd","price_dollars":"0.8100","delta_fp":"1754.38","side":"no","ts":"2026-07-01T02:36:10.126634Z","ts_ms":1782873370126}}

{"type":"orderbook_delta","sid":1,"seq":2474,"msg":{"market_ticker":"KXNEXTTEAMNBA-26LJAM-GSW","market_id":"abbbad28-f309-4dd5-af38-2ad7ebf2acc3","price_dollars":"0.5200","delta_fp":"-0.21","side":"no","ts":"2026-07-01T02:36:10.38403Z","ts_ms":1782873370384}}

{"type":"orderbook_delta","sid":1,"seq":2475,"msg":{"market_ticker":"KXNEXTTEAMNBA-26LJAM-CLE","market_id":"7552b8d4-05de-4e41-84a8-97b0684da4a9","price_dollars":"0.7400","delta_fp":"-1.26","side":"no","ts":"2026-07-01T02:36:12.253493Z","ts_ms":1782873372253}}

{"type":"orderbook_delta","sid":1,"seq":2476,"msg":{"market_ticker":"KXNEXTTEAMNBA-26LJAM-MIA","market_id":"492cb255-91da-4c91-bc9e-f83d090cc6dd","price_dollars":"0.8300","delta_fp":"-0.39","side":"no","ts":"2026-07-01T02:36:12.264818Z","ts_ms":1782873372264}}

{"type":"orderbook_delta","sid":1,"seq":2477,"msg":{"market_ticker":"KXNEXTTEAMNBA-26LJAM-GSW","market_id":"abbbad28-f309-4dd5-af38-2ad7ebf2acc3","price_dollars":"0.0100","delta_fp":"1.00","side":"yes","ts":"2026-07-01T02:36:13.259018Z","ts_ms":1782873373259}}

{"type":"orderbook_delta","sid":1,"seq":2478,"msg":{"market_ticker":"KXNEXTTEAMNBA-26LJAM-GSW","market_id":"abbbad28-f309-4dd5-af38-2ad7ebf2acc3","price_dollars":"0.0100","delta_fp":"1.00","side":"yes","ts":"2026-07-01T02:36:13.259935Z","ts_ms":1782873373259}}

{"type":"orderbook_delta","sid":1,"seq":2479,"msg":{"market_ticker":"KXNEXTTEAMNBA-26LJAM-GSW","market_id":"abbbad28-f309-4dd5-af38-2ad7ebf2acc3","price_dollars":"0.0100","delta_fp":"1.00","side":"yes","ts":"2026-07-01T02:36:13.260606Z","ts_ms":1782873373260}}

{"type":"orderbook_delta","sid":1,"seq":2480,"msg":{"market_ticker":"KXNEXTTEAMNBA-26LJAM-GSW","market_id":"abbbad28-f309-4dd5-af38-2ad7ebf2acc3","price_dollars":"0.0100","delta_fp":"1.00","side":"yes","ts":"2026-07-01T02:36:13.26211Z","ts_ms":1782873373262}}

{"type":"orderbook_delta","sid":1,"seq":2481,"msg":{"market_ticker":"KXNEXTTEAMNBA-26LJAM-GSW","market_id":"abbbad28-f309-4dd5-af38-2ad7ebf2acc3","price_dollars":"0.0100","delta_fp":"1.00","side":"yes","ts":"2026-07-01T02:36:13.263107Z","ts_ms":1782873373263}}

{"type":"orderbook_delta","sid":1,"seq":2482,"msg":{"market_ticker":"KXNEXTTEAMNBA-26LJAM-GSW","market_id":"abbbad28-f309-4dd5-af38-2ad7ebf2acc3","price_dollars":"0.0100","delta_fp":"1.00","side":"yes","ts":"2026-07-01T02:36:13.26435Z","ts_ms":1782873373264}}

{"type":"orderbook_delta","sid":1,"seq":2483,"msg":{"market_ticker":"KXNEXTTEAMNBA-26LJAM-GSW","market_id":"abbbad28-f309-4dd5-af38-2ad7ebf2acc3","price_dollars":"0.0100","delta_fp":"1.00","side":"yes","ts":"2026-07-01T02:36:13.265085Z","ts_ms":1782873373265}}

{"type":"orderbook_delta","sid":1,"seq":2484,"msg":{"market_ticker":"KXNEXTTEAMNBA-26LJAM-GSW","market_id":"abbbad28-f309-4dd5-af38-2ad7ebf2acc3","price_dollars":"0.0100","delta_fp":"1.00","side":"yes","ts":"2026-07-01T02:36:13.266007Z","ts_ms":1782873373266}}

{"type":"orderbook_delta","sid":1,"seq":2485,"msg":{"market_ticker":"KXNEXTTEAMNBA-26LJAM-GSW","market_id":"abbbad28-f309-4dd5-af38-2ad7ebf2acc3","price_dollars":"0.0100","delta_fp":"1.00","side":"yes","ts":"2026-07-01T02:36:13.26697Z","ts_ms":1782873373266}}

{"type":"orderbook_delta","sid":1,"seq":2486,"msg":{"market_ticker":"KXNEXTTEAMNBA-26LJAM-GSW","market_id":"abbbad28-f309-4dd5-af38-2ad7ebf2acc3","price_dollars":"0.0100","delta_fp":"1.00","side":"yes","ts":"2026-07-01T02:36:13.267818Z","ts_ms":1782873373267}}

{"type":"orderbook_delta","sid":1,"seq":2487,"msg":{"market_ticker":"KXNEXTTEAMNBA-26LJAM-GSW","market_id":"abbbad28-f309-4dd5-af38-2ad7ebf2acc3","price_dollars":"0.0100","delta_fp":"1.00","side":"yes","ts":"2026-07-01T02:36:13.268602Z","ts_ms":1782873373268}}

{"type":"orderbook_delta","sid":1,"seq":2488,"msg":{"market_ticker":"KXNEXTTEAMNBA-26LJAM-GSW","market_id":"abbbad28-f309-4dd5-af38-2ad7ebf2acc3","price_dollars":"0.0100","delta_fp":"1.00","side":"yes","ts":"2026-07-01T02:36:13.269253Z","ts_ms":1782873373269}}

{"type":"orderbook_delta","sid":1,"seq":2489,"msg":{"market_ticker":"KXNEXTTEAMNBA-26LJAM-GSW","market_id":"abbbad28-f309-4dd5-af38-2ad7ebf2acc3","price_dollars":"0.0100","delta_fp":"1.00","side":"yes","ts":"2026-07-01T02:36:13.270089Z","ts_ms":1782873373270}}

{"type":"orderbook_delta","sid":1,"seq":2490,"msg":{"market_ticker":"KXNEXTTEAMNBA-26LJAM-GSW","market_id":"abbbad28-f309-4dd5-af38-2ad7ebf2acc3","price_dollars":"0.0100","delta_fp":"1.00","side":"yes","ts":"2026-07-01T02:36:13.270783Z","ts_ms":1782873373270}}

{"type":"orderbook_delta","sid":1,"seq":2491,"msg":{"market_ticker":"KXNEXTTEAMNBA-26LJAM-GSW","market_id":"abbbad28-f309-4dd5-af38-2ad7ebf2acc3","price_dollars":"0.0100","delta_fp":"1.00","side":"yes","ts":"2026-07-01T02:36:13.271356Z","ts_ms":1782873373271}}

{"type":"orderbook_delta","sid":1,"seq":2492,"msg":{"market_ticker":"KXNEXTTEAMNBA-26LJAM-GSW","market_id":"abbbad28-f309-4dd5-af38-2ad7ebf2acc3","price_dollars":"0.0100","delta_fp":"1.00","side":"yes","ts":"2026-07-01T02:36:13.272058Z","ts_ms":1782873373272}}

{"type":"orderbook_delta","sid":1,"seq":2493,"msg":{"market_ticker":"KXNEXTTEAMNBA-26LJAM-GSW","market_id":"abbbad28-f309-4dd5-af38-2ad7ebf2acc3","price_dollars":"0.0100","delta_fp":"1.00","side":"yes","ts":"2026-07-01T02:36:13.272478Z","ts_ms":1782873373272}}

{"type":"orderbook_delta","sid":1,"seq":2494,"msg":{"market_ticker":"KXNEXTTEAMNBA-26LJAM-GSW","market_id":"abbbad28-f309-4dd5-af38-2ad7ebf2acc3","price_dollars":"0.0100","delta_fp":"1.00","side":"yes","ts":"2026-07-01T02:36:13.272835Z","ts_ms":1782873373272}}

{"type":"orderbook_delta","sid":1,"seq":2495,"msg":{"market_ticker":"KXNEXTTEAMNBA-26LJAM-GSW","market_id":"abbbad28-f309-4dd5-af38-2ad7ebf2acc3","price_dollars":"0.0100","delta_fp":"1.00","side":"yes","ts":"2026-07-01T02:36:13.273302Z","ts_ms":1782873373273}}

{"type":"orderbook_delta","sid":1,"seq":2496,"msg":{"market_ticker":"KXNEXTTEAMNBA-26LJAM-GSW","market_id":"abbbad28-f309-4dd5-af38-2ad7ebf2acc3","price_dollars":"0.0100","delta_fp":"1.00","side":"yes","ts":"2026-07-01T02:36:13.273726Z","ts_ms":1782873373273}}

{"type":"orderbook_delta","sid":1,"seq":2497,"msg":{"market_ticker":"KXNEXTTEAMNBA-26LJAM-GSW","market_id":"abbbad28-f309-4dd5-af38-2ad7ebf2acc3","price_dollars":"0.5200","delta_fp":"-1.06","side":"no","ts":"2026-07-01T02:36:13.592558Z","ts_ms":1782873373592}}

{"type":"orderbook_delta","sid":1,"seq":2498,"msg":{"market_ticker":"KXNEXTTEAMNBA-26LJAM-CLE","market_id":"7552b8d4-05de-4e41-84a8-97b0684da4a9","price_dollars":"0.7400","delta_fp":"-1.90","side":"no","ts":"2026-07-01T02:36:13.772565Z","ts_ms":1782873373772}}

{"type":"orderbook_delta","sid":1,"seq":2499,"msg":{"market_ticker":"KXNEXTTEAMNBA-26LJAM-MIA","market_id":"492cb255-91da-4c91-bc9e-f83d090cc6dd","price_dollars":"0.0100","delta_fp":"1.00","side":"yes","ts":"2026-07-01T02:36:15.015513Z","ts_ms":1782873375015}}

{"type":"orderbook_delta","sid":1,"seq":2500,"msg":{"market_ticker":"KXNEXTTEAMNBA-26LJAM-MIA","market_id":"492cb255-91da-4c91-bc9e-f83d090cc6dd","price_dollars":"0.0100","delta_fp":"1.00","side":"yes","ts":"2026-07-01T02:36:15.015831Z","ts_ms":1782873375015}}

{"type":"orderbook_delta","sid":1,"seq":2501,"msg":{"market_ticker":"KXNEXTTEAMNBA-26LJAM-MIA","market_id":"492cb255-91da-4c91-bc9e-f83d090cc6dd","price_dollars":"0.0100","delta_fp":"1.00","side":"yes","ts":"2026-07-01T02:36:15.016122Z","ts_ms":1782873375016}}

{"type":"orderbook_delta","sid":1,"seq":2502,"msg":{"market_ticker":"KXNEXTTEAMNBA-26LJAM-MIA","market_id":"492cb255-91da-4c91-bc9e-f83d090cc6dd","price_dollars":"0.0100","delta_fp":"1.00","side":"yes","ts":"2026-07-01T02:36:15.016472Z","ts_ms":1782873375016}}

{"type":"orderbook_delta","sid":1,"seq":2503,"msg":{"market_ticker":"KXNEXTTEAMNBA-26LJAM-MIA","market_id":"492cb255-91da-4c91-bc9e-f83d090cc6dd","price_dollars":"0.0100","delta_fp":"1.00","side":"yes","ts":"2026-07-01T02:36:15.016771Z","ts_ms":1782873375016}}

{"type":"orderbook_delta","sid":1,"seq":2504,"msg":{"market_ticker":"KXNEXTTEAMNBA-26LJAM-MIA","market_id":"492cb255-91da-4c91-bc9e-f83d090cc6dd","price_dollars":"0.0100","delta_fp":"1.00","side":"yes","ts":"2026-07-01T02:36:15.017013Z","ts_ms":1782873375017}}

{"type":"orderbook_delta","sid":1,"seq":2505,"msg":{"market_ticker":"KXNEXTTEAMNBA-26LJAM-MIA","market_id":"492cb255-91da-4c91-bc9e-f83d090cc6dd","price_dollars":"0.0100","delta_fp":"1.00","side":"yes","ts":"2026-07-01T02:36:15.017264Z","ts_ms":1782873375017}}

{"type":"orderbook_delta","sid":1,"seq":2506,"msg":{"market_ticker":"KXNEXTTEAMNBA-26LJAM-MIA","market_id":"492cb255-91da-4c91-bc9e-f83d090cc6dd","price_dollars":"0.0100","delta_fp":"1.00","side":"yes","ts":"2026-07-01T02:36:15.017614Z","ts_ms":1782873375017}}

{"type":"orderbook_delta","sid":1,"seq":2507,"msg":{"market_ticker":"KXNEXTTEAMNBA-26LJAM-MIA","market_id":"492cb255-91da-4c91-bc9e-f83d090cc6dd","price_dollars":"0.0100","delta_fp":"1.00","side":"yes","ts":"2026-07-01T02:36:15.017919Z","ts_ms":1782873375017}}

{"type":"orderbook_delta","sid":1,"seq":2508,"msg":{"market_ticker":"KXNEXTTEAMNBA-26LJAM-MIA","market_id":"492cb255-91da-4c91-bc9e-f83d090cc6dd","price_dollars":"0.0100","delta_fp":"1.00","side":"yes","ts":"2026-07-01T02:36:15.01822Z","ts_ms":1782873375018}}

{"type":"orderbook_delta","sid":1,"seq":2509,"msg":{"market_ticker":"KXNEXTTEAMNBA-26LJAM-MIA","market_id":"492cb255-91da-4c91-bc9e-f83d090cc6dd","price_dollars":"0.0100","delta_fp":"1.00","side":"yes","ts":"2026-07-01T02:36:15.01848Z","ts_ms":1782873375018}}

{"type":"orderbook_delta","sid":1,"seq":2510,"msg":{"market_ticker":"KXNEXTTEAMNBA-26LJAM-MIA","market_id":"492cb255-91da-4c91-bc9e-f83d090cc6dd","price_dollars":"0.0100","delta_fp":"1.00","side":"yes","ts":"2026-07-01T02:36:15.018785Z","ts_ms":1782873375018}}

{"type":"orderbook_delta","sid":1,"seq":2511,"msg":{"market_ticker":"KXNEXTTEAMNBA-26LJAM-MIA","market_id":"492cb255-91da-4c91-bc9e-f83d090cc6dd","price_dollars":"0.0100","delta_fp":"1.00","side":"yes","ts":"2026-07-01T02:36:15.01904Z","ts_ms":1782873375019}}

{"type":"orderbook_delta","sid":1,"seq":2512,"msg":{"market_ticker":"KXNEXTTEAMNBA-26LJAM-MIA","market_id":"492cb255-91da-4c91-bc9e-f83d090cc6dd","price_dollars":"0.0100","delta_fp":"1.00","side":"yes","ts":"2026-07-01T02:36:15.019252Z","ts_ms":1782873375019}}

{"type":"orderbook_delta","sid":1,"seq":2513,"msg":{"market_ticker":"KXNEXTTEAMNBA-26LJAM-MIA","market_id":"492cb255-91da-4c91-bc9e-f83d090cc6dd","price_dollars":"0.0100","delta_fp":"1.00","side":"yes","ts":"2026-07-01T02:36:15.019511Z","ts_ms":1782873375019}}

{"type":"orderbook_delta","sid":1,"seq":2514,"msg":{"market_ticker":"KXNEXTTEAMNBA-26LJAM-MIA","market_id":"492cb255-91da-4c91-bc9e-f83d090cc6dd","price_dollars":"0.0100","delta_fp":"1.00","side":"yes","ts":"2026-07-01T02:36:15.019842Z","ts_ms":1782873375019}}

{"type":"orderbook_delta","sid":1,"seq":2515,"msg":{"market_ticker":"KXNEXTTEAMNBA-26LJAM-MIA","market_id":"492cb255-91da-4c91-bc9e-f83d090cc6dd","price_dollars":"0.0100","delta_fp":"1.00","side":"yes","ts":"2026-07-01T02:36:15.020127Z","ts_ms":1782873375020}}

{"type":"orderbook_delta","sid":1,"seq":2516,"msg":{"market_ticker":"KXNEXTTEAMNBA-26LJAM-MIA","market_id":"492cb255-91da-4c91-bc9e-f83d090cc6dd","price_dollars":"0.0100","delta_fp":"1.00","side":"yes","ts":"2026-07-01T02:36:15.020518Z","ts_ms":1782873375020}}

{"type":"orderbook_delta","sid":1,"seq":2517,"msg":{"market_ticker":"KXNEXTTEAMNBA-26LJAM-MIA","market_id":"492cb255-91da-4c91-bc9e-f83d090cc6dd","price_dollars":"0.0100","delta_fp":"1.00","side":"yes","ts":"2026-07-01T02:36:15.020847Z","ts_ms":1782873375020}}

{"type":"orderbook_delta","sid":1,"seq":2518,"msg":{"market_ticker":"KXNEXTTEAMNBA-26LJAM-MIA","market_id":"492cb255-91da-4c91-bc9e-f83d090cc6dd","price_dollars":"0.0100","delta_fp":"1.00","side":"yes","ts":"2026-07-01T02:36:15.021156Z","ts_ms":1782873375021}}

{"type":"orderbook_delta","sid":1,"seq":2519,"msg":{"market_ticker":"KXNEXTTEAMNBA-26LJAM-MIA","market_id":"492cb255-91da-4c91-bc9e-f83d090cc6dd","price_dollars":"0.8300","delta_fp":"-0.15","side":"no","ts":"2026-07-01T02:36:15.460648Z","ts_ms":1782873375460}}

{"type":"orderbook_delta","sid":1,"seq":2520,"msg":{"market_ticker":"KXNEXTTEAMNBA-26LJAM-GSW","market_id":"abbbad28-f309-4dd5-af38-2ad7ebf2acc3","price_dollars":"0.5200","delta_fp":"-1.10","side":"no","ts":"2026-07-01T02:36:15.487094Z","ts_ms":1782873375487}}

{"type":"orderbook_delta","sid":1,"seq":2521,"msg":{"market_ticker":"KXNEXTTEAMNBA-26LJAM-MIA","market_id":"492cb255-91da-4c91-bc9e-f83d090cc6dd","price_dollars":"0.8300","delta_fp":"-1.13","side":"no","ts":"2026-07-01T02:36:16.994933Z","ts_ms":1782873376994}}

{"type":"orderbook_delta","sid":1,"seq":2522,"msg":{"market_ticker":"KXNEXTTEAMNBA-26LJAM-CLE","market_id":"7552b8d4-05de-4e41-84a8-97b0684da4a9","price_dollars":"0.7400","delta_fp":"-0.75","side":"no","ts":"2026-07-01T02:36:17.062049Z","ts_ms":1782873377062}}

{"type":"orderbook_delta","sid":1,"seq":2523,"msg":{"market_ticker":"KXNEXTTEAMNBA-26LJAM-MIA","market_id":"492cb255-91da-4c91-bc9e-f83d090cc6dd","price_dollars":"0.8300","delta_fp":"-0.52","side":"no","ts":"2026-07-01T02:36:17.064079Z","ts_ms":1782873377064}}

{"type":"orderbook_delta","sid":1,"seq":2524,"msg":{"market_ticker":"KXNEXTTEAMNBA-26LJAM-MIA","market_id":"492cb255-91da-4c91-bc9e-f83d090cc6dd","price_dollars":"0.8300","delta_fp":"-1.55","side":"no","ts":"2026-07-01T02:36:18.663448Z","ts_ms":1782873378663}}

{"type":"orderbook_delta","sid":1,"seq":2525,"msg":{"market_ticker":"KXNEXTTEAMNBA-26LJAM-MIA","market_id":"492cb255-91da-4c91-bc9e-f83d090cc6dd","price_dollars":"0.8300","delta_fp":"-1.51","side":"no","ts":"2026-07-01T02:36:18.772188Z","ts_ms":1782873378772}}

{"type":"orderbook_delta","sid":1,"seq":2526,"msg":{"market_ticker":"KXNEXTTEAMNBA-26LJAM-GSW","market_id":"abbbad28-f309-4dd5-af38-2ad7ebf2acc3","price_dollars":"0.0100","delta_fp":"1.00","side":"yes","ts":"2026-07-01T02:36:20.068905Z","ts_ms":1782873380068}}

{"type":"orderbook_delta","sid":1,"seq":2527,"msg":{"market_ticker":"KXNEXTTEAMNBA-26LJAM-GSW","market_id":"abbbad28-f309-4dd5-af38-2ad7ebf2acc3","price_dollars":"0.0100","delta_fp":"1.00","side":"yes","ts":"2026-07-01T02:36:20.069674Z","ts_ms":1782873380069}}

{"type":"orderbook_delta","sid":1,"seq":2528,"msg":{"market_ticker":"KXNEXTTEAMNBA-26LJAM-GSW","market_id":"abbbad28-f309-4dd5-af38-2ad7ebf2acc3","price_dollars":"0.0100","delta_fp":"1.00","side":"yes","ts":"2026-07-01T02:36:20.070783Z","ts_ms":1782873380070}}

{"type":"orderbook_delta","sid":1,"seq":2529,"msg":{"market_ticker":"KXNEXTTEAMNBA-26LJAM-GSW","market_id":"abbbad28-f309-4dd5-af38-2ad7ebf2acc3","price_dollars":"0.0100","delta_fp":"1.00","side":"yes","ts":"2026-07-01T02:36:20.071423Z","ts_ms":1782873380071}}

{"type":"orderbook_delta","sid":1,"seq":2530,"msg":{"market_ticker":"KXNEXTTEAMNBA-26LJAM-GSW","market_id":"abbbad28-f309-4dd5-af38-2ad7ebf2acc3","price_dollars":"0.0100","delta_fp":"1.00","side":"yes","ts":"2026-07-01T02:36:20.072201Z","ts_ms":1782873380072}}

{"type":"orderbook_delta","sid":1,"seq":2531,"msg":{"market_ticker":"KXNEXTTEAMNBA-26LJAM-GSW","market_id":"abbbad28-f309-4dd5-af38-2ad7ebf2acc3","price_dollars":"0.0100","delta_fp":"1.00","side":"yes","ts":"2026-07-01T02:36:20.073133Z","ts_ms":1782873380073}}

{"type":"orderbook_delta","sid":1,"seq":2532,"msg":{"market_ticker":"KXNEXTTEAMNBA-26LJAM-GSW","market_id":"abbbad28-f309-4dd5-af38-2ad7ebf2acc3","price_dollars":"0.0100","delta_fp":"1.00","side":"yes","ts":"2026-07-01T02:36:20.073958Z","ts_ms":1782873380073}}

{"type":"orderbook_delta","sid":1,"seq":2533,"msg":{"market_ticker":"KXNEXTTEAMNBA-26LJAM-GSW","market_id":"abbbad28-f309-4dd5-af38-2ad7ebf2acc3","price_dollars":"0.0100","delta_fp":"1.00","side":"yes","ts":"2026-07-01T02:36:20.074904Z","ts_ms":1782873380074}}

{"type":"orderbook_delta","sid":1,"seq":2534,"msg":{"market_ticker":"KXNEXTTEAMNBA-26LJAM-GSW","market_id":"abbbad28-f309-4dd5-af38-2ad7ebf2acc3","price_dollars":"0.0100","delta_fp":"1.00","side":"yes","ts":"2026-07-01T02:36:20.075688Z","ts_ms":1782873380075}}

{"type":"orderbook_delta","sid":1,"seq":2535,"msg":{"market_ticker":"KXNEXTTEAMNBA-26LJAM-GSW","market_id":"abbbad28-f309-4dd5-af38-2ad7ebf2acc3","price_dollars":"0.0100","delta_fp":"1.00","side":"yes","ts":"2026-07-01T02:36:20.076545Z","ts_ms":1782873380076}}

{"type":"orderbook_delta","sid":1,"seq":2536,"msg":{"market_ticker":"KXNEXTTEAMNBA-26LJAM-GSW","market_id":"abbbad28-f309-4dd5-af38-2ad7ebf2acc3","price_dollars":"0.0100","delta_fp":"1.00","side":"yes","ts":"2026-07-01T02:36:20.077315Z","ts_ms":1782873380077}}

{"type":"orderbook_delta","sid":1,"seq":2537,"msg":{"market_ticker":"KXNEXTTEAMNBA-26LJAM-GSW","market_id":"abbbad28-f309-4dd5-af38-2ad7ebf2acc3","price_dollars":"0.0100","delta_fp":"1.00","side":"yes","ts":"2026-07-01T02:36:20.077977Z","ts_ms":1782873380077}}

{"type":"orderbook_delta","sid":1,"seq":2538,"msg":{"market_ticker":"KXNEXTTEAMNBA-26LJAM-GSW","market_id":"abbbad28-f309-4dd5-af38-2ad7ebf2acc3","price_dollars":"0.0100","delta_fp":"1.00","side":"yes","ts":"2026-07-01T02:36:20.0786Z","ts_ms":1782873380078}}

{"type":"orderbook_delta","sid":1,"seq":2539,"msg":{"market_ticker":"KXNEXTTEAMNBA-26LJAM-GSW","market_id":"abbbad28-f309-4dd5-af38-2ad7ebf2acc3","price_dollars":"0.0100","delta_fp":"1.00","side":"yes","ts":"2026-07-01T02:36:20.079177Z","ts_ms":1782873380079}}

{"type":"orderbook_delta","sid":1,"seq":2540,"msg":{"market_ticker":"KXNEXTTEAMNBA-26LJAM-GSW","market_id":"abbbad28-f309-4dd5-af38-2ad7ebf2acc3","price_dollars":"0.0100","delta_fp":"1.00","side":"yes","ts":"2026-07-01T02:36:20.079562Z","ts_ms":1782873380079}}

{"type":"orderbook_delta","sid":1,"seq":2541,"msg":{"market_ticker":"KXNEXTTEAMNBA-26LJAM-GSW","market_id":"abbbad28-f309-4dd5-af38-2ad7ebf2acc3","price_dollars":"0.0100","delta_fp":"1.00","side":"yes","ts":"2026-07-01T02:36:20.079899Z","ts_ms":1782873380079}}

{"type":"orderbook_delta","sid":1,"seq":2542,"msg":{"market_ticker":"KXNEXTTEAMNBA-26LJAM-GSW","market_id":"abbbad28-f309-4dd5-af38-2ad7ebf2acc3","price_dollars":"0.0100","delta_fp":"1.00","side":"yes","ts":"2026-07-01T02:36:20.080235Z","ts_ms":1782873380080}}

{"type":"orderbook_delta","sid":1,"seq":2543,"msg":{"market_ticker":"KXNEXTTEAMNBA-26LJAM-GSW","market_id":"abbbad28-f309-4dd5-af38-2ad7ebf2acc3","price_dollars":"0.0100","delta_fp":"1.00","side":"yes","ts":"2026-07-01T02:36:20.080723Z","ts_ms":1782873380080}}

{"type":"orderbook_delta","sid":1,"seq":2544,"msg":{"market_ticker":"KXNEXTTEAMNBA-26LJAM-GSW","market_id":"abbbad28-f309-4dd5-af38-2ad7ebf2acc3","price_dollars":"0.0100","delta_fp":"1.00","side":"yes","ts":"2026-07-01T02:36:20.081191Z","ts_ms":1782873380081}}

{"type":"orderbook_delta","sid":1,"seq":2545,"msg":{"market_ticker":"KXNEXTTEAMNBA-26LJAM-GSW","market_id":"abbbad28-f309-4dd5-af38-2ad7ebf2acc3","price_dollars":"0.0100","delta_fp":"1.00","side":"yes","ts":"2026-07-01T02:36:20.081529Z","ts_ms":1782873380081}}

{"type":"orderbook_delta","sid":1,"seq":2546,"msg":{"market_ticker":"KXNEXTTEAMNBA-26LJAM-CLE","market_id":"7552b8d4-05de-4e41-84a8-97b0684da4a9","price_dollars":"0.7400","delta_fp":"-1.09","side":"no","ts":"2026-07-01T02:36:20.294338Z","ts_ms":1782873380294}}

{"type":"orderbook_delta","sid":1,"seq":2547,"msg":{"market_ticker":"KXNEXTTEAMNBA-26LJAM-GSW","market_id":"abbbad28-f309-4dd5-af38-2ad7ebf2acc3","price_dollars":"0.5200","delta_fp":"-0.05","side":"no","ts":"2026-07-01T02:36:20.379665Z","ts_ms":1782873380379}}

{"type":"orderbook_delta","sid":1,"seq":2548,"msg":{"market_ticker":"KXNEXTTEAMNBA-26LJAM-MIA","market_id":"492cb255-91da-4c91-bc9e-f83d090cc6dd","price_dollars":"0.0100","delta_fp":"1.00","side":"yes","ts":"2026-07-01T02:36:21.229938Z","ts_ms":1782873381229}}

{"type":"orderbook_delta","sid":1,"seq":2549,"msg":{"market_ticker":"KXNEXTTEAMNBA-26LJAM-MIA","market_id":"492cb255-91da-4c91-bc9e-f83d090cc6dd","price_dollars":"0.0100","delta_fp":"1.00","side":"yes","ts":"2026-07-01T02:36:21.230411Z","ts_ms":1782873381230}}

{"type":"orderbook_delta","sid":1,"seq":2550,"msg":{"market_ticker":"KXNEXTTEAMNBA-26LJAM-MIA","market_id":"492cb255-91da-4c91-bc9e-f83d090cc6dd","price_dollars":"0.0100","delta_fp":"1.00","side":"yes","ts":"2026-07-01T02:36:21.23084Z","ts_ms":1782873381230}}

{"type":"orderbook_delta","sid":1,"seq":2551,"msg":{"market_ticker":"KXNEXTTEAMNBA-26LJAM-MIA","market_id":"492cb255-91da-4c91-bc9e-f83d090cc6dd","price_dollars":"0.0100","delta_fp":"1.00","side":"yes","ts":"2026-07-01T02:36:21.231126Z","ts_ms":1782873381231}}

{"type":"orderbook_delta","sid":1,"seq":2552,"msg":{"market_ticker":"KXNEXTTEAMNBA-26LJAM-MIA","market_id":"492cb255-91da-4c91-bc9e-f83d090cc6dd","price_dollars":"0.0100","delta_fp":"1.00","side":"yes","ts":"2026-07-01T02:36:21.231483Z","ts_ms":1782873381231}}

{"type":"orderbook_delta","sid":1,"seq":2553,"msg":{"market_ticker":"KXNEXTTEAMNBA-26LJAM-MIA","market_id":"492cb255-91da-4c91-bc9e-f83d090cc6dd","price_dollars":"0.0100","delta_fp":"1.00","side":"yes","ts":"2026-07-01T02:36:21.231928Z","ts_ms":1782873381231}}

{"type":"orderbook_delta","sid":1,"seq":2554,"msg":{"market_ticker":"KXNEXTTEAMNBA-26LJAM-MIA","market_id":"492cb255-91da-4c91-bc9e-f83d090cc6dd","price_dollars":"0.0100","delta_fp":"1.00","side":"yes","ts":"2026-07-01T02:36:21.23236Z","ts_ms":1782873381232}}

{"type":"orderbook_delta","sid":1,"seq":2555,"msg":{"market_ticker":"KXNEXTTEAMNBA-26LJAM-MIA","market_id":"492cb255-91da-4c91-bc9e-f83d090cc6dd","price_dollars":"0.0100","delta_fp":"1.00","side":"yes","ts":"2026-07-01T02:36:21.232885Z","ts_ms":1782873381232}}

{"type":"orderbook_delta","sid":1,"seq":2556,"msg":{"market_ticker":"KXNEXTTEAMNBA-26LJAM-MIA","market_id":"492cb255-91da-4c91-bc9e-f83d090cc6dd","price_dollars":"0.0100","delta_fp":"1.00","side":"yes","ts":"2026-07-01T02:36:21.233539Z","ts_ms":1782873381233}}

{"type":"orderbook_delta","sid":1,"seq":2557,"msg":{"market_ticker":"KXNEXTTEAMNBA-26LJAM-MIA","market_id":"492cb255-91da-4c91-bc9e-f83d090cc6dd","price_dollars":"0.0100","delta_fp":"1.00","side":"yes","ts":"2026-07-01T02:36:21.234087Z","ts_ms":1782873381234}}

{"type":"orderbook_delta","sid":1,"seq":2558,"msg":{"market_ticker":"KXNEXTTEAMNBA-26LJAM-MIA","market_id":"492cb255-91da-4c91-bc9e-f83d090cc6dd","price_dollars":"0.0100","delta_fp":"1.00","side":"yes","ts":"2026-07-01T02:36:21.23445Z","ts_ms":1782873381234}}

{"type":"orderbook_delta","sid":1,"seq":2559,"msg":{"market_ticker":"KXNEXTTEAMNBA-26LJAM-MIA","market_id":"492cb255-91da-4c91-bc9e-f83d090cc6dd","price_dollars":"0.0100","delta_fp":"1.00","side":"yes","ts":"2026-07-01T02:36:21.235311Z","ts_ms":1782873381235}}

{"type":"orderbook_delta","sid":1,"seq":2560,"msg":{"market_ticker":"KXNEXTTEAMNBA-26LJAM-MIA","market_id":"492cb255-91da-4c91-bc9e-f83d090cc6dd","price_dollars":"0.0100","delta_fp":"1.00","side":"yes","ts":"2026-07-01T02:36:21.236015Z","ts_ms":1782873381236}}

{"type":"orderbook_delta","sid":1,"seq":2561,"msg":{"market_ticker":"KXNEXTTEAMNBA-26LJAM-MIA","market_id":"492cb255-91da-4c91-bc9e-f83d090cc6dd","price_dollars":"0.0100","delta_fp":"1.00","side":"yes","ts":"2026-07-01T02:36:21.236737Z","ts_ms":1782873381236}}

{"type":"orderbook_delta","sid":1,"seq":2562,"msg":{"market_ticker":"KXNEXTTEAMNBA-26LJAM-MIA","market_id":"492cb255-91da-4c91-bc9e-f83d090cc6dd","price_dollars":"0.0100","delta_fp":"1.00","side":"yes","ts":"2026-07-01T02:36:21.23749Z","ts_ms":1782873381237}}

{"type":"orderbook_delta","sid":1,"seq":2563,"msg":{"market_ticker":"KXNEXTTEAMNBA-26LJAM-MIA","market_id":"492cb255-91da-4c91-bc9e-f83d090cc6dd","price_dollars":"0.0100","delta_fp":"1.00","side":"yes","ts":"2026-07-01T02:36:21.238434Z","ts_ms":1782873381238}}

{"type":"orderbook_delta","sid":1,"seq":2564,"msg":{"market_ticker":"KXNEXTTEAMNBA-26LJAM-MIA","market_id":"492cb255-91da-4c91-bc9e-f83d090cc6dd","price_dollars":"0.0100","delta_fp":"1.00","side":"yes","ts":"2026-07-01T02:36:21.239183Z","ts_ms":1782873381239}}

{"type":"orderbook_delta","sid":1,"seq":2565,"msg":{"market_ticker":"KXNEXTTEAMNBA-26LJAM-MIA","market_id":"492cb255-91da-4c91-bc9e-f83d090cc6dd","price_dollars":"0.0100","delta_fp":"1.00","side":"yes","ts":"2026-07-01T02:36:21.239548Z","ts_ms":1782873381239}}

{"type":"orderbook_delta","sid":1,"seq":2566,"msg":{"market_ticker":"KXNEXTTEAMNBA-26LJAM-MIA","market_id":"492cb255-91da-4c91-bc9e-f83d090cc6dd","price_dollars":"0.0100","delta_fp":"1.00","side":"yes","ts":"2026-07-01T02:36:21.240121Z","ts_ms":1782873381240}}

{"type":"orderbook_delta","sid":1,"seq":2567,"msg":{"market_ticker":"KXNEXTTEAMNBA-26LJAM-MIA","market_id":"492cb255-91da-4c91-bc9e-f83d090cc6dd","price_dollars":"0.0100","delta_fp":"1.00","side":"yes","ts":"2026-07-01T02:36:21.240642Z","ts_ms":1782873381240}}

{"type":"orderbook_delta","sid":1,"seq":2568,"msg":{"market_ticker":"KXNEXTTEAMNBA-26LJAM-GSW","market_id":"abbbad28-f309-4dd5-af38-2ad7ebf2acc3","price_dollars":"0.0100","delta_fp":"-1.00","side":"yes","ts":"2026-07-01T02:36:21.963812Z","ts_ms":1782873381963}}

{"type":"orderbook_delta","sid":1,"seq":2569,"msg":{"market_ticker":"KXNEXTTEAMNBA-26LJAM-GSW","market_id":"abbbad28-f309-4dd5-af38-2ad7ebf2acc3","price_dollars":"0.0100","delta_fp":"-1.00","side":"yes","ts":"2026-07-01T02:36:21.964736Z","ts_ms":1782873381964}}

{"type":"orderbook_delta","sid":1,"seq":2570,"msg":{"market_ticker":"KXNEXTTEAMNBA-26LJAM-GSW","market_id":"abbbad28-f309-4dd5-af38-2ad7ebf2acc3","price_dollars":"0.0100","delta_fp":"-1.00","side":"yes","ts":"2026-07-01T02:36:21.965525Z","ts_ms":1782873381965}}

{"type":"orderbook_delta","sid":1,"seq":2571,"msg":{"market_ticker":"KXNEXTTEAMNBA-26LJAM-GSW","market_id":"abbbad28-f309-4dd5-af38-2ad7ebf2acc3","price_dollars":"0.0100","delta_fp":"-1.00","side":"yes","ts":"2026-07-01T02:36:21.966197Z","ts_ms":1782873381966}}

{"type":"orderbook_delta","sid":1,"seq":2572,"msg":{"market_ticker":"KXNEXTTEAMNBA-26LJAM-GSW","market_id":"abbbad28-f309-4dd5-af38-2ad7ebf2acc3","price_dollars":"0.0100","delta_fp":"-1.00","side":"yes","ts":"2026-07-01T02:36:21.966893Z","ts_ms":1782873381966}}

{"type":"orderbook_delta","sid":1,"seq":2573,"msg":{"market_ticker":"KXNEXTTEAMNBA-26LJAM-GSW","market_id":"abbbad28-f309-4dd5-af38-2ad7ebf2acc3","price_dollars":"0.0100","delta_fp":"-1.00","side":"yes","ts":"2026-07-01T02:36:21.96752Z","ts_ms":1782873381967}}

{"type":"orderbook_delta","sid":1,"seq":2574,"msg":{"market_ticker":"KXNEXTTEAMNBA-26LJAM-GSW","market_id":"abbbad28-f309-4dd5-af38-2ad7ebf2acc3","price_dollars":"0.0100","delta_fp":"-1.00","side":"yes","ts":"2026-07-01T02:36:21.968349Z","ts_ms":1782873381968}}

{"type":"orderbook_delta","sid":1,"seq":2575,"msg":{"market_ticker":"KXNEXTTEAMNBA-26LJAM-GSW","market_id":"abbbad28-f309-4dd5-af38-2ad7ebf2acc3","price_dollars":"0.0100","delta_fp":"-1.00","side":"yes","ts":"2026-07-01T02:36:21.969206Z","ts_ms":1782873381969}}

{"type":"orderbook_delta","sid":1,"seq":2576,"msg":{"market_ticker":"KXNEXTTEAMNBA-26LJAM-GSW","market_id":"abbbad28-f309-4dd5-af38-2ad7ebf2acc3","price_dollars":"0.0100","delta_fp":"-1.00","side":"yes","ts":"2026-07-01T02:36:21.971649Z","ts_ms":1782873381971}}

{"type":"orderbook_delta","sid":1,"seq":2577,"msg":{"market_ticker":"KXNEXTTEAMNBA-26LJAM-GSW","market_id":"abbbad28-f309-4dd5-af38-2ad7ebf2acc3","price_dollars":"0.0100","delta_fp":"-1.00","side":"yes","ts":"2026-07-01T02:36:21.972041Z","ts_ms":1782873381972}}

{"type":"orderbook_delta","sid":1,"seq":2578,"msg":{"market_ticker":"KXNEXTTEAMNBA-26LJAM-GSW","market_id":"abbbad28-f309-4dd5-af38-2ad7ebf2acc3","price_dollars":"0.0100","delta_fp":"-1.00","side":"yes","ts":"2026-07-01T02:36:21.972605Z","ts_ms":1782873381972}}

{"type":"orderbook_delta","sid":1,"seq":2579,"msg":{"market_ticker":"KXNEXTTEAMNBA-26LJAM-GSW","market_id":"abbbad28-f309-4dd5-af38-2ad7ebf2acc3","price_dollars":"0.0100","delta_fp":"-1.00","side":"yes","ts":"2026-07-01T02:36:21.973112Z","ts_ms":1782873381973}}

{"type":"orderbook_delta","sid":1,"seq":2580,"msg":{"market_ticker":"KXNEXTTEAMNBA-26LJAM-GSW","market_id":"abbbad28-f309-4dd5-af38-2ad7ebf2acc3","price_dollars":"0.0100","delta_fp":"-1.00","side":"yes","ts":"2026-07-01T02:36:21.973646Z","ts_ms":1782873381973}}

{"type":"orderbook_delta","sid":1,"seq":2581,"msg":{"market_ticker":"KXNEXTTEAMNBA-26LJAM-GSW","market_id":"abbbad28-f309-4dd5-af38-2ad7ebf2acc3","price_dollars":"0.0100","delta_fp":"-1.00","side":"yes","ts":"2026-07-01T02:36:21.974042Z","ts_ms":1782873381974}}

{"type":"orderbook_delta","sid":1,"seq":2582,"msg":{"market_ticker":"KXNEXTTEAMNBA-26LJAM-GSW","market_id":"abbbad28-f309-4dd5-af38-2ad7ebf2acc3","price_dollars":"0.0100","delta_fp":"-1.00","side":"yes","ts":"2026-07-01T02:36:21.974452Z","ts_ms":1782873381974}}

{"type":"orderbook_delta","sid":1,"seq":2583,"msg":{"market_ticker":"KXNEXTTEAMNBA-26LJAM-GSW","market_id":"abbbad28-f309-4dd5-af38-2ad7ebf2acc3","price_dollars":"0.0100","delta_fp":"-1.00","side":"yes","ts":"2026-07-01T02:36:21.97474Z","ts_ms":1782873381974}}

{"type":"orderbook_delta","sid":1,"seq":2584,"msg":{"market_ticker":"KXNEXTTEAMNBA-26LJAM-GSW","market_id":"abbbad28-f309-4dd5-af38-2ad7ebf2acc3","price_dollars":"0.0100","delta_fp":"-1.00","side":"yes","ts":"2026-07-01T02:36:21.97515Z","ts_ms":1782873381975}}

{"type":"orderbook_delta","sid":1,"seq":2585,"msg":{"market_ticker":"KXNEXTTEAMNBA-26LJAM-GSW","market_id":"abbbad28-f309-4dd5-af38-2ad7ebf2acc3","price_dollars":"0.0100","delta_fp":"-1.00","side":"yes","ts":"2026-07-01T02:36:21.975417Z","ts_ms":1782873381975}}

{"type":"orderbook_delta","sid":1,"seq":2586,"msg":{"market_ticker":"KXNEXTTEAMNBA-26LJAM-GSW","market_id":"abbbad28-f309-4dd5-af38-2ad7ebf2acc3","price_dollars":"0.0100","delta_fp":"-1.00","side":"yes","ts":"2026-07-01T02:36:21.975651Z","ts_ms":1782873381975}}

{"type":"orderbook_delta","sid":1,"seq":2587,"msg":{"market_ticker":"KXNEXTTEAMNBA-26LJAM-GSW","market_id":"abbbad28-f309-4dd5-af38-2ad7ebf2acc3","price_dollars":"0.0100","delta_fp":"-1.00","side":"yes","ts":"2026-07-01T02:36:21.975987Z","ts_ms":1782873381975}}

{"type":"orderbook_delta","sid":1,"seq":2588,"msg":{"market_ticker":"KXNEXTTEAMNBA-26LJAM-GSW","market_id":"abbbad28-f309-4dd5-af38-2ad7ebf2acc3","price_dollars":"0.5200","delta_fp":"-0.14","side":"no","ts":"2026-07-01T02:36:22.004757Z","ts_ms":1782873382004}}

{"type":"orderbook_delta","sid":1,"seq":2589,"msg":{"market_ticker":"KXNEXTTEAMNBA-26LJAM-CLE","market_id":"7552b8d4-05de-4e41-84a8-97b0684da4a9","price_dollars":"0.7400","delta_fp":"-0.44","side":"no","ts":"2026-07-01T02:36:23.670424Z","ts_ms":1782873383670}}

{"type":"orderbook_delta","sid":1,"seq":2590,"msg":{"market_ticker":"KXNEXTTEAMNBA-26LJAM-CLE","market_id":"7552b8d4-05de-4e41-84a8-97b0684da4a9","price_dollars":"0.7400","delta_fp":"-1.09","side":"no","ts":"2026-07-01T02:36:25.208862Z","ts_ms":1782873385208}}

{"type":"orderbook_delta","sid":1,"seq":2591,"msg":{"market_ticker":"KXNEXTTEAMNBA-26LJAM-GSW","market_id":"abbbad28-f309-4dd5-af38-2ad7ebf2acc3","price_dollars":"0.5200","delta_fp":"-1.24","side":"no","ts":"2026-07-01T02:36:25.272279Z","ts_ms":1782873385272}}

{"type":"orderbook_delta","sid":1,"seq":2592,"msg":{"market_ticker":"KXNEXTTEAMNBA-26LJAM-MIA","market_id":"492cb255-91da-4c91-bc9e-f83d090cc6dd","price_dollars":"0.8300","delta_fp":"-1.61","side":"no","ts":"2026-07-01T02:36:25.272844Z","ts_ms":1782873385272}}

{"type":"orderbook_delta","sid":1,"seq":2593,"msg":{"market_ticker":"KXNEXTTEAMNBA-26LJAM-MIA","market_id":"492cb255-91da-4c91-bc9e-f83d090cc6dd","price_dollars":"0.8300","delta_fp":"-1.92","side":"no","ts":"2026-07-01T02:36:25.290958Z","ts_ms":1782873385290}}

{"type":"orderbook_delta","sid":1,"seq":2594,"msg":{"market_ticker":"KXNEXTTEAMNBA-26LJAM-GSW","market_id":"abbbad28-f309-4dd5-af38-2ad7ebf2acc3","price_dollars":"0.0100","delta_fp":"1.00","side":"yes","ts":"2026-07-01T02:36:26.317671Z","ts_ms":1782873386317}}

{"type":"orderbook_delta","sid":1,"seq":2595,"msg":{"market_ticker":"KXNEXTTEAMNBA-26LJAM-GSW","market_id":"abbbad28-f309-4dd5-af38-2ad7ebf2acc3","price_dollars":"0.0100","delta_fp":"1.00","side":"yes","ts":"2026-07-01T02:36:26.31819Z","ts_ms":1782873386318}}

{"type":"orderbook_delta","sid":1,"seq":2596,"msg":{"market_ticker":"KXNEXTTEAMNBA-26LJAM-GSW","market_id":"abbbad28-f309-4dd5-af38-2ad7ebf2acc3","price_dollars":"0.0100","delta_fp":"1.00","side":"yes","ts":"2026-07-01T02:36:26.318628Z","ts_ms":1782873386318}}

{"type":"orderbook_delta","sid":1,"seq":2597,"msg":{"market_ticker":"KXNEXTTEAMNBA-26LJAM-GSW","market_id":"abbbad28-f309-4dd5-af38-2ad7ebf2acc3","price_dollars":"0.0100","delta_fp":"1.00","side":"yes","ts":"2026-07-01T02:36:26.319151Z","ts_ms":1782873386319}}

{"type":"orderbook_delta","sid":1,"seq":2598,"msg":{"market_ticker":"KXNEXTTEAMNBA-26LJAM-GSW","market_id":"abbbad28-f309-4dd5-af38-2ad7ebf2acc3","price_dollars":"0.0100","delta_fp":"1.00","side":"yes","ts":"2026-07-01T02:36:26.319527Z","ts_ms":1782873386319}}

{"type":"orderbook_delta","sid":1,"seq":2599,"msg":{"market_ticker":"KXNEXTTEAMNBA-26LJAM-GSW","market_id":"abbbad28-f309-4dd5-af38-2ad7ebf2acc3","price_dollars":"0.0100","delta_fp":"1.00","side":"yes","ts":"2026-07-01T02:36:26.319988Z","ts_ms":1782873386319}}

{"type":"orderbook_delta","sid":1,"seq":2600,"msg":{"market_ticker":"KXNEXTTEAMNBA-26LJAM-GSW","market_id":"abbbad28-f309-4dd5-af38-2ad7ebf2acc3","price_dollars":"0.0100","delta_fp":"1.00","side":"yes","ts":"2026-07-01T02:36:26.320472Z","ts_ms":1782873386320}}

{"type":"orderbook_delta","sid":1,"seq":2601,"msg":{"market_ticker":"KXNEXTTEAMNBA-26LJAM-GSW","market_id":"abbbad28-f309-4dd5-af38-2ad7ebf2acc3","price_dollars":"0.0100","delta_fp":"1.00","side":"yes","ts":"2026-07-01T02:36:26.320997Z","ts_ms":1782873386320}}

{"type":"orderbook_delta","sid":1,"seq":2602,"msg":{"market_ticker":"KXNEXTTEAMNBA-26LJAM-GSW","market_id":"abbbad28-f309-4dd5-af38-2ad7ebf2acc3","price_dollars":"0.0100","delta_fp":"1.00","side":"yes","ts":"2026-07-01T02:36:26.321435Z","ts_ms":1782873386321}}

{"type":"orderbook_delta","sid":1,"seq":2603,"msg":{"market_ticker":"KXNEXTTEAMNBA-26LJAM-GSW","market_id":"abbbad28-f309-4dd5-af38-2ad7ebf2acc3","price_dollars":"0.0100","delta_fp":"1.00","side":"yes","ts":"2026-07-01T02:36:26.321876Z","ts_ms":1782873386321}}

{"type":"orderbook_delta","sid":1,"seq":2604,"msg":{"market_ticker":"KXNEXTTEAMNBA-26LJAM-GSW","market_id":"abbbad28-f309-4dd5-af38-2ad7ebf2acc3","price_dollars":"0.0100","delta_fp":"1.00","side":"yes","ts":"2026-07-01T02:36:26.322281Z","ts_ms":1782873386322}}

{"type":"orderbook_delta","sid":1,"seq":2605,"msg":{"market_ticker":"KXNEXTTEAMNBA-26LJAM-GSW","market_id":"abbbad28-f309-4dd5-af38-2ad7ebf2acc3","price_dollars":"0.0100","delta_fp":"1.00","side":"yes","ts":"2026-07-01T02:36:26.3227Z","ts_ms":1782873386322}}

{"type":"orderbook_delta","sid":1,"seq":2606,"msg":{"market_ticker":"KXNEXTTEAMNBA-26LJAM-GSW","market_id":"abbbad28-f309-4dd5-af38-2ad7ebf2acc3","price_dollars":"0.0100","delta_fp":"1.00","side":"yes","ts":"2026-07-01T02:36:26.323123Z","ts_ms":1782873386323}}

{"type":"orderbook_delta","sid":1,"seq":2607,"msg":{"market_ticker":"KXNEXTTEAMNBA-26LJAM-GSW","market_id":"abbbad28-f309-4dd5-af38-2ad7ebf2acc3","price_dollars":"0.0100","delta_fp":"1.00","side":"yes","ts":"2026-07-01T02:36:26.323449Z","ts_ms":1782873386323}}

{"type":"orderbook_delta","sid":1,"seq":2608,"msg":{"market_ticker":"KXNEXTTEAMNBA-26LJAM-GSW","market_id":"abbbad28-f309-4dd5-af38-2ad7ebf2acc3","price_dollars":"0.0100","delta_fp":"1.00","side":"yes","ts":"2026-07-01T02:36:26.323836Z","ts_ms":1782873386323}}

{"type":"orderbook_delta","sid":1,"seq":2609,"msg":{"market_ticker":"KXNEXTTEAMNBA-26LJAM-GSW","market_id":"abbbad28-f309-4dd5-af38-2ad7ebf2acc3","price_dollars":"0.0100","delta_fp":"1.00","side":"yes","ts":"2026-07-01T02:36:26.324268Z","ts_ms":1782873386324}}

{"type":"orderbook_delta","sid":1,"seq":2610,"msg":{"market_ticker":"KXNEXTTEAMNBA-26LJAM-GSW","market_id":"abbbad28-f309-4dd5-af38-2ad7ebf2acc3","price_dollars":"0.0100","delta_fp":"1.00","side":"yes","ts":"2026-07-01T02:36:26.324552Z","ts_ms":1782873386324}}

{"type":"orderbook_delta","sid":1,"seq":2611,"msg":{"market_ticker":"KXNEXTTEAMNBA-26LJAM-GSW","market_id":"abbbad28-f309-4dd5-af38-2ad7ebf2acc3","price_dollars":"0.0100","delta_fp":"1.00","side":"yes","ts":"2026-07-01T02:36:26.32503Z","ts_ms":1782873386325}}

{"type":"orderbook_delta","sid":1,"seq":2612,"msg":{"market_ticker":"KXNEXTTEAMNBA-26LJAM-GSW","market_id":"abbbad28-f309-4dd5-af38-2ad7ebf2acc3","price_dollars":"0.0100","delta_fp":"1.00","side":"yes","ts":"2026-07-01T02:36:26.325652Z","ts_ms":1782873386325}}

{"type":"orderbook_delta","sid":1,"seq":2613,"msg":{"market_ticker":"KXNEXTTEAMNBA-26LJAM-GSW","market_id":"abbbad28-f309-4dd5-af38-2ad7ebf2acc3","price_dollars":"0.0100","delta_fp":"1.00","side":"yes","ts":"2026-07-01T02:36:26.325956Z","ts_ms":1782873386325}}

{"type":"orderbook_delta","sid":1,"seq":2614,"msg":{"market_ticker":"KXNEXTTEAMNBA-26LJAM-CLE","market_id":"7552b8d4-05de-4e41-84a8-97b0684da4a9","price_dollars":"0.7400","delta_fp":"-0.71","side":"no","ts":"2026-07-01T02:36:26.778007Z","ts_ms":1782873386778}}

{"type":"orderbook_delta","sid":1,"seq":2615,"msg":{"market_ticker":"KXNEXTTEAMNBA-26LJAM-MIA","market_id":"492cb255-91da-4c91-bc9e-f83d090cc6dd","price_dollars":"0.8300","delta_fp":"-1.79","side":"no","ts":"2026-07-01T02:36:26.870407Z","ts_ms":1782873386870}}

{"type":"orderbook_delta","sid":1,"seq":2616,"msg":{"market_ticker":"KXNEXTTEAMNBA-26LJAM-MIA","market_id":"492cb255-91da-4c91-bc9e-f83d090cc6dd","price_dollars":"0.0100","delta_fp":"1.00","side":"yes","ts":"2026-07-01T02:36:27.552578Z","ts_ms":1782873387552}}

{"type":"orderbook_delta","sid":1,"seq":2617,"msg":{"market_ticker":"KXNEXTTEAMNBA-26LJAM-MIA","market_id":"492cb255-91da-4c91-bc9e-f83d090cc6dd","price_dollars":"0.0100","delta_fp":"1.00","side":"yes","ts":"2026-07-01T02:36:27.553184Z","ts_ms":1782873387553}}

{"type":"orderbook_delta","sid":1,"seq":2618,"msg":{"market_ticker":"KXNEXTTEAMNBA-26LJAM-MIA","market_id":"492cb255-91da-4c91-bc9e-f83d090cc6dd","price_dollars":"0.0100","delta_fp":"1.00","side":"yes","ts":"2026-07-01T02:36:27.553777Z","ts_ms":1782873387553}}

{"type":"orderbook_delta","sid":1,"seq":2619,"msg":{"market_ticker":"KXNEXTTEAMNBA-26LJAM-MIA","market_id":"492cb255-91da-4c91-bc9e-f83d090cc6dd","price_dollars":"0.0100","delta_fp":"1.00","side":"yes","ts":"2026-07-01T02:36:27.554343Z","ts_ms":1782873387554}}

{"type":"orderbook_delta","sid":1,"seq":2620,"msg":{"market_ticker":"KXNEXTTEAMNBA-26LJAM-MIA","market_id":"492cb255-91da-4c91-bc9e-f83d090cc6dd","price_dollars":"0.0100","delta_fp":"1.00","side":"yes","ts":"2026-07-01T02:36:27.554885Z","ts_ms":1782873387554}}

{"type":"orderbook_delta","sid":1,"seq":2621,"msg":{"market_ticker":"KXNEXTTEAMNBA-26LJAM-MIA","market_id":"492cb255-91da-4c91-bc9e-f83d090cc6dd","price_dollars":"0.0100","delta_fp":"1.00","side":"yes","ts":"2026-07-01T02:36:27.555417Z","ts_ms":1782873387555}}

{"type":"orderbook_delta","sid":1,"seq":2622,"msg":{"market_ticker":"KXNEXTTEAMNBA-26LJAM-MIA","market_id":"492cb255-91da-4c91-bc9e-f83d090cc6dd","price_dollars":"0.0100","delta_fp":"1.00","side":"yes","ts":"2026-07-01T02:36:27.555908Z","ts_ms":1782873387555}}

{"type":"orderbook_delta","sid":1,"seq":2623,"msg":{"market_ticker":"KXNEXTTEAMNBA-26LJAM-MIA","market_id":"492cb255-91da-4c91-bc9e-f83d090cc6dd","price_dollars":"0.0100","delta_fp":"1.00","side":"yes","ts":"2026-07-01T02:36:27.556511Z","ts_ms":1782873387556}}

{"type":"orderbook_delta","sid":1,"seq":2624,"msg":{"market_ticker":"KXNEXTTEAMNBA-26LJAM-MIA","market_id":"492cb255-91da-4c91-bc9e-f83d090cc6dd","price_dollars":"0.0100","delta_fp":"1.00","side":"yes","ts":"2026-07-01T02:36:27.557034Z","ts_ms":1782873387557}}

{"type":"orderbook_delta","sid":1,"seq":2625,"msg":{"market_ticker":"KXNEXTTEAMNBA-26LJAM-MIA","market_id":"492cb255-91da-4c91-bc9e-f83d090cc6dd","price_dollars":"0.0100","delta_fp":"1.00","side":"yes","ts":"2026-07-01T02:36:27.55766Z","ts_ms":1782873387557}}

{"type":"orderbook_delta","sid":1,"seq":2626,"msg":{"market_ticker":"KXNEXTTEAMNBA-26LJAM-MIA","market_id":"492cb255-91da-4c91-bc9e-f83d090cc6dd","price_dollars":"0.0100","delta_fp":"1.00","side":"yes","ts":"2026-07-01T02:36:27.558498Z","ts_ms":1782873387558}}

{"type":"orderbook_delta","sid":1,"seq":2627,"msg":{"market_ticker":"KXNEXTTEAMNBA-26LJAM-MIA","market_id":"492cb255-91da-4c91-bc9e-f83d090cc6dd","price_dollars":"0.0100","delta_fp":"1.00","side":"yes","ts":"2026-07-01T02:36:27.558984Z","ts_ms":1782873387558}}

{"type":"orderbook_delta","sid":1,"seq":2628,"msg":{"market_ticker":"KXNEXTTEAMNBA-26LJAM-MIA","market_id":"492cb255-91da-4c91-bc9e-f83d090cc6dd","price_dollars":"0.0100","delta_fp":"1.00","side":"yes","ts":"2026-07-01T02:36:27.559509Z","ts_ms":1782873387559}}

{"type":"orderbook_delta","sid":1,"seq":2629,"msg":{"market_ticker":"KXNEXTTEAMNBA-26LJAM-MIA","market_id":"492cb255-91da-4c91-bc9e-f83d090cc6dd","price_dollars":"0.0100","delta_fp":"1.00","side":"yes","ts":"2026-07-01T02:36:27.559928Z","ts_ms":1782873387559}}

{"type":"orderbook_delta","sid":1,"seq":2630,"msg":{"market_ticker":"KXNEXTTEAMNBA-26LJAM-MIA","market_id":"492cb255-91da-4c91-bc9e-f83d090cc6dd","price_dollars":"0.0100","delta_fp":"1.00","side":"yes","ts":"2026-07-01T02:36:27.560373Z","ts_ms":1782873387560}}

{"type":"orderbook_delta","sid":1,"seq":2631,"msg":{"market_ticker":"KXNEXTTEAMNBA-26LJAM-MIA","market_id":"492cb255-91da-4c91-bc9e-f83d090cc6dd","price_dollars":"0.0100","delta_fp":"1.00","side":"yes","ts":"2026-07-01T02:36:27.560767Z","ts_ms":1782873387560}}

{"type":"orderbook_delta","sid":1,"seq":2632,"msg":{"market_ticker":"KXNEXTTEAMNBA-26LJAM-MIA","market_id":"492cb255-91da-4c91-bc9e-f83d090cc6dd","price_dollars":"0.0100","delta_fp":"1.00","side":"yes","ts":"2026-07-01T02:36:27.561241Z","ts_ms":1782873387561}}

{"type":"orderbook_delta","sid":1,"seq":2633,"msg":{"market_ticker":"KXNEXTTEAMNBA-26LJAM-MIA","market_id":"492cb255-91da-4c91-bc9e-f83d090cc6dd","price_dollars":"0.0100","delta_fp":"1.00","side":"yes","ts":"2026-07-01T02:36:27.561925Z","ts_ms":1782873387561}}

{"type":"orderbook_delta","sid":1,"seq":2634,"msg":{"market_ticker":"KXNEXTTEAMNBA-26LJAM-MIA","market_id":"492cb255-91da-4c91-bc9e-f83d090cc6dd","price_dollars":"0.0100","delta_fp":"1.00","side":"yes","ts":"2026-07-01T02:36:27.56232Z","ts_ms":1782873387562}}

{"type":"orderbook_delta","sid":1,"seq":2635,"msg":{"market_ticker":"KXNEXTTEAMNBA-26LJAM-MIA","market_id":"492cb255-91da-4c91-bc9e-f83d090cc6dd","price_dollars":"0.0100","delta_fp":"1.00","side":"yes","ts":"2026-07-01T02:36:27.56277Z","ts_ms":1782873387562}}

{"type":"orderbook_delta","sid":1,"seq":2636,"msg":{"market_ticker":"KXNEXTTEAMNBA-26LJAM-GSW","market_id":"abbbad28-f309-4dd5-af38-2ad7ebf2acc3","price_dollars":"0.5200","delta_fp":"-1.28","side":"no","ts":"2026-07-01T02:36:28.364762Z","ts_ms":1782873388364}}

{"type":"orderbook_delta","sid":1,"seq":2637,"msg":{"market_ticker":"KXNEXTTEAMNBA-26LJAM-MIA","market_id":"492cb255-91da-4c91-bc9e-f83d090cc6dd","price_dollars":"0.8300","delta_fp":"-5.52","side":"no","ts":"2026-07-01T02:36:28.379294Z","ts_ms":1782873388379}}

{"type":"fill","sid":2,"msg":{"trade_id":"50e18226-f10d-6545-cd2c-77bed448a872","order_id":"e38f5479-9936-491b-98ca-44813f47b76d","market_ticker":"KXNEXTTEAMNBA-26LJAM-MIA","is_taker":true,"side":"yes","ts":1782873388,"ts_ms":1782873388379,"yes_price_dollars":"0.1700","count_fp":"5.52","fee_cost":"0.054600","action":"buy","post_position_fp":"5.52","purchased_side":"yes","outcome_side":"yes","book_side":"bid","subaccount":0}}

{"type":"orderbook_delta","sid":1,"seq":2638,"msg":{"market_ticker":"KXNEXTTEAMNBA-26LJAM-CLE","market_id":"7552b8d4-05de-4e41-84a8-97b0684da4a9","price_dollars":"0.7400","delta_fp":"-0.77","side":"no","ts":"2026-07-01T02:36:28.484889Z","ts_ms":1782873388484}}

{"type":"orderbook_delta","sid":1,"seq":2639,"msg":{"market_ticker":"KXNEXTTEAMNBA-26LJAM-MIA","market_id":"492cb255-91da-4c91-bc9e-f83d090cc6dd","price_dollars":"0.0100","delta_fp":"-1.00","side":"yes","ts":"2026-07-01T02:36:29.454031Z","ts_ms":1782873389454}}

{"type":"orderbook_delta","sid":1,"seq":2640,"msg":{"market_ticker":"KXNEXTTEAMNBA-26LJAM-MIA","market_id":"492cb255-91da-4c91-bc9e-f83d090cc6dd","price_dollars":"0.0100","delta_fp":"-1.00","side":"yes","ts":"2026-07-01T02:36:29.454766Z","ts_ms":1782873389454}}

{"type":"orderbook_delta","sid":1,"seq":2641,"msg":{"market_ticker":"KXNEXTTEAMNBA-26LJAM-MIA","market_id":"492cb255-91da-4c91-bc9e-f83d090cc6dd","price_dollars":"0.0100","delta_fp":"-1.00","side":"yes","ts":"2026-07-01T02:36:29.455546Z","ts_ms":1782873389455}}

{"type":"orderbook_delta","sid":1,"seq":2642,"msg":{"market_ticker":"KXNEXTTEAMNBA-26LJAM-MIA","market_id":"492cb255-91da-4c91-bc9e-f83d090cc6dd","price_dollars":"0.0100","delta_fp":"-1.00","side":"yes","ts":"2026-07-01T02:36:29.456193Z","ts_ms":1782873389456}}

{"type":"orderbook_delta","sid":1,"seq":2643,"msg":{"market_ticker":"KXNEXTTEAMNBA-26LJAM-MIA","market_id":"492cb255-91da-4c91-bc9e-f83d090cc6dd","price_dollars":"0.0100","delta_fp":"-1.00","side":"yes","ts":"2026-07-01T02:36:29.456673Z","ts_ms":1782873389456}}

{"type":"orderbook_delta","sid":1,"seq":2644,"msg":{"market_ticker":"KXNEXTTEAMNBA-26LJAM-MIA","market_id":"492cb255-91da-4c91-bc9e-f83d090cc6dd","price_dollars":"0.0100","delta_fp":"-1.00","side":"yes","ts":"2026-07-01T02:36:29.45726Z","ts_ms":1782873389457}}

{"type":"orderbook_delta","sid":1,"seq":2645,"msg":{"market_ticker":"KXNEXTTEAMNBA-26LJAM-MIA","market_id":"492cb255-91da-4c91-bc9e-f83d090cc6dd","price_dollars":"0.0100","delta_fp":"-1.00","side":"yes","ts":"2026-07-01T02:36:29.457906Z","ts_ms":1782873389457}}

{"type":"orderbook_delta","sid":1,"seq":2646,"msg":{"market_ticker":"KXNEXTTEAMNBA-26LJAM-MIA","market_id":"492cb255-91da-4c91-bc9e-f83d090cc6dd","price_dollars":"0.0100","delta_fp":"-1.00","side":"yes","ts":"2026-07-01T02:36:29.458408Z","ts_ms":1782873389458}}

{"type":"orderbook_delta","sid":1,"seq":2647,"msg":{"market_ticker":"KXNEXTTEAMNBA-26LJAM-MIA","market_id":"492cb255-91da-4c91-bc9e-f83d090cc6dd","price_dollars":"0.0100","delta_fp":"-1.00","side":"yes","ts":"2026-07-01T02:36:29.458876Z","ts_ms":1782873389458}}

{"type":"orderbook_delta","sid":1,"seq":2648,"msg":{"market_ticker":"KXNEXTTEAMNBA-26LJAM-MIA","market_id":"492cb255-91da-4c91-bc9e-f83d090cc6dd","price_dollars":"0.0100","delta_fp":"-1.00","side":"yes","ts":"2026-07-01T02:36:29.45947Z","ts_ms":1782873389459}}

{"type":"orderbook_delta","sid":1,"seq":2649,"msg":{"market_ticker":"KXNEXTTEAMNBA-26LJAM-MIA","market_id":"492cb255-91da-4c91-bc9e-f83d090cc6dd","price_dollars":"0.0100","delta_fp":"-1.00","side":"yes","ts":"2026-07-01T02:36:29.459825Z","ts_ms":1782873389459}}

{"type":"orderbook_delta","sid":1,"seq":2650,"msg":{"market_ticker":"KXNEXTTEAMNBA-26LJAM-MIA","market_id":"492cb255-91da-4c91-bc9e-f83d090cc6dd","price_dollars":"0.0100","delta_fp":"-1.00","side":"yes","ts":"2026-07-01T02:36:29.460286Z","ts_ms":1782873389460}}

{"type":"orderbook_delta","sid":1,"seq":2651,"msg":{"market_ticker":"KXNEXTTEAMNBA-26LJAM-MIA","market_id":"492cb255-91da-4c91-bc9e-f83d090cc6dd","price_dollars":"0.0100","delta_fp":"-1.00","side":"yes","ts":"2026-07-01T02:36:29.460936Z","ts_ms":1782873389460}}

{"type":"orderbook_delta","sid":1,"seq":2652,"msg":{"market_ticker":"KXNEXTTEAMNBA-26LJAM-MIA","market_id":"492cb255-91da-4c91-bc9e-f83d090cc6dd","price_dollars":"0.0100","delta_fp":"-1.00","side":"yes","ts":"2026-07-01T02:36:29.461388Z","ts_ms":1782873389461}}

{"type":"orderbook_delta","sid":1,"seq":2653,"msg":{"market_ticker":"KXNEXTTEAMNBA-26LJAM-MIA","market_id":"492cb255-91da-4c91-bc9e-f83d090cc6dd","price_dollars":"0.0100","delta_fp":"-1.00","side":"yes","ts":"2026-07-01T02:36:29.461647Z","ts_ms":1782873389461}}

{"type":"orderbook_delta","sid":1,"seq":2654,"msg":{"market_ticker":"KXNEXTTEAMNBA-26LJAM-MIA","market_id":"492cb255-91da-4c91-bc9e-f83d090cc6dd","price_dollars":"0.0100","delta_fp":"-1.00","side":"yes","ts":"2026-07-01T02:36:29.462072Z","ts_ms":1782873389462}}

{"type":"orderbook_delta","sid":1,"seq":2655,"msg":{"market_ticker":"KXNEXTTEAMNBA-26LJAM-MIA","market_id":"492cb255-91da-4c91-bc9e-f83d090cc6dd","price_dollars":"0.0100","delta_fp":"-1.00","side":"yes","ts":"2026-07-01T02:36:29.462589Z","ts_ms":1782873389462}}

{"type":"orderbook_delta","sid":1,"seq":2656,"msg":{"market_ticker":"KXNEXTTEAMNBA-26LJAM-MIA","market_id":"492cb255-91da-4c91-bc9e-f83d090cc6dd","price_dollars":"0.0100","delta_fp":"-1.00","side":"yes","ts":"2026-07-01T02:36:29.463041Z","ts_ms":1782873389463}}

{"type":"orderbook_delta","sid":1,"seq":2657,"msg":{"market_ticker":"KXNEXTTEAMNBA-26LJAM-MIA","market_id":"492cb255-91da-4c91-bc9e-f83d090cc6dd","price_dollars":"0.0100","delta_fp":"-1.00","side":"yes","ts":"2026-07-01T02:36:29.463521Z","ts_ms":1782873389463}}

{"type":"orderbook_delta","sid":1,"seq":2658,"msg":{"market_ticker":"KXNEXTTEAMNBA-26LJAM-MIA","market_id":"492cb255-91da-4c91-bc9e-f83d090cc6dd","price_dollars":"0.0100","delta_fp":"-1.00","side":"yes","ts":"2026-07-01T02:36:29.463843Z","ts_ms":1782873389463}}

{"type":"orderbook_delta","sid":1,"seq":2659,"msg":{"market_ticker":"KXNEXTTEAMNBA-26LJAM-GSW","market_id":"abbbad28-f309-4dd5-af38-2ad7ebf2acc3","price_dollars":"0.5200","delta_fp":"-1.62","side":"no","ts":"2026-07-01T02:36:29.781129Z","ts_ms":1782873389781}}

{"type":"orderbook_delta","sid":1,"seq":2660,"msg":{"market_ticker":"KXNEXTTEAMNBA-26LJAM-CLE","market_id":"7552b8d4-05de-4e41-84a8-97b0684da4a9","price_dollars":"0.7400","delta_fp":"-1.97","side":"no","ts":"2026-07-01T02:36:30.085403Z","ts_ms":1782873390085}}

{"type":"orderbook_delta","sid":1,"seq":2661,"msg":{"market_ticker":"KXNEXTTEAMNBA-26LJAM-MIA","market_id":"492cb255-91da-4c91-bc9e-f83d090cc6dd","price_dollars":"0.8300","delta_fp":"-1.54","side":"no","ts":"2026-07-01T02:36:30.171904Z","ts_ms":1782873390171}}

{"type":"orderbook_delta","sid":1,"seq":2662,"msg":{"market_ticker":"KXNEXTTEAMNBA-26LJAM-GSW","market_id":"abbbad28-f309-4dd5-af38-2ad7ebf2acc3","price_dollars":"0.5200","delta_fp":"-1.36","side":"no","ts":"2026-07-01T02:36:31.684664Z","ts_ms":1782873391684}}

{"type":"orderbook_delta","sid":1,"seq":2663,"msg":{"market_ticker":"KXNEXTTEAMNBA-26LJAM-MIA","market_id":"492cb255-91da-4c91-bc9e-f83d090cc6dd","price_dollars":"0.8300","delta_fp":"-1.71","side":"no","ts":"2026-07-01T02:36:31.705654Z","ts_ms":1782873391705}}

{"type":"orderbook_delta","sid":1,"seq":2664,"msg":{"market_ticker":"KXNEXTTEAMNBA-26LJAM-CLE","market_id":"7552b8d4-05de-4e41-84a8-97b0684da4a9","price_dollars":"0.7400","delta_fp":"-1.03","side":"no","ts":"2026-07-01T02:36:31.774358Z","ts_ms":1782873391774}}

{"type":"orderbook_delta","sid":1,"seq":2665,"msg":{"market_ticker":"KXNEXTTEAMNBA-26LJAM-GSW","market_id":"abbbad28-f309-4dd5-af38-2ad7ebf2acc3","price_dollars":"0.0100","delta_fp":"1.00","side":"yes","ts":"2026-07-01T02:36:33.12672Z","ts_ms":1782873393126}}

{"type":"orderbook_delta","sid":1,"seq":2666,"msg":{"market_ticker":"KXNEXTTEAMNBA-26LJAM-GSW","market_id":"abbbad28-f309-4dd5-af38-2ad7ebf2acc3","price_dollars":"0.0100","delta_fp":"1.00","side":"yes","ts":"2026-07-01T02:36:33.127068Z","ts_ms":1782873393127}}

{"type":"orderbook_delta","sid":1,"seq":2667,"msg":{"market_ticker":"KXNEXTTEAMNBA-26LJAM-GSW","market_id":"abbbad28-f309-4dd5-af38-2ad7ebf2acc3","price_dollars":"0.0100","delta_fp":"1.00","side":"yes","ts":"2026-07-01T02:36:33.127343Z","ts_ms":1782873393127}}

{"type":"orderbook_delta","sid":1,"seq":2668,"msg":{"market_ticker":"KXNEXTTEAMNBA-26LJAM-GSW","market_id":"abbbad28-f309-4dd5-af38-2ad7ebf2acc3","price_dollars":"0.0100","delta_fp":"1.00","side":"yes","ts":"2026-07-01T02:36:33.127624Z","ts_ms":1782873393127}}

{"type":"orderbook_delta","sid":1,"seq":2669,"msg":{"market_ticker":"KXNEXTTEAMNBA-26LJAM-GSW","market_id":"abbbad28-f309-4dd5-af38-2ad7ebf2acc3","price_dollars":"0.0100","delta_fp":"1.00","side":"yes","ts":"2026-07-01T02:36:33.128049Z","ts_ms":1782873393128}}

{"type":"orderbook_delta","sid":1,"seq":2670,"msg":{"market_ticker":"KXNEXTTEAMNBA-26LJAM-GSW","market_id":"abbbad28-f309-4dd5-af38-2ad7ebf2acc3","price_dollars":"0.0100","delta_fp":"1.00","side":"yes","ts":"2026-07-01T02:36:33.128398Z","ts_ms":1782873393128}}

{"type":"orderbook_delta","sid":1,"seq":2671,"msg":{"market_ticker":"KXNEXTTEAMNBA-26LJAM-GSW","market_id":"abbbad28-f309-4dd5-af38-2ad7ebf2acc3","price_dollars":"0.0100","delta_fp":"1.00","side":"yes","ts":"2026-07-01T02:36:33.128856Z","ts_ms":1782873393128}}

{"type":"orderbook_delta","sid":1,"seq":2672,"msg":{"market_ticker":"KXNEXTTEAMNBA-26LJAM-GSW","market_id":"abbbad28-f309-4dd5-af38-2ad7ebf2acc3","price_dollars":"0.0100","delta_fp":"1.00","side":"yes","ts":"2026-07-01T02:36:33.129287Z","ts_ms":1782873393129}}

{"type":"orderbook_delta","sid":1,"seq":2673,"msg":{"market_ticker":"KXNEXTTEAMNBA-26LJAM-GSW","market_id":"abbbad28-f309-4dd5-af38-2ad7ebf2acc3","price_dollars":"0.0100","delta_fp":"1.00","side":"yes","ts":"2026-07-01T02:36:33.129733Z","ts_ms":1782873393129}}

{"type":"orderbook_delta","sid":1,"seq":2674,"msg":{"market_ticker":"KXNEXTTEAMNBA-26LJAM-GSW","market_id":"abbbad28-f309-4dd5-af38-2ad7ebf2acc3","price_dollars":"0.0100","delta_fp":"1.00","side":"yes","ts":"2026-07-01T02:36:33.129962Z","ts_ms":1782873393129}}

{"type":"orderbook_delta","sid":1,"seq":2675,"msg":{"market_ticker":"KXNEXTTEAMNBA-26LJAM-GSW","market_id":"abbbad28-f309-4dd5-af38-2ad7ebf2acc3","price_dollars":"0.0100","delta_fp":"1.00","side":"yes","ts":"2026-07-01T02:36:33.130205Z","ts_ms":1782873393130}}

{"type":"orderbook_delta","sid":1,"seq":2676,"msg":{"market_ticker":"KXNEXTTEAMNBA-26LJAM-GSW","market_id":"abbbad28-f309-4dd5-af38-2ad7ebf2acc3","price_dollars":"0.0100","delta_fp":"1.00","side":"yes","ts":"2026-07-01T02:36:33.130468Z","ts_ms":1782873393130}}

{"type":"orderbook_delta","sid":1,"seq":2677,"msg":{"market_ticker":"KXNEXTTEAMNBA-26LJAM-GSW","market_id":"abbbad28-f309-4dd5-af38-2ad7ebf2acc3","price_dollars":"0.0100","delta_fp":"1.00","side":"yes","ts":"2026-07-01T02:36:33.130715Z","ts_ms":1782873393130}}

{"type":"orderbook_delta","sid":1,"seq":2678,"msg":{"market_ticker":"KXNEXTTEAMNBA-26LJAM-GSW","market_id":"abbbad28-f309-4dd5-af38-2ad7ebf2acc3","price_dollars":"0.0100","delta_fp":"1.00","side":"yes","ts":"2026-07-01T02:36:33.130952Z","ts_ms":1782873393130}}

{"type":"orderbook_delta","sid":1,"seq":2679,"msg":{"market_ticker":"KXNEXTTEAMNBA-26LJAM-GSW","market_id":"abbbad28-f309-4dd5-af38-2ad7ebf2acc3","price_dollars":"0.0100","delta_fp":"1.00","side":"yes","ts":"2026-07-01T02:36:33.131326Z","ts_ms":1782873393131}}

{"type":"orderbook_delta","sid":1,"seq":2680,"msg":{"market_ticker":"KXNEXTTEAMNBA-26LJAM-GSW","market_id":"abbbad28-f309-4dd5-af38-2ad7ebf2acc3","price_dollars":"0.0100","delta_fp":"1.00","side":"yes","ts":"2026-07-01T02:36:33.131576Z","ts_ms":1782873393131}}

{"type":"orderbook_delta","sid":1,"seq":2681,"msg":{"market_ticker":"KXNEXTTEAMNBA-26LJAM-GSW","market_id":"abbbad28-f309-4dd5-af38-2ad7ebf2acc3","price_dollars":"0.0100","delta_fp":"1.00","side":"yes","ts":"2026-07-01T02:36:33.131851Z","ts_ms":1782873393131}}

{"type":"orderbook_delta","sid":1,"seq":2682,"msg":{"market_ticker":"KXNEXTTEAMNBA-26LJAM-GSW","market_id":"abbbad28-f309-4dd5-af38-2ad7ebf2acc3","price_dollars":"0.0100","delta_fp":"1.00","side":"yes","ts":"2026-07-01T02:36:33.132167Z","ts_ms":1782873393132}}

{"type":"orderbook_delta","sid":1,"seq":2683,"msg":{"market_ticker":"KXNEXTTEAMNBA-26LJAM-GSW","market_id":"abbbad28-f309-4dd5-af38-2ad7ebf2acc3","price_dollars":"0.0100","delta_fp":"1.00","side":"yes","ts":"2026-07-01T02:36:33.132476Z","ts_ms":1782873393132}}

{"type":"orderbook_delta","sid":1,"seq":2684,"msg":{"market_ticker":"KXNEXTTEAMNBA-26LJAM-GSW","market_id":"abbbad28-f309-4dd5-af38-2ad7ebf2acc3","price_dollars":"0.0100","delta_fp":"1.00","side":"yes","ts":"2026-07-01T02:36:33.132742Z","ts_ms":1782873393132}}

{"type":"orderbook_delta","sid":1,"seq":2685,"msg":{"market_ticker":"KXNEXTTEAMNBA-26LJAM-MIA","market_id":"492cb255-91da-4c91-bc9e-f83d090cc6dd","price_dollars":"0.0100","delta_fp":"1.00","side":"yes","ts":"2026-07-01T02:36:34.428193Z","ts_ms":1782873394428}}

{"type":"orderbook_delta","sid":1,"seq":2686,"msg":{"market_ticker":"KXNEXTTEAMNBA-26LJAM-MIA","market_id":"492cb255-91da-4c91-bc9e-f83d090cc6dd","price_dollars":"0.0100","delta_fp":"1.00","side":"yes","ts":"2026-07-01T02:36:34.428723Z","ts_ms":1782873394428}}

{"type":"orderbook_delta","sid":1,"seq":2687,"msg":{"market_ticker":"KXNEXTTEAMNBA-26LJAM-MIA","market_id":"492cb255-91da-4c91-bc9e-f83d090cc6dd","price_dollars":"0.0100","delta_fp":"1.00","side":"yes","ts":"2026-07-01T02:36:34.429292Z","ts_ms":1782873394429}}

{"type":"orderbook_delta","sid":1,"seq":2688,"msg":{"market_ticker":"KXNEXTTEAMNBA-26LJAM-MIA","market_id":"492cb255-91da-4c91-bc9e-f83d090cc6dd","price_dollars":"0.0100","delta_fp":"1.00","side":"yes","ts":"2026-07-01T02:36:34.429831Z","ts_ms":1782873394429}}

{"type":"orderbook_delta","sid":1,"seq":2689,"msg":{"market_ticker":"KXNEXTTEAMNBA-26LJAM-MIA","market_id":"492cb255-91da-4c91-bc9e-f83d090cc6dd","price_dollars":"0.0100","delta_fp":"1.00","side":"yes","ts":"2026-07-01T02:36:34.431123Z","ts_ms":1782873394431}}

{"type":"orderbook_delta","sid":1,"seq":2690,"msg":{"market_ticker":"KXNEXTTEAMNBA-26LJAM-MIA","market_id":"492cb255-91da-4c91-bc9e-f83d090cc6dd","price_dollars":"0.0100","delta_fp":"1.00","side":"yes","ts":"2026-07-01T02:36:34.432242Z","ts_ms":1782873394432}}

{"type":"orderbook_delta","sid":1,"seq":2691,"msg":{"market_ticker":"KXNEXTTEAMNBA-26LJAM-MIA","market_id":"492cb255-91da-4c91-bc9e-f83d090cc6dd","price_dollars":"0.0100","delta_fp":"1.00","side":"yes","ts":"2026-07-01T02:36:34.432836Z","ts_ms":1782873394432}}

{"type":"orderbook_delta","sid":1,"seq":2692,"msg":{"market_ticker":"KXNEXTTEAMNBA-26LJAM-MIA","market_id":"492cb255-91da-4c91-bc9e-f83d090cc6dd","price_dollars":"0.0100","delta_fp":"1.00","side":"yes","ts":"2026-07-01T02:36:34.433342Z","ts_ms":1782873394433}}

{"type":"orderbook_delta","sid":1,"seq":2693,"msg":{"market_ticker":"KXNEXTTEAMNBA-26LJAM-MIA","market_id":"492cb255-91da-4c91-bc9e-f83d090cc6dd","price_dollars":"0.0100","delta_fp":"1.00","side":"yes","ts":"2026-07-01T02:36:34.433821Z","ts_ms":1782873394433}}

{"type":"orderbook_delta","sid":1,"seq":2694,"msg":{"market_ticker":"KXNEXTTEAMNBA-26LJAM-MIA","market_id":"492cb255-91da-4c91-bc9e-f83d090cc6dd","price_dollars":"0.0100","delta_fp":"1.00","side":"yes","ts":"2026-07-01T02:36:34.434464Z","ts_ms":1782873394434}}

{"type":"orderbook_delta","sid":1,"seq":2695,"msg":{"market_ticker":"KXNEXTTEAMNBA-26LJAM-MIA","market_id":"492cb255-91da-4c91-bc9e-f83d090cc6dd","price_dollars":"0.0100","delta_fp":"1.00","side":"yes","ts":"2026-07-01T02:36:34.435307Z","ts_ms":1782873394435}}

{"type":"orderbook_delta","sid":1,"seq":2696,"msg":{"market_ticker":"KXNEXTTEAMNBA-26LJAM-MIA","market_id":"492cb255-91da-4c91-bc9e-f83d090cc6dd","price_dollars":"0.0100","delta_fp":"1.00","side":"yes","ts":"2026-07-01T02:36:34.435963Z","ts_ms":1782873394435}}

{"type":"orderbook_delta","sid":1,"seq":2697,"msg":{"market_ticker":"KXNEXTTEAMNBA-26LJAM-MIA","market_id":"492cb255-91da-4c91-bc9e-f83d090cc6dd","price_dollars":"0.0100","delta_fp":"1.00","side":"yes","ts":"2026-07-01T02:36:34.4367Z","ts_ms":1782873394436}}

{"type":"orderbook_delta","sid":1,"seq":2698,"msg":{"market_ticker":"KXNEXTTEAMNBA-26LJAM-MIA","market_id":"492cb255-91da-4c91-bc9e-f83d090cc6dd","price_dollars":"0.0100","delta_fp":"1.00","side":"yes","ts":"2026-07-01T02:36:34.437181Z","ts_ms":1782873394437}}

{"type":"orderbook_delta","sid":1,"seq":2699,"msg":{"market_ticker":"KXNEXTTEAMNBA-26LJAM-MIA","market_id":"492cb255-91da-4c91-bc9e-f83d090cc6dd","price_dollars":"0.0100","delta_fp":"1.00","side":"yes","ts":"2026-07-01T02:36:34.437934Z","ts_ms":1782873394437}}

{"type":"orderbook_delta","sid":1,"seq":2700,"msg":{"market_ticker":"KXNEXTTEAMNBA-26LJAM-MIA","market_id":"492cb255-91da-4c91-bc9e-f83d090cc6dd","price_dollars":"0.0100","delta_fp":"1.00","side":"yes","ts":"2026-07-01T02:36:34.438578Z","ts_ms":1782873394438}}

{"type":"orderbook_delta","sid":1,"seq":2701,"msg":{"market_ticker":"KXNEXTTEAMNBA-26LJAM-MIA","market_id":"492cb255-91da-4c91-bc9e-f83d090cc6dd","price_dollars":"0.0100","delta_fp":"1.00","side":"yes","ts":"2026-07-01T02:36:34.439193Z","ts_ms":1782873394439}}

{"type":"orderbook_delta","sid":1,"seq":2702,"msg":{"market_ticker":"KXNEXTTEAMNBA-26LJAM-MIA","market_id":"492cb255-91da-4c91-bc9e-f83d090cc6dd","price_dollars":"0.0100","delta_fp":"1.00","side":"yes","ts":"2026-07-01T02:36:34.439644Z","ts_ms":1782873394439}}

{"type":"orderbook_delta","sid":1,"seq":2703,"msg":{"market_ticker":"KXNEXTTEAMNBA-26LJAM-MIA","market_id":"492cb255-91da-4c91-bc9e-f83d090cc6dd","price_dollars":"0.0100","delta_fp":"1.00","side":"yes","ts":"2026-07-01T02:36:34.440249Z","ts_ms":1782873394440}}

{"type":"orderbook_delta","sid":1,"seq":2704,"msg":{"market_ticker":"KXNEXTTEAMNBA-26LJAM-MIA","market_id":"492cb255-91da-4c91-bc9e-f83d090cc6dd","price_dollars":"0.0100","delta_fp":"1.00","side":"yes","ts":"2026-07-01T02:36:34.440838Z","ts_ms":1782873394440}}

{"type":"orderbook_delta","sid":1,"seq":2705,"msg":{"market_ticker":"KXNEXTTEAMNBA-26LJAM-MIA","market_id":"492cb255-91da-4c91-bc9e-f83d090cc6dd","price_dollars":"0.8300","delta_fp":"-1.33","side":"no","ts":"2026-07-01T02:36:34.89628Z","ts_ms":1782873394896}}

{"type":"orderbook_delta","sid":1,"seq":2706,"msg":{"market_ticker":"KXNEXTTEAMNBA-26LJAM-MIA","market_id":"492cb255-91da-4c91-bc9e-f83d090cc6dd","price_dollars":"0.8300","delta_fp":"-0.39","side":"no","ts":"2026-07-01T02:36:34.909337Z","ts_ms":1782873394909}}

{"type":"orderbook_delta","sid":1,"seq":2707,"msg":{"market_ticker":"KXNEXTTEAMNBA-26LJAM-CLE","market_id":"7552b8d4-05de-4e41-84a8-97b0684da4a9","price_dollars":"0.7400","delta_fp":"-1.65","side":"no","ts":"2026-07-01T02:36:34.98521Z","ts_ms":1782873394985}}

{"type":"orderbook_delta","sid":1,"seq":2708,"msg":{"market_ticker":"KXNEXTTEAMNBA-26LJAM-GSW","market_id":"abbbad28-f309-4dd5-af38-2ad7ebf2acc3","price_dollars":"0.0100","delta_fp":"-1.00","side":"yes","ts":"2026-07-01T02:36:35.782196Z","ts_ms":1782873395782}}

{"type":"orderbook_delta","sid":1,"seq":2709,"msg":{"market_ticker":"KXNEXTTEAMNBA-26LJAM-GSW","market_id":"abbbad28-f309-4dd5-af38-2ad7ebf2acc3","price_dollars":"0.0100","delta_fp":"-1.00","side":"yes","ts":"2026-07-01T02:36:35.782435Z","ts_ms":1782873395782}}

{"type":"orderbook_delta","sid":1,"seq":2710,"msg":{"market_ticker":"KXNEXTTEAMNBA-26LJAM-GSW","market_id":"abbbad28-f309-4dd5-af38-2ad7ebf2acc3","price_dollars":"0.0100","delta_fp":"-1.00","side":"yes","ts":"2026-07-01T02:36:35.782881Z","ts_ms":1782873395782}}

{"type":"orderbook_delta","sid":1,"seq":2711,"msg":{"market_ticker":"KXNEXTTEAMNBA-26LJAM-GSW","market_id":"abbbad28-f309-4dd5-af38-2ad7ebf2acc3","price_dollars":"0.0100","delta_fp":"-1.00","side":"yes","ts":"2026-07-01T02:36:35.783288Z","ts_ms":1782873395783}}

{"type":"orderbook_delta","sid":1,"seq":2712,"msg":{"market_ticker":"KXNEXTTEAMNBA-26LJAM-GSW","market_id":"abbbad28-f309-4dd5-af38-2ad7ebf2acc3","price_dollars":"0.0100","delta_fp":"-1.00","side":"yes","ts":"2026-07-01T02:36:35.783524Z","ts_ms":1782873395783}}

{"type":"orderbook_delta","sid":1,"seq":2713,"msg":{"market_ticker":"KXNEXTTEAMNBA-26LJAM-GSW","market_id":"abbbad28-f309-4dd5-af38-2ad7ebf2acc3","price_dollars":"0.0100","delta_fp":"-1.00","side":"yes","ts":"2026-07-01T02:36:35.784047Z","ts_ms":1782873395784}}

{"type":"orderbook_delta","sid":1,"seq":2714,"msg":{"market_ticker":"KXNEXTTEAMNBA-26LJAM-GSW","market_id":"abbbad28-f309-4dd5-af38-2ad7ebf2acc3","price_dollars":"0.0100","delta_fp":"-1.00","side":"yes","ts":"2026-07-01T02:36:35.78434Z","ts_ms":1782873395784}}

{"type":"orderbook_delta","sid":1,"seq":2715,"msg":{"market_ticker":"KXNEXTTEAMNBA-26LJAM-GSW","market_id":"abbbad28-f309-4dd5-af38-2ad7ebf2acc3","price_dollars":"0.0100","delta_fp":"-1.00","side":"yes","ts":"2026-07-01T02:36:35.784815Z","ts_ms":1782873395784}}

{"type":"orderbook_delta","sid":1,"seq":2716,"msg":{"market_ticker":"KXNEXTTEAMNBA-26LJAM-GSW","market_id":"abbbad28-f309-4dd5-af38-2ad7ebf2acc3","price_dollars":"0.0100","delta_fp":"-1.00","side":"yes","ts":"2026-07-01T02:36:35.78518Z","ts_ms":1782873395785}}

{"type":"orderbook_delta","sid":1,"seq":2717,"msg":{"market_ticker":"KXNEXTTEAMNBA-26LJAM-GSW","market_id":"abbbad28-f309-4dd5-af38-2ad7ebf2acc3","price_dollars":"0.0100","delta_fp":"-1.00","side":"yes","ts":"2026-07-01T02:36:35.785542Z","ts_ms":1782873395785}}

{"type":"orderbook_delta","sid":1,"seq":2718,"msg":{"market_ticker":"KXNEXTTEAMNBA-26LJAM-GSW","market_id":"abbbad28-f309-4dd5-af38-2ad7ebf2acc3","price_dollars":"0.0100","delta_fp":"-1.00","side":"yes","ts":"2026-07-01T02:36:35.785894Z","ts_ms":1782873395785}}

{"type":"orderbook_delta","sid":1,"seq":2719,"msg":{"market_ticker":"KXNEXTTEAMNBA-26LJAM-GSW","market_id":"abbbad28-f309-4dd5-af38-2ad7ebf2acc3","price_dollars":"0.0100","delta_fp":"-1.00","side":"yes","ts":"2026-07-01T02:36:35.786241Z","ts_ms":1782873395786}}

{"type":"orderbook_delta","sid":1,"seq":2720,"msg":{"market_ticker":"KXNEXTTEAMNBA-26LJAM-GSW","market_id":"abbbad28-f309-4dd5-af38-2ad7ebf2acc3","price_dollars":"0.0100","delta_fp":"-1.00","side":"yes","ts":"2026-07-01T02:36:35.786582Z","ts_ms":1782873395786}}

{"type":"orderbook_delta","sid":1,"seq":2721,"msg":{"market_ticker":"KXNEXTTEAMNBA-26LJAM-GSW","market_id":"abbbad28-f309-4dd5-af38-2ad7ebf2acc3","price_dollars":"0.0100","delta_fp":"-1.00","side":"yes","ts":"2026-07-01T02:36:35.78681Z","ts_ms":1782873395786}}

{"type":"orderbook_delta","sid":1,"seq":2722,"msg":{"market_ticker":"KXNEXTTEAMNBA-26LJAM-GSW","market_id":"abbbad28-f309-4dd5-af38-2ad7ebf2acc3","price_dollars":"0.0100","delta_fp":"-1.00","side":"yes","ts":"2026-07-01T02:36:35.787248Z","ts_ms":1782873395787}}

{"type":"orderbook_delta","sid":1,"seq":2723,"msg":{"market_ticker":"KXNEXTTEAMNBA-26LJAM-GSW","market_id":"abbbad28-f309-4dd5-af38-2ad7ebf2acc3","price_dollars":"0.0100","delta_fp":"-1.00","side":"yes","ts":"2026-07-01T02:36:35.787712Z","ts_ms":1782873395787}}

{"type":"orderbook_delta","sid":1,"seq":2724,"msg":{"market_ticker":"KXNEXTTEAMNBA-26LJAM-GSW","market_id":"abbbad28-f309-4dd5-af38-2ad7ebf2acc3","price_dollars":"0.0100","delta_fp":"-1.00","side":"yes","ts":"2026-07-01T02:36:35.788137Z","ts_ms":1782873395788}}

{"type":"orderbook_delta","sid":1,"seq":2725,"msg":{"market_ticker":"KXNEXTTEAMNBA-26LJAM-GSW","market_id":"abbbad28-f309-4dd5-af38-2ad7ebf2acc3","price_dollars":"0.0100","delta_fp":"-1.00","side":"yes","ts":"2026-07-01T02:36:35.788494Z","ts_ms":1782873395788}}

{"type":"orderbook_delta","sid":1,"seq":2726,"msg":{"market_ticker":"KXNEXTTEAMNBA-26LJAM-GSW","market_id":"abbbad28-f309-4dd5-af38-2ad7ebf2acc3","price_dollars":"0.0100","delta_fp":"-1.00","side":"yes","ts":"2026-07-01T02:36:35.788961Z","ts_ms":1782873395788}}

{"type":"orderbook_delta","sid":1,"seq":2727,"msg":{"market_ticker":"KXNEXTTEAMNBA-26LJAM-GSW","market_id":"abbbad28-f309-4dd5-af38-2ad7ebf2acc3","price_dollars":"0.0100","delta_fp":"-1.00","side":"yes","ts":"2026-07-01T02:36:35.789439Z","ts_ms":1782873395789}}

{"type":"orderbook_delta","sid":1,"seq":2728,"msg":{"market_ticker":"KXNEXTTEAMNBA-26LJAM-MIA","market_id":"492cb255-91da-4c91-bc9e-f83d090cc6dd","price_dollars":"0.8300","delta_fp":"-0.42","side":"no","ts":"2026-07-01T02:36:36.578798Z","ts_ms":1782873396578}}

{"type":"orderbook_delta","sid":1,"seq":2729,"msg":{"market_ticker":"KXNEXTTEAMNBA-26LJAM-MIA","market_id":"492cb255-91da-4c91-bc9e-f83d090cc6dd","price_dollars":"0.1600","delta_fp":"-1.16","side":"yes","ts":"2026-07-01T02:36:36.915377Z","ts_ms":1782873396915}}

{"type":"fill","sid":2,"msg":{"trade_id":"a7506988-e321-402d-957d-e04ebc074634","order_id":"d44d09d0-db92-4016-8e26-86176733cd6c","market_ticker":"KXNEXTTEAMNBA-26LJAM-MIA","is_taker":true,"side":"no","ts":1782873396,"ts_ms":1782873396915,"yes_price_dollars":"0.1600","count_fp":"1.16","fee_cost":"0.011000","action":"buy","post_position_fp":"4.36","purchased_side":"no","outcome_side":"no","book_side":"ask","subaccount":0}}

{"type":"orderbook_delta","sid":1,"seq":2730,"msg":{"market_ticker":"KXNEXTTEAMNBA-26LJAM-GSW","market_id":"abbbad28-f309-4dd5-af38-2ad7ebf2acc3","price_dollars":"0.5200","delta_fp":"-0.44","side":"no","ts":"2026-07-01T02:36:38.285551Z","ts_ms":1782873398285}}

{"type":"orderbook_delta","sid":1,"seq":2731,"msg":{"market_ticker":"KXNEXTTEAMNBA-26LJAM-CLE","market_id":"7552b8d4-05de-4e41-84a8-97b0684da4a9","price_dollars":"0.7400","delta_fp":"-0.61","side":"no","ts":"2026-07-01T02:36:38.3034Z","ts_ms":1782873398303}}

{"type":"orderbook_delta","sid":1,"seq":2732,"msg":{"market_ticker":"KXNEXTTEAMNBA-26LJAM-MIA","market_id":"492cb255-91da-4c91-bc9e-f83d090cc6dd","price_dollars":"0.8300","delta_fp":"-0.95","side":"no","ts":"2026-07-01T02:36:39.862359Z","ts_ms":1782873399862}}

{"type":"orderbook_delta","sid":1,"seq":2733,"msg":{"market_ticker":"KXNEXTTEAMNBA-26LJAM-GSW","market_id":"abbbad28-f309-4dd5-af38-2ad7ebf2acc3","price_dollars":"0.5200","delta_fp":"-0.55","side":"no","ts":"2026-07-01T02:36:39.909849Z","ts_ms":1782873399909}}

{"type":"orderbook_delta","sid":1,"seq":2734,"msg":{"market_ticker":"KXNEXTTEAMNBA-26LJAM-GSW","market_id":"abbbad28-f309-4dd5-af38-2ad7ebf2acc3","price_dollars":"0.0100","delta_fp":"1.00","side":"yes","ts":"2026-07-01T02:36:40.725608Z","ts_ms":1782873400725}}

{"type":"orderbook_delta","sid":1,"seq":2735,"msg":{"market_ticker":"KXNEXTTEAMNBA-26LJAM-GSW","market_id":"abbbad28-f309-4dd5-af38-2ad7ebf2acc3","price_dollars":"0.0100","delta_fp":"1.00","side":"yes","ts":"2026-07-01T02:36:40.726054Z","ts_ms":1782873400726}}

{"type":"orderbook_delta","sid":1,"seq":2736,"msg":{"market_ticker":"KXNEXTTEAMNBA-26LJAM-GSW","market_id":"abbbad28-f309-4dd5-af38-2ad7ebf2acc3","price_dollars":"0.0100","delta_fp":"1.00","side":"yes","ts":"2026-07-01T02:36:40.72653Z","ts_ms":1782873400726}}

{"type":"orderbook_delta","sid":1,"seq":2737,"msg":{"market_ticker":"KXNEXTTEAMNBA-26LJAM-GSW","market_id":"abbbad28-f309-4dd5-af38-2ad7ebf2acc3","price_dollars":"0.0100","delta_fp":"1.00","side":"yes","ts":"2026-07-01T02:36:40.726956Z","ts_ms":1782873400726}}

{"type":"orderbook_delta","sid":1,"seq":2738,"msg":{"market_ticker":"KXNEXTTEAMNBA-26LJAM-GSW","market_id":"abbbad28-f309-4dd5-af38-2ad7ebf2acc3","price_dollars":"0.0100","delta_fp":"1.00","side":"yes","ts":"2026-07-01T02:36:40.727349Z","ts_ms":1782873400727}}

{"type":"orderbook_delta","sid":1,"seq":2739,"msg":{"market_ticker":"KXNEXTTEAMNBA-26LJAM-GSW","market_id":"abbbad28-f309-4dd5-af38-2ad7ebf2acc3","price_dollars":"0.0100","delta_fp":"1.00","side":"yes","ts":"2026-07-01T02:36:40.72782Z","ts_ms":1782873400727}}

{"type":"orderbook_delta","sid":1,"seq":2740,"msg":{"market_ticker":"KXNEXTTEAMNBA-26LJAM-GSW","market_id":"abbbad28-f309-4dd5-af38-2ad7ebf2acc3","price_dollars":"0.0100","delta_fp":"1.00","side":"yes","ts":"2026-07-01T02:36:40.728293Z","ts_ms":1782873400728}}

{"type":"orderbook_delta","sid":1,"seq":2741,"msg":{"market_ticker":"KXNEXTTEAMNBA-26LJAM-GSW","market_id":"abbbad28-f309-4dd5-af38-2ad7ebf2acc3","price_dollars":"0.0100","delta_fp":"1.00","side":"yes","ts":"2026-07-01T02:36:40.728638Z","ts_ms":1782873400728}}

{"type":"orderbook_delta","sid":1,"seq":2742,"msg":{"market_ticker":"KXNEXTTEAMNBA-26LJAM-GSW","market_id":"abbbad28-f309-4dd5-af38-2ad7ebf2acc3","price_dollars":"0.0100","delta_fp":"1.00","side":"yes","ts":"2026-07-01T02:36:40.729087Z","ts_ms":1782873400729}}

{"type":"orderbook_delta","sid":1,"seq":2743,"msg":{"market_ticker":"KXNEXTTEAMNBA-26LJAM-GSW","market_id":"abbbad28-f309-4dd5-af38-2ad7ebf2acc3","price_dollars":"0.0100","delta_fp":"1.00","side":"yes","ts":"2026-07-01T02:36:40.729513Z","ts_ms":1782873400729}}

{"type":"orderbook_delta","sid":1,"seq":2744,"msg":{"market_ticker":"KXNEXTTEAMNBA-26LJAM-GSW","market_id":"abbbad28-f309-4dd5-af38-2ad7ebf2acc3","price_dollars":"0.0100","delta_fp":"1.00","side":"yes","ts":"2026-07-01T02:36:40.729874Z","ts_ms":1782873400729}}

{"type":"orderbook_delta","sid":1,"seq":2745,"msg":{"market_ticker":"KXNEXTTEAMNBA-26LJAM-GSW","market_id":"abbbad28-f309-4dd5-af38-2ad7ebf2acc3","price_dollars":"0.0100","delta_fp":"1.00","side":"yes","ts":"2026-07-01T02:36:40.730424Z","ts_ms":1782873400730}}

{"type":"orderbook_delta","sid":1,"seq":2746,"msg":{"market_ticker":"KXNEXTTEAMNBA-26LJAM-GSW","market_id":"abbbad28-f309-4dd5-af38-2ad7ebf2acc3","price_dollars":"0.0100","delta_fp":"1.00","side":"yes","ts":"2026-07-01T02:36:40.730887Z","ts_ms":1782873400730}}

{"type":"orderbook_delta","sid":1,"seq":2747,"msg":{"market_ticker":"KXNEXTTEAMNBA-26LJAM-GSW","market_id":"abbbad28-f309-4dd5-af38-2ad7ebf2acc3","price_dollars":"0.0100","delta_fp":"1.00","side":"yes","ts":"2026-07-01T02:36:40.731345Z","ts_ms":1782873400731}}

{"type":"orderbook_delta","sid":1,"seq":2748,"msg":{"market_ticker":"KXNEXTTEAMNBA-26LJAM-GSW","market_id":"abbbad28-f309-4dd5-af38-2ad7ebf2acc3","price_dollars":"0.0100","delta_fp":"1.00","side":"yes","ts":"2026-07-01T02:36:40.73169Z","ts_ms":1782873400731}}

{"type":"orderbook_delta","sid":1,"seq":2749,"msg":{"market_ticker":"KXNEXTTEAMNBA-26LJAM-GSW","market_id":"abbbad28-f309-4dd5-af38-2ad7ebf2acc3","price_dollars":"0.0100","delta_fp":"1.00","side":"yes","ts":"2026-07-01T02:36:40.732178Z","ts_ms":1782873400732}}

{"type":"orderbook_delta","sid":1,"seq":2750,"msg":{"market_ticker":"KXNEXTTEAMNBA-26LJAM-GSW","market_id":"abbbad28-f309-4dd5-af38-2ad7ebf2acc3","price_dollars":"0.0100","delta_fp":"1.00","side":"yes","ts":"2026-07-01T02:36:40.732596Z","ts_ms":1782873400732}}

{"type":"orderbook_delta","sid":1,"seq":2751,"msg":{"market_ticker":"KXNEXTTEAMNBA-26LJAM-GSW","market_id":"abbbad28-f309-4dd5-af38-2ad7ebf2acc3","price_dollars":"0.0100","delta_fp":"1.00","side":"yes","ts":"2026-07-01T02:36:40.73307Z","ts_ms":1782873400733}}

{"type":"orderbook_delta","sid":1,"seq":2752,"msg":{"market_ticker":"KXNEXTTEAMNBA-26LJAM-GSW","market_id":"abbbad28-f309-4dd5-af38-2ad7ebf2acc3","price_dollars":"0.0100","delta_fp":"1.00","side":"yes","ts":"2026-07-01T02:36:40.733525Z","ts_ms":1782873400733}}

{"type":"orderbook_delta","sid":1,"seq":2753,"msg":{"market_ticker":"KXNEXTTEAMNBA-26LJAM-MIA","market_id":"492cb255-91da-4c91-bc9e-f83d090cc6dd","price_dollars":"0.0100","delta_fp":"1.00","side":"yes","ts":"2026-07-01T02:36:40.733711Z","ts_ms":1782873400733}}

{"type":"orderbook_delta","sid":1,"seq":2754,"msg":{"market_ticker":"KXNEXTTEAMNBA-26LJAM-GSW","market_id":"abbbad28-f309-4dd5-af38-2ad7ebf2acc3","price_dollars":"0.0100","delta_fp":"1.00","side":"yes","ts":"2026-07-01T02:36:40.734105Z","ts_ms":1782873400734}}

{"type":"orderbook_delta","sid":1,"seq":2755,"msg":{"market_ticker":"KXNEXTTEAMNBA-26LJAM-MIA","market_id":"492cb255-91da-4c91-bc9e-f83d090cc6dd","price_dollars":"0.0100","delta_fp":"1.00","side":"yes","ts":"2026-07-01T02:36:40.734287Z","ts_ms":1782873400734}}

{"type":"orderbook_delta","sid":1,"seq":2756,"msg":{"market_ticker":"KXNEXTTEAMNBA-26LJAM-MIA","market_id":"492cb255-91da-4c91-bc9e-f83d090cc6dd","price_dollars":"0.0100","delta_fp":"1.00","side":"yes","ts":"2026-07-01T02:36:40.734687Z","ts_ms":1782873400734}}

{"type":"orderbook_delta","sid":1,"seq":2757,"msg":{"market_ticker":"KXNEXTTEAMNBA-26LJAM-MIA","market_id":"492cb255-91da-4c91-bc9e-f83d090cc6dd","price_dollars":"0.0100","delta_fp":"1.00","side":"yes","ts":"2026-07-01T02:36:40.736235Z","ts_ms":1782873400736}}

{"type":"orderbook_delta","sid":1,"seq":2758,"msg":{"market_ticker":"KXNEXTTEAMNBA-26LJAM-MIA","market_id":"492cb255-91da-4c91-bc9e-f83d090cc6dd","price_dollars":"0.0100","delta_fp":"1.00","side":"yes","ts":"2026-07-01T02:36:40.736666Z","ts_ms":1782873400736}}

{"type":"orderbook_delta","sid":1,"seq":2759,"msg":{"market_ticker":"KXNEXTTEAMNBA-26LJAM-MIA","market_id":"492cb255-91da-4c91-bc9e-f83d090cc6dd","price_dollars":"0.0100","delta_fp":"1.00","side":"yes","ts":"2026-07-01T02:36:40.737158Z","ts_ms":1782873400737}}

{"type":"orderbook_delta","sid":1,"seq":2760,"msg":{"market_ticker":"KXNEXTTEAMNBA-26LJAM-MIA","market_id":"492cb255-91da-4c91-bc9e-f83d090cc6dd","price_dollars":"0.0100","delta_fp":"1.00","side":"yes","ts":"2026-07-01T02:36:40.737563Z","ts_ms":1782873400737}}

{"type":"orderbook_delta","sid":1,"seq":2761,"msg":{"market_ticker":"KXNEXTTEAMNBA-26LJAM-MIA","market_id":"492cb255-91da-4c91-bc9e-f83d090cc6dd","price_dollars":"0.0100","delta_fp":"1.00","side":"yes","ts":"2026-07-01T02:36:40.737997Z","ts_ms":1782873400737}}

{"type":"orderbook_delta","sid":1,"seq":2762,"msg":{"market_ticker":"KXNEXTTEAMNBA-26LJAM-MIA","market_id":"492cb255-91da-4c91-bc9e-f83d090cc6dd","price_dollars":"0.0100","delta_fp":"1.00","side":"yes","ts":"2026-07-01T02:36:40.738385Z","ts_ms":1782873400738}}

{"type":"orderbook_delta","sid":1,"seq":2763,"msg":{"market_ticker":"KXNEXTTEAMNBA-26LJAM-MIA","market_id":"492cb255-91da-4c91-bc9e-f83d090cc6dd","price_dollars":"0.0100","delta_fp":"1.00","side":"yes","ts":"2026-07-01T02:36:40.738735Z","ts_ms":1782873400738}}

{"type":"orderbook_delta","sid":1,"seq":2764,"msg":{"market_ticker":"KXNEXTTEAMNBA-26LJAM-MIA","market_id":"492cb255-91da-4c91-bc9e-f83d090cc6dd","price_dollars":"0.0100","delta_fp":"1.00","side":"yes","ts":"2026-07-01T02:36:40.739088Z","ts_ms":1782873400739}}

{"type":"orderbook_delta","sid":1,"seq":2765,"msg":{"market_ticker":"KXNEXTTEAMNBA-26LJAM-MIA","market_id":"492cb255-91da-4c91-bc9e-f83d090cc6dd","price_dollars":"0.0100","delta_fp":"1.00","side":"yes","ts":"2026-07-01T02:36:40.739832Z","ts_ms":1782873400739}}

{"type":"orderbook_delta","sid":1,"seq":2766,"msg":{"market_ticker":"KXNEXTTEAMNBA-26LJAM-MIA","market_id":"492cb255-91da-4c91-bc9e-f83d090cc6dd","price_dollars":"0.0100","delta_fp":"1.00","side":"yes","ts":"2026-07-01T02:36:40.740216Z","ts_ms":1782873400740}}

{"type":"orderbook_delta","sid":1,"seq":2767,"msg":{"market_ticker":"KXNEXTTEAMNBA-26LJAM-MIA","market_id":"492cb255-91da-4c91-bc9e-f83d090cc6dd","price_dollars":"0.0100","delta_fp":"1.00","side":"yes","ts":"2026-07-01T02:36:40.740574Z","ts_ms":1782873400740}}

{"type":"orderbook_delta","sid":1,"seq":2768,"msg":{"market_ticker":"KXNEXTTEAMNBA-26LJAM-MIA","market_id":"492cb255-91da-4c91-bc9e-f83d090cc6dd","price_dollars":"0.0100","delta_fp":"1.00","side":"yes","ts":"2026-07-01T02:36:40.740897Z","ts_ms":1782873400740}}

{"type":"orderbook_delta","sid":1,"seq":2769,"msg":{"market_ticker":"KXNEXTTEAMNBA-26LJAM-MIA","market_id":"492cb255-91da-4c91-bc9e-f83d090cc6dd","price_dollars":"0.0100","delta_fp":"1.00","side":"yes","ts":"2026-07-01T02:36:40.741205Z","ts_ms":1782873400741}}

{"type":"orderbook_delta","sid":1,"seq":2770,"msg":{"market_ticker":"KXNEXTTEAMNBA-26LJAM-MIA","market_id":"492cb255-91da-4c91-bc9e-f83d090cc6dd","price_dollars":"0.0100","delta_fp":"1.00","side":"yes","ts":"2026-07-01T02:36:40.741521Z","ts_ms":1782873400741}}

{"type":"orderbook_delta","sid":1,"seq":2771,"msg":{"market_ticker":"KXNEXTTEAMNBA-26LJAM-MIA","market_id":"492cb255-91da-4c91-bc9e-f83d090cc6dd","price_dollars":"0.0100","delta_fp":"1.00","side":"yes","ts":"2026-07-01T02:36:40.741869Z","ts_ms":1782873400741}}

{"type":"orderbook_delta","sid":1,"seq":2772,"msg":{"market_ticker":"KXNEXTTEAMNBA-26LJAM-MIA","market_id":"492cb255-91da-4c91-bc9e-f83d090cc6dd","price_dollars":"0.0100","delta_fp":"1.00","side":"yes","ts":"2026-07-01T02:36:40.742187Z","ts_ms":1782873400742}}

{"type":"orderbook_delta","sid":1,"seq":2773,"msg":{"market_ticker":"KXNEXTTEAMNBA-26LJAM-MIA","market_id":"492cb255-91da-4c91-bc9e-f83d090cc6dd","price_dollars":"0.0100","delta_fp":"1.00","side":"yes","ts":"2026-07-01T02:36:40.742576Z","ts_ms":1782873400742}}

{"type":"orderbook_delta","sid":1,"seq":2774,"msg":{"market_ticker":"KXNEXTTEAMNBA-26LJAM-MIA","market_id":"492cb255-91da-4c91-bc9e-f83d090cc6dd","price_dollars":"0.8300","delta_fp":"-0.54","side":"no","ts":"2026-07-01T02:36:41.376454Z","ts_ms":1782873401376}}

{"type":"orderbook_delta","sid":1,"seq":2775,"msg":{"market_ticker":"KXNEXTTEAMNBA-26LJAM-CLE","market_id":"7552b8d4-05de-4e41-84a8-97b0684da4a9","price_dollars":"0.7400","delta_fp":"-1.72","side":"no","ts":"2026-07-01T02:36:43.102345Z","ts_ms":1782873403102}}

{"type":"orderbook_delta","sid":1,"seq":2776,"msg":{"market_ticker":"KXNEXTTEAMNBA-26LJAM-MIA","market_id":"492cb255-91da-4c91-bc9e-f83d090cc6dd","price_dollars":"0.8300","delta_fp":"-1.82","side":"no","ts":"2026-07-01T02:36:44.787176Z","ts_ms":1782873404787}}

{"type":"orderbook_delta","sid":1,"seq":2777,"msg":{"market_ticker":"KXNEXTTEAMNBA-26LJAM-MIA","market_id":"492cb255-91da-4c91-bc9e-f83d090cc6dd","price_dollars":"0.8300","delta_fp":"-0.45","side":"no","ts":"2026-07-01T02:36:45.571904Z","ts_ms":1782873405571}}

{"type":"orderbook_delta","sid":1,"seq":2778,"msg":{"market_ticker":"KXNEXTTEAMNBA-26LJAM-CLE","market_id":"7552b8d4-05de-4e41-84a8-97b0684da4a9","price_dollars":"0.7400","delta_fp":"-0.26","side":"no","ts":"2026-07-01T02:36:46.384175Z","ts_ms":1782873406384}}

{"type":"orderbook_delta","sid":1,"seq":2779,"msg":{"market_ticker":"KXNEXTTEAMNBA-26LJAM-MIA","market_id":"492cb255-91da-4c91-bc9e-f83d090cc6dd","price_dollars":"0.8300","delta_fp":"-0.03","side":"no","ts":"2026-07-01T02:36:46.387422Z","ts_ms":1782873406387}}

{"type":"orderbook_delta","sid":1,"seq":2780,"msg":{"market_ticker":"KXNEXTTEAMNBA-26LJAM-MIA","market_id":"492cb255-91da-4c91-bc9e-f83d090cc6dd","price_dollars":"0.0100","delta_fp":"1.00","side":"yes","ts":"2026-07-01T02:36:47.040049Z","ts_ms":1782873407040}}

{"type":"orderbook_delta","sid":1,"seq":2781,"msg":{"market_ticker":"KXNEXTTEAMNBA-26LJAM-MIA","market_id":"492cb255-91da-4c91-bc9e-f83d090cc6dd","price_dollars":"0.0100","delta_fp":"1.00","side":"yes","ts":"2026-07-01T02:36:47.040384Z","ts_ms":1782873407040}}

{"type":"orderbook_delta","sid":1,"seq":2782,"msg":{"market_ticker":"KXNEXTTEAMNBA-26LJAM-MIA","market_id":"492cb255-91da-4c91-bc9e-f83d090cc6dd","price_dollars":"0.0100","delta_fp":"1.00","side":"yes","ts":"2026-07-01T02:36:47.040805Z","ts_ms":1782873407040}}

{"type":"orderbook_delta","sid":1,"seq":2783,"msg":{"market_ticker":"KXNEXTTEAMNBA-26LJAM-MIA","market_id":"492cb255-91da-4c91-bc9e-f83d090cc6dd","price_dollars":"0.0100","delta_fp":"1.00","side":"yes","ts":"2026-07-01T02:36:47.041265Z","ts_ms":1782873407041}}

{"type":"orderbook_delta","sid":1,"seq":2784,"msg":{"market_ticker":"KXNEXTTEAMNBA-26LJAM-MIA","market_id":"492cb255-91da-4c91-bc9e-f83d090cc6dd","price_dollars":"0.0100","delta_fp":"1.00","side":"yes","ts":"2026-07-01T02:36:47.041727Z","ts_ms":1782873407041}}

{"type":"orderbook_delta","sid":1,"seq":2785,"msg":{"market_ticker":"KXNEXTTEAMNBA-26LJAM-MIA","market_id":"492cb255-91da-4c91-bc9e-f83d090cc6dd","price_dollars":"0.0100","delta_fp":"1.00","side":"yes","ts":"2026-07-01T02:36:47.042204Z","ts_ms":1782873407042}}

{"type":"orderbook_delta","sid":1,"seq":2786,"msg":{"market_ticker":"KXNEXTTEAMNBA-26LJAM-MIA","market_id":"492cb255-91da-4c91-bc9e-f83d090cc6dd","price_dollars":"0.0100","delta_fp":"1.00","side":"yes","ts":"2026-07-01T02:36:47.042719Z","ts_ms":1782873407042}}

{"type":"orderbook_delta","sid":1,"seq":2787,"msg":{"market_ticker":"KXNEXTTEAMNBA-26LJAM-MIA","market_id":"492cb255-91da-4c91-bc9e-f83d090cc6dd","price_dollars":"0.0100","delta_fp":"1.00","side":"yes","ts":"2026-07-01T02:36:47.04309Z","ts_ms":1782873407043}}

{"type":"orderbook_delta","sid":1,"seq":2788,"msg":{"market_ticker":"KXNEXTTEAMNBA-26LJAM-MIA","market_id":"492cb255-91da-4c91-bc9e-f83d090cc6dd","price_dollars":"0.0100","delta_fp":"1.00","side":"yes","ts":"2026-07-01T02:36:47.043503Z","ts_ms":1782873407043}}

{"type":"orderbook_delta","sid":1,"seq":2789,"msg":{"market_ticker":"KXNEXTTEAMNBA-26LJAM-MIA","market_id":"492cb255-91da-4c91-bc9e-f83d090cc6dd","price_dollars":"0.0100","delta_fp":"1.00","side":"yes","ts":"2026-07-01T02:36:47.043981Z","ts_ms":1782873407043}}

{"type":"orderbook_delta","sid":1,"seq":2790,"msg":{"market_ticker":"KXNEXTTEAMNBA-26LJAM-MIA","market_id":"492cb255-91da-4c91-bc9e-f83d090cc6dd","price_dollars":"0.0100","delta_fp":"1.00","side":"yes","ts":"2026-07-01T02:36:47.044435Z","ts_ms":1782873407044}}

{"type":"orderbook_delta","sid":1,"seq":2791,"msg":{"market_ticker":"KXNEXTTEAMNBA-26LJAM-MIA","market_id":"492cb255-91da-4c91-bc9e-f83d090cc6dd","price_dollars":"0.0100","delta_fp":"1.00","side":"yes","ts":"2026-07-01T02:36:47.044831Z","ts_ms":1782873407044}}

{"type":"orderbook_delta","sid":1,"seq":2792,"msg":{"market_ticker":"KXNEXTTEAMNBA-26LJAM-MIA","market_id":"492cb255-91da-4c91-bc9e-f83d090cc6dd","price_dollars":"0.0100","delta_fp":"1.00","side":"yes","ts":"2026-07-01T02:36:47.045613Z","ts_ms":1782873407045}}

{"type":"orderbook_delta","sid":1,"seq":2793,"msg":{"market_ticker":"KXNEXTTEAMNBA-26LJAM-MIA","market_id":"492cb255-91da-4c91-bc9e-f83d090cc6dd","price_dollars":"0.0100","delta_fp":"1.00","side":"yes","ts":"2026-07-01T02:36:47.046065Z","ts_ms":1782873407046}}

{"type":"orderbook_delta","sid":1,"seq":2794,"msg":{"market_ticker":"KXNEXTTEAMNBA-26LJAM-MIA","market_id":"492cb255-91da-4c91-bc9e-f83d090cc6dd","price_dollars":"0.0100","delta_fp":"1.00","side":"yes","ts":"2026-07-01T02:36:47.046532Z","ts_ms":1782873407046}}

{"type":"orderbook_delta","sid":1,"seq":2795,"msg":{"market_ticker":"KXNEXTTEAMNBA-26LJAM-MIA","market_id":"492cb255-91da-4c91-bc9e-f83d090cc6dd","price_dollars":"0.0100","delta_fp":"1.00","side":"yes","ts":"2026-07-01T02:36:47.047041Z","ts_ms":1782873407047}}

{"type":"orderbook_delta","sid":1,"seq":2796,"msg":{"market_ticker":"KXNEXTTEAMNBA-26LJAM-MIA","market_id":"492cb255-91da-4c91-bc9e-f83d090cc6dd","price_dollars":"0.0100","delta_fp":"1.00","side":"yes","ts":"2026-07-01T02:36:47.047451Z","ts_ms":1782873407047}}

{"type":"orderbook_delta","sid":1,"seq":2797,"msg":{"market_ticker":"KXNEXTTEAMNBA-26LJAM-MIA","market_id":"492cb255-91da-4c91-bc9e-f83d090cc6dd","price_dollars":"0.0100","delta_fp":"1.00","side":"yes","ts":"2026-07-01T02:36:47.047901Z","ts_ms":1782873407047}}

{"type":"orderbook_delta","sid":1,"seq":2798,"msg":{"market_ticker":"KXNEXTTEAMNBA-26LJAM-MIA","market_id":"492cb255-91da-4c91-bc9e-f83d090cc6dd","price_dollars":"0.0100","delta_fp":"1.00","side":"yes","ts":"2026-07-01T02:36:47.048273Z","ts_ms":1782873407048}}

{"type":"orderbook_delta","sid":1,"seq":2799,"msg":{"market_ticker":"KXNEXTTEAMNBA-26LJAM-MIA","market_id":"492cb255-91da-4c91-bc9e-f83d090cc6dd","price_dollars":"0.0100","delta_fp":"1.00","side":"yes","ts":"2026-07-01T02:36:47.048699Z","ts_ms":1782873407048}}

{"type":"orderbook_delta","sid":1,"seq":2800,"msg":{"market_ticker":"KXNEXTTEAMNBA-26LJAM-MIA","market_id":"492cb255-91da-4c91-bc9e-f83d090cc6dd","price_dollars":"0.8300","delta_fp":"-0.74","side":"no","ts":"2026-07-01T02:36:47.694409Z","ts_ms":1782873407694}}

{"type":"orderbook_delta","sid":1,"seq":2801,"msg":{"market_ticker":"KXNEXTTEAMNBA-26LJAM-GSW","market_id":"abbbad28-f309-4dd5-af38-2ad7ebf2acc3","price_dollars":"0.5200","delta_fp":"-1.35","side":"no","ts":"2026-07-01T02:36:47.963602Z","ts_ms":1782873407963}}

{"type":"orderbook_delta","sid":1,"seq":2802,"msg":{"market_ticker":"KXNEXTTEAMNBA-26LJAM-MIA","market_id":"492cb255-91da-4c91-bc9e-f83d090cc6dd","price_dollars":"0.8300","delta_fp":"-0.98","side":"no","ts":"2026-07-01T02:36:47.975176Z","ts_ms":1782873407975}}

{"type":"orderbook_delta","sid":1,"seq":2803,"msg":{"market_ticker":"KXNEXTTEAMNBA-26LJAM-CLE","market_id":"7552b8d4-05de-4e41-84a8-97b0684da4a9","price_dollars":"0.7400","delta_fp":"-0.06","side":"no","ts":"2026-07-01T02:36:47.97654Z","ts_ms":1782873407976}}

{"type":"orderbook_delta","sid":1,"seq":2804,"msg":{"market_ticker":"KXNEXTTEAMNBA-26LJAM-GSW","market_id":"abbbad28-f309-4dd5-af38-2ad7ebf2acc3","price_dollars":"0.4700","delta_fp":"709.21","side":"yes","ts":"2026-07-01T02:36:48.937895Z","ts_ms":1782873408937}}

{"type":"orderbook_delta","sid":1,"seq":2805,"msg":{"market_ticker":"KXNEXTTEAMNBA-26LJAM-GSW","market_id":"abbbad28-f309-4dd5-af38-2ad7ebf2acc3","price_dollars":"0.4600","delta_fp":"724.63","side":"yes","ts":"2026-07-01T02:36:48.938595Z","ts_ms":1782873408938}}

{"type":"orderbook_delta","sid":1,"seq":2806,"msg":{"market_ticker":"KXNEXTTEAMNBA-26LJAM-GSW","market_id":"abbbad28-f309-4dd5-af38-2ad7ebf2acc3","price_dollars":"0.4500","delta_fp":"740.74","side":"yes","ts":"2026-07-01T02:36:48.939496Z","ts_ms":1782873408939}}

{"type":"orderbook_delta","sid":1,"seq":2807,"msg":{"market_ticker":"KXNEXTTEAMNBA-26LJAM-GSW","market_id":"abbbad28-f309-4dd5-af38-2ad7ebf2acc3","price_dollars":"0.5200","delta_fp":"694.44","side":"no","ts":"2026-07-01T02:36:48.940239Z","ts_ms":1782873408940}}

{"type":"orderbook_delta","sid":1,"seq":2808,"msg":{"market_ticker":"KXNEXTTEAMNBA-26LJAM-GSW","market_id":"abbbad28-f309-4dd5-af38-2ad7ebf2acc3","price_dollars":"0.5100","delta_fp":"680.27","side":"no","ts":"2026-07-01T02:36:48.941259Z","ts_ms":1782873408941}}

{"type":"orderbook_delta","sid":1,"seq":2809,"msg":{"market_ticker":"KXNEXTTEAMNBA-26LJAM-GSW","market_id":"abbbad28-f309-4dd5-af38-2ad7ebf2acc3","price_dollars":"0.5000","delta_fp":"666.66","side":"no","ts":"2026-07-01T02:36:48.942016Z","ts_ms":1782873408942}}

{"type":"orderbook_delta","sid":1,"seq":2810,"msg":{"market_ticker":"KXNEXTTEAMNBA-26LJAM-CLE","market_id":"7552b8d4-05de-4e41-84a8-97b0684da4a9","price_dollars":"0.7400","delta_fp":"-1.73","side":"no","ts":"2026-07-01T02:36:49.410892Z","ts_ms":1782873409410}}

{"type":"orderbook_delta","sid":1,"seq":2811,"msg":{"market_ticker":"KXNEXTTEAMNBA-26LJAM-CLE","market_id":"7552b8d4-05de-4e41-84a8-97b0684da4a9","price_dollars":"0.7400","delta_fp":"-0.40","side":"no","ts":"2026-07-01T02:36:49.488473Z","ts_ms":1782873409488}}

{"type":"orderbook_delta","sid":1,"seq":2812,"msg":{"market_ticker":"KXNEXTTEAMNBA-26LJAM-CLE","market_id":"7552b8d4-05de-4e41-84a8-97b0684da4a9","price_dollars":"0.7400","delta_fp":"-0.87","side":"no","ts":"2026-07-01T02:36:51.072543Z","ts_ms":1782873411072}}

{"type":"orderbook_delta","sid":1,"seq":2813,"msg":{"market_ticker":"KXNEXTTEAMNBA-26LJAM-GSW","market_id":"abbbad28-f309-4dd5-af38-2ad7ebf2acc3","price_dollars":"0.5200","delta_fp":"-1.74","side":"no","ts":"2026-07-01T02:36:51.103665Z","ts_ms":1782873411103}}

{"type":"orderbook_delta","sid":1,"seq":2814,"msg":{"market_ticker":"KXNEXTTEAMNBA-26LJAM-CLE","market_id":"7552b8d4-05de-4e41-84a8-97b0684da4a9","price_dollars":"0.7400","delta_fp":"-0.27","side":"no","ts":"2026-07-01T02:36:52.676178Z","ts_ms":1782873412676}}

{"type":"orderbook_delta","sid":1,"seq":2815,"msg":{"market_ticker":"KXNEXTTEAMNBA-26LJAM-CLE","market_id":"7552b8d4-05de-4e41-84a8-97b0684da4a9","price_dollars":"0.7400","delta_fp":"-1.95","side":"no","ts":"2026-07-01T02:36:52.692327Z","ts_ms":1782873412692}}

{"type":"orderbook_delta","sid":1,"seq":2816,"msg":{"market_ticker":"KXNEXTTEAMNBA-26LJAM-MIA","market_id":"492cb255-91da-4c91-bc9e-f83d090cc6dd","price_dollars":"0.8300","delta_fp":"-0.97","side":"no","ts":"2026-07-01T02:36:52.754704Z","ts_ms":1782873412754}}

{"type":"orderbook_delta","sid":1,"seq":2817,"msg":{"market_ticker":"KXNEXTTEAMNBA-26LJAM-GSW","market_id":"abbbad28-f309-4dd5-af38-2ad7ebf2acc3","price_dollars":"0.0100","delta_fp":"1.00","side":"yes","ts":"2026-07-01T02:36:53.655959Z","ts_ms":1782873413655}}

{"type":"orderbook_delta","sid":1,"seq":2818,"msg":{"market_ticker":"KXNEXTTEAMNBA-26LJAM-GSW","market_id":"abbbad28-f309-4dd5-af38-2ad7ebf2acc3","price_dollars":"0.0100","delta_fp":"1.00","side":"yes","ts":"2026-07-01T02:36:53.656644Z","ts_ms":1782873413656}}

{"type":"orderbook_delta","sid":1,"seq":2819,"msg":{"market_ticker":"KXNEXTTEAMNBA-26LJAM-GSW","market_id":"abbbad28-f309-4dd5-af38-2ad7ebf2acc3","price_dollars":"0.0100","delta_fp":"1.00","side":"yes","ts":"2026-07-01T02:36:53.657202Z","ts_ms":1782873413657}}

{"type":"orderbook_delta","sid":1,"seq":2820,"msg":{"market_ticker":"KXNEXTTEAMNBA-26LJAM-GSW","market_id":"abbbad28-f309-4dd5-af38-2ad7ebf2acc3","price_dollars":"0.0100","delta_fp":"1.00","side":"yes","ts":"2026-07-01T02:36:53.658011Z","ts_ms":1782873413658}}

{"type":"orderbook_delta","sid":1,"seq":2821,"msg":{"market_ticker":"KXNEXTTEAMNBA-26LJAM-GSW","market_id":"abbbad28-f309-4dd5-af38-2ad7ebf2acc3","price_dollars":"0.0100","delta_fp":"1.00","side":"yes","ts":"2026-07-01T02:36:53.65876Z","ts_ms":1782873413658}}

{"type":"orderbook_delta","sid":1,"seq":2822,"msg":{"market_ticker":"KXNEXTTEAMNBA-26LJAM-GSW","market_id":"abbbad28-f309-4dd5-af38-2ad7ebf2acc3","price_dollars":"0.0100","delta_fp":"1.00","side":"yes","ts":"2026-07-01T02:36:53.659492Z","ts_ms":1782873413659}}

{"type":"orderbook_delta","sid":1,"seq":2823,"msg":{"market_ticker":"KXNEXTTEAMNBA-26LJAM-CLE","market_id":"7552b8d4-05de-4e41-84a8-97b0684da4a9","price_dollars":"0.0100","delta_fp":"1.00","side":"yes","ts":"2026-07-01T02:36:53.659747Z","ts_ms":1782873413659}}

{"type":"orderbook_delta","sid":1,"seq":2824,"msg":{"market_ticker":"KXNEXTTEAMNBA-26LJAM-GSW","market_id":"abbbad28-f309-4dd5-af38-2ad7ebf2acc3","price_dollars":"0.0100","delta_fp":"1.00","side":"yes","ts":"2026-07-01T02:36:53.66018Z","ts_ms":1782873413660}}

{"type":"orderbook_delta","sid":1,"seq":2825,"msg":{"market_ticker":"KXNEXTTEAMNBA-26LJAM-GSW","market_id":"abbbad28-f309-4dd5-af38-2ad7ebf2acc3","price_dollars":"0.0100","delta_fp":"1.00","side":"yes","ts":"2026-07-01T02:36:53.663604Z","ts_ms":1782873413663}}

{"type":"orderbook_delta","sid":1,"seq":2826,"msg":{"market_ticker":"KXNEXTTEAMNBA-26LJAM-GSW","market_id":"abbbad28-f309-4dd5-af38-2ad7ebf2acc3","price_dollars":"0.0100","delta_fp":"1.00","side":"yes","ts":"2026-07-01T02:36:53.666942Z","ts_ms":1782873413666}}

{"type":"orderbook_delta","sid":1,"seq":2827,"msg":{"market_ticker":"KXNEXTTEAMNBA-26LJAM-GSW","market_id":"abbbad28-f309-4dd5-af38-2ad7ebf2acc3","price_dollars":"0.0100","delta_fp":"1.00","side":"yes","ts":"2026-07-01T02:36:53.66761Z","ts_ms":1782873413667}}

{"type":"orderbook_delta","sid":1,"seq":2828,"msg":{"market_ticker":"KXNEXTTEAMNBA-26LJAM-GSW","market_id":"abbbad28-f309-4dd5-af38-2ad7ebf2acc3","price_dollars":"0.0100","delta_fp":"1.00","side":"yes","ts":"2026-07-01T02:36:53.668079Z","ts_ms":1782873413668}}

{"type":"orderbook_delta","sid":1,"seq":2829,"msg":{"market_ticker":"KXNEXTTEAMNBA-26LJAM-GSW","market_id":"abbbad28-f309-4dd5-af38-2ad7ebf2acc3","price_dollars":"0.0100","delta_fp":"1.00","side":"yes","ts":"2026-07-01T02:36:53.668658Z","ts_ms":1782873413668}}

{"type":"orderbook_delta","sid":1,"seq":2830,"msg":{"market_ticker":"KXNEXTTEAMNBA-26LJAM-GSW","market_id":"abbbad28-f309-4dd5-af38-2ad7ebf2acc3","price_dollars":"0.0100","delta_fp":"1.00","side":"yes","ts":"2026-07-01T02:36:53.669224Z","ts_ms":1782873413669}}

{"type":"orderbook_delta","sid":1,"seq":2831,"msg":{"market_ticker":"KXNEXTTEAMNBA-26LJAM-GSW","market_id":"abbbad28-f309-4dd5-af38-2ad7ebf2acc3","price_dollars":"0.0100","delta_fp":"1.00","side":"yes","ts":"2026-07-01T02:36:53.669688Z","ts_ms":1782873413669}}

{"type":"orderbook_delta","sid":1,"seq":2832,"msg":{"market_ticker":"KXNEXTTEAMNBA-26LJAM-GSW","market_id":"abbbad28-f309-4dd5-af38-2ad7ebf2acc3","price_dollars":"0.0100","delta_fp":"1.00","side":"yes","ts":"2026-07-01T02:36:53.670097Z","ts_ms":1782873413670}}

{"type":"orderbook_delta","sid":1,"seq":2833,"msg":{"market_ticker":"KXNEXTTEAMNBA-26LJAM-GSW","market_id":"abbbad28-f309-4dd5-af38-2ad7ebf2acc3","price_dollars":"0.0100","delta_fp":"1.00","side":"yes","ts":"2026-07-01T02:36:53.670532Z","ts_ms":1782873413670}}

{"type":"orderbook_delta","sid":1,"seq":2834,"msg":{"market_ticker":"KXNEXTTEAMNBA-26LJAM-GSW","market_id":"abbbad28-f309-4dd5-af38-2ad7ebf2acc3","price_dollars":"0.0100","delta_fp":"1.00","side":"yes","ts":"2026-07-01T02:36:53.670945Z","ts_ms":1782873413670}}

{"type":"orderbook_delta","sid":1,"seq":2835,"msg":{"market_ticker":"KXNEXTTEAMNBA-26LJAM-GSW","market_id":"abbbad28-f309-4dd5-af38-2ad7ebf2acc3","price_dollars":"0.0100","delta_fp":"1.00","side":"yes","ts":"2026-07-01T02:36:53.671313Z","ts_ms":1782873413671}}

{"type":"orderbook_delta","sid":1,"seq":2836,"msg":{"market_ticker":"KXNEXTTEAMNBA-26LJAM-GSW","market_id":"abbbad28-f309-4dd5-af38-2ad7ebf2acc3","price_dollars":"0.0100","delta_fp":"1.00","side":"yes","ts":"2026-07-01T02:36:53.671638Z","ts_ms":1782873413671}}

{"type":"orderbook_delta","sid":1,"seq":2837,"msg":{"market_ticker":"KXNEXTTEAMNBA-26LJAM-GSW","market_id":"abbbad28-f309-4dd5-af38-2ad7ebf2acc3","price_dollars":"0.0100","delta_fp":"1.00","side":"yes","ts":"2026-07-01T02:36:53.671916Z","ts_ms":1782873413671}}

{"type":"orderbook_delta","sid":1,"seq":2838,"msg":{"market_ticker":"KXNEXTTEAMNBA-26LJAM-CLE","market_id":"7552b8d4-05de-4e41-84a8-97b0684da4a9","price_dollars":"0.7400","delta_fp":"-1.24","side":"no","ts":"2026-07-01T02:36:54.198133Z","ts_ms":1782873414198}}

{"type":"orderbook_delta","sid":1,"seq":2839,"msg":{"market_ticker":"KXNEXTTEAMNBA-26LJAM-MIA","market_id":"492cb255-91da-4c91-bc9e-f83d090cc6dd","price_dollars":"0.1600","delta_fp":"2083.33","side":"yes","ts":"2026-07-01T02:36:55.530632Z","ts_ms":1782873415530}}

{"type":"orderbook_delta","sid":1,"seq":2840,"msg":{"market_ticker":"KXNEXTTEAMNBA-26LJAM-MIA","market_id":"492cb255-91da-4c91-bc9e-f83d090cc6dd","price_dollars":"0.1500","delta_fp":"2222.22","side":"yes","ts":"2026-07-01T02:36:55.531092Z","ts_ms":1782873415531}}

{"type":"orderbook_delta","sid":1,"seq":2841,"msg":{"market_ticker":"KXNEXTTEAMNBA-26LJAM-MIA","market_id":"492cb255-91da-4c91-bc9e-f83d090cc6dd","price_dollars":"0.1400","delta_fp":"2380.95","side":"yes","ts":"2026-07-01T02:36:55.531762Z","ts_ms":1782873415531}}

{"type":"orderbook_delta","sid":1,"seq":2842,"msg":{"market_ticker":"KXNEXTTEAMNBA-26LJAM-MIA","market_id":"492cb255-91da-4c91-bc9e-f83d090cc6dd","price_dollars":"0.8300","delta_fp":"1960.78","side":"no","ts":"2026-07-01T02:36:55.532406Z","ts_ms":1782873415532}}

{"type":"orderbook_delta","sid":1,"seq":2843,"msg":{"market_ticker":"KXNEXTTEAMNBA-26LJAM-MIA","market_id":"492cb255-91da-4c91-bc9e-f83d090cc6dd","price_dollars":"0.8200","delta_fp":"1851.85","side":"no","ts":"2026-07-01T02:36:55.532864Z","ts_ms":1782873415532}}

{"type":"orderbook_delta","sid":1,"seq":2844,"msg":{"market_ticker":"KXNEXTTEAMNBA-26LJAM-MIA","market_id":"492cb255-91da-4c91-bc9e-f83d090cc6dd","price_dollars":"0.8100","delta_fp":"1754.38","side":"no","ts":"2026-07-01T02:36:55.533372Z","ts_ms":1782873415533}}

{"type":"orderbook_delta","sid":1,"seq":2845,"msg":{"market_ticker":"KXNEXTTEAMNBA-26LJAM-MIA","market_id":"492cb255-91da-4c91-bc9e-f83d090cc6dd","price_dollars":"0.8300","delta_fp":"-1.24","side":"no","ts":"2026-07-01T02:36:55.693793Z","ts_ms":1782873415693}}

{"type":"orderbook_delta","sid":1,"seq":2846,"msg":{"market_ticker":"KXNEXTTEAMNBA-26LJAM-GSW","market_id":"abbbad28-f309-4dd5-af38-2ad7ebf2acc3","price_dollars":"0.5200","delta_fp":"-0.54","side":"no","ts":"2026-07-01T02:36:57.379788Z","ts_ms":1782873417379}}

{"type":"orderbook_delta","sid":1,"seq":2847,"msg":{"market_ticker":"KXNEXTTEAMNBA-26LJAM-CLE","market_id":"7552b8d4-05de-4e41-84a8-97b0684da4a9","price_dollars":"0.7400","delta_fp":"-0.32","side":"no","ts":"2026-07-01T02:36:58.629389Z","ts_ms":1782873418629}}

{"type":"orderbook_delta","sid":1,"seq":2848,"msg":{"market_ticker":"KXNEXTTEAMNBA-26LJAM-GSW","market_id":"abbbad28-f309-4dd5-af38-2ad7ebf2acc3","price_dollars":"0.5200","delta_fp":"-0.80","side":"no","ts":"2026-07-01T02:36:58.965962Z","ts_ms":1782873418965}}

{"type":"orderbook_delta","sid":1,"seq":2849,"msg":{"market_ticker":"KXNEXTTEAMNBA-26LJAM-MIA","market_id":"492cb255-91da-4c91-bc9e-f83d090cc6dd","price_dollars":"0.8300","delta_fp":"-0.64","side":"no","ts":"2026-07-01T02:36:59.007374Z","ts_ms":1782873419007}}

{"type":"orderbook_delta","sid":1,"seq":2850,"msg":{"market_ticker":"KXNEXTTEAMNBA-26LJAM-MIA","market_id":"492cb255-91da-4c91-bc9e-f83d090cc6dd","price_dollars":"0.8300","delta_fp":"-1.77","side":"no","ts":"2026-07-01T02:36:59.069882Z","ts_ms":1782873419069}}

{"type":"orderbook_delta","sid":1,"seq":2851,"msg":{"market_ticker":"KXNEXTTEAMNBA-26LJAM-MIA","market_id":"492cb255-91da-4c91-bc9e-f83d090cc6dd","price_dollars":"0.0100","delta_fp":"1.00","side":"yes","ts":"2026-07-01T02:36:59.841134Z","ts_ms":1782873419841}}

{"type":"orderbook_delta","sid":1,"seq":2852,"msg":{"market_ticker":"KXNEXTTEAMNBA-26LJAM-MIA","market_id":"492cb255-91da-4c91-bc9e-f83d090cc6dd","price_dollars":"0.0100","delta_fp":"1.00","side":"yes","ts":"2026-07-01T02:36:59.841582Z","ts_ms":1782873419841}}

{"type":"orderbook_delta","sid":1,"seq":2853,"msg":{"market_ticker":"KXNEXTTEAMNBA-26LJAM-MIA","market_id":"492cb255-91da-4c91-bc9e-f83d090cc6dd","price_dollars":"0.0100","delta_fp":"1.00","side":"yes","ts":"2026-07-01T02:36:59.842015Z","ts_ms":1782873419842}}

{"type":"orderbook_delta","sid":1,"seq":2854,"msg":{"market_ticker":"KXNEXTTEAMNBA-26LJAM-MIA","market_id":"492cb255-91da-4c91-bc9e-f83d090cc6dd","price_dollars":"0.0100","delta_fp":"1.00","side":"yes","ts":"2026-07-01T02:36:59.842466Z","ts_ms":1782873419842}}

{"type":"orderbook_delta","sid":1,"seq":2855,"msg":{"market_ticker":"KXNEXTTEAMNBA-26LJAM-MIA","market_id":"492cb255-91da-4c91-bc9e-f83d090cc6dd","price_dollars":"0.0100","delta_fp":"1.00","side":"yes","ts":"2026-07-01T02:36:59.842914Z","ts_ms":1782873419842}}

{"type":"orderbook_delta","sid":1,"seq":2856,"msg":{"market_ticker":"KXNEXTTEAMNBA-26LJAM-MIA","market_id":"492cb255-91da-4c91-bc9e-f83d090cc6dd","price_dollars":"0.0100","delta_fp":"1.00","side":"yes","ts":"2026-07-01T02:36:59.84325Z","ts_ms":1782873419843}}

{"type":"orderbook_delta","sid":1,"seq":2857,"msg":{"market_ticker":"KXNEXTTEAMNBA-26LJAM-MIA","market_id":"492cb255-91da-4c91-bc9e-f83d090cc6dd","price_dollars":"0.0100","delta_fp":"1.00","side":"yes","ts":"2026-07-01T02:36:59.843754Z","ts_ms":1782873419843}}

{"type":"orderbook_delta","sid":1,"seq":2858,"msg":{"market_ticker":"KXNEXTTEAMNBA-26LJAM-MIA","market_id":"492cb255-91da-4c91-bc9e-f83d090cc6dd","price_dollars":"0.0100","delta_fp":"1.00","side":"yes","ts":"2026-07-01T02:36:59.84419Z","ts_ms":1782873419844}}

{"type":"orderbook_delta","sid":1,"seq":2859,"msg":{"market_ticker":"KXNEXTTEAMNBA-26LJAM-MIA","market_id":"492cb255-91da-4c91-bc9e-f83d090cc6dd","price_dollars":"0.0100","delta_fp":"1.00","side":"yes","ts":"2026-07-01T02:36:59.844677Z","ts_ms":1782873419844}}

{"type":"orderbook_delta","sid":1,"seq":2860,"msg":{"market_ticker":"KXNEXTTEAMNBA-26LJAM-MIA","market_id":"492cb255-91da-4c91-bc9e-f83d090cc6dd","price_dollars":"0.0100","delta_fp":"1.00","side":"yes","ts":"2026-07-01T02:36:59.845176Z","ts_ms":1782873419845}}

{"type":"orderbook_delta","sid":1,"seq":2861,"msg":{"market_ticker":"KXNEXTTEAMNBA-26LJAM-MIA","market_id":"492cb255-91da-4c91-bc9e-f83d090cc6dd","price_dollars":"0.0100","delta_fp":"1.00","side":"yes","ts":"2026-07-01T02:36:59.845741Z","ts_ms":1782873419845}}

{"type":"orderbook_delta","sid":1,"seq":2862,"msg":{"market_ticker":"KXNEXTTEAMNBA-26LJAM-MIA","market_id":"492cb255-91da-4c91-bc9e-f83d090cc6dd","price_dollars":"0.0100","delta_fp":"1.00","side":"yes","ts":"2026-07-01T02:36:59.846373Z","ts_ms":1782873419846}}

{"type":"orderbook_delta","sid":1,"seq":2863,"msg":{"market_ticker":"KXNEXTTEAMNBA-26LJAM-MIA","market_id":"492cb255-91da-4c91-bc9e-f83d090cc6dd","price_dollars":"0.0100","delta_fp":"1.00","side":"yes","ts":"2026-07-01T02:36:59.846815Z","ts_ms":1782873419846}}

{"type":"orderbook_delta","sid":1,"seq":2864,"msg":{"market_ticker":"KXNEXTTEAMNBA-26LJAM-GSW","market_id":"abbbad28-f309-4dd5-af38-2ad7ebf2acc3","price_dollars":"0.0100","delta_fp":"1.00","side":"yes","ts":"2026-07-01T02:36:59.847109Z","ts_ms":1782873419847}}

{"type":"orderbook_delta","sid":1,"seq":2865,"msg":{"market_ticker":"KXNEXTTEAMNBA-26LJAM-MIA","market_id":"492cb255-91da-4c91-bc9e-f83d090cc6dd","price_dollars":"0.0100","delta_fp":"1.00","side":"yes","ts":"2026-07-01T02:36:59.84719Z","ts_ms":1782873419847}}

{"type":"orderbook_delta","sid":1,"seq":2866,"msg":{"market_ticker":"KXNEXTTEAMNBA-26LJAM-GSW","market_id":"abbbad28-f309-4dd5-af38-2ad7ebf2acc3","price_dollars":"0.0100","delta_fp":"1.00","side":"yes","ts":"2026-07-01T02:36:59.847682Z","ts_ms":1782873419847}}

{"type":"orderbook_delta","sid":1,"seq":2867,"msg":{"market_ticker":"KXNEXTTEAMNBA-26LJAM-MIA","market_id":"492cb255-91da-4c91-bc9e-f83d090cc6dd","price_dollars":"0.0100","delta_fp":"1.00","side":"yes","ts":"2026-07-01T02:36:59.847735Z","ts_ms":1782873419847}}

{"type":"orderbook_delta","sid":1,"seq":2868,"msg":{"market_ticker":"KXNEXTTEAMNBA-26LJAM-MIA","market_id":"492cb255-91da-4c91-bc9e-f83d090cc6dd","price_dollars":"0.0100","delta_fp":"1.00","side":"yes","ts":"2026-07-01T02:36:59.848278Z","ts_ms":1782873419848}}

{"type":"orderbook_delta","sid":1,"seq":2869,"msg":{"market_ticker":"KXNEXTTEAMNBA-26LJAM-GSW","market_id":"abbbad28-f309-4dd5-af38-2ad7ebf2acc3","price_dollars":"0.0100","delta_fp":"1.00","side":"yes","ts":"2026-07-01T02:36:59.848429Z","ts_ms":1782873419848}}

{"type":"orderbook_delta","sid":1,"seq":2870,"msg":{"market_ticker":"KXNEXTTEAMNBA-26LJAM-MIA","market_id":"492cb255-91da-4c91-bc9e-f83d090cc6dd","price_dollars":"0.0100","delta_fp":"1.00","side":"yes","ts":"2026-07-01T02:36:59.848652Z","ts_ms":1782873419848}}

{"type":"orderbook_delta","sid":1,"seq":2871,"msg":{"market_ticker":"KXNEXTTEAMNBA-26LJAM-GSW","market_id":"abbbad28-f309-4dd5-af38-2ad7ebf2acc3","price_dollars":"0.0100","delta_fp":"1.00","side":"yes","ts":"2026-07-01T02:36:59.848899Z","ts_ms":1782873419848}}

{"type":"orderbook_delta","sid":1,"seq":2872,"msg":{"market_ticker":"KXNEXTTEAMNBA-26LJAM-MIA","market_id":"492cb255-91da-4c91-bc9e-f83d090cc6dd","price_dollars":"0.0100","delta_fp":"1.00","side":"yes","ts":"2026-07-01T02:36:59.849089Z","ts_ms":1782873419849}}

{"type":"orderbook_delta","sid":1,"seq":2873,"msg":{"market_ticker":"KXNEXTTEAMNBA-26LJAM-GSW","market_id":"abbbad28-f309-4dd5-af38-2ad7ebf2acc3","price_dollars":"0.0100","delta_fp":"1.00","side":"yes","ts":"2026-07-01T02:36:59.849236Z","ts_ms":1782873419849}}

{"type":"orderbook_delta","sid":1,"seq":2874,"msg":{"market_ticker":"KXNEXTTEAMNBA-26LJAM-MIA","market_id":"492cb255-91da-4c91-bc9e-f83d090cc6dd","price_dollars":"0.0100","delta_fp":"1.00","side":"yes","ts":"2026-07-01T02:36:59.849639Z","ts_ms":1782873419849}}

{"type":"orderbook_delta","sid":1,"seq":2875,"msg":{"market_ticker":"KXNEXTTEAMNBA-26LJAM-GSW","market_id":"abbbad28-f309-4dd5-af38-2ad7ebf2acc3","price_dollars":"0.0100","delta_fp":"1.00","side":"yes","ts":"2026-07-01T02:36:59.849676Z","ts_ms":1782873419849}}

{"type":"orderbook_delta","sid":1,"seq":2876,"msg":{"market_ticker":"KXNEXTTEAMNBA-26LJAM-MIA","market_id":"492cb255-91da-4c91-bc9e-f83d090cc6dd","price_dollars":"0.0100","delta_fp":"1.00","side":"yes","ts":"2026-07-01T02:36:59.850087Z","ts_ms":1782873419850}}

{"type":"orderbook_delta","sid":1,"seq":2877,"msg":{"market_ticker":"KXNEXTTEAMNBA-26LJAM-GSW","market_id":"abbbad28-f309-4dd5-af38-2ad7ebf2acc3","price_dollars":"0.0100","delta_fp":"1.00","side":"yes","ts":"2026-07-01T02:36:59.850315Z","ts_ms":1782873419850}}

{"type":"orderbook_delta","sid":1,"seq":2878,"msg":{"market_ticker":"KXNEXTTEAMNBA-26LJAM-GSW","market_id":"abbbad28-f309-4dd5-af38-2ad7ebf2acc3","price_dollars":"0.0100","delta_fp":"1.00","side":"yes","ts":"2026-07-01T02:36:59.850797Z","ts_ms":1782873419850}}

{"type":"orderbook_delta","sid":1,"seq":2879,"msg":{"market_ticker":"KXNEXTTEAMNBA-26LJAM-GSW","market_id":"abbbad28-f309-4dd5-af38-2ad7ebf2acc3","price_dollars":"0.0100","delta_fp":"1.00","side":"yes","ts":"2026-07-01T02:36:59.851255Z","ts_ms":1782873419851}}

{"type":"orderbook_delta","sid":1,"seq":2880,"msg":{"market_ticker":"KXNEXTTEAMNBA-26LJAM-GSW","market_id":"abbbad28-f309-4dd5-af38-2ad7ebf2acc3","price_dollars":"0.0100","delta_fp":"1.00","side":"yes","ts":"2026-07-01T02:36:59.851726Z","ts_ms":1782873419851}}

{"type":"orderbook_delta","sid":1,"seq":2881,"msg":{"market_ticker":"KXNEXTTEAMNBA-26LJAM-GSW","market_id":"abbbad28-f309-4dd5-af38-2ad7ebf2acc3","price_dollars":"0.0100","delta_fp":"1.00","side":"yes","ts":"2026-07-01T02:36:59.852289Z","ts_ms":1782873419852}}

{"type":"orderbook_delta","sid":1,"seq":2882,"msg":{"market_ticker":"KXNEXTTEAMNBA-26LJAM-GSW","market_id":"abbbad28-f309-4dd5-af38-2ad7ebf2acc3","price_dollars":"0.0100","delta_fp":"1.00","side":"yes","ts":"2026-07-01T02:36:59.852588Z","ts_ms":1782873419852}}

{"type":"orderbook_delta","sid":1,"seq":2883,"msg":{"market_ticker":"KXNEXTTEAMNBA-26LJAM-GSW","market_id":"abbbad28-f309-4dd5-af38-2ad7ebf2acc3","price_dollars":"0.0100","delta_fp":"1.00","side":"yes","ts":"2026-07-01T02:36:59.853104Z","ts_ms":1782873419853}}

{"type":"orderbook_delta","sid":1,"seq":2884,"msg":{"market_ticker":"KXNEXTTEAMNBA-26LJAM-GSW","market_id":"abbbad28-f309-4dd5-af38-2ad7ebf2acc3","price_dollars":"0.0100","delta_fp":"1.00","side":"yes","ts":"2026-07-01T02:36:59.853536Z","ts_ms":1782873419853}}

{"type":"orderbook_delta","sid":1,"seq":2885,"msg":{"market_ticker":"KXNEXTTEAMNBA-26LJAM-GSW","market_id":"abbbad28-f309-4dd5-af38-2ad7ebf2acc3","price_dollars":"0.0100","delta_fp":"1.00","side":"yes","ts":"2026-07-01T02:36:59.853837Z","ts_ms":1782873419853}}

{"type":"orderbook_delta","sid":1,"seq":2886,"msg":{"market_ticker":"KXNEXTTEAMNBA-26LJAM-GSW","market_id":"abbbad28-f309-4dd5-af38-2ad7ebf2acc3","price_dollars":"0.0100","delta_fp":"1.00","side":"yes","ts":"2026-07-01T02:36:59.854084Z","ts_ms":1782873419854}}

{"type":"orderbook_delta","sid":1,"seq":2887,"msg":{"market_ticker":"KXNEXTTEAMNBA-26LJAM-GSW","market_id":"abbbad28-f309-4dd5-af38-2ad7ebf2acc3","price_dollars":"0.0100","delta_fp":"1.00","side":"yes","ts":"2026-07-01T02:36:59.854472Z","ts_ms":1782873419854}}

{"type":"orderbook_delta","sid":1,"seq":2888,"msg":{"market_ticker":"KXNEXTTEAMNBA-26LJAM-GSW","market_id":"abbbad28-f309-4dd5-af38-2ad7ebf2acc3","price_dollars":"0.0100","delta_fp":"1.00","side":"yes","ts":"2026-07-01T02:36:59.854874Z","ts_ms":1782873419854}}

{"type":"orderbook_delta","sid":1,"seq":2889,"msg":{"market_ticker":"KXNEXTTEAMNBA-26LJAM-GSW","market_id":"abbbad28-f309-4dd5-af38-2ad7ebf2acc3","price_dollars":"0.0100","delta_fp":"1.00","side":"yes","ts":"2026-07-01T02:36:59.855273Z","ts_ms":1782873419855}}

{"type":"orderbook_delta","sid":1,"seq":2890,"msg":{"market_ticker":"KXNEXTTEAMNBA-26LJAM-GSW","market_id":"abbbad28-f309-4dd5-af38-2ad7ebf2acc3","price_dollars":"0.0100","delta_fp":"1.00","side":"yes","ts":"2026-07-01T02:36:59.855698Z","ts_ms":1782873419855}}

{"type":"orderbook_delta","sid":1,"seq":2891,"msg":{"market_ticker":"KXNEXTTEAMNBA-26LJAM-CLE","market_id":"7552b8d4-05de-4e41-84a8-97b0684da4a9","price_dollars":"0.7400","delta_fp":"-1.98","side":"no","ts":"2026-07-01T02:37:00.300427Z","ts_ms":1782873420300}}

{"type":"orderbook_delta","sid":1,"seq":2892,"msg":{"market_ticker":"KXNEXTTEAMNBA-26LJAM-MIA","market_id":"492cb255-91da-4c91-bc9e-f83d090cc6dd","price_dollars":"0.8300","delta_fp":"-0.69","side":"no","ts":"2026-07-01T02:37:00.304884Z","ts_ms":1782873420304}}

{"type":"orderbook_delta","sid":1,"seq":2893,"msg":{"market_ticker":"KXNEXTTEAMNBA-26LJAM-CLE","market_id":"7552b8d4-05de-4e41-84a8-97b0684da4a9","price_dollars":"0.7400","delta_fp":"-1.70","side":"no","ts":"2026-07-01T02:37:00.577727Z","ts_ms":1782873420577}}

{"type":"orderbook_delta","sid":1,"seq":2894,"msg":{"market_ticker":"KXNEXTTEAMNBA-26LJAM-GSW","market_id":"abbbad28-f309-4dd5-af38-2ad7ebf2acc3","price_dollars":"0.5200","delta_fp":"-1.95","side":"no","ts":"2026-07-01T02:37:00.598498Z","ts_ms":1782873420598}}

