{"type":"orderbook_delta","sid":1,"seq":759,"msg":{"market_ticker":"KXNEXTTEAMNBA-26LJAM-GSW","market_id":"abbbad28-f309-4dd5-af38-2ad7ebf2acc3","price_dollars":"0.0100","delta_fp":"-1.00","side":"yes","ts":"2026-07-01T02:33:06.670556Z","ts_ms":1782873186670}}

{"type":"orderbook_delta","sid":1,"seq":760,"msg":{"market_ticker":"KXNEXTTEAMNBA-26LJAM-GSW","market_id":"abbbad28-f309-4dd5-af38-2ad7ebf2acc3","price_dollars":"0.0100","delta_fp":"-1.00","side":"yes","ts":"2026-07-01T02:33:06.670556Z","ts_ms":1782873186670}}

{"type":"orderbook_delta","sid":1,"seq":761,"msg":{"market_ticker":"KXNEXTTEAMNBA-26LJAM-GSW","market_id":"abbbad28-f309-4dd5-af38-2ad7ebf2acc3","price_dollars":"0.0100","delta_fp":"-1.00","side":"yes","ts":"2026-07-01T02:33:06.670556Z","ts_ms":1782873186670}}

{"type":"orderbook_delta","sid":1,"seq":762,"msg":{"market_ticker":"KXNEXTTEAMNBA-26LJAM-GSW","market_id":"abbbad28-f309-4dd5-af38-2ad7ebf2acc3","price_dollars":"0.0100","delta_fp":"-1.00","side":"yes","ts":"2026-07-01T02:33:06.670556Z","ts_ms":1782873186670}}

{"type":"orderbook_delta","sid":1,"seq":763,"msg":{"market_ticker":"KXNEXTTEAMNBA-26LJAM-GSW","market_id":"abbbad28-f309-4dd5-af38-2ad7ebf2acc3","price_dollars":"0.0100","delta_fp":"-1.00","side":"yes","ts":"2026-07-01T02:33:06.670556Z","ts_ms":1782873186670}}

{"type":"orderbook_delta","sid":1,"seq":764,"msg":{"market_ticker":"KXNEXTTEAMNBA-26LJAM-GSW","market_id":"abbbad28-f309-4dd5-af38-2ad7ebf2acc3","price_dollars":"0.0100","delta_fp":"-1.00","side":"yes","ts":"2026-07-01T02:33:06.670556Z","ts_ms":1782873186670}}

{"type":"orderbook_delta","sid":1,"seq":765,"msg":{"market_ticker":"KXNEXTTEAMNBA-26LJAM-GSW","market_id":"abbbad28-f309-4dd5-af38-2ad7ebf2acc3","price_dollars":"0.0100","delta_fp":"-1.00","side":"yes","ts":"2026-07-01T02:33:06.670556Z","ts_ms":1782873186670}}

{"type":"orderbook_delta","sid":1,"seq":766,"msg":{"market_ticker":"KXNEXTTEAMNBA-26LJAM-GSW","market_id":"abbbad28-f309-4dd5-af38-2ad7ebf2acc3","price_dollars":"0.0100","delta_fp":"-1.00","side":"yes","ts":"2026-07-01T02:33:06.670556Z","ts_ms":1782873186670}}

{"type":"orderbook_delta","sid":1,"seq":767,"msg":{"market_ticker":"KXNEXTTEAMNBA-26LJAM-GSW","market_id":"abbbad28-f309-4dd5-af38-2ad7ebf2acc3","price_dollars":"0.0100","delta_fp":"-1.00","side":"yes","ts":"2026-07-01T02:33:06.670556Z","ts_ms":1782873186670}}

{"type":"orderbook_delta","sid":1,"seq":768,"msg":{"market_ticker":"KXNEXTTEAMNBA-26LJAM-GSW","market_id":"abbbad28-f309-4dd5-af38-2ad7ebf2acc3","price_dollars":"0.0100","delta_fp":"-1.00","side":"yes","ts":"2026-07-01T02:33:06.670556Z","ts_ms":1782873186670}}

{"type":"orderbook_delta","sid":1,"seq":769,"msg":{"market_ticker":"KXNEXTTEAMNBA-26LJAM-GSW","market_id":"abbbad28-f309-4dd5-af38-2ad7ebf2acc3","price_dollars":"0.0100","delta_fp":"-1.00","side":"yes","ts":"2026-07-01T02:33:06.670556Z","ts_ms":1782873186670}}

{"type":"orderbook_delta","sid":1,"seq":770,"msg":{"market_ticker":"KXNEXTTEAMNBA-26LJAM-GSW","market_id":"abbbad28-f309-4dd5-af38-2ad7ebf2acc3","price_dollars":"0.0100","delta_fp":"-1.00","side":"yes","ts":"2026-07-01T02:33:06.670556Z","ts_ms":1782873186670}}

{"type":"orderbook_delta","sid":1,"seq":771,"msg":{"market_ticker":"KXNEXTTEAMNBA-26LJAM-GSW","market_id":"abbbad28-f309-4dd5-af38-2ad7ebf2acc3","price_dollars":"0.0100","delta_fp":"-1.00","side":"yes","ts":"2026-07-01T02:33:06.670556Z","ts_ms":1782873186670}}

{"type":"orderbook_delta","sid":1,"seq":772,"msg":{"market_ticker":"KXNEXTTEAMNBA-26LJAM-GSW","market_id":"abbbad28-f309-4dd5-af38-2ad7ebf2acc3","price_dollars":"0.0100","delta_fp":"-1.00","side":"yes","ts":"2026-07-01T02:33:06.670556Z","ts_ms":1782873186670}}

{"type":"orderbook_delta","sid":1,"seq":773,"msg":{"market_ticker":"KXNEXTTEAMNBA-26LJAM-GSW","market_id":"abbbad28-f309-4dd5-af38-2ad7ebf2acc3","price_dollars":"0.0100","delta_fp":"-1.00","side":"yes","ts":"2026-07-01T02:33:06.670556Z","ts_ms":1782873186670}}

{"type":"orderbook_delta","sid":1,"seq":774,"msg":{"market_ticker":"KXNEXTTEAMNBA-26LJAM-GSW","market_id":"abbbad28-f309-4dd5-af38-2ad7ebf2acc3","price_dollars":"0.0100","delta_fp":"-1.00","side":"yes","ts":"2026-07-01T02:33:06.670556Z","ts_ms":1782873186670}}

{"type":"orderbook_delta","sid":1,"seq":775,"msg":{"market_ticker":"KXNEXTTEAMNBA-26LJAM-GSW","market_id":"abbbad28-f309-4dd5-af38-2ad7ebf2acc3","price_dollars":"0.0100","delta_fp":"-1.00","side":"yes","ts":"2026-07-01T02:33:06.670556Z","ts_ms":1782873186670}}

{"type":"orderbook_delta","sid":1,"seq":776,"msg":{"market_ticker":"KXNEXTTEAMNBA-26LJAM-GSW","market_id":"abbbad28-f309-4dd5-af38-2ad7ebf2acc3","price_dollars":"0.0100","delta_fp":"-1.00","side":"yes","ts":"2026-07-01T02:33:06.670556Z","ts_ms":1782873186670}}

{"type":"orderbook_delta","sid":1,"seq":777,"msg":{"market_ticker":"KXNEXTTEAMNBA-26LJAM-GSW","market_id":"abbbad28-f309-4dd5-af38-2ad7ebf2acc3","price_dollars":"0.0100","delta_fp":"-1.00","side":"yes","ts":"2026-07-01T02:33:06.670556Z","ts_ms":1782873186670}}

{"type":"orderbook_delta","sid":1,"seq":778,"msg":{"market_ticker":"KXNEXTTEAMNBA-26LJAM-GSW","market_id":"abbbad28-f309-4dd5-af38-2ad7ebf2acc3","price_dollars":"0.0100","delta_fp":"-1.00","side":"yes","ts":"2026-07-01T02:33:06.670556Z","ts_ms":1782873186670}}

{"type":"orderbook_delta","sid":1,"seq":779,"msg":{"market_ticker":"KXNEXTTEAMNBA-26LJAM-GSW","market_id":"abbbad28-f309-4dd5-af38-2ad7ebf2acc3","price_dollars":"0.0100","delta_fp":"-1.00","side":"yes","ts":"2026-07-01T02:33:06.670556Z","ts_ms":1782873186670}}

{"type":"orderbook_delta","sid":1,"seq":780,"msg":{"market_ticker":"KXNEXTTEAMNBA-26LJAM-GSW","market_id":"abbbad28-f309-4dd5-af38-2ad7ebf2acc3","price_dollars":"0.0100","delta_fp":"-1.00","side":"yes","ts":"2026-07-01T02:33:06.670556Z","ts_ms":1782873186670}}

{"type":"orderbook_delta","sid":1,"seq":781,"msg":{"market_ticker":"KXNEXTTEAMNBA-26LJAM-GSW","market_id":"abbbad28-f309-4dd5-af38-2ad7ebf2acc3","price_dollars":"0.0100","delta_fp":"-1.00","side":"yes","ts":"2026-07-01T02:33:06.670556Z","ts_ms":1782873186670}}

{"type":"orderbook_delta","sid":1,"seq":782,"msg":{"market_ticker":"KXNEXTTEAMNBA-26LJAM-GSW","market_id":"abbbad28-f309-4dd5-af38-2ad7ebf2acc3","price_dollars":"0.0100","delta_fp":"-1.00","side":"yes","ts":"2026-07-01T02:33:06.670556Z","ts_ms":1782873186670}}

{"type":"orderbook_delta","sid":1,"seq":783,"msg":{"market_ticker":"KXNEXTTEAMNBA-26LJAM-GSW","market_id":"abbbad28-f309-4dd5-af38-2ad7ebf2acc3","price_dollars":"0.0100","delta_fp":"-1.00","side":"yes","ts":"2026-07-01T02:33:06.670556Z","ts_ms":1782873186670}}

{"type":"orderbook_delta","sid":1,"seq":784,"msg":{"market_ticker":"KXNEXTTEAMNBA-26LJAM-GSW","market_id":"abbbad28-f309-4dd5-af38-2ad7ebf2acc3","price_dollars":"0.0100","delta_fp":"-1.00","side":"yes","ts":"2026-07-01T02:33:06.670556Z","ts_ms":1782873186670}}

{"type":"orderbook_delta","sid":1,"seq":785,"msg":{"market_ticker":"KXNEXTTEAMNBA-26LJAM-GSW","market_id":"abbbad28-f309-4dd5-af38-2ad7ebf2acc3","price_dollars":"0.0100","delta_fp":"-1.00","side":"yes","ts":"2026-07-01T02:33:06.670556Z","ts_ms":1782873186670}}

{"type":"orderbook_delta","sid":1,"seq":786,"msg":{"market_ticker":"KXNEXTTEAMNBA-26LJAM-GSW","market_id":"abbbad28-f309-4dd5-af38-2ad7ebf2acc3","price_dollars":"0.0100","delta_fp":"-1.00","side":"yes","ts":"2026-07-01T02:33:06.670556Z","ts_ms":1782873186670}}

{"type":"orderbook_delta","sid":1,"seq":787,"msg":{"market_ticker":"KXNEXTTEAMNBA-26LJAM-GSW","market_id":"abbbad28-f309-4dd5-af38-2ad7ebf2acc3","price_dollars":"0.0100","delta_fp":"-1.00","side":"yes","ts":"2026-07-01T02:33:06.670556Z","ts_ms":1782873186670}}

{"type":"orderbook_delta","sid":1,"seq":788,"msg":{"market_ticker":"KXNEXTTEAMNBA-26LJAM-GSW","market_id":"abbbad28-f309-4dd5-af38-2ad7ebf2acc3","price_dollars":"0.0100","delta_fp":"-1.00","side":"yes","ts":"2026-07-01T02:33:06.670556Z","ts_ms":1782873186670}}

{"type":"orderbook_delta","sid":1,"seq":789,"msg":{"market_ticker":"KXNEXTTEAMNBA-26LJAM-GSW","market_id":"abbbad28-f309-4dd5-af38-2ad7ebf2acc3","price_dollars":"0.0100","delta_fp":"-1.00","side":"yes","ts":"2026-07-01T02:33:06.670556Z","ts_ms":1782873186670}}

{"type":"orderbook_delta","sid":1,"seq":790,"msg":{"market_ticker":"KXNEXTTEAMNBA-26LJAM-GSW","market_id":"abbbad28-f309-4dd5-af38-2ad7ebf2acc3","price_dollars":"0.0100","delta_fp":"-1.00","side":"yes","ts":"2026-07-01T02:33:06.670556Z","ts_ms":1782873186670}}

{"type":"orderbook_delta","sid":1,"seq":791,"msg":{"market_ticker":"KXNEXTTEAMNBA-26LJAM-GSW","market_id":"abbbad28-f309-4dd5-af38-2ad7ebf2acc3","price_dollars":"0.0100","delta_fp":"-1.00","side":"yes","ts":"2026-07-01T02:33:06.670556Z","ts_ms":1782873186670}}

{"type":"orderbook_delta","sid":1,"seq":792,"msg":{"market_ticker":"KXNEXTTEAMNBA-26LJAM-GSW","market_id":"abbbad28-f309-4dd5-af38-2ad7ebf2acc3","price_dollars":"0.0100","delta_fp":"-1.00","side":"yes","ts":"2026-07-01T02:33:06.670556Z","ts_ms":1782873186670}}

{"type":"orderbook_delta","sid":1,"seq":793,"msg":{"market_ticker":"KXNEXTTEAMNBA-26LJAM-GSW","market_id":"abbbad28-f309-4dd5-af38-2ad7ebf2acc3","price_dollars":"0.0100","delta_fp":"-1.00","side":"yes","ts":"2026-07-01T02:33:06.670556Z","ts_ms":1782873186670}}

{"type":"orderbook_delta","sid":1,"seq":794,"msg":{"market_ticker":"KXNEXTTEAMNBA-26LJAM-GSW","market_id":"abbbad28-f309-4dd5-af38-2ad7ebf2acc3","price_dollars":"0.0100","delta_fp":"-1.00","side":"yes","ts":"2026-07-01T02:33:06.670556Z","ts_ms":1782873186670}}

{"type":"orderbook_delta","sid":1,"seq":795,"msg":{"market_ticker":"KXNEXTTEAMNBA-26LJAM-GSW","market_id":"abbbad28-f309-4dd5-af38-2ad7ebf2acc3","price_dollars":"0.0100","delta_fp":"-1.00","side":"yes","ts":"2026-07-01T02:33:06.670556Z","ts_ms":1782873186670}}

{"type":"orderbook_delta","sid":1,"seq":796,"msg":{"market_ticker":"KXNEXTTEAMNBA-26LJAM-GSW","market_id":"abbbad28-f309-4dd5-af38-2ad7ebf2acc3","price_dollars":"0.0100","delta_fp":"-1.00","side":"yes","ts":"2026-07-01T02:33:06.670556Z","ts_ms":1782873186670}}

{"type":"orderbook_delta","sid":1,"seq":797,"msg":{"market_ticker":"KXNEXTTEAMNBA-26LJAM-GSW","market_id":"abbbad28-f309-4dd5-af38-2ad7ebf2acc3","price_dollars":"0.0100","delta_fp":"-1.00","side":"yes","ts":"2026-07-01T02:33:06.670556Z","ts_ms":1782873186670}}

{"type":"orderbook_delta","sid":1,"seq":798,"msg":{"market_ticker":"KXNEXTTEAMNBA-26LJAM-GSW","market_id":"abbbad28-f309-4dd5-af38-2ad7ebf2acc3","price_dollars":"0.0100","delta_fp":"-1.00","side":"yes","ts":"2026-07-01T02:33:06.670556Z","ts_ms":1782873186670}}

{"type":"orderbook_delta","sid":1,"seq":799,"msg":{"market_ticker":"KXNEXTTEAMNBA-26LJAM-GSW","market_id":"abbbad28-f309-4dd5-af38-2ad7ebf2acc3","price_dollars":"0.0100","delta_fp":"-1.00","side":"yes","ts":"2026-07-01T02:33:06.670556Z","ts_ms":1782873186670}}

{"type":"orderbook_delta","sid":1,"seq":800,"msg":{"market_ticker":"KXNEXTTEAMNBA-26LJAM-GSW","market_id":"abbbad28-f309-4dd5-af38-2ad7ebf2acc3","price_dollars":"0.0100","delta_fp":"-1.00","side":"yes","ts":"2026-07-01T02:33:06.670556Z","ts_ms":1782873186670}}

{"type":"orderbook_delta","sid":1,"seq":801,"msg":{"market_ticker":"KXNEXTTEAMNBA-26LJAM-GSW","market_id":"abbbad28-f309-4dd5-af38-2ad7ebf2acc3","price_dollars":"0.0100","delta_fp":"-1.00","side":"yes","ts":"2026-07-01T02:33:06.670556Z","ts_ms":1782873186670}}

{"type":"orderbook_delta","sid":1,"seq":802,"msg":{"market_ticker":"KXNEXTTEAMNBA-26LJAM-GSW","market_id":"abbbad28-f309-4dd5-af38-2ad7ebf2acc3","price_dollars":"0.0100","delta_fp":"-1.00","side":"yes","ts":"2026-07-01T02:33:06.670556Z","ts_ms":1782873186670}}

{"type":"orderbook_delta","sid":1,"seq":803,"msg":{"market_ticker":"KXNEXTTEAMNBA-26LJAM-GSW","market_id":"abbbad28-f309-4dd5-af38-2ad7ebf2acc3","price_dollars":"0.0100","delta_fp":"-1.00","side":"yes","ts":"2026-07-01T02:33:06.670556Z","ts_ms":1782873186670}}

{"type":"orderbook_delta","sid":1,"seq":804,"msg":{"market_ticker":"KXNEXTTEAMNBA-26LJAM-GSW","market_id":"abbbad28-f309-4dd5-af38-2ad7ebf2acc3","price_dollars":"0.0100","delta_fp":"-1.00","side":"yes","ts":"2026-07-01T02:33:06.670556Z","ts_ms":1782873186670}}

{"type":"orderbook_delta","sid":1,"seq":805,"msg":{"market_ticker":"KXNEXTTEAMNBA-26LJAM-GSW","market_id":"abbbad28-f309-4dd5-af38-2ad7ebf2acc3","price_dollars":"0.0100","delta_fp":"-1.00","side":"yes","ts":"2026-07-01T02:33:06.670556Z","ts_ms":1782873186670}}

{"type":"orderbook_delta","sid":1,"seq":806,"msg":{"market_ticker":"KXNEXTTEAMNBA-26LJAM-GSW","market_id":"abbbad28-f309-4dd5-af38-2ad7ebf2acc3","price_dollars":"0.0100","delta_fp":"-1.00","side":"yes","ts":"2026-07-01T02:33:06.670556Z","ts_ms":1782873186670}}

{"type":"orderbook_delta","sid":1,"seq":807,"msg":{"market_ticker":"KXNEXTTEAMNBA-26LJAM-GSW","market_id":"abbbad28-f309-4dd5-af38-2ad7ebf2acc3","price_dollars":"0.0100","delta_fp":"-1.00","side":"yes","ts":"2026-07-01T02:33:06.670556Z","ts_ms":1782873186670}}

{"type":"orderbook_delta","sid":1,"seq":808,"msg":{"market_ticker":"KXNEXTTEAMNBA-26LJAM-GSW","market_id":"abbbad28-f309-4dd5-af38-2ad7ebf2acc3","price_dollars":"0.0100","delta_fp":"-1.00","side":"yes","ts":"2026-07-01T02:33:06.670556Z","ts_ms":1782873186670}}

{"type":"orderbook_delta","sid":1,"seq":809,"msg":{"market_ticker":"KXNEXTTEAMNBA-26LJAM-GSW","market_id":"abbbad28-f309-4dd5-af38-2ad7ebf2acc3","price_dollars":"0.0100","delta_fp":"-1.00","side":"yes","ts":"2026-07-01T02:33:06.670556Z","ts_ms":1782873186670}}

{"type":"orderbook_delta","sid":1,"seq":810,"msg":{"market_ticker":"KXNEXTTEAMNBA-26LJAM-GSW","market_id":"abbbad28-f309-4dd5-af38-2ad7ebf2acc3","price_dollars":"0.0100","delta_fp":"-1.00","side":"yes","ts":"2026-07-01T02:33:06.670556Z","ts_ms":1782873186670}}

{"type":"orderbook_delta","sid":1,"seq":811,"msg":{"market_ticker":"KXNEXTTEAMNBA-26LJAM-GSW","market_id":"abbbad28-f309-4dd5-af38-2ad7ebf2acc3","price_dollars":"0.0100","delta_fp":"-1.00","side":"yes","ts":"2026-07-01T02:33:06.670556Z","ts_ms":1782873186670}}

{"type":"orderbook_delta","sid":1,"seq":812,"msg":{"market_ticker":"KXNEXTTEAMNBA-26LJAM-GSW","market_id":"abbbad28-f309-4dd5-af38-2ad7ebf2acc3","price_dollars":"0.0100","delta_fp":"-1.00","side":"yes","ts":"2026-07-01T02:33:06.670556Z","ts_ms":1782873186670}}

{"type":"orderbook_delta","sid":1,"seq":813,"msg":{"market_ticker":"KXNEXTTEAMNBA-26LJAM-GSW","market_id":"abbbad28-f309-4dd5-af38-2ad7ebf2acc3","price_dollars":"0.0100","delta_fp":"-1.00","side":"yes","ts":"2026-07-01T02:33:06.670556Z","ts_ms":1782873186670}}

{"type":"orderbook_delta","sid":1,"seq":814,"msg":{"market_ticker":"KXNEXTTEAMNBA-26LJAM-GSW","market_id":"abbbad28-f309-4dd5-af38-2ad7ebf2acc3","price_dollars":"0.0100","delta_fp":"-1.00","side":"yes","ts":"2026-07-01T02:33:06.670556Z","ts_ms":1782873186670}}

{"type":"orderbook_delta","sid":1,"seq":815,"msg":{"market_ticker":"KXNEXTTEAMNBA-26LJAM-GSW","market_id":"abbbad28-f309-4dd5-af38-2ad7ebf2acc3","price_dollars":"0.0100","delta_fp":"-1.00","side":"yes","ts":"2026-07-01T02:33:06.670556Z","ts_ms":1782873186670}}

{"type":"orderbook_delta","sid":1,"seq":816,"msg":{"market_ticker":"KXNEXTTEAMNBA-26LJAM-GSW","market_id":"abbbad28-f309-4dd5-af38-2ad7ebf2acc3","price_dollars":"0.0100","delta_fp":"-1.00","side":"yes","ts":"2026-07-01T02:33:06.670556Z","ts_ms":1782873186670}}

{"type":"orderbook_delta","sid":1,"seq":817,"msg":{"market_ticker":"KXNEXTTEAMNBA-26LJAM-GSW","market_id":"abbbad28-f309-4dd5-af38-2ad7ebf2acc3","price_dollars":"0.0100","delta_fp":"-1.00","side":"yes","ts":"2026-07-01T02:33:06.670556Z","ts_ms":1782873186670}}

{"type":"orderbook_delta","sid":1,"seq":818,"msg":{"market_ticker":"KXNEXTTEAMNBA-26LJAM-GSW","market_id":"abbbad28-f309-4dd5-af38-2ad7ebf2acc3","price_dollars":"0.0100","delta_fp":"-1.00","side":"yes","ts":"2026-07-01T02:33:06.670556Z","ts_ms":1782873186670}}

{"type":"orderbook_delta","sid":1,"seq":819,"msg":{"market_ticker":"KXNEXTTEAMNBA-26LJAM-GSW","market_id":"abbbad28-f309-4dd5-af38-2ad7ebf2acc3","price_dollars":"0.0100","delta_fp":"-1.00","side":"yes","ts":"2026-07-01T02:33:06.670556Z","ts_ms":1782873186670}}

{"type":"orderbook_delta","sid":1,"seq":820,"msg":{"market_ticker":"KXNEXTTEAMNBA-26LJAM-GSW","market_id":"abbbad28-f309-4dd5-af38-2ad7ebf2acc3","price_dollars":"0.0100","delta_fp":"-1.00","side":"yes","ts":"2026-07-01T02:33:06.670556Z","ts_ms":1782873186670}}

{"type":"orderbook_delta","sid":1,"seq":821,"msg":{"market_ticker":"KXNEXTTEAMNBA-26LJAM-GSW","market_id":"abbbad28-f309-4dd5-af38-2ad7ebf2acc3","price_dollars":"0.0100","delta_fp":"-1.00","side":"yes","ts":"2026-07-01T02:33:06.670556Z","ts_ms":1782873186670}}

{"type":"orderbook_delta","sid":1,"seq":822,"msg":{"market_ticker":"KXNEXTTEAMNBA-26LJAM-GSW","market_id":"abbbad28-f309-4dd5-af38-2ad7ebf2acc3","price_dollars":"0.0100","delta_fp":"-1.00","side":"yes","ts":"2026-07-01T02:33:06.670556Z","ts_ms":1782873186670}}

{"type":"orderbook_delta","sid":1,"seq":823,"msg":{"market_ticker":"KXNEXTTEAMNBA-26LJAM-GSW","market_id":"abbbad28-f309-4dd5-af38-2ad7ebf2acc3","price_dollars":"0.0100","delta_fp":"-1.00","side":"yes","ts":"2026-07-01T02:33:06.670556Z","ts_ms":1782873186670}}

{"type":"orderbook_delta","sid":1,"seq":824,"msg":{"market_ticker":"KXNEXTTEAMNBA-26LJAM-GSW","market_id":"abbbad28-f309-4dd5-af38-2ad7ebf2acc3","price_dollars":"0.0100","delta_fp":"-1.00","side":"yes","ts":"2026-07-01T02:33:06.670556Z","ts_ms":1782873186670}}

{"type":"orderbook_delta","sid":1,"seq":825,"msg":{"market_ticker":"KXNEXTTEAMNBA-26LJAM-GSW","market_id":"abbbad28-f309-4dd5-af38-2ad7ebf2acc3","price_dollars":"0.0100","delta_fp":"-1.00","side":"yes","ts":"2026-07-01T02:33:06.670556Z","ts_ms":1782873186670}}

{"type":"orderbook_delta","sid":1,"seq":826,"msg":{"market_ticker":"KXNEXTTEAMNBA-26LJAM-GSW","market_id":"abbbad28-f309-4dd5-af38-2ad7ebf2acc3","price_dollars":"0.0100","delta_fp":"-1.00","side":"yes","ts":"2026-07-01T02:33:06.670556Z","ts_ms":1782873186670}}

{"type":"orderbook_delta","sid":1,"seq":827,"msg":{"market_ticker":"KXNEXTTEAMNBA-26LJAM-GSW","market_id":"abbbad28-f309-4dd5-af38-2ad7ebf2acc3","price_dollars":"0.0100","delta_fp":"-1.00","side":"yes","ts":"2026-07-01T02:33:06.670556Z","ts_ms":1782873186670}}

{"type":"orderbook_delta","sid":1,"seq":828,"msg":{"market_ticker":"KXNEXTTEAMNBA-26LJAM-GSW","market_id":"abbbad28-f309-4dd5-af38-2ad7ebf2acc3","price_dollars":"0.0100","delta_fp":"-1.00","side":"yes","ts":"2026-07-01T02:33:06.670556Z","ts_ms":1782873186670}}

{"type":"orderbook_delta","sid":1,"seq":829,"msg":{"market_ticker":"KXNEXTTEAMNBA-26LJAM-GSW","market_id":"abbbad28-f309-4dd5-af38-2ad7ebf2acc3","price_dollars":"0.0100","delta_fp":"-1.00","side":"yes","ts":"2026-07-01T02:33:06.670556Z","ts_ms":1782873186670}}

{"type":"orderbook_delta","sid":1,"seq":830,"msg":{"market_ticker":"KXNEXTTEAMNBA-26LJAM-GSW","market_id":"abbbad28-f309-4dd5-af38-2ad7ebf2acc3","price_dollars":"0.0100","delta_fp":"-1.00","side":"yes","ts":"2026-07-01T02:33:06.670556Z","ts_ms":1782873186670}}

{"type":"orderbook_delta","sid":1,"seq":831,"msg":{"market_ticker":"KXNEXTTEAMNBA-26LJAM-GSW","market_id":"abbbad28-f309-4dd5-af38-2ad7ebf2acc3","price_dollars":"0.0100","delta_fp":"-1.00","side":"yes","ts":"2026-07-01T02:33:06.670556Z","ts_ms":1782873186670}}

{"type":"orderbook_delta","sid":1,"seq":832,"msg":{"market_ticker":"KXNEXTTEAMNBA-26LJAM-GSW","market_id":"abbbad28-f309-4dd5-af38-2ad7ebf2acc3","price_dollars":"0.0100","delta_fp":"-1.00","side":"yes","ts":"2026-07-01T02:33:06.670556Z","ts_ms":1782873186670}}

{"type":"orderbook_delta","sid":1,"seq":833,"msg":{"market_ticker":"KXNEXTTEAMNBA-26LJAM-GSW","market_id":"abbbad28-f309-4dd5-af38-2ad7ebf2acc3","price_dollars":"0.4700","delta_fp":"-709.21","side":"yes","ts":"2026-07-01T02:33:06.670556Z","ts_ms":1782873186670}}

{"type":"orderbook_delta","sid":1,"seq":834,"msg":{"market_ticker":"KXNEXTTEAMNBA-26LJAM-GSW","market_id":"abbbad28-f309-4dd5-af38-2ad7ebf2acc3","price_dollars":"0.4600","delta_fp":"-724.63","side":"yes","ts":"2026-07-01T02:33:06.670556Z","ts_ms":1782873186670}}

{"type":"orderbook_delta","sid":1,"seq":835,"msg":{"market_ticker":"KXNEXTTEAMNBA-26LJAM-GSW","market_id":"abbbad28-f309-4dd5-af38-2ad7ebf2acc3","price_dollars":"0.4500","delta_fp":"-740.74","side":"yes","ts":"2026-07-01T02:33:06.670556Z","ts_ms":1782873186670}}

{"type":"orderbook_delta","sid":1,"seq":836,"msg":{"market_ticker":"KXNEXTTEAMNBA-26LJAM-GSW","market_id":"abbbad28-f309-4dd5-af38-2ad7ebf2acc3","price_dollars":"0.0100","delta_fp":"-1.00","side":"yes","ts":"2026-07-01T02:33:06.670556Z","ts_ms":1782873186670}}

{"type":"orderbook_delta","sid":1,"seq":837,"msg":{"market_ticker":"KXNEXTTEAMNBA-26LJAM-GSW","market_id":"abbbad28-f309-4dd5-af38-2ad7ebf2acc3","price_dollars":"0.0100","delta_fp":"-1.00","side":"yes","ts":"2026-07-01T02:33:06.670556Z","ts_ms":1782873186670}}

{"type":"orderbook_delta","sid":1,"seq":838,"msg":{"market_ticker":"KXNEXTTEAMNBA-26LJAM-GSW","market_id":"abbbad28-f309-4dd5-af38-2ad7ebf2acc3","price_dollars":"0.0100","delta_fp":"-1.00","side":"yes","ts":"2026-07-01T02:33:06.670556Z","ts_ms":1782873186670}}

{"type":"orderbook_delta","sid":1,"seq":839,"msg":{"market_ticker":"KXNEXTTEAMNBA-26LJAM-GSW","market_id":"abbbad28-f309-4dd5-af38-2ad7ebf2acc3","price_dollars":"0.0100","delta_fp":"-1.00","side":"yes","ts":"2026-07-01T02:33:06.670556Z","ts_ms":1782873186670}}

{"type":"orderbook_delta","sid":1,"seq":840,"msg":{"market_ticker":"KXNEXTTEAMNBA-26LJAM-GSW","market_id":"abbbad28-f309-4dd5-af38-2ad7ebf2acc3","price_dollars":"0.0100","delta_fp":"-1.00","side":"yes","ts":"2026-07-01T02:33:06.670556Z","ts_ms":1782873186670}}

{"type":"orderbook_delta","sid":1,"seq":841,"msg":{"market_ticker":"KXNEXTTEAMNBA-26LJAM-GSW","market_id":"abbbad28-f309-4dd5-af38-2ad7ebf2acc3","price_dollars":"0.0100","delta_fp":"-1.00","side":"yes","ts":"2026-07-01T02:33:06.670556Z","ts_ms":1782873186670}}

{"type":"orderbook_delta","sid":1,"seq":842,"msg":{"market_ticker":"KXNEXTTEAMNBA-26LJAM-GSW","market_id":"abbbad28-f309-4dd5-af38-2ad7ebf2acc3","price_dollars":"0.0100","delta_fp":"-1.00","side":"yes","ts":"2026-07-01T02:33:06.670556Z","ts_ms":1782873186670}}

{"type":"orderbook_delta","sid":1,"seq":843,"msg":{"market_ticker":"KXNEXTTEAMNBA-26LJAM-GSW","market_id":"abbbad28-f309-4dd5-af38-2ad7ebf2acc3","price_dollars":"0.0100","delta_fp":"-1.00","side":"yes","ts":"2026-07-01T02:33:06.670556Z","ts_ms":1782873186670}}

{"type":"orderbook_delta","sid":1,"seq":844,"msg":{"market_ticker":"KXNEXTTEAMNBA-26LJAM-GSW","market_id":"abbbad28-f309-4dd5-af38-2ad7ebf2acc3","price_dollars":"0.0100","delta_fp":"-1.00","side":"yes","ts":"2026-07-01T02:33:06.670556Z","ts_ms":1782873186670}}

{"type":"orderbook_delta","sid":1,"seq":845,"msg":{"market_ticker":"KXNEXTTEAMNBA-26LJAM-GSW","market_id":"abbbad28-f309-4dd5-af38-2ad7ebf2acc3","price_dollars":"0.0100","delta_fp":"-1.00","side":"yes","ts":"2026-07-01T02:33:06.670556Z","ts_ms":1782873186670}}

{"type":"orderbook_delta","sid":1,"seq":846,"msg":{"market_ticker":"KXNEXTTEAMNBA-26LJAM-GSW","market_id":"abbbad28-f309-4dd5-af38-2ad7ebf2acc3","price_dollars":"0.0100","delta_fp":"-1.00","side":"yes","ts":"2026-07-01T02:33:06.670556Z","ts_ms":1782873186670}}

{"type":"orderbook_delta","sid":1,"seq":847,"msg":{"market_ticker":"KXNEXTTEAMNBA-26LJAM-GSW","market_id":"abbbad28-f309-4dd5-af38-2ad7ebf2acc3","price_dollars":"0.0100","delta_fp":"-1.00","side":"yes","ts":"2026-07-01T02:33:06.670556Z","ts_ms":1782873186670}}

{"type":"orderbook_delta","sid":1,"seq":848,"msg":{"market_ticker":"KXNEXTTEAMNBA-26LJAM-GSW","market_id":"abbbad28-f309-4dd5-af38-2ad7ebf2acc3","price_dollars":"0.0100","delta_fp":"-1.00","side":"yes","ts":"2026-07-01T02:33:06.670556Z","ts_ms":1782873186670}}

{"type":"orderbook_delta","sid":1,"seq":849,"msg":{"market_ticker":"KXNEXTTEAMNBA-26LJAM-GSW","market_id":"abbbad28-f309-4dd5-af38-2ad7ebf2acc3","price_dollars":"0.0100","delta_fp":"-1.00","side":"yes","ts":"2026-07-01T02:33:06.670556Z","ts_ms":1782873186670}}

{"type":"orderbook_delta","sid":1,"seq":850,"msg":{"market_ticker":"KXNEXTTEAMNBA-26LJAM-GSW","market_id":"abbbad28-f309-4dd5-af38-2ad7ebf2acc3","price_dollars":"0.0100","delta_fp":"-1.00","side":"yes","ts":"2026-07-01T02:33:06.670556Z","ts_ms":1782873186670}}

{"type":"orderbook_delta","sid":1,"seq":851,"msg":{"market_ticker":"KXNEXTTEAMNBA-26LJAM-GSW","market_id":"abbbad28-f309-4dd5-af38-2ad7ebf2acc3","price_dollars":"0.0100","delta_fp":"-1.00","side":"yes","ts":"2026-07-01T02:33:06.670556Z","ts_ms":1782873186670}}

{"type":"orderbook_delta","sid":1,"seq":852,"msg":{"market_ticker":"KXNEXTTEAMNBA-26LJAM-GSW","market_id":"abbbad28-f309-4dd5-af38-2ad7ebf2acc3","price_dollars":"0.0100","delta_fp":"-1.00","side":"yes","ts":"2026-07-01T02:33:06.670556Z","ts_ms":1782873186670}}

{"type":"orderbook_delta","sid":1,"seq":853,"msg":{"market_ticker":"KXNEXTTEAMNBA-26LJAM-GSW","market_id":"abbbad28-f309-4dd5-af38-2ad7ebf2acc3","price_dollars":"0.0100","delta_fp":"-1.00","side":"yes","ts":"2026-07-01T02:33:06.670556Z","ts_ms":1782873186670}}

{"type":"orderbook_delta","sid":1,"seq":854,"msg":{"market_ticker":"KXNEXTTEAMNBA-26LJAM-GSW","market_id":"abbbad28-f309-4dd5-af38-2ad7ebf2acc3","price_dollars":"0.0100","delta_fp":"-1.00","side":"yes","ts":"2026-07-01T02:33:06.670556Z","ts_ms":1782873186670}}

{"type":"orderbook_delta","sid":1,"seq":855,"msg":{"market_ticker":"KXNEXTTEAMNBA-26LJAM-GSW","market_id":"abbbad28-f309-4dd5-af38-2ad7ebf2acc3","price_dollars":"0.0100","delta_fp":"-1.00","side":"yes","ts":"2026-07-01T02:33:06.670556Z","ts_ms":1782873186670}}

{"type":"orderbook_delta","sid":1,"seq":856,"msg":{"market_ticker":"KXNEXTTEAMNBA-26LJAM-GSW","market_id":"abbbad28-f309-4dd5-af38-2ad7ebf2acc3","price_dollars":"0.0100","delta_fp":"-1.00","side":"yes","ts":"2026-07-01T02:33:06.670556Z","ts_ms":1782873186670}}

{"type":"orderbook_delta","sid":1,"seq":857,"msg":{"market_ticker":"KXNEXTTEAMNBA-26LJAM-GSW","market_id":"abbbad28-f309-4dd5-af38-2ad7ebf2acc3","price_dollars":"0.0100","delta_fp":"-1.00","side":"yes","ts":"2026-07-01T02:33:06.670556Z","ts_ms":1782873186670}}

{"type":"orderbook_delta","sid":1,"seq":858,"msg":{"market_ticker":"KXNEXTTEAMNBA-26LJAM-GSW","market_id":"abbbad28-f309-4dd5-af38-2ad7ebf2acc3","price_dollars":"0.0100","delta_fp":"-1.00","side":"yes","ts":"2026-07-01T02:33:06.670556Z","ts_ms":1782873186670}}

{"type":"orderbook_delta","sid":1,"seq":859,"msg":{"market_ticker":"KXNEXTTEAMNBA-26LJAM-GSW","market_id":"abbbad28-f309-4dd5-af38-2ad7ebf2acc3","price_dollars":"0.0100","delta_fp":"-1.00","side":"yes","ts":"2026-07-01T02:33:06.670556Z","ts_ms":1782873186670}}

{"type":"orderbook_delta","sid":1,"seq":860,"msg":{"market_ticker":"KXNEXTTEAMNBA-26LJAM-GSW","market_id":"abbbad28-f309-4dd5-af38-2ad7ebf2acc3","price_dollars":"0.0100","delta_fp":"-1.00","side":"yes","ts":"2026-07-01T02:33:06.670556Z","ts_ms":1782873186670}}

{"type":"orderbook_delta","sid":1,"seq":861,"msg":{"market_ticker":"KXNEXTTEAMNBA-26LJAM-GSW","market_id":"abbbad28-f309-4dd5-af38-2ad7ebf2acc3","price_dollars":"0.0100","delta_fp":"-1.00","side":"yes","ts":"2026-07-01T02:33:06.670556Z","ts_ms":1782873186670}}

{"type":"orderbook_delta","sid":1,"seq":862,"msg":{"market_ticker":"KXNEXTTEAMNBA-26LJAM-GSW","market_id":"abbbad28-f309-4dd5-af38-2ad7ebf2acc3","price_dollars":"0.0100","delta_fp":"-1.00","side":"yes","ts":"2026-07-01T02:33:06.670556Z","ts_ms":1782873186670}}

{"type":"orderbook_delta","sid":1,"seq":863,"msg":{"market_ticker":"KXNEXTTEAMNBA-26LJAM-GSW","market_id":"abbbad28-f309-4dd5-af38-2ad7ebf2acc3","price_dollars":"0.0100","delta_fp":"-1.00","side":"yes","ts":"2026-07-01T02:33:06.670556Z","ts_ms":1782873186670}}

{"type":"orderbook_delta","sid":1,"seq":864,"msg":{"market_ticker":"KXNEXTTEAMNBA-26LJAM-GSW","market_id":"abbbad28-f309-4dd5-af38-2ad7ebf2acc3","price_dollars":"0.0100","delta_fp":"-1.00","side":"yes","ts":"2026-07-01T02:33:06.670556Z","ts_ms":1782873186670}}

{"type":"orderbook_delta","sid":1,"seq":865,"msg":{"market_ticker":"KXNEXTTEAMNBA-26LJAM-GSW","market_id":"abbbad28-f309-4dd5-af38-2ad7ebf2acc3","price_dollars":"0.0100","delta_fp":"-1.00","side":"yes","ts":"2026-07-01T02:33:06.670556Z","ts_ms":1782873186670}}

{"type":"orderbook_delta","sid":1,"seq":866,"msg":{"market_ticker":"KXNEXTTEAMNBA-26LJAM-GSW","market_id":"abbbad28-f309-4dd5-af38-2ad7ebf2acc3","price_dollars":"0.0100","delta_fp":"-1.00","side":"yes","ts":"2026-07-01T02:33:06.670556Z","ts_ms":1782873186670}}

{"type":"orderbook_delta","sid":1,"seq":867,"msg":{"market_ticker":"KXNEXTTEAMNBA-26LJAM-GSW","market_id":"abbbad28-f309-4dd5-af38-2ad7ebf2acc3","price_dollars":"0.0100","delta_fp":"-1.00","side":"yes","ts":"2026-07-01T02:33:06.670556Z","ts_ms":1782873186670}}

{"type":"orderbook_delta","sid":1,"seq":868,"msg":{"market_ticker":"KXNEXTTEAMNBA-26LJAM-GSW","market_id":"abbbad28-f309-4dd5-af38-2ad7ebf2acc3","price_dollars":"0.0100","delta_fp":"-1.00","side":"yes","ts":"2026-07-01T02:33:06.670556Z","ts_ms":1782873186670}}

{"type":"orderbook_delta","sid":1,"seq":869,"msg":{"market_ticker":"KXNEXTTEAMNBA-26LJAM-GSW","market_id":"abbbad28-f309-4dd5-af38-2ad7ebf2acc3","price_dollars":"0.0100","delta_fp":"-1.00","side":"yes","ts":"2026-07-01T02:33:06.670556Z","ts_ms":1782873186670}}

{"type":"orderbook_delta","sid":1,"seq":870,"msg":{"market_ticker":"KXNEXTTEAMNBA-26LJAM-GSW","market_id":"abbbad28-f309-4dd5-af38-2ad7ebf2acc3","price_dollars":"0.0100","delta_fp":"-1.00","side":"yes","ts":"2026-07-01T02:33:06.670556Z","ts_ms":1782873186670}}

{"type":"orderbook_delta","sid":1,"seq":871,"msg":{"market_ticker":"KXNEXTTEAMNBA-26LJAM-GSW","market_id":"abbbad28-f309-4dd5-af38-2ad7ebf2acc3","price_dollars":"0.0100","delta_fp":"-1.00","side":"yes","ts":"2026-07-01T02:33:06.670556Z","ts_ms":1782873186670}}

{"type":"orderbook_delta","sid":1,"seq":872,"msg":{"market_ticker":"KXNEXTTEAMNBA-26LJAM-GSW","market_id":"abbbad28-f309-4dd5-af38-2ad7ebf2acc3","price_dollars":"0.0100","delta_fp":"-1.00","side":"yes","ts":"2026-07-01T02:33:06.670556Z","ts_ms":1782873186670}}

{"type":"orderbook_delta","sid":1,"seq":873,"msg":{"market_ticker":"KXNEXTTEAMNBA-26LJAM-GSW","market_id":"abbbad28-f309-4dd5-af38-2ad7ebf2acc3","price_dollars":"0.0100","delta_fp":"-1.00","side":"yes","ts":"2026-07-01T02:33:06.670556Z","ts_ms":1782873186670}}

{"type":"orderbook_delta","sid":1,"seq":874,"msg":{"market_ticker":"KXNEXTTEAMNBA-26LJAM-GSW","market_id":"abbbad28-f309-4dd5-af38-2ad7ebf2acc3","price_dollars":"0.0100","delta_fp":"-1.00","side":"yes","ts":"2026-07-01T02:33:06.670556Z","ts_ms":1782873186670}}

{"type":"orderbook_delta","sid":1,"seq":875,"msg":{"market_ticker":"KXNEXTTEAMNBA-26LJAM-GSW","market_id":"abbbad28-f309-4dd5-af38-2ad7ebf2acc3","price_dollars":"0.0100","delta_fp":"-1.00","side":"yes","ts":"2026-07-01T02:33:06.670556Z","ts_ms":1782873186670}}

{"type":"orderbook_delta","sid":1,"seq":876,"msg":{"market_ticker":"KXNEXTTEAMNBA-26LJAM-GSW","market_id":"abbbad28-f309-4dd5-af38-2ad7ebf2acc3","price_dollars":"0.0100","delta_fp":"-1.00","side":"yes","ts":"2026-07-01T02:33:06.670556Z","ts_ms":1782873186670}}

{"type":"orderbook_delta","sid":1,"seq":877,"msg":{"market_ticker":"KXNEXTTEAMNBA-26LJAM-GSW","market_id":"abbbad28-f309-4dd5-af38-2ad7ebf2acc3","price_dollars":"0.0100","delta_fp":"-1.00","side":"yes","ts":"2026-07-01T02:33:06.670556Z","ts_ms":1782873186670}}

{"type":"orderbook_delta","sid":1,"seq":878,"msg":{"market_ticker":"KXNEXTTEAMNBA-26LJAM-GSW","market_id":"abbbad28-f309-4dd5-af38-2ad7ebf2acc3","price_dollars":"0.0100","delta_fp":"-1.00","side":"yes","ts":"2026-07-01T02:33:06.670556Z","ts_ms":1782873186670}}

{"type":"orderbook_delta","sid":1,"seq":879,"msg":{"market_ticker":"KXNEXTTEAMNBA-26LJAM-GSW","market_id":"abbbad28-f309-4dd5-af38-2ad7ebf2acc3","price_dollars":"0.0100","delta_fp":"-1.00","side":"yes","ts":"2026-07-01T02:33:06.670556Z","ts_ms":1782873186670}}

{"type":"orderbook_delta","sid":1,"seq":880,"msg":{"market_ticker":"KXNEXTTEAMNBA-26LJAM-GSW","market_id":"abbbad28-f309-4dd5-af38-2ad7ebf2acc3","price_dollars":"0.0100","delta_fp":"-1.00","side":"yes","ts":"2026-07-01T02:33:06.670556Z","ts_ms":1782873186670}}

{"type":"orderbook_delta","sid":1,"seq":881,"msg":{"market_ticker":"KXNEXTTEAMNBA-26LJAM-GSW","market_id":"abbbad28-f309-4dd5-af38-2ad7ebf2acc3","price_dollars":"0.0100","delta_fp":"-1.00","side":"yes","ts":"2026-07-01T02:33:06.670556Z","ts_ms":1782873186670}}

{"type":"orderbook_delta","sid":1,"seq":882,"msg":{"market_ticker":"KXNEXTTEAMNBA-26LJAM-GSW","market_id":"abbbad28-f309-4dd5-af38-2ad7ebf2acc3","price_dollars":"0.0100","delta_fp":"-1.00","side":"yes","ts":"2026-07-01T02:33:06.670556Z","ts_ms":1782873186670}}

{"type":"orderbook_delta","sid":1,"seq":883,"msg":{"market_ticker":"KXNEXTTEAMNBA-26LJAM-GSW","market_id":"abbbad28-f309-4dd5-af38-2ad7ebf2acc3","price_dollars":"0.0100","delta_fp":"-1.00","side":"yes","ts":"2026-07-01T02:33:06.670556Z","ts_ms":1782873186670}}

{"type":"orderbook_delta","sid":1,"seq":884,"msg":{"market_ticker":"KXNEXTTEAMNBA-26LJAM-GSW","market_id":"abbbad28-f309-4dd5-af38-2ad7ebf2acc3","price_dollars":"0.0100","delta_fp":"-1.00","side":"yes","ts":"2026-07-01T02:33:06.670556Z","ts_ms":1782873186670}}

{"type":"orderbook_delta","sid":1,"seq":885,"msg":{"market_ticker":"KXNEXTTEAMNBA-26LJAM-GSW","market_id":"abbbad28-f309-4dd5-af38-2ad7ebf2acc3","price_dollars":"0.0100","delta_fp":"-1.00","side":"yes","ts":"2026-07-01T02:33:06.670556Z","ts_ms":1782873186670}}

{"type":"orderbook_delta","sid":1,"seq":886,"msg":{"market_ticker":"KXNEXTTEAMNBA-26LJAM-GSW","market_id":"abbbad28-f309-4dd5-af38-2ad7ebf2acc3","price_dollars":"0.0100","delta_fp":"-1.00","side":"yes","ts":"2026-07-01T02:33:06.670556Z","ts_ms":1782873186670}}

{"type":"orderbook_delta","sid":1,"seq":887,"msg":{"market_ticker":"KXNEXTTEAMNBA-26LJAM-GSW","market_id":"abbbad28-f309-4dd5-af38-2ad7ebf2acc3","price_dollars":"0.0100","delta_fp":"-1.00","side":"yes","ts":"2026-07-01T02:33:06.670556Z","ts_ms":1782873186670}}

{"type":"orderbook_delta","sid":1,"seq":888,"msg":{"market_ticker":"KXNEXTTEAMNBA-26LJAM-GSW","market_id":"abbbad28-f309-4dd5-af38-2ad7ebf2acc3","price_dollars":"0.0100","delta_fp":"-1.00","side":"yes","ts":"2026-07-01T02:33:06.670556Z","ts_ms":1782873186670}}

{"type":"orderbook_delta","sid":1,"seq":889,"msg":{"market_ticker":"KXNEXTTEAMNBA-26LJAM-GSW","market_id":"abbbad28-f309-4dd5-af38-2ad7ebf2acc3","price_dollars":"0.0100","delta_fp":"-1.00","side":"yes","ts":"2026-07-01T02:33:06.670556Z","ts_ms":1782873186670}}

{"type":"orderbook_delta","sid":1,"seq":890,"msg":{"market_ticker":"KXNEXTTEAMNBA-26LJAM-GSW","market_id":"abbbad28-f309-4dd5-af38-2ad7ebf2acc3","price_dollars":"0.0100","delta_fp":"-1.00","side":"yes","ts":"2026-07-01T02:33:06.670556Z","ts_ms":1782873186670}}

{"type":"orderbook_delta","sid":1,"seq":891,"msg":{"market_ticker":"KXNEXTTEAMNBA-26LJAM-GSW","market_id":"abbbad28-f309-4dd5-af38-2ad7ebf2acc3","price_dollars":"0.0100","delta_fp":"-1.00","side":"yes","ts":"2026-07-01T02:33:06.670556Z","ts_ms":1782873186670}}

{"type":"orderbook_delta","sid":1,"seq":892,"msg":{"market_ticker":"KXNEXTTEAMNBA-26LJAM-GSW","market_id":"abbbad28-f309-4dd5-af38-2ad7ebf2acc3","price_dollars":"0.0100","delta_fp":"-1.00","side":"yes","ts":"2026-07-01T02:33:06.670556Z","ts_ms":1782873186670}}

{"type":"orderbook_delta","sid":1,"seq":893,"msg":{"market_ticker":"KXNEXTTEAMNBA-26LJAM-GSW","market_id":"abbbad28-f309-4dd5-af38-2ad7ebf2acc3","price_dollars":"0.0100","delta_fp":"-1.00","side":"yes","ts":"2026-07-01T02:33:06.670556Z","ts_ms":1782873186670}}

{"type":"orderbook_delta","sid":1,"seq":894,"msg":{"market_ticker":"KXNEXTTEAMNBA-26LJAM-GSW","market_id":"abbbad28-f309-4dd5-af38-2ad7ebf2acc3","price_dollars":"0.0100","delta_fp":"-1.00","side":"yes","ts":"2026-07-01T02:33:06.670556Z","ts_ms":1782873186670}}

{"type":"orderbook_delta","sid":1,"seq":895,"msg":{"market_ticker":"KXNEXTTEAMNBA-26LJAM-GSW","market_id":"abbbad28-f309-4dd5-af38-2ad7ebf2acc3","price_dollars":"0.0100","delta_fp":"-1.00","side":"yes","ts":"2026-07-01T02:33:06.670556Z","ts_ms":1782873186670}}

{"type":"orderbook_delta","sid":1,"seq":896,"msg":{"market_ticker":"KXNEXTTEAMNBA-26LJAM-GSW","market_id":"abbbad28-f309-4dd5-af38-2ad7ebf2acc3","price_dollars":"0.4700","delta_fp":"-709.21","side":"yes","ts":"2026-07-01T02:33:06.670556Z","ts_ms":1782873186670}}

{"type":"orderbook_delta","sid":1,"seq":897,"msg":{"market_ticker":"KXNEXTTEAMNBA-26LJAM-GSW","market_id":"abbbad28-f309-4dd5-af38-2ad7ebf2acc3","price_dollars":"0.4600","delta_fp":"-724.63","side":"yes","ts":"2026-07-01T02:33:06.670556Z","ts_ms":1782873186670}}

{"type":"orderbook_delta","sid":1,"seq":898,"msg":{"market_ticker":"KXNEXTTEAMNBA-26LJAM-GSW","market_id":"abbbad28-f309-4dd5-af38-2ad7ebf2acc3","price_dollars":"0.4500","delta_fp":"-740.74","side":"yes","ts":"2026-07-01T02:33:06.670556Z","ts_ms":1782873186670}}

{"type":"orderbook_delta","sid":1,"seq":899,"msg":{"market_ticker":"KXNEXTTEAMNBA-26LJAM-GSW","market_id":"abbbad28-f309-4dd5-af38-2ad7ebf2acc3","price_dollars":"0.0100","delta_fp":"-1.00","side":"yes","ts":"2026-07-01T02:33:06.670556Z","ts_ms":1782873186670}}

{"type":"orderbook_delta","sid":1,"seq":900,"msg":{"market_ticker":"KXNEXTTEAMNBA-26LJAM-GSW","market_id":"abbbad28-f309-4dd5-af38-2ad7ebf2acc3","price_dollars":"0.0100","delta_fp":"-1.00","side":"yes","ts":"2026-07-01T02:33:06.670556Z","ts_ms":1782873186670}}

{"type":"orderbook_delta","sid":1,"seq":901,"msg":{"market_ticker":"KXNEXTTEAMNBA-26LJAM-GSW","market_id":"abbbad28-f309-4dd5-af38-2ad7ebf2acc3","price_dollars":"0.0100","delta_fp":"-1.00","side":"yes","ts":"2026-07-01T02:33:06.670556Z","ts_ms":1782873186670}}

{"type":"orderbook_delta","sid":1,"seq":902,"msg":{"market_ticker":"KXNEXTTEAMNBA-26LJAM-GSW","market_id":"abbbad28-f309-4dd5-af38-2ad7ebf2acc3","price_dollars":"0.0100","delta_fp":"-1.00","side":"yes","ts":"2026-07-01T02:33:06.670556Z","ts_ms":1782873186670}}

{"type":"orderbook_delta","sid":1,"seq":903,"msg":{"market_ticker":"KXNEXTTEAMNBA-26LJAM-GSW","market_id":"abbbad28-f309-4dd5-af38-2ad7ebf2acc3","price_dollars":"0.0100","delta_fp":"-1.00","side":"yes","ts":"2026-07-01T02:33:06.670556Z","ts_ms":1782873186670}}

{"type":"orderbook_delta","sid":1,"seq":904,"msg":{"market_ticker":"KXNEXTTEAMNBA-26LJAM-GSW","market_id":"abbbad28-f309-4dd5-af38-2ad7ebf2acc3","price_dollars":"0.0100","delta_fp":"-1.00","side":"yes","ts":"2026-07-01T02:33:06.670556Z","ts_ms":1782873186670}}

{"type":"orderbook_delta","sid":1,"seq":905,"msg":{"market_ticker":"KXNEXTTEAMNBA-26LJAM-GSW","market_id":"abbbad28-f309-4dd5-af38-2ad7ebf2acc3","price_dollars":"0.0100","delta_fp":"-1.00","side":"yes","ts":"2026-07-01T02:33:06.670556Z","ts_ms":1782873186670}}

{"type":"orderbook_delta","sid":1,"seq":906,"msg":{"market_ticker":"KXNEXTTEAMNBA-26LJAM-GSW","market_id":"abbbad28-f309-4dd5-af38-2ad7ebf2acc3","price_dollars":"0.0100","delta_fp":"-1.00","side":"yes","ts":"2026-07-01T02:33:06.670556Z","ts_ms":1782873186670}}

{"type":"orderbook_delta","sid":1,"seq":907,"msg":{"market_ticker":"KXNEXTTEAMNBA-26LJAM-GSW","market_id":"abbbad28-f309-4dd5-af38-2ad7ebf2acc3","price_dollars":"0.0100","delta_fp":"-1.00","side":"yes","ts":"2026-07-01T02:33:06.670556Z","ts_ms":1782873186670}}

{"type":"orderbook_delta","sid":1,"seq":908,"msg":{"market_ticker":"KXNEXTTEAMNBA-26LJAM-GSW","market_id":"abbbad28-f309-4dd5-af38-2ad7ebf2acc3","price_dollars":"0.0100","delta_fp":"-1.00","side":"yes","ts":"2026-07-01T02:33:06.670556Z","ts_ms":1782873186670}}

{"type":"orderbook_delta","sid":1,"seq":909,"msg":{"market_ticker":"KXNEXTTEAMNBA-26LJAM-GSW","market_id":"abbbad28-f309-4dd5-af38-2ad7ebf2acc3","price_dollars":"0.0100","delta_fp":"-1.00","side":"yes","ts":"2026-07-01T02:33:06.670556Z","ts_ms":1782873186670}}

{"type":"orderbook_delta","sid":1,"seq":910,"msg":{"market_ticker":"KXNEXTTEAMNBA-26LJAM-GSW","market_id":"abbbad28-f309-4dd5-af38-2ad7ebf2acc3","price_dollars":"0.0100","delta_fp":"-1.00","side":"yes","ts":"2026-07-01T02:33:06.670556Z","ts_ms":1782873186670}}

{"type":"orderbook_delta","sid":1,"seq":911,"msg":{"market_ticker":"KXNEXTTEAMNBA-26LJAM-GSW","market_id":"abbbad28-f309-4dd5-af38-2ad7ebf2acc3","price_dollars":"0.0100","delta_fp":"-1.00","side":"yes","ts":"2026-07-01T02:33:06.670556Z","ts_ms":1782873186670}}

{"type":"orderbook_delta","sid":1,"seq":912,"msg":{"market_ticker":"KXNEXTTEAMNBA-26LJAM-GSW","market_id":"abbbad28-f309-4dd5-af38-2ad7ebf2acc3","price_dollars":"0.0100","delta_fp":"-1.00","side":"yes","ts":"2026-07-01T02:33:06.670556Z","ts_ms":1782873186670}}

{"type":"orderbook_delta","sid":1,"seq":913,"msg":{"market_ticker":"KXNEXTTEAMNBA-26LJAM-GSW","market_id":"abbbad28-f309-4dd5-af38-2ad7ebf2acc3","price_dollars":"0.0100","delta_fp":"-1.00","side":"yes","ts":"2026-07-01T02:33:06.670556Z","ts_ms":1782873186670}}

{"type":"orderbook_delta","sid":1,"seq":914,"msg":{"market_ticker":"KXNEXTTEAMNBA-26LJAM-GSW","market_id":"abbbad28-f309-4dd5-af38-2ad7ebf2acc3","price_dollars":"0.0100","delta_fp":"-1.00","side":"yes","ts":"2026-07-01T02:33:06.670556Z","ts_ms":1782873186670}}

{"type":"orderbook_delta","sid":1,"seq":915,"msg":{"market_ticker":"KXNEXTTEAMNBA-26LJAM-GSW","market_id":"abbbad28-f309-4dd5-af38-2ad7ebf2acc3","price_dollars":"0.0100","delta_fp":"-1.00","side":"yes","ts":"2026-07-01T02:33:06.670556Z","ts_ms":1782873186670}}

{"type":"orderbook_delta","sid":1,"seq":916,"msg":{"market_ticker":"KXNEXTTEAMNBA-26LJAM-GSW","market_id":"abbbad28-f309-4dd5-af38-2ad7ebf2acc3","price_dollars":"0.0100","delta_fp":"-1.00","side":"yes","ts":"2026-07-01T02:33:06.670556Z","ts_ms":1782873186670}}

{"type":"orderbook_delta","sid":1,"seq":917,"msg":{"market_ticker":"KXNEXTTEAMNBA-26LJAM-GSW","market_id":"abbbad28-f309-4dd5-af38-2ad7ebf2acc3","price_dollars":"0.0100","delta_fp":"-1.00","side":"yes","ts":"2026-07-01T02:33:06.670556Z","ts_ms":1782873186670}}

{"type":"orderbook_delta","sid":1,"seq":918,"msg":{"market_ticker":"KXNEXTTEAMNBA-26LJAM-GSW","market_id":"abbbad28-f309-4dd5-af38-2ad7ebf2acc3","price_dollars":"0.0100","delta_fp":"-1.00","side":"yes","ts":"2026-07-01T02:33:06.670556Z","ts_ms":1782873186670}}

{"type":"orderbook_delta","sid":1,"seq":919,"msg":{"market_ticker":"KXNEXTTEAMNBA-26LJAM-GSW","market_id":"abbbad28-f309-4dd5-af38-2ad7ebf2acc3","price_dollars":"0.0100","delta_fp":"-1.00","side":"yes","ts":"2026-07-01T02:33:06.670556Z","ts_ms":1782873186670}}

{"type":"orderbook_delta","sid":1,"seq":920,"msg":{"market_ticker":"KXNEXTTEAMNBA-26LJAM-GSW","market_id":"abbbad28-f309-4dd5-af38-2ad7ebf2acc3","price_dollars":"0.0100","delta_fp":"-1.00","side":"yes","ts":"2026-07-01T02:33:06.670556Z","ts_ms":1782873186670}}

{"type":"orderbook_delta","sid":1,"seq":921,"msg":{"market_ticker":"KXNEXTTEAMNBA-26LJAM-GSW","market_id":"abbbad28-f309-4dd5-af38-2ad7ebf2acc3","price_dollars":"0.0100","delta_fp":"-1.00","side":"yes","ts":"2026-07-01T02:33:06.670556Z","ts_ms":1782873186670}}

{"type":"orderbook_delta","sid":1,"seq":922,"msg":{"market_ticker":"KXNEXTTEAMNBA-26LJAM-GSW","market_id":"abbbad28-f309-4dd5-af38-2ad7ebf2acc3","price_dollars":"0.0100","delta_fp":"-1.00","side":"yes","ts":"2026-07-01T02:33:06.670556Z","ts_ms":1782873186670}}

{"type":"orderbook_delta","sid":1,"seq":923,"msg":{"market_ticker":"KXNEXTTEAMNBA-26LJAM-GSW","market_id":"abbbad28-f309-4dd5-af38-2ad7ebf2acc3","price_dollars":"0.0100","delta_fp":"-1.00","side":"yes","ts":"2026-07-01T02:33:06.670556Z","ts_ms":1782873186670}}

{"type":"orderbook_delta","sid":1,"seq":924,"msg":{"market_ticker":"KXNEXTTEAMNBA-26LJAM-GSW","market_id":"abbbad28-f309-4dd5-af38-2ad7ebf2acc3","price_dollars":"0.0100","delta_fp":"-1.00","side":"yes","ts":"2026-07-01T02:33:06.670556Z","ts_ms":1782873186670}}

{"type":"orderbook_delta","sid":1,"seq":925,"msg":{"market_ticker":"KXNEXTTEAMNBA-26LJAM-GSW","market_id":"abbbad28-f309-4dd5-af38-2ad7ebf2acc3","price_dollars":"0.0100","delta_fp":"-1.00","side":"yes","ts":"2026-07-01T02:33:06.670556Z","ts_ms":1782873186670}}

{"type":"orderbook_delta","sid":1,"seq":926,"msg":{"market_ticker":"KXNEXTTEAMNBA-26LJAM-GSW","market_id":"abbbad28-f309-4dd5-af38-2ad7ebf2acc3","price_dollars":"0.0100","delta_fp":"-1.00","side":"yes","ts":"2026-07-01T02:33:06.670556Z","ts_ms":1782873186670}}

{"type":"orderbook_delta","sid":1,"seq":927,"msg":{"market_ticker":"KXNEXTTEAMNBA-26LJAM-GSW","market_id":"abbbad28-f309-4dd5-af38-2ad7ebf2acc3","price_dollars":"0.0100","delta_fp":"-1.00","side":"yes","ts":"2026-07-01T02:33:06.670556Z","ts_ms":1782873186670}}

{"type":"orderbook_delta","sid":1,"seq":928,"msg":{"market_ticker":"KXNEXTTEAMNBA-26LJAM-GSW","market_id":"abbbad28-f309-4dd5-af38-2ad7ebf2acc3","price_dollars":"0.0100","delta_fp":"-1.00","side":"yes","ts":"2026-07-01T02:33:06.670556Z","ts_ms":1782873186670}}

{"type":"orderbook_delta","sid":1,"seq":929,"msg":{"market_ticker":"KXNEXTTEAMNBA-26LJAM-GSW","market_id":"abbbad28-f309-4dd5-af38-2ad7ebf2acc3","price_dollars":"0.0100","delta_fp":"-1.00","side":"yes","ts":"2026-07-01T02:33:06.670556Z","ts_ms":1782873186670}}

{"type":"orderbook_delta","sid":1,"seq":930,"msg":{"market_ticker":"KXNEXTTEAMNBA-26LJAM-GSW","market_id":"abbbad28-f309-4dd5-af38-2ad7ebf2acc3","price_dollars":"0.0100","delta_fp":"-1.00","side":"yes","ts":"2026-07-01T02:33:06.670556Z","ts_ms":1782873186670}}

{"type":"orderbook_delta","sid":1,"seq":931,"msg":{"market_ticker":"KXNEXTTEAMNBA-26LJAM-GSW","market_id":"abbbad28-f309-4dd5-af38-2ad7ebf2acc3","price_dollars":"0.0100","delta_fp":"-1.00","side":"yes","ts":"2026-07-01T02:33:06.670556Z","ts_ms":1782873186670}}

{"type":"orderbook_delta","sid":1,"seq":932,"msg":{"market_ticker":"KXNEXTTEAMNBA-26LJAM-GSW","market_id":"abbbad28-f309-4dd5-af38-2ad7ebf2acc3","price_dollars":"0.0100","delta_fp":"-1.00","side":"yes","ts":"2026-07-01T02:33:06.670556Z","ts_ms":1782873186670}}

{"type":"orderbook_delta","sid":1,"seq":933,"msg":{"market_ticker":"KXNEXTTEAMNBA-26LJAM-GSW","market_id":"abbbad28-f309-4dd5-af38-2ad7ebf2acc3","price_dollars":"0.0100","delta_fp":"-1.00","side":"yes","ts":"2026-07-01T02:33:06.670556Z","ts_ms":1782873186670}}

{"type":"orderbook_delta","sid":1,"seq":934,"msg":{"market_ticker":"KXNEXTTEAMNBA-26LJAM-GSW","market_id":"abbbad28-f309-4dd5-af38-2ad7ebf2acc3","price_dollars":"0.0100","delta_fp":"-1.00","side":"yes","ts":"2026-07-01T02:33:06.670556Z","ts_ms":1782873186670}}

{"type":"orderbook_delta","sid":1,"seq":935,"msg":{"market_ticker":"KXNEXTTEAMNBA-26LJAM-GSW","market_id":"abbbad28-f309-4dd5-af38-2ad7ebf2acc3","price_dollars":"0.0100","delta_fp":"-1.00","side":"yes","ts":"2026-07-01T02:33:06.670556Z","ts_ms":1782873186670}}

{"type":"orderbook_delta","sid":1,"seq":936,"msg":{"market_ticker":"KXNEXTTEAMNBA-26LJAM-GSW","market_id":"abbbad28-f309-4dd5-af38-2ad7ebf2acc3","price_dollars":"0.0100","delta_fp":"-1.00","side":"yes","ts":"2026-07-01T02:33:06.670556Z","ts_ms":1782873186670}}

{"type":"orderbook_delta","sid":1,"seq":937,"msg":{"market_ticker":"KXNEXTTEAMNBA-26LJAM-GSW","market_id":"abbbad28-f309-4dd5-af38-2ad7ebf2acc3","price_dollars":"0.0100","delta_fp":"-1.00","side":"yes","ts":"2026-07-01T02:33:06.670556Z","ts_ms":1782873186670}}

{"type":"orderbook_delta","sid":1,"seq":938,"msg":{"market_ticker":"KXNEXTTEAMNBA-26LJAM-GSW","market_id":"abbbad28-f309-4dd5-af38-2ad7ebf2acc3","price_dollars":"0.0100","delta_fp":"-1.00","side":"yes","ts":"2026-07-01T02:33:06.670556Z","ts_ms":1782873186670}}

{"type":"orderbook_delta","sid":1,"seq":939,"msg":{"market_ticker":"KXNEXTTEAMNBA-26LJAM-GSW","market_id":"abbbad28-f309-4dd5-af38-2ad7ebf2acc3","price_dollars":"0.0100","delta_fp":"-1.00","side":"yes","ts":"2026-07-01T02:33:06.670556Z","ts_ms":1782873186670}}

{"type":"orderbook_delta","sid":1,"seq":940,"msg":{"market_ticker":"KXNEXTTEAMNBA-26LJAM-GSW","market_id":"abbbad28-f309-4dd5-af38-2ad7ebf2acc3","price_dollars":"0.0100","delta_fp":"-1.00","side":"yes","ts":"2026-07-01T02:33:06.670556Z","ts_ms":1782873186670}}

{"type":"orderbook_delta","sid":1,"seq":941,"msg":{"market_ticker":"KXNEXTTEAMNBA-26LJAM-GSW","market_id":"abbbad28-f309-4dd5-af38-2ad7ebf2acc3","price_dollars":"0.0100","delta_fp":"-1.00","side":"yes","ts":"2026-07-01T02:33:06.670556Z","ts_ms":1782873186670}}

{"type":"orderbook_delta","sid":1,"seq":942,"msg":{"market_ticker":"KXNEXTTEAMNBA-26LJAM-GSW","market_id":"abbbad28-f309-4dd5-af38-2ad7ebf2acc3","price_dollars":"0.0100","delta_fp":"-1.00","side":"yes","ts":"2026-07-01T02:33:06.670556Z","ts_ms":1782873186670}}

{"type":"orderbook_delta","sid":1,"seq":943,"msg":{"market_ticker":"KXNEXTTEAMNBA-26LJAM-GSW","market_id":"abbbad28-f309-4dd5-af38-2ad7ebf2acc3","price_dollars":"0.0100","delta_fp":"-1.00","side":"yes","ts":"2026-07-01T02:33:06.670556Z","ts_ms":1782873186670}}

{"type":"orderbook_delta","sid":1,"seq":944,"msg":{"market_ticker":"KXNEXTTEAMNBA-26LJAM-GSW","market_id":"abbbad28-f309-4dd5-af38-2ad7ebf2acc3","price_dollars":"0.0100","delta_fp":"-1.00","side":"yes","ts":"2026-07-01T02:33:06.670556Z","ts_ms":1782873186670}}

{"type":"orderbook_delta","sid":1,"seq":945,"msg":{"market_ticker":"KXNEXTTEAMNBA-26LJAM-GSW","market_id":"abbbad28-f309-4dd5-af38-2ad7ebf2acc3","price_dollars":"0.0100","delta_fp":"-1.00","side":"yes","ts":"2026-07-01T02:33:06.670556Z","ts_ms":1782873186670}}

{"type":"orderbook_delta","sid":1,"seq":946,"msg":{"market_ticker":"KXNEXTTEAMNBA-26LJAM-GSW","market_id":"abbbad28-f309-4dd5-af38-2ad7ebf2acc3","price_dollars":"0.0100","delta_fp":"-1.00","side":"yes","ts":"2026-07-01T02:33:06.670556Z","ts_ms":1782873186670}}

{"type":"orderbook_delta","sid":1,"seq":947,"msg":{"market_ticker":"KXNEXTTEAMNBA-26LJAM-GSW","market_id":"abbbad28-f309-4dd5-af38-2ad7ebf2acc3","price_dollars":"0.0100","delta_fp":"-1.00","side":"yes","ts":"2026-07-01T02:33:06.670556Z","ts_ms":1782873186670}}

{"type":"orderbook_delta","sid":1,"seq":948,"msg":{"market_ticker":"KXNEXTTEAMNBA-26LJAM-GSW","market_id":"abbbad28-f309-4dd5-af38-2ad7ebf2acc3","price_dollars":"0.0100","delta_fp":"-1.00","side":"yes","ts":"2026-07-01T02:33:06.670556Z","ts_ms":1782873186670}}

{"type":"orderbook_delta","sid":1,"seq":949,"msg":{"market_ticker":"KXNEXTTEAMNBA-26LJAM-GSW","market_id":"abbbad28-f309-4dd5-af38-2ad7ebf2acc3","price_dollars":"0.0100","delta_fp":"-1.00","side":"yes","ts":"2026-07-01T02:33:06.670556Z","ts_ms":1782873186670}}

{"type":"orderbook_delta","sid":1,"seq":950,"msg":{"market_ticker":"KXNEXTTEAMNBA-26LJAM-GSW","market_id":"abbbad28-f309-4dd5-af38-2ad7ebf2acc3","price_dollars":"0.0100","delta_fp":"-1.00","side":"yes","ts":"2026-07-01T02:33:06.670556Z","ts_ms":1782873186670}}

{"type":"orderbook_delta","sid":1,"seq":951,"msg":{"market_ticker":"KXNEXTTEAMNBA-26LJAM-GSW","market_id":"abbbad28-f309-4dd5-af38-2ad7ebf2acc3","price_dollars":"0.0100","delta_fp":"-1.00","side":"yes","ts":"2026-07-01T02:33:06.670556Z","ts_ms":1782873186670}}

{"type":"orderbook_delta","sid":1,"seq":952,"msg":{"market_ticker":"KXNEXTTEAMNBA-26LJAM-GSW","market_id":"abbbad28-f309-4dd5-af38-2ad7ebf2acc3","price_dollars":"0.0100","delta_fp":"-1.00","side":"yes","ts":"2026-07-01T02:33:06.670556Z","ts_ms":1782873186670}}

{"type":"orderbook_delta","sid":1,"seq":953,"msg":{"market_ticker":"KXNEXTTEAMNBA-26LJAM-GSW","market_id":"abbbad28-f309-4dd5-af38-2ad7ebf2acc3","price_dollars":"0.0100","delta_fp":"-1.00","side":"yes","ts":"2026-07-01T02:33:06.670556Z","ts_ms":1782873186670}}

{"type":"orderbook_delta","sid":1,"seq":954,"msg":{"market_ticker":"KXNEXTTEAMNBA-26LJAM-GSW","market_id":"abbbad28-f309-4dd5-af38-2ad7ebf2acc3","price_dollars":"0.0100","delta_fp":"-1.00","side":"yes","ts":"2026-07-01T02:33:06.670556Z","ts_ms":1782873186670}}

{"type":"orderbook_delta","sid":1,"seq":955,"msg":{"market_ticker":"KXNEXTTEAMNBA-26LJAM-GSW","market_id":"abbbad28-f309-4dd5-af38-2ad7ebf2acc3","price_dollars":"0.0100","delta_fp":"-1.00","side":"yes","ts":"2026-07-01T02:33:06.670556Z","ts_ms":1782873186670}}

{"type":"orderbook_delta","sid":1,"seq":956,"msg":{"market_ticker":"KXNEXTTEAMNBA-26LJAM-GSW","market_id":"abbbad28-f309-4dd5-af38-2ad7ebf2acc3","price_dollars":"0.0100","delta_fp":"-1.00","side":"yes","ts":"2026-07-01T02:33:06.670556Z","ts_ms":1782873186670}}

{"type":"orderbook_delta","sid":1,"seq":957,"msg":{"market_ticker":"KXNEXTTEAMNBA-26LJAM-GSW","market_id":"abbbad28-f309-4dd5-af38-2ad7ebf2acc3","price_dollars":"0.0100","delta_fp":"-1.00","side":"yes","ts":"2026-07-01T02:33:06.670556Z","ts_ms":1782873186670}}

{"type":"orderbook_delta","sid":1,"seq":958,"msg":{"market_ticker":"KXNEXTTEAMNBA-26LJAM-GSW","market_id":"abbbad28-f309-4dd5-af38-2ad7ebf2acc3","price_dollars":"0.0100","delta_fp":"-1.00","side":"yes","ts":"2026-07-01T02:33:06.670556Z","ts_ms":1782873186670}}

{"type":"orderbook_delta","sid":1,"seq":959,"msg":{"market_ticker":"KXNEXTTEAMNBA-26LJAM-GSW","market_id":"abbbad28-f309-4dd5-af38-2ad7ebf2acc3","price_dollars":"0.0100","delta_fp":"-1.00","side":"yes","ts":"2026-07-01T02:33:06.670556Z","ts_ms":1782873186670}}

{"type":"orderbook_delta","sid":1,"seq":960,"msg":{"market_ticker":"KXNEXTTEAMNBA-26LJAM-GSW","market_id":"abbbad28-f309-4dd5-af38-2ad7ebf2acc3","price_dollars":"0.0100","delta_fp":"-1.00","side":"yes","ts":"2026-07-01T02:33:06.670556Z","ts_ms":1782873186670}}

{"type":"orderbook_delta","sid":1,"seq":961,"msg":{"market_ticker":"KXNEXTTEAMNBA-26LJAM-GSW","market_id":"abbbad28-f309-4dd5-af38-2ad7ebf2acc3","price_dollars":"0.0100","delta_fp":"-1.00","side":"yes","ts":"2026-07-01T02:33:06.670556Z","ts_ms":1782873186670}}

{"type":"orderbook_delta","sid":1,"seq":962,"msg":{"market_ticker":"KXNEXTTEAMNBA-26LJAM-GSW","market_id":"abbbad28-f309-4dd5-af38-2ad7ebf2acc3","price_dollars":"0.0100","delta_fp":"-1.00","side":"yes","ts":"2026-07-01T02:33:06.670556Z","ts_ms":1782873186670}}

{"type":"orderbook_delta","sid":1,"seq":963,"msg":{"market_ticker":"KXNEXTTEAMNBA-26LJAM-GSW","market_id":"abbbad28-f309-4dd5-af38-2ad7ebf2acc3","price_dollars":"0.0100","delta_fp":"-1.00","side":"yes","ts":"2026-07-01T02:33:06.670556Z","ts_ms":1782873186670}}

{"type":"orderbook_delta","sid":1,"seq":964,"msg":{"market_ticker":"KXNEXTTEAMNBA-26LJAM-GSW","market_id":"abbbad28-f309-4dd5-af38-2ad7ebf2acc3","price_dollars":"0.0100","delta_fp":"-1.00","side":"yes","ts":"2026-07-01T02:33:06.670556Z","ts_ms":1782873186670}}

{"type":"orderbook_delta","sid":1,"seq":965,"msg":{"market_ticker":"KXNEXTTEAMNBA-26LJAM-GSW","market_id":"abbbad28-f309-4dd5-af38-2ad7ebf2acc3","price_dollars":"0.0100","delta_fp":"-1.00","side":"yes","ts":"2026-07-01T02:33:06.670556Z","ts_ms":1782873186670}}

{"type":"orderbook_delta","sid":1,"seq":966,"msg":{"market_ticker":"KXNEXTTEAMNBA-26LJAM-GSW","market_id":"abbbad28-f309-4dd5-af38-2ad7ebf2acc3","price_dollars":"0.0100","delta_fp":"-1.00","side":"yes","ts":"2026-07-01T02:33:06.670556Z","ts_ms":1782873186670}}

{"type":"orderbook_delta","sid":1,"seq":967,"msg":{"market_ticker":"KXNEXTTEAMNBA-26LJAM-GSW","market_id":"abbbad28-f309-4dd5-af38-2ad7ebf2acc3","price_dollars":"0.0100","delta_fp":"-1.00","side":"yes","ts":"2026-07-01T02:33:06.670556Z","ts_ms":1782873186670}}

{"type":"orderbook_delta","sid":1,"seq":968,"msg":{"market_ticker":"KXNEXTTEAMNBA-26LJAM-GSW","market_id":"abbbad28-f309-4dd5-af38-2ad7ebf2acc3","price_dollars":"0.0100","delta_fp":"-1.00","side":"yes","ts":"2026-07-01T02:33:06.670556Z","ts_ms":1782873186670}}

{"type":"orderbook_delta","sid":1,"seq":969,"msg":{"market_ticker":"KXNEXTTEAMNBA-26LJAM-GSW","market_id":"abbbad28-f309-4dd5-af38-2ad7ebf2acc3","price_dollars":"0.0100","delta_fp":"-1.00","side":"yes","ts":"2026-07-01T02:33:06.670556Z","ts_ms":1782873186670}}

{"type":"orderbook_delta","sid":1,"seq":970,"msg":{"market_ticker":"KXNEXTTEAMNBA-26LJAM-GSW","market_id":"abbbad28-f309-4dd5-af38-2ad7ebf2acc3","price_dollars":"0.0100","delta_fp":"-1.00","side":"yes","ts":"2026-07-01T02:33:06.670556Z","ts_ms":1782873186670}}

{"type":"orderbook_delta","sid":1,"seq":971,"msg":{"market_ticker":"KXNEXTTEAMNBA-26LJAM-GSW","market_id":"abbbad28-f309-4dd5-af38-2ad7ebf2acc3","price_dollars":"0.0100","delta_fp":"-1.00","side":"yes","ts":"2026-07-01T02:33:06.670556Z","ts_ms":1782873186670}}

{"type":"orderbook_delta","sid":1,"seq":972,"msg":{"market_ticker":"KXNEXTTEAMNBA-26LJAM-GSW","market_id":"abbbad28-f309-4dd5-af38-2ad7ebf2acc3","price_dollars":"0.0100","delta_fp":"-1.00","side":"yes","ts":"2026-07-01T02:33:06.670556Z","ts_ms":1782873186670}}

{"type":"orderbook_delta","sid":1,"seq":973,"msg":{"market_ticker":"KXNEXTTEAMNBA-26LJAM-GSW","market_id":"abbbad28-f309-4dd5-af38-2ad7ebf2acc3","price_dollars":"0.0100","delta_fp":"-1.00","side":"yes","ts":"2026-07-01T02:33:06.670556Z","ts_ms":1782873186670}}

{"type":"orderbook_delta","sid":1,"seq":974,"msg":{"market_ticker":"KXNEXTTEAMNBA-26LJAM-GSW","market_id":"abbbad28-f309-4dd5-af38-2ad7ebf2acc3","price_dollars":"0.0100","delta_fp":"-1.00","side":"yes","ts":"2026-07-01T02:33:06.670556Z","ts_ms":1782873186670}}

{"type":"orderbook_delta","sid":1,"seq":975,"msg":{"market_ticker":"KXNEXTTEAMNBA-26LJAM-GSW","market_id":"abbbad28-f309-4dd5-af38-2ad7ebf2acc3","price_dollars":"0.0100","delta_fp":"-1.00","side":"yes","ts":"2026-07-01T02:33:06.670556Z","ts_ms":1782873186670}}

{"type":"orderbook_delta","sid":1,"seq":976,"msg":{"market_ticker":"KXNEXTTEAMNBA-26LJAM-GSW","market_id":"abbbad28-f309-4dd5-af38-2ad7ebf2acc3","price_dollars":"0.0100","delta_fp":"-1.00","side":"yes","ts":"2026-07-01T02:33:06.670556Z","ts_ms":1782873186670}}

{"type":"orderbook_delta","sid":1,"seq":977,"msg":{"market_ticker":"KXNEXTTEAMNBA-26LJAM-GSW","market_id":"abbbad28-f309-4dd5-af38-2ad7ebf2acc3","price_dollars":"0.0100","delta_fp":"-1.00","side":"yes","ts":"2026-07-01T02:33:06.670556Z","ts_ms":1782873186670}}

{"type":"orderbook_delta","sid":1,"seq":978,"msg":{"market_ticker":"KXNEXTTEAMNBA-26LJAM-GSW","market_id":"abbbad28-f309-4dd5-af38-2ad7ebf2acc3","price_dollars":"0.0100","delta_fp":"-1.00","side":"yes","ts":"2026-07-01T02:33:06.670556Z","ts_ms":1782873186670}}

{"type":"orderbook_delta","sid":1,"seq":979,"msg":{"market_ticker":"KXNEXTTEAMNBA-26LJAM-GSW","market_id":"abbbad28-f309-4dd5-af38-2ad7ebf2acc3","price_dollars":"0.0100","delta_fp":"-1.00","side":"yes","ts":"2026-07-01T02:33:06.670556Z","ts_ms":1782873186670}}

{"type":"orderbook_delta","sid":1,"seq":980,"msg":{"market_ticker":"KXNEXTTEAMNBA-26LJAM-GSW","market_id":"abbbad28-f309-4dd5-af38-2ad7ebf2acc3","price_dollars":"0.0100","delta_fp":"-1.00","side":"yes","ts":"2026-07-01T02:33:06.670556Z","ts_ms":1782873186670}}

{"type":"orderbook_delta","sid":1,"seq":981,"msg":{"market_ticker":"KXNEXTTEAMNBA-26LJAM-GSW","market_id":"abbbad28-f309-4dd5-af38-2ad7ebf2acc3","price_dollars":"0.0100","delta_fp":"-1.00","side":"yes","ts":"2026-07-01T02:33:06.670556Z","ts_ms":1782873186670}}

{"type":"orderbook_delta","sid":1,"seq":982,"msg":{"market_ticker":"KXNEXTTEAMNBA-26LJAM-GSW","market_id":"abbbad28-f309-4dd5-af38-2ad7ebf2acc3","price_dollars":"0.0100","delta_fp":"-1.00","side":"yes","ts":"2026-07-01T02:33:06.670556Z","ts_ms":1782873186670}}

{"type":"orderbook_delta","sid":1,"seq":983,"msg":{"market_ticker":"KXNEXTTEAMNBA-26LJAM-GSW","market_id":"abbbad28-f309-4dd5-af38-2ad7ebf2acc3","price_dollars":"0.0100","delta_fp":"-1.00","side":"yes","ts":"2026-07-01T02:33:06.670556Z","ts_ms":1782873186670}}

{"type":"orderbook_delta","sid":1,"seq":984,"msg":{"market_ticker":"KXNEXTTEAMNBA-26LJAM-GSW","market_id":"abbbad28-f309-4dd5-af38-2ad7ebf2acc3","price_dollars":"0.0100","delta_fp":"-1.00","side":"yes","ts":"2026-07-01T02:33:06.670556Z","ts_ms":1782873186670}}

{"type":"orderbook_delta","sid":1,"seq":985,"msg":{"market_ticker":"KXNEXTTEAMNBA-26LJAM-GSW","market_id":"abbbad28-f309-4dd5-af38-2ad7ebf2acc3","price_dollars":"0.0100","delta_fp":"-1.00","side":"yes","ts":"2026-07-01T02:33:06.670556Z","ts_ms":1782873186670}}

{"type":"orderbook_delta","sid":1,"seq":986,"msg":{"market_ticker":"KXNEXTTEAMNBA-26LJAM-GSW","market_id":"abbbad28-f309-4dd5-af38-2ad7ebf2acc3","price_dollars":"0.0100","delta_fp":"-1.00","side":"yes","ts":"2026-07-01T02:33:06.670556Z","ts_ms":1782873186670}}

{"type":"orderbook_delta","sid":1,"seq":987,"msg":{"market_ticker":"KXNEXTTEAMNBA-26LJAM-GSW","market_id":"abbbad28-f309-4dd5-af38-2ad7ebf2acc3","price_dollars":"0.0100","delta_fp":"-1.00","side":"yes","ts":"2026-07-01T02:33:06.670556Z","ts_ms":1782873186670}}

{"type":"orderbook_delta","sid":1,"seq":988,"msg":{"market_ticker":"KXNEXTTEAMNBA-26LJAM-GSW","market_id":"abbbad28-f309-4dd5-af38-2ad7ebf2acc3","price_dollars":"0.0100","delta_fp":"-1.00","side":"yes","ts":"2026-07-01T02:33:06.670556Z","ts_ms":1782873186670}}

{"type":"orderbook_delta","sid":1,"seq":989,"msg":{"market_ticker":"KXNEXTTEAMNBA-26LJAM-GSW","market_id":"abbbad28-f309-4dd5-af38-2ad7ebf2acc3","price_dollars":"0.0100","delta_fp":"-1.00","side":"yes","ts":"2026-07-01T02:33:06.670556Z","ts_ms":1782873186670}}

{"type":"orderbook_delta","sid":1,"seq":990,"msg":{"market_ticker":"KXNEXTTEAMNBA-26LJAM-GSW","market_id":"abbbad28-f309-4dd5-af38-2ad7ebf2acc3","price_dollars":"0.0100","delta_fp":"-1.00","side":"yes","ts":"2026-07-01T02:33:06.670556Z","ts_ms":1782873186670}}

{"type":"orderbook_delta","sid":1,"seq":991,"msg":{"market_ticker":"KXNEXTTEAMNBA-26LJAM-GSW","market_id":"abbbad28-f309-4dd5-af38-2ad7ebf2acc3","price_dollars":"0.0100","delta_fp":"-1.00","side":"yes","ts":"2026-07-01T02:33:06.670556Z","ts_ms":1782873186670}}

{"type":"orderbook_delta","sid":1,"seq":992,"msg":{"market_ticker":"KXNEXTTEAMNBA-26LJAM-GSW","market_id":"abbbad28-f309-4dd5-af38-2ad7ebf2acc3","price_dollars":"0.0100","delta_fp":"-1.00","side":"yes","ts":"2026-07-01T02:33:06.670556Z","ts_ms":1782873186670}}

{"type":"orderbook_delta","sid":1,"seq":993,"msg":{"market_ticker":"KXNEXTTEAMNBA-26LJAM-GSW","market_id":"abbbad28-f309-4dd5-af38-2ad7ebf2acc3","price_dollars":"0.0100","delta_fp":"-1.00","side":"yes","ts":"2026-07-01T02:33:06.670556Z","ts_ms":1782873186670}}

{"type":"orderbook_delta","sid":1,"seq":994,"msg":{"market_ticker":"KXNEXTTEAMNBA-26LJAM-GSW","market_id":"abbbad28-f309-4dd5-af38-2ad7ebf2acc3","price_dollars":"0.0100","delta_fp":"-1.00","side":"yes","ts":"2026-07-01T02:33:06.670556Z","ts_ms":1782873186670}}

{"type":"orderbook_delta","sid":1,"seq":995,"msg":{"market_ticker":"KXNEXTTEAMNBA-26LJAM-GSW","market_id":"abbbad28-f309-4dd5-af38-2ad7ebf2acc3","price_dollars":"0.0100","delta_fp":"-1.00","side":"yes","ts":"2026-07-01T02:33:06.670556Z","ts_ms":1782873186670}}

{"type":"orderbook_delta","sid":1,"seq":996,"msg":{"market_ticker":"KXNEXTTEAMNBA-26LJAM-GSW","market_id":"abbbad28-f309-4dd5-af38-2ad7ebf2acc3","price_dollars":"0.0100","delta_fp":"-1.00","side":"yes","ts":"2026-07-01T02:33:06.670556Z","ts_ms":1782873186670}}

{"type":"orderbook_delta","sid":1,"seq":997,"msg":{"market_ticker":"KXNEXTTEAMNBA-26LJAM-GSW","market_id":"abbbad28-f309-4dd5-af38-2ad7ebf2acc3","price_dollars":"0.0100","delta_fp":"-1.00","side":"yes","ts":"2026-07-01T02:33:06.670556Z","ts_ms":1782873186670}}

{"type":"orderbook_delta","sid":1,"seq":998,"msg":{"market_ticker":"KXNEXTTEAMNBA-26LJAM-GSW","market_id":"abbbad28-f309-4dd5-af38-2ad7ebf2acc3","price_dollars":"0.0100","delta_fp":"-1.00","side":"yes","ts":"2026-07-01T02:33:06.670556Z","ts_ms":1782873186670}}

{"type":"orderbook_delta","sid":1,"seq":999,"msg":{"market_ticker":"KXNEXTTEAMNBA-26LJAM-MIA","market_id":"492cb255-91da-4c91-bc9e-f83d090cc6dd","price_dollars":"0.8300","delta_fp":"-1.77","side":"no","ts":"2026-07-01T02:33:08.095406Z","ts_ms":1782873188095}}

{"type":"orderbook_delta","sid":1,"seq":1000,"msg":{"market_ticker":"KXNEXTTEAMNBA-26LJAM-CLE","market_id":"7552b8d4-05de-4e41-84a8-97b0684da4a9","price_dollars":"0.7400","delta_fp":"-1.68","side":"no","ts":"2026-07-01T02:33:08.113272Z","ts_ms":1782873188113}}

{"type":"orderbook_delta","sid":1,"seq":1001,"msg":{"market_ticker":"KXNEXTTEAMNBA-26LJAM-MIA","market_id":"492cb255-91da-4c91-bc9e-f83d090cc6dd","price_dollars":"0.8300","delta_fp":"-0.13","side":"no","ts":"2026-07-01T02:33:09.775053Z","ts_ms":1782873189775}}

{"type":"orderbook_delta","sid":1,"seq":1002,"msg":{"market_ticker":"KXNEXTTEAMNBA-26LJAM-GSW","market_id":"abbbad28-f309-4dd5-af38-2ad7ebf2acc3","price_dollars":"0.5200","delta_fp":"-0.72","side":"no","ts":"2026-07-01T02:33:09.802848Z","ts_ms":1782873189802}}

{"type":"orderbook_delta","sid":1,"seq":1003,"msg":{"market_ticker":"KXNEXTTEAMNBA-26LJAM-GSW","market_id":"abbbad28-f309-4dd5-af38-2ad7ebf2acc3","price_dollars":"0.5200","delta_fp":"-694.44","side":"no","ts":"2026-07-01T02:33:09.92237Z","ts_ms":1782873189922}}

{"type":"orderbook_delta","sid":1,"seq":1004,"msg":{"market_ticker":"KXNEXTTEAMNBA-26LJAM-GSW","market_id":"abbbad28-f309-4dd5-af38-2ad7ebf2acc3","price_dollars":"0.5100","delta_fp":"-680.27","side":"no","ts":"2026-07-01T02:33:09.92237Z","ts_ms":1782873189922}}

{"type":"orderbook_delta","sid":1,"seq":1005,"msg":{"market_ticker":"KXNEXTTEAMNBA-26LJAM-GSW","market_id":"abbbad28-f309-4dd5-af38-2ad7ebf2acc3","price_dollars":"0.5000","delta_fp":"-666.66","side":"no","ts":"2026-07-01T02:33:09.92237Z","ts_ms":1782873189922}}

{"type":"orderbook_delta","sid":1,"seq":1006,"msg":{"market_ticker":"KXNEXTTEAMNBA-26LJAM-GSW","market_id":"abbbad28-f309-4dd5-af38-2ad7ebf2acc3","price_dollars":"0.5200","delta_fp":"-694.44","side":"no","ts":"2026-07-01T02:33:09.92237Z","ts_ms":1782873189922}}

{"type":"orderbook_delta","sid":1,"seq":1007,"msg":{"market_ticker":"KXNEXTTEAMNBA-26LJAM-GSW","market_id":"abbbad28-f309-4dd5-af38-2ad7ebf2acc3","price_dollars":"0.5100","delta_fp":"-680.27","side":"no","ts":"2026-07-01T02:33:09.92237Z","ts_ms":1782873189922}}

{"type":"orderbook_delta","sid":1,"seq":1008,"msg":{"market_ticker":"KXNEXTTEAMNBA-26LJAM-GSW","market_id":"abbbad28-f309-4dd5-af38-2ad7ebf2acc3","price_dollars":"0.5000","delta_fp":"-666.66","side":"no","ts":"2026-07-01T02:33:09.92237Z","ts_ms":1782873189922}}

{"type":"orderbook_delta","sid":1,"seq":1009,"msg":{"market_ticker":"KXNEXTTEAMNBA-26LJAM-GSW","market_id":"abbbad28-f309-4dd5-af38-2ad7ebf2acc3","price_dollars":"0.5200","delta_fp":"-694.44","side":"no","ts":"2026-07-01T02:33:09.92237Z","ts_ms":1782873189922}}

{"type":"orderbook_delta","sid":1,"seq":1010,"msg":{"market_ticker":"KXNEXTTEAMNBA-26LJAM-GSW","market_id":"abbbad28-f309-4dd5-af38-2ad7ebf2acc3","price_dollars":"0.5100","delta_fp":"-680.27","side":"no","ts":"2026-07-01T02:33:09.92237Z","ts_ms":1782873189922}}

{"type":"orderbook_delta","sid":1,"seq":1011,"msg":{"market_ticker":"KXNEXTTEAMNBA-26LJAM-GSW","market_id":"abbbad28-f309-4dd5-af38-2ad7ebf2acc3","price_dollars":"0.5000","delta_fp":"-666.66","side":"no","ts":"2026-07-01T02:33:09.92237Z","ts_ms":1782873189922}}

{"type":"orderbook_delta","sid":1,"seq":1012,"msg":{"market_ticker":"KXNEXTTEAMNBA-26LJAM-GSW","market_id":"abbbad28-f309-4dd5-af38-2ad7ebf2acc3","price_dollars":"0.0100","delta_fp":"1.00","side":"yes","ts":"2026-07-01T02:33:10.660219Z","ts_ms":1782873190660}}

{"type":"orderbook_delta","sid":1,"seq":1013,"msg":{"market_ticker":"KXNEXTTEAMNBA-26LJAM-GSW","market_id":"abbbad28-f309-4dd5-af38-2ad7ebf2acc3","price_dollars":"0.0100","delta_fp":"1.00","side":"yes","ts":"2026-07-01T02:33:10.660767Z","ts_ms":1782873190660}}

{"type":"orderbook_delta","sid":1,"seq":1014,"msg":{"market_ticker":"KXNEXTTEAMNBA-26LJAM-GSW","market_id":"abbbad28-f309-4dd5-af38-2ad7ebf2acc3","price_dollars":"0.0100","delta_fp":"1.00","side":"yes","ts":"2026-07-01T02:33:10.661172Z","ts_ms":1782873190661}}

{"type":"orderbook_delta","sid":1,"seq":1015,"msg":{"market_ticker":"KXNEXTTEAMNBA-26LJAM-GSW","market_id":"abbbad28-f309-4dd5-af38-2ad7ebf2acc3","price_dollars":"0.0100","delta_fp":"1.00","side":"yes","ts":"2026-07-01T02:33:10.661646Z","ts_ms":1782873190661}}

{"type":"orderbook_delta","sid":1,"seq":1016,"msg":{"market_ticker":"KXNEXTTEAMNBA-26LJAM-GSW","market_id":"abbbad28-f309-4dd5-af38-2ad7ebf2acc3","price_dollars":"0.0100","delta_fp":"1.00","side":"yes","ts":"2026-07-01T02:33:10.662208Z","ts_ms":1782873190662}}

{"type":"orderbook_delta","sid":1,"seq":1017,"msg":{"market_ticker":"KXNEXTTEAMNBA-26LJAM-GSW","market_id":"abbbad28-f309-4dd5-af38-2ad7ebf2acc3","price_dollars":"0.0100","delta_fp":"1.00","side":"yes","ts":"2026-07-01T02:33:10.662954Z","ts_ms":1782873190662}}

{"type":"orderbook_delta","sid":1,"seq":1018,"msg":{"market_ticker":"KXNEXTTEAMNBA-26LJAM-GSW","market_id":"abbbad28-f309-4dd5-af38-2ad7ebf2acc3","price_dollars":"0.0100","delta_fp":"1.00","side":"yes","ts":"2026-07-01T02:33:10.663494Z","ts_ms":1782873190663}}

{"type":"orderbook_delta","sid":1,"seq":1019,"msg":{"market_ticker":"KXNEXTTEAMNBA-26LJAM-GSW","market_id":"abbbad28-f309-4dd5-af38-2ad7ebf2acc3","price_dollars":"0.0100","delta_fp":"1.00","side":"yes","ts":"2026-07-01T02:33:10.664141Z","ts_ms":1782873190664}}

{"type":"orderbook_delta","sid":1,"seq":1020,"msg":{"market_ticker":"KXNEXTTEAMNBA-26LJAM-GSW","market_id":"abbbad28-f309-4dd5-af38-2ad7ebf2acc3","price_dollars":"0.0100","delta_fp":"1.00","side":"yes","ts":"2026-07-01T02:33:10.66489Z","ts_ms":1782873190664}}

{"type":"orderbook_delta","sid":1,"seq":1021,"msg":{"market_ticker":"KXNEXTTEAMNBA-26LJAM-GSW","market_id":"abbbad28-f309-4dd5-af38-2ad7ebf2acc3","price_dollars":"0.0100","delta_fp":"1.00","side":"yes","ts":"2026-07-01T02:33:10.665544Z","ts_ms":1782873190665}}

{"type":"orderbook_delta","sid":1,"seq":1022,"msg":{"market_ticker":"KXNEXTTEAMNBA-26LJAM-GSW","market_id":"abbbad28-f309-4dd5-af38-2ad7ebf2acc3","price_dollars":"0.0100","delta_fp":"1.00","side":"yes","ts":"2026-07-01T02:33:10.66611Z","ts_ms":1782873190666}}

{"type":"orderbook_delta","sid":1,"seq":1023,"msg":{"market_ticker":"KXNEXTTEAMNBA-26LJAM-GSW","market_id":"abbbad28-f309-4dd5-af38-2ad7ebf2acc3","price_dollars":"0.0100","delta_fp":"1.00","side":"yes","ts":"2026-07-01T02:33:10.666545Z","ts_ms":1782873190666}}

{"type":"orderbook_delta","sid":1,"seq":1024,"msg":{"market_ticker":"KXNEXTTEAMNBA-26LJAM-GSW","market_id":"abbbad28-f309-4dd5-af38-2ad7ebf2acc3","price_dollars":"0.0100","delta_fp":"1.00","side":"yes","ts":"2026-07-01T02:33:10.667087Z","ts_ms":1782873190667}}

{"type":"orderbook_delta","sid":1,"seq":1025,"msg":{"market_ticker":"KXNEXTTEAMNBA-26LJAM-GSW","market_id":"abbbad28-f309-4dd5-af38-2ad7ebf2acc3","price_dollars":"0.0100","delta_fp":"1.00","side":"yes","ts":"2026-07-01T02:33:10.667737Z","ts_ms":1782873190667}}

{"type":"orderbook_delta","sid":1,"seq":1026,"msg":{"market_ticker":"KXNEXTTEAMNBA-26LJAM-GSW","market_id":"abbbad28-f309-4dd5-af38-2ad7ebf2acc3","price_dollars":"0.0100","delta_fp":"1.00","side":"yes","ts":"2026-07-01T02:33:10.668306Z","ts_ms":1782873190668}}

{"type":"orderbook_delta","sid":1,"seq":1027,"msg":{"market_ticker":"KXNEXTTEAMNBA-26LJAM-GSW","market_id":"abbbad28-f309-4dd5-af38-2ad7ebf2acc3","price_dollars":"0.0100","delta_fp":"1.00","side":"yes","ts":"2026-07-01T02:33:10.669045Z","ts_ms":1782873190669}}

{"type":"orderbook_delta","sid":1,"seq":1028,"msg":{"market_ticker":"KXNEXTTEAMNBA-26LJAM-GSW","market_id":"abbbad28-f309-4dd5-af38-2ad7ebf2acc3","price_dollars":"0.0100","delta_fp":"1.00","side":"yes","ts":"2026-07-01T02:33:10.669631Z","ts_ms":1782873190669}}

{"type":"orderbook_delta","sid":1,"seq":1029,"msg":{"market_ticker":"KXNEXTTEAMNBA-26LJAM-GSW","market_id":"abbbad28-f309-4dd5-af38-2ad7ebf2acc3","price_dollars":"0.0100","delta_fp":"1.00","side":"yes","ts":"2026-07-01T02:33:10.670164Z","ts_ms":1782873190670}}

{"type":"orderbook_delta","sid":1,"seq":1030,"msg":{"market_ticker":"KXNEXTTEAMNBA-26LJAM-GSW","market_id":"abbbad28-f309-4dd5-af38-2ad7ebf2acc3","price_dollars":"0.0100","delta_fp":"1.00","side":"yes","ts":"2026-07-01T02:33:10.670585Z","ts_ms":1782873190670}}

{"type":"orderbook_delta","sid":1,"seq":1031,"msg":{"market_ticker":"KXNEXTTEAMNBA-26LJAM-GSW","market_id":"abbbad28-f309-4dd5-af38-2ad7ebf2acc3","price_dollars":"0.0100","delta_fp":"1.00","side":"yes","ts":"2026-07-01T02:33:10.671082Z","ts_ms":1782873190671}}

{"type":"orderbook_delta","sid":1,"seq":1032,"msg":{"market_ticker":"KXNEXTTEAMNBA-26LJAM-MIA","market_id":"492cb255-91da-4c91-bc9e-f83d090cc6dd","price_dollars":"0.0100","delta_fp":"1.00","side":"yes","ts":"2026-07-01T02:33:11.936194Z","ts_ms":1782873191936}}

{"type":"orderbook_delta","sid":1,"seq":1033,"msg":{"market_ticker":"KXNEXTTEAMNBA-26LJAM-MIA","market_id":"492cb255-91da-4c91-bc9e-f83d090cc6dd","price_dollars":"0.0100","delta_fp":"1.00","side":"yes","ts":"2026-07-01T02:33:11.936737Z","ts_ms":1782873191936}}

{"type":"orderbook_delta","sid":1,"seq":1034,"msg":{"market_ticker":"KXNEXTTEAMNBA-26LJAM-MIA","market_id":"492cb255-91da-4c91-bc9e-f83d090cc6dd","price_dollars":"0.0100","delta_fp":"1.00","side":"yes","ts":"2026-07-01T02:33:11.937135Z","ts_ms":1782873191937}}

{"type":"orderbook_delta","sid":1,"seq":1035,"msg":{"market_ticker":"KXNEXTTEAMNBA-26LJAM-MIA","market_id":"492cb255-91da-4c91-bc9e-f83d090cc6dd","price_dollars":"0.0100","delta_fp":"1.00","side":"yes","ts":"2026-07-01T02:33:11.937687Z","ts_ms":1782873191937}}

{"type":"orderbook_delta","sid":1,"seq":1036,"msg":{"market_ticker":"KXNEXTTEAMNBA-26LJAM-MIA","market_id":"492cb255-91da-4c91-bc9e-f83d090cc6dd","price_dollars":"0.0100","delta_fp":"1.00","side":"yes","ts":"2026-07-01T02:33:11.93817Z","ts_ms":1782873191938}}

{"type":"orderbook_delta","sid":1,"seq":1037,"msg":{"market_ticker":"KXNEXTTEAMNBA-26LJAM-MIA","market_id":"492cb255-91da-4c91-bc9e-f83d090cc6dd","price_dollars":"0.0100","delta_fp":"1.00","side":"yes","ts":"2026-07-01T02:33:11.938608Z","ts_ms":1782873191938}}

{"type":"orderbook_delta","sid":1,"seq":1038,"msg":{"market_ticker":"KXNEXTTEAMNBA-26LJAM-MIA","market_id":"492cb255-91da-4c91-bc9e-f83d090cc6dd","price_dollars":"0.0100","delta_fp":"1.00","side":"yes","ts":"2026-07-01T02:33:11.93911Z","ts_ms":1782873191939}}

{"type":"orderbook_delta","sid":1,"seq":1039,"msg":{"market_ticker":"KXNEXTTEAMNBA-26LJAM-MIA","market_id":"492cb255-91da-4c91-bc9e-f83d090cc6dd","price_dollars":"0.0100","delta_fp":"1.00","side":"yes","ts":"2026-07-01T02:33:11.939712Z","ts_ms":1782873191939}}

{"type":"orderbook_delta","sid":1,"seq":1040,"msg":{"market_ticker":"KXNEXTTEAMNBA-26LJAM-MIA","market_id":"492cb255-91da-4c91-bc9e-f83d090cc6dd","price_dollars":"0.0100","delta_fp":"1.00","side":"yes","ts":"2026-07-01T02:33:11.940285Z","ts_ms":1782873191940}}

{"type":"orderbook_delta","sid":1,"seq":1041,"msg":{"market_ticker":"KXNEXTTEAMNBA-26LJAM-MIA","market_id":"492cb255-91da-4c91-bc9e-f83d090cc6dd","price_dollars":"0.0100","delta_fp":"1.00","side":"yes","ts":"2026-07-01T02:33:11.94067Z","ts_ms":1782873191940}}

{"type":"orderbook_delta","sid":1,"seq":1042,"msg":{"market_ticker":"KXNEXTTEAMNBA-26LJAM-MIA","market_id":"492cb255-91da-4c91-bc9e-f83d090cc6dd","price_dollars":"0.0100","delta_fp":"1.00","side":"yes","ts":"2026-07-01T02:33:11.941003Z","ts_ms":1782873191941}}

{"type":"orderbook_delta","sid":1,"seq":1043,"msg":{"market_ticker":"KXNEXTTEAMNBA-26LJAM-MIA","market_id":"492cb255-91da-4c91-bc9e-f83d090cc6dd","price_dollars":"0.0100","delta_fp":"1.00","side":"yes","ts":"2026-07-01T02:33:11.941377Z","ts_ms":1782873191941}}

{"type":"orderbook_delta","sid":1,"seq":1044,"msg":{"market_ticker":"KXNEXTTEAMNBA-26LJAM-MIA","market_id":"492cb255-91da-4c91-bc9e-f83d090cc6dd","price_dollars":"0.0100","delta_fp":"1.00","side":"yes","ts":"2026-07-01T02:33:11.941911Z","ts_ms":1782873191941}}

{"type":"orderbook_delta","sid":1,"seq":1045,"msg":{"market_ticker":"KXNEXTTEAMNBA-26LJAM-MIA","market_id":"492cb255-91da-4c91-bc9e-f83d090cc6dd","price_dollars":"0.0100","delta_fp":"1.00","side":"yes","ts":"2026-07-01T02:33:11.942487Z","ts_ms":1782873191942}}

{"type":"orderbook_delta","sid":1,"seq":1046,"msg":{"market_ticker":"KXNEXTTEAMNBA-26LJAM-MIA","market_id":"492cb255-91da-4c91-bc9e-f83d090cc6dd","price_dollars":"0.0100","delta_fp":"1.00","side":"yes","ts":"2026-07-01T02:33:11.942825Z","ts_ms":1782873191942}}

{"type":"orderbook_delta","sid":1,"seq":1047,"msg":{"market_ticker":"KXNEXTTEAMNBA-26LJAM-MIA","market_id":"492cb255-91da-4c91-bc9e-f83d090cc6dd","price_dollars":"0.0100","delta_fp":"1.00","side":"yes","ts":"2026-07-01T02:33:11.943206Z","ts_ms":1782873191943}}

{"type":"orderbook_delta","sid":1,"seq":1048,"msg":{"market_ticker":"KXNEXTTEAMNBA-26LJAM-MIA","market_id":"492cb255-91da-4c91-bc9e-f83d090cc6dd","price_dollars":"0.0100","delta_fp":"1.00","side":"yes","ts":"2026-07-01T02:33:11.943626Z","ts_ms":1782873191943}}

{"type":"orderbook_delta","sid":1,"seq":1049,"msg":{"market_ticker":"KXNEXTTEAMNBA-26LJAM-MIA","market_id":"492cb255-91da-4c91-bc9e-f83d090cc6dd","price_dollars":"0.0100","delta_fp":"1.00","side":"yes","ts":"2026-07-01T02:33:11.944218Z","ts_ms":1782873191944}}

{"type":"orderbook_delta","sid":1,"seq":1050,"msg":{"market_ticker":"KXNEXTTEAMNBA-26LJAM-MIA","market_id":"492cb255-91da-4c91-bc9e-f83d090cc6dd","price_dollars":"0.0100","delta_fp":"1.00","side":"yes","ts":"2026-07-01T02:33:11.944609Z","ts_ms":1782873191944}}

{"type":"orderbook_delta","sid":1,"seq":1051,"msg":{"market_ticker":"KXNEXTTEAMNBA-26LJAM-MIA","market_id":"492cb255-91da-4c91-bc9e-f83d090cc6dd","price_dollars":"0.0100","delta_fp":"1.00","side":"yes","ts":"2026-07-01T02:33:11.94515Z","ts_ms":1782873191945}}

{"type":"orderbook_delta","sid":1,"seq":1052,"msg":{"market_ticker":"KXNEXTTEAMNBA-26LJAM-CLE","market_id":"7552b8d4-05de-4e41-84a8-97b0684da4a9","price_dollars":"0.7400","delta_fp":"-1.26","side":"no","ts":"2026-07-01T02:33:12.997601Z","ts_ms":1782873192997}}

{"type":"orderbook_delta","sid":1,"seq":1053,"msg":{"market_ticker":"KXNEXTTEAMNBA-26LJAM-MIA","market_id":"492cb255-91da-4c91-bc9e-f83d090cc6dd","price_dollars":"0.8300","delta_fp":"-0.92","side":"no","ts":"2026-07-01T02:33:13.055625Z","ts_ms":1782873193055}}

{"type":"orderbook_delta","sid":1,"seq":1054,"msg":{"market_ticker":"KXNEXTTEAMNBA-26LJAM-GSW","market_id":"abbbad28-f309-4dd5-af38-2ad7ebf2acc3","price_dollars":"0.5200","delta_fp":"-0.48","side":"no","ts":"2026-07-01T02:33:13.07771Z","ts_ms":1782873193077}}

{"type":"orderbook_delta","sid":1,"seq":1055,"msg":{"market_ticker":"KXNEXTTEAMNBA-26LJAM-CLE","market_id":"7552b8d4-05de-4e41-84a8-97b0684da4a9","price_dollars":"0.7400","delta_fp":"-0.21","side":"no","ts":"2026-07-01T02:33:14.776645Z","ts_ms":1782873194776}}

{"type":"orderbook_delta","sid":1,"seq":1056,"msg":{"market_ticker":"KXNEXTTEAMNBA-26LJAM-MIA","market_id":"492cb255-91da-4c91-bc9e-f83d090cc6dd","price_dollars":"0.8300","delta_fp":"-1.45","side":"no","ts":"2026-07-01T02:33:14.864364Z","ts_ms":1782873194864}}

{"type":"orderbook_delta","sid":1,"seq":1057,"msg":{"market_ticker":"KXNEXTTEAMNBA-26LJAM-GSW","market_id":"abbbad28-f309-4dd5-af38-2ad7ebf2acc3","price_dollars":"0.5200","delta_fp":"-1.53","side":"no","ts":"2026-07-01T02:33:16.394442Z","ts_ms":1782873196394}}

{"type":"orderbook_delta","sid":1,"seq":1058,"msg":{"market_ticker":"KXNEXTTEAMNBA-26LJAM-GSW","market_id":"abbbad28-f309-4dd5-af38-2ad7ebf2acc3","price_dollars":"0.5200","delta_fp":"-1.47","side":"no","ts":"2026-07-01T02:33:16.461101Z","ts_ms":1782873196461}}

{"type":"orderbook_delta","sid":1,"seq":1059,"msg":{"market_ticker":"KXNEXTTEAMNBA-26LJAM-CLE","market_id":"7552b8d4-05de-4e41-84a8-97b0684da4a9","price_dollars":"0.7400","delta_fp":"-0.08","side":"no","ts":"2026-07-01T02:33:16.508947Z","ts_ms":1782873196508}}

{"type":"orderbook_delta","sid":1,"seq":1060,"msg":{"market_ticker":"KXNEXTTEAMNBA-26LJAM-GSW","market_id":"abbbad28-f309-4dd5-af38-2ad7ebf2acc3","price_dollars":"0.0100","delta_fp":"1.00","side":"yes","ts":"2026-07-01T02:33:17.369265Z","ts_ms":1782873197369}}

{"type":"orderbook_delta","sid":1,"seq":1061,"msg":{"market_ticker":"KXNEXTTEAMNBA-26LJAM-GSW","market_id":"abbbad28-f309-4dd5-af38-2ad7ebf2acc3","price_dollars":"0.0100","delta_fp":"1.00","side":"yes","ts":"2026-07-01T02:33:17.370594Z","ts_ms":1782873197370}}

{"type":"orderbook_delta","sid":1,"seq":1062,"msg":{"market_ticker":"KXNEXTTEAMNBA-26LJAM-GSW","market_id":"abbbad28-f309-4dd5-af38-2ad7ebf2acc3","price_dollars":"0.0100","delta_fp":"1.00","side":"yes","ts":"2026-07-01T02:33:17.371674Z","ts_ms":1782873197371}}

{"type":"orderbook_delta","sid":1,"seq":1063,"msg":{"market_ticker":"KXNEXTTEAMNBA-26LJAM-GSW","market_id":"abbbad28-f309-4dd5-af38-2ad7ebf2acc3","price_dollars":"0.0100","delta_fp":"1.00","side":"yes","ts":"2026-07-01T02:33:17.372651Z","ts_ms":1782873197372}}

{"type":"orderbook_delta","sid":1,"seq":1064,"msg":{"market_ticker":"KXNEXTTEAMNBA-26LJAM-GSW","market_id":"abbbad28-f309-4dd5-af38-2ad7ebf2acc3","price_dollars":"0.0100","delta_fp":"1.00","side":"yes","ts":"2026-07-01T02:33:17.373597Z","ts_ms":1782873197373}}

{"type":"orderbook_delta","sid":1,"seq":1065,"msg":{"market_ticker":"KXNEXTTEAMNBA-26LJAM-GSW","market_id":"abbbad28-f309-4dd5-af38-2ad7ebf2acc3","price_dollars":"0.0100","delta_fp":"1.00","side":"yes","ts":"2026-07-01T02:33:17.374211Z","ts_ms":1782873197374}}

{"type":"orderbook_delta","sid":1,"seq":1066,"msg":{"market_ticker":"KXNEXTTEAMNBA-26LJAM-GSW","market_id":"abbbad28-f309-4dd5-af38-2ad7ebf2acc3","price_dollars":"0.0100","delta_fp":"1.00","side":"yes","ts":"2026-07-01T02:33:17.375026Z","ts_ms":1782873197375}}

{"type":"orderbook_delta","sid":1,"seq":1067,"msg":{"market_ticker":"KXNEXTTEAMNBA-26LJAM-GSW","market_id":"abbbad28-f309-4dd5-af38-2ad7ebf2acc3","price_dollars":"0.0100","delta_fp":"1.00","side":"yes","ts":"2026-07-01T02:33:17.375808Z","ts_ms":1782873197375}}

{"type":"orderbook_delta","sid":1,"seq":1068,"msg":{"market_ticker":"KXNEXTTEAMNBA-26LJAM-GSW","market_id":"abbbad28-f309-4dd5-af38-2ad7ebf2acc3","price_dollars":"0.0100","delta_fp":"1.00","side":"yes","ts":"2026-07-01T02:33:17.376349Z","ts_ms":1782873197376}}

{"type":"orderbook_delta","sid":1,"seq":1069,"msg":{"market_ticker":"KXNEXTTEAMNBA-26LJAM-GSW","market_id":"abbbad28-f309-4dd5-af38-2ad7ebf2acc3","price_dollars":"0.0100","delta_fp":"1.00","side":"yes","ts":"2026-07-01T02:33:17.37684Z","ts_ms":1782873197376}}

{"type":"orderbook_delta","sid":1,"seq":1070,"msg":{"market_ticker":"KXNEXTTEAMNBA-26LJAM-GSW","market_id":"abbbad28-f309-4dd5-af38-2ad7ebf2acc3","price_dollars":"0.0100","delta_fp":"1.00","side":"yes","ts":"2026-07-01T02:33:17.377502Z","ts_ms":1782873197377}}

{"type":"orderbook_delta","sid":1,"seq":1071,"msg":{"market_ticker":"KXNEXTTEAMNBA-26LJAM-GSW","market_id":"abbbad28-f309-4dd5-af38-2ad7ebf2acc3","price_dollars":"0.0100","delta_fp":"1.00","side":"yes","ts":"2026-07-01T02:33:17.378238Z","ts_ms":1782873197378}}

{"type":"orderbook_delta","sid":1,"seq":1072,"msg":{"market_ticker":"KXNEXTTEAMNBA-26LJAM-GSW","market_id":"abbbad28-f309-4dd5-af38-2ad7ebf2acc3","price_dollars":"0.0100","delta_fp":"1.00","side":"yes","ts":"2026-07-01T02:33:17.378758Z","ts_ms":1782873197378}}

{"type":"orderbook_delta","sid":1,"seq":1073,"msg":{"market_ticker":"KXNEXTTEAMNBA-26LJAM-GSW","market_id":"abbbad28-f309-4dd5-af38-2ad7ebf2acc3","price_dollars":"0.0100","delta_fp":"1.00","side":"yes","ts":"2026-07-01T02:33:17.379155Z","ts_ms":1782873197379}}

{"type":"orderbook_delta","sid":1,"seq":1074,"msg":{"market_ticker":"KXNEXTTEAMNBA-26LJAM-GSW","market_id":"abbbad28-f309-4dd5-af38-2ad7ebf2acc3","price_dollars":"0.0100","delta_fp":"1.00","side":"yes","ts":"2026-07-01T02:33:17.379754Z","ts_ms":1782873197379}}

{"type":"orderbook_delta","sid":1,"seq":1075,"msg":{"market_ticker":"KXNEXTTEAMNBA-26LJAM-GSW","market_id":"abbbad28-f309-4dd5-af38-2ad7ebf2acc3","price_dollars":"0.0100","delta_fp":"1.00","side":"yes","ts":"2026-07-01T02:33:17.380232Z","ts_ms":1782873197380}}

{"type":"orderbook_delta","sid":1,"seq":1076,"msg":{"market_ticker":"KXNEXTTEAMNBA-26LJAM-GSW","market_id":"abbbad28-f309-4dd5-af38-2ad7ebf2acc3","price_dollars":"0.0100","delta_fp":"1.00","side":"yes","ts":"2026-07-01T02:33:17.380619Z","ts_ms":1782873197380}}

{"type":"orderbook_delta","sid":1,"seq":1077,"msg":{"market_ticker":"KXNEXTTEAMNBA-26LJAM-GSW","market_id":"abbbad28-f309-4dd5-af38-2ad7ebf2acc3","price_dollars":"0.0100","delta_fp":"1.00","side":"yes","ts":"2026-07-01T02:33:17.381013Z","ts_ms":1782873197381}}

{"type":"orderbook_delta","sid":1,"seq":1078,"msg":{"market_ticker":"KXNEXTTEAMNBA-26LJAM-GSW","market_id":"abbbad28-f309-4dd5-af38-2ad7ebf2acc3","price_dollars":"0.0100","delta_fp":"1.00","side":"yes","ts":"2026-07-01T02:33:17.381416Z","ts_ms":1782873197381}}

{"type":"orderbook_delta","sid":1,"seq":1079,"msg":{"market_ticker":"KXNEXTTEAMNBA-26LJAM-GSW","market_id":"abbbad28-f309-4dd5-af38-2ad7ebf2acc3","price_dollars":"0.0100","delta_fp":"1.00","side":"yes","ts":"2026-07-01T02:33:17.381829Z","ts_ms":1782873197381}}

{"type":"orderbook_delta","sid":1,"seq":1080,"msg":{"market_ticker":"KXNEXTTEAMNBA-26LJAM-MIA","market_id":"492cb255-91da-4c91-bc9e-f83d090cc6dd","price_dollars":"0.8300","delta_fp":"-1.02","side":"no","ts":"2026-07-01T02:33:18.072692Z","ts_ms":1782873198072}}

{"type":"orderbook_delta","sid":1,"seq":1081,"msg":{"market_ticker":"KXNEXTTEAMNBA-26LJAM-GSW","market_id":"abbbad28-f309-4dd5-af38-2ad7ebf2acc3","price_dollars":"0.5200","delta_fp":"-1.26","side":"no","ts":"2026-07-01T02:33:18.090716Z","ts_ms":1782873198090}}

{"type":"orderbook_delta","sid":1,"seq":1082,"msg":{"market_ticker":"KXNEXTTEAMNBA-26LJAM-MIA","market_id":"492cb255-91da-4c91-bc9e-f83d090cc6dd","price_dollars":"0.0100","delta_fp":"1.00","side":"yes","ts":"2026-07-01T02:33:18.650567Z","ts_ms":1782873198650}}

{"type":"orderbook_delta","sid":1,"seq":1083,"msg":{"market_ticker":"KXNEXTTEAMNBA-26LJAM-MIA","market_id":"492cb255-91da-4c91-bc9e-f83d090cc6dd","price_dollars":"0.0100","delta_fp":"1.00","side":"yes","ts":"2026-07-01T02:33:18.651101Z","ts_ms":1782873198651}}

{"type":"orderbook_delta","sid":1,"seq":1084,"msg":{"market_ticker":"KXNEXTTEAMNBA-26LJAM-MIA","market_id":"492cb255-91da-4c91-bc9e-f83d090cc6dd","price_dollars":"0.0100","delta_fp":"1.00","side":"yes","ts":"2026-07-01T02:33:18.651636Z","ts_ms":1782873198651}}

{"type":"orderbook_delta","sid":1,"seq":1085,"msg":{"market_ticker":"KXNEXTTEAMNBA-26LJAM-MIA","market_id":"492cb255-91da-4c91-bc9e-f83d090cc6dd","price_dollars":"0.0100","delta_fp":"1.00","side":"yes","ts":"2026-07-01T02:33:18.652125Z","ts_ms":1782873198652}}

{"type":"orderbook_delta","sid":1,"seq":1086,"msg":{"market_ticker":"KXNEXTTEAMNBA-26LJAM-MIA","market_id":"492cb255-91da-4c91-bc9e-f83d090cc6dd","price_dollars":"0.0100","delta_fp":"1.00","side":"yes","ts":"2026-07-01T02:33:18.65267Z","ts_ms":1782873198652}}

{"type":"orderbook_delta","sid":1,"seq":1087,"msg":{"market_ticker":"KXNEXTTEAMNBA-26LJAM-MIA","market_id":"492cb255-91da-4c91-bc9e-f83d090cc6dd","price_dollars":"0.0100","delta_fp":"1.00","side":"yes","ts":"2026-07-01T02:33:18.653108Z","ts_ms":1782873198653}}

{"type":"orderbook_delta","sid":1,"seq":1088,"msg":{"market_ticker":"KXNEXTTEAMNBA-26LJAM-MIA","market_id":"492cb255-91da-4c91-bc9e-f83d090cc6dd","price_dollars":"0.0100","delta_fp":"1.00","side":"yes","ts":"2026-07-01T02:33:18.653631Z","ts_ms":1782873198653}}

{"type":"orderbook_delta","sid":1,"seq":1089,"msg":{"market_ticker":"KXNEXTTEAMNBA-26LJAM-MIA","market_id":"492cb255-91da-4c91-bc9e-f83d090cc6dd","price_dollars":"0.0100","delta_fp":"1.00","side":"yes","ts":"2026-07-01T02:33:18.654408Z","ts_ms":1782873198654}}

{"type":"orderbook_delta","sid":1,"seq":1090,"msg":{"market_ticker":"KXNEXTTEAMNBA-26LJAM-MIA","market_id":"492cb255-91da-4c91-bc9e-f83d090cc6dd","price_dollars":"0.0100","delta_fp":"1.00","side":"yes","ts":"2026-07-01T02:33:18.654935Z","ts_ms":1782873198654}}

{"type":"orderbook_delta","sid":1,"seq":1091,"msg":{"market_ticker":"KXNEXTTEAMNBA-26LJAM-MIA","market_id":"492cb255-91da-4c91-bc9e-f83d090cc6dd","price_dollars":"0.0100","delta_fp":"1.00","side":"yes","ts":"2026-07-01T02:33:18.655514Z","ts_ms":1782873198655}}

{"type":"orderbook_delta","sid":1,"seq":1092,"msg":{"market_ticker":"KXNEXTTEAMNBA-26LJAM-MIA","market_id":"492cb255-91da-4c91-bc9e-f83d090cc6dd","price_dollars":"0.0100","delta_fp":"1.00","side":"yes","ts":"2026-07-01T02:33:18.656129Z","ts_ms":1782873198656}}

{"type":"orderbook_delta","sid":1,"seq":1093,"msg":{"market_ticker":"KXNEXTTEAMNBA-26LJAM-MIA","market_id":"492cb255-91da-4c91-bc9e-f83d090cc6dd","price_dollars":"0.0100","delta_fp":"1.00","side":"yes","ts":"2026-07-01T02:33:18.656814Z","ts_ms":1782873198656}}

{"type":"orderbook_delta","sid":1,"seq":1094,"msg":{"market_ticker":"KXNEXTTEAMNBA-26LJAM-MIA","market_id":"492cb255-91da-4c91-bc9e-f83d090cc6dd","price_dollars":"0.0100","delta_fp":"1.00","side":"yes","ts":"2026-07-01T02:33:18.657398Z","ts_ms":1782873198657}}

{"type":"orderbook_delta","sid":1,"seq":1095,"msg":{"market_ticker":"KXNEXTTEAMNBA-26LJAM-MIA","market_id":"492cb255-91da-4c91-bc9e-f83d090cc6dd","price_dollars":"0.0100","delta_fp":"1.00","side":"yes","ts":"2026-07-01T02:33:18.657866Z","ts_ms":1782873198657}}

{"type":"orderbook_delta","sid":1,"seq":1096,"msg":{"market_ticker":"KXNEXTTEAMNBA-26LJAM-MIA","market_id":"492cb255-91da-4c91-bc9e-f83d090cc6dd","price_dollars":"0.0100","delta_fp":"1.00","side":"yes","ts":"2026-07-01T02:33:18.658241Z","ts_ms":1782873198658}}

{"type":"orderbook_delta","sid":1,"seq":1097,"msg":{"market_ticker":"KXNEXTTEAMNBA-26LJAM-MIA","market_id":"492cb255-91da-4c91-bc9e-f83d090cc6dd","price_dollars":"0.0100","delta_fp":"1.00","side":"yes","ts":"2026-07-01T02:33:18.658544Z","ts_ms":1782873198658}}

{"type":"orderbook_delta","sid":1,"seq":1098,"msg":{"market_ticker":"KXNEXTTEAMNBA-26LJAM-MIA","market_id":"492cb255-91da-4c91-bc9e-f83d090cc6dd","price_dollars":"0.0100","delta_fp":"1.00","side":"yes","ts":"2026-07-01T02:33:18.659169Z","ts_ms":1782873198659}}

{"type":"orderbook_delta","sid":1,"seq":1099,"msg":{"market_ticker":"KXNEXTTEAMNBA-26LJAM-MIA","market_id":"492cb255-91da-4c91-bc9e-f83d090cc6dd","price_dollars":"0.0100","delta_fp":"1.00","side":"yes","ts":"2026-07-01T02:33:18.659607Z","ts_ms":1782873198659}}

{"type":"orderbook_delta","sid":1,"seq":1100,"msg":{"market_ticker":"KXNEXTTEAMNBA-26LJAM-MIA","market_id":"492cb255-91da-4c91-bc9e-f83d090cc6dd","price_dollars":"0.0100","delta_fp":"1.00","side":"yes","ts":"2026-07-01T02:33:18.660211Z","ts_ms":1782873198660}}

{"type":"orderbook_delta","sid":1,"seq":1101,"msg":{"market_ticker":"KXNEXTTEAMNBA-26LJAM-MIA","market_id":"492cb255-91da-4c91-bc9e-f83d090cc6dd","price_dollars":"0.0100","delta_fp":"1.00","side":"yes","ts":"2026-07-01T02:33:18.660543Z","ts_ms":1782873198660}}

{"type":"orderbook_delta","sid":1,"seq":1102,"msg":{"market_ticker":"KXNEXTTEAMNBA-26LJAM-GSW","market_id":"abbbad28-f309-4dd5-af38-2ad7ebf2acc3","price_dollars":"0.0100","delta_fp":"-1.00","side":"yes","ts":"2026-07-01T02:33:19.335671Z","ts_ms":1782873199335}}

{"type":"orderbook_delta","sid":1,"seq":1103,"msg":{"market_ticker":"KXNEXTTEAMNBA-26LJAM-GSW","market_id":"abbbad28-f309-4dd5-af38-2ad7ebf2acc3","price_dollars":"0.0100","delta_fp":"-1.00","side":"yes","ts":"2026-07-01T02:33:19.336195Z","ts_ms":1782873199336}}

{"type":"orderbook_delta","sid":1,"seq":1104,"msg":{"market_ticker":"KXNEXTTEAMNBA-26LJAM-GSW","market_id":"abbbad28-f309-4dd5-af38-2ad7ebf2acc3","price_dollars":"0.0100","delta_fp":"-1.00","side":"yes","ts":"2026-07-01T02:33:19.336881Z","ts_ms":1782873199336}}

{"type":"orderbook_delta","sid":1,"seq":1105,"msg":{"market_ticker":"KXNEXTTEAMNBA-26LJAM-GSW","market_id":"abbbad28-f309-4dd5-af38-2ad7ebf2acc3","price_dollars":"0.0100","delta_fp":"-1.00","side":"yes","ts":"2026-07-01T02:33:19.337628Z","ts_ms":1782873199337}}

{"type":"orderbook_delta","sid":1,"seq":1106,"msg":{"market_ticker":"KXNEXTTEAMNBA-26LJAM-GSW","market_id":"abbbad28-f309-4dd5-af38-2ad7ebf2acc3","price_dollars":"0.0100","delta_fp":"-1.00","side":"yes","ts":"2026-07-01T02:33:19.338396Z","ts_ms":1782873199338}}

{"type":"orderbook_delta","sid":1,"seq":1107,"msg":{"market_ticker":"KXNEXTTEAMNBA-26LJAM-GSW","market_id":"abbbad28-f309-4dd5-af38-2ad7ebf2acc3","price_dollars":"0.0100","delta_fp":"-1.00","side":"yes","ts":"2026-07-01T02:33:19.339292Z","ts_ms":1782873199339}}

{"type":"orderbook_delta","sid":1,"seq":1108,"msg":{"market_ticker":"KXNEXTTEAMNBA-26LJAM-GSW","market_id":"abbbad28-f309-4dd5-af38-2ad7ebf2acc3","price_dollars":"0.0100","delta_fp":"-1.00","side":"yes","ts":"2026-07-01T02:33:19.34008Z","ts_ms":1782873199340}}

{"type":"orderbook_delta","sid":1,"seq":1109,"msg":{"market_ticker":"KXNEXTTEAMNBA-26LJAM-GSW","market_id":"abbbad28-f309-4dd5-af38-2ad7ebf2acc3","price_dollars":"0.0100","delta_fp":"-1.00","side":"yes","ts":"2026-07-01T02:33:19.340639Z","ts_ms":1782873199340}}

{"type":"orderbook_delta","sid":1,"seq":1110,"msg":{"market_ticker":"KXNEXTTEAMNBA-26LJAM-GSW","market_id":"abbbad28-f309-4dd5-af38-2ad7ebf2acc3","price_dollars":"0.0100","delta_fp":"-1.00","side":"yes","ts":"2026-07-01T02:33:19.341274Z","ts_ms":1782873199341}}

{"type":"orderbook_delta","sid":1,"seq":1111,"msg":{"market_ticker":"KXNEXTTEAMNBA-26LJAM-GSW","market_id":"abbbad28-f309-4dd5-af38-2ad7ebf2acc3","price_dollars":"0.0100","delta_fp":"-1.00","side":"yes","ts":"2026-07-01T02:33:19.341798Z","ts_ms":1782873199341}}

{"type":"orderbook_delta","sid":1,"seq":1112,"msg":{"market_ticker":"KXNEXTTEAMNBA-26LJAM-GSW","market_id":"abbbad28-f309-4dd5-af38-2ad7ebf2acc3","price_dollars":"0.0100","delta_fp":"-1.00","side":"yes","ts":"2026-07-01T02:33:19.342382Z","ts_ms":1782873199342}}

{"type":"orderbook_delta","sid":1,"seq":1113,"msg":{"market_ticker":"KXNEXTTEAMNBA-26LJAM-GSW","market_id":"abbbad28-f309-4dd5-af38-2ad7ebf2acc3","price_dollars":"0.0100","delta_fp":"-1.00","side":"yes","ts":"2026-07-01T02:33:19.343056Z","ts_ms":1782873199343}}

{"type":"orderbook_delta","sid":1,"seq":1114,"msg":{"market_ticker":"KXNEXTTEAMNBA-26LJAM-GSW","market_id":"abbbad28-f309-4dd5-af38-2ad7ebf2acc3","price_dollars":"0.0100","delta_fp":"-1.00","side":"yes","ts":"2026-07-01T02:33:19.343657Z","ts_ms":1782873199343}}

{"type":"orderbook_delta","sid":1,"seq":1115,"msg":{"market_ticker":"KXNEXTTEAMNBA-26LJAM-GSW","market_id":"abbbad28-f309-4dd5-af38-2ad7ebf2acc3","price_dollars":"0.0100","delta_fp":"-1.00","side":"yes","ts":"2026-07-01T02:33:19.344097Z","ts_ms":1782873199344}}

{"type":"orderbook_delta","sid":1,"seq":1116,"msg":{"market_ticker":"KXNEXTTEAMNBA-26LJAM-GSW","market_id":"abbbad28-f309-4dd5-af38-2ad7ebf2acc3","price_dollars":"0.0100","delta_fp":"-1.00","side":"yes","ts":"2026-07-01T02:33:19.344568Z","ts_ms":1782873199344}}

{"type":"orderbook_delta","sid":1,"seq":1117,"msg":{"market_ticker":"KXNEXTTEAMNBA-26LJAM-GSW","market_id":"abbbad28-f309-4dd5-af38-2ad7ebf2acc3","price_dollars":"0.0100","delta_fp":"-1.00","side":"yes","ts":"2026-07-01T02:33:19.345013Z","ts_ms":1782873199345}}

{"type":"orderbook_delta","sid":1,"seq":1118,"msg":{"market_ticker":"KXNEXTTEAMNBA-26LJAM-GSW","market_id":"abbbad28-f309-4dd5-af38-2ad7ebf2acc3","price_dollars":"0.0100","delta_fp":"-1.00","side":"yes","ts":"2026-07-01T02:33:19.345485Z","ts_ms":1782873199345}}

{"type":"orderbook_delta","sid":1,"seq":1119,"msg":{"market_ticker":"KXNEXTTEAMNBA-26LJAM-GSW","market_id":"abbbad28-f309-4dd5-af38-2ad7ebf2acc3","price_dollars":"0.0100","delta_fp":"-1.00","side":"yes","ts":"2026-07-01T02:33:19.345858Z","ts_ms":1782873199345}}

{"type":"orderbook_delta","sid":1,"seq":1120,"msg":{"market_ticker":"KXNEXTTEAMNBA-26LJAM-GSW","market_id":"abbbad28-f309-4dd5-af38-2ad7ebf2acc3","price_dollars":"0.0100","delta_fp":"-1.00","side":"yes","ts":"2026-07-01T02:33:19.346275Z","ts_ms":1782873199346}}

{"type":"orderbook_delta","sid":1,"seq":1121,"msg":{"market_ticker":"KXNEXTTEAMNBA-26LJAM-GSW","market_id":"abbbad28-f309-4dd5-af38-2ad7ebf2acc3","price_dollars":"0.0100","delta_fp":"-1.00","side":"yes","ts":"2026-07-01T02:33:19.346635Z","ts_ms":1782873199346}}

{"type":"orderbook_delta","sid":1,"seq":1122,"msg":{"market_ticker":"KXNEXTTEAMNBA-26LJAM-CLE","market_id":"7552b8d4-05de-4e41-84a8-97b0684da4a9","price_dollars":"0.7400","delta_fp":"-1.01","side":"no","ts":"2026-07-01T02:33:19.685584Z","ts_ms":1782873199685}}

{"type":"orderbook_delta","sid":1,"seq":1123,"msg":{"market_ticker":"KXNEXTTEAMNBA-26LJAM-MIA","market_id":"492cb255-91da-4c91-bc9e-f83d090cc6dd","price_dollars":"0.8300","delta_fp":"-0.15","side":"no","ts":"2026-07-01T02:33:19.689345Z","ts_ms":1782873199689}}

{"type":"orderbook_delta","sid":1,"seq":1124,"msg":{"market_ticker":"KXNEXTTEAMNBA-26LJAM-MIA","market_id":"492cb255-91da-4c91-bc9e-f83d090cc6dd","price_dollars":"0.0100","delta_fp":"-1.00","side":"yes","ts":"2026-07-01T02:33:20.638013Z","ts_ms":1782873200638}}

{"type":"orderbook_delta","sid":1,"seq":1125,"msg":{"market_ticker":"KXNEXTTEAMNBA-26LJAM-MIA","market_id":"492cb255-91da-4c91-bc9e-f83d090cc6dd","price_dollars":"0.0100","delta_fp":"-1.00","side":"yes","ts":"2026-07-01T02:33:20.638485Z","ts_ms":1782873200638}}

{"type":"orderbook_delta","sid":1,"seq":1126,"msg":{"market_ticker":"KXNEXTTEAMNBA-26LJAM-MIA","market_id":"492cb255-91da-4c91-bc9e-f83d090cc6dd","price_dollars":"0.0100","delta_fp":"-1.00","side":"yes","ts":"2026-07-01T02:33:20.639165Z","ts_ms":1782873200639}}

{"type":"orderbook_delta","sid":1,"seq":1127,"msg":{"market_ticker":"KXNEXTTEAMNBA-26LJAM-MIA","market_id":"492cb255-91da-4c91-bc9e-f83d090cc6dd","price_dollars":"0.0100","delta_fp":"-1.00","side":"yes","ts":"2026-07-01T02:33:20.639764Z","ts_ms":1782873200639}}

{"type":"orderbook_delta","sid":1,"seq":1128,"msg":{"market_ticker":"KXNEXTTEAMNBA-26LJAM-MIA","market_id":"492cb255-91da-4c91-bc9e-f83d090cc6dd","price_dollars":"0.0100","delta_fp":"-1.00","side":"yes","ts":"2026-07-01T02:33:20.640285Z","ts_ms":1782873200640}}

{"type":"orderbook_delta","sid":1,"seq":1129,"msg":{"market_ticker":"KXNEXTTEAMNBA-26LJAM-MIA","market_id":"492cb255-91da-4c91-bc9e-f83d090cc6dd","price_dollars":"0.0100","delta_fp":"-1.00","side":"yes","ts":"2026-07-01T02:33:20.640884Z","ts_ms":1782873200640}}

{"type":"orderbook_delta","sid":1,"seq":1130,"msg":{"market_ticker":"KXNEXTTEAMNBA-26LJAM-MIA","market_id":"492cb255-91da-4c91-bc9e-f83d090cc6dd","price_dollars":"0.0100","delta_fp":"-1.00","side":"yes","ts":"2026-07-01T02:33:20.641528Z","ts_ms":1782873200641}}

{"type":"orderbook_delta","sid":1,"seq":1131,"msg":{"market_ticker":"KXNEXTTEAMNBA-26LJAM-MIA","market_id":"492cb255-91da-4c91-bc9e-f83d090cc6dd","price_dollars":"0.0100","delta_fp":"-1.00","side":"yes","ts":"2026-07-01T02:33:20.642112Z","ts_ms":1782873200642}}

{"type":"orderbook_delta","sid":1,"seq":1132,"msg":{"market_ticker":"KXNEXTTEAMNBA-26LJAM-MIA","market_id":"492cb255-91da-4c91-bc9e-f83d090cc6dd","price_dollars":"0.0100","delta_fp":"-1.00","side":"yes","ts":"2026-07-01T02:33:20.642804Z","ts_ms":1782873200642}}

{"type":"orderbook_delta","sid":1,"seq":1133,"msg":{"market_ticker":"KXNEXTTEAMNBA-26LJAM-MIA","market_id":"492cb255-91da-4c91-bc9e-f83d090cc6dd","price_dollars":"0.0100","delta_fp":"-1.00","side":"yes","ts":"2026-07-01T02:33:20.643383Z","ts_ms":1782873200643}}

{"type":"orderbook_delta","sid":1,"seq":1134,"msg":{"market_ticker":"KXNEXTTEAMNBA-26LJAM-MIA","market_id":"492cb255-91da-4c91-bc9e-f83d090cc6dd","price_dollars":"0.0100","delta_fp":"-1.00","side":"yes","ts":"2026-07-01T02:33:20.643986Z","ts_ms":1782873200643}}

{"type":"orderbook_delta","sid":1,"seq":1135,"msg":{"market_ticker":"KXNEXTTEAMNBA-26LJAM-MIA","market_id":"492cb255-91da-4c91-bc9e-f83d090cc6dd","price_dollars":"0.0100","delta_fp":"-1.00","side":"yes","ts":"2026-07-01T02:33:20.644365Z","ts_ms":1782873200644}}

{"type":"orderbook_delta","sid":1,"seq":1136,"msg":{"market_ticker":"KXNEXTTEAMNBA-26LJAM-MIA","market_id":"492cb255-91da-4c91-bc9e-f83d090cc6dd","price_dollars":"0.0100","delta_fp":"-1.00","side":"yes","ts":"2026-07-01T02:33:20.644912Z","ts_ms":1782873200644}}

{"type":"orderbook_delta","sid":1,"seq":1137,"msg":{"market_ticker":"KXNEXTTEAMNBA-26LJAM-MIA","market_id":"492cb255-91da-4c91-bc9e-f83d090cc6dd","price_dollars":"0.0100","delta_fp":"-1.00","side":"yes","ts":"2026-07-01T02:33:20.645421Z","ts_ms":1782873200645}}

{"type":"orderbook_delta","sid":1,"seq":1138,"msg":{"market_ticker":"KXNEXTTEAMNBA-26LJAM-MIA","market_id":"492cb255-91da-4c91-bc9e-f83d090cc6dd","price_dollars":"0.0100","delta_fp":"-1.00","side":"yes","ts":"2026-07-01T02:33:20.645849Z","ts_ms":1782873200645}}

{"type":"orderbook_delta","sid":1,"seq":1139,"msg":{"market_ticker":"KXNEXTTEAMNBA-26LJAM-MIA","market_id":"492cb255-91da-4c91-bc9e-f83d090cc6dd","price_dollars":"0.0100","delta_fp":"-1.00","side":"yes","ts":"2026-07-01T02:33:20.646203Z","ts_ms":1782873200646}}

{"type":"orderbook_delta","sid":1,"seq":1140,"msg":{"market_ticker":"KXNEXTTEAMNBA-26LJAM-MIA","market_id":"492cb255-91da-4c91-bc9e-f83d090cc6dd","price_dollars":"0.0100","delta_fp":"-1.00","side":"yes","ts":"2026-07-01T02:33:20.646552Z","ts_ms":1782873200646}}

{"type":"orderbook_delta","sid":1,"seq":1141,"msg":{"market_ticker":"KXNEXTTEAMNBA-26LJAM-MIA","market_id":"492cb255-91da-4c91-bc9e-f83d090cc6dd","price_dollars":"0.0100","delta_fp":"-1.00","side":"yes","ts":"2026-07-01T02:33:20.646973Z","ts_ms":1782873200646}}

{"type":"orderbook_delta","sid":1,"seq":1142,"msg":{"market_ticker":"KXNEXTTEAMNBA-26LJAM-MIA","market_id":"492cb255-91da-4c91-bc9e-f83d090cc6dd","price_dollars":"0.0100","delta_fp":"-1.00","side":"yes","ts":"2026-07-01T02:33:20.647503Z","ts_ms":1782873200647}}

{"type":"orderbook_delta","sid":1,"seq":1143,"msg":{"market_ticker":"KXNEXTTEAMNBA-26LJAM-MIA","market_id":"492cb255-91da-4c91-bc9e-f83d090cc6dd","price_dollars":"0.0100","delta_fp":"-1.00","side":"yes","ts":"2026-07-01T02:33:20.64799Z","ts_ms":1782873200647}}

{"type":"orderbook_delta","sid":1,"seq":1144,"msg":{"market_ticker":"KXNEXTTEAMNBA-26LJAM-CLE","market_id":"7552b8d4-05de-4e41-84a8-97b0684da4a9","price_dollars":"0.7400","delta_fp":"-1.85","side":"no","ts":"2026-07-01T02:33:22.302953Z","ts_ms":1782873202302}}

{"type":"orderbook_delta","sid":1,"seq":1145,"msg":{"market_ticker":"KXNEXTTEAMNBA-26LJAM-GSW","market_id":"abbbad28-f309-4dd5-af38-2ad7ebf2acc3","price_dollars":"0.5200","delta_fp":"-1.72","side":"no","ts":"2026-07-01T02:33:22.307005Z","ts_ms":1782873202307}}

{"type":"orderbook_delta","sid":1,"seq":1146,"msg":{"market_ticker":"KXNEXTTEAMNBA-26LJAM-MIA","market_id":"492cb255-91da-4c91-bc9e-f83d090cc6dd","price_dollars":"0.8300","delta_fp":"-0.33","side":"no","ts":"2026-07-01T02:33:23.868935Z","ts_ms":1782873203868}}

{"type":"orderbook_delta","sid":1,"seq":1147,"msg":{"market_ticker":"KXNEXTTEAMNBA-26LJAM-CLE","market_id":"7552b8d4-05de-4e41-84a8-97b0684da4a9","price_dollars":"0.7400","delta_fp":"-0.48","side":"no","ts":"2026-07-01T02:33:23.962139Z","ts_ms":1782873203962}}

{"type":"orderbook_delta","sid":1,"seq":1148,"msg":{"market_ticker":"KXNEXTTEAMNBA-26LJAM-MIA","market_id":"492cb255-91da-4c91-bc9e-f83d090cc6dd","price_dollars":"0.8300","delta_fp":"-1.20","side":"no","ts":"2026-07-01T02:33:24.055364Z","ts_ms":1782873204055}}

{"type":"orderbook_delta","sid":1,"seq":1149,"msg":{"market_ticker":"KXNEXTTEAMNBA-26LJAM-GSW","market_id":"abbbad28-f309-4dd5-af38-2ad7ebf2acc3","price_dollars":"0.0100","delta_fp":"1.00","side":"yes","ts":"2026-07-01T02:33:24.526289Z","ts_ms":1782873204526}}

{"type":"orderbook_delta","sid":1,"seq":1150,"msg":{"market_ticker":"KXNEXTTEAMNBA-26LJAM-GSW","market_id":"abbbad28-f309-4dd5-af38-2ad7ebf2acc3","price_dollars":"0.0100","delta_fp":"1.00","side":"yes","ts":"2026-07-01T02:33:24.526798Z","ts_ms":1782873204526}}

{"type":"orderbook_delta","sid":1,"seq":1151,"msg":{"market_ticker":"KXNEXTTEAMNBA-26LJAM-GSW","market_id":"abbbad28-f309-4dd5-af38-2ad7ebf2acc3","price_dollars":"0.0100","delta_fp":"1.00","side":"yes","ts":"2026-07-01T02:33:24.527207Z","ts_ms":1782873204527}}

{"type":"orderbook_delta","sid":1,"seq":1152,"msg":{"market_ticker":"KXNEXTTEAMNBA-26LJAM-GSW","market_id":"abbbad28-f309-4dd5-af38-2ad7ebf2acc3","price_dollars":"0.0100","delta_fp":"1.00","side":"yes","ts":"2026-07-01T02:33:24.527608Z","ts_ms":1782873204527}}

{"type":"orderbook_delta","sid":1,"seq":1153,"msg":{"market_ticker":"KXNEXTTEAMNBA-26LJAM-GSW","market_id":"abbbad28-f309-4dd5-af38-2ad7ebf2acc3","price_dollars":"0.0100","delta_fp":"1.00","side":"yes","ts":"2026-07-01T02:33:24.528399Z","ts_ms":1782873204528}}

{"type":"orderbook_delta","sid":1,"seq":1154,"msg":{"market_ticker":"KXNEXTTEAMNBA-26LJAM-GSW","market_id":"abbbad28-f309-4dd5-af38-2ad7ebf2acc3","price_dollars":"0.0100","delta_fp":"1.00","side":"yes","ts":"2026-07-01T02:33:24.529158Z","ts_ms":1782873204529}}

{"type":"orderbook_delta","sid":1,"seq":1155,"msg":{"market_ticker":"KXNEXTTEAMNBA-26LJAM-GSW","market_id":"abbbad28-f309-4dd5-af38-2ad7ebf2acc3","price_dollars":"0.0100","delta_fp":"1.00","side":"yes","ts":"2026-07-01T02:33:24.529747Z","ts_ms":1782873204529}}

{"type":"orderbook_delta","sid":1,"seq":1156,"msg":{"market_ticker":"KXNEXTTEAMNBA-26LJAM-GSW","market_id":"abbbad28-f309-4dd5-af38-2ad7ebf2acc3","price_dollars":"0.0100","delta_fp":"1.00","side":"yes","ts":"2026-07-01T02:33:24.530674Z","ts_ms":1782873204530}}

{"type":"orderbook_delta","sid":1,"seq":1157,"msg":{"market_ticker":"KXNEXTTEAMNBA-26LJAM-GSW","market_id":"abbbad28-f309-4dd5-af38-2ad7ebf2acc3","price_dollars":"0.0100","delta_fp":"1.00","side":"yes","ts":"2026-07-01T02:33:24.531364Z","ts_ms":1782873204531}}

{"type":"orderbook_delta","sid":1,"seq":1158,"msg":{"market_ticker":"KXNEXTTEAMNBA-26LJAM-GSW","market_id":"abbbad28-f309-4dd5-af38-2ad7ebf2acc3","price_dollars":"0.0100","delta_fp":"1.00","side":"yes","ts":"2026-07-01T02:33:24.532417Z","ts_ms":1782873204532}}

{"type":"orderbook_delta","sid":1,"seq":1159,"msg":{"market_ticker":"KXNEXTTEAMNBA-26LJAM-GSW","market_id":"abbbad28-f309-4dd5-af38-2ad7ebf2acc3","price_dollars":"0.0100","delta_fp":"1.00","side":"yes","ts":"2026-07-01T02:33:24.533613Z","ts_ms":1782873204533}}

{"type":"orderbook_delta","sid":1,"seq":1160,"msg":{"market_ticker":"KXNEXTTEAMNBA-26LJAM-GSW","market_id":"abbbad28-f309-4dd5-af38-2ad7ebf2acc3","price_dollars":"0.0100","delta_fp":"1.00","side":"yes","ts":"2026-07-01T02:33:24.53474Z","ts_ms":1782873204534}}

{"type":"orderbook_delta","sid":1,"seq":1161,"msg":{"market_ticker":"KXNEXTTEAMNBA-26LJAM-GSW","market_id":"abbbad28-f309-4dd5-af38-2ad7ebf2acc3","price_dollars":"0.0100","delta_fp":"1.00","side":"yes","ts":"2026-07-01T02:33:24.535544Z","ts_ms":1782873204535}}

{"type":"orderbook_delta","sid":1,"seq":1162,"msg":{"market_ticker":"KXNEXTTEAMNBA-26LJAM-GSW","market_id":"abbbad28-f309-4dd5-af38-2ad7ebf2acc3","price_dollars":"0.0100","delta_fp":"1.00","side":"yes","ts":"2026-07-01T02:33:24.536666Z","ts_ms":1782873204536}}

{"type":"orderbook_delta","sid":1,"seq":1163,"msg":{"market_ticker":"KXNEXTTEAMNBA-26LJAM-GSW","market_id":"abbbad28-f309-4dd5-af38-2ad7ebf2acc3","price_dollars":"0.0100","delta_fp":"1.00","side":"yes","ts":"2026-07-01T02:33:24.537724Z","ts_ms":1782873204537}}

{"type":"orderbook_delta","sid":1,"seq":1164,"msg":{"market_ticker":"KXNEXTTEAMNBA-26LJAM-GSW","market_id":"abbbad28-f309-4dd5-af38-2ad7ebf2acc3","price_dollars":"0.0100","delta_fp":"1.00","side":"yes","ts":"2026-07-01T02:33:24.538454Z","ts_ms":1782873204538}}

{"type":"orderbook_delta","sid":1,"seq":1165,"msg":{"market_ticker":"KXNEXTTEAMNBA-26LJAM-GSW","market_id":"abbbad28-f309-4dd5-af38-2ad7ebf2acc3","price_dollars":"0.0100","delta_fp":"1.00","side":"yes","ts":"2026-07-01T02:33:24.539177Z","ts_ms":1782873204539}}

{"type":"orderbook_delta","sid":1,"seq":1166,"msg":{"market_ticker":"KXNEXTTEAMNBA-26LJAM-GSW","market_id":"abbbad28-f309-4dd5-af38-2ad7ebf2acc3","price_dollars":"0.0100","delta_fp":"1.00","side":"yes","ts":"2026-07-01T02:33:24.539826Z","ts_ms":1782873204539}}

{"type":"orderbook_delta","sid":1,"seq":1167,"msg":{"market_ticker":"KXNEXTTEAMNBA-26LJAM-GSW","market_id":"abbbad28-f309-4dd5-af38-2ad7ebf2acc3","price_dollars":"0.0100","delta_fp":"1.00","side":"yes","ts":"2026-07-01T02:33:24.540397Z","ts_ms":1782873204540}}

{"type":"orderbook_delta","sid":1,"seq":1168,"msg":{"market_ticker":"KXNEXTTEAMNBA-26LJAM-GSW","market_id":"abbbad28-f309-4dd5-af38-2ad7ebf2acc3","price_dollars":"0.0100","delta_fp":"1.00","side":"yes","ts":"2026-07-01T02:33:24.541112Z","ts_ms":1782873204541}}

{"type":"orderbook_delta","sid":1,"seq":1169,"msg":{"market_ticker":"KXNEXTTEAMNBA-26LJAM-CLE","market_id":"7552b8d4-05de-4e41-84a8-97b0684da4a9","price_dollars":"0.7400","delta_fp":"-1.76","side":"no","ts":"2026-07-01T02:33:24.76529Z","ts_ms":1782873204765}}

{"type":"orderbook_delta","sid":1,"seq":1170,"msg":{"market_ticker":"KXNEXTTEAMNBA-26LJAM-MIA","market_id":"492cb255-91da-4c91-bc9e-f83d090cc6dd","price_dollars":"0.8300","delta_fp":"-0.72","side":"no","ts":"2026-07-01T02:33:24.766904Z","ts_ms":1782873204766}}

{"type":"orderbook_delta","sid":1,"seq":1171,"msg":{"market_ticker":"KXNEXTTEAMNBA-26LJAM-MIA","market_id":"492cb255-91da-4c91-bc9e-f83d090cc6dd","price_dollars":"0.8300","delta_fp":"-1.65","side":"no","ts":"2026-07-01T02:33:25.657194Z","ts_ms":1782873205657}}

{"type":"orderbook_delta","sid":1,"seq":1172,"msg":{"market_ticker":"KXNEXTTEAMNBA-26LJAM-MIA","market_id":"492cb255-91da-4c91-bc9e-f83d090cc6dd","price_dollars":"0.0100","delta_fp":"1.00","side":"yes","ts":"2026-07-01T02:33:25.765556Z","ts_ms":1782873205765}}

{"type":"orderbook_delta","sid":1,"seq":1173,"msg":{"market_ticker":"KXNEXTTEAMNBA-26LJAM-MIA","market_id":"492cb255-91da-4c91-bc9e-f83d090cc6dd","price_dollars":"0.0100","delta_fp":"1.00","side":"yes","ts":"2026-07-01T02:33:25.765921Z","ts_ms":1782873205765}}

{"type":"orderbook_delta","sid":1,"seq":1174,"msg":{"market_ticker":"KXNEXTTEAMNBA-26LJAM-MIA","market_id":"492cb255-91da-4c91-bc9e-f83d090cc6dd","price_dollars":"0.0100","delta_fp":"1.00","side":"yes","ts":"2026-07-01T02:33:25.766376Z","ts_ms":1782873205766}}

{"type":"orderbook_delta","sid":1,"seq":1175,"msg":{"market_ticker":"KXNEXTTEAMNBA-26LJAM-MIA","market_id":"492cb255-91da-4c91-bc9e-f83d090cc6dd","price_dollars":"0.0100","delta_fp":"1.00","side":"yes","ts":"2026-07-01T02:33:25.76705Z","ts_ms":1782873205767}}

{"type":"orderbook_delta","sid":1,"seq":1176,"msg":{"market_ticker":"KXNEXTTEAMNBA-26LJAM-MIA","market_id":"492cb255-91da-4c91-bc9e-f83d090cc6dd","price_dollars":"0.0100","delta_fp":"1.00","side":"yes","ts":"2026-07-01T02:33:25.767524Z","ts_ms":1782873205767}}

{"type":"orderbook_delta","sid":1,"seq":1177,"msg":{"market_ticker":"KXNEXTTEAMNBA-26LJAM-MIA","market_id":"492cb255-91da-4c91-bc9e-f83d090cc6dd","price_dollars":"0.0100","delta_fp":"1.00","side":"yes","ts":"2026-07-01T02:33:25.768022Z","ts_ms":1782873205768}}

{"type":"orderbook_delta","sid":1,"seq":1178,"msg":{"market_ticker":"KXNEXTTEAMNBA-26LJAM-MIA","market_id":"492cb255-91da-4c91-bc9e-f83d090cc6dd","price_dollars":"0.0100","delta_fp":"1.00","side":"yes","ts":"2026-07-01T02:33:25.768633Z","ts_ms":1782873205768}}

{"type":"orderbook_delta","sid":1,"seq":1179,"msg":{"market_ticker":"KXNEXTTEAMNBA-26LJAM-MIA","market_id":"492cb255-91da-4c91-bc9e-f83d090cc6dd","price_dollars":"0.0100","delta_fp":"1.00","side":"yes","ts":"2026-07-01T02:33:25.769185Z","ts_ms":1782873205769}}

{"type":"orderbook_delta","sid":1,"seq":1180,"msg":{"market_ticker":"KXNEXTTEAMNBA-26LJAM-MIA","market_id":"492cb255-91da-4c91-bc9e-f83d090cc6dd","price_dollars":"0.0100","delta_fp":"1.00","side":"yes","ts":"2026-07-01T02:33:25.769643Z","ts_ms":1782873205769}}

{"type":"orderbook_delta","sid":1,"seq":1181,"msg":{"market_ticker":"KXNEXTTEAMNBA-26LJAM-MIA","market_id":"492cb255-91da-4c91-bc9e-f83d090cc6dd","price_dollars":"0.0100","delta_fp":"1.00","side":"yes","ts":"2026-07-01T02:33:25.769967Z","ts_ms":1782873205769}}

{"type":"orderbook_delta","sid":1,"seq":1182,"msg":{"market_ticker":"KXNEXTTEAMNBA-26LJAM-MIA","market_id":"492cb255-91da-4c91-bc9e-f83d090cc6dd","price_dollars":"0.0100","delta_fp":"1.00","side":"yes","ts":"2026-07-01T02:33:25.770488Z","ts_ms":1782873205770}}

{"type":"orderbook_delta","sid":1,"seq":1183,"msg":{"market_ticker":"KXNEXTTEAMNBA-26LJAM-MIA","market_id":"492cb255-91da-4c91-bc9e-f83d090cc6dd","price_dollars":"0.0100","delta_fp":"1.00","side":"yes","ts":"2026-07-01T02:33:25.770842Z","ts_ms":1782873205770}}

{"type":"orderbook_delta","sid":1,"seq":1184,"msg":{"market_ticker":"KXNEXTTEAMNBA-26LJAM-MIA","market_id":"492cb255-91da-4c91-bc9e-f83d090cc6dd","price_dollars":"0.0100","delta_fp":"1.00","side":"yes","ts":"2026-07-01T02:33:25.771163Z","ts_ms":1782873205771}}

{"type":"orderbook_delta","sid":1,"seq":1185,"msg":{"market_ticker":"KXNEXTTEAMNBA-26LJAM-MIA","market_id":"492cb255-91da-4c91-bc9e-f83d090cc6dd","price_dollars":"0.0100","delta_fp":"1.00","side":"yes","ts":"2026-07-01T02:33:25.771631Z","ts_ms":1782873205771}}

{"type":"orderbook_delta","sid":1,"seq":1186,"msg":{"market_ticker":"KXNEXTTEAMNBA-26LJAM-MIA","market_id":"492cb255-91da-4c91-bc9e-f83d090cc6dd","price_dollars":"0.0100","delta_fp":"1.00","side":"yes","ts":"2026-07-01T02:33:25.772039Z","ts_ms":1782873205772}}

{"type":"orderbook_delta","sid":1,"seq":1187,"msg":{"market_ticker":"KXNEXTTEAMNBA-26LJAM-MIA","market_id":"492cb255-91da-4c91-bc9e-f83d090cc6dd","price_dollars":"0.0100","delta_fp":"1.00","side":"yes","ts":"2026-07-01T02:33:25.772491Z","ts_ms":1782873205772}}

{"type":"orderbook_delta","sid":1,"seq":1188,"msg":{"market_ticker":"KXNEXTTEAMNBA-26LJAM-MIA","market_id":"492cb255-91da-4c91-bc9e-f83d090cc6dd","price_dollars":"0.0100","delta_fp":"1.00","side":"yes","ts":"2026-07-01T02:33:25.773Z","ts_ms":1782873205773}}

{"type":"orderbook_delta","sid":1,"seq":1189,"msg":{"market_ticker":"KXNEXTTEAMNBA-26LJAM-MIA","market_id":"492cb255-91da-4c91-bc9e-f83d090cc6dd","price_dollars":"0.0100","delta_fp":"1.00","side":"yes","ts":"2026-07-01T02:33:25.77367Z","ts_ms":1782873205773}}

{"type":"orderbook_delta","sid":1,"seq":1190,"msg":{"market_ticker":"KXNEXTTEAMNBA-26LJAM-MIA","market_id":"492cb255-91da-4c91-bc9e-f83d090cc6dd","price_dollars":"0.0100","delta_fp":"1.00","side":"yes","ts":"2026-07-01T02:33:25.774058Z","ts_ms":1782873205774}}

{"type":"orderbook_delta","sid":1,"seq":1191,"msg":{"market_ticker":"KXNEXTTEAMNBA-26LJAM-MIA","market_id":"492cb255-91da-4c91-bc9e-f83d090cc6dd","price_dollars":"0.0100","delta_fp":"1.00","side":"yes","ts":"2026-07-01T02:33:25.774473Z","ts_ms":1782873205774}}

{"type":"orderbook_delta","sid":1,"seq":1192,"msg":{"market_ticker":"KXNEXTTEAMNBA-26LJAM-GSW","market_id":"abbbad28-f309-4dd5-af38-2ad7ebf2acc3","price_dollars":"0.0100","delta_fp":"-1.00","side":"yes","ts":"2026-07-01T02:33:26.452023Z","ts_ms":1782873206452}}

{"type":"orderbook_delta","sid":1,"seq":1193,"msg":{"market_ticker":"KXNEXTTEAMNBA-26LJAM-GSW","market_id":"abbbad28-f309-4dd5-af38-2ad7ebf2acc3","price_dollars":"0.0100","delta_fp":"-1.00","side":"yes","ts":"2026-07-01T02:33:26.452731Z","ts_ms":1782873206452}}

{"type":"orderbook_delta","sid":1,"seq":1194,"msg":{"market_ticker":"KXNEXTTEAMNBA-26LJAM-GSW","market_id":"abbbad28-f309-4dd5-af38-2ad7ebf2acc3","price_dollars":"0.0100","delta_fp":"-1.00","side":"yes","ts":"2026-07-01T02:33:26.453416Z","ts_ms":1782873206453}}

{"type":"orderbook_delta","sid":1,"seq":1195,"msg":{"market_ticker":"KXNEXTTEAMNBA-26LJAM-GSW","market_id":"abbbad28-f309-4dd5-af38-2ad7ebf2acc3","price_dollars":"0.0100","delta_fp":"-1.00","side":"yes","ts":"2026-07-01T02:33:26.454306Z","ts_ms":1782873206454}}

{"type":"orderbook_delta","sid":1,"seq":1196,"msg":{"market_ticker":"KXNEXTTEAMNBA-26LJAM-GSW","market_id":"abbbad28-f309-4dd5-af38-2ad7ebf2acc3","price_dollars":"0.0100","delta_fp":"-1.00","side":"yes","ts":"2026-07-01T02:33:26.454907Z","ts_ms":1782873206454}}

{"type":"orderbook_delta","sid":1,"seq":1197,"msg":{"market_ticker":"KXNEXTTEAMNBA-26LJAM-GSW","market_id":"abbbad28-f309-4dd5-af38-2ad7ebf2acc3","price_dollars":"0.0100","delta_fp":"-1.00","side":"yes","ts":"2026-07-01T02:33:26.455592Z","ts_ms":1782873206455}}

{"type":"orderbook_delta","sid":1,"seq":1198,"msg":{"market_ticker":"KXNEXTTEAMNBA-26LJAM-GSW","market_id":"abbbad28-f309-4dd5-af38-2ad7ebf2acc3","price_dollars":"0.0100","delta_fp":"-1.00","side":"yes","ts":"2026-07-01T02:33:26.456394Z","ts_ms":1782873206456}}

{"type":"orderbook_delta","sid":1,"seq":1199,"msg":{"market_ticker":"KXNEXTTEAMNBA-26LJAM-GSW","market_id":"abbbad28-f309-4dd5-af38-2ad7ebf2acc3","price_dollars":"0.0100","delta_fp":"-1.00","side":"yes","ts":"2026-07-01T02:33:26.45737Z","ts_ms":1782873206457}}

{"type":"orderbook_delta","sid":1,"seq":1200,"msg":{"market_ticker":"KXNEXTTEAMNBA-26LJAM-GSW","market_id":"abbbad28-f309-4dd5-af38-2ad7ebf2acc3","price_dollars":"0.0100","delta_fp":"-1.00","side":"yes","ts":"2026-07-01T02:33:26.45838Z","ts_ms":1782873206458}}

{"type":"orderbook_delta","sid":1,"seq":1201,"msg":{"market_ticker":"KXNEXTTEAMNBA-26LJAM-GSW","market_id":"abbbad28-f309-4dd5-af38-2ad7ebf2acc3","price_dollars":"0.0100","delta_fp":"-1.00","side":"yes","ts":"2026-07-01T02:33:26.459076Z","ts_ms":1782873206459}}

{"type":"orderbook_delta","sid":1,"seq":1202,"msg":{"market_ticker":"KXNEXTTEAMNBA-26LJAM-GSW","market_id":"abbbad28-f309-4dd5-af38-2ad7ebf2acc3","price_dollars":"0.0100","delta_fp":"-1.00","side":"yes","ts":"2026-07-01T02:33:26.460732Z","ts_ms":1782873206460}}

{"type":"orderbook_delta","sid":1,"seq":1203,"msg":{"market_ticker":"KXNEXTTEAMNBA-26LJAM-GSW","market_id":"abbbad28-f309-4dd5-af38-2ad7ebf2acc3","price_dollars":"0.0100","delta_fp":"-1.00","side":"yes","ts":"2026-07-01T02:33:26.461395Z","ts_ms":1782873206461}}

{"type":"orderbook_delta","sid":1,"seq":1204,"msg":{"market_ticker":"KXNEXTTEAMNBA-26LJAM-GSW","market_id":"abbbad28-f309-4dd5-af38-2ad7ebf2acc3","price_dollars":"0.0100","delta_fp":"-1.00","side":"yes","ts":"2026-07-01T02:33:26.462114Z","ts_ms":1782873206462}}

{"type":"orderbook_delta","sid":1,"seq":1205,"msg":{"market_ticker":"KXNEXTTEAMNBA-26LJAM-GSW","market_id":"abbbad28-f309-4dd5-af38-2ad7ebf2acc3","price_dollars":"0.0100","delta_fp":"-1.00","side":"yes","ts":"2026-07-01T02:33:26.462718Z","ts_ms":1782873206462}}

{"type":"orderbook_delta","sid":1,"seq":1206,"msg":{"market_ticker":"KXNEXTTEAMNBA-26LJAM-GSW","market_id":"abbbad28-f309-4dd5-af38-2ad7ebf2acc3","price_dollars":"0.5200","delta_fp":"-0.38","side":"no","ts":"2026-07-01T02:33:26.463066Z","ts_ms":1782873206463}}

{"type":"orderbook_delta","sid":1,"seq":1207,"msg":{"market_ticker":"KXNEXTTEAMNBA-26LJAM-GSW","market_id":"abbbad28-f309-4dd5-af38-2ad7ebf2acc3","price_dollars":"0.0100","delta_fp":"-1.00","side":"yes","ts":"2026-07-01T02:33:26.463201Z","ts_ms":1782873206463}}

{"type":"orderbook_delta","sid":1,"seq":1208,"msg":{"market_ticker":"KXNEXTTEAMNBA-26LJAM-GSW","market_id":"abbbad28-f309-4dd5-af38-2ad7ebf2acc3","price_dollars":"0.0100","delta_fp":"-1.00","side":"yes","ts":"2026-07-01T02:33:26.46367Z","ts_ms":1782873206463}}

{"type":"orderbook_delta","sid":1,"seq":1209,"msg":{"market_ticker":"KXNEXTTEAMNBA-26LJAM-GSW","market_id":"abbbad28-f309-4dd5-af38-2ad7ebf2acc3","price_dollars":"0.0100","delta_fp":"-1.00","side":"yes","ts":"2026-07-01T02:33:26.464096Z","ts_ms":1782873206464}}

{"type":"orderbook_delta","sid":1,"seq":1210,"msg":{"market_ticker":"KXNEXTTEAMNBA-26LJAM-GSW","market_id":"abbbad28-f309-4dd5-af38-2ad7ebf2acc3","price_dollars":"0.0100","delta_fp":"-1.00","side":"yes","ts":"2026-07-01T02:33:26.464461Z","ts_ms":1782873206464}}

{"type":"orderbook_delta","sid":1,"seq":1211,"msg":{"market_ticker":"KXNEXTTEAMNBA-26LJAM-GSW","market_id":"abbbad28-f309-4dd5-af38-2ad7ebf2acc3","price_dollars":"0.0100","delta_fp":"-1.00","side":"yes","ts":"2026-07-01T02:33:26.464785Z","ts_ms":1782873206464}}

{"type":"orderbook_delta","sid":1,"seq":1212,"msg":{"market_ticker":"KXNEXTTEAMNBA-26LJAM-GSW","market_id":"abbbad28-f309-4dd5-af38-2ad7ebf2acc3","price_dollars":"0.0100","delta_fp":"-1.00","side":"yes","ts":"2026-07-01T02:33:26.465322Z","ts_ms":1782873206465}}

{"type":"orderbook_delta","sid":1,"seq":1213,"msg":{"market_ticker":"KXNEXTTEAMNBA-26LJAM-GSW","market_id":"abbbad28-f309-4dd5-af38-2ad7ebf2acc3","price_dollars":"0.5200","delta_fp":"-1.84","side":"no","ts":"2026-07-01T02:33:26.470399Z","ts_ms":1782873206470}}

{"type":"orderbook_delta","sid":1,"seq":1214,"msg":{"market_ticker":"KXNEXTTEAMNBA-26LJAM-MIA","market_id":"492cb255-91da-4c91-bc9e-f83d090cc6dd","price_dollars":"0.8300","delta_fp":"-0.93","side":"no","ts":"2026-07-01T02:33:26.482412Z","ts_ms":1782873206482}}

{"type":"orderbook_delta","sid":1,"seq":1215,"msg":{"market_ticker":"KXNEXTTEAMNBA-26LJAM-CLE","market_id":"7552b8d4-05de-4e41-84a8-97b0684da4a9","price_dollars":"0.7400","delta_fp":"-0.72","side":"no","ts":"2026-07-01T02:33:26.558876Z","ts_ms":1782873206558}}

{"type":"orderbook_delta","sid":1,"seq":1216,"msg":{"market_ticker":"KXNEXTTEAMNBA-26LJAM-GSW","market_id":"abbbad28-f309-4dd5-af38-2ad7ebf2acc3","price_dollars":"0.5200","delta_fp":"-694.44","side":"no","ts":"2026-07-01T02:33:27.269197Z","ts_ms":1782873207269}}

{"type":"orderbook_delta","sid":1,"seq":1217,"msg":{"market_ticker":"KXNEXTTEAMNBA-26LJAM-GSW","market_id":"abbbad28-f309-4dd5-af38-2ad7ebf2acc3","price_dollars":"0.5100","delta_fp":"-680.27","side":"no","ts":"2026-07-01T02:33:27.269197Z","ts_ms":1782873207269}}

{"type":"orderbook_delta","sid":1,"seq":1218,"msg":{"market_ticker":"KXNEXTTEAMNBA-26LJAM-GSW","market_id":"abbbad28-f309-4dd5-af38-2ad7ebf2acc3","price_dollars":"0.5000","delta_fp":"-666.66","side":"no","ts":"2026-07-01T02:33:27.269197Z","ts_ms":1782873207269}}

{"type":"orderbook_delta","sid":1,"seq":1219,"msg":{"market_ticker":"KXNEXTTEAMNBA-26LJAM-GSW","market_id":"abbbad28-f309-4dd5-af38-2ad7ebf2acc3","price_dollars":"0.5200","delta_fp":"-0.47","side":"no","ts":"2026-07-01T02:33:28.087157Z","ts_ms":1782873208087}}

{"type":"orderbook_delta","sid":1,"seq":1220,"msg":{"market_ticker":"KXNEXTTEAMNBA-26LJAM-CLE","market_id":"7552b8d4-05de-4e41-84a8-97b0684da4a9","price_dollars":"0.7400","delta_fp":"-0.12","side":"no","ts":"2026-07-01T02:33:28.093037Z","ts_ms":1782873208093}}

{"type":"orderbook_delta","sid":1,"seq":1221,"msg":{"market_ticker":"KXNEXTTEAMNBA-26LJAM-GSW","market_id":"abbbad28-f309-4dd5-af38-2ad7ebf2acc3","price_dollars":"0.5200","delta_fp":"-1.07","side":"no","ts":"2026-07-01T02:33:29.585456Z","ts_ms":1782873209585}}

{"type":"orderbook_delta","sid":1,"seq":1222,"msg":{"market_ticker":"KXNEXTTEAMNBA-26LJAM-GSW","market_id":"abbbad28-f309-4dd5-af38-2ad7ebf2acc3","price_dollars":"0.5200","delta_fp":"-1.52","side":"no","ts":"2026-07-01T02:33:29.800903Z","ts_ms":1782873209800}}

{"type":"orderbook_delta","sid":1,"seq":1223,"msg":{"market_ticker":"KXNEXTTEAMNBA-26LJAM-MIA","market_id":"492cb255-91da-4c91-bc9e-f83d090cc6dd","price_dollars":"0.8300","delta_fp":"-1.48","side":"no","ts":"2026-07-01T02:33:29.853678Z","ts_ms":1782873209853}}

{"type":"orderbook_delta","sid":1,"seq":1224,"msg":{"market_ticker":"KXNEXTTEAMNBA-26LJAM-CLE","market_id":"7552b8d4-05de-4e41-84a8-97b0684da4a9","price_dollars":"0.7400","delta_fp":"-1.62","side":"no","ts":"2026-07-01T02:33:29.853819Z","ts_ms":1782873209853}}

{"type":"orderbook_delta","sid":1,"seq":1225,"msg":{"market_ticker":"KXNEXTTEAMNBA-26LJAM-GSW","market_id":"abbbad28-f309-4dd5-af38-2ad7ebf2acc3","price_dollars":"0.5200","delta_fp":"-1.96","side":"no","ts":"2026-07-01T02:33:31.482432Z","ts_ms":1782873211482}}

{"type":"orderbook_delta","sid":1,"seq":1226,"msg":{"market_ticker":"KXNEXTTEAMNBA-26LJAM-GSW","market_id":"abbbad28-f309-4dd5-af38-2ad7ebf2acc3","price_dollars":"0.5200","delta_fp":"-1.26","side":"no","ts":"2026-07-01T02:33:31.497258Z","ts_ms":1782873211497}}

{"type":"orderbook_delta","sid":1,"seq":1227,"msg":{"market_ticker":"KXNEXTTEAMNBA-26LJAM-MIA","market_id":"492cb255-91da-4c91-bc9e-f83d090cc6dd","price_dollars":"0.0100","delta_fp":"1.00","side":"yes","ts":"2026-07-01T02:33:32.452017Z","ts_ms":1782873212452}}

{"type":"orderbook_delta","sid":1,"seq":1228,"msg":{"market_ticker":"KXNEXTTEAMNBA-26LJAM-MIA","market_id":"492cb255-91da-4c91-bc9e-f83d090cc6dd","price_dollars":"0.0100","delta_fp":"1.00","side":"yes","ts":"2026-07-01T02:33:32.452559Z","ts_ms":1782873212452}}

{"type":"orderbook_delta","sid":1,"seq":1229,"msg":{"market_ticker":"KXNEXTTEAMNBA-26LJAM-MIA","market_id":"492cb255-91da-4c91-bc9e-f83d090cc6dd","price_dollars":"0.0100","delta_fp":"1.00","side":"yes","ts":"2026-07-01T02:33:32.453153Z","ts_ms":1782873212453}}

{"type":"orderbook_delta","sid":1,"seq":1230,"msg":{"market_ticker":"KXNEXTTEAMNBA-26LJAM-MIA","market_id":"492cb255-91da-4c91-bc9e-f83d090cc6dd","price_dollars":"0.0100","delta_fp":"1.00","side":"yes","ts":"2026-07-01T02:33:32.453641Z","ts_ms":1782873212453}}

{"type":"orderbook_delta","sid":1,"seq":1231,"msg":{"market_ticker":"KXNEXTTEAMNBA-26LJAM-MIA","market_id":"492cb255-91da-4c91-bc9e-f83d090cc6dd","price_dollars":"0.0100","delta_fp":"1.00","side":"yes","ts":"2026-07-01T02:33:32.454168Z","ts_ms":1782873212454}}

{"type":"orderbook_delta","sid":1,"seq":1232,"msg":{"market_ticker":"KXNEXTTEAMNBA-26LJAM-MIA","market_id":"492cb255-91da-4c91-bc9e-f83d090cc6dd","price_dollars":"0.0100","delta_fp":"1.00","side":"yes","ts":"2026-07-01T02:33:32.454654Z","ts_ms":1782873212454}}

{"type":"orderbook_delta","sid":1,"seq":1233,"msg":{"market_ticker":"KXNEXTTEAMNBA-26LJAM-MIA","market_id":"492cb255-91da-4c91-bc9e-f83d090cc6dd","price_dollars":"0.0100","delta_fp":"1.00","side":"yes","ts":"2026-07-01T02:33:32.455034Z","ts_ms":1782873212455}}

{"type":"orderbook_delta","sid":1,"seq":1234,"msg":{"market_ticker":"KXNEXTTEAMNBA-26LJAM-MIA","market_id":"492cb255-91da-4c91-bc9e-f83d090cc6dd","price_dollars":"0.0100","delta_fp":"1.00","side":"yes","ts":"2026-07-01T02:33:32.455508Z","ts_ms":1782873212455}}

{"type":"orderbook_delta","sid":1,"seq":1235,"msg":{"market_ticker":"KXNEXTTEAMNBA-26LJAM-MIA","market_id":"492cb255-91da-4c91-bc9e-f83d090cc6dd","price_dollars":"0.0100","delta_fp":"1.00","side":"yes","ts":"2026-07-01T02:33:32.456092Z","ts_ms":1782873212456}}

{"type":"orderbook_delta","sid":1,"seq":1236,"msg":{"market_ticker":"KXNEXTTEAMNBA-26LJAM-MIA","market_id":"492cb255-91da-4c91-bc9e-f83d090cc6dd","price_dollars":"0.0100","delta_fp":"1.00","side":"yes","ts":"2026-07-01T02:33:32.456758Z","ts_ms":1782873212456}}

{"type":"orderbook_delta","sid":1,"seq":1237,"msg":{"market_ticker":"KXNEXTTEAMNBA-26LJAM-MIA","market_id":"492cb255-91da-4c91-bc9e-f83d090cc6dd","price_dollars":"0.0100","delta_fp":"1.00","side":"yes","ts":"2026-07-01T02:33:32.457077Z","ts_ms":1782873212457}}

{"type":"orderbook_delta","sid":1,"seq":1238,"msg":{"market_ticker":"KXNEXTTEAMNBA-26LJAM-MIA","market_id":"492cb255-91da-4c91-bc9e-f83d090cc6dd","price_dollars":"0.0100","delta_fp":"1.00","side":"yes","ts":"2026-07-01T02:33:32.457373Z","ts_ms":1782873212457}}

{"type":"orderbook_delta","sid":1,"seq":1239,"msg":{"market_ticker":"KXNEXTTEAMNBA-26LJAM-MIA","market_id":"492cb255-91da-4c91-bc9e-f83d090cc6dd","price_dollars":"0.0100","delta_fp":"1.00","side":"yes","ts":"2026-07-01T02:33:32.457748Z","ts_ms":1782873212457}}

{"type":"orderbook_delta","sid":1,"seq":1240,"msg":{"market_ticker":"KXNEXTTEAMNBA-26LJAM-MIA","market_id":"492cb255-91da-4c91-bc9e-f83d090cc6dd","price_dollars":"0.0100","delta_fp":"1.00","side":"yes","ts":"2026-07-01T02:33:32.458179Z","ts_ms":1782873212458}}

{"type":"orderbook_delta","sid":1,"seq":1241,"msg":{"market_ticker":"KXNEXTTEAMNBA-26LJAM-MIA","market_id":"492cb255-91da-4c91-bc9e-f83d090cc6dd","price_dollars":"0.0100","delta_fp":"1.00","side":"yes","ts":"2026-07-01T02:33:32.458586Z","ts_ms":1782873212458}}

{"type":"orderbook_delta","sid":1,"seq":1242,"msg":{"market_ticker":"KXNEXTTEAMNBA-26LJAM-MIA","market_id":"492cb255-91da-4c91-bc9e-f83d090cc6dd","price_dollars":"0.0100","delta_fp":"1.00","side":"yes","ts":"2026-07-01T02:33:32.4589Z","ts_ms":1782873212458}}

{"type":"orderbook_delta","sid":1,"seq":1243,"msg":{"market_ticker":"KXNEXTTEAMNBA-26LJAM-MIA","market_id":"492cb255-91da-4c91-bc9e-f83d090cc6dd","price_dollars":"0.0100","delta_fp":"1.00","side":"yes","ts":"2026-07-01T02:33:32.459316Z","ts_ms":1782873212459}}

{"type":"orderbook_delta","sid":1,"seq":1244,"msg":{"market_ticker":"KXNEXTTEAMNBA-26LJAM-MIA","market_id":"492cb255-91da-4c91-bc9e-f83d090cc6dd","price_dollars":"0.0100","delta_fp":"1.00","side":"yes","ts":"2026-07-01T02:33:32.459769Z","ts_ms":1782873212459}}

{"type":"orderbook_delta","sid":1,"seq":1245,"msg":{"market_ticker":"KXNEXTTEAMNBA-26LJAM-MIA","market_id":"492cb255-91da-4c91-bc9e-f83d090cc6dd","price_dollars":"0.0100","delta_fp":"1.00","side":"yes","ts":"2026-07-01T02:33:32.460243Z","ts_ms":1782873212460}}

{"type":"orderbook_delta","sid":1,"seq":1246,"msg":{"market_ticker":"KXNEXTTEAMNBA-26LJAM-MIA","market_id":"492cb255-91da-4c91-bc9e-f83d090cc6dd","price_dollars":"0.0100","delta_fp":"1.00","side":"yes","ts":"2026-07-01T02:33:32.460551Z","ts_ms":1782873212460}}

{"type":"orderbook_delta","sid":1,"seq":1247,"msg":{"market_ticker":"KXNEXTTEAMNBA-26LJAM-GSW","market_id":"abbbad28-f309-4dd5-af38-2ad7ebf2acc3","price_dollars":"0.5200","delta_fp":"-1.76","side":"no","ts":"2026-07-01T02:33:33.004226Z","ts_ms":1782873213004}}

{"type":"orderbook_delta","sid":1,"seq":1248,"msg":{"market_ticker":"KXNEXTTEAMNBA-26LJAM-MIA","market_id":"492cb255-91da-4c91-bc9e-f83d090cc6dd","price_dollars":"0.8300","delta_fp":"-1.78","side":"no","ts":"2026-07-01T02:33:33.061645Z","ts_ms":1782873213061}}

{"type":"orderbook_delta","sid":1,"seq":1249,"msg":{"market_ticker":"KXNEXTTEAMNBA-26LJAM-MIA","market_id":"492cb255-91da-4c91-bc9e-f83d090cc6dd","price_dollars":"0.8300","delta_fp":"-1.65","side":"no","ts":"2026-07-01T02:33:33.099948Z","ts_ms":1782873213099}}

{"type":"orderbook_delta","sid":1,"seq":1250,"msg":{"market_ticker":"KXNEXTTEAMNBA-26LJAM-GSW","market_id":"abbbad28-f309-4dd5-af38-2ad7ebf2acc3","price_dollars":"0.4700","delta_fp":"709.21","side":"yes","ts":"2026-07-01T02:33:33.130781Z","ts_ms":1782873213130}}

{"type":"orderbook_delta","sid":1,"seq":1251,"msg":{"market_ticker":"KXNEXTTEAMNBA-26LJAM-GSW","market_id":"abbbad28-f309-4dd5-af38-2ad7ebf2acc3","price_dollars":"0.4600","delta_fp":"724.63","side":"yes","ts":"2026-07-01T02:33:33.131355Z","ts_ms":1782873213131}}

{"type":"orderbook_delta","sid":1,"seq":1252,"msg":{"market_ticker":"KXNEXTTEAMNBA-26LJAM-GSW","market_id":"abbbad28-f309-4dd5-af38-2ad7ebf2acc3","price_dollars":"0.4500","delta_fp":"740.74","side":"yes","ts":"2026-07-01T02:33:33.132497Z","ts_ms":1782873213132}}

{"type":"orderbook_delta","sid":1,"seq":1253,"msg":{"market_ticker":"KXNEXTTEAMNBA-26LJAM-GSW","market_id":"abbbad28-f309-4dd5-af38-2ad7ebf2acc3","price_dollars":"0.5200","delta_fp":"-0.14","side":"no","ts":"2026-07-01T02:33:33.175908Z","ts_ms":1782873213175}}

{"type":"orderbook_delta","sid":1,"seq":1254,"msg":{"market_ticker":"KXNEXTTEAMNBA-26LJAM-CLE","market_id":"7552b8d4-05de-4e41-84a8-97b0684da4a9","price_dollars":"0.7400","delta_fp":"-1.84","side":"no","ts":"2026-07-01T02:33:36.08735Z","ts_ms":1782873216087}}

{"type":"orderbook_delta","sid":1,"seq":1255,"msg":{"market_ticker":"KXNEXTTEAMNBA-26LJAM-MIA","market_id":"492cb255-91da-4c91-bc9e-f83d090cc6dd","price_dollars":"0.8300","delta_fp":"-0.58","side":"no","ts":"2026-07-01T02:33:36.386141Z","ts_ms":1782873216386}}

{"type":"orderbook_delta","sid":1,"seq":1256,"msg":{"market_ticker":"KXNEXTTEAMNBA-26LJAM-GSW","market_id":"abbbad28-f309-4dd5-af38-2ad7ebf2acc3","price_dollars":"0.5200","delta_fp":"-0.80","side":"no","ts":"2026-07-01T02:33:38.157136Z","ts_ms":1782873218157}}

{"type":"orderbook_delta","sid":1,"seq":1257,"msg":{"market_ticker":"KXNEXTTEAMNBA-26LJAM-CLE","market_id":"7552b8d4-05de-4e41-84a8-97b0684da4a9","price_dollars":"0.7400","delta_fp":"-1.81","side":"no","ts":"2026-07-01T02:33:38.158401Z","ts_ms":1782873218158}}

{"type":"orderbook_delta","sid":1,"seq":1258,"msg":{"market_ticker":"KXNEXTTEAMNBA-26LJAM-CLE","market_id":"7552b8d4-05de-4e41-84a8-97b0684da4a9","price_dollars":"0.7400","delta_fp":"-396.87","side":"no","ts":"2026-07-01T02:33:38.435312Z","ts_ms":1782873218435}}

{"type":"orderbook_delta","sid":1,"seq":1259,"msg":{"market_ticker":"KXNEXTTEAMNBA-26LJAM-CLE","market_id":"7552b8d4-05de-4e41-84a8-97b0684da4a9","price_dollars":"0.7300","delta_fp":"-1234.56","side":"no","ts":"2026-07-01T02:33:38.435312Z","ts_ms":1782873218435}}

{"type":"orderbook_delta","sid":1,"seq":1260,"msg":{"market_ticker":"KXNEXTTEAMNBA-26LJAM-CLE","market_id":"7552b8d4-05de-4e41-84a8-97b0684da4a9","price_dollars":"0.7200","delta_fp":"-1190.47","side":"no","ts":"2026-07-01T02:33:38.435312Z","ts_ms":1782873218435}}

{"type":"orderbook_delta","sid":1,"seq":1261,"msg":{"market_ticker":"KXNEXTTEAMNBA-26LJAM-CLE","market_id":"7552b8d4-05de-4e41-84a8-97b0684da4a9","price_dollars":"0.7400","delta_fp":"-1282.05","side":"no","ts":"2026-07-01T02:33:38.435312Z","ts_ms":1782873218435}}

{"type":"orderbook_delta","sid":1,"seq":1262,"msg":{"market_ticker":"KXNEXTTEAMNBA-26LJAM-CLE","market_id":"7552b8d4-05de-4e41-84a8-97b0684da4a9","price_dollars":"0.7300","delta_fp":"-1234.56","side":"no","ts":"2026-07-01T02:33:38.435312Z","ts_ms":1782873218435}}

{"type":"orderbook_delta","sid":1,"seq":1263,"msg":{"market_ticker":"KXNEXTTEAMNBA-26LJAM-CLE","market_id":"7552b8d4-05de-4e41-84a8-97b0684da4a9","price_dollars":"0.7200","delta_fp":"-1190.47","side":"no","ts":"2026-07-01T02:33:38.435312Z","ts_ms":1782873218435}}

{"type":"orderbook_delta","sid":1,"seq":1264,"msg":{"market_ticker":"KXNEXTTEAMNBA-26LJAM-MIA","market_id":"492cb255-91da-4c91-bc9e-f83d090cc6dd","price_dollars":"0.0100","delta_fp":"1.00","side":"yes","ts":"2026-07-01T02:33:39.025361Z","ts_ms":1782873219025}}

{"type":"orderbook_delta","sid":1,"seq":1265,"msg":{"market_ticker":"KXNEXTTEAMNBA-26LJAM-MIA","market_id":"492cb255-91da-4c91-bc9e-f83d090cc6dd","price_dollars":"0.0100","delta_fp":"1.00","side":"yes","ts":"2026-07-01T02:33:39.025819Z","ts_ms":1782873219025}}

{"type":"orderbook_delta","sid":1,"seq":1266,"msg":{"market_ticker":"KXNEXTTEAMNBA-26LJAM-MIA","market_id":"492cb255-91da-4c91-bc9e-f83d090cc6dd","price_dollars":"0.0100","delta_fp":"1.00","side":"yes","ts":"2026-07-01T02:33:39.026256Z","ts_ms":1782873219026}}

{"type":"orderbook_delta","sid":1,"seq":1267,"msg":{"market_ticker":"KXNEXTTEAMNBA-26LJAM-MIA","market_id":"492cb255-91da-4c91-bc9e-f83d090cc6dd","price_dollars":"0.0100","delta_fp":"1.00","side":"yes","ts":"2026-07-01T02:33:39.026837Z","ts_ms":1782873219026}}

{"type":"orderbook_delta","sid":1,"seq":1268,"msg":{"market_ticker":"KXNEXTTEAMNBA-26LJAM-MIA","market_id":"492cb255-91da-4c91-bc9e-f83d090cc6dd","price_dollars":"0.0100","delta_fp":"1.00","side":"yes","ts":"2026-07-01T02:33:39.027284Z","ts_ms":1782873219027}}

{"type":"orderbook_delta","sid":1,"seq":1269,"msg":{"market_ticker":"KXNEXTTEAMNBA-26LJAM-MIA","market_id":"492cb255-91da-4c91-bc9e-f83d090cc6dd","price_dollars":"0.0100","delta_fp":"1.00","side":"yes","ts":"2026-07-01T02:33:39.027791Z","ts_ms":1782873219027}}

{"type":"orderbook_delta","sid":1,"seq":1270,"msg":{"market_ticker":"KXNEXTTEAMNBA-26LJAM-MIA","market_id":"492cb255-91da-4c91-bc9e-f83d090cc6dd","price_dollars":"0.0100","delta_fp":"1.00","side":"yes","ts":"2026-07-01T02:33:39.028326Z","ts_ms":1782873219028}}

{"type":"orderbook_delta","sid":1,"seq":1271,"msg":{"market_ticker":"KXNEXTTEAMNBA-26LJAM-MIA","market_id":"492cb255-91da-4c91-bc9e-f83d090cc6dd","price_dollars":"0.0100","delta_fp":"1.00","side":"yes","ts":"2026-07-01T02:33:39.028793Z","ts_ms":1782873219028}}

{"type":"orderbook_delta","sid":1,"seq":1272,"msg":{"market_ticker":"KXNEXTTEAMNBA-26LJAM-MIA","market_id":"492cb255-91da-4c91-bc9e-f83d090cc6dd","price_dollars":"0.0100","delta_fp":"1.00","side":"yes","ts":"2026-07-01T02:33:39.029265Z","ts_ms":1782873219029}}

{"type":"orderbook_delta","sid":1,"seq":1273,"msg":{"market_ticker":"KXNEXTTEAMNBA-26LJAM-MIA","market_id":"492cb255-91da-4c91-bc9e-f83d090cc6dd","price_dollars":"0.0100","delta_fp":"1.00","side":"yes","ts":"2026-07-01T02:33:39.029798Z","ts_ms":1782873219029}}

{"type":"orderbook_delta","sid":1,"seq":1274,"msg":{"market_ticker":"KXNEXTTEAMNBA-26LJAM-MIA","market_id":"492cb255-91da-4c91-bc9e-f83d090cc6dd","price_dollars":"0.0100","delta_fp":"1.00","side":"yes","ts":"2026-07-01T02:33:39.030233Z","ts_ms":1782873219030}}

{"type":"orderbook_delta","sid":1,"seq":1275,"msg":{"market_ticker":"KXNEXTTEAMNBA-26LJAM-MIA","market_id":"492cb255-91da-4c91-bc9e-f83d090cc6dd","price_dollars":"0.0100","delta_fp":"1.00","side":"yes","ts":"2026-07-01T02:33:39.030954Z","ts_ms":1782873219030}}

{"type":"orderbook_delta","sid":1,"seq":1276,"msg":{"market_ticker":"KXNEXTTEAMNBA-26LJAM-MIA","market_id":"492cb255-91da-4c91-bc9e-f83d090cc6dd","price_dollars":"0.0100","delta_fp":"1.00","side":"yes","ts":"2026-07-01T02:33:39.031318Z","ts_ms":1782873219031}}

{"type":"orderbook_delta","sid":1,"seq":1277,"msg":{"market_ticker":"KXNEXTTEAMNBA-26LJAM-MIA","market_id":"492cb255-91da-4c91-bc9e-f83d090cc6dd","price_dollars":"0.0100","delta_fp":"1.00","side":"yes","ts":"2026-07-01T02:33:39.031809Z","ts_ms":1782873219031}}

{"type":"orderbook_delta","sid":1,"seq":1278,"msg":{"market_ticker":"KXNEXTTEAMNBA-26LJAM-MIA","market_id":"492cb255-91da-4c91-bc9e-f83d090cc6dd","price_dollars":"0.0100","delta_fp":"1.00","side":"yes","ts":"2026-07-01T02:33:39.032113Z","ts_ms":1782873219032}}

{"type":"orderbook_delta","sid":1,"seq":1279,"msg":{"market_ticker":"KXNEXTTEAMNBA-26LJAM-MIA","market_id":"492cb255-91da-4c91-bc9e-f83d090cc6dd","price_dollars":"0.0100","delta_fp":"1.00","side":"yes","ts":"2026-07-01T02:33:39.032662Z","ts_ms":1782873219032}}

{"type":"orderbook_delta","sid":1,"seq":1280,"msg":{"market_ticker":"KXNEXTTEAMNBA-26LJAM-MIA","market_id":"492cb255-91da-4c91-bc9e-f83d090cc6dd","price_dollars":"0.0100","delta_fp":"1.00","side":"yes","ts":"2026-07-01T02:33:39.033165Z","ts_ms":1782873219033}}

{"type":"orderbook_delta","sid":1,"seq":1281,"msg":{"market_ticker":"KXNEXTTEAMNBA-26LJAM-MIA","market_id":"492cb255-91da-4c91-bc9e-f83d090cc6dd","price_dollars":"0.0100","delta_fp":"1.00","side":"yes","ts":"2026-07-01T02:33:39.033478Z","ts_ms":1782873219033}}

{"type":"orderbook_delta","sid":1,"seq":1282,"msg":{"market_ticker":"KXNEXTTEAMNBA-26LJAM-MIA","market_id":"492cb255-91da-4c91-bc9e-f83d090cc6dd","price_dollars":"0.0100","delta_fp":"1.00","side":"yes","ts":"2026-07-01T02:33:39.034Z","ts_ms":1782873219034}}

{"type":"orderbook_delta","sid":1,"seq":1283,"msg":{"market_ticker":"KXNEXTTEAMNBA-26LJAM-MIA","market_id":"492cb255-91da-4c91-bc9e-f83d090cc6dd","price_dollars":"0.0100","delta_fp":"1.00","side":"yes","ts":"2026-07-01T02:33:39.034561Z","ts_ms":1782873219034}}

{"type":"orderbook_delta","sid":1,"seq":1284,"msg":{"market_ticker":"KXNEXTTEAMNBA-26LJAM-CLE","market_id":"7552b8d4-05de-4e41-84a8-97b0684da4a9","price_dollars":"0.7400","delta_fp":"-1.45","side":"no","ts":"2026-07-01T02:33:39.763544Z","ts_ms":1782873219763}}

{"type":"orderbook_delta","sid":1,"seq":1285,"msg":{"market_ticker":"KXNEXTTEAMNBA-26LJAM-MIA","market_id":"492cb255-91da-4c91-bc9e-f83d090cc6dd","price_dollars":"0.8300","delta_fp":"-1.98","side":"no","ts":"2026-07-01T02:33:39.79489Z","ts_ms":1782873219794}}

{"type":"orderbook_delta","sid":1,"seq":1286,"msg":{"market_ticker":"KXNEXTTEAMNBA-26LJAM-GSW","market_id":"abbbad28-f309-4dd5-af38-2ad7ebf2acc3","price_dollars":"0.4700","delta_fp":"709.21","side":"yes","ts":"2026-07-01T02:33:39.820217Z","ts_ms":1782873219820}}

{"type":"orderbook_delta","sid":1,"seq":1287,"msg":{"market_ticker":"KXNEXTTEAMNBA-26LJAM-GSW","market_id":"abbbad28-f309-4dd5-af38-2ad7ebf2acc3","price_dollars":"0.4600","delta_fp":"724.63","side":"yes","ts":"2026-07-01T02:33:39.820793Z","ts_ms":1782873219820}}

{"type":"orderbook_delta","sid":1,"seq":1288,"msg":{"market_ticker":"KXNEXTTEAMNBA-26LJAM-GSW","market_id":"abbbad28-f309-4dd5-af38-2ad7ebf2acc3","price_dollars":"0.4500","delta_fp":"740.74","side":"yes","ts":"2026-07-01T02:33:39.821264Z","ts_ms":1782873219821}}

{"type":"orderbook_delta","sid":1,"seq":1289,"msg":{"market_ticker":"KXNEXTTEAMNBA-26LJAM-GSW","market_id":"abbbad28-f309-4dd5-af38-2ad7ebf2acc3","price_dollars":"0.5200","delta_fp":"-0.27","side":"no","ts":"2026-07-01T02:33:41.299346Z","ts_ms":1782873221299}}

{"type":"orderbook_delta","sid":1,"seq":1290,"msg":{"market_ticker":"KXNEXTTEAMNBA-26LJAM-CLE","market_id":"7552b8d4-05de-4e41-84a8-97b0684da4a9","price_dollars":"0.7400","delta_fp":"-1.30","side":"no","ts":"2026-07-01T02:33:43.082141Z","ts_ms":1782873223082}}

{"type":"orderbook_delta","sid":1,"seq":1291,"msg":{"market_ticker":"KXNEXTTEAMNBA-26LJAM-GSW","market_id":"abbbad28-f309-4dd5-af38-2ad7ebf2acc3","price_dollars":"0.5200","delta_fp":"-0.12","side":"no","ts":"2026-07-01T02:33:44.690096Z","ts_ms":1782873224690}}

{"type":"orderbook_delta","sid":1,"seq":1292,"msg":{"market_ticker":"KXNEXTTEAMNBA-26LJAM-GSW","market_id":"abbbad28-f309-4dd5-af38-2ad7ebf2acc3","price_dollars":"0.5200","delta_fp":"694.44","side":"no","ts":"2026-07-01T02:33:46.969141Z","ts_ms":1782873226969}}

{"type":"orderbook_delta","sid":1,"seq":1293,"msg":{"market_ticker":"KXNEXTTEAMNBA-26LJAM-GSW","market_id":"abbbad28-f309-4dd5-af38-2ad7ebf2acc3","price_dollars":"0.5100","delta_fp":"680.27","side":"no","ts":"2026-07-01T02:33:46.969559Z","ts_ms":1782873226969}}

{"type":"orderbook_delta","sid":1,"seq":1294,"msg":{"market_ticker":"KXNEXTTEAMNBA-26LJAM-GSW","market_id":"abbbad28-f309-4dd5-af38-2ad7ebf2acc3","price_dollars":"0.5000","delta_fp":"666.66","side":"no","ts":"2026-07-01T02:33:46.970079Z","ts_ms":1782873226970}}

{"type":"orderbook_delta","sid":1,"seq":1295,"msg":{"market_ticker":"KXNEXTTEAMNBA-26LJAM-GSW","market_id":"abbbad28-f309-4dd5-af38-2ad7ebf2acc3","price_dollars":"0.5200","delta_fp":"-1.72","side":"no","ts":"2026-07-01T02:33:47.97858Z","ts_ms":1782873227978}}

{"type":"orderbook_delta","sid":1,"seq":1296,"msg":{"market_ticker":"KXNEXTTEAMNBA-26LJAM-MIA","market_id":"492cb255-91da-4c91-bc9e-f83d090cc6dd","price_dollars":"0.8300","delta_fp":"-0.85","side":"no","ts":"2026-07-01T02:33:48.066732Z","ts_ms":1782873228066}}

{"type":"orderbook_delta","sid":1,"seq":1297,"msg":{"market_ticker":"KXNEXTTEAMNBA-26LJAM-CLE","market_id":"7552b8d4-05de-4e41-84a8-97b0684da4a9","price_dollars":"0.7400","delta_fp":"-0.74","side":"no","ts":"2026-07-01T02:33:48.077597Z","ts_ms":1782873228077}}

{"type":"orderbook_delta","sid":1,"seq":1298,"msg":{"market_ticker":"KXNEXTTEAMNBA-26LJAM-MIA","market_id":"492cb255-91da-4c91-bc9e-f83d090cc6dd","price_dollars":"0.1600","delta_fp":"2083.33","side":"yes","ts":"2026-07-01T02:33:48.238361Z","ts_ms":1782873228238}}

{"type":"orderbook_delta","sid":1,"seq":1299,"msg":{"market_ticker":"KXNEXTTEAMNBA-26LJAM-MIA","market_id":"492cb255-91da-4c91-bc9e-f83d090cc6dd","price_dollars":"0.1500","delta_fp":"2222.22","side":"yes","ts":"2026-07-01T02:33:48.238973Z","ts_ms":1782873228238}}

{"type":"orderbook_delta","sid":1,"seq":1300,"msg":{"market_ticker":"KXNEXTTEAMNBA-26LJAM-MIA","market_id":"492cb255-91da-4c91-bc9e-f83d090cc6dd","price_dollars":"0.1400","delta_fp":"2380.95","side":"yes","ts":"2026-07-01T02:33:48.239698Z","ts_ms":1782873228239}}

{"type":"orderbook_delta","sid":1,"seq":1301,"msg":{"market_ticker":"KXNEXTTEAMNBA-26LJAM-MIA","market_id":"492cb255-91da-4c91-bc9e-f83d090cc6dd","price_dollars":"0.8300","delta_fp":"1960.78","side":"no","ts":"2026-07-01T02:33:48.24031Z","ts_ms":1782873228240}}

{"type":"orderbook_delta","sid":1,"seq":1302,"msg":{"market_ticker":"KXNEXTTEAMNBA-26LJAM-MIA","market_id":"492cb255-91da-4c91-bc9e-f83d090cc6dd","price_dollars":"0.8200","delta_fp":"1851.85","side":"no","ts":"2026-07-01T02:33:48.241089Z","ts_ms":1782873228241}}

{"type":"orderbook_delta","sid":1,"seq":1303,"msg":{"market_ticker":"KXNEXTTEAMNBA-26LJAM-MIA","market_id":"492cb255-91da-4c91-bc9e-f83d090cc6dd","price_dollars":"0.8100","delta_fp":"1754.38","side":"no","ts":"2026-07-01T02:33:48.241735Z","ts_ms":1782873228241}}

{"type":"orderbook_delta","sid":1,"seq":1304,"msg":{"market_ticker":"KXNEXTTEAMNBA-26LJAM-MIA","market_id":"492cb255-91da-4c91-bc9e-f83d090cc6dd","price_dollars":"0.8300","delta_fp":"-1.99","side":"no","ts":"2026-07-01T02:33:51.069418Z","ts_ms":1782873231069}}

{"type":"orderbook_delta","sid":1,"seq":1305,"msg":{"market_ticker":"KXNEXTTEAMNBA-26LJAM-CLE","market_id":"7552b8d4-05de-4e41-84a8-97b0684da4a9","price_dollars":"0.7400","delta_fp":"-1.37","side":"no","ts":"2026-07-01T02:33:51.368289Z","ts_ms":1782873231368}}

{"type":"orderbook_delta","sid":1,"seq":1306,"msg":{"market_ticker":"KXNEXTTEAMNBA-26LJAM-GSW","market_id":"abbbad28-f309-4dd5-af38-2ad7ebf2acc3","price_dollars":"0.0100","delta_fp":"1.00","side":"yes","ts":"2026-07-01T02:33:51.634951Z","ts_ms":1782873231634}}

{"type":"orderbook_delta","sid":1,"seq":1307,"msg":{"market_ticker":"KXNEXTTEAMNBA-26LJAM-GSW","market_id":"abbbad28-f309-4dd5-af38-2ad7ebf2acc3","price_dollars":"0.0100","delta_fp":"1.00","side":"yes","ts":"2026-07-01T02:33:51.635538Z","ts_ms":1782873231635}}

{"type":"orderbook_delta","sid":1,"seq":1308,"msg":{"market_ticker":"KXNEXTTEAMNBA-26LJAM-GSW","market_id":"abbbad28-f309-4dd5-af38-2ad7ebf2acc3","price_dollars":"0.0100","delta_fp":"1.00","side":"yes","ts":"2026-07-01T02:33:51.636112Z","ts_ms":1782873231636}}

{"type":"orderbook_delta","sid":1,"seq":1309,"msg":{"market_ticker":"KXNEXTTEAMNBA-26LJAM-GSW","market_id":"abbbad28-f309-4dd5-af38-2ad7ebf2acc3","price_dollars":"0.0100","delta_fp":"1.00","side":"yes","ts":"2026-07-01T02:33:51.636863Z","ts_ms":1782873231636}}

{"type":"orderbook_delta","sid":1,"seq":1310,"msg":{"market_ticker":"KXNEXTTEAMNBA-26LJAM-GSW","market_id":"abbbad28-f309-4dd5-af38-2ad7ebf2acc3","price_dollars":"0.0100","delta_fp":"1.00","side":"yes","ts":"2026-07-01T02:33:51.63733Z","ts_ms":1782873231637}}

{"type":"orderbook_delta","sid":1,"seq":1311,"msg":{"market_ticker":"KXNEXTTEAMNBA-26LJAM-GSW","market_id":"abbbad28-f309-4dd5-af38-2ad7ebf2acc3","price_dollars":"0.0100","delta_fp":"1.00","side":"yes","ts":"2026-07-01T02:33:51.637742Z","ts_ms":1782873231637}}

{"type":"orderbook_delta","sid":1,"seq":1312,"msg":{"market_ticker":"KXNEXTTEAMNBA-26LJAM-GSW","market_id":"abbbad28-f309-4dd5-af38-2ad7ebf2acc3","price_dollars":"0.0100","delta_fp":"1.00","side":"yes","ts":"2026-07-01T02:33:51.63884Z","ts_ms":1782873231638}}

{"type":"orderbook_delta","sid":1,"seq":1313,"msg":{"market_ticker":"KXNEXTTEAMNBA-26LJAM-GSW","market_id":"abbbad28-f309-4dd5-af38-2ad7ebf2acc3","price_dollars":"0.0100","delta_fp":"1.00","side":"yes","ts":"2026-07-01T02:33:51.63969Z","ts_ms":1782873231639}}

{"type":"orderbook_delta","sid":1,"seq":1314,"msg":{"market_ticker":"KXNEXTTEAMNBA-26LJAM-GSW","market_id":"abbbad28-f309-4dd5-af38-2ad7ebf2acc3","price_dollars":"0.0100","delta_fp":"1.00","side":"yes","ts":"2026-07-01T02:33:51.640265Z","ts_ms":1782873231640}}

{"type":"orderbook_delta","sid":1,"seq":1315,"msg":{"market_ticker":"KXNEXTTEAMNBA-26LJAM-GSW","market_id":"abbbad28-f309-4dd5-af38-2ad7ebf2acc3","price_dollars":"0.0100","delta_fp":"1.00","side":"yes","ts":"2026-07-01T02:33:51.641219Z","ts_ms":1782873231641}}

{"type":"orderbook_delta","sid":1,"seq":1316,"msg":{"market_ticker":"KXNEXTTEAMNBA-26LJAM-GSW","market_id":"abbbad28-f309-4dd5-af38-2ad7ebf2acc3","price_dollars":"0.0100","delta_fp":"1.00","side":"yes","ts":"2026-07-01T02:33:51.641998Z","ts_ms":1782873231641}}

{"type":"orderbook_delta","sid":1,"seq":1317,"msg":{"market_ticker":"KXNEXTTEAMNBA-26LJAM-GSW","market_id":"abbbad28-f309-4dd5-af38-2ad7ebf2acc3","price_dollars":"0.0100","delta_fp":"1.00","side":"yes","ts":"2026-07-01T02:33:51.642698Z","ts_ms":1782873231642}}

{"type":"orderbook_delta","sid":1,"seq":1318,"msg":{"market_ticker":"KXNEXTTEAMNBA-26LJAM-GSW","market_id":"abbbad28-f309-4dd5-af38-2ad7ebf2acc3","price_dollars":"0.0100","delta_fp":"1.00","side":"yes","ts":"2026-07-01T02:33:51.64336Z","ts_ms":1782873231643}}

{"type":"orderbook_delta","sid":1,"seq":1319,"msg":{"market_ticker":"KXNEXTTEAMNBA-26LJAM-GSW","market_id":"abbbad28-f309-4dd5-af38-2ad7ebf2acc3","price_dollars":"0.0100","delta_fp":"1.00","side":"yes","ts":"2026-07-01T02:33:51.643714Z","ts_ms":1782873231643}}

{"type":"orderbook_delta","sid":1,"seq":1320,"msg":{"market_ticker":"KXNEXTTEAMNBA-26LJAM-GSW","market_id":"abbbad28-f309-4dd5-af38-2ad7ebf2acc3","price_dollars":"0.0100","delta_fp":"1.00","side":"yes","ts":"2026-07-01T02:33:51.644561Z","ts_ms":1782873231644}}

{"type":"orderbook_delta","sid":1,"seq":1321,"msg":{"market_ticker":"KXNEXTTEAMNBA-26LJAM-GSW","market_id":"abbbad28-f309-4dd5-af38-2ad7ebf2acc3","price_dollars":"0.0100","delta_fp":"1.00","side":"yes","ts":"2026-07-01T02:33:51.645061Z","ts_ms":1782873231645}}

{"type":"orderbook_delta","sid":1,"seq":1322,"msg":{"market_ticker":"KXNEXTTEAMNBA-26LJAM-GSW","market_id":"abbbad28-f309-4dd5-af38-2ad7ebf2acc3","price_dollars":"0.0100","delta_fp":"1.00","side":"yes","ts":"2026-07-01T02:33:51.645728Z","ts_ms":1782873231645}}

{"type":"orderbook_delta","sid":1,"seq":1323,"msg":{"market_ticker":"KXNEXTTEAMNBA-26LJAM-GSW","market_id":"abbbad28-f309-4dd5-af38-2ad7ebf2acc3","price_dollars":"0.0100","delta_fp":"1.00","side":"yes","ts":"2026-07-01T02:33:51.646575Z","ts_ms":1782873231646}}

{"type":"orderbook_delta","sid":1,"seq":1324,"msg":{"market_ticker":"KXNEXTTEAMNBA-26LJAM-GSW","market_id":"abbbad28-f309-4dd5-af38-2ad7ebf2acc3","price_dollars":"0.0100","delta_fp":"1.00","side":"yes","ts":"2026-07-01T02:33:51.647192Z","ts_ms":1782873231647}}

{"type":"orderbook_delta","sid":1,"seq":1325,"msg":{"market_ticker":"KXNEXTTEAMNBA-26LJAM-GSW","market_id":"abbbad28-f309-4dd5-af38-2ad7ebf2acc3","price_dollars":"0.0100","delta_fp":"1.00","side":"yes","ts":"2026-07-01T02:33:51.64772Z","ts_ms":1782873231647}}

{"type":"orderbook_delta","sid":1,"seq":1326,"msg":{"market_ticker":"KXNEXTTEAMNBA-26LJAM-GSW","market_id":"abbbad28-f309-4dd5-af38-2ad7ebf2acc3","price_dollars":"0.5200","delta_fp":"-0.23","side":"no","ts":"2026-07-01T02:33:52.168704Z","ts_ms":1782873232168}}

{"type":"orderbook_delta","sid":1,"seq":1327,"msg":{"market_ticker":"KXNEXTTEAMNBA-26LJAM-MIA","market_id":"492cb255-91da-4c91-bc9e-f83d090cc6dd","price_dollars":"0.0100","delta_fp":"1.00","side":"yes","ts":"2026-07-01T02:33:52.718953Z","ts_ms":1782873232718}}

{"type":"orderbook_delta","sid":1,"seq":1328,"msg":{"market_ticker":"KXNEXTTEAMNBA-26LJAM-MIA","market_id":"492cb255-91da-4c91-bc9e-f83d090cc6dd","price_dollars":"0.0100","delta_fp":"1.00","side":"yes","ts":"2026-07-01T02:33:52.71956Z","ts_ms":1782873232719}}

{"type":"orderbook_delta","sid":1,"seq":1329,"msg":{"market_ticker":"KXNEXTTEAMNBA-26LJAM-MIA","market_id":"492cb255-91da-4c91-bc9e-f83d090cc6dd","price_dollars":"0.0100","delta_fp":"1.00","side":"yes","ts":"2026-07-01T02:33:52.720228Z","ts_ms":1782873232720}}

{"type":"orderbook_delta","sid":1,"seq":1330,"msg":{"market_ticker":"KXNEXTTEAMNBA-26LJAM-MIA","market_id":"492cb255-91da-4c91-bc9e-f83d090cc6dd","price_dollars":"0.0100","delta_fp":"1.00","side":"yes","ts":"2026-07-01T02:33:52.720875Z","ts_ms":1782873232720}}

{"type":"orderbook_delta","sid":1,"seq":1331,"msg":{"market_ticker":"KXNEXTTEAMNBA-26LJAM-MIA","market_id":"492cb255-91da-4c91-bc9e-f83d090cc6dd","price_dollars":"0.0100","delta_fp":"1.00","side":"yes","ts":"2026-07-01T02:33:52.721512Z","ts_ms":1782873232721}}

{"type":"orderbook_delta","sid":1,"seq":1332,"msg":{"market_ticker":"KXNEXTTEAMNBA-26LJAM-MIA","market_id":"492cb255-91da-4c91-bc9e-f83d090cc6dd","price_dollars":"0.0100","delta_fp":"1.00","side":"yes","ts":"2026-07-01T02:33:52.722161Z","ts_ms":1782873232722}}

{"type":"orderbook_delta","sid":1,"seq":1333,"msg":{"market_ticker":"KXNEXTTEAMNBA-26LJAM-MIA","market_id":"492cb255-91da-4c91-bc9e-f83d090cc6dd","price_dollars":"0.0100","delta_fp":"1.00","side":"yes","ts":"2026-07-01T02:33:52.722602Z","ts_ms":1782873232722}}

{"type":"orderbook_delta","sid":1,"seq":1334,"msg":{"market_ticker":"KXNEXTTEAMNBA-26LJAM-MIA","market_id":"492cb255-91da-4c91-bc9e-f83d090cc6dd","price_dollars":"0.0100","delta_fp":"1.00","side":"yes","ts":"2026-07-01T02:33:52.723183Z","ts_ms":1782873232723}}

{"type":"orderbook_delta","sid":1,"seq":1335,"msg":{"market_ticker":"KXNEXTTEAMNBA-26LJAM-MIA","market_id":"492cb255-91da-4c91-bc9e-f83d090cc6dd","price_dollars":"0.0100","delta_fp":"1.00","side":"yes","ts":"2026-07-01T02:33:52.723522Z","ts_ms":1782873232723}}

{"type":"orderbook_delta","sid":1,"seq":1336,"msg":{"market_ticker":"KXNEXTTEAMNBA-26LJAM-MIA","market_id":"492cb255-91da-4c91-bc9e-f83d090cc6dd","price_dollars":"0.0100","delta_fp":"1.00","side":"yes","ts":"2026-07-01T02:33:52.72393Z","ts_ms":1782873232723}}

{"type":"orderbook_delta","sid":1,"seq":1337,"msg":{"market_ticker":"KXNEXTTEAMNBA-26LJAM-MIA","market_id":"492cb255-91da-4c91-bc9e-f83d090cc6dd","price_dollars":"0.0100","delta_fp":"1.00","side":"yes","ts":"2026-07-01T02:33:52.724417Z","ts_ms":1782873232724}}

{"type":"orderbook_delta","sid":1,"seq":1338,"msg":{"market_ticker":"KXNEXTTEAMNBA-26LJAM-MIA","market_id":"492cb255-91da-4c91-bc9e-f83d090cc6dd","price_dollars":"0.0100","delta_fp":"1.00","side":"yes","ts":"2026-07-01T02:33:52.724804Z","ts_ms":1782873232724}}

{"type":"orderbook_delta","sid":1,"seq":1339,"msg":{"market_ticker":"KXNEXTTEAMNBA-26LJAM-MIA","market_id":"492cb255-91da-4c91-bc9e-f83d090cc6dd","price_dollars":"0.0100","delta_fp":"1.00","side":"yes","ts":"2026-07-01T02:33:52.725095Z","ts_ms":1782873232725}}

{"type":"orderbook_delta","sid":1,"seq":1340,"msg":{"market_ticker":"KXNEXTTEAMNBA-26LJAM-MIA","market_id":"492cb255-91da-4c91-bc9e-f83d090cc6dd","price_dollars":"0.0100","delta_fp":"1.00","side":"yes","ts":"2026-07-01T02:33:52.725511Z","ts_ms":1782873232725}}

{"type":"orderbook_delta","sid":1,"seq":1341,"msg":{"market_ticker":"KXNEXTTEAMNBA-26LJAM-MIA","market_id":"492cb255-91da-4c91-bc9e-f83d090cc6dd","price_dollars":"0.0100","delta_fp":"1.00","side":"yes","ts":"2026-07-01T02:33:52.725853Z","ts_ms":1782873232725}}

{"type":"orderbook_delta","sid":1,"seq":1342,"msg":{"market_ticker":"KXNEXTTEAMNBA-26LJAM-MIA","market_id":"492cb255-91da-4c91-bc9e-f83d090cc6dd","price_dollars":"0.0100","delta_fp":"1.00","side":"yes","ts":"2026-07-01T02:33:52.726312Z","ts_ms":1782873232726}}

{"type":"orderbook_delta","sid":1,"seq":1343,"msg":{"market_ticker":"KXNEXTTEAMNBA-26LJAM-MIA","market_id":"492cb255-91da-4c91-bc9e-f83d090cc6dd","price_dollars":"0.0100","delta_fp":"1.00","side":"yes","ts":"2026-07-01T02:33:52.726844Z","ts_ms":1782873232726}}

{"type":"orderbook_delta","sid":1,"seq":1344,"msg":{"market_ticker":"KXNEXTTEAMNBA-26LJAM-MIA","market_id":"492cb255-91da-4c91-bc9e-f83d090cc6dd","price_dollars":"0.0100","delta_fp":"1.00","side":"yes","ts":"2026-07-01T02:33:52.72729Z","ts_ms":1782873232727}}

{"type":"orderbook_delta","sid":1,"seq":1345,"msg":{"market_ticker":"KXNEXTTEAMNBA-26LJAM-MIA","market_id":"492cb255-91da-4c91-bc9e-f83d090cc6dd","price_dollars":"0.0100","delta_fp":"1.00","side":"yes","ts":"2026-07-01T02:33:52.727566Z","ts_ms":1782873232727}}

{"type":"orderbook_delta","sid":1,"seq":1346,"msg":{"market_ticker":"KXNEXTTEAMNBA-26LJAM-MIA","market_id":"492cb255-91da-4c91-bc9e-f83d090cc6dd","price_dollars":"0.0100","delta_fp":"1.00","side":"yes","ts":"2026-07-01T02:33:52.728032Z","ts_ms":1782873232728}}

{"type":"orderbook_delta","sid":1,"seq":1347,"msg":{"market_ticker":"KXNEXTTEAMNBA-26LJAM-CLE","market_id":"7552b8d4-05de-4e41-84a8-97b0684da4a9","price_dollars":"0.7400","delta_fp":"-1.14","side":"no","ts":"2026-07-01T02:33:52.986829Z","ts_ms":1782873232986}}

{"type":"orderbook_delta","sid":1,"seq":1348,"msg":{"market_ticker":"KXNEXTTEAMNBA-26LJAM-MIA","market_id":"492cb255-91da-4c91-bc9e-f83d090cc6dd","price_dollars":"0.8300","delta_fp":"-0.91","side":"no","ts":"2026-07-01T02:33:52.992192Z","ts_ms":1782873232992}}

{"type":"orderbook_delta","sid":1,"seq":1349,"msg":{"market_ticker":"KXNEXTTEAMNBA-26LJAM-GSW","market_id":"abbbad28-f309-4dd5-af38-2ad7ebf2acc3","price_dollars":"0.0100","delta_fp":"-1.00","side":"yes","ts":"2026-07-01T02:33:53.352426Z","ts_ms":1782873233352}}

{"type":"orderbook_delta","sid":1,"seq":1350,"msg":{"market_ticker":"KXNEXTTEAMNBA-26LJAM-GSW","market_id":"abbbad28-f309-4dd5-af38-2ad7ebf2acc3","price_dollars":"0.0100","delta_fp":"-1.00","side":"yes","ts":"2026-07-01T02:33:53.352735Z","ts_ms":1782873233352}}

{"type":"orderbook_delta","sid":1,"seq":1351,"msg":{"market_ticker":"KXNEXTTEAMNBA-26LJAM-GSW","market_id":"abbbad28-f309-4dd5-af38-2ad7ebf2acc3","price_dollars":"0.0100","delta_fp":"-1.00","side":"yes","ts":"2026-07-01T02:33:53.353104Z","ts_ms":1782873233353}}

{"type":"orderbook_delta","sid":1,"seq":1352,"msg":{"market_ticker":"KXNEXTTEAMNBA-26LJAM-GSW","market_id":"abbbad28-f309-4dd5-af38-2ad7ebf2acc3","price_dollars":"0.0100","delta_fp":"-1.00","side":"yes","ts":"2026-07-01T02:33:53.353632Z","ts_ms":1782873233353}}

{"type":"orderbook_delta","sid":1,"seq":1353,"msg":{"market_ticker":"KXNEXTTEAMNBA-26LJAM-GSW","market_id":"abbbad28-f309-4dd5-af38-2ad7ebf2acc3","price_dollars":"0.0100","delta_fp":"-1.00","side":"yes","ts":"2026-07-01T02:33:53.354119Z","ts_ms":1782873233354}}

{"type":"orderbook_delta","sid":1,"seq":1354,"msg":{"market_ticker":"KXNEXTTEAMNBA-26LJAM-GSW","market_id":"abbbad28-f309-4dd5-af38-2ad7ebf2acc3","price_dollars":"0.0100","delta_fp":"-1.00","side":"yes","ts":"2026-07-01T02:33:53.354701Z","ts_ms":1782873233354}}

{"type":"orderbook_delta","sid":1,"seq":1355,"msg":{"market_ticker":"KXNEXTTEAMNBA-26LJAM-GSW","market_id":"abbbad28-f309-4dd5-af38-2ad7ebf2acc3","price_dollars":"0.0100","delta_fp":"-1.00","side":"yes","ts":"2026-07-01T02:33:53.355376Z","ts_ms":1782873233355}}

{"type":"orderbook_delta","sid":1,"seq":1356,"msg":{"market_ticker":"KXNEXTTEAMNBA-26LJAM-GSW","market_id":"abbbad28-f309-4dd5-af38-2ad7ebf2acc3","price_dollars":"0.0100","delta_fp":"-1.00","side":"yes","ts":"2026-07-01T02:33:53.356249Z","ts_ms":1782873233356}}

{"type":"orderbook_delta","sid":1,"seq":1357,"msg":{"market_ticker":"KXNEXTTEAMNBA-26LJAM-GSW","market_id":"abbbad28-f309-4dd5-af38-2ad7ebf2acc3","price_dollars":"0.0100","delta_fp":"-1.00","side":"yes","ts":"2026-07-01T02:33:53.35682Z","ts_ms":1782873233356}}

{"type":"orderbook_delta","sid":1,"seq":1358,"msg":{"market_ticker":"KXNEXTTEAMNBA-26LJAM-GSW","market_id":"abbbad28-f309-4dd5-af38-2ad7ebf2acc3","price_dollars":"0.0100","delta_fp":"-1.00","side":"yes","ts":"2026-07-01T02:33:53.357673Z","ts_ms":1782873233357}}

{"type":"orderbook_delta","sid":1,"seq":1359,"msg":{"market_ticker":"KXNEXTTEAMNBA-26LJAM-GSW","market_id":"abbbad28-f309-4dd5-af38-2ad7ebf2acc3","price_dollars":"0.0100","delta_fp":"-1.00","side":"yes","ts":"2026-07-01T02:33:53.358311Z","ts_ms":1782873233358}}

{"type":"orderbook_delta","sid":1,"seq":1360,"msg":{"market_ticker":"KXNEXTTEAMNBA-26LJAM-GSW","market_id":"abbbad28-f309-4dd5-af38-2ad7ebf2acc3","price_dollars":"0.0100","delta_fp":"-1.00","side":"yes","ts":"2026-07-01T02:33:53.359177Z","ts_ms":1782873233359}}

{"type":"orderbook_delta","sid":1,"seq":1361,"msg":{"market_ticker":"KXNEXTTEAMNBA-26LJAM-GSW","market_id":"abbbad28-f309-4dd5-af38-2ad7ebf2acc3","price_dollars":"0.0100","delta_fp":"-1.00","side":"yes","ts":"2026-07-01T02:33:53.359976Z","ts_ms":1782873233359}}

{"type":"orderbook_delta","sid":1,"seq":1362,"msg":{"market_ticker":"KXNEXTTEAMNBA-26LJAM-GSW","market_id":"abbbad28-f309-4dd5-af38-2ad7ebf2acc3","price_dollars":"0.0100","delta_fp":"-1.00","side":"yes","ts":"2026-07-01T02:33:53.360532Z","ts_ms":1782873233360}}

{"type":"orderbook_delta","sid":1,"seq":1363,"msg":{"market_ticker":"KXNEXTTEAMNBA-26LJAM-GSW","market_id":"abbbad28-f309-4dd5-af38-2ad7ebf2acc3","price_dollars":"0.0100","delta_fp":"-1.00","side":"yes","ts":"2026-07-01T02:33:53.361156Z","ts_ms":1782873233361}}

{"type":"orderbook_delta","sid":1,"seq":1364,"msg":{"market_ticker":"KXNEXTTEAMNBA-26LJAM-GSW","market_id":"abbbad28-f309-4dd5-af38-2ad7ebf2acc3","price_dollars":"0.0100","delta_fp":"-1.00","side":"yes","ts":"2026-07-01T02:33:53.36189Z","ts_ms":1782873233361}}

{"type":"orderbook_delta","sid":1,"seq":1365,"msg":{"market_ticker":"KXNEXTTEAMNBA-26LJAM-GSW","market_id":"abbbad28-f309-4dd5-af38-2ad7ebf2acc3","price_dollars":"0.0100","delta_fp":"-1.00","side":"yes","ts":"2026-07-01T02:33:53.362463Z","ts_ms":1782873233362}}

{"type":"orderbook_delta","sid":1,"seq":1366,"msg":{"market_ticker":"KXNEXTTEAMNBA-26LJAM-GSW","market_id":"abbbad28-f309-4dd5-af38-2ad7ebf2acc3","price_dollars":"0.0100","delta_fp":"-1.00","side":"yes","ts":"2026-07-01T02:33:53.3631Z","ts_ms":1782873233363}}

{"type":"orderbook_delta","sid":1,"seq":1367,"msg":{"market_ticker":"KXNEXTTEAMNBA-26LJAM-GSW","market_id":"abbbad28-f309-4dd5-af38-2ad7ebf2acc3","price_dollars":"0.0100","delta_fp":"-1.00","side":"yes","ts":"2026-07-01T02:33:53.363764Z","ts_ms":1782873233363}}

{"type":"orderbook_delta","sid":1,"seq":1368,"msg":{"market_ticker":"KXNEXTTEAMNBA-26LJAM-GSW","market_id":"abbbad28-f309-4dd5-af38-2ad7ebf2acc3","price_dollars":"0.0100","delta_fp":"-1.00","side":"yes","ts":"2026-07-01T02:33:53.364271Z","ts_ms":1782873233364}}

{"type":"orderbook_delta","sid":1,"seq":1369,"msg":{"market_ticker":"KXNEXTTEAMNBA-26LJAM-GSW","market_id":"abbbad28-f309-4dd5-af38-2ad7ebf2acc3","price_dollars":"0.5200","delta_fp":"-0.39","side":"no","ts":"2026-07-01T02:33:54.654994Z","ts_ms":1782873234654}}

{"type":"orderbook_delta","sid":1,"seq":1370,"msg":{"market_ticker":"KXNEXTTEAMNBA-26LJAM-MIA","market_id":"492cb255-91da-4c91-bc9e-f83d090cc6dd","price_dollars":"0.0100","delta_fp":"-1.00","side":"yes","ts":"2026-07-01T02:33:54.656121Z","ts_ms":1782873234656}}

{"type":"orderbook_delta","sid":1,"seq":1371,"msg":{"market_ticker":"KXNEXTTEAMNBA-26LJAM-MIA","market_id":"492cb255-91da-4c91-bc9e-f83d090cc6dd","price_dollars":"0.0100","delta_fp":"-1.00","side":"yes","ts":"2026-07-01T02:33:54.656588Z","ts_ms":1782873234656}}

{"type":"orderbook_delta","sid":1,"seq":1372,"msg":{"market_ticker":"KXNEXTTEAMNBA-26LJAM-MIA","market_id":"492cb255-91da-4c91-bc9e-f83d090cc6dd","price_dollars":"0.0100","delta_fp":"-1.00","side":"yes","ts":"2026-07-01T02:33:54.657068Z","ts_ms":1782873234657}}

{"type":"orderbook_delta","sid":1,"seq":1373,"msg":{"market_ticker":"KXNEXTTEAMNBA-26LJAM-MIA","market_id":"492cb255-91da-4c91-bc9e-f83d090cc6dd","price_dollars":"0.0100","delta_fp":"-1.00","side":"yes","ts":"2026-07-01T02:33:54.657768Z","ts_ms":1782873234657}}

{"type":"orderbook_delta","sid":1,"seq":1374,"msg":{"market_ticker":"KXNEXTTEAMNBA-26LJAM-MIA","market_id":"492cb255-91da-4c91-bc9e-f83d090cc6dd","price_dollars":"0.0100","delta_fp":"-1.00","side":"yes","ts":"2026-07-01T02:33:54.658439Z","ts_ms":1782873234658}}

{"type":"orderbook_delta","sid":1,"seq":1375,"msg":{"market_ticker":"KXNEXTTEAMNBA-26LJAM-MIA","market_id":"492cb255-91da-4c91-bc9e-f83d090cc6dd","price_dollars":"0.0100","delta_fp":"-1.00","side":"yes","ts":"2026-07-01T02:33:54.658913Z","ts_ms":1782873234658}}

{"type":"orderbook_delta","sid":1,"seq":1376,"msg":{"market_ticker":"KXNEXTTEAMNBA-26LJAM-MIA","market_id":"492cb255-91da-4c91-bc9e-f83d090cc6dd","price_dollars":"0.0100","delta_fp":"-1.00","side":"yes","ts":"2026-07-01T02:33:54.659399Z","ts_ms":1782873234659}}

{"type":"orderbook_delta","sid":1,"seq":1377,"msg":{"market_ticker":"KXNEXTTEAMNBA-26LJAM-MIA","market_id":"492cb255-91da-4c91-bc9e-f83d090cc6dd","price_dollars":"0.0100","delta_fp":"-1.00","side":"yes","ts":"2026-07-01T02:33:54.65983Z","ts_ms":1782873234659}}

{"type":"orderbook_delta","sid":1,"seq":1378,"msg":{"market_ticker":"KXNEXTTEAMNBA-26LJAM-MIA","market_id":"492cb255-91da-4c91-bc9e-f83d090cc6dd","price_dollars":"0.0100","delta_fp":"-1.00","side":"yes","ts":"2026-07-01T02:33:54.660316Z","ts_ms":1782873234660}}

{"type":"orderbook_delta","sid":1,"seq":1379,"msg":{"market_ticker":"KXNEXTTEAMNBA-26LJAM-MIA","market_id":"492cb255-91da-4c91-bc9e-f83d090cc6dd","price_dollars":"0.0100","delta_fp":"-1.00","side":"yes","ts":"2026-07-01T02:33:54.660662Z","ts_ms":1782873234660}}

{"type":"orderbook_delta","sid":1,"seq":1380,"msg":{"market_ticker":"KXNEXTTEAMNBA-26LJAM-MIA","market_id":"492cb255-91da-4c91-bc9e-f83d090cc6dd","price_dollars":"0.0100","delta_fp":"-1.00","side":"yes","ts":"2026-07-01T02:33:54.661265Z","ts_ms":1782873234661}}

{"type":"orderbook_delta","sid":1,"seq":1381,"msg":{"market_ticker":"KXNEXTTEAMNBA-26LJAM-MIA","market_id":"492cb255-91da-4c91-bc9e-f83d090cc6dd","price_dollars":"0.0100","delta_fp":"-1.00","side":"yes","ts":"2026-07-01T02:33:54.661847Z","ts_ms":1782873234661}}

{"type":"orderbook_delta","sid":1,"seq":1382,"msg":{"market_ticker":"KXNEXTTEAMNBA-26LJAM-CLE","market_id":"7552b8d4-05de-4e41-84a8-97b0684da4a9","price_dollars":"0.7400","delta_fp":"-0.87","side":"no","ts":"2026-07-01T02:33:54.66214Z","ts_ms":1782873234662}}

{"type":"orderbook_delta","sid":1,"seq":1383,"msg":{"market_ticker":"KXNEXTTEAMNBA-26LJAM-MIA","market_id":"492cb255-91da-4c91-bc9e-f83d090cc6dd","price_dollars":"0.0100","delta_fp":"-1.00","side":"yes","ts":"2026-07-01T02:33:54.662337Z","ts_ms":1782873234662}}

{"type":"orderbook_delta","sid":1,"seq":1384,"msg":{"market_ticker":"KXNEXTTEAMNBA-26LJAM-MIA","market_id":"492cb255-91da-4c91-bc9e-f83d090cc6dd","price_dollars":"0.0100","delta_fp":"-1.00","side":"yes","ts":"2026-07-01T02:33:54.663008Z","ts_ms":1782873234663}}

{"type":"orderbook_delta","sid":1,"seq":1385,"msg":{"market_ticker":"KXNEXTTEAMNBA-26LJAM-MIA","market_id":"492cb255-91da-4c91-bc9e-f83d090cc6dd","price_dollars":"0.0100","delta_fp":"-1.00","side":"yes","ts":"2026-07-01T02:33:54.663634Z","ts_ms":1782873234663}}

{"type":"orderbook_delta","sid":1,"seq":1386,"msg":{"market_ticker":"KXNEXTTEAMNBA-26LJAM-MIA","market_id":"492cb255-91da-4c91-bc9e-f83d090cc6dd","price_dollars":"0.0100","delta_fp":"-1.00","side":"yes","ts":"2026-07-01T02:33:54.664166Z","ts_ms":1782873234664}}

{"type":"orderbook_delta","sid":1,"seq":1387,"msg":{"market_ticker":"KXNEXTTEAMNBA-26LJAM-MIA","market_id":"492cb255-91da-4c91-bc9e-f83d090cc6dd","price_dollars":"0.0100","delta_fp":"-1.00","side":"yes","ts":"2026-07-01T02:33:54.66458Z","ts_ms":1782873234664}}

{"type":"orderbook_delta","sid":1,"seq":1388,"msg":{"market_ticker":"KXNEXTTEAMNBA-26LJAM-MIA","market_id":"492cb255-91da-4c91-bc9e-f83d090cc6dd","price_dollars":"0.0100","delta_fp":"-1.00","side":"yes","ts":"2026-07-01T02:33:54.66513Z","ts_ms":1782873234665}}

{"type":"orderbook_delta","sid":1,"seq":1389,"msg":{"market_ticker":"KXNEXTTEAMNBA-26LJAM-MIA","market_id":"492cb255-91da-4c91-bc9e-f83d090cc6dd","price_dollars":"0.0100","delta_fp":"-1.00","side":"yes","ts":"2026-07-01T02:33:54.665554Z","ts_ms":1782873234665}}

{"type":"orderbook_delta","sid":1,"seq":1390,"msg":{"market_ticker":"KXNEXTTEAMNBA-26LJAM-MIA","market_id":"492cb255-91da-4c91-bc9e-f83d090cc6dd","price_dollars":"0.0100","delta_fp":"-1.00","side":"yes","ts":"2026-07-01T02:33:54.666077Z","ts_ms":1782873234666}}

{"type":"orderbook_delta","sid":1,"seq":1391,"msg":{"market_ticker":"KXNEXTTEAMNBA-26LJAM-CLE","market_id":"7552b8d4-05de-4e41-84a8-97b0684da4a9","price_dollars":"0.7400","delta_fp":"-0.27","side":"no","ts":"2026-07-01T02:33:54.67226Z","ts_ms":1782873234672}}

{"type":"orderbook_delta","sid":1,"seq":1392,"msg":{"market_ticker":"KXNEXTTEAMNBA-26LJAM-MIA","market_id":"492cb255-91da-4c91-bc9e-f83d090cc6dd","price_dollars":"0.8300","delta_fp":"-1.84","side":"no","ts":"2026-07-01T02:33:57.757473Z","ts_ms":1782873237757}}

{"type":"orderbook_delta","sid":1,"seq":1393,"msg":{"market_ticker":"KXNEXTTEAMNBA-26LJAM-CLE","market_id":"7552b8d4-05de-4e41-84a8-97b0684da4a9","price_dollars":"0.7400","delta_fp":"-0.33","side":"no","ts":"2026-07-01T02:33:57.766371Z","ts_ms":1782873237766}}

{"type":"orderbook_delta","sid":1,"seq":1394,"msg":{"market_ticker":"KXNEXTTEAMNBA-26LJAM-GSW","market_id":"abbbad28-f309-4dd5-af38-2ad7ebf2acc3","price_dollars":"0.0100","delta_fp":"1.00","side":"yes","ts":"2026-07-01T02:33:57.824471Z","ts_ms":1782873237824}}

{"type":"orderbook_delta","sid":1,"seq":1395,"msg":{"market_ticker":"KXNEXTTEAMNBA-26LJAM-GSW","market_id":"abbbad28-f309-4dd5-af38-2ad7ebf2acc3","price_dollars":"0.0100","delta_fp":"1.00","side":"yes","ts":"2026-07-01T02:33:57.825278Z","ts_ms":1782873237825}}

{"type":"orderbook_delta","sid":1,"seq":1396,"msg":{"market_ticker":"KXNEXTTEAMNBA-26LJAM-GSW","market_id":"abbbad28-f309-4dd5-af38-2ad7ebf2acc3","price_dollars":"0.0100","delta_fp":"1.00","side":"yes","ts":"2026-07-01T02:33:57.826142Z","ts_ms":1782873237826}}

{"type":"orderbook_delta","sid":1,"seq":1397,"msg":{"market_ticker":"KXNEXTTEAMNBA-26LJAM-GSW","market_id":"abbbad28-f309-4dd5-af38-2ad7ebf2acc3","price_dollars":"0.0100","delta_fp":"1.00","side":"yes","ts":"2026-07-01T02:33:57.826853Z","ts_ms":1782873237826}}

{"type":"orderbook_delta","sid":1,"seq":1398,"msg":{"market_ticker":"KXNEXTTEAMNBA-26LJAM-GSW","market_id":"abbbad28-f309-4dd5-af38-2ad7ebf2acc3","price_dollars":"0.0100","delta_fp":"1.00","side":"yes","ts":"2026-07-01T02:33:57.827634Z","ts_ms":1782873237827}}

{"type":"orderbook_delta","sid":1,"seq":1399,"msg":{"market_ticker":"KXNEXTTEAMNBA-26LJAM-GSW","market_id":"abbbad28-f309-4dd5-af38-2ad7ebf2acc3","price_dollars":"0.0100","delta_fp":"1.00","side":"yes","ts":"2026-07-01T02:33:57.828489Z","ts_ms":1782873237828}}

{"type":"orderbook_delta","sid":1,"seq":1400,"msg":{"market_ticker":"KXNEXTTEAMNBA-26LJAM-GSW","market_id":"abbbad28-f309-4dd5-af38-2ad7ebf2acc3","price_dollars":"0.0100","delta_fp":"1.00","side":"yes","ts":"2026-07-01T02:33:57.82925Z","ts_ms":1782873237829}}

{"type":"orderbook_delta","sid":1,"seq":1401,"msg":{"market_ticker":"KXNEXTTEAMNBA-26LJAM-GSW","market_id":"abbbad28-f309-4dd5-af38-2ad7ebf2acc3","price_dollars":"0.0100","delta_fp":"1.00","side":"yes","ts":"2026-07-01T02:33:57.830032Z","ts_ms":1782873237830}}

{"type":"orderbook_delta","sid":1,"seq":1402,"msg":{"market_ticker":"KXNEXTTEAMNBA-26LJAM-GSW","market_id":"abbbad28-f309-4dd5-af38-2ad7ebf2acc3","price_dollars":"0.0100","delta_fp":"1.00","side":"yes","ts":"2026-07-01T02:33:57.830844Z","ts_ms":1782873237830}}

{"type":"orderbook_delta","sid":1,"seq":1403,"msg":{"market_ticker":"KXNEXTTEAMNBA-26LJAM-GSW","market_id":"abbbad28-f309-4dd5-af38-2ad7ebf2acc3","price_dollars":"0.0100","delta_fp":"1.00","side":"yes","ts":"2026-07-01T02:33:57.831452Z","ts_ms":1782873237831}}

{"type":"orderbook_delta","sid":1,"seq":1404,"msg":{"market_ticker":"KXNEXTTEAMNBA-26LJAM-GSW","market_id":"abbbad28-f309-4dd5-af38-2ad7ebf2acc3","price_dollars":"0.0100","delta_fp":"1.00","side":"yes","ts":"2026-07-01T02:33:57.832151Z","ts_ms":1782873237832}}

{"type":"orderbook_delta","sid":1,"seq":1405,"msg":{"market_ticker":"KXNEXTTEAMNBA-26LJAM-GSW","market_id":"abbbad28-f309-4dd5-af38-2ad7ebf2acc3","price_dollars":"0.0100","delta_fp":"1.00","side":"yes","ts":"2026-07-01T02:33:57.832575Z","ts_ms":1782873237832}}

{"type":"orderbook_delta","sid":1,"seq":1406,"msg":{"market_ticker":"KXNEXTTEAMNBA-26LJAM-GSW","market_id":"abbbad28-f309-4dd5-af38-2ad7ebf2acc3","price_dollars":"0.0100","delta_fp":"1.00","side":"yes","ts":"2026-07-01T02:33:57.833469Z","ts_ms":1782873237833}}

{"type":"orderbook_delta","sid":1,"seq":1407,"msg":{"market_ticker":"KXNEXTTEAMNBA-26LJAM-GSW","market_id":"abbbad28-f309-4dd5-af38-2ad7ebf2acc3","price_dollars":"0.0100","delta_fp":"1.00","side":"yes","ts":"2026-07-01T02:33:57.834209Z","ts_ms":1782873237834}}

{"type":"orderbook_delta","sid":1,"seq":1408,"msg":{"market_ticker":"KXNEXTTEAMNBA-26LJAM-GSW","market_id":"abbbad28-f309-4dd5-af38-2ad7ebf2acc3","price_dollars":"0.0100","delta_fp":"1.00","side":"yes","ts":"2026-07-01T02:33:57.834843Z","ts_ms":1782873237834}}

{"type":"orderbook_delta","sid":1,"seq":1409,"msg":{"market_ticker":"KXNEXTTEAMNBA-26LJAM-GSW","market_id":"abbbad28-f309-4dd5-af38-2ad7ebf2acc3","price_dollars":"0.0100","delta_fp":"1.00","side":"yes","ts":"2026-07-01T02:33:57.835439Z","ts_ms":1782873237835}}

{"type":"orderbook_delta","sid":1,"seq":1410,"msg":{"market_ticker":"KXNEXTTEAMNBA-26LJAM-GSW","market_id":"abbbad28-f309-4dd5-af38-2ad7ebf2acc3","price_dollars":"0.0100","delta_fp":"1.00","side":"yes","ts":"2026-07-01T02:33:57.836073Z","ts_ms":1782873237836}}

{"type":"orderbook_delta","sid":1,"seq":1411,"msg":{"market_ticker":"KXNEXTTEAMNBA-26LJAM-GSW","market_id":"abbbad28-f309-4dd5-af38-2ad7ebf2acc3","price_dollars":"0.0100","delta_fp":"1.00","side":"yes","ts":"2026-07-01T02:33:57.836412Z","ts_ms":1782873237836}}

{"type":"orderbook_delta","sid":1,"seq":1412,"msg":{"market_ticker":"KXNEXTTEAMNBA-26LJAM-GSW","market_id":"abbbad28-f309-4dd5-af38-2ad7ebf2acc3","price_dollars":"0.0100","delta_fp":"1.00","side":"yes","ts":"2026-07-01T02:33:57.836899Z","ts_ms":1782873237836}}

{"type":"orderbook_delta","sid":1,"seq":1413,"msg":{"market_ticker":"KXNEXTTEAMNBA-26LJAM-GSW","market_id":"abbbad28-f309-4dd5-af38-2ad7ebf2acc3","price_dollars":"0.0100","delta_fp":"1.00","side":"yes","ts":"2026-07-01T02:33:57.837431Z","ts_ms":1782873237837}}

{"type":"orderbook_delta","sid":1,"seq":1414,"msg":{"market_ticker":"KXNEXTTEAMNBA-26LJAM-MIA","market_id":"492cb255-91da-4c91-bc9e-f83d090cc6dd","price_dollars":"0.0100","delta_fp":"1.00","side":"yes","ts":"2026-07-01T02:33:59.040833Z","ts_ms":1782873239040}}

{"type":"orderbook_delta","sid":1,"seq":1415,"msg":{"market_ticker":"KXNEXTTEAMNBA-26LJAM-MIA","market_id":"492cb255-91da-4c91-bc9e-f83d090cc6dd","price_dollars":"0.0100","delta_fp":"1.00","side":"yes","ts":"2026-07-01T02:33:59.041341Z","ts_ms":1782873239041}}

{"type":"orderbook_delta","sid":1,"seq":1416,"msg":{"market_ticker":"KXNEXTTEAMNBA-26LJAM-MIA","market_id":"492cb255-91da-4c91-bc9e-f83d090cc6dd","price_dollars":"0.0100","delta_fp":"1.00","side":"yes","ts":"2026-07-01T02:33:59.041762Z","ts_ms":1782873239041}}

{"type":"orderbook_delta","sid":1,"seq":1417,"msg":{"market_ticker":"KXNEXTTEAMNBA-26LJAM-MIA","market_id":"492cb255-91da-4c91-bc9e-f83d090cc6dd","price_dollars":"0.0100","delta_fp":"1.00","side":"yes","ts":"2026-07-01T02:33:59.04244Z","ts_ms":1782873239042}}

{"type":"orderbook_delta","sid":1,"seq":1418,"msg":{"market_ticker":"KXNEXTTEAMNBA-26LJAM-MIA","market_id":"492cb255-91da-4c91-bc9e-f83d090cc6dd","price_dollars":"0.0100","delta_fp":"1.00","side":"yes","ts":"2026-07-01T02:33:59.043107Z","ts_ms":1782873239043}}

{"type":"orderbook_delta","sid":1,"seq":1419,"msg":{"market_ticker":"KXNEXTTEAMNBA-26LJAM-MIA","market_id":"492cb255-91da-4c91-bc9e-f83d090cc6dd","price_dollars":"0.0100","delta_fp":"1.00","side":"yes","ts":"2026-07-01T02:33:59.043452Z","ts_ms":1782873239043}}

{"type":"orderbook_delta","sid":1,"seq":1420,"msg":{"market_ticker":"KXNEXTTEAMNBA-26LJAM-MIA","market_id":"492cb255-91da-4c91-bc9e-f83d090cc6dd","price_dollars":"0.0100","delta_fp":"1.00","side":"yes","ts":"2026-07-01T02:33:59.043865Z","ts_ms":1782873239043}}

{"type":"orderbook_delta","sid":1,"seq":1421,"msg":{"market_ticker":"KXNEXTTEAMNBA-26LJAM-MIA","market_id":"492cb255-91da-4c91-bc9e-f83d090cc6dd","price_dollars":"0.0100","delta_fp":"1.00","side":"yes","ts":"2026-07-01T02:33:59.044319Z","ts_ms":1782873239044}}

{"type":"orderbook_delta","sid":1,"seq":1422,"msg":{"market_ticker":"KXNEXTTEAMNBA-26LJAM-MIA","market_id":"492cb255-91da-4c91-bc9e-f83d090cc6dd","price_dollars":"0.0100","delta_fp":"1.00","side":"yes","ts":"2026-07-01T02:33:59.044666Z","ts_ms":1782873239044}}

{"type":"orderbook_delta","sid":1,"seq":1423,"msg":{"market_ticker":"KXNEXTTEAMNBA-26LJAM-MIA","market_id":"492cb255-91da-4c91-bc9e-f83d090cc6dd","price_dollars":"0.0100","delta_fp":"1.00","side":"yes","ts":"2026-07-01T02:33:59.04517Z","ts_ms":1782873239045}}

{"type":"orderbook_delta","sid":1,"seq":1424,"msg":{"market_ticker":"KXNEXTTEAMNBA-26LJAM-MIA","market_id":"492cb255-91da-4c91-bc9e-f83d090cc6dd","price_dollars":"0.0100","delta_fp":"1.00","side":"yes","ts":"2026-07-01T02:33:59.045721Z","ts_ms":1782873239045}}

{"type":"orderbook_delta","sid":1,"seq":1425,"msg":{"market_ticker":"KXNEXTTEAMNBA-26LJAM-MIA","market_id":"492cb255-91da-4c91-bc9e-f83d090cc6dd","price_dollars":"0.0100","delta_fp":"1.00","side":"yes","ts":"2026-07-01T02:33:59.046181Z","ts_ms":1782873239046}}

{"type":"orderbook_delta","sid":1,"seq":1426,"msg":{"market_ticker":"KXNEXTTEAMNBA-26LJAM-MIA","market_id":"492cb255-91da-4c91-bc9e-f83d090cc6dd","price_dollars":"0.0100","delta_fp":"1.00","side":"yes","ts":"2026-07-01T02:33:59.046864Z","ts_ms":1782873239046}}

{"type":"orderbook_delta","sid":1,"seq":1427,"msg":{"market_ticker":"KXNEXTTEAMNBA-26LJAM-MIA","market_id":"492cb255-91da-4c91-bc9e-f83d090cc6dd","price_dollars":"0.0100","delta_fp":"1.00","side":"yes","ts":"2026-07-01T02:33:59.047305Z","ts_ms":1782873239047}}

{"type":"orderbook_delta","sid":1,"seq":1428,"msg":{"market_ticker":"KXNEXTTEAMNBA-26LJAM-MIA","market_id":"492cb255-91da-4c91-bc9e-f83d090cc6dd","price_dollars":"0.0100","delta_fp":"1.00","side":"yes","ts":"2026-07-01T02:33:59.047641Z","ts_ms":1782873239047}}

{"type":"orderbook_delta","sid":1,"seq":1429,"msg":{"market_ticker":"KXNEXTTEAMNBA-26LJAM-MIA","market_id":"492cb255-91da-4c91-bc9e-f83d090cc6dd","price_dollars":"0.0100","delta_fp":"1.00","side":"yes","ts":"2026-07-01T02:33:59.048093Z","ts_ms":1782873239048}}

{"type":"orderbook_delta","sid":1,"seq":1430,"msg":{"market_ticker":"KXNEXTTEAMNBA-26LJAM-MIA","market_id":"492cb255-91da-4c91-bc9e-f83d090cc6dd","price_dollars":"0.0100","delta_fp":"1.00","side":"yes","ts":"2026-07-01T02:33:59.048809Z","ts_ms":1782873239048}}

{"type":"orderbook_delta","sid":1,"seq":1431,"msg":{"market_ticker":"KXNEXTTEAMNBA-26LJAM-MIA","market_id":"492cb255-91da-4c91-bc9e-f83d090cc6dd","price_dollars":"0.0100","delta_fp":"1.00","side":"yes","ts":"2026-07-01T02:33:59.049289Z","ts_ms":1782873239049}}

{"type":"orderbook_delta","sid":1,"seq":1432,"msg":{"market_ticker":"KXNEXTTEAMNBA-26LJAM-MIA","market_id":"492cb255-91da-4c91-bc9e-f83d090cc6dd","price_dollars":"0.0100","delta_fp":"1.00","side":"yes","ts":"2026-07-01T02:33:59.049772Z","ts_ms":1782873239049}}

{"type":"orderbook_delta","sid":1,"seq":1433,"msg":{"market_ticker":"KXNEXTTEAMNBA-26LJAM-MIA","market_id":"492cb255-91da-4c91-bc9e-f83d090cc6dd","price_dollars":"0.0100","delta_fp":"1.00","side":"yes","ts":"2026-07-01T02:33:59.050267Z","ts_ms":1782873239050}}

{"type":"orderbook_delta","sid":1,"seq":1434,"msg":{"market_ticker":"KXNEXTTEAMNBA-26LJAM-MIA","market_id":"492cb255-91da-4c91-bc9e-f83d090cc6dd","price_dollars":"0.8300","delta_fp":"-1.32","side":"no","ts":"2026-07-01T02:33:59.368463Z","ts_ms":1782873239368}}

{"type":"orderbook_delta","sid":1,"seq":1435,"msg":{"market_ticker":"KXNEXTTEAMNBA-26LJAM-CLE","market_id":"7552b8d4-05de-4e41-84a8-97b0684da4a9","price_dollars":"0.7400","delta_fp":"-0.92","side":"no","ts":"2026-07-01T02:33:59.390805Z","ts_ms":1782873239390}}

{"type":"orderbook_delta","sid":1,"seq":1436,"msg":{"market_ticker":"KXNEXTTEAMNBA-26LJAM-GSW","market_id":"abbbad28-f309-4dd5-af38-2ad7ebf2acc3","price_dollars":"0.5200","delta_fp":"-0.21","side":"no","ts":"2026-07-01T02:33:59.468989Z","ts_ms":1782873239468}}

{"type":"orderbook_delta","sid":1,"seq":1437,"msg":{"market_ticker":"KXNEXTTEAMNBA-26LJAM-GSW","market_id":"abbbad28-f309-4dd5-af38-2ad7ebf2acc3","price_dollars":"0.0100","delta_fp":"-1.00","side":"yes","ts":"2026-07-01T02:33:59.654979Z","ts_ms":1782873239654}}

{"type":"orderbook_delta","sid":1,"seq":1438,"msg":{"market_ticker":"KXNEXTTEAMNBA-26LJAM-GSW","market_id":"abbbad28-f309-4dd5-af38-2ad7ebf2acc3","price_dollars":"0.0100","delta_fp":"-1.00","side":"yes","ts":"2026-07-01T02:33:59.65565Z","ts_ms":1782873239655}}

{"type":"orderbook_delta","sid":1,"seq":1439,"msg":{"market_ticker":"KXNEXTTEAMNBA-26LJAM-GSW","market_id":"abbbad28-f309-4dd5-af38-2ad7ebf2acc3","price_dollars":"0.0100","delta_fp":"-1.00","side":"yes","ts":"2026-07-01T02:33:59.656389Z","ts_ms":1782873239656}}

{"type":"orderbook_delta","sid":1,"seq":1440,"msg":{"market_ticker":"KXNEXTTEAMNBA-26LJAM-GSW","market_id":"abbbad28-f309-4dd5-af38-2ad7ebf2acc3","price_dollars":"0.0100","delta_fp":"-1.00","side":"yes","ts":"2026-07-01T02:33:59.656993Z","ts_ms":1782873239656}}

{"type":"orderbook_delta","sid":1,"seq":1441,"msg":{"market_ticker":"KXNEXTTEAMNBA-26LJAM-GSW","market_id":"abbbad28-f309-4dd5-af38-2ad7ebf2acc3","price_dollars":"0.0100","delta_fp":"-1.00","side":"yes","ts":"2026-07-01T02:33:59.65778Z","ts_ms":1782873239657}}

{"type":"orderbook_delta","sid":1,"seq":1442,"msg":{"market_ticker":"KXNEXTTEAMNBA-26LJAM-GSW","market_id":"abbbad28-f309-4dd5-af38-2ad7ebf2acc3","price_dollars":"0.0100","delta_fp":"-1.00","side":"yes","ts":"2026-07-01T02:33:59.658476Z","ts_ms":1782873239658}}

{"type":"orderbook_delta","sid":1,"seq":1443,"msg":{"market_ticker":"KXNEXTTEAMNBA-26LJAM-GSW","market_id":"abbbad28-f309-4dd5-af38-2ad7ebf2acc3","price_dollars":"0.0100","delta_fp":"-1.00","side":"yes","ts":"2026-07-01T02:33:59.659567Z","ts_ms":1782873239659}}

{"type":"orderbook_delta","sid":1,"seq":1444,"msg":{"market_ticker":"KXNEXTTEAMNBA-26LJAM-GSW","market_id":"abbbad28-f309-4dd5-af38-2ad7ebf2acc3","price_dollars":"0.0100","delta_fp":"-1.00","side":"yes","ts":"2026-07-01T02:33:59.660408Z","ts_ms":1782873239660}}

{"type":"orderbook_delta","sid":1,"seq":1445,"msg":{"market_ticker":"KXNEXTTEAMNBA-26LJAM-GSW","market_id":"abbbad28-f309-4dd5-af38-2ad7ebf2acc3","price_dollars":"0.0100","delta_fp":"-1.00","side":"yes","ts":"2026-07-01T02:33:59.661027Z","ts_ms":1782873239661}}

{"type":"orderbook_delta","sid":1,"seq":1446,"msg":{"market_ticker":"KXNEXTTEAMNBA-26LJAM-GSW","market_id":"abbbad28-f309-4dd5-af38-2ad7ebf2acc3","price_dollars":"0.0100","delta_fp":"-1.00","side":"yes","ts":"2026-07-01T02:33:59.661877Z","ts_ms":1782873239661}}

{"type":"orderbook_delta","sid":1,"seq":1447,"msg":{"market_ticker":"KXNEXTTEAMNBA-26LJAM-GSW","market_id":"abbbad28-f309-4dd5-af38-2ad7ebf2acc3","price_dollars":"0.0100","delta_fp":"-1.00","side":"yes","ts":"2026-07-01T02:33:59.662465Z","ts_ms":1782873239662}}

{"type":"orderbook_delta","sid":1,"seq":1448,"msg":{"market_ticker":"KXNEXTTEAMNBA-26LJAM-GSW","market_id":"abbbad28-f309-4dd5-af38-2ad7ebf2acc3","price_dollars":"0.0100","delta_fp":"-1.00","side":"yes","ts":"2026-07-01T02:33:59.663046Z","ts_ms":1782873239663}}

{"type":"orderbook_delta","sid":1,"seq":1449,"msg":{"market_ticker":"KXNEXTTEAMNBA-26LJAM-GSW","market_id":"abbbad28-f309-4dd5-af38-2ad7ebf2acc3","price_dollars":"0.0100","delta_fp":"-1.00","side":"yes","ts":"2026-07-01T02:33:59.663537Z","ts_ms":1782873239663}}

{"type":"orderbook_delta","sid":1,"seq":1450,"msg":{"market_ticker":"KXNEXTTEAMNBA-26LJAM-GSW","market_id":"abbbad28-f309-4dd5-af38-2ad7ebf2acc3","price_dollars":"0.0100","delta_fp":"-1.00","side":"yes","ts":"2026-07-01T02:33:59.664073Z","ts_ms":1782873239664}}

{"type":"orderbook_delta","sid":1,"seq":1451,"msg":{"market_ticker":"KXNEXTTEAMNBA-26LJAM-GSW","market_id":"abbbad28-f309-4dd5-af38-2ad7ebf2acc3","price_dollars":"0.0100","delta_fp":"-1.00","side":"yes","ts":"2026-07-01T02:33:59.664567Z","ts_ms":1782873239664}}

{"type":"orderbook_delta","sid":1,"seq":1452,"msg":{"market_ticker":"KXNEXTTEAMNBA-26LJAM-GSW","market_id":"abbbad28-f309-4dd5-af38-2ad7ebf2acc3","price_dollars":"0.0100","delta_fp":"-1.00","side":"yes","ts":"2026-07-01T02:33:59.665Z","ts_ms":1782873239665}}

{"type":"orderbook_delta","sid":1,"seq":1453,"msg":{"market_ticker":"KXNEXTTEAMNBA-26LJAM-GSW","market_id":"abbbad28-f309-4dd5-af38-2ad7ebf2acc3","price_dollars":"0.0100","delta_fp":"-1.00","side":"yes","ts":"2026-07-01T02:33:59.665499Z","ts_ms":1782873239665}}

{"type":"orderbook_delta","sid":1,"seq":1454,"msg":{"market_ticker":"KXNEXTTEAMNBA-26LJAM-GSW","market_id":"abbbad28-f309-4dd5-af38-2ad7ebf2acc3","price_dollars":"0.0100","delta_fp":"-1.00","side":"yes","ts":"2026-07-01T02:33:59.665965Z","ts_ms":1782873239665}}

{"type":"orderbook_delta","sid":1,"seq":1455,"msg":{"market_ticker":"KXNEXTTEAMNBA-26LJAM-GSW","market_id":"abbbad28-f309-4dd5-af38-2ad7ebf2acc3","price_dollars":"0.0100","delta_fp":"-1.00","side":"yes","ts":"2026-07-01T02:33:59.666455Z","ts_ms":1782873239666}}

{"type":"orderbook_delta","sid":1,"seq":1456,"msg":{"market_ticker":"KXNEXTTEAMNBA-26LJAM-GSW","market_id":"abbbad28-f309-4dd5-af38-2ad7ebf2acc3","price_dollars":"0.0100","delta_fp":"-1.00","side":"yes","ts":"2026-07-01T02:33:59.666904Z","ts_ms":1782873239666}}

{"type":"orderbook_delta","sid":1,"seq":1457,"msg":{"market_ticker":"KXNEXTTEAMNBA-26LJAM-GSW","market_id":"abbbad28-f309-4dd5-af38-2ad7ebf2acc3","price_dollars":"0.5200","delta_fp":"-1.48","side":"no","ts":"2026-07-01T02:34:00.985309Z","ts_ms":1782873240985}}

{"type":"orderbook_delta","sid":1,"seq":1458,"msg":{"market_ticker":"KXNEXTTEAMNBA-26LJAM-GSW","market_id":"abbbad28-f309-4dd5-af38-2ad7ebf2acc3","price_dollars":"0.5200","delta_fp":"-1.48","side":"no","ts":"2026-07-01T02:34:01.009289Z","ts_ms":1782873241009}}

{"type":"orderbook_delta","sid":1,"seq":1459,"msg":{"market_ticker":"KXNEXTTEAMNBA-26LJAM-MIA","market_id":"492cb255-91da-4c91-bc9e-f83d090cc6dd","price_dollars":"0.8300","delta_fp":"-0.84","side":"no","ts":"2026-07-01T02:34:02.581888Z","ts_ms":1782873242581}}

{"type":"orderbook_delta","sid":1,"seq":1460,"msg":{"market_ticker":"KXNEXTTEAMNBA-26LJAM-GSW","market_id":"abbbad28-f309-4dd5-af38-2ad7ebf2acc3","price_dollars":"0.5200","delta_fp":"-0.06","side":"no","ts":"2026-07-01T02:34:02.592408Z","ts_ms":1782873242592}}

{"type":"orderbook_delta","sid":1,"seq":1461,"msg":{"market_ticker":"KXNEXTTEAMNBA-26LJAM-CLE","market_id":"7552b8d4-05de-4e41-84a8-97b0684da4a9","price_dollars":"0.7400","delta_fp":"-1.12","side":"no","ts":"2026-07-01T02:34:04.184087Z","ts_ms":1782873244184}}

{"type":"orderbook_delta","sid":1,"seq":1462,"msg":{"market_ticker":"KXNEXTTEAMNBA-26LJAM-GSW","market_id":"abbbad28-f309-4dd5-af38-2ad7ebf2acc3","price_dollars":"0.0100","delta_fp":"1.00","side":"yes","ts":"2026-07-01T02:34:04.652568Z","ts_ms":1782873244652}}

{"type":"orderbook_delta","sid":1,"seq":1463,"msg":{"market_ticker":"KXNEXTTEAMNBA-26LJAM-GSW","market_id":"abbbad28-f309-4dd5-af38-2ad7ebf2acc3","price_dollars":"0.0100","delta_fp":"1.00","side":"yes","ts":"2026-07-01T02:34:04.653258Z","ts_ms":1782873244653}}

{"type":"orderbook_delta","sid":1,"seq":1464,"msg":{"market_ticker":"KXNEXTTEAMNBA-26LJAM-GSW","market_id":"abbbad28-f309-4dd5-af38-2ad7ebf2acc3","price_dollars":"0.0100","delta_fp":"1.00","side":"yes","ts":"2026-07-01T02:34:04.654008Z","ts_ms":1782873244654}}

{"type":"orderbook_delta","sid":1,"seq":1465,"msg":{"market_ticker":"KXNEXTTEAMNBA-26LJAM-GSW","market_id":"abbbad28-f309-4dd5-af38-2ad7ebf2acc3","price_dollars":"0.0100","delta_fp":"1.00","side":"yes","ts":"2026-07-01T02:34:04.654675Z","ts_ms":1782873244654}}

{"type":"orderbook_delta","sid":1,"seq":1466,"msg":{"market_ticker":"KXNEXTTEAMNBA-26LJAM-GSW","market_id":"abbbad28-f309-4dd5-af38-2ad7ebf2acc3","price_dollars":"0.0100","delta_fp":"1.00","side":"yes","ts":"2026-07-01T02:34:04.655454Z","ts_ms":1782873244655}}

{"type":"orderbook_delta","sid":1,"seq":1467,"msg":{"market_ticker":"KXNEXTTEAMNBA-26LJAM-GSW","market_id":"abbbad28-f309-4dd5-af38-2ad7ebf2acc3","price_dollars":"0.0100","delta_fp":"1.00","side":"yes","ts":"2026-07-01T02:34:04.656111Z","ts_ms":1782873244656}}

{"type":"orderbook_delta","sid":1,"seq":1468,"msg":{"market_ticker":"KXNEXTTEAMNBA-26LJAM-GSW","market_id":"abbbad28-f309-4dd5-af38-2ad7ebf2acc3","price_dollars":"0.0100","delta_fp":"1.00","side":"yes","ts":"2026-07-01T02:34:04.656812Z","ts_ms":1782873244656}}

{"type":"orderbook_delta","sid":1,"seq":1469,"msg":{"market_ticker":"KXNEXTTEAMNBA-26LJAM-GSW","market_id":"abbbad28-f309-4dd5-af38-2ad7ebf2acc3","price_dollars":"0.0100","delta_fp":"1.00","side":"yes","ts":"2026-07-01T02:34:04.65756Z","ts_ms":1782873244657}}

{"type":"orderbook_delta","sid":1,"seq":1470,"msg":{"market_ticker":"KXNEXTTEAMNBA-26LJAM-GSW","market_id":"abbbad28-f309-4dd5-af38-2ad7ebf2acc3","price_dollars":"0.0100","delta_fp":"1.00","side":"yes","ts":"2026-07-01T02:34:04.658214Z","ts_ms":1782873244658}}

{"type":"orderbook_delta","sid":1,"seq":1471,"msg":{"market_ticker":"KXNEXTTEAMNBA-26LJAM-GSW","market_id":"abbbad28-f309-4dd5-af38-2ad7ebf2acc3","price_dollars":"0.0100","delta_fp":"1.00","side":"yes","ts":"2026-07-01T02:34:04.658836Z","ts_ms":1782873244658}}

{"type":"orderbook_delta","sid":1,"seq":1472,"msg":{"market_ticker":"KXNEXTTEAMNBA-26LJAM-GSW","market_id":"abbbad28-f309-4dd5-af38-2ad7ebf2acc3","price_dollars":"0.0100","delta_fp":"1.00","side":"yes","ts":"2026-07-01T02:34:04.659475Z","ts_ms":1782873244659}}

{"type":"orderbook_delta","sid":1,"seq":1473,"msg":{"market_ticker":"KXNEXTTEAMNBA-26LJAM-GSW","market_id":"abbbad28-f309-4dd5-af38-2ad7ebf2acc3","price_dollars":"0.0100","delta_fp":"1.00","side":"yes","ts":"2026-07-01T02:34:04.66003Z","ts_ms":1782873244660}}

{"type":"orderbook_delta","sid":1,"seq":1474,"msg":{"market_ticker":"KXNEXTTEAMNBA-26LJAM-GSW","market_id":"abbbad28-f309-4dd5-af38-2ad7ebf2acc3","price_dollars":"0.0100","delta_fp":"1.00","side":"yes","ts":"2026-07-01T02:34:04.660774Z","ts_ms":1782873244660}}

{"type":"orderbook_delta","sid":1,"seq":1475,"msg":{"market_ticker":"KXNEXTTEAMNBA-26LJAM-GSW","market_id":"abbbad28-f309-4dd5-af38-2ad7ebf2acc3","price_dollars":"0.0100","delta_fp":"1.00","side":"yes","ts":"2026-07-01T02:34:04.661481Z","ts_ms":1782873244661}}

{"type":"orderbook_delta","sid":1,"seq":1476,"msg":{"market_ticker":"KXNEXTTEAMNBA-26LJAM-GSW","market_id":"abbbad28-f309-4dd5-af38-2ad7ebf2acc3","price_dollars":"0.0100","delta_fp":"1.00","side":"yes","ts":"2026-07-01T02:34:04.661934Z","ts_ms":1782873244661}}

{"type":"orderbook_delta","sid":1,"seq":1477,"msg":{"market_ticker":"KXNEXTTEAMNBA-26LJAM-GSW","market_id":"abbbad28-f309-4dd5-af38-2ad7ebf2acc3","price_dollars":"0.0100","delta_fp":"1.00","side":"yes","ts":"2026-07-01T02:34:04.662339Z","ts_ms":1782873244662}}

{"type":"orderbook_delta","sid":1,"seq":1478,"msg":{"market_ticker":"KXNEXTTEAMNBA-26LJAM-GSW","market_id":"abbbad28-f309-4dd5-af38-2ad7ebf2acc3","price_dollars":"0.0100","delta_fp":"1.00","side":"yes","ts":"2026-07-01T02:34:04.662848Z","ts_ms":1782873244662}}

{"type":"orderbook_delta","sid":1,"seq":1479,"msg":{"market_ticker":"KXNEXTTEAMNBA-26LJAM-GSW","market_id":"abbbad28-f309-4dd5-af38-2ad7ebf2acc3","price_dollars":"0.0100","delta_fp":"1.00","side":"yes","ts":"2026-07-01T02:34:04.663299Z","ts_ms":1782873244663}}

{"type":"orderbook_delta","sid":1,"seq":1480,"msg":{"market_ticker":"KXNEXTTEAMNBA-26LJAM-GSW","market_id":"abbbad28-f309-4dd5-af38-2ad7ebf2acc3","price_dollars":"0.0100","delta_fp":"1.00","side":"yes","ts":"2026-07-01T02:34:04.663852Z","ts_ms":1782873244663}}

{"type":"orderbook_delta","sid":1,"seq":1481,"msg":{"market_ticker":"KXNEXTTEAMNBA-26LJAM-GSW","market_id":"abbbad28-f309-4dd5-af38-2ad7ebf2acc3","price_dollars":"0.0100","delta_fp":"1.00","side":"yes","ts":"2026-07-01T02:34:04.664314Z","ts_ms":1782873244664}}

{"type":"orderbook_delta","sid":1,"seq":1482,"msg":{"market_ticker":"KXNEXTTEAMNBA-26LJAM-MIA","market_id":"492cb255-91da-4c91-bc9e-f83d090cc6dd","price_dollars":"0.0100","delta_fp":"1.00","side":"yes","ts":"2026-07-01T02:34:05.754445Z","ts_ms":1782873245754}}

{"type":"orderbook_delta","sid":1,"seq":1483,"msg":{"market_ticker":"KXNEXTTEAMNBA-26LJAM-MIA","market_id":"492cb255-91da-4c91-bc9e-f83d090cc6dd","price_dollars":"0.0100","delta_fp":"1.00","side":"yes","ts":"2026-07-01T02:34:05.755064Z","ts_ms":1782873245755}}

{"type":"orderbook_delta","sid":1,"seq":1484,"msg":{"market_ticker":"KXNEXTTEAMNBA-26LJAM-MIA","market_id":"492cb255-91da-4c91-bc9e-f83d090cc6dd","price_dollars":"0.0100","delta_fp":"1.00","side":"yes","ts":"2026-07-01T02:34:05.755681Z","ts_ms":1782873245755}}

{"type":"orderbook_delta","sid":1,"seq":1485,"msg":{"market_ticker":"KXNEXTTEAMNBA-26LJAM-MIA","market_id":"492cb255-91da-4c91-bc9e-f83d090cc6dd","price_dollars":"0.0100","delta_fp":"1.00","side":"yes","ts":"2026-07-01T02:34:05.757222Z","ts_ms":1782873245757}}

{"type":"orderbook_delta","sid":1,"seq":1486,"msg":{"market_ticker":"KXNEXTTEAMNBA-26LJAM-MIA","market_id":"492cb255-91da-4c91-bc9e-f83d090cc6dd","price_dollars":"0.0100","delta_fp":"1.00","side":"yes","ts":"2026-07-01T02:34:05.757761Z","ts_ms":1782873245757}}

{"type":"orderbook_delta","sid":1,"seq":1487,"msg":{"market_ticker":"KXNEXTTEAMNBA-26LJAM-MIA","market_id":"492cb255-91da-4c91-bc9e-f83d090cc6dd","price_dollars":"0.0100","delta_fp":"1.00","side":"yes","ts":"2026-07-01T02:34:05.758237Z","ts_ms":1782873245758}}

{"type":"orderbook_delta","sid":1,"seq":1488,"msg":{"market_ticker":"KXNEXTTEAMNBA-26LJAM-MIA","market_id":"492cb255-91da-4c91-bc9e-f83d090cc6dd","price_dollars":"0.0100","delta_fp":"1.00","side":"yes","ts":"2026-07-01T02:34:05.758674Z","ts_ms":1782873245758}}

{"type":"orderbook_delta","sid":1,"seq":1489,"msg":{"market_ticker":"KXNEXTTEAMNBA-26LJAM-MIA","market_id":"492cb255-91da-4c91-bc9e-f83d090cc6dd","price_dollars":"0.0100","delta_fp":"1.00","side":"yes","ts":"2026-07-01T02:34:05.759055Z","ts_ms":1782873245759}}

{"type":"orderbook_delta","sid":1,"seq":1490,"msg":{"market_ticker":"KXNEXTTEAMNBA-26LJAM-MIA","market_id":"492cb255-91da-4c91-bc9e-f83d090cc6dd","price_dollars":"0.0100","delta_fp":"1.00","side":"yes","ts":"2026-07-01T02:34:05.759511Z","ts_ms":1782873245759}}

{"type":"orderbook_delta","sid":1,"seq":1491,"msg":{"market_ticker":"KXNEXTTEAMNBA-26LJAM-MIA","market_id":"492cb255-91da-4c91-bc9e-f83d090cc6dd","price_dollars":"0.0100","delta_fp":"1.00","side":"yes","ts":"2026-07-01T02:34:05.759882Z","ts_ms":1782873245759}}

{"type":"orderbook_delta","sid":1,"seq":1492,"msg":{"market_ticker":"KXNEXTTEAMNBA-26LJAM-MIA","market_id":"492cb255-91da-4c91-bc9e-f83d090cc6dd","price_dollars":"0.0100","delta_fp":"1.00","side":"yes","ts":"2026-07-01T02:34:05.760315Z","ts_ms":1782873245760}}

{"type":"orderbook_delta","sid":1,"seq":1493,"msg":{"market_ticker":"KXNEXTTEAMNBA-26LJAM-MIA","market_id":"492cb255-91da-4c91-bc9e-f83d090cc6dd","price_dollars":"0.0100","delta_fp":"1.00","side":"yes","ts":"2026-07-01T02:34:05.760774Z","ts_ms":1782873245760}}

{"type":"orderbook_delta","sid":1,"seq":1494,"msg":{"market_ticker":"KXNEXTTEAMNBA-26LJAM-MIA","market_id":"492cb255-91da-4c91-bc9e-f83d090cc6dd","price_dollars":"0.0100","delta_fp":"1.00","side":"yes","ts":"2026-07-01T02:34:05.761172Z","ts_ms":1782873245761}}

{"type":"orderbook_delta","sid":1,"seq":1495,"msg":{"market_ticker":"KXNEXTTEAMNBA-26LJAM-MIA","market_id":"492cb255-91da-4c91-bc9e-f83d090cc6dd","price_dollars":"0.0100","delta_fp":"1.00","side":"yes","ts":"2026-07-01T02:34:05.761583Z","ts_ms":1782873245761}}

{"type":"orderbook_delta","sid":1,"seq":1496,"msg":{"market_ticker":"KXNEXTTEAMNBA-26LJAM-MIA","market_id":"492cb255-91da-4c91-bc9e-f83d090cc6dd","price_dollars":"0.0100","delta_fp":"1.00","side":"yes","ts":"2026-07-01T02:34:05.761998Z","ts_ms":1782873245761}}

{"type":"orderbook_delta","sid":1,"seq":1497,"msg":{"market_ticker":"KXNEXTTEAMNBA-26LJAM-MIA","market_id":"492cb255-91da-4c91-bc9e-f83d090cc6dd","price_dollars":"0.0100","delta_fp":"1.00","side":"yes","ts":"2026-07-01T02:34:05.762445Z","ts_ms":1782873245762}}

{"type":"orderbook_delta","sid":1,"seq":1498,"msg":{"market_ticker":"KXNEXTTEAMNBA-26LJAM-MIA","market_id":"492cb255-91da-4c91-bc9e-f83d090cc6dd","price_dollars":"0.0100","delta_fp":"1.00","side":"yes","ts":"2026-07-01T02:34:05.762822Z","ts_ms":1782873245762}}

{"type":"orderbook_delta","sid":1,"seq":1499,"msg":{"market_ticker":"KXNEXTTEAMNBA-26LJAM-MIA","market_id":"492cb255-91da-4c91-bc9e-f83d090cc6dd","price_dollars":"0.0100","delta_fp":"1.00","side":"yes","ts":"2026-07-01T02:34:05.763324Z","ts_ms":1782873245763}}

{"type":"orderbook_delta","sid":1,"seq":1500,"msg":{"market_ticker":"KXNEXTTEAMNBA-26LJAM-MIA","market_id":"492cb255-91da-4c91-bc9e-f83d090cc6dd","price_dollars":"0.0100","delta_fp":"1.00","side":"yes","ts":"2026-07-01T02:34:05.763808Z","ts_ms":1782873245763}}

{"type":"orderbook_delta","sid":1,"seq":1501,"msg":{"market_ticker":"KXNEXTTEAMNBA-26LJAM-MIA","market_id":"492cb255-91da-4c91-bc9e-f83d090cc6dd","price_dollars":"0.0100","delta_fp":"1.00","side":"yes","ts":"2026-07-01T02:34:05.764189Z","ts_ms":1782873245764}}

{"type":"orderbook_delta","sid":1,"seq":1502,"msg":{"market_ticker":"KXNEXTTEAMNBA-26LJAM-CLE","market_id":"7552b8d4-05de-4e41-84a8-97b0684da4a9","price_dollars":"0.7400","delta_fp":"-0.95","side":"no","ts":"2026-07-01T02:34:05.76423Z","ts_ms":1782873245764}}

{"type":"orderbook_delta","sid":1,"seq":1503,"msg":{"market_ticker":"KXNEXTTEAMNBA-26LJAM-GSW","market_id":"abbbad28-f309-4dd5-af38-2ad7ebf2acc3","price_dollars":"0.5200","delta_fp":"-1.58","side":"no","ts":"2026-07-01T02:34:05.773999Z","ts_ms":1782873245773}}

{"type":"orderbook_delta","sid":1,"seq":1504,"msg":{"market_ticker":"KXNEXTTEAMNBA-26LJAM-MIA","market_id":"492cb255-91da-4c91-bc9e-f83d090cc6dd","price_dollars":"0.8300","delta_fp":"-0.99","side":"no","ts":"2026-07-01T02:34:07.166774Z","ts_ms":1782873247166}}

{"type":"orderbook_delta","sid":1,"seq":1505,"msg":{"market_ticker":"KXNEXTTEAMNBA-26LJAM-CLE","market_id":"7552b8d4-05de-4e41-84a8-97b0684da4a9","price_dollars":"0.7400","delta_fp":"-1.78","side":"no","ts":"2026-07-01T02:34:07.361341Z","ts_ms":1782873247361}}

{"type":"orderbook_delta","sid":1,"seq":1506,"msg":{"market_ticker":"KXNEXTTEAMNBA-26LJAM-GSW","market_id":"abbbad28-f309-4dd5-af38-2ad7ebf2acc3","price_dollars":"0.5200","delta_fp":"-1.20","side":"no","ts":"2026-07-01T02:34:07.388919Z","ts_ms":1782873247388}}

{"type":"orderbook_delta","sid":1,"seq":1507,"msg":{"market_ticker":"KXNEXTTEAMNBA-26LJAM-GSW","market_id":"abbbad28-f309-4dd5-af38-2ad7ebf2acc3","price_dollars":"0.5200","delta_fp":"-1.16","side":"no","ts":"2026-07-01T02:34:07.465668Z","ts_ms":1782873247465}}

{"type":"orderbook_delta","sid":1,"seq":1508,"msg":{"market_ticker":"KXNEXTTEAMNBA-26LJAM-MIA","market_id":"492cb255-91da-4c91-bc9e-f83d090cc6dd","price_dollars":"0.8300","delta_fp":"-1.26","side":"no","ts":"2026-07-01T02:34:08.979796Z","ts_ms":1782873248979}}

{"type":"orderbook_delta","sid":1,"seq":1509,"msg":{"market_ticker":"KXNEXTTEAMNBA-26LJAM-MIA","market_id":"492cb255-91da-4c91-bc9e-f83d090cc6dd","price_dollars":"0.8300","delta_fp":"-1.81","side":"no","ts":"2026-07-01T02:34:10.588188Z","ts_ms":1782873250588}}

{"type":"orderbook_delta","sid":1,"seq":1510,"msg":{"market_ticker":"KXNEXTTEAMNBA-26LJAM-MIA","market_id":"492cb255-91da-4c91-bc9e-f83d090cc6dd","price_dollars":"0.8300","delta_fp":"-0.88","side":"no","ts":"2026-07-01T02:34:10.600789Z","ts_ms":1782873250600}}

{"type":"orderbook_delta","sid":1,"seq":1511,"msg":{"market_ticker":"KXNEXTTEAMNBA-26LJAM-GSW","market_id":"abbbad28-f309-4dd5-af38-2ad7ebf2acc3","price_dollars":"0.0100","delta_fp":"1.00","side":"yes","ts":"2026-07-01T02:34:10.871803Z","ts_ms":1782873250871}}

{"type":"orderbook_delta","sid":1,"seq":1512,"msg":{"market_ticker":"KXNEXTTEAMNBA-26LJAM-GSW","market_id":"abbbad28-f309-4dd5-af38-2ad7ebf2acc3","price_dollars":"0.0100","delta_fp":"1.00","side":"yes","ts":"2026-07-01T02:34:10.8724Z","ts_ms":1782873250872}}

{"type":"orderbook_delta","sid":1,"seq":1513,"msg":{"market_ticker":"KXNEXTTEAMNBA-26LJAM-GSW","market_id":"abbbad28-f309-4dd5-af38-2ad7ebf2acc3","price_dollars":"0.0100","delta_fp":"1.00","side":"yes","ts":"2026-07-01T02:34:10.873045Z","ts_ms":1782873250873}}

{"type":"orderbook_delta","sid":1,"seq":1514,"msg":{"market_ticker":"KXNEXTTEAMNBA-26LJAM-GSW","market_id":"abbbad28-f309-4dd5-af38-2ad7ebf2acc3","price_dollars":"0.0100","delta_fp":"1.00","side":"yes","ts":"2026-07-01T02:34:10.873716Z","ts_ms":1782873250873}}

{"type":"orderbook_delta","sid":1,"seq":1515,"msg":{"market_ticker":"KXNEXTTEAMNBA-26LJAM-GSW","market_id":"abbbad28-f309-4dd5-af38-2ad7ebf2acc3","price_dollars":"0.0100","delta_fp":"1.00","side":"yes","ts":"2026-07-01T02:34:10.874183Z","ts_ms":1782873250874}}

{"type":"orderbook_delta","sid":1,"seq":1516,"msg":{"market_ticker":"KXNEXTTEAMNBA-26LJAM-GSW","market_id":"abbbad28-f309-4dd5-af38-2ad7ebf2acc3","price_dollars":"0.0100","delta_fp":"1.00","side":"yes","ts":"2026-07-01T02:34:10.874647Z","ts_ms":1782873250874}}

{"type":"orderbook_delta","sid":1,"seq":1517,"msg":{"market_ticker":"KXNEXTTEAMNBA-26LJAM-GSW","market_id":"abbbad28-f309-4dd5-af38-2ad7ebf2acc3","price_dollars":"0.0100","delta_fp":"1.00","side":"yes","ts":"2026-07-01T02:34:10.875239Z","ts_ms":1782873250875}}

{"type":"orderbook_delta","sid":1,"seq":1518,"msg":{"market_ticker":"KXNEXTTEAMNBA-26LJAM-GSW","market_id":"abbbad28-f309-4dd5-af38-2ad7ebf2acc3","price_dollars":"0.0100","delta_fp":"1.00","side":"yes","ts":"2026-07-01T02:34:10.875589Z","ts_ms":1782873250875}}

{"type":"orderbook_delta","sid":1,"seq":1519,"msg":{"market_ticker":"KXNEXTTEAMNBA-26LJAM-GSW","market_id":"abbbad28-f309-4dd5-af38-2ad7ebf2acc3","price_dollars":"0.0100","delta_fp":"1.00","side":"yes","ts":"2026-07-01T02:34:10.876031Z","ts_ms":1782873250876}}

{"type":"orderbook_delta","sid":1,"seq":1520,"msg":{"market_ticker":"KXNEXTTEAMNBA-26LJAM-GSW","market_id":"abbbad28-f309-4dd5-af38-2ad7ebf2acc3","price_dollars":"0.0100","delta_fp":"1.00","side":"yes","ts":"2026-07-01T02:34:10.876393Z","ts_ms":1782873250876}}

